
#######################################################################
# +-----------------------------------------------------------------+ #
# |                            BO3 object                           | #
# +-----------------------------------------------------------------+ #
#######################################################################

Author: totemo

Description: No description given

Version: 3

SettingsMode: WriteWithoutComments


#######################################################################
# +-----------------------------------------------------------------+ #
# |                          Main settings                          | #
# +-----------------------------------------------------------------+ #
#######################################################################

Tree: false

Frequency: 0

Rarity: 100.0

RotateRandomly: true

SpawnHeight: highestBlock

SpawnHeightOffset: 0

SpawnHeightVariance: 0

##############################
# Height Limits for the BO3. #
##############################

MinHeight: 0

MaxHeight: 256

######################
# Extrusion settings #
######################

ExtrudeMode: None

ExtrudeThroughBlocks: AIR

MaxBranchDepth: 10

ExcludedBiomes: All


#######################################################################
# +-----------------------------------------------------------------+ #
# |                      Source block settings                      | #
# +-----------------------------------------------------------------+ #
#######################################################################

SourceBlocks: AIR

MaxPercentageOutsideSourceBlock: 10

OutsideSourceBlock: placeAnyway

IsOTGPlus: false


#######################################################################
# +-----------------------------------------------------------------+ #
# |                              Blocks                             | #
# +-----------------------------------------------------------------+ #
#######################################################################

Block(-21,28,-5,PURPUR_STAIRS:4)
Block(-21,28,-4,PURPUR_STAIRS:4)
Block(-21,28,-3,PURPUR_STAIRS:0)
Block(-21,28,-2,PURPUR_STAIRS:0)
Block(-21,28,-1,PURPUR_STAIRS:4)
Block(-21,28,0,PURPUR_STAIRS:4)
Block(-21,28,1,PURPUR_STAIRS:0)
Block(-21,28,2,PURPUR_STAIRS:0)
Block(-21,28,3,PURPUR_STAIRS:4)
Block(-21,28,4,PURPUR_STAIRS:4)
Block(-21,28,5,PURPUR_STAIRS:0)
Block(-21,28,6,PURPUR_STAIRS:0)
Block(-21,28,7,PURPUR_STAIRS:4)
Block(-21,28,8,PURPUR_STAIRS:7)
Block(-20,24,-4,PURPUR_STAIRS:4)
Block(-20,24,-3,PURPUR_STAIRS:4)
Block(-20,24,-2,PURPUR_STAIRS:0)
Block(-20,24,-1,PURPUR_STAIRS:4)
Block(-20,24,0,PURPUR_STAIRS:4)
Block(-20,24,1,PURPUR_STAIRS:0)
Block(-20,24,2,PURPUR_STAIRS:0)
Block(-20,24,3,PURPUR_STAIRS:4)
Block(-20,24,4,PURPUR_STAIRS:4)
Block(-20,24,5,PURPUR_STAIRS:0)
Block(-20,24,6,PURPUR_STAIRS:4)
Block(-20,24,7,PURPUR_STAIRS:7)
Block(-20,25,-4,END_ROD)
Block(-20,25,7,END_ROD)
Block(-20,28,-5,PURPUR_STAIRS:6)
Block(-20,28,-4,PURPUR_BLOCK)
Block(-20,28,-3,PURPUR_BLOCK)
Block(-20,28,-2,PURPUR_BLOCK)
Block(-20,28,-1,PURPUR_BLOCK)
Block(-20,28,0,PURPUR_BLOCK)
Block(-20,28,1,PURPUR_BLOCK)
Block(-20,28,2,PURPUR_BLOCK)
Block(-20,28,3,PURPUR_BLOCK)
Block(-20,28,4,PURPUR_BLOCK)
Block(-20,28,5,PURPUR_BLOCK)
Block(-20,28,6,PURPUR_BLOCK)
Block(-20,28,7,PURPUR_BLOCK)
Block(-20,28,8,PURPUR_STAIRS:7)
Block(-20,29,-4,END_ROD)
Block(-20,29,7,END_ROD)
Block(-19,24,-4,PURPUR_STAIRS:6)
Block(-19,24,-3,PURPUR_BLOCK)
Block(-19,24,-2,PURPUR_BLOCK)
Block(-19,24,-1,PURPUR_BLOCK)
Block(-19,24,0,PURPUR_BLOCK)
Block(-19,24,1,PURPUR_BLOCK)
Block(-19,24,2,PURPUR_BLOCK)
Block(-19,24,3,PURPUR_BLOCK)
Block(-19,24,4,PURPUR_BLOCK)
Block(-19,24,5,PURPUR_BLOCK)
Block(-19,24,6,PURPUR_BLOCK)
Block(-19,24,7,PURPUR_STAIRS:7)
Block(-19,25,-3,PURPUR_PILLAR:0)
Block(-19,25,-2,END_BRICKS)
Block(-19,25,-1,END_BRICKS)
Block(-19,25,0,END_BRICKS)
Block(-19,25,1,END_BRICKS)
Block(-19,25,2,END_BRICKS)
Block(-19,25,3,END_BRICKS)
Block(-19,25,4,END_BRICKS)
Block(-19,25,5,END_BRICKS)
Block(-19,25,6,PURPUR_PILLAR:0)
Block(-19,26,-3,PURPUR_PILLAR:0)
Block(-19,26,-2,END_BRICKS)
Block(-19,26,-1,STAINED_GLASS:2)
Block(-19,26,0,END_BRICKS)
Block(-19,26,1,END_BRICKS)
Block(-19,26,2,END_BRICKS)
Block(-19,26,3,END_BRICKS)
Block(-19,26,4,STAINED_GLASS:2)
Block(-19,26,5,END_BRICKS)
Block(-19,26,6,PURPUR_PILLAR:0)
Block(-19,27,-3,PURPUR_PILLAR:0)
Block(-19,27,-2,END_BRICKS)
Block(-19,27,-1,STAINED_GLASS:2)
Block(-19,27,0,END_BRICKS)
Block(-19,27,1,END_BRICKS)
Block(-19,27,2,END_BRICKS)
Block(-19,27,3,END_BRICKS)
Block(-19,27,4,STAINED_GLASS:2)
Block(-19,27,5,END_BRICKS)
Block(-19,27,6,PURPUR_PILLAR:0)
Block(-19,28,-5,PURPUR_STAIRS:2)
Block(-19,28,-4,PURPUR_BLOCK)
Block(-19,28,-3,PURPUR_BLOCK)
Block(-19,28,-2,PURPUR_BLOCK)
Block(-19,28,-1,PURPUR_BLOCK)
Block(-19,28,0,PURPUR_BLOCK)
Block(-19,28,1,PURPUR_BLOCK)
Block(-19,28,2,PURPUR_BLOCK)
Block(-19,28,3,PURPUR_BLOCK)
Block(-19,28,4,PURPUR_BLOCK)
Block(-19,28,5,PURPUR_BLOCK)
Block(-19,28,6,PURPUR_BLOCK)
Block(-19,28,7,PURPUR_BLOCK)
Block(-19,28,8,PURPUR_STAIRS:0)
Block(-18,20,-2,PURPUR_BLOCK)
Block(-18,20,-1,PURPUR_BLOCK)
Block(-18,20,0,PURPUR_BLOCK)
Block(-18,20,1,PURPUR_BLOCK)
Block(-18,20,2,PURPUR_BLOCK)
Block(-18,20,3,PURPUR_BLOCK)
Block(-18,20,4,PURPUR_BLOCK)
Block(-18,20,5,PURPUR_BLOCK)
Block(-18,21,-2,PURPUR_PILLAR:0)
Block(-18,21,-1,END_BRICKS)
Block(-18,21,0,END_BRICKS)
Block(-18,21,1,END_BRICKS)
Block(-18,21,2,END_BRICKS)
Block(-18,21,3,END_BRICKS)
Block(-18,21,4,END_BRICKS)
Block(-18,21,5,PURPUR_PILLAR:0)
Block(-18,22,-2,PURPUR_PILLAR:0)
Block(-18,22,-1,END_BRICKS)
Block(-18,22,0,STAINED_GLASS:2)
Block(-18,22,1,END_BRICKS)
Block(-18,22,2,END_BRICKS)
Block(-18,22,3,STAINED_GLASS:2)
Block(-18,22,4,END_BRICKS)
Block(-18,22,5,PURPUR_PILLAR:0)
Block(-18,23,-2,PURPUR_PILLAR:0)
Block(-18,23,-1,END_BRICKS)
Block(-18,23,0,STAINED_GLASS:2)
Block(-18,23,1,END_BRICKS)
Block(-18,23,2,END_BRICKS)
Block(-18,23,3,STAINED_GLASS:2)
Block(-18,23,4,END_BRICKS)
Block(-18,23,5,PURPUR_PILLAR:0)
Block(-18,24,-4,PURPUR_STAIRS:2)
Block(-18,24,-3,PURPUR_BLOCK)
Block(-18,24,-2,PURPUR_BLOCK)
Block(-18,24,-1,PURPUR_BLOCK)
Block(-18,24,0,PURPUR_BLOCK)
Block(-18,24,1,PURPUR_BLOCK)
Block(-18,24,2,PURPUR_BLOCK)
Block(-18,24,3,PURPUR_BLOCK)
Block(-18,24,4,PURPUR_BLOCK)
Block(-18,24,5,PURPUR_BLOCK)
Block(-18,24,6,PURPUR_BLOCK)
Block(-18,24,7,PURPUR_STAIRS:0)
Block(-18,25,-3,END_BRICKS)
Block(-18,25,6,END_BRICKS)
Block(-18,26,-3,END_BRICKS)
Block(-18,26,6,END_BRICKS)
Block(-18,27,-3,END_BRICKS)
Block(-18,27,6,END_BRICKS)
Block(-18,28,-5,PURPUR_STAIRS:2)
Block(-18,28,-4,PURPUR_BLOCK)
Block(-18,28,-3,PURPUR_BLOCK)
Block(-18,28,-2,PURPUR_BLOCK)
Block(-18,28,-1,PURPUR_BLOCK)
Block(-18,28,0,PURPUR_BLOCK)
Block(-18,28,1,PURPUR_BLOCK)
Block(-18,28,2,PURPUR_BLOCK)
Block(-18,28,3,PURPUR_BLOCK)
Block(-18,28,4,PURPUR_BLOCK)
Block(-18,28,5,PURPUR_BLOCK)
Block(-18,28,6,PURPUR_BLOCK)
Block(-18,28,7,PURPUR_BLOCK)
Block(-18,28,8,PURPUR_STAIRS:0)
Block(-17,20,-2,PURPUR_BLOCK)
Block(-17,20,-1,PURPUR_BLOCK)
Block(-17,20,0,PURPUR_BLOCK)
Block(-17,20,1,PURPUR_BLOCK)
Block(-17,20,2,PURPUR_BLOCK)
Block(-17,20,3,PURPUR_BLOCK)
Block(-17,20,4,PURPUR_BLOCK)
Block(-17,20,5,PURPUR_BLOCK)
Block(-17,21,-2,END_BRICKS)
Block(-17,21,5,END_BRICKS)
Block(-17,22,-2,END_BRICKS)
Block(-17,22,5,END_BRICKS)
Block(-17,23,-2,END_BRICKS)
Block(-17,23,5,END_BRICKS)
Block(-17,24,-4,PURPUR_STAIRS:6)
Block(-17,24,-3,PURPUR_BLOCK)
Block(-17,24,-2,PURPUR_BLOCK)
Block(-17,24,5,PURPUR_BLOCK)
Block(-17,24,6,PURPUR_BLOCK)
Block(-17,24,7,PURPUR_STAIRS:7)
Block(-17,25,-3,END_BRICKS)
Block(-17,25,6,END_BRICKS)
Block(-17,26,-3,STAINED_GLASS:2)
Block(-17,26,6,STAINED_GLASS:2)
Block(-17,27,-3,STAINED_GLASS:2)
Block(-17,27,6,STAINED_GLASS:2)
Block(-17,28,-5,PURPUR_STAIRS:6)
Block(-17,28,-4,PURPUR_BLOCK)
Block(-17,28,-3,PURPUR_BLOCK)
Block(-17,28,-2,PURPUR_BLOCK)
Block(-17,28,-1,PURPUR_BLOCK)
Block(-17,28,0,PURPUR_BLOCK)
Block(-17,28,1,PURPUR_BLOCK)
Block(-17,28,2,PURPUR_BLOCK)
Block(-17,28,3,PURPUR_BLOCK)
Block(-17,28,4,PURPUR_BLOCK)
Block(-17,28,5,PURPUR_BLOCK)
Block(-17,28,6,PURPUR_BLOCK)
Block(-17,28,7,PURPUR_BLOCK)
Block(-17,28,8,PURPUR_STAIRS:7)
Block(-16,20,-2,PURPUR_BLOCK)
Block(-16,20,-1,PURPUR_BLOCK)
Block(-16,20,0,PURPUR_BLOCK)
Block(-16,20,1,PURPUR_BLOCK)
Block(-16,20,2,PURPUR_BLOCK)
Block(-16,20,3,PURPUR_BLOCK)
Block(-16,20,4,PURPUR_BLOCK)
Block(-16,20,5,PURPUR_BLOCK)
Block(-16,21,-2,END_BRICKS)
Block(-16,21,5,END_BRICKS)
Block(-16,22,-2,STAINED_GLASS:2)
Block(-16,22,5,STAINED_GLASS:2)
Block(-16,23,-2,STAINED_GLASS:2)
Block(-16,23,2,PURPUR_SLAB)
Block(-16,23,5,STAINED_GLASS:2)
Block(-16,24,-4,PURPUR_STAIRS:6)
Block(-16,24,-3,PURPUR_BLOCK)
Block(-16,24,-2,PURPUR_BLOCK)
Block(-16,24,5,PURPUR_BLOCK)
Block(-16,24,6,PURPUR_BLOCK)
Block(-16,24,7,PURPUR_STAIRS:7)
Block(-16,25,-3,END_BRICKS)
Block(-16,25,6,END_BRICKS)
Block(-16,26,-3,END_BRICKS)
Block(-16,26,6,END_BRICKS)
Block(-16,27,-3,END_BRICKS)
Block(-16,27,6,END_BRICKS)
Block(-16,28,-5,PURPUR_STAIRS:6)
Block(-16,28,-4,PURPUR_BLOCK)
Block(-16,28,-3,PURPUR_BLOCK)
Block(-16,28,-2,PURPUR_BLOCK)
Block(-16,28,-1,PURPUR_BLOCK)
Block(-16,28,0,PURPUR_BLOCK)
Block(-16,28,1,PURPUR_BLOCK)
Block(-16,28,2,PURPUR_BLOCK)
Block(-16,28,3,PURPUR_BLOCK)
Block(-16,28,4,PURPUR_BLOCK)
Block(-16,28,5,PURPUR_BLOCK)
Block(-16,28,6,PURPUR_BLOCK)
Block(-16,28,7,PURPUR_BLOCK)
Block(-16,28,8,PURPUR_STAIRS:7)
Block(-15,20,-2,PURPUR_BLOCK)
Block(-15,20,-1,PURPUR_BLOCK)
Block(-15,20,0,PURPUR_BLOCK)
Block(-15,20,1,PURPUR_BLOCK)
Block(-15,20,2,PURPUR_BLOCK)
Block(-15,20,3,PURPUR_BLOCK)
Block(-15,20,4,PURPUR_BLOCK)
Block(-15,20,5,PURPUR_BLOCK)
Block(-15,21,-2,END_BRICKS)
Block(-15,21,1,PURPUR_BLOCK)
Block(-15,21,2,PURPUR_BLOCK)
Block(-15,21,5,END_BRICKS)
Block(-15,22,-2,END_BRICKS)
Block(-15,22,0,PURPUR_SLAB)
Block(-15,22,1,PURPUR_STAIRS:2)
Block(-15,22,2,PURPUR_BLOCK)
Block(-15,22,5,END_BRICKS)
Block(-15,23,-2,END_BRICKS)
Block(-15,23,2,PURPUR_STAIRS:0)
Block(-15,23,5,END_BRICKS)
Block(-15,24,-4,PURPUR_STAIRS:2)
Block(-15,24,-3,PURPUR_BLOCK)
Block(-15,24,-2,PURPUR_BLOCK)
Block(-15,24,5,PURPUR_BLOCK)
Block(-15,24,6,PURPUR_BLOCK)
Block(-15,24,7,PURPUR_STAIRS:0)
Block(-15,25,-3,END_BRICKS)
Block(-15,25,6,END_BRICKS)
Block(-15,26,-3,END_BRICKS)
Block(-15,26,6,END_BRICKS)
Block(-15,27,-3,END_BRICKS)
Block(-15,27,6,END_BRICKS)
Block(-15,28,-5,PURPUR_STAIRS:2)
Block(-15,28,-4,PURPUR_BLOCK)
Block(-15,28,-3,PURPUR_BLOCK)
Block(-15,28,-2,PURPUR_BLOCK)
Block(-15,28,-1,PURPUR_BLOCK)
Block(-15,28,0,PURPUR_BLOCK)
Block(-15,28,1,PURPUR_BLOCK)
Block(-15,28,2,PURPUR_BLOCK)
Block(-15,28,3,PURPUR_BLOCK)
Block(-15,28,4,PURPUR_BLOCK)
Block(-15,28,5,PURPUR_BLOCK)
Block(-15,28,6,PURPUR_BLOCK)
Block(-15,28,7,PURPUR_BLOCK)
Block(-15,28,8,PURPUR_STAIRS:0)
Block(-14,20,-2,PURPUR_BLOCK)
Block(-14,20,-1,PURPUR_BLOCK)
Block(-14,20,0,PURPUR_BLOCK)
Block(-14,20,1,PURPUR_BLOCK)
Block(-14,20,2,PURPUR_BLOCK)
Block(-14,20,3,PURPUR_BLOCK)
Block(-14,20,4,PURPUR_BLOCK)
Block(-14,20,5,PURPUR_BLOCK)
Block(-14,21,-2,END_BRICKS)
Block(-14,21,1,PURPUR_STAIRS:1)
Block(-14,21,2,PURPUR_BLOCK)
Block(-14,21,5,END_BRICKS)
Block(-14,22,-2,END_BRICKS)
Block(-14,22,2,PURPUR_BLOCK)
Block(-14,22,5,END_BRICKS)
Block(-14,23,-2,END_BRICKS)
Block(-14,23,2,PURPUR_BLOCK)
Block(-14,23,3,PURPUR_SLAB:8)
Block(-14,23,5,END_BRICKS)
Block(-14,24,-4,PURPUR_STAIRS:2)
Block(-14,24,-3,PURPUR_BLOCK)
Block(-14,24,-2,PURPUR_BLOCK)
Block(-14,24,-1,PURPUR_SLAB:8)
Block(-14,24,0,PURPUR_SLAB:8)
Block(-14,24,1,PURPUR_SLAB:8)
Block(-14,24,2,PURPUR_STAIRS:0)
Block(-14,24,5,PURPUR_BLOCK)
Block(-14,24,6,PURPUR_BLOCK)
Block(-14,24,7,PURPUR_STAIRS:0)
Block(-14,25,-3,END_BRICKS)
Block(-14,25,6,END_BRICKS)
Block(-14,26,-3,END_BRICKS)
Block(-14,26,6,END_BRICKS)
Block(-14,27,-3,END_BRICKS)
Block(-14,27,6,END_BRICKS)
Block(-14,28,-5,PURPUR_STAIRS:2)
Block(-14,28,-4,PURPUR_BLOCK)
Block(-14,28,-3,PURPUR_BLOCK)
Block(-14,28,-2,PURPUR_BLOCK)
Block(-14,28,-1,PURPUR_BLOCK)
Block(-14,28,0,PURPUR_BLOCK)
Block(-14,28,1,PURPUR_BLOCK)
Block(-14,28,2,PURPUR_BLOCK)
Block(-14,28,3,PURPUR_BLOCK)
Block(-14,28,4,PURPUR_BLOCK)
Block(-14,28,5,PURPUR_BLOCK)
Block(-14,28,6,PURPUR_BLOCK)
Block(-14,28,7,PURPUR_BLOCK)
Block(-14,28,8,PURPUR_STAIRS:0)
Block(-13,20,-2,PURPUR_BLOCK)
Block(-13,20,-1,PURPUR_BLOCK)
Block(-13,20,0,PURPUR_BLOCK)
Block(-13,20,1,PURPUR_BLOCK)
Block(-13,20,2,PURPUR_BLOCK)
Block(-13,20,3,PURPUR_BLOCK)
Block(-13,20,4,PURPUR_BLOCK)
Block(-13,20,5,PURPUR_BLOCK)
Block(-13,21,-2,END_BRICKS)
Block(-13,21,1,PURPUR_SLAB)
Block(-13,21,5,END_BRICKS)
Block(-13,22,-2,STAINED_GLASS:2)
Block(-13,22,5,STAINED_GLASS:2)
Block(-13,23,-2,STAINED_GLASS:2)
Block(-13,23,5,STAINED_GLASS:2)
Block(-13,24,-4,PURPUR_STAIRS:6)
Block(-13,24,-3,PURPUR_BLOCK)
Block(-13,24,-2,PURPUR_BLOCK)
Block(-13,24,5,PURPUR_BLOCK)
Block(-13,24,6,PURPUR_BLOCK)
Block(-13,24,7,PURPUR_STAIRS:7)
Block(-13,25,-3,END_BRICKS)
Block(-13,25,-2,PURPUR_STAIRS:7)
Block(-13,25,6,END_BRICKS)
Block(-13,26,-3,END_BRICKS)
Block(-13,26,-2,PURPUR_STAIRS:0)
Block(-13,26,6,END_BRICKS)
Block(-13,27,-3,END_BRICKS)
Block(-13,27,-2,PURPUR_STAIRS:7)
Block(-13,27,6,END_BRICKS)
Block(-13,28,-5,PURPUR_STAIRS:6)
Block(-13,28,-4,PURPUR_BLOCK)
Block(-13,28,-3,PURPUR_BLOCK)
Block(-13,28,-2,PURPUR_BLOCK)
Block(-13,28,-1,PURPUR_BLOCK)
Block(-13,28,0,PURPUR_BLOCK)
Block(-13,28,1,PURPUR_BLOCK)
Block(-13,28,2,PURPUR_BLOCK)
Block(-13,28,3,PURPUR_BLOCK)
Block(-13,28,4,PURPUR_BLOCK)
Block(-13,28,5,PURPUR_BLOCK)
Block(-13,28,6,PURPUR_BLOCK)
Block(-13,28,7,PURPUR_BLOCK)
Block(-13,28,8,PURPUR_STAIRS:7)
Block(-12,20,-2,PURPUR_BLOCK)
Block(-12,20,-1,PURPUR_BLOCK)
Block(-12,20,0,PURPUR_BLOCK)
Block(-12,20,1,PURPUR_BLOCK)
Block(-12,20,2,PURPUR_BLOCK)
Block(-12,20,3,PURPUR_BLOCK)
Block(-12,20,4,PURPUR_BLOCK)
Block(-12,20,5,PURPUR_BLOCK)
Block(-12,21,-2,END_BRICKS)
Block(-12,21,5,END_BRICKS)
Block(-12,22,-2,END_BRICKS)
Block(-12,22,5,END_BRICKS)
Block(-12,23,-2,END_BRICKS)
Block(-12,23,5,END_BRICKS)
Block(-12,24,-4,PURPUR_STAIRS:6)
Block(-12,24,-3,PURPUR_BLOCK)
Block(-12,24,-2,PURPUR_BLOCK)
Block(-12,24,5,PURPUR_BLOCK)
Block(-12,24,6,PURPUR_BLOCK)
Block(-12,24,7,PURPUR_STAIRS:7)
Block(-12,25,-3,END_BRICKS)
Block(-12,25,-2,PURPUR_STAIRS:7)
Block(-12,25,6,END_BRICKS)
Block(-12,26,-3,END_BRICKS)
Block(-12,26,-2,PURPUR_STAIRS:0)
Block(-12,26,6,STAINED_GLASS:2)
Block(-12,27,-3,END_BRICKS)
Block(-12,27,-2,PURPUR_STAIRS:7)
Block(-12,27,6,STAINED_GLASS:2)
Block(-12,28,-5,PURPUR_STAIRS:6)
Block(-12,28,-4,PURPUR_BLOCK)
Block(-12,28,-3,PURPUR_BLOCK)
Block(-12,28,-2,PURPUR_BLOCK)
Block(-12,28,-1,PURPUR_BLOCK)
Block(-12,28,0,PURPUR_BLOCK)
Block(-12,28,1,PURPUR_BLOCK)
Block(-12,28,2,PURPUR_BLOCK)
Block(-12,28,3,PURPUR_BLOCK)
Block(-12,28,4,PURPUR_BLOCK)
Block(-12,28,5,PURPUR_BLOCK)
Block(-12,28,6,PURPUR_BLOCK)
Block(-12,28,7,PURPUR_BLOCK)
Block(-12,28,8,PURPUR_STAIRS:7)
Block(-11,20,-2,PURPUR_BLOCK)
Block(-11,20,-1,PURPUR_BLOCK)
Block(-11,20,0,PURPUR_BLOCK)
Block(-11,20,1,PURPUR_BLOCK)
Block(-11,20,2,PURPUR_BLOCK)
Block(-11,20,3,PURPUR_BLOCK)
Block(-11,20,4,PURPUR_BLOCK)
Block(-11,20,5,PURPUR_BLOCK)
Block(-11,21,-2,PURPUR_PILLAR:0)
Block(-11,21,-1,END_BRICKS)
Block(-11,21,0,END_BRICKS)
Block(-11,21,3,END_BRICKS)
Block(-11,21,4,END_BRICKS)
Block(-11,21,5,PURPUR_PILLAR:0)
Block(-11,22,-2,PURPUR_PILLAR:0)
Block(-11,22,-1,END_BRICKS)
Block(-11,22,0,END_BRICKS)
Block(-11,22,3,END_BRICKS)
Block(-11,22,4,END_BRICKS)
Block(-11,22,5,PURPUR_PILLAR:0)
Block(-11,23,-2,PURPUR_PILLAR:0)
Block(-11,23,-1,END_BRICKS)
Block(-11,23,0,END_BRICKS)
Block(-11,23,3,END_BRICKS)
Block(-11,23,4,END_BRICKS)
Block(-11,23,5,PURPUR_PILLAR:0)
Block(-11,24,-4,PURPUR_STAIRS:2)
Block(-11,24,-3,PURPUR_BLOCK)
Block(-11,24,-2,PURPUR_BLOCK)
Block(-11,24,-1,PURPUR_BLOCK)
Block(-11,24,0,PURPUR_BLOCK)
Block(-11,24,1,PURPUR_BLOCK)
Block(-11,24,2,PURPUR_BLOCK)
Block(-11,24,3,PURPUR_BLOCK)
Block(-11,24,4,PURPUR_BLOCK)
Block(-11,24,5,PURPUR_BLOCK)
Block(-11,24,6,PURPUR_BLOCK)
Block(-11,24,7,PURPUR_STAIRS:0)
Block(-11,25,-3,END_BRICKS)
Block(-11,25,-2,CHEST:3,EndTowerB/1-chest.nbt)
Block(-11,25,6,END_BRICKS)
Block(-11,26,-3,END_BRICKS)
Block(-11,26,6,END_BRICKS)
Block(-11,27,-3,END_BRICKS)
Block(-11,27,6,END_BRICKS)
Block(-11,28,-5,PURPUR_STAIRS:2)
Block(-11,28,-4,PURPUR_BLOCK)
Block(-11,28,-3,PURPUR_BLOCK)
Block(-11,28,-2,PURPUR_BLOCK)
Block(-11,28,-1,PURPUR_BLOCK)
Block(-11,28,0,PURPUR_BLOCK)
Block(-11,28,1,PURPUR_BLOCK)
Block(-11,28,2,PURPUR_BLOCK)
Block(-11,28,3,PURPUR_BLOCK)
Block(-11,28,4,PURPUR_BLOCK)
Block(-11,28,5,PURPUR_BLOCK)
Block(-11,28,6,PURPUR_BLOCK)
Block(-11,28,7,PURPUR_BLOCK)
Block(-11,28,8,PURPUR_STAIRS:0)
Block(-10,20,-1,PURPUR_STAIRS:1)
Block(-10,20,0,PURPUR_BLOCK)
Block(-10,20,1,PURPUR_BLOCK)
Block(-10,20,2,PURPUR_BLOCK)
Block(-10,20,3,PURPUR_BLOCK)
Block(-10,20,4,PURPUR_STAIRS:1)
Block(-10,24,-4,PURPUR_STAIRS:6)
Block(-10,24,-3,PURPUR_BLOCK)
Block(-10,24,-2,PURPUR_BLOCK)
Block(-10,24,-1,PURPUR_BLOCK)
Block(-10,24,0,PURPUR_BLOCK)
Block(-10,24,1,PURPUR_BLOCK)
Block(-10,24,2,PURPUR_BLOCK)
Block(-10,24,3,PURPUR_BLOCK)
Block(-10,24,4,PURPUR_BLOCK)
Block(-10,24,5,PURPUR_BLOCK)
Block(-10,24,6,PURPUR_BLOCK)
Block(-10,24,7,PURPUR_STAIRS:7)
Block(-10,25,-3,PURPUR_PILLAR:0)
Block(-10,25,-2,END_BRICKS)
Block(-10,25,-1,END_BRICKS)
Block(-10,25,0,END_BRICKS)
Block(-10,25,1,END_BRICKS)
Block(-10,25,2,END_BRICKS)
Block(-10,25,3,END_BRICKS)
Block(-10,25,4,END_BRICKS)
Block(-10,25,5,END_BRICKS)
Block(-10,25,6,PURPUR_PILLAR:0)
Block(-10,26,-3,PURPUR_PILLAR:0)
Block(-10,26,-2,END_BRICKS)
Block(-10,26,-1,STAINED_GLASS:2)
Block(-10,26,0,END_BRICKS)
Block(-10,26,1,END_BRICKS)
Block(-10,26,2,END_BRICKS)
Block(-10,26,3,END_BRICKS)
Block(-10,26,4,STAINED_GLASS:2)
Block(-10,26,5,END_BRICKS)
Block(-10,26,6,PURPUR_PILLAR:0)
Block(-10,27,-3,PURPUR_PILLAR:0)
Block(-10,27,-2,END_BRICKS)
Block(-10,27,-1,STAINED_GLASS:2)
Block(-10,27,0,END_BRICKS)
Block(-10,27,1,END_BRICKS)
Block(-10,27,2,END_BRICKS)
Block(-10,27,3,END_BRICKS)
Block(-10,27,4,STAINED_GLASS:2)
Block(-10,27,5,END_BRICKS)
Block(-10,27,6,PURPUR_PILLAR:0)
Block(-10,28,-5,PURPUR_STAIRS:2)
Block(-10,28,-4,PURPUR_BLOCK)
Block(-10,28,-3,PURPUR_BLOCK)
Block(-10,28,-2,PURPUR_BLOCK)
Block(-10,28,-1,PURPUR_BLOCK)
Block(-10,28,0,PURPUR_BLOCK)
Block(-10,28,1,PURPUR_BLOCK)
Block(-10,28,2,PURPUR_BLOCK)
Block(-10,28,3,PURPUR_BLOCK)
Block(-10,28,4,PURPUR_BLOCK)
Block(-10,28,5,PURPUR_BLOCK)
Block(-10,28,6,PURPUR_BLOCK)
Block(-10,28,7,PURPUR_BLOCK)
Block(-10,28,8,PURPUR_STAIRS:0)
Block(-9,19,0,PURPUR_BLOCK)
Block(-9,19,1,PURPUR_BLOCK)
Block(-9,19,2,PURPUR_BLOCK)
Block(-9,20,-1,PURPUR_BLOCK)
Block(-9,20,0,PURPUR_BLOCK)
Block(-9,20,1,PURPUR_BLOCK)
Block(-9,20,2,PURPUR_BLOCK)
Block(-9,20,3,PURPUR_BLOCK)
Block(-9,21,-1,PURPUR_BLOCK)
Block(-9,21,3,PURPUR_BLOCK)
Block(-9,22,-1,PURPUR_BLOCK)
Block(-9,22,3,PURPUR_BLOCK)
Block(-9,23,-1,PURPUR_BLOCK)
Block(-9,23,0,PURPUR_SLAB:8)
Block(-9,23,2,PURPUR_SLAB:8)
Block(-9,23,3,PURPUR_BLOCK)
Block(-9,24,-4,PURPUR_STAIRS:6)
Block(-9,24,-3,PURPUR_STAIRS:5)
Block(-9,24,-2,PURPUR_STAIRS:1)
Block(-9,24,-1,PURPUR_SLAB)
Block(-9,24,0,PURPUR_BLOCK)
Block(-9,24,1,PURPUR_BLOCK)
Block(-9,24,2,PURPUR_BLOCK)
Block(-9,24,3,PURPUR_SLAB)
Block(-9,24,4,PURPUR_STAIRS:5)
Block(-9,24,5,PURPUR_STAIRS:1)
Block(-9,24,6,PURPUR_STAIRS:5)
Block(-9,24,7,PURPUR_STAIRS:5)
Block(-9,25,-4,END_ROD)
Block(-9,25,7,END_ROD)
Block(-9,28,-5,PURPUR_STAIRS:6)
Block(-9,28,-4,PURPUR_BLOCK)
Block(-9,28,-3,PURPUR_BLOCK)
Block(-9,28,-2,PURPUR_BLOCK)
Block(-9,28,-1,PURPUR_BLOCK)
Block(-9,28,0,PURPUR_BLOCK)
Block(-9,28,1,PURPUR_BLOCK)
Block(-9,28,2,PURPUR_BLOCK)
Block(-9,28,3,PURPUR_BLOCK)
Block(-9,28,4,PURPUR_BLOCK)
Block(-9,28,5,PURPUR_BLOCK)
Block(-9,28,6,PURPUR_BLOCK)
Block(-9,28,7,PURPUR_BLOCK)
Block(-9,28,8,PURPUR_STAIRS:7)
Block(-9,29,-4,END_ROD)
Block(-9,29,7,END_ROD)
Block(-8,12,-8,PURPUR_STAIRS:6)
Block(-8,12,-7,PURPUR_STAIRS:4)
Block(-8,12,-6,PURPUR_STAIRS:0)
Block(-8,12,-5,PURPUR_STAIRS:0)
Block(-8,12,-4,PURPUR_STAIRS:4)
Block(-8,12,-3,PURPUR_STAIRS:4)
Block(-8,12,-2,PURPUR_STAIRS:0)
Block(-8,12,-1,PURPUR_STAIRS:4)
Block(-8,12,0,PURPUR_STAIRS:4)
Block(-8,12,1,PURPUR_STAIRS:0)
Block(-8,12,2,PURPUR_STAIRS:4)
Block(-8,12,3,PURPUR_STAIRS:4)
Block(-8,12,4,PURPUR_STAIRS:0)
Block(-8,12,5,PURPUR_STAIRS:0)
Block(-8,12,6,PURPUR_STAIRS:4)
Block(-8,12,7,PURPUR_STAIRS:7)
Block(-8,19,1,PURPUR_PILLAR)
Block(-8,20,-1,PURPUR_BLOCK)
Block(-8,20,0,PURPUR_STAIRS:1)
Block(-8,20,1,PURPUR_STAIRS:1)
Block(-8,20,2,PURPUR_STAIRS:1)
Block(-8,20,3,PURPUR_BLOCK)
Block(-8,21,-1,PURPUR_BLOCK)
Block(-8,21,3,PURPUR_BLOCK)
Block(-8,22,-1,END_ROD)
Block(-8,22,3,END_ROD)
Block(-8,28,-5,PURPUR_STAIRS:6)
Block(-8,28,-4,PURPUR_STAIRS:5)
Block(-8,28,-3,PURPUR_STAIRS:1)
Block(-8,28,-2,PURPUR_STAIRS:1)
Block(-8,28,-1,PURPUR_STAIRS:5)
Block(-8,28,0,PURPUR_STAIRS:5)
Block(-8,28,1,PURPUR_STAIRS:1)
Block(-8,28,2,PURPUR_STAIRS:1)
Block(-8,28,3,PURPUR_STAIRS:5)
Block(-8,28,4,PURPUR_STAIRS:5)
Block(-8,28,5,PURPUR_STAIRS:1)
Block(-8,28,6,PURPUR_STAIRS:1)
Block(-8,28,7,PURPUR_STAIRS:5)
Block(-8,28,8,PURPUR_STAIRS:5)
Block(-7,8,-7,PURPUR_STAIRS:4)
Block(-7,8,-6,PURPUR_STAIRS:4)
Block(-7,8,-5,PURPUR_STAIRS:0)
Block(-7,8,-4,PURPUR_STAIRS:0)
Block(-7,8,-3,PURPUR_STAIRS:4)
Block(-7,8,-2,PURPUR_STAIRS:4)
Block(-7,8,-1,PURPUR_STAIRS:0)
Block(-7,8,0,PURPUR_STAIRS:0)
Block(-7,8,1,PURPUR_STAIRS:4)
Block(-7,8,2,PURPUR_STAIRS:4)
Block(-7,8,3,PURPUR_STAIRS:0)
Block(-7,8,4,PURPUR_STAIRS:0)
Block(-7,8,5,PURPUR_STAIRS:4)
Block(-7,8,6,PURPUR_STAIRS:7)
Block(-7,9,-7,END_ROD)
Block(-7,9,6,END_ROD)
Block(-7,12,-8,PURPUR_STAIRS:6)
Block(-7,12,-7,PURPUR_BLOCK)
Block(-7,12,-6,PURPUR_BLOCK)
Block(-7,12,-5,PURPUR_BLOCK)
Block(-7,12,-4,PURPUR_BLOCK)
Block(-7,12,-3,PURPUR_BLOCK)
Block(-7,12,-2,PURPUR_BLOCK)
Block(-7,12,-1,PURPUR_BLOCK)
Block(-7,12,0,PURPUR_BLOCK)
Block(-7,12,1,PURPUR_BLOCK)
Block(-7,12,2,PURPUR_BLOCK)
Block(-7,12,3,PURPUR_BLOCK)
Block(-7,12,4,PURPUR_BLOCK)
Block(-7,12,5,PURPUR_BLOCK)
Block(-7,12,6,PURPUR_BLOCK)
Block(-7,12,7,PURPUR_STAIRS:7)
Block(-7,13,-7,END_ROD)
Block(-7,13,6,END_ROD)
Block(-7,18,0,PURPUR_STAIRS:6)
Block(-7,18,1,PURPUR_BLOCK)
Block(-7,18,2,PURPUR_STAIRS:7)
Block(-7,19,-1,PURPUR_BLOCK)
Block(-7,19,0,PURPUR_STAIRS:1)
Block(-7,19,1,PURPUR_STAIRS:1)
Block(-7,19,2,PURPUR_STAIRS:1)
Block(-7,19,3,PURPUR_BLOCK)
Block(-7,20,-1,PURPUR_STAIRS:2)
Block(-7,20,3,PURPUR_STAIRS:0)
Block(-6,4,-6,PURPUR_STAIRS:4)
Block(-6,4,-5,PURPUR_STAIRS:4)
Block(-6,4,-4,PURPUR_STAIRS:0)
Block(-6,4,-3,PURPUR_STAIRS:4)
Block(-6,4,-2,PURPUR_STAIRS:4)
Block(-6,4,-1,PURPUR_STAIRS:0)
Block(-6,4,0,PURPUR_STAIRS:0)
Block(-6,4,1,PURPUR_STAIRS:4)
Block(-6,4,2,PURPUR_STAIRS:4)
Block(-6,4,3,PURPUR_STAIRS:0)
Block(-6,4,4,PURPUR_STAIRS:4)
Block(-6,4,5,PURPUR_STAIRS:7)
Block(-6,5,-6,END_ROD)
Block(-6,5,5,END_ROD)
Block(-6,8,-7,PURPUR_STAIRS:6)
Block(-6,8,-6,PURPUR_BLOCK)
Block(-6,8,-5,PURPUR_BLOCK)
Block(-6,8,-4,PURPUR_BLOCK)
Block(-6,8,-3,PURPUR_BLOCK)
Block(-6,8,-2,PURPUR_BLOCK)
Block(-6,8,-1,PURPUR_BLOCK)
Block(-6,8,0,PURPUR_BLOCK)
Block(-6,8,1,PURPUR_BLOCK)
Block(-6,8,2,PURPUR_BLOCK)
Block(-6,8,3,PURPUR_BLOCK)
Block(-6,8,4,PURPUR_BLOCK)
Block(-6,8,5,PURPUR_BLOCK)
Block(-6,8,6,PURPUR_STAIRS:7)
Block(-6,9,-6,PURPUR_PILLAR:0)
Block(-6,9,-5,END_BRICKS)
Block(-6,9,-4,END_BRICKS)
Block(-6,9,-3,END_BRICKS)
Block(-6,9,-2,END_BRICKS)
Block(-6,9,-1,END_BRICKS)
Block(-6,9,0,END_BRICKS)
Block(-6,9,1,END_BRICKS)
Block(-6,9,2,END_BRICKS)
Block(-6,9,3,END_BRICKS)
Block(-6,9,4,END_BRICKS)
Block(-6,9,5,PURPUR_PILLAR:0)
Block(-6,10,-6,PURPUR_PILLAR:0)
Block(-6,10,-5,END_BRICKS)
Block(-6,10,-4,STAINED_GLASS:2)
Block(-6,10,-3,END_BRICKS)
Block(-6,10,-2,STAINED_GLASS:2)
Block(-6,10,-1,END_BRICKS)
Block(-6,10,0,END_BRICKS)
Block(-6,10,1,STAINED_GLASS:2)
Block(-6,10,2,END_BRICKS)
Block(-6,10,3,STAINED_GLASS:2)
Block(-6,10,4,END_BRICKS)
Block(-6,10,5,PURPUR_PILLAR:0)
Block(-6,11,-6,PURPUR_PILLAR:0)
Block(-6,11,-5,END_BRICKS)
Block(-6,11,-4,STAINED_GLASS:2)
Block(-6,11,-3,END_BRICKS)
Block(-6,11,-2,STAINED_GLASS:2)
Block(-6,11,-1,END_BRICKS)
Block(-6,11,0,END_BRICKS)
Block(-6,11,1,STAINED_GLASS:2)
Block(-6,11,2,END_BRICKS)
Block(-6,11,3,STAINED_GLASS:2)
Block(-6,11,4,END_BRICKS)
Block(-6,11,5,PURPUR_PILLAR:0)
Block(-6,12,-8,PURPUR_STAIRS:2)
Block(-6,12,-7,PURPUR_BLOCK)
Block(-6,12,-6,PURPUR_BLOCK)
Block(-6,12,-5,PURPUR_BLOCK)
Block(-6,12,-4,PURPUR_BLOCK)
Block(-6,12,-3,PURPUR_BLOCK)
Block(-6,12,-2,PURPUR_BLOCK)
Block(-6,12,-1,PURPUR_BLOCK)
Block(-6,12,0,PURPUR_BLOCK)
Block(-6,12,1,PURPUR_BLOCK)
Block(-6,12,2,PURPUR_BLOCK)
Block(-6,12,3,PURPUR_BLOCK)
Block(-6,12,4,PURPUR_BLOCK)
Block(-6,12,5,PURPUR_BLOCK)
Block(-6,12,6,PURPUR_BLOCK)
Block(-6,12,7,PURPUR_STAIRS:0)
Block(-6,17,0,PURPUR_STAIRS:6)
Block(-6,17,1,PURPUR_BLOCK)
Block(-6,17,2,PURPUR_STAIRS:7)
Block(-6,18,-1,PURPUR_BLOCK)
Block(-6,18,0,PURPUR_STAIRS:1)
Block(-6,18,1,PURPUR_STAIRS:1)
Block(-6,18,2,PURPUR_STAIRS:1)
Block(-6,18,3,PURPUR_BLOCK)
Block(-6,19,-1,PURPUR_STAIRS:2)
Block(-6,19,3,PURPUR_STAIRS:0)
Block(-5,4,-6,PURPUR_STAIRS:6)
Block(-5,4,-5,PURPUR_BLOCK)
Block(-5,4,-4,PURPUR_BLOCK)
Block(-5,4,-3,PURPUR_BLOCK)
Block(-5,4,-2,PURPUR_BLOCK)
Block(-5,4,-1,PURPUR_BLOCK)
Block(-5,4,0,PURPUR_BLOCK)
Block(-5,4,1,PURPUR_BLOCK)
Block(-5,4,2,PURPUR_BLOCK)
Block(-5,4,3,PURPUR_BLOCK)
Block(-5,4,4,PURPUR_BLOCK)
Block(-5,4,5,PURPUR_STAIRS:7)
Block(-5,5,-5,PURPUR_PILLAR:0)
Block(-5,5,-4,END_BRICKS)
Block(-5,5,-3,END_BRICKS)
Block(-5,5,-2,END_BRICKS)
Block(-5,5,-1,END_BRICKS)
Block(-5,5,0,END_BRICKS)
Block(-5,5,1,END_BRICKS)
Block(-5,5,2,END_BRICKS)
Block(-5,5,3,END_BRICKS)
Block(-5,5,4,PURPUR_PILLAR:0)
Block(-5,6,-5,PURPUR_PILLAR:0)
Block(-5,6,-4,END_BRICKS)
Block(-5,6,-3,STAINED_GLASS:2)
Block(-5,6,-2,END_BRICKS)
Block(-5,6,-1,END_BRICKS)
Block(-5,6,0,END_BRICKS)
Block(-5,6,1,END_BRICKS)
Block(-5,6,2,STAINED_GLASS:2)
Block(-5,6,3,END_BRICKS)
Block(-5,6,4,PURPUR_PILLAR:0)
Block(-5,7,-5,PURPUR_PILLAR:0)
Block(-5,7,-4,END_BRICKS)
Block(-5,7,-3,STAINED_GLASS:2)
Block(-5,7,-2,END_BRICKS)
Block(-5,7,-1,END_BRICKS)
Block(-5,7,0,END_BRICKS)
Block(-5,7,1,END_BRICKS)
Block(-5,7,2,STAINED_GLASS:2)
Block(-5,7,3,END_BRICKS)
Block(-5,7,4,PURPUR_PILLAR:0)
Block(-5,8,-7,PURPUR_STAIRS:2)
Block(-5,8,-6,PURPUR_BLOCK)
Block(-5,8,-5,PURPUR_BLOCK)
Block(-5,8,-4,PURPUR_BLOCK)
Block(-5,8,-3,PURPUR_BLOCK)
Block(-5,8,-2,PURPUR_BLOCK)
Block(-5,8,-1,PURPUR_BLOCK)
Block(-5,8,0,PURPUR_BLOCK)
Block(-5,8,1,PURPUR_BLOCK)
Block(-5,8,2,PURPUR_BLOCK)
Block(-5,8,3,PURPUR_BLOCK)
Block(-5,8,4,PURPUR_BLOCK)
Block(-5,8,5,PURPUR_BLOCK)
Block(-5,8,6,PURPUR_STAIRS:0)
Block(-5,9,-6,END_BRICKS)
Block(-5,9,-1,PURPUR_STAIRS:2)
Block(-5,9,0,PURPUR_STAIRS:0)
Block(-5,9,5,END_BRICKS)
Block(-5,10,-6,END_BRICKS)
Block(-5,10,5,END_BRICKS)
Block(-5,11,-6,END_BRICKS)
Block(-5,11,5,END_BRICKS)
Block(-5,12,-8,PURPUR_STAIRS:2)
Block(-5,12,-7,PURPUR_BLOCK)
Block(-5,12,-6,PURPUR_BLOCK)
Block(-5,12,-5,PURPUR_BLOCK)
Block(-5,12,-4,PURPUR_BLOCK)
Block(-5,12,-3,PURPUR_BLOCK)
Block(-5,12,-2,PURPUR_BLOCK)
Block(-5,12,-1,PURPUR_BLOCK)
Block(-5,12,0,PURPUR_BLOCK)
Block(-5,12,1,PURPUR_BLOCK)
Block(-5,12,2,PURPUR_BLOCK)
Block(-5,12,3,PURPUR_BLOCK)
Block(-5,12,4,PURPUR_BLOCK)
Block(-5,12,5,PURPUR_BLOCK)
Block(-5,12,6,PURPUR_BLOCK)
Block(-5,12,7,PURPUR_STAIRS:0)
Block(-5,16,0,PURPUR_BLOCK)
Block(-5,16,1,PURPUR_BLOCK)
Block(-5,16,2,PURPUR_BLOCK)
Block(-5,17,-1,PURPUR_BLOCK)
Block(-5,17,0,PURPUR_STAIRS:1)
Block(-5,17,1,PURPUR_STAIRS:1)
Block(-5,17,2,PURPUR_STAIRS:1)
Block(-5,17,3,PURPUR_BLOCK)
Block(-5,18,-1,PURPUR_STAIRS:2)
Block(-5,18,3,PURPUR_STAIRS:0)
Block(-5,24,-1,WALL_BANNER:4,EndTowerB/2-banner.nbt)
Block(-5,24,3,WALL_BANNER:4,EndTowerB/3-banner.nbt)
Block(-5,28,-3,PURPUR_STAIRS:4)
Block(-5,28,-2,PURPUR_STAIRS:4)
Block(-5,28,-1,PURPUR_STAIRS:0)
Block(-5,28,0,PURPUR_STAIRS:0)
Block(-5,28,1,PURPUR_STAIRS:4)
Block(-5,28,2,PURPUR_STAIRS:0)
Block(-5,28,3,PURPUR_STAIRS:0)
Block(-5,28,4,PURPUR_STAIRS:4)
Block(-5,28,5,PURPUR_STAIRS:7)
Block(-4,0,-4,PURPUR_BLOCK)
Block(-4,0,-3,PURPUR_BLOCK)
Block(-4,0,-2,PURPUR_BLOCK)
Block(-4,0,-1,PURPUR_BLOCK)
Block(-4,0,0,PURPUR_BLOCK)
Block(-4,0,1,PURPUR_BLOCK)
Block(-4,0,2,PURPUR_BLOCK)
Block(-4,0,3,PURPUR_BLOCK)
Block(-4,1,-4,PURPUR_PILLAR:0)
Block(-4,1,-3,END_BRICKS)
Block(-4,1,-2,END_BRICKS)
Block(-4,1,-1,END_BRICKS)
Block(-4,1,0,END_BRICKS)
Block(-4,1,1,END_BRICKS)
Block(-4,1,2,END_BRICKS)
Block(-4,1,3,PURPUR_PILLAR:0)
Block(-4,2,-4,PURPUR_PILLAR:0)
Block(-4,2,-3,END_BRICKS)
Block(-4,2,-2,END_BRICKS)
Block(-4,2,-1,END_BRICKS)
Block(-4,2,0,END_BRICKS)
Block(-4,2,1,END_BRICKS)
Block(-4,2,2,END_BRICKS)
Block(-4,2,3,PURPUR_PILLAR:0)
Block(-4,3,-4,PURPUR_PILLAR:0)
Block(-4,3,-3,END_BRICKS)
Block(-4,3,-2,END_BRICKS)
Block(-4,3,-1,END_BRICKS)
Block(-4,3,0,END_BRICKS)
Block(-4,3,1,END_BRICKS)
Block(-4,3,2,END_BRICKS)
Block(-4,3,3,PURPUR_PILLAR:0)
Block(-4,4,-6,PURPUR_STAIRS:2)
Block(-4,4,-5,PURPUR_BLOCK)
Block(-4,4,-4,PURPUR_BLOCK)
Block(-4,4,-3,PURPUR_BLOCK)
Block(-4,4,-2,PURPUR_BLOCK)
Block(-4,4,-1,PURPUR_BLOCK)
Block(-4,4,0,PURPUR_BLOCK)
Block(-4,4,1,PURPUR_BLOCK)
Block(-4,4,2,PURPUR_BLOCK)
Block(-4,4,3,PURPUR_BLOCK)
Block(-4,4,4,PURPUR_BLOCK)
Block(-4,4,5,PURPUR_STAIRS:0)
Block(-4,5,-5,END_BRICKS)
Block(-4,5,4,END_BRICKS)
Block(-4,6,-5,END_BRICKS)
Block(-4,6,4,END_BRICKS)
Block(-4,7,-5,END_BRICKS)
Block(-4,7,4,END_BRICKS)
Block(-4,8,-7,PURPUR_STAIRS:2)
Block(-4,8,-6,PURPUR_BLOCK)
Block(-4,8,-5,PURPUR_BLOCK)
Block(-4,8,-4,PURPUR_BLOCK)
Block(-4,8,-3,PURPUR_BLOCK)
Block(-4,8,-2,PURPUR_BLOCK)
Block(-4,8,-1,PURPUR_BLOCK)
Block(-4,8,0,PURPUR_BLOCK)
Block(-4,8,1,PURPUR_BLOCK)
Block(-4,8,2,PURPUR_BLOCK)
Block(-4,8,3,PURPUR_BLOCK)
Block(-4,8,4,PURPUR_BLOCK)
Block(-4,8,5,PURPUR_BLOCK)
Block(-4,8,6,PURPUR_STAIRS:0)
Block(-4,9,-6,END_BRICKS)
Block(-4,9,5,END_BRICKS)
Block(-4,10,-6,STAINED_GLASS:2)
Block(-4,10,5,STAINED_GLASS:2)
Block(-4,11,-6,STAINED_GLASS:2)
Block(-4,11,5,STAINED_GLASS:2)
Block(-4,12,-8,PURPUR_STAIRS:6)
Block(-4,12,-7,PURPUR_BLOCK)
Block(-4,12,-6,PURPUR_BLOCK)
Block(-4,12,-5,PURPUR_BLOCK)
Block(-4,12,-4,PURPUR_BLOCK)
Block(-4,12,-3,PURPUR_BLOCK)
Block(-4,12,-2,PURPUR_BLOCK)
Block(-4,12,-1,PURPUR_BLOCK)
Block(-4,12,0,PURPUR_BLOCK)
Block(-4,12,1,PURPUR_BLOCK)
Block(-4,12,2,PURPUR_BLOCK)
Block(-4,12,3,PURPUR_BLOCK)
Block(-4,12,4,PURPUR_BLOCK)
Block(-4,12,5,PURPUR_BLOCK)
Block(-4,12,6,PURPUR_BLOCK)
Block(-4,12,7,PURPUR_STAIRS:7)
Block(-4,14,1,PURPUR_STAIRS:4)
Block(-4,16,-1,PURPUR_STAIRS:6)
Block(-4,16,0,PURPUR_BLOCK)
Block(-4,16,1,PURPUR_BLOCK)
Block(-4,16,2,PURPUR_BLOCK)
Block(-4,16,3,PURPUR_STAIRS:7)
Block(-4,17,-1,PURPUR_BLOCK)
Block(-4,17,3,PURPUR_BLOCK)
Block(-4,18,-1,END_ROD)
Block(-4,18,3,END_ROD)
Block(-4,22,1,PURPUR_STAIRS:4)
Block(-4,24,-2,PURPUR_STAIRS:6)
Block(-4,24,-1,PURPUR_STAIRS:4)
Block(-4,24,0,PURPUR_STAIRS:0)
Block(-4,24,1,PURPUR_STAIRS:4)
Block(-4,24,2,PURPUR_STAIRS:0)
Block(-4,24,3,PURPUR_STAIRS:4)
Block(-4,24,4,PURPUR_STAIRS:7)
Block(-4,25,-2,END_ROD)
Block(-4,25,4,END_ROD)
Block(-4,28,-3,PURPUR_STAIRS:6)
Block(-4,28,-2,PURPUR_BLOCK)
Block(-4,28,-1,PURPUR_BLOCK)
Block(-4,28,0,PURPUR_BLOCK)
Block(-4,28,1,PURPUR_BLOCK)
Block(-4,28,2,PURPUR_BLOCK)
Block(-4,28,3,PURPUR_BLOCK)
Block(-4,28,4,PURPUR_BLOCK)
Block(-4,28,5,PURPUR_STAIRS:7)
Block(-3,0,-4,PURPUR_BLOCK)
Block(-3,0,-3,PURPUR_BLOCK)
Block(-3,0,-2,PURPUR_BLOCK)
Block(-3,0,-1,PURPUR_BLOCK)
Block(-3,0,0,PURPUR_BLOCK)
Block(-3,0,1,PURPUR_BLOCK)
Block(-3,0,2,PURPUR_BLOCK)
Block(-3,0,3,PURPUR_BLOCK)
Block(-3,1,-4,END_BRICKS)
Block(-3,1,-3,PURPUR_SLAB:8)
Block(-3,1,3,END_BRICKS)
Block(-3,2,-4,END_BRICKS)
Block(-3,2,-3,PURPUR_SLAB)
Block(-3,2,-2,PURPUR_BLOCK)
Block(-3,2,-1,PURPUR_SLAB:8)
Block(-3,2,3,END_BRICKS)
Block(-3,3,-4,END_BRICKS)
Block(-3,3,-1,PURPUR_SLAB)
Block(-3,3,0,PURPUR_BLOCK)
Block(-3,3,1,PURPUR_SLAB:8)
Block(-3,3,3,END_BRICKS)
Block(-3,4,-6,PURPUR_STAIRS:6)
Block(-3,4,-5,PURPUR_BLOCK)
Block(-3,4,-4,PURPUR_BLOCK)
Block(-3,4,1,PURPUR_SLAB)
Block(-3,4,2,PURPUR_BLOCK)
Block(-3,4,3,PURPUR_BLOCK)
Block(-3,4,4,PURPUR_BLOCK)
Block(-3,4,5,PURPUR_STAIRS:7)
Block(-3,5,-5,END_BRICKS)
Block(-3,5,4,END_BRICKS)
Block(-3,6,-5,STAINED_GLASS:2)
Block(-3,6,4,STAINED_GLASS:2)
Block(-3,7,-5,STAINED_GLASS:2)
Block(-3,7,4,STAINED_GLASS:2)
Block(-3,8,-7,PURPUR_STAIRS:6)
Block(-3,8,-6,PURPUR_BLOCK)
Block(-3,8,-5,PURPUR_BLOCK)
Block(-3,8,-4,PURPUR_BLOCK)
Block(-3,8,-3,PURPUR_BLOCK)
Block(-3,8,-2,PURPUR_BLOCK)
Block(-3,8,-1,PURPUR_BLOCK)
Block(-3,8,0,PURPUR_BLOCK)
Block(-3,8,1,PURPUR_BLOCK)
Block(-3,8,2,PURPUR_BLOCK)
Block(-3,8,3,PURPUR_BLOCK)
Block(-3,8,4,PURPUR_BLOCK)
Block(-3,8,5,PURPUR_BLOCK)
Block(-3,8,6,PURPUR_STAIRS:7)
Block(-3,9,-6,END_BRICKS)
Block(-3,9,5,END_BRICKS)
Block(-3,10,-6,END_BRICKS)
Block(-3,10,5,END_BRICKS)
Block(-3,11,-6,END_BRICKS)
Block(-3,11,5,END_BRICKS)
Block(-3,12,-8,PURPUR_STAIRS:6)
Block(-3,12,-7,PURPUR_BLOCK)
Block(-3,12,-6,PURPUR_BLOCK)
Block(-3,12,-5,PURPUR_BLOCK)
Block(-3,12,-4,PURPUR_BLOCK)
Block(-3,12,-3,PURPUR_BLOCK)
Block(-3,12,-2,PURPUR_BLOCK)
Block(-3,12,-1,PURPUR_BLOCK)
Block(-3,12,0,PURPUR_BLOCK)
Block(-3,12,1,PURPUR_BLOCK)
Block(-3,12,2,PURPUR_BLOCK)
Block(-3,12,3,PURPUR_BLOCK)
Block(-3,12,4,PURPUR_BLOCK)
Block(-3,12,5,PURPUR_BLOCK)
Block(-3,12,6,PURPUR_BLOCK)
Block(-3,12,7,PURPUR_STAIRS:7)
Block(-3,13,0,PURPUR_PILLAR:0)
Block(-3,13,1,PURPUR_PILLAR:0)
Block(-3,13,2,PURPUR_PILLAR:0)
Block(-3,14,0,PURPUR_PILLAR:0)
Block(-3,14,1,PURPUR_PILLAR)
Block(-3,14,2,PURPUR_PILLAR:0)
Block(-3,15,0,PURPUR_PILLAR:0)
Block(-3,15,1,PURPUR_PILLAR:0)
Block(-3,15,2,PURPUR_PILLAR:0)
Block(-3,16,-1,PURPUR_BLOCK)
Block(-3,16,0,PURPUR_BLOCK)
Block(-3,16,1,PURPUR_BLOCK)
Block(-3,16,2,PURPUR_BLOCK)
Block(-3,16,3,PURPUR_BLOCK)
Block(-3,17,-1,PURPUR_BLOCK)
Block(-3,17,3,PURPUR_BLOCK)
Block(-3,18,-1,PURPUR_BLOCK)
Block(-3,18,3,PURPUR_BLOCK)
Block(-3,19,-1,PURPUR_BLOCK)
Block(-3,19,0,PURPUR_SLAB:8)
Block(-3,19,2,PURPUR_SLAB:8)
Block(-3,19,3,PURPUR_BLOCK)
Block(-3,20,-1,PURPUR_SLAB)
Block(-3,20,0,PURPUR_BLOCK)
Block(-3,20,1,PURPUR_BLOCK)
Block(-3,20,2,PURPUR_BLOCK)
Block(-3,20,3,PURPUR_SLAB)
Block(-3,21,0,PURPUR_PILLAR:0)
Block(-3,21,1,PURPUR_PILLAR:0)
Block(-3,21,2,PURPUR_PILLAR:0)
Block(-3,22,0,PURPUR_PILLAR:0)
Block(-3,22,1,PURPUR_PILLAR)
Block(-3,22,2,PURPUR_PILLAR:0)
Block(-3,23,0,PURPUR_PILLAR:0)
Block(-3,23,1,PURPUR_PILLAR:0)
Block(-3,23,2,PURPUR_PILLAR:0)
Block(-3,24,-3,WALL_BANNER,EndTowerB/4-banner.nbt)
Block(-3,24,-2,PURPUR_STAIRS:6)
Block(-3,24,-1,PURPUR_BLOCK)
Block(-3,24,0,PURPUR_BLOCK)
Block(-3,24,1,PURPUR_BLOCK)
Block(-3,24,2,PURPUR_BLOCK)
Block(-3,24,3,PURPUR_BLOCK)
Block(-3,24,4,PURPUR_STAIRS:7)
Block(-3,24,5,WALL_BANNER:3,EndTowerB/5-banner.nbt)
Block(-3,25,-1,PURPUR_PILLAR:0)
Block(-3,25,0,END_BRICKS)
Block(-3,25,1,END_BRICKS)
Block(-3,25,2,END_BRICKS)
Block(-3,25,3,PURPUR_PILLAR:0)
Block(-3,26,-1,PURPUR_PILLAR:0)
Block(-3,26,0,END_BRICKS)
Block(-3,26,1,STAINED_GLASS:2)
Block(-3,26,2,END_BRICKS)
Block(-3,26,3,PURPUR_PILLAR:0)
Block(-3,27,-1,PURPUR_PILLAR:0)
Block(-3,27,0,END_BRICKS)
Block(-3,27,1,STAINED_GLASS:2)
Block(-3,27,2,END_BRICKS)
Block(-3,27,3,PURPUR_PILLAR:0)
Block(-3,28,-3,PURPUR_STAIRS:2)
Block(-3,28,-2,PURPUR_BLOCK)
Block(-3,28,-1,PURPUR_BLOCK)
Block(-3,28,0,PURPUR_BLOCK)
Block(-3,28,1,PURPUR_BLOCK)
Block(-3,28,2,PURPUR_BLOCK)
Block(-3,28,3,PURPUR_BLOCK)
Block(-3,28,4,PURPUR_BLOCK)
Block(-3,28,5,PURPUR_STAIRS:0)
Block(-2,0,-4,PURPUR_BLOCK)
Block(-2,0,-3,PURPUR_BLOCK)
Block(-2,0,-2,PURPUR_BLOCK)
Block(-2,0,-1,PURPUR_BLOCK)
Block(-2,0,0,PURPUR_BLOCK)
Block(-2,0,1,PURPUR_BLOCK)
Block(-2,0,2,PURPUR_BLOCK)
Block(-2,0,3,PURPUR_BLOCK)
Block(-2,1,-4,END_BRICKS)
Block(-2,1,-3,PURPUR_BLOCK)
Block(-2,1,3,END_BRICKS)
Block(-2,2,-4,STAINED_GLASS:2)
Block(-2,2,3,STAINED_GLASS:2)
Block(-2,3,-4,STAINED_GLASS:2)
Block(-2,3,3,STAINED_GLASS:2)
Block(-2,4,-6,PURPUR_STAIRS:6)
Block(-2,4,-5,PURPUR_BLOCK)
Block(-2,4,-4,PURPUR_BLOCK)
Block(-2,4,-2,PURPUR_BLOCK)
Block(-2,4,-1,PURPUR_BLOCK)
Block(-2,4,0,PURPUR_BLOCK)
Block(-2,4,1,PURPUR_BLOCK)
Block(-2,4,2,PURPUR_BLOCK)
Block(-2,4,3,PURPUR_BLOCK)
Block(-2,4,4,PURPUR_BLOCK)
Block(-2,4,5,PURPUR_STAIRS:7)
Block(-2,5,-5,END_BRICKS)
Block(-2,5,4,END_BRICKS)
Block(-2,6,-5,END_BRICKS)
Block(-2,6,4,END_BRICKS)
Block(-2,7,-5,END_BRICKS)
Block(-2,7,4,END_BRICKS)
Block(-2,8,-7,PURPUR_STAIRS:6)
Block(-2,8,-6,PURPUR_BLOCK)
Block(-2,8,-5,PURPUR_BLOCK)
Block(-2,8,-4,PURPUR_BLOCK)
Block(-2,8,-3,PURPUR_BLOCK)
Block(-2,8,-2,PURPUR_BLOCK)
Block(-2,8,-1,PURPUR_BLOCK)
Block(-2,8,0,PURPUR_BLOCK)
Block(-2,8,1,PURPUR_BLOCK)
Block(-2,8,2,PURPUR_BLOCK)
Block(-2,8,3,PURPUR_BLOCK)
Block(-2,8,4,PURPUR_BLOCK)
Block(-2,8,5,PURPUR_BLOCK)
Block(-2,8,6,PURPUR_STAIRS:7)
Block(-2,9,-6,END_BRICKS)
Block(-2,9,5,END_BRICKS)
Block(-2,10,-6,STAINED_GLASS:2)
Block(-2,10,5,STAINED_GLASS:2)
Block(-2,11,-6,STAINED_GLASS:2)
Block(-2,11,5,STAINED_GLASS:2)
Block(-2,12,-8,PURPUR_STAIRS:2)
Block(-2,12,-7,PURPUR_BLOCK)
Block(-2,12,-6,PURPUR_BLOCK)
Block(-2,12,-5,PURPUR_BLOCK)
Block(-2,12,-4,PURPUR_BLOCK)
Block(-2,12,-3,PURPUR_BLOCK)
Block(-2,12,-2,PURPUR_BLOCK)
Block(-2,12,-1,PURPUR_BLOCK)
Block(-2,12,3,PURPUR_BLOCK)
Block(-2,12,4,PURPUR_BLOCK)
Block(-2,12,5,PURPUR_BLOCK)
Block(-2,12,6,PURPUR_BLOCK)
Block(-2,12,7,PURPUR_STAIRS:0)
Block(-2,13,-1,PURPUR_PILLAR:0)
Block(-2,13,1,PURPUR_SLAB)
Block(-2,13,3,PURPUR_PILLAR:0)
Block(-2,14,-1,PURPUR_PILLAR:0)
Block(-2,14,3,PURPUR_PILLAR:0)
Block(-2,15,-1,PURPUR_PILLAR:0)
Block(-2,15,3,PURPUR_PILLAR:0)
Block(-2,16,-1,PURPUR_BLOCK)
Block(-2,16,3,PURPUR_BLOCK)
Block(-2,17,-1,PURPUR_PILLAR:0)
Block(-2,17,1,PURPUR_SLAB)
Block(-2,17,3,PURPUR_PILLAR:0)
Block(-2,18,-1,PURPUR_PILLAR:0)
Block(-2,18,3,PURPUR_PILLAR:0)
Block(-2,19,-1,PURPUR_PILLAR:0)
Block(-2,19,3,PURPUR_PILLAR:0)
Block(-2,20,-1,PURPUR_BLOCK)
Block(-2,20,3,PURPUR_BLOCK)
Block(-2,21,-1,PURPUR_PILLAR:0)
Block(-2,21,1,PURPUR_SLAB)
Block(-2,21,3,PURPUR_PILLAR:0)
Block(-2,22,-1,PURPUR_PILLAR:0)
Block(-2,22,3,PURPUR_PILLAR:0)
Block(-2,23,-1,PURPUR_PILLAR:0)
Block(-2,23,3,PURPUR_PILLAR:0)
Block(-2,24,-2,PURPUR_STAIRS:2)
Block(-2,24,-1,PURPUR_BLOCK)
Block(-2,24,0,PURPUR_BLOCK)
Block(-2,24,1,PURPUR_SLAB)
Block(-2,24,2,PURPUR_SLAB)
Block(-2,24,3,PURPUR_BLOCK)
Block(-2,24,4,PURPUR_STAIRS:0)
Block(-2,25,3,END_BRICKS)
Block(-2,26,3,END_BRICKS)
Block(-2,27,-1,END_BRICKS)
Block(-2,27,3,END_BRICKS)
Block(-2,28,-3,PURPUR_STAIRS:2)
Block(-2,28,-2,PURPUR_BLOCK)
Block(-2,28,-1,PURPUR_BLOCK)
Block(-2,28,0,PURPUR_BLOCK)
Block(-2,28,1,PURPUR_BLOCK)
Block(-2,28,2,PURPUR_BLOCK)
Block(-2,28,3,PURPUR_BLOCK)
Block(-2,28,4,PURPUR_BLOCK)
Block(-2,28,5,PURPUR_STAIRS:0)
Block(-1,0,-4,PURPUR_BLOCK)
Block(-1,0,-3,PURPUR_BLOCK)
Block(-1,0,-2,PURPUR_BLOCK)
Block(-1,0,-1,PURPUR_BLOCK)
Block(-1,0,0,PURPUR_BLOCK)
Block(-1,0,1,PURPUR_BLOCK)
Block(-1,0,2,PURPUR_BLOCK)
Block(-1,0,3,PURPUR_BLOCK)
Block(-1,1,-4,END_BRICKS)
Block(-1,1,-3,PURPUR_SLAB)
Block(-1,1,3,END_BRICKS)
Block(-1,2,-4,END_BRICKS)
Block(-1,2,3,END_BRICKS)
Block(-1,3,-4,END_BRICKS)
Block(-1,3,3,END_BRICKS)
Block(-1,4,-6,PURPUR_STAIRS:2)
Block(-1,4,-5,PURPUR_BLOCK)
Block(-1,4,-4,PURPUR_BLOCK)
Block(-1,4,-2,PURPUR_BLOCK)
Block(-1,4,-1,PURPUR_BLOCK)
Block(-1,4,0,PURPUR_BLOCK)
Block(-1,4,1,PURPUR_BLOCK)
Block(-1,4,2,PURPUR_BLOCK)
Block(-1,4,3,PURPUR_BLOCK)
Block(-1,4,4,PURPUR_BLOCK)
Block(-1,4,5,PURPUR_STAIRS:0)
Block(-1,5,-5,END_BRICKS)
Block(-1,5,4,END_BRICKS)
Block(-1,6,-5,END_BRICKS)
Block(-1,6,4,END_BRICKS)
Block(-1,7,-5,END_BRICKS)
Block(-1,7,4,END_BRICKS)
Block(-1,8,-7,PURPUR_STAIRS:2)
Block(-1,8,-6,PURPUR_BLOCK)
Block(-1,8,-5,PURPUR_BLOCK)
Block(-1,8,-4,PURPUR_BLOCK)
Block(-1,8,-3,PURPUR_BLOCK)
Block(-1,8,-2,PURPUR_BLOCK)
Block(-1,8,-1,PURPUR_BLOCK)
Block(-1,8,0,PURPUR_BLOCK)
Block(-1,8,1,PURPUR_BLOCK)
Block(-1,8,2,PURPUR_BLOCK)
Block(-1,8,3,PURPUR_BLOCK)
Block(-1,8,4,PURPUR_BLOCK)
Block(-1,8,5,PURPUR_BLOCK)
Block(-1,8,6,PURPUR_STAIRS:0)
Block(-1,9,-6,END_BRICKS)
Block(-1,9,5,END_BRICKS)
Block(-1,10,-6,END_BRICKS)
Block(-1,10,5,END_BRICKS)
Block(-1,11,-6,END_BRICKS)
Block(-1,11,5,END_BRICKS)
Block(-1,12,-8,PURPUR_STAIRS:6)
Block(-1,12,-7,PURPUR_BLOCK)
Block(-1,12,-6,PURPUR_BLOCK)
Block(-1,12,-5,PURPUR_BLOCK)
Block(-1,12,-4,PURPUR_BLOCK)
Block(-1,12,-3,PURPUR_BLOCK)
Block(-1,12,-2,PURPUR_BLOCK)
Block(-1,12,-1,PURPUR_BLOCK)
Block(-1,12,2,PURPUR_SLAB)
Block(-1,12,3,PURPUR_BLOCK)
Block(-1,12,4,PURPUR_BLOCK)
Block(-1,12,5,PURPUR_BLOCK)
Block(-1,12,6,PURPUR_BLOCK)
Block(-1,12,7,PURPUR_STAIRS:7)
Block(-1,13,-1,PURPUR_PILLAR:0)
Block(-1,13,3,PURPUR_PILLAR:0)
Block(-1,14,-2,PURPUR_STAIRS:6)
Block(-1,14,-1,PURPUR_PILLAR:8)
Block(-1,14,0,PURPUR_SLAB)
Block(-1,14,3,PURPUR_PILLAR:8)
Block(-1,14,4,PURPUR_STAIRS:7)
Block(-1,15,-1,PURPUR_PILLAR:0)
Block(-1,15,3,PURPUR_PILLAR:0)
Block(-1,16,-1,PURPUR_BLOCK)
Block(-1,16,2,PURPUR_SLAB)
Block(-1,16,3,PURPUR_BLOCK)
Block(-1,17,-1,PURPUR_PILLAR:0)
Block(-1,17,3,PURPUR_PILLAR:0)
Block(-1,18,-2,PURPUR_STAIRS:6)
Block(-1,18,-1,PURPUR_PILLAR:8)
Block(-1,18,0,PURPUR_SLAB)
Block(-1,18,3,PURPUR_PILLAR:8)
Block(-1,18,4,PURPUR_STAIRS:7)
Block(-1,19,-1,PURPUR_PILLAR:0)
Block(-1,19,3,PURPUR_PILLAR:0)
Block(-1,20,-1,PURPUR_BLOCK)
Block(-1,20,2,PURPUR_SLAB)
Block(-1,20,3,PURPUR_BLOCK)
Block(-1,21,-1,PURPUR_PILLAR:0)
Block(-1,21,3,PURPUR_PILLAR:0)
Block(-1,22,-2,PURPUR_STAIRS:6)
Block(-1,22,-1,PURPUR_PILLAR:8)
Block(-1,22,0,PURPUR_SLAB)
Block(-1,22,3,PURPUR_PILLAR:8)
Block(-1,22,4,PURPUR_STAIRS:7)
Block(-1,23,-1,PURPUR_PILLAR:0)
Block(-1,23,3,PURPUR_PILLAR:0)
Block(-1,24,-2,PURPUR_STAIRS:6)
Block(-1,24,-1,PURPUR_BLOCK)
Block(-1,24,3,PURPUR_BLOCK)
Block(-1,24,4,PURPUR_STAIRS:7)
Block(-1,25,3,END_BRICKS)
Block(-1,26,3,STAINED_GLASS:2)
Block(-1,27,-1,END_BRICKS)
Block(-1,27,3,STAINED_GLASS:2)
Block(-1,28,-3,PURPUR_STAIRS:6)
Block(-1,28,-2,PURPUR_BLOCK)
Block(-1,28,-1,PURPUR_BLOCK)
Block(-1,28,0,PURPUR_BLOCK)
Block(-1,28,1,PURPUR_BLOCK)
Block(-1,28,2,PURPUR_BLOCK)
Block(-1,28,3,PURPUR_BLOCK)
Block(-1,28,4,PURPUR_BLOCK)
Block(-1,28,5,PURPUR_STAIRS:7)
Block(0,0,-4,PURPUR_BLOCK)
Block(0,0,-3,PURPUR_BLOCK)
Block(0,0,-2,PURPUR_BLOCK)
Block(0,0,-1,PURPUR_BLOCK)
Block(0,0,0,PURPUR_BLOCK)
Block(0,0,1,PURPUR_BLOCK)
Block(0,0,2,PURPUR_BLOCK)
Block(0,0,3,PURPUR_BLOCK)
Block(0,1,-4,END_BRICKS)
Block(0,1,3,END_BRICKS)
Block(0,2,-4,END_BRICKS)
Block(0,2,3,END_BRICKS)
Block(0,3,-4,END_BRICKS)
Block(0,3,3,END_BRICKS)
Block(0,4,-6,PURPUR_STAIRS:2)
Block(0,4,-5,PURPUR_BLOCK)
Block(0,4,-4,PURPUR_BLOCK)
Block(0,4,-2,PURPUR_BLOCK)
Block(0,4,-1,PURPUR_BLOCK)
Block(0,4,0,PURPUR_BLOCK)
Block(0,4,1,PURPUR_BLOCK)
Block(0,4,2,PURPUR_BLOCK)
Block(0,4,3,PURPUR_BLOCK)
Block(0,4,4,PURPUR_BLOCK)
Block(0,4,5,PURPUR_STAIRS:0)
Block(0,5,-5,END_BRICKS)
Block(0,5,4,END_BRICKS)
Block(0,6,-5,END_BRICKS)
Block(0,6,4,END_BRICKS)
Block(0,7,-5,END_BRICKS)
Block(0,7,4,END_BRICKS)
Block(0,8,-7,PURPUR_STAIRS:2)
Block(0,8,-6,PURPUR_BLOCK)
Block(0,8,-5,PURPUR_BLOCK)
Block(0,8,-4,PURPUR_BLOCK)
Block(0,8,-3,PURPUR_BLOCK)
Block(0,8,-2,PURPUR_BLOCK)
Block(0,8,-1,PURPUR_BLOCK)
Block(0,8,0,PURPUR_BLOCK)
Block(0,8,1,PURPUR_BLOCK)
Block(0,8,2,PURPUR_BLOCK)
Block(0,8,3,PURPUR_BLOCK)
Block(0,8,4,PURPUR_BLOCK)
Block(0,8,5,PURPUR_BLOCK)
Block(0,8,6,PURPUR_STAIRS:0)
Block(0,9,-6,END_BRICKS)
Block(0,9,1,LADDER:4)
Block(0,9,5,END_BRICKS)
Block(0,10,-6,END_BRICKS)
Block(0,10,1,LADDER:4)
Block(0,10,5,END_BRICKS)
Block(0,11,-6,END_BRICKS)
Block(0,11,1,LADDER:4)
Block(0,11,5,END_BRICKS)
Block(0,12,-8,PURPUR_STAIRS:6)
Block(0,12,-7,PURPUR_BLOCK)
Block(0,12,-6,PURPUR_BLOCK)
Block(0,12,-5,PURPUR_BLOCK)
Block(0,12,-4,PURPUR_BLOCK)
Block(0,12,-3,PURPUR_BLOCK)
Block(0,12,-2,PURPUR_BLOCK)
Block(0,12,-1,PURPUR_BLOCK)
Block(0,12,3,PURPUR_BLOCK)
Block(0,12,4,PURPUR_BLOCK)
Block(0,12,5,PURPUR_BLOCK)
Block(0,12,6,PURPUR_BLOCK)
Block(0,12,7,PURPUR_STAIRS:7)
Block(0,13,-1,PURPUR_PILLAR:0)
Block(0,13,3,PURPUR_PILLAR:0)
Block(0,14,-1,PURPUR_PILLAR:0)
Block(0,14,3,PURPUR_PILLAR:0)
Block(0,15,-1,PURPUR_PILLAR:0)
Block(0,15,1,PURPUR_SLAB)
Block(0,15,3,PURPUR_PILLAR:0)
Block(0,16,-1,PURPUR_BLOCK)
Block(0,16,3,PURPUR_BLOCK)
Block(0,17,-1,PURPUR_PILLAR:0)
Block(0,17,3,PURPUR_PILLAR:0)
Block(0,18,-1,PURPUR_PILLAR:0)
Block(0,18,3,PURPUR_PILLAR:0)
Block(0,19,-1,PURPUR_PILLAR:0)
Block(0,19,1,PURPUR_SLAB)
Block(0,19,3,PURPUR_PILLAR:0)
Block(0,20,-1,PURPUR_BLOCK)
Block(0,20,3,PURPUR_BLOCK)
Block(0,21,-1,PURPUR_PILLAR:0)
Block(0,21,3,PURPUR_PILLAR:0)
Block(0,22,-1,PURPUR_PILLAR:0)
Block(0,22,3,PURPUR_PILLAR:0)
Block(0,23,-1,PURPUR_PILLAR:0)
Block(0,23,1,PURPUR_SLAB)
Block(0,23,3,PURPUR_PILLAR:0)
Block(0,24,-2,PURPUR_STAIRS:2)
Block(0,24,-1,PURPUR_BLOCK)
Block(0,24,3,PURPUR_BLOCK)
Block(0,24,4,PURPUR_STAIRS:0)
Block(0,25,-1,END_BRICKS)
Block(0,25,3,END_BRICKS)
Block(0,26,-1,END_BRICKS)
Block(0,26,3,END_BRICKS)
Block(0,27,-1,END_BRICKS)
Block(0,27,3,END_BRICKS)
Block(0,28,-3,PURPUR_STAIRS:2)
Block(0,28,-2,PURPUR_BLOCK)
Block(0,28,-1,PURPUR_BLOCK)
Block(0,28,0,PURPUR_BLOCK)
Block(0,28,1,PURPUR_BLOCK)
Block(0,28,2,PURPUR_BLOCK)
Block(0,28,3,PURPUR_BLOCK)
Block(0,28,4,PURPUR_BLOCK)
Block(0,28,5,PURPUR_STAIRS:0)
Block(1,0,-4,PURPUR_BLOCK)
Block(1,0,-3,PURPUR_BLOCK)
Block(1,0,-2,PURPUR_BLOCK)
Block(1,0,-1,PURPUR_BLOCK)
Block(1,0,0,PURPUR_BLOCK)
Block(1,0,1,PURPUR_BLOCK)
Block(1,0,2,PURPUR_BLOCK)
Block(1,0,3,PURPUR_BLOCK)
Block(1,1,-4,END_BRICKS)
Block(1,1,3,END_BRICKS)
Block(1,2,-4,STAINED_GLASS:2)
Block(1,2,3,STAINED_GLASS:2)
Block(1,3,-4,STAINED_GLASS:2)
Block(1,3,3,STAINED_GLASS:2)
Block(1,4,-6,PURPUR_STAIRS:6)
Block(1,4,-5,PURPUR_BLOCK)
Block(1,4,-4,PURPUR_BLOCK)
Block(1,4,-3,PURPUR_BLOCK)
Block(1,4,-2,PURPUR_BLOCK)
Block(1,4,-1,PURPUR_BLOCK)
Block(1,4,0,PURPUR_BLOCK)
Block(1,4,1,PURPUR_BLOCK)
Block(1,4,2,PURPUR_BLOCK)
Block(1,4,3,PURPUR_BLOCK)
Block(1,4,4,PURPUR_BLOCK)
Block(1,4,5,PURPUR_STAIRS:7)
Block(1,5,-5,END_BRICKS)
Block(1,5,4,END_BRICKS)
Block(1,6,-5,END_BRICKS)
Block(1,6,4,END_BRICKS)
Block(1,7,-5,END_BRICKS)
Block(1,7,4,END_BRICKS)
Block(1,8,-7,PURPUR_STAIRS:6)
Block(1,8,-6,PURPUR_BLOCK)
Block(1,8,-5,PURPUR_BLOCK)
Block(1,8,-4,PURPUR_BLOCK)
Block(1,8,-3,PURPUR_BLOCK)
Block(1,8,-2,PURPUR_BLOCK)
Block(1,8,-1,PURPUR_BLOCK)
Block(1,8,0,PURPUR_BLOCK)
Block(1,8,1,PURPUR_BLOCK)
Block(1,8,2,PURPUR_BLOCK)
Block(1,8,3,PURPUR_BLOCK)
Block(1,8,4,PURPUR_BLOCK)
Block(1,8,5,PURPUR_BLOCK)
Block(1,8,6,PURPUR_STAIRS:7)
Block(1,9,-6,END_BRICKS)
Block(1,9,1,PURPUR_PILLAR:0)
Block(1,9,5,END_BRICKS)
Block(1,10,-6,STAINED_GLASS:2)
Block(1,10,1,PURPUR_PILLAR:0)
Block(1,10,5,STAINED_GLASS:2)
Block(1,11,-6,STAINED_GLASS:2)
Block(1,11,1,PURPUR_PILLAR:0)
Block(1,11,5,STAINED_GLASS:2)
Block(1,12,-8,PURPUR_STAIRS:2)
Block(1,12,-7,PURPUR_BLOCK)
Block(1,12,-6,PURPUR_BLOCK)
Block(1,12,-5,PURPUR_BLOCK)
Block(1,12,-4,PURPUR_BLOCK)
Block(1,12,-3,PURPUR_BLOCK)
Block(1,12,-2,PURPUR_BLOCK)
Block(1,12,-1,PURPUR_BLOCK)
Block(1,12,0,PURPUR_BLOCK)
Block(1,12,1,PURPUR_BLOCK)
Block(1,12,2,PURPUR_BLOCK)
Block(1,12,3,PURPUR_BLOCK)
Block(1,12,4,PURPUR_BLOCK)
Block(1,12,5,PURPUR_BLOCK)
Block(1,12,6,PURPUR_BLOCK)
Block(1,12,7,PURPUR_STAIRS:0)
Block(1,13,0,PURPUR_PILLAR:0)
Block(1,13,1,PURPUR_PILLAR:0)
Block(1,13,2,PURPUR_PILLAR:0)
Block(1,14,0,PURPUR_PILLAR:0)
Block(1,14,1,PURPUR_PILLAR)
Block(1,14,2,PURPUR_PILLAR:0)
Block(1,15,0,PURPUR_PILLAR:0)
Block(1,15,1,PURPUR_PILLAR:0)
Block(1,15,2,PURPUR_PILLAR:0)
Block(1,16,0,PURPUR_BLOCK)
Block(1,16,1,PURPUR_BLOCK)
Block(1,16,2,PURPUR_BLOCK)
Block(1,17,0,PURPUR_PILLAR:0)
Block(1,17,1,PURPUR_PILLAR:0)
Block(1,17,2,PURPUR_PILLAR:0)
Block(1,18,0,PURPUR_PILLAR:0)
Block(1,18,1,PURPUR_PILLAR)
Block(1,18,2,PURPUR_PILLAR:0)
Block(1,19,0,PURPUR_PILLAR:0)
Block(1,19,1,PURPUR_PILLAR:0)
Block(1,19,2,PURPUR_PILLAR:0)
Block(1,20,0,PURPUR_BLOCK)
Block(1,20,1,PURPUR_BLOCK)
Block(1,20,2,PURPUR_BLOCK)
Block(1,21,0,PURPUR_PILLAR:0)
Block(1,21,1,PURPUR_PILLAR:0)
Block(1,21,2,PURPUR_PILLAR:0)
Block(1,22,0,PURPUR_PILLAR:0)
Block(1,22,1,PURPUR_PILLAR)
Block(1,22,2,PURPUR_PILLAR:0)
Block(1,23,0,PURPUR_PILLAR:0)
Block(1,23,1,PURPUR_PILLAR:0)
Block(1,23,2,PURPUR_PILLAR:0)
Block(1,24,-3,WALL_BANNER,EndTowerB/6-banner.nbt)
Block(1,24,-2,PURPUR_STAIRS:6)
Block(1,24,-1,PURPUR_BLOCK)
Block(1,24,0,PURPUR_BLOCK)
Block(1,24,1,PURPUR_BLOCK)
Block(1,24,2,PURPUR_BLOCK)
Block(1,24,3,PURPUR_BLOCK)
Block(1,24,4,PURPUR_STAIRS:7)
Block(1,24,5,WALL_BANNER:3,EndTowerB/7-banner.nbt)
Block(1,25,-1,PURPUR_PILLAR:0)
Block(1,25,0,END_BRICKS)
Block(1,25,1,END_BRICKS)
Block(1,25,2,END_BRICKS)
Block(1,25,3,PURPUR_PILLAR:0)
Block(1,26,-1,PURPUR_PILLAR:0)
Block(1,26,0,END_BRICKS)
Block(1,26,1,STAINED_GLASS:2)
Block(1,26,2,END_BRICKS)
Block(1,26,3,PURPUR_PILLAR:0)
Block(1,27,-1,PURPUR_PILLAR:0)
Block(1,27,0,END_BRICKS)
Block(1,27,1,STAINED_GLASS:2)
Block(1,27,2,END_BRICKS)
Block(1,27,3,PURPUR_PILLAR:0)
Block(1,28,-3,PURPUR_STAIRS:2)
Block(1,28,-2,PURPUR_BLOCK)
Block(1,28,-1,PURPUR_BLOCK)
Block(1,28,0,PURPUR_BLOCK)
Block(1,28,1,PURPUR_BLOCK)
Block(1,28,2,PURPUR_BLOCK)
Block(1,28,3,PURPUR_BLOCK)
Block(1,28,4,PURPUR_BLOCK)
Block(1,28,5,PURPUR_STAIRS:0)
Block(2,0,-4,PURPUR_BLOCK)
Block(2,0,-3,PURPUR_BLOCK)
Block(2,0,-2,PURPUR_BLOCK)
Block(2,0,-1,PURPUR_BLOCK)
Block(2,0,0,PURPUR_BLOCK)
Block(2,0,1,PURPUR_BLOCK)
Block(2,0,2,PURPUR_BLOCK)
Block(2,0,3,PURPUR_BLOCK)
Block(2,1,-4,END_BRICKS)
Block(2,1,3,END_BRICKS)
Block(2,2,-4,END_BRICKS)
Block(2,2,3,END_BRICKS)
Block(2,3,-4,END_BRICKS)
Block(2,3,3,END_BRICKS)
Block(2,4,-6,PURPUR_STAIRS:6)
Block(2,4,-5,PURPUR_BLOCK)
Block(2,4,-4,PURPUR_BLOCK)
Block(2,4,-3,PURPUR_BLOCK)
Block(2,4,-2,PURPUR_BLOCK)
Block(2,4,-1,PURPUR_BLOCK)
Block(2,4,0,PURPUR_BLOCK)
Block(2,4,1,PURPUR_BLOCK)
Block(2,4,2,PURPUR_BLOCK)
Block(2,4,3,PURPUR_BLOCK)
Block(2,4,4,PURPUR_BLOCK)
Block(2,4,5,PURPUR_STAIRS:7)
Block(2,5,-5,END_BRICKS)
Block(2,5,4,END_BRICKS)
Block(2,6,-5,STAINED_GLASS:2)
Block(2,6,4,STAINED_GLASS:2)
Block(2,7,-5,STAINED_GLASS:2)
Block(2,7,4,STAINED_GLASS:2)
Block(2,8,-7,PURPUR_STAIRS:6)
Block(2,8,-6,PURPUR_BLOCK)
Block(2,8,-5,PURPUR_BLOCK)
Block(2,8,-4,PURPUR_BLOCK)
Block(2,8,-3,PURPUR_BLOCK)
Block(2,8,-2,PURPUR_BLOCK)
Block(2,8,-1,PURPUR_BLOCK)
Block(2,8,0,PURPUR_BLOCK)
Block(2,8,1,PURPUR_BLOCK)
Block(2,8,2,PURPUR_BLOCK)
Block(2,8,3,PURPUR_BLOCK)
Block(2,8,4,PURPUR_BLOCK)
Block(2,8,5,PURPUR_BLOCK)
Block(2,8,6,PURPUR_STAIRS:7)
Block(2,9,-6,END_BRICKS)
Block(2,9,5,END_BRICKS)
Block(2,10,-6,END_BRICKS)
Block(2,10,5,END_BRICKS)
Block(2,11,-6,END_BRICKS)
Block(2,11,5,END_BRICKS)
Block(2,12,-8,PURPUR_STAIRS:6)
Block(2,12,-7,PURPUR_BLOCK)
Block(2,12,-6,PURPUR_BLOCK)
Block(2,12,-5,PURPUR_BLOCK)
Block(2,12,-4,PURPUR_BLOCK)
Block(2,12,-3,PURPUR_BLOCK)
Block(2,12,-2,PURPUR_BLOCK)
Block(2,12,-1,PURPUR_BLOCK)
Block(2,12,0,PURPUR_BLOCK)
Block(2,12,1,PURPUR_BLOCK)
Block(2,12,2,PURPUR_BLOCK)
Block(2,12,3,PURPUR_BLOCK)
Block(2,12,4,PURPUR_BLOCK)
Block(2,12,5,PURPUR_BLOCK)
Block(2,12,6,PURPUR_BLOCK)
Block(2,12,7,PURPUR_STAIRS:7)
Block(2,14,1,PURPUR_STAIRS:5)
Block(2,18,1,PURPUR_STAIRS:5)
Block(2,22,1,PURPUR_STAIRS:5)
Block(2,24,-2,PURPUR_STAIRS:5)
Block(2,24,-1,PURPUR_STAIRS:5)
Block(2,24,0,PURPUR_STAIRS:1)
Block(2,24,1,PURPUR_STAIRS:5)
Block(2,24,2,PURPUR_STAIRS:1)
Block(2,24,3,PURPUR_STAIRS:5)
Block(2,24,4,PURPUR_STAIRS:7)
Block(2,25,-2,END_ROD)
Block(2,25,4,END_ROD)
Block(2,28,-3,PURPUR_STAIRS:6)
Block(2,28,-2,PURPUR_BLOCK)
Block(2,28,-1,PURPUR_BLOCK)
Block(2,28,0,PURPUR_BLOCK)
Block(2,28,1,PURPUR_BLOCK)
Block(2,28,2,PURPUR_BLOCK)
Block(2,28,3,PURPUR_BLOCK)
Block(2,28,4,PURPUR_BLOCK)
Block(2,28,5,PURPUR_STAIRS:7)
Block(3,0,-4,PURPUR_BLOCK)
Block(3,0,-3,PURPUR_BLOCK)
Block(3,0,-2,PURPUR_BLOCK)
Block(3,0,-1,PURPUR_BLOCK)
Block(3,0,0,PURPUR_BLOCK)
Block(3,0,1,PURPUR_BLOCK)
Block(3,0,2,PURPUR_BLOCK)
Block(3,0,3,PURPUR_BLOCK)
Block(3,1,-4,PURPUR_PILLAR:0)
Block(3,1,-3,END_BRICKS)
Block(3,1,-2,END_BRICKS)
Block(3,1,1,END_BRICKS)
Block(3,1,2,END_BRICKS)
Block(3,1,3,PURPUR_PILLAR:0)
Block(3,2,-4,PURPUR_PILLAR:0)
Block(3,2,-3,END_BRICKS)
Block(3,2,-2,END_BRICKS)
Block(3,2,1,END_BRICKS)
Block(3,2,2,END_BRICKS)
Block(3,2,3,PURPUR_PILLAR:0)
Block(3,3,-4,PURPUR_PILLAR:0)
Block(3,3,-3,END_BRICKS)
Block(3,3,-2,END_BRICKS)
Block(3,3,1,END_BRICKS)
Block(3,3,2,END_BRICKS)
Block(3,3,3,PURPUR_PILLAR:0)
Block(3,4,-6,PURPUR_STAIRS:2)
Block(3,4,-5,PURPUR_BLOCK)
Block(3,4,-4,PURPUR_BLOCK)
Block(3,4,-3,PURPUR_BLOCK)
Block(3,4,-2,PURPUR_BLOCK)
Block(3,4,-1,PURPUR_BLOCK)
Block(3,4,0,PURPUR_BLOCK)
Block(3,4,1,PURPUR_BLOCK)
Block(3,4,2,PURPUR_BLOCK)
Block(3,4,3,PURPUR_BLOCK)
Block(3,4,4,PURPUR_BLOCK)
Block(3,4,5,PURPUR_STAIRS:0)
Block(3,5,-5,END_BRICKS)
Block(3,5,1,PURPUR_SLAB:8)
Block(3,5,2,PURPUR_BLOCK)
Block(3,5,3,PURPUR_SLAB)
Block(3,5,4,END_BRICKS)
Block(3,6,-5,END_BRICKS)
Block(3,6,-1,PURPUR_SLAB:8)
Block(3,6,0,PURPUR_BLOCK)
Block(3,6,1,PURPUR_SLAB)
Block(3,6,4,END_BRICKS)
Block(3,7,-5,END_BRICKS)
Block(3,7,-3,PURPUR_SLAB:8)
Block(3,7,-2,PURPUR_BLOCK)
Block(3,7,-1,PURPUR_SLAB)
Block(3,7,4,END_BRICKS)
Block(3,8,-7,PURPUR_STAIRS:2)
Block(3,8,-6,PURPUR_BLOCK)
Block(3,8,-5,PURPUR_BLOCK)
Block(3,8,-4,PURPUR_BLOCK)
Block(3,8,-3,PURPUR_SLAB)
Block(3,8,4,PURPUR_BLOCK)
Block(3,8,5,PURPUR_BLOCK)
Block(3,8,6,PURPUR_STAIRS:0)
Block(3,9,-6,END_BRICKS)
Block(3,9,5,END_BRICKS)
Block(3,10,-6,STAINED_GLASS:2)
Block(3,10,5,STAINED_GLASS:2)
Block(3,11,-6,STAINED_GLASS:2)
Block(3,11,5,STAINED_GLASS:2)
Block(3,12,-8,PURPUR_STAIRS:6)
Block(3,12,-7,PURPUR_BLOCK)
Block(3,12,-6,PURPUR_BLOCK)
Block(3,12,-5,PURPUR_BLOCK)
Block(3,12,-4,PURPUR_BLOCK)
Block(3,12,-3,PURPUR_BLOCK)
Block(3,12,-2,PURPUR_BLOCK)
Block(3,12,-1,PURPUR_BLOCK)
Block(3,12,0,PURPUR_BLOCK)
Block(3,12,1,PURPUR_BLOCK)
Block(3,12,2,PURPUR_BLOCK)
Block(3,12,3,PURPUR_BLOCK)
Block(3,12,4,PURPUR_BLOCK)
Block(3,12,5,PURPUR_BLOCK)
Block(3,12,6,PURPUR_BLOCK)
Block(3,12,7,PURPUR_STAIRS:7)
Block(3,24,-1,WALL_BANNER:5,EndTowerB/8-banner.nbt)
Block(3,24,3,WALL_BANNER:5,EndTowerB/9-banner.nbt)
Block(3,28,-3,PURPUR_STAIRS:6)
Block(3,28,-2,PURPUR_STAIRS:5)
Block(3,28,-1,PURPUR_STAIRS:1)
Block(3,28,0,PURPUR_STAIRS:1)
Block(3,28,1,PURPUR_STAIRS:5)
Block(3,28,2,PURPUR_STAIRS:1)
Block(3,28,3,PURPUR_STAIRS:1)
Block(3,28,4,PURPUR_STAIRS:5)
Block(3,28,5,PURPUR_STAIRS:5)
Block(4,0,-3,PURPUR_STAIRS:1)
Block(4,0,-2,PURPUR_BLOCK)
Block(4,0,-1,PURPUR_BLOCK)
Block(4,0,0,PURPUR_BLOCK)
Block(4,0,1,PURPUR_BLOCK)
Block(4,0,2,PURPUR_STAIRS:1)
Block(4,4,-6,PURPUR_STAIRS:6)
Block(4,4,-5,PURPUR_BLOCK)
Block(4,4,-4,PURPUR_BLOCK)
Block(4,4,-3,PURPUR_BLOCK)
Block(4,4,-2,PURPUR_BLOCK)
Block(4,4,-1,PURPUR_BLOCK)
Block(4,4,0,PURPUR_BLOCK)
Block(4,4,1,PURPUR_BLOCK)
Block(4,4,2,PURPUR_BLOCK)
Block(4,4,3,PURPUR_BLOCK)
Block(4,4,4,PURPUR_BLOCK)
Block(4,4,5,PURPUR_STAIRS:7)
Block(4,5,-5,PURPUR_PILLAR:0)
Block(4,5,-4,END_BRICKS)
Block(4,5,-3,END_BRICKS)
Block(4,5,-2,END_BRICKS)
Block(4,5,-1,END_BRICKS)
Block(4,5,0,END_BRICKS)
Block(4,5,1,END_BRICKS)
Block(4,5,2,END_BRICKS)
Block(4,5,3,END_BRICKS)
Block(4,5,4,PURPUR_PILLAR:0)
Block(4,6,-5,PURPUR_PILLAR:0)
Block(4,6,-4,END_BRICKS)
Block(4,6,-3,END_BRICKS)
Block(4,6,-2,END_BRICKS)
Block(4,6,-1,END_BRICKS)
Block(4,6,0,END_BRICKS)
Block(4,6,1,END_BRICKS)
Block(4,6,2,STAINED_GLASS:2)
Block(4,6,3,END_BRICKS)
Block(4,6,4,PURPUR_PILLAR:0)
Block(4,7,-5,PURPUR_PILLAR:0)
Block(4,7,-4,END_BRICKS)
Block(4,7,-3,END_BRICKS)
Block(4,7,-2,END_BRICKS)
Block(4,7,-1,END_BRICKS)
Block(4,7,0,END_BRICKS)
Block(4,7,1,END_BRICKS)
Block(4,7,2,STAINED_GLASS:2)
Block(4,7,3,END_BRICKS)
Block(4,7,4,PURPUR_PILLAR:0)
Block(4,8,-7,PURPUR_STAIRS:2)
Block(4,8,-6,PURPUR_BLOCK)
Block(4,8,-5,PURPUR_BLOCK)
Block(4,8,-4,PURPUR_BLOCK)
Block(4,8,-3,PURPUR_BLOCK)
Block(4,8,-2,PURPUR_BLOCK)
Block(4,8,-1,PURPUR_BLOCK)
Block(4,8,0,PURPUR_BLOCK)
Block(4,8,1,PURPUR_BLOCK)
Block(4,8,2,PURPUR_BLOCK)
Block(4,8,3,PURPUR_BLOCK)
Block(4,8,4,PURPUR_BLOCK)
Block(4,8,5,PURPUR_BLOCK)
Block(4,8,6,PURPUR_STAIRS:0)
Block(4,9,-6,END_BRICKS)
Block(4,9,5,END_BRICKS)
Block(4,10,-6,END_BRICKS)
Block(4,10,5,END_BRICKS)
Block(4,11,-6,END_BRICKS)
Block(4,11,5,END_BRICKS)
Block(4,12,-8,PURPUR_STAIRS:2)
Block(4,12,-7,PURPUR_BLOCK)
Block(4,12,-6,PURPUR_BLOCK)
Block(4,12,-5,PURPUR_BLOCK)
Block(4,12,-4,PURPUR_BLOCK)
Block(4,12,-3,PURPUR_BLOCK)
Block(4,12,-2,PURPUR_BLOCK)
Block(4,12,-1,PURPUR_BLOCK)
Block(4,12,0,PURPUR_BLOCK)
Block(4,12,1,PURPUR_BLOCK)
Block(4,12,2,PURPUR_BLOCK)
Block(4,12,3,PURPUR_BLOCK)
Block(4,12,4,PURPUR_BLOCK)
Block(4,12,5,PURPUR_BLOCK)
Block(4,12,6,PURPUR_BLOCK)
Block(4,12,7,PURPUR_STAIRS:0)
Block(5,4,-6,PURPUR_STAIRS:5)
Block(5,4,-5,PURPUR_STAIRS:5)
Block(5,4,-4,PURPUR_STAIRS:1)
Block(5,4,-3,PURPUR_STAIRS:5)
Block(5,4,-2,PURPUR_STAIRS:5)
Block(5,4,-1,PURPUR_STAIRS:1)
Block(5,4,0,PURPUR_STAIRS:1)
Block(5,4,1,PURPUR_STAIRS:5)
Block(5,4,2,PURPUR_STAIRS:5)
Block(5,4,3,PURPUR_STAIRS:1)
Block(5,4,4,PURPUR_STAIRS:5)
Block(5,4,5,PURPUR_STAIRS:5)
Block(5,5,-6,END_ROD)
Block(5,5,5,END_ROD)
Block(5,8,-7,PURPUR_STAIRS:6)
Block(5,8,-6,PURPUR_BLOCK)
Block(5,8,-5,PURPUR_BLOCK)
Block(5,8,-4,PURPUR_BLOCK)
Block(5,8,-3,PURPUR_BLOCK)
Block(5,8,-2,PURPUR_BLOCK)
Block(5,8,-1,PURPUR_BLOCK)
Block(5,8,0,PURPUR_BLOCK)
Block(5,8,1,PURPUR_BLOCK)
Block(5,8,2,PURPUR_BLOCK)
Block(5,8,3,PURPUR_BLOCK)
Block(5,8,4,PURPUR_BLOCK)
Block(5,8,5,PURPUR_BLOCK)
Block(5,8,6,PURPUR_STAIRS:7)
Block(5,9,-6,PURPUR_PILLAR:0)
Block(5,9,-5,END_BRICKS)
Block(5,9,-4,END_BRICKS)
Block(5,9,-3,END_BRICKS)
Block(5,9,-2,END_BRICKS)
Block(5,9,-1,END_BRICKS)
Block(5,9,0,END_BRICKS)
Block(5,9,1,END_BRICKS)
Block(5,9,2,END_BRICKS)
Block(5,9,3,END_BRICKS)
Block(5,9,4,END_BRICKS)
Block(5,9,5,PURPUR_PILLAR:0)
Block(5,10,-6,PURPUR_PILLAR:0)
Block(5,10,-5,END_BRICKS)
Block(5,10,-4,STAINED_GLASS:2)
Block(5,10,-3,END_BRICKS)
Block(5,10,-2,STAINED_GLASS:2)
Block(5,10,-1,END_BRICKS)
Block(5,10,0,END_BRICKS)
Block(5,10,1,STAINED_GLASS:2)
Block(5,10,2,END_BRICKS)
Block(5,10,3,STAINED_GLASS:2)
Block(5,10,4,END_BRICKS)
Block(5,10,5,PURPUR_PILLAR:0)
Block(5,11,-6,PURPUR_PILLAR:0)
Block(5,11,-5,END_BRICKS)
Block(5,11,-4,STAINED_GLASS:2)
Block(5,11,-3,END_BRICKS)
Block(5,11,-2,STAINED_GLASS:2)
Block(5,11,-1,END_BRICKS)
Block(5,11,0,END_BRICKS)
Block(5,11,1,STAINED_GLASS:2)
Block(5,11,2,END_BRICKS)
Block(5,11,3,STAINED_GLASS:2)
Block(5,11,4,END_BRICKS)
Block(5,11,5,PURPUR_PILLAR:0)
Block(5,12,-8,PURPUR_STAIRS:2)
Block(5,12,-7,PURPUR_BLOCK)
Block(5,12,-6,PURPUR_BLOCK)
Block(5,12,-5,PURPUR_BLOCK)
Block(5,12,-4,PURPUR_BLOCK)
Block(5,12,-3,PURPUR_BLOCK)
Block(5,12,-2,PURPUR_BLOCK)
Block(5,12,-1,PURPUR_BLOCK)
Block(5,12,0,PURPUR_BLOCK)
Block(5,12,1,PURPUR_BLOCK)
Block(5,12,2,PURPUR_BLOCK)
Block(5,12,3,PURPUR_BLOCK)
Block(5,12,4,PURPUR_BLOCK)
Block(5,12,5,PURPUR_BLOCK)
Block(5,12,6,PURPUR_BLOCK)
Block(5,12,7,PURPUR_STAIRS:0)
Block(6,8,-7,PURPUR_STAIRS:6)
Block(6,8,-6,PURPUR_STAIRS:5)
Block(6,8,-5,PURPUR_STAIRS:1)
Block(6,8,-4,PURPUR_STAIRS:1)
Block(6,8,-3,PURPUR_STAIRS:5)
Block(6,8,-2,PURPUR_STAIRS:5)
Block(6,8,-1,PURPUR_STAIRS:1)
Block(6,8,0,PURPUR_STAIRS:1)
Block(6,8,1,PURPUR_STAIRS:5)
Block(6,8,2,PURPUR_STAIRS:5)
Block(6,8,3,PURPUR_STAIRS:1)
Block(6,8,4,PURPUR_STAIRS:1)
Block(6,8,5,PURPUR_STAIRS:5)
Block(6,8,6,PURPUR_STAIRS:5)
Block(6,9,-7,END_ROD)
Block(6,9,6,END_ROD)
Block(6,12,-8,PURPUR_STAIRS:6)
Block(6,12,-7,PURPUR_BLOCK)
Block(6,12,-6,PURPUR_BLOCK)
Block(6,12,-5,PURPUR_BLOCK)
Block(6,12,-4,PURPUR_BLOCK)
Block(6,12,-3,PURPUR_BLOCK)
Block(6,12,-2,PURPUR_BLOCK)
Block(6,12,-1,PURPUR_BLOCK)
Block(6,12,0,PURPUR_BLOCK)
Block(6,12,1,PURPUR_BLOCK)
Block(6,12,2,PURPUR_BLOCK)
Block(6,12,3,PURPUR_BLOCK)
Block(6,12,4,PURPUR_BLOCK)
Block(6,12,5,PURPUR_BLOCK)
Block(6,12,6,PURPUR_BLOCK)
Block(6,12,7,PURPUR_STAIRS:7)
Block(6,13,-7,END_ROD)
Block(6,13,6,END_ROD)
Block(7,12,-8,PURPUR_STAIRS:5)
Block(7,12,-7,PURPUR_STAIRS:5)
Block(7,12,-6,PURPUR_STAIRS:1)
Block(7,12,-5,PURPUR_STAIRS:1)
Block(7,12,-4,PURPUR_STAIRS:5)
Block(7,12,-3,PURPUR_STAIRS:5)
Block(7,12,-2,PURPUR_STAIRS:1)
Block(7,12,-1,PURPUR_STAIRS:5)
Block(7,12,0,PURPUR_STAIRS:5)
Block(7,12,1,PURPUR_STAIRS:1)
Block(7,12,2,PURPUR_STAIRS:5)
Block(7,12,3,PURPUR_STAIRS:5)
Block(7,12,4,PURPUR_STAIRS:1)
Block(7,12,5,PURPUR_STAIRS:1)
Block(7,12,6,PURPUR_STAIRS:5)
Block(7,12,7,PURPUR_STAIRS:7)

#######################################################################
# +-----------------------------------------------------------------+ #
# |                            BO3 checks                           | #
# +-----------------------------------------------------------------+ #
#######################################################################


#######################################################################
# +-----------------------------------------------------------------+ #
# |                             Branches                            | #
# +-----------------------------------------------------------------+ #
#######################################################################


#######################################################################
# +-----------------------------------------------------------------+ #
# |                             Entities                            | #
# +-----------------------------------------------------------------+ #
#######################################################################

Entity(-18,25,-2,SHULKER,1)
Entity(-18,25,5,SHULKER,1)
Entity(-15,19,3,SHULKER,1)
Entity(-11,25,5,SHULKER,1)
Entity(-10,22,0,SHULKER,1)
Entity(-5,9,-5,SHULKER,1)
Entity(-4,23,0,SHULKER,1)
Entity(-1,27,1,SHULKER,1)
Entity(0,14,1,SHULKER,1)
Entity(4,2,-2,SHULKER,1)
Entity(4,2,1,SHULKER,1)
Entity(4,9,4,SHULKER,1)

#######################################################################
# +-----------------------------------------------------------------+ #
# |                            Particles                            | #
# +-----------------------------------------------------------------+ #
#######################################################################


#######################################################################
# +-----------------------------------------------------------------+ #
# |                             Spawners                            | #
# +-----------------------------------------------------------------+ #
#######################################################################


#######################################################################
# +-----------------------------------------------------------------+ #
# |                             ModData                             | #
# +-----------------------------------------------------------------+ #
#######################################################################

