
#######################################################################
# +-----------------------------------------------------------------+ #
# |                            BO3 object                           | #
# +-----------------------------------------------------------------+ #
#######################################################################

Author: totemo

Description: No description given

Version: 3

SettingsMode: WriteWithoutComments


#######################################################################
# +-----------------------------------------------------------------+ #
# |                          Main settings                          | #
# +-----------------------------------------------------------------+ #
#######################################################################

Tree: false

Frequency: 0

Rarity: 100.0

RotateRandomly: true

SpawnHeight: highestBlock

SpawnHeightOffset: 0

SpawnHeightVariance: 0

##############################
# Height Limits for the BO3. #
##############################

MinHeight: 0

MaxHeight: 256

######################
# Extrusion settings #
######################

ExtrudeMode: None

ExtrudeThroughBlocks: AIR

MaxBranchDepth: 10

ExcludedBiomes: All


#######################################################################
# +-----------------------------------------------------------------+ #
# |                      Source block settings                      | #
# +-----------------------------------------------------------------+ #
#######################################################################

SourceBlocks: AIR

MaxPercentageOutsideSourceBlock: 10

OutsideSourceBlock: placeAnyway

IsOTGPlus: false


#######################################################################
# +-----------------------------------------------------------------+ #
# |                              Blocks                             | #
# +-----------------------------------------------------------------+ #
#######################################################################

Block(-16,11,-1,PURPUR_BLOCK)
Block(-16,11,0,PURPUR_BLOCK)
Block(-16,11,1,PURPUR_BLOCK)
Block(-16,12,-2,PURPUR_BLOCK)
Block(-16,12,-1,PURPUR_BLOCK)
Block(-16,12,0,PURPUR_BLOCK)
Block(-16,12,1,PURPUR_BLOCK)
Block(-16,12,2,PURPUR_BLOCK)
Block(-16,13,-2,PURPUR_BLOCK)
Block(-16,13,2,PURPUR_BLOCK)
Block(-16,14,-2,PURPUR_BLOCK)
Block(-16,14,2,PURPUR_BLOCK)
Block(-16,15,-2,PURPUR_BLOCK)
Block(-16,15,-1,PURPUR_SLAB:8)
Block(-16,15,1,PURPUR_SLAB:8)
Block(-16,15,2,PURPUR_BLOCK)
Block(-16,16,-2,PURPUR_SLAB)
Block(-16,16,-1,PURPUR_BLOCK)
Block(-16,16,0,PURPUR_BLOCK)
Block(-16,16,1,PURPUR_BLOCK)
Block(-16,16,2,PURPUR_SLAB)
Block(-15,11,0,PURPUR_PILLAR)
Block(-15,12,-2,PURPUR_BLOCK)
Block(-15,12,-1,PURPUR_STAIRS:1)
Block(-15,12,0,PURPUR_STAIRS:1)
Block(-15,12,1,PURPUR_STAIRS:1)
Block(-15,12,2,PURPUR_BLOCK)
Block(-15,13,-2,PURPUR_BLOCK)
Block(-15,13,2,PURPUR_BLOCK)
Block(-15,14,-2,END_ROD)
Block(-15,14,2,END_ROD)
Block(-14,10,-1,PURPUR_STAIRS:6)
Block(-14,10,0,PURPUR_BLOCK)
Block(-14,10,1,PURPUR_STAIRS:7)
Block(-14,11,-2,PURPUR_BLOCK)
Block(-14,11,-1,PURPUR_STAIRS:1)
Block(-14,11,0,PURPUR_STAIRS:1)
Block(-14,11,1,PURPUR_STAIRS:1)
Block(-14,11,2,PURPUR_BLOCK)
Block(-14,12,-2,PURPUR_STAIRS:2)
Block(-14,12,2,PURPUR_STAIRS:0)
Block(-13,9,-1,PURPUR_STAIRS:6)
Block(-13,9,0,PURPUR_BLOCK)
Block(-13,9,1,PURPUR_STAIRS:7)
Block(-13,10,-2,PURPUR_BLOCK)
Block(-13,10,-1,PURPUR_STAIRS:1)
Block(-13,10,0,PURPUR_STAIRS:1)
Block(-13,10,1,PURPUR_STAIRS:1)
Block(-13,10,2,PURPUR_BLOCK)
Block(-13,11,-2,PURPUR_STAIRS:2)
Block(-13,11,2,PURPUR_STAIRS:0)
Block(-12,7,0,PURPUR_PILLAR)
Block(-12,8,-1,PURPUR_BLOCK)
Block(-12,8,0,PURPUR_BLOCK)
Block(-12,8,1,PURPUR_BLOCK)
Block(-12,9,-2,PURPUR_BLOCK)
Block(-12,9,-1,PURPUR_STAIRS:1)
Block(-12,9,0,PURPUR_STAIRS:1)
Block(-12,9,1,PURPUR_STAIRS:1)
Block(-12,9,2,PURPUR_BLOCK)
Block(-12,10,-2,PURPUR_STAIRS:2)
Block(-12,10,2,PURPUR_STAIRS:0)
Block(-11,7,-1,PURPUR_STAIRS:6)
Block(-11,7,0,PURPUR_PILLAR)
Block(-11,7,1,PURPUR_STAIRS:7)
Block(-11,8,-2,PURPUR_STAIRS:6)
Block(-11,8,-1,PURPUR_BLOCK)
Block(-11,8,0,PURPUR_BLOCK)
Block(-11,8,1,PURPUR_BLOCK)
Block(-11,8,2,PURPUR_STAIRS:7)
Block(-11,9,-2,PURPUR_BLOCK)
Block(-11,9,2,PURPUR_BLOCK)
Block(-10,7,0,PURPUR_PILLAR)
Block(-10,8,-2,PURPUR_BLOCK)
Block(-10,8,-1,PURPUR_BLOCK)
Block(-10,8,0,PURPUR_BLOCK)
Block(-10,8,1,PURPUR_BLOCK)
Block(-10,8,2,PURPUR_BLOCK)
Block(-10,9,-2,PURPUR_STAIRS:2)
Block(-10,9,2,PURPUR_STAIRS:0)
Block(-9,7,0,PURPUR_PILLAR)
Block(-9,8,-2,PURPUR_BLOCK)
Block(-9,8,-1,PURPUR_BLOCK)
Block(-9,8,0,PURPUR_BLOCK)
Block(-9,8,1,PURPUR_BLOCK)
Block(-9,8,2,PURPUR_BLOCK)
Block(-9,9,-2,PURPUR_STAIRS:2)
Block(-9,9,2,PURPUR_STAIRS:0)
Block(-8,7,0,PURPUR_PILLAR)
Block(-8,8,-2,PURPUR_BLOCK)
Block(-8,8,-1,PURPUR_BLOCK)
Block(-8,8,0,PURPUR_BLOCK)
Block(-8,8,1,PURPUR_BLOCK)
Block(-8,8,2,PURPUR_BLOCK)
Block(-8,9,-2,PURPUR_STAIRS:2)
Block(-8,9,2,PURPUR_STAIRS:0)
Block(-8,20,-8,PURPUR_STAIRS:4)
Block(-8,20,-7,PURPUR_STAIRS:4)
Block(-8,20,-6,PURPUR_STAIRS:0)
Block(-8,20,-5,PURPUR_STAIRS:0)
Block(-8,20,-4,PURPUR_STAIRS:4)
Block(-8,20,-3,PURPUR_STAIRS:4)
Block(-8,20,-2,PURPUR_STAIRS:0)
Block(-8,20,-1,PURPUR_STAIRS:0)
Block(-8,20,0,PURPUR_STAIRS:4)
Block(-8,20,1,PURPUR_STAIRS:0)
Block(-8,20,2,PURPUR_STAIRS:0)
Block(-8,20,3,PURPUR_STAIRS:4)
Block(-8,20,4,PURPUR_STAIRS:4)
Block(-8,20,5,PURPUR_STAIRS:0)
Block(-8,20,6,PURPUR_STAIRS:0)
Block(-8,20,7,PURPUR_STAIRS:4)
Block(-8,20,8,PURPUR_STAIRS:7)
Block(-7,7,-1,PURPUR_STAIRS:6)
Block(-7,7,0,PURPUR_PILLAR)
Block(-7,7,1,PURPUR_STAIRS:7)
Block(-7,8,-2,PURPUR_STAIRS:6)
Block(-7,8,-1,PURPUR_BLOCK)
Block(-7,8,0,PURPUR_BLOCK)
Block(-7,8,1,PURPUR_BLOCK)
Block(-7,8,2,PURPUR_STAIRS:7)
Block(-7,9,-2,PURPUR_BLOCK)
Block(-7,9,2,PURPUR_BLOCK)
Block(-7,16,-7,PURPUR_STAIRS:4)
Block(-7,16,-6,PURPUR_STAIRS:4)
Block(-7,16,-5,PURPUR_STAIRS:0)
Block(-7,16,-4,PURPUR_STAIRS:0)
Block(-7,16,-3,PURPUR_STAIRS:4)
Block(-7,16,3,PURPUR_STAIRS:4)
Block(-7,16,4,PURPUR_STAIRS:0)
Block(-7,16,5,PURPUR_STAIRS:0)
Block(-7,16,6,PURPUR_STAIRS:4)
Block(-7,16,7,PURPUR_STAIRS:7)
Block(-7,17,-7,END_ROD)
Block(-7,17,7,END_ROD)
Block(-7,20,-8,PURPUR_STAIRS:6)
Block(-7,20,-7,PURPUR_BLOCK)
Block(-7,20,-6,PURPUR_BLOCK)
Block(-7,20,-5,PURPUR_BLOCK)
Block(-7,20,-4,PURPUR_BLOCK)
Block(-7,20,-3,PURPUR_BLOCK)
Block(-7,20,-2,PURPUR_BLOCK)
Block(-7,20,-1,PURPUR_BLOCK)
Block(-7,20,0,PURPUR_BLOCK)
Block(-7,20,1,PURPUR_BLOCK)
Block(-7,20,2,PURPUR_BLOCK)
Block(-7,20,3,PURPUR_BLOCK)
Block(-7,20,4,PURPUR_BLOCK)
Block(-7,20,5,PURPUR_BLOCK)
Block(-7,20,6,PURPUR_BLOCK)
Block(-7,20,7,PURPUR_BLOCK)
Block(-7,20,8,PURPUR_STAIRS:7)
Block(-6,0,-2,PURPUR_BLOCK)
Block(-6,0,-1,PURPUR_STAIRS:0)
Block(-6,0,0,PURPUR_STAIRS:0)
Block(-6,0,1,PURPUR_STAIRS:0)
Block(-6,0,2,PURPUR_BLOCK)
Block(-6,1,-2,PURPUR_BLOCK)
Block(-6,1,2,PURPUR_BLOCK)
Block(-6,2,-2,END_ROD)
Block(-6,2,2,END_ROD)
Block(-6,6,0,PURPUR_STAIRS:4)
Block(-6,7,0,PURPUR_PILLAR)
Block(-6,8,-2,PURPUR_BLOCK)
Block(-6,8,-1,PURPUR_STAIRS:0)
Block(-6,8,0,PURPUR_STAIRS:0)
Block(-6,8,1,PURPUR_STAIRS:0)
Block(-6,8,2,PURPUR_BLOCK)
Block(-6,9,-2,PURPUR_BLOCK)
Block(-6,9,2,PURPUR_BLOCK)
Block(-6,10,-2,END_ROD)
Block(-6,10,2,END_ROD)
Block(-6,14,0,PURPUR_STAIRS:4)
Block(-6,15,0,PURPUR_PILLAR)
Block(-6,16,-7,PURPUR_STAIRS:6)
Block(-6,16,-6,PURPUR_BLOCK)
Block(-6,16,-5,PURPUR_BLOCK)
Block(-6,16,-4,PURPUR_BLOCK)
Block(-6,16,-3,PURPUR_BLOCK)
Block(-6,16,-2,PURPUR_BLOCK)
Block(-6,16,-1,PURPUR_BLOCK)
Block(-6,16,0,PURPUR_BLOCK)
Block(-6,16,1,PURPUR_BLOCK)
Block(-6,16,2,PURPUR_BLOCK)
Block(-6,16,3,PURPUR_BLOCK)
Block(-6,16,4,PURPUR_BLOCK)
Block(-6,16,5,PURPUR_BLOCK)
Block(-6,16,6,PURPUR_BLOCK)
Block(-6,16,7,PURPUR_STAIRS:7)
Block(-6,17,-6,PURPUR_PILLAR:0)
Block(-6,17,-5,END_BRICKS)
Block(-6,17,-4,END_BRICKS)
Block(-6,17,-3,END_BRICKS)
Block(-6,17,-2,END_BRICKS)
Block(-6,17,-1,END_BRICKS)
Block(-6,17,0,END_BRICKS)
Block(-6,17,1,END_BRICKS)
Block(-6,17,2,END_BRICKS)
Block(-6,17,3,END_BRICKS)
Block(-6,17,4,END_BRICKS)
Block(-6,17,5,END_BRICKS)
Block(-6,17,6,PURPUR_PILLAR:0)
Block(-6,18,-6,PURPUR_PILLAR:0)
Block(-6,18,-5,END_BRICKS)
Block(-6,18,-4,END_BRICKS)
Block(-6,18,-3,END_BRICKS)
Block(-6,18,-2,END_BRICKS)
Block(-6,18,-1,END_BRICKS)
Block(-6,18,0,END_BRICKS)
Block(-6,18,1,STAINED_GLASS:2)
Block(-6,18,2,END_BRICKS)
Block(-6,18,3,END_BRICKS)
Block(-6,18,4,STAINED_GLASS:2)
Block(-6,18,5,END_BRICKS)
Block(-6,18,6,PURPUR_PILLAR:0)
Block(-6,19,-6,PURPUR_PILLAR:0)
Block(-6,19,-5,END_BRICKS)
Block(-6,19,-4,END_BRICKS)
Block(-6,19,-3,END_BRICKS)
Block(-6,19,-2,END_BRICKS)
Block(-6,19,-1,END_BRICKS)
Block(-6,19,0,END_BRICKS)
Block(-6,19,1,STAINED_GLASS:2)
Block(-6,19,2,END_BRICKS)
Block(-6,19,3,END_BRICKS)
Block(-6,19,4,STAINED_GLASS:2)
Block(-6,19,5,END_BRICKS)
Block(-6,19,6,PURPUR_PILLAR:0)
Block(-6,20,-8,PURPUR_STAIRS:2)
Block(-6,20,-7,PURPUR_BLOCK)
Block(-6,20,-6,PURPUR_BLOCK)
Block(-6,20,-5,PURPUR_BLOCK)
Block(-6,20,-4,PURPUR_BLOCK)
Block(-6,20,-3,PURPUR_BLOCK)
Block(-6,20,-2,PURPUR_BLOCK)
Block(-6,20,-1,PURPUR_BLOCK)
Block(-6,20,0,PURPUR_BLOCK)
Block(-6,20,1,PURPUR_BLOCK)
Block(-6,20,2,PURPUR_BLOCK)
Block(-6,20,3,PURPUR_BLOCK)
Block(-6,20,4,PURPUR_BLOCK)
Block(-6,20,5,PURPUR_BLOCK)
Block(-6,20,6,PURPUR_BLOCK)
Block(-6,20,7,PURPUR_BLOCK)
Block(-6,20,8,PURPUR_STAIRS:0)
Block(-6,21,-3,PURPUR_STAIRS:0)
Block(-6,21,-2,PURPUR_STAIRS:0)
Block(-6,21,-1,PURPUR_STAIRS:0)
Block(-6,21,0,PURPUR_STAIRS:0)
Block(-6,21,1,PURPUR_STAIRS:0)
Block(-5,0,-2,PURPUR_BLOCK)
Block(-5,0,-1,PURPUR_BLOCK)
Block(-5,0,0,PURPUR_BLOCK)
Block(-5,0,1,PURPUR_BLOCK)
Block(-5,0,2,PURPUR_BLOCK)
Block(-5,1,-2,PURPUR_BLOCK)
Block(-5,1,2,PURPUR_BLOCK)
Block(-5,2,-2,PURPUR_BLOCK)
Block(-5,2,2,PURPUR_BLOCK)
Block(-5,3,-2,PURPUR_BLOCK)
Block(-5,3,-1,PURPUR_SLAB:8)
Block(-5,3,1,PURPUR_SLAB:8)
Block(-5,3,2,PURPUR_BLOCK)
Block(-5,4,-2,PURPUR_SLAB)
Block(-5,4,-1,PURPUR_BLOCK)
Block(-5,4,0,PURPUR_BLOCK)
Block(-5,4,1,PURPUR_BLOCK)
Block(-5,4,2,PURPUR_SLAB)
Block(-5,5,-1,PURPUR_PILLAR:0)
Block(-5,5,0,PURPUR_PILLAR:0)
Block(-5,5,1,PURPUR_PILLAR:0)
Block(-5,6,-1,PURPUR_PILLAR:0)
Block(-5,6,0,PURPUR_PILLAR)
Block(-5,6,1,PURPUR_PILLAR:0)
Block(-5,7,-1,PURPUR_BLOCK)
Block(-5,7,0,PURPUR_BLOCK)
Block(-5,7,1,PURPUR_BLOCK)
Block(-5,8,-2,PURPUR_BLOCK)
Block(-5,8,-1,PURPUR_BLOCK)
Block(-5,8,0,PURPUR_BLOCK)
Block(-5,8,1,PURPUR_BLOCK)
Block(-5,8,2,PURPUR_BLOCK)
Block(-5,9,-2,PURPUR_BLOCK)
Block(-5,9,2,PURPUR_BLOCK)
Block(-5,10,-2,PURPUR_BLOCK)
Block(-5,10,2,PURPUR_BLOCK)
Block(-5,11,-2,PURPUR_BLOCK)
Block(-5,11,-1,PURPUR_SLAB:8)
Block(-5,11,1,PURPUR_SLAB:8)
Block(-5,11,2,PURPUR_BLOCK)
Block(-5,12,-2,PURPUR_SLAB)
Block(-5,12,-1,PURPUR_BLOCK)
Block(-5,12,0,PURPUR_BLOCK)
Block(-5,12,1,PURPUR_BLOCK)
Block(-5,12,2,PURPUR_SLAB)
Block(-5,13,-1,PURPUR_PILLAR:0)
Block(-5,13,0,PURPUR_PILLAR:0)
Block(-5,13,1,PURPUR_PILLAR:0)
Block(-5,14,-1,PURPUR_PILLAR:0)
Block(-5,14,0,PURPUR_PILLAR)
Block(-5,14,1,PURPUR_PILLAR:0)
Block(-5,15,-1,PURPUR_BLOCK)
Block(-5,15,0,PURPUR_BLOCK)
Block(-5,15,1,PURPUR_BLOCK)
Block(-5,16,-7,PURPUR_STAIRS:2)
Block(-5,16,-6,PURPUR_BLOCK)
Block(-5,16,-5,PURPUR_BLOCK)
Block(-5,16,-4,PURPUR_BLOCK)
Block(-5,16,-3,PURPUR_BLOCK)
Block(-5,16,-2,PURPUR_BLOCK)
Block(-5,16,-1,PURPUR_BLOCK)
Block(-5,16,0,PURPUR_BLOCK)
Block(-5,16,1,PURPUR_BLOCK)
Block(-5,16,2,PURPUR_BLOCK)
Block(-5,16,3,PURPUR_BLOCK)
Block(-5,16,4,PURPUR_BLOCK)
Block(-5,16,5,PURPUR_BLOCK)
Block(-5,16,6,PURPUR_BLOCK)
Block(-5,16,7,PURPUR_STAIRS:0)
Block(-5,17,-6,END_BRICKS)
Block(-5,17,-5,CHEST:3,EndTowerE/1-chest.nbt)
Block(-5,17,-1,PURPUR_SLAB:8)
Block(-5,17,0,PURPUR_BLOCK)
Block(-5,17,1,PURPUR_SLAB)
Block(-5,17,6,END_BRICKS)
Block(-5,18,-6,END_BRICKS)
Block(-5,18,-3,PURPUR_SLAB:8)
Block(-5,18,-2,PURPUR_BLOCK)
Block(-5,18,-1,PURPUR_SLAB)
Block(-5,18,6,END_BRICKS)
Block(-5,19,-6,END_BRICKS)
Block(-5,19,-5,PURPUR_SLAB:8)
Block(-5,19,-4,PURPUR_BLOCK)
Block(-5,19,-3,PURPUR_SLAB)
Block(-5,19,6,END_BRICKS)
Block(-5,20,-8,PURPUR_STAIRS:2)
Block(-5,20,-7,PURPUR_BLOCK)
Block(-5,20,-6,PURPUR_BLOCK)
Block(-5,20,-5,PURPUR_SLAB)
Block(-5,20,1,PURPUR_BLOCK)
Block(-5,20,2,PURPUR_BLOCK)
Block(-5,20,3,PURPUR_BLOCK)
Block(-5,20,4,PURPUR_BLOCK)
Block(-5,20,5,PURPUR_BLOCK)
Block(-5,20,6,PURPUR_BLOCK)
Block(-5,20,7,PURPUR_BLOCK)
Block(-5,20,8,PURPUR_STAIRS:0)
Block(-5,21,1,PURPUR_STAIRS:0)
Block(-4,0,-3,PURPUR_BLOCK)
Block(-4,0,-2,PURPUR_BLOCK)
Block(-4,0,-1,PURPUR_BLOCK)
Block(-4,0,0,PURPUR_BLOCK)
Block(-4,0,1,PURPUR_BLOCK)
Block(-4,0,2,PURPUR_BLOCK)
Block(-4,0,3,PURPUR_BLOCK)
Block(-4,1,-3,PURPUR_PILLAR:0)
Block(-4,1,-2,PURPUR_PILLAR:0)
Block(-4,1,-1,PURPUR_SLAB)
Block(-4,1,2,PURPUR_PILLAR:0)
Block(-4,1,3,PURPUR_PILLAR:0)
Block(-4,2,-3,PURPUR_PILLAR:0)
Block(-4,2,-2,PURPUR_PILLAR:0)
Block(-4,2,2,PURPUR_PILLAR:0)
Block(-4,2,3,PURPUR_PILLAR:0)
Block(-4,3,-3,PURPUR_PILLAR:0)
Block(-4,3,-2,PURPUR_PILLAR:0)
Block(-4,3,2,PURPUR_PILLAR:0)
Block(-4,3,3,PURPUR_PILLAR:0)
Block(-4,4,-3,PURPUR_BLOCK)
Block(-4,4,-2,PURPUR_BLOCK)
Block(-4,4,2,PURPUR_BLOCK)
Block(-4,4,3,PURPUR_BLOCK)
Block(-4,5,-3,PURPUR_PILLAR:0)
Block(-4,5,-2,PURPUR_PILLAR:0)
Block(-4,5,2,PURPUR_PILLAR:0)
Block(-4,5,3,PURPUR_PILLAR:0)
Block(-4,6,-3,PURPUR_PILLAR:0)
Block(-4,6,-2,PURPUR_PILLAR:0)
Block(-4,6,2,PURPUR_PILLAR:0)
Block(-4,6,3,PURPUR_PILLAR:0)
Block(-4,7,-3,PURPUR_PILLAR:0)
Block(-4,7,-2,PURPUR_PILLAR:0)
Block(-4,7,2,PURPUR_PILLAR:0)
Block(-4,7,3,PURPUR_PILLAR:0)
Block(-4,8,-3,PURPUR_BLOCK)
Block(-4,8,-2,PURPUR_BLOCK)
Block(-4,8,1,PURPUR_SLAB)
Block(-4,8,2,PURPUR_BLOCK)
Block(-4,8,3,PURPUR_BLOCK)
Block(-4,9,-3,PURPUR_PILLAR:0)
Block(-4,9,-2,PURPUR_PILLAR:0)
Block(-4,9,-1,PURPUR_SLAB)
Block(-4,9,2,PURPUR_PILLAR:0)
Block(-4,9,3,PURPUR_PILLAR:0)
Block(-4,10,-3,PURPUR_PILLAR:0)
Block(-4,10,-2,PURPUR_PILLAR:0)
Block(-4,10,2,PURPUR_PILLAR:0)
Block(-4,10,3,PURPUR_PILLAR:0)
Block(-4,11,-3,PURPUR_PILLAR:0)
Block(-4,11,-2,PURPUR_PILLAR:0)
Block(-4,11,2,PURPUR_PILLAR:0)
Block(-4,11,3,PURPUR_PILLAR:0)
Block(-4,12,-3,PURPUR_BLOCK)
Block(-4,12,-2,PURPUR_BLOCK)
Block(-4,12,2,PURPUR_BLOCK)
Block(-4,12,3,PURPUR_BLOCK)
Block(-4,13,-3,PURPUR_PILLAR:0)
Block(-4,13,-2,PURPUR_PILLAR:0)
Block(-4,13,2,PURPUR_PILLAR:0)
Block(-4,13,3,PURPUR_PILLAR:0)
Block(-4,14,-3,PURPUR_PILLAR:0)
Block(-4,14,-2,PURPUR_PILLAR:0)
Block(-4,14,2,PURPUR_PILLAR:0)
Block(-4,14,3,PURPUR_PILLAR:0)
Block(-4,15,-3,PURPUR_PILLAR:0)
Block(-4,15,-2,PURPUR_PILLAR:0)
Block(-4,15,2,PURPUR_PILLAR:0)
Block(-4,15,3,PURPUR_PILLAR:0)
Block(-4,16,-7,PURPUR_STAIRS:2)
Block(-4,16,-6,PURPUR_BLOCK)
Block(-4,16,-5,PURPUR_BLOCK)
Block(-4,16,-4,PURPUR_BLOCK)
Block(-4,16,-3,PURPUR_BLOCK)
Block(-4,16,-2,PURPUR_BLOCK)
Block(-4,16,-1,PURPUR_BLOCK)
Block(-4,16,1,PURPUR_SLAB)
Block(-4,16,2,PURPUR_BLOCK)
Block(-4,16,3,PURPUR_BLOCK)
Block(-4,16,4,PURPUR_BLOCK)
Block(-4,16,5,PURPUR_BLOCK)
Block(-4,16,6,PURPUR_BLOCK)
Block(-4,16,7,PURPUR_STAIRS:0)
Block(-4,17,-6,END_BRICKS)
Block(-4,17,6,END_BRICKS)
Block(-4,18,-6,END_BRICKS)
Block(-4,18,6,STAINED_GLASS:2)
Block(-4,19,-6,END_BRICKS)
Block(-4,19,6,STAINED_GLASS:2)
Block(-4,20,-8,PURPUR_STAIRS:6)
Block(-4,20,-7,PURPUR_BLOCK)
Block(-4,20,-6,PURPUR_BLOCK)
Block(-4,20,-5,PURPUR_BLOCK)
Block(-4,20,-4,PURPUR_BLOCK)
Block(-4,20,-3,PURPUR_BLOCK)
Block(-4,20,-2,PURPUR_BLOCK)
Block(-4,20,-1,PURPUR_BLOCK)
Block(-4,20,0,PURPUR_BLOCK)
Block(-4,20,1,PURPUR_BLOCK)
Block(-4,20,2,PURPUR_BLOCK)
Block(-4,20,3,PURPUR_BLOCK)
Block(-4,20,4,PURPUR_BLOCK)
Block(-4,20,5,PURPUR_BLOCK)
Block(-4,20,6,PURPUR_BLOCK)
Block(-4,20,7,PURPUR_BLOCK)
Block(-4,20,8,PURPUR_STAIRS:7)
Block(-4,21,-3,PURPUR_STAIRS:1)
Block(-4,21,-2,PURPUR_STAIRS:1)
Block(-4,21,-1,PURPUR_STAIRS:1)
Block(-4,21,0,PURPUR_STAIRS:1)
Block(-4,21,1,PURPUR_STAIRS:0)
Block(-3,0,-4,PURPUR_BLOCK)
Block(-3,0,-3,PURPUR_BLOCK)
Block(-3,0,-2,PURPUR_BLOCK)
Block(-3,0,-1,PURPUR_BLOCK)
Block(-3,0,0,PURPUR_BLOCK)
Block(-3,0,1,PURPUR_BLOCK)
Block(-3,0,2,PURPUR_BLOCK)
Block(-3,0,3,PURPUR_BLOCK)
Block(-3,0,4,PURPUR_BLOCK)
Block(-3,1,-4,PURPUR_PILLAR:0)
Block(-3,1,4,PURPUR_PILLAR:0)
Block(-3,2,-4,PURPUR_PILLAR:0)
Block(-3,2,-2,END_ROD:5)
Block(-3,2,4,PURPUR_PILLAR:0)
Block(-3,3,-4,PURPUR_PILLAR:0)
Block(-3,3,4,PURPUR_PILLAR:0)
Block(-3,4,-4,PURPUR_BLOCK)
Block(-3,4,4,PURPUR_BLOCK)
Block(-3,5,-4,PURPUR_PILLAR:0)
Block(-3,5,4,PURPUR_PILLAR:0)
Block(-3,6,-4,PURPUR_PILLAR:0)
Block(-3,6,4,PURPUR_PILLAR:0)
Block(-3,7,-4,PURPUR_PILLAR:0)
Block(-3,7,2,END_ROD:5)
Block(-3,7,4,PURPUR_PILLAR:0)
Block(-3,8,-4,PURPUR_BLOCK)
Block(-3,8,4,PURPUR_BLOCK)
Block(-3,9,-4,PURPUR_PILLAR:0)
Block(-3,9,4,PURPUR_PILLAR:0)
Block(-3,10,-4,PURPUR_PILLAR:0)
Block(-3,10,-2,END_ROD:5)
Block(-3,10,4,PURPUR_PILLAR:0)
Block(-3,11,-4,PURPUR_PILLAR:0)
Block(-3,11,4,PURPUR_PILLAR:0)
Block(-3,12,-4,PURPUR_BLOCK)
Block(-3,12,4,PURPUR_BLOCK)
Block(-3,13,-4,PURPUR_PILLAR:0)
Block(-3,13,4,PURPUR_PILLAR:0)
Block(-3,14,-4,PURPUR_PILLAR:0)
Block(-3,14,4,PURPUR_PILLAR:0)
Block(-3,15,-4,PURPUR_PILLAR:0)
Block(-3,15,2,END_ROD:5)
Block(-3,15,4,PURPUR_PILLAR:0)
Block(-3,16,-7,PURPUR_STAIRS:6)
Block(-3,16,-6,PURPUR_BLOCK)
Block(-3,16,-5,PURPUR_BLOCK)
Block(-3,16,-4,PURPUR_BLOCK)
Block(-3,16,-3,PURPUR_BLOCK)
Block(-3,16,-2,PURPUR_BLOCK)
Block(-3,16,-1,PURPUR_BLOCK)
Block(-3,16,4,PURPUR_BLOCK)
Block(-3,16,5,PURPUR_BLOCK)
Block(-3,16,6,PURPUR_BLOCK)
Block(-3,16,7,PURPUR_STAIRS:7)
Block(-3,17,-6,END_BRICKS)
Block(-3,17,6,END_BRICKS)
Block(-3,18,-6,END_BRICKS)
Block(-3,18,6,END_BRICKS)
Block(-3,19,-6,END_BRICKS)
Block(-3,19,6,END_BRICKS)
Block(-3,20,-8,PURPUR_STAIRS:6)
Block(-3,20,-7,PURPUR_BLOCK)
Block(-3,20,-6,PURPUR_BLOCK)
Block(-3,20,-5,PURPUR_BLOCK)
Block(-3,20,-4,PURPUR_BLOCK)
Block(-3,20,-3,PURPUR_BLOCK)
Block(-3,20,-2,PURPUR_BLOCK)
Block(-3,20,-1,PURPUR_BLOCK)
Block(-3,20,0,PURPUR_BLOCK)
Block(-3,20,1,PURPUR_BLOCK)
Block(-3,20,2,PURPUR_BLOCK)
Block(-3,20,3,PURPUR_BLOCK)
Block(-3,20,4,PURPUR_BLOCK)
Block(-3,20,5,PURPUR_BLOCK)
Block(-3,20,6,PURPUR_BLOCK)
Block(-3,20,7,PURPUR_BLOCK)
Block(-3,20,8,PURPUR_STAIRS:7)
Block(-2,0,-6,PURPUR_BLOCK)
Block(-2,0,-5,PURPUR_BLOCK)
Block(-2,0,-4,PURPUR_BLOCK)
Block(-2,0,-3,PURPUR_BLOCK)
Block(-2,0,-2,PURPUR_BLOCK)
Block(-2,0,-1,PURPUR_BLOCK)
Block(-2,0,0,PURPUR_BLOCK)
Block(-2,0,1,PURPUR_BLOCK)
Block(-2,0,2,PURPUR_BLOCK)
Block(-2,0,3,PURPUR_BLOCK)
Block(-2,0,4,PURPUR_BLOCK)
Block(-2,0,5,PURPUR_BLOCK)
Block(-2,0,6,PURPUR_BLOCK)
Block(-2,1,-6,PURPUR_BLOCK)
Block(-2,1,-5,PURPUR_BLOCK)
Block(-2,1,-4,PURPUR_PILLAR:0)
Block(-2,1,4,PURPUR_PILLAR:0)
Block(-2,1,5,PURPUR_BLOCK)
Block(-2,1,6,PURPUR_BLOCK)
Block(-2,2,-6,END_ROD)
Block(-2,2,-5,PURPUR_BLOCK)
Block(-2,2,-4,PURPUR_PILLAR:0)
Block(-2,2,4,PURPUR_PILLAR:0)
Block(-2,2,5,PURPUR_BLOCK)
Block(-2,2,6,END_ROD)
Block(-2,3,-5,PURPUR_BLOCK)
Block(-2,3,-4,PURPUR_PILLAR:0)
Block(-2,3,-3,END_ROD:3)
Block(-2,3,4,PURPUR_PILLAR:0)
Block(-2,3,5,PURPUR_BLOCK)
Block(-2,4,-5,PURPUR_SLAB)
Block(-2,4,-4,PURPUR_BLOCK)
Block(-2,4,4,PURPUR_BLOCK)
Block(-2,4,5,PURPUR_SLAB)
Block(-2,5,-4,PURPUR_PILLAR:0)
Block(-2,5,4,PURPUR_PILLAR:0)
Block(-2,6,-4,PURPUR_PILLAR:0)
Block(-2,6,3,END_ROD:2)
Block(-2,6,4,PURPUR_PILLAR:0)
Block(-2,7,-4,PURPUR_PILLAR:0)
Block(-2,7,4,PURPUR_PILLAR:0)
Block(-2,8,-4,PURPUR_BLOCK)
Block(-2,8,4,PURPUR_BLOCK)
Block(-2,8,5,PURPUR_BLOCK)
Block(-2,8,6,PURPUR_BLOCK)
Block(-2,9,-4,PURPUR_PILLAR:0)
Block(-2,9,4,PURPUR_PILLAR:0)
Block(-2,9,5,PURPUR_BLOCK)
Block(-2,9,6,PURPUR_BLOCK)
Block(-2,10,-4,PURPUR_PILLAR:0)
Block(-2,10,4,PURPUR_PILLAR:0)
Block(-2,10,5,PURPUR_BLOCK)
Block(-2,10,6,END_ROD)
Block(-2,11,-4,PURPUR_PILLAR:0)
Block(-2,11,-3,END_ROD:3)
Block(-2,11,4,PURPUR_PILLAR:0)
Block(-2,11,5,PURPUR_BLOCK)
Block(-2,12,-4,PURPUR_BLOCK)
Block(-2,12,4,PURPUR_BLOCK)
Block(-2,12,5,PURPUR_SLAB)
Block(-2,13,-4,PURPUR_PILLAR:0)
Block(-2,13,4,PURPUR_PILLAR:0)
Block(-2,14,-4,PURPUR_PILLAR:0)
Block(-2,14,3,END_ROD:2)
Block(-2,14,4,PURPUR_PILLAR:0)
Block(-2,15,-4,PURPUR_PILLAR:0)
Block(-2,15,4,PURPUR_PILLAR:0)
Block(-2,16,-7,PURPUR_STAIRS:6)
Block(-2,16,-6,PURPUR_BLOCK)
Block(-2,16,-5,PURPUR_BLOCK)
Block(-2,16,-4,PURPUR_BLOCK)
Block(-2,16,-3,PURPUR_BLOCK)
Block(-2,16,-2,PURPUR_BLOCK)
Block(-2,16,-1,PURPUR_BLOCK)
Block(-2,16,4,PURPUR_BLOCK)
Block(-2,16,5,PURPUR_BLOCK)
Block(-2,16,6,PURPUR_BLOCK)
Block(-2,16,7,PURPUR_STAIRS:7)
Block(-2,17,-6,END_BRICKS)
Block(-2,17,6,END_BRICKS)
Block(-2,18,-6,END_BRICKS)
Block(-2,18,6,END_BRICKS)
Block(-2,19,-6,END_BRICKS)
Block(-2,19,6,END_BRICKS)
Block(-2,20,-8,PURPUR_STAIRS:2)
Block(-2,20,-7,PURPUR_BLOCK)
Block(-2,20,-6,PURPUR_BLOCK)
Block(-2,20,-5,PURPUR_BLOCK)
Block(-2,20,-4,PURPUR_BLOCK)
Block(-2,20,-3,PURPUR_BLOCK)
Block(-2,20,-2,PURPUR_BLOCK)
Block(-2,20,-1,PURPUR_BLOCK)
Block(-2,20,0,PURPUR_BLOCK)
Block(-2,20,1,PURPUR_BLOCK)
Block(-2,20,2,PURPUR_BLOCK)
Block(-2,20,3,PURPUR_BLOCK)
Block(-2,20,4,PURPUR_BLOCK)
Block(-2,20,5,PURPUR_BLOCK)
Block(-2,20,6,PURPUR_BLOCK)
Block(-2,20,7,PURPUR_BLOCK)
Block(-2,20,8,PURPUR_STAIRS:0)
Block(-1,0,-6,PURPUR_STAIRS:2)
Block(-1,0,-5,PURPUR_BLOCK)
Block(-1,0,-4,PURPUR_BLOCK)
Block(-1,0,-3,PURPUR_BLOCK)
Block(-1,0,-2,PURPUR_BLOCK)
Block(-1,0,-1,PURPUR_BLOCK)
Block(-1,0,0,PURPUR_BLOCK)
Block(-1,0,1,PURPUR_BLOCK)
Block(-1,0,2,PURPUR_BLOCK)
Block(-1,0,3,PURPUR_BLOCK)
Block(-1,0,4,PURPUR_BLOCK)
Block(-1,0,5,PURPUR_BLOCK)
Block(-1,0,6,PURPUR_STAIRS:0)
Block(-1,3,-5,PURPUR_SLAB:8)
Block(-1,3,5,PURPUR_SLAB:8)
Block(-1,4,-5,PURPUR_BLOCK)
Block(-1,4,-4,PURPUR_SLAB)
Block(-1,4,5,PURPUR_BLOCK)
Block(-1,5,-5,PURPUR_PILLAR:0)
Block(-1,5,4,PURPUR_SLAB)
Block(-1,5,5,PURPUR_PILLAR:0)
Block(-1,6,-5,PURPUR_PILLAR:0)
Block(-1,6,5,PURPUR_PILLAR:0)
Block(-1,7,-5,PURPUR_PILLAR:0)
Block(-1,7,5,PURPUR_BLOCK)
Block(-1,8,-5,PURPUR_BLOCK)
Block(-1,8,5,PURPUR_BLOCK)
Block(-1,8,6,PURPUR_STAIRS:0)
Block(-1,9,-5,PURPUR_PILLAR:0)
Block(-1,10,-5,PURPUR_PILLAR:0)
Block(-1,11,-5,PURPUR_PILLAR:0)
Block(-1,11,5,PURPUR_SLAB:8)
Block(-1,12,-5,PURPUR_BLOCK)
Block(-1,12,-4,PURPUR_SLAB)
Block(-1,12,5,PURPUR_BLOCK)
Block(-1,13,-5,PURPUR_PILLAR:0)
Block(-1,13,4,PURPUR_SLAB)
Block(-1,13,5,PURPUR_PILLAR:0)
Block(-1,14,-5,PURPUR_PILLAR:0)
Block(-1,14,5,PURPUR_PILLAR:0)
Block(-1,15,-5,PURPUR_PILLAR:0)
Block(-1,15,5,PURPUR_BLOCK)
Block(-1,16,-7,PURPUR_STAIRS:2)
Block(-1,16,-6,PURPUR_BLOCK)
Block(-1,16,-5,PURPUR_BLOCK)
Block(-1,16,-4,PURPUR_BLOCK)
Block(-1,16,-3,PURPUR_BLOCK)
Block(-1,16,-2,PURPUR_BLOCK)
Block(-1,16,-1,PURPUR_BLOCK)
Block(-1,16,5,PURPUR_BLOCK)
Block(-1,16,6,PURPUR_BLOCK)
Block(-1,16,7,PURPUR_STAIRS:0)
Block(-1,17,-6,END_BRICKS)
Block(-1,17,-1,PURPUR_PILLAR:0)
Block(-1,17,6,END_BRICKS)
Block(-1,18,-6,STAINED_GLASS:2)
Block(-1,18,-1,PURPUR_PILLAR:0)
Block(-1,18,6,STAINED_GLASS:2)
Block(-1,19,-6,STAINED_GLASS:2)
Block(-1,19,-1,PURPUR_PILLAR:0)
Block(-1,19,6,STAINED_GLASS:2)
Block(-1,20,-8,PURPUR_STAIRS:2)
Block(-1,20,-7,PURPUR_BLOCK)
Block(-1,20,-6,PURPUR_BLOCK)
Block(-1,20,-5,PURPUR_BLOCK)
Block(-1,20,-4,PURPUR_BLOCK)
Block(-1,20,-3,PURPUR_BLOCK)
Block(-1,20,-2,PURPUR_BLOCK)
Block(-1,20,-1,PURPUR_BLOCK)
Block(-1,20,0,PURPUR_BLOCK)
Block(-1,20,1,PURPUR_BLOCK)
Block(-1,20,2,PURPUR_BLOCK)
Block(-1,20,3,PURPUR_BLOCK)
Block(-1,20,4,PURPUR_BLOCK)
Block(-1,20,5,PURPUR_BLOCK)
Block(-1,20,6,PURPUR_BLOCK)
Block(-1,20,7,PURPUR_BLOCK)
Block(-1,20,8,PURPUR_STAIRS:0)
Block(0,0,-6,PURPUR_STAIRS:2)
Block(0,0,-5,PURPUR_BLOCK)
Block(0,0,-4,PURPUR_BLOCK)
Block(0,0,-3,PURPUR_BLOCK)
Block(0,0,-2,PURPUR_BLOCK)
Block(0,0,-1,PURPUR_BLOCK)
Block(0,0,0,PURPUR_BLOCK)
Block(0,0,1,PURPUR_BLOCK)
Block(0,0,2,PURPUR_BLOCK)
Block(0,0,3,PURPUR_BLOCK)
Block(0,0,4,PURPUR_BLOCK)
Block(0,0,5,PURPUR_BLOCK)
Block(0,0,6,PURPUR_STAIRS:0)
Block(0,4,-5,PURPUR_BLOCK)
Block(0,4,5,PURPUR_BLOCK)
Block(0,5,-5,PURPUR_PILLAR:0)
Block(0,5,5,PURPUR_PILLAR:0)
Block(0,6,-6,PURPUR_STAIRS:6)
Block(0,6,-5,PURPUR_PILLAR:8)
Block(0,6,5,PURPUR_PILLAR:8)
Block(0,6,6,PURPUR_STAIRS:7)
Block(0,7,-5,PURPUR_PILLAR:0)
Block(0,7,5,PURPUR_BLOCK)
Block(0,7,6,PURPUR_PILLAR:8)
Block(0,8,-5,PURPUR_BLOCK)
Block(0,8,5,PURPUR_BLOCK)
Block(0,8,6,PURPUR_STAIRS:0)
Block(0,9,-5,PURPUR_PILLAR:0)
Block(0,10,-6,PURPUR_STAIRS:6)
Block(0,10,-5,PURPUR_PILLAR:8)
Block(0,11,-5,PURPUR_PILLAR:0)
Block(0,12,-5,PURPUR_BLOCK)
Block(0,12,5,PURPUR_BLOCK)
Block(0,13,-5,PURPUR_PILLAR:0)
Block(0,13,5,PURPUR_PILLAR:0)
Block(0,14,-6,PURPUR_STAIRS:6)
Block(0,14,-5,PURPUR_PILLAR:8)
Block(0,14,5,PURPUR_PILLAR:8)
Block(0,14,6,PURPUR_STAIRS:7)
Block(0,15,-5,PURPUR_PILLAR:0)
Block(0,15,5,PURPUR_BLOCK)
Block(0,15,6,PURPUR_PILLAR:8)
Block(0,16,-7,PURPUR_STAIRS:2)
Block(0,16,-6,PURPUR_BLOCK)
Block(0,16,-5,PURPUR_BLOCK)
Block(0,16,5,PURPUR_BLOCK)
Block(0,16,6,PURPUR_BLOCK)
Block(0,16,7,PURPUR_STAIRS:0)
Block(0,17,-6,END_BRICKS)
Block(0,17,6,END_BRICKS)
Block(0,18,-6,END_BRICKS)
Block(0,18,6,END_BRICKS)
Block(0,19,-6,END_BRICKS)
Block(0,19,6,END_BRICKS)
Block(0,20,-8,PURPUR_STAIRS:6)
Block(0,20,-7,PURPUR_BLOCK)
Block(0,20,-6,PURPUR_BLOCK)
Block(0,20,-5,PURPUR_BLOCK)
Block(0,20,-4,PURPUR_BLOCK)
Block(0,20,-3,PURPUR_BLOCK)
Block(0,20,-2,PURPUR_BLOCK)
Block(0,20,-1,PURPUR_BLOCK)
Block(0,20,0,PURPUR_BLOCK)
Block(0,20,1,PURPUR_BLOCK)
Block(0,20,2,PURPUR_BLOCK)
Block(0,20,3,PURPUR_BLOCK)
Block(0,20,4,PURPUR_BLOCK)
Block(0,20,5,PURPUR_BLOCK)
Block(0,20,6,PURPUR_BLOCK)
Block(0,20,7,PURPUR_BLOCK)
Block(0,20,8,PURPUR_STAIRS:7)
Block(1,0,-6,PURPUR_STAIRS:2)
Block(1,0,-5,PURPUR_BLOCK)
Block(1,0,-4,PURPUR_BLOCK)
Block(1,0,-3,PURPUR_BLOCK)
Block(1,0,-2,PURPUR_BLOCK)
Block(1,0,-1,PURPUR_BLOCK)
Block(1,0,0,PURPUR_BLOCK)
Block(1,0,1,PURPUR_BLOCK)
Block(1,0,2,PURPUR_BLOCK)
Block(1,0,3,PURPUR_BLOCK)
Block(1,0,4,PURPUR_BLOCK)
Block(1,0,5,PURPUR_BLOCK)
Block(1,0,6,PURPUR_STAIRS:0)
Block(1,3,-5,PURPUR_SLAB:8)
Block(1,3,5,PURPUR_SLAB:8)
Block(1,4,-5,PURPUR_BLOCK)
Block(1,4,4,PURPUR_SLAB)
Block(1,4,5,PURPUR_BLOCK)
Block(1,5,-5,PURPUR_PILLAR:0)
Block(1,5,-4,PURPUR_SLAB)
Block(1,5,5,PURPUR_PILLAR:0)
Block(1,6,-5,PURPUR_PILLAR:0)
Block(1,6,5,PURPUR_PILLAR:0)
Block(1,7,-5,PURPUR_PILLAR:0)
Block(1,7,5,PURPUR_BLOCK)
Block(1,8,-5,PURPUR_BLOCK)
Block(1,8,5,PURPUR_BLOCK)
Block(1,8,6,PURPUR_STAIRS:0)
Block(1,9,-5,PURPUR_PILLAR:0)
Block(1,10,-5,PURPUR_PILLAR:0)
Block(1,11,-5,PURPUR_PILLAR:0)
Block(1,11,5,PURPUR_SLAB:8)
Block(1,12,-5,PURPUR_BLOCK)
Block(1,12,4,PURPUR_SLAB)
Block(1,12,5,PURPUR_BLOCK)
Block(1,13,-5,PURPUR_PILLAR:0)
Block(1,13,-4,PURPUR_SLAB)
Block(1,13,5,PURPUR_PILLAR:0)
Block(1,14,-5,PURPUR_PILLAR:0)
Block(1,14,5,PURPUR_PILLAR:0)
Block(1,15,-5,PURPUR_PILLAR:0)
Block(1,15,5,PURPUR_BLOCK)
Block(1,16,-7,PURPUR_STAIRS:2)
Block(1,16,-6,PURPUR_BLOCK)
Block(1,16,-5,PURPUR_BLOCK)
Block(1,16,1,PURPUR_BLOCK)
Block(1,16,2,PURPUR_BLOCK)
Block(1,16,3,PURPUR_BLOCK)
Block(1,16,4,PURPUR_BLOCK)
Block(1,16,5,PURPUR_BLOCK)
Block(1,16,6,PURPUR_BLOCK)
Block(1,16,7,PURPUR_STAIRS:0)
Block(1,17,-6,END_BRICKS)
Block(1,17,1,PURPUR_PILLAR:0)
Block(1,17,6,END_BRICKS)
Block(1,18,-6,STAINED_GLASS:2)
Block(1,18,1,PURPUR_PILLAR:0)
Block(1,18,6,STAINED_GLASS:2)
Block(1,19,-6,STAINED_GLASS:2)
Block(1,19,1,PURPUR_PILLAR:0)
Block(1,19,6,STAINED_GLASS:2)
Block(1,20,-8,PURPUR_STAIRS:2)
Block(1,20,-7,PURPUR_BLOCK)
Block(1,20,-6,PURPUR_BLOCK)
Block(1,20,-5,PURPUR_BLOCK)
Block(1,20,-4,PURPUR_BLOCK)
Block(1,20,-3,PURPUR_BLOCK)
Block(1,20,-2,PURPUR_BLOCK)
Block(1,20,-1,PURPUR_BLOCK)
Block(1,20,0,PURPUR_BLOCK)
Block(1,20,1,PURPUR_BLOCK)
Block(1,20,2,PURPUR_BLOCK)
Block(1,20,3,PURPUR_BLOCK)
Block(1,20,4,PURPUR_BLOCK)
Block(1,20,5,PURPUR_BLOCK)
Block(1,20,6,PURPUR_BLOCK)
Block(1,20,7,PURPUR_BLOCK)
Block(1,20,8,PURPUR_STAIRS:0)
Block(2,0,-6,PURPUR_BLOCK)
Block(2,0,-5,PURPUR_BLOCK)
Block(2,0,-4,PURPUR_BLOCK)
Block(2,0,-3,PURPUR_BLOCK)
Block(2,0,-2,PURPUR_BLOCK)
Block(2,0,-1,PURPUR_BLOCK)
Block(2,0,0,PURPUR_BLOCK)
Block(2,0,1,PURPUR_BLOCK)
Block(2,0,2,PURPUR_BLOCK)
Block(2,0,3,PURPUR_BLOCK)
Block(2,0,4,PURPUR_BLOCK)
Block(2,0,5,PURPUR_BLOCK)
Block(2,0,6,PURPUR_BLOCK)
Block(2,1,-6,PURPUR_BLOCK)
Block(2,1,-5,PURPUR_BLOCK)
Block(2,1,-4,PURPUR_PILLAR:0)
Block(2,1,4,PURPUR_PILLAR:0)
Block(2,1,5,PURPUR_BLOCK)
Block(2,1,6,PURPUR_BLOCK)
Block(2,2,-6,END_ROD)
Block(2,2,-5,PURPUR_BLOCK)
Block(2,2,-4,PURPUR_PILLAR:0)
Block(2,2,4,PURPUR_PILLAR:0)
Block(2,2,5,PURPUR_BLOCK)
Block(2,2,6,END_ROD)
Block(2,3,-5,PURPUR_BLOCK)
Block(2,3,-4,PURPUR_PILLAR:0)
Block(2,3,3,END_ROD:2)
Block(2,3,4,PURPUR_PILLAR:0)
Block(2,3,5,PURPUR_BLOCK)
Block(2,4,-5,PURPUR_SLAB)
Block(2,4,-4,PURPUR_BLOCK)
Block(2,4,4,PURPUR_BLOCK)
Block(2,4,5,PURPUR_SLAB)
Block(2,5,-4,PURPUR_PILLAR:0)
Block(2,5,4,PURPUR_PILLAR:0)
Block(2,6,-4,PURPUR_PILLAR:0)
Block(2,6,-3,END_ROD:3)
Block(2,6,4,PURPUR_PILLAR:0)
Block(2,7,-4,PURPUR_PILLAR:0)
Block(2,7,4,PURPUR_PILLAR:0)
Block(2,8,-4,PURPUR_BLOCK)
Block(2,8,4,PURPUR_BLOCK)
Block(2,8,5,PURPUR_BLOCK)
Block(2,8,6,PURPUR_BLOCK)
Block(2,9,-4,PURPUR_PILLAR:0)
Block(2,9,4,PURPUR_PILLAR:0)
Block(2,9,5,PURPUR_BLOCK)
Block(2,9,6,PURPUR_BLOCK)
Block(2,10,-4,PURPUR_PILLAR:0)
Block(2,10,4,PURPUR_PILLAR:0)
Block(2,10,5,PURPUR_BLOCK)
Block(2,10,6,END_ROD)
Block(2,11,-4,PURPUR_PILLAR:0)
Block(2,11,3,END_ROD:2)
Block(2,11,4,PURPUR_PILLAR:0)
Block(2,11,5,PURPUR_BLOCK)
Block(2,12,-4,PURPUR_BLOCK)
Block(2,12,4,PURPUR_BLOCK)
Block(2,12,5,PURPUR_SLAB)
Block(2,13,-4,PURPUR_PILLAR:0)
Block(2,13,4,PURPUR_PILLAR:0)
Block(2,14,-4,PURPUR_PILLAR:0)
Block(2,14,-3,END_ROD:3)
Block(2,14,4,PURPUR_PILLAR:0)
Block(2,15,-4,PURPUR_PILLAR:0)
Block(2,15,4,PURPUR_PILLAR:0)
Block(2,16,-7,PURPUR_STAIRS:6)
Block(2,16,-6,PURPUR_BLOCK)
Block(2,16,-5,PURPUR_BLOCK)
Block(2,16,-4,PURPUR_BLOCK)
Block(2,16,1,PURPUR_BLOCK)
Block(2,16,2,PURPUR_BLOCK)
Block(2,16,3,PURPUR_BLOCK)
Block(2,16,4,PURPUR_BLOCK)
Block(2,16,5,PURPUR_BLOCK)
Block(2,16,6,PURPUR_BLOCK)
Block(2,16,7,PURPUR_STAIRS:7)
Block(2,17,-6,END_BRICKS)
Block(2,17,6,END_BRICKS)
Block(2,18,-6,END_BRICKS)
Block(2,18,6,END_BRICKS)
Block(2,19,-6,END_BRICKS)
Block(2,19,6,END_BRICKS)
Block(2,20,-8,PURPUR_STAIRS:2)
Block(2,20,-7,PURPUR_BLOCK)
Block(2,20,-6,PURPUR_BLOCK)
Block(2,20,-5,PURPUR_BLOCK)
Block(2,20,-4,PURPUR_BLOCK)
Block(2,20,-3,PURPUR_BLOCK)
Block(2,20,-2,PURPUR_BLOCK)
Block(2,20,-1,PURPUR_BLOCK)
Block(2,20,0,PURPUR_BLOCK)
Block(2,20,1,PURPUR_BLOCK)
Block(2,20,2,PURPUR_BLOCK)
Block(2,20,3,PURPUR_BLOCK)
Block(2,20,4,PURPUR_BLOCK)
Block(2,20,5,PURPUR_BLOCK)
Block(2,20,6,PURPUR_BLOCK)
Block(2,20,7,PURPUR_BLOCK)
Block(2,20,8,PURPUR_STAIRS:0)
Block(3,0,-4,PURPUR_BLOCK)
Block(3,0,-3,PURPUR_BLOCK)
Block(3,0,-2,PURPUR_BLOCK)
Block(3,0,-1,PURPUR_BLOCK)
Block(3,0,0,PURPUR_BLOCK)
Block(3,0,1,PURPUR_BLOCK)
Block(3,0,2,PURPUR_BLOCK)
Block(3,0,3,PURPUR_BLOCK)
Block(3,0,4,PURPUR_BLOCK)
Block(3,1,-4,PURPUR_PILLAR:0)
Block(3,1,4,PURPUR_PILLAR:0)
Block(3,2,-4,PURPUR_PILLAR:0)
Block(3,2,2,END_ROD:4)
Block(3,2,4,PURPUR_PILLAR:0)
Block(3,3,-4,PURPUR_PILLAR:0)
Block(3,3,4,PURPUR_PILLAR:0)
Block(3,4,-4,PURPUR_BLOCK)
Block(3,4,4,PURPUR_BLOCK)
Block(3,5,-4,PURPUR_PILLAR:0)
Block(3,5,4,PURPUR_PILLAR:0)
Block(3,6,-4,PURPUR_PILLAR:0)
Block(3,6,4,PURPUR_PILLAR:0)
Block(3,7,-4,PURPUR_PILLAR:0)
Block(3,7,-2,END_ROD:4)
Block(3,7,4,PURPUR_PILLAR:0)
Block(3,8,-4,PURPUR_BLOCK)
Block(3,8,4,PURPUR_BLOCK)
Block(3,9,-4,PURPUR_PILLAR:0)
Block(3,9,4,PURPUR_PILLAR:0)
Block(3,10,-4,PURPUR_PILLAR:0)
Block(3,10,2,END_ROD:4)
Block(3,10,4,PURPUR_PILLAR:0)
Block(3,11,-4,PURPUR_PILLAR:0)
Block(3,11,4,PURPUR_PILLAR:0)
Block(3,12,-4,PURPUR_BLOCK)
Block(3,12,4,PURPUR_BLOCK)
Block(3,13,-4,PURPUR_PILLAR:0)
Block(3,13,4,PURPUR_PILLAR:0)
Block(3,14,-4,PURPUR_PILLAR:0)
Block(3,14,4,PURPUR_PILLAR:0)
Block(3,15,-4,PURPUR_PILLAR:0)
Block(3,15,-2,END_ROD:4)
Block(3,15,4,PURPUR_PILLAR:0)
Block(3,16,-7,PURPUR_STAIRS:6)
Block(3,16,-6,PURPUR_BLOCK)
Block(3,16,-5,PURPUR_BLOCK)
Block(3,16,-4,PURPUR_BLOCK)
Block(3,16,1,PURPUR_BLOCK)
Block(3,16,2,PURPUR_BLOCK)
Block(3,16,3,PURPUR_BLOCK)
Block(3,16,4,PURPUR_BLOCK)
Block(3,16,5,PURPUR_BLOCK)
Block(3,16,6,PURPUR_BLOCK)
Block(3,16,7,PURPUR_STAIRS:7)
Block(3,17,-6,END_BRICKS)
Block(3,17,6,END_BRICKS)
Block(3,18,-6,END_BRICKS)
Block(3,18,6,END_BRICKS)
Block(3,19,-6,END_BRICKS)
Block(3,19,6,END_BRICKS)
Block(3,20,-8,PURPUR_STAIRS:6)
Block(3,20,-7,PURPUR_BLOCK)
Block(3,20,-6,PURPUR_BLOCK)
Block(3,20,-5,PURPUR_BLOCK)
Block(3,20,-4,PURPUR_BLOCK)
Block(3,20,-3,PURPUR_BLOCK)
Block(3,20,-2,PURPUR_BLOCK)
Block(3,20,-1,PURPUR_BLOCK)
Block(3,20,0,PURPUR_BLOCK)
Block(3,20,1,PURPUR_BLOCK)
Block(3,20,2,PURPUR_BLOCK)
Block(3,20,3,PURPUR_BLOCK)
Block(3,20,4,PURPUR_BLOCK)
Block(3,20,5,PURPUR_BLOCK)
Block(3,20,6,PURPUR_BLOCK)
Block(3,20,7,PURPUR_BLOCK)
Block(3,20,8,PURPUR_STAIRS:7)
Block(4,0,-3,PURPUR_BLOCK)
Block(4,0,-2,PURPUR_BLOCK)
Block(4,0,-1,PURPUR_BLOCK)
Block(4,0,0,PURPUR_BLOCK)
Block(4,0,1,PURPUR_BLOCK)
Block(4,0,2,PURPUR_BLOCK)
Block(4,0,3,PURPUR_BLOCK)
Block(4,1,-3,PURPUR_PILLAR:0)
Block(4,1,-2,PURPUR_PILLAR:0)
Block(4,1,1,PURPUR_SLAB)
Block(4,1,2,PURPUR_PILLAR:0)
Block(4,1,3,PURPUR_PILLAR:0)
Block(4,2,-3,PURPUR_PILLAR:0)
Block(4,2,-2,PURPUR_PILLAR:0)
Block(4,2,2,PURPUR_PILLAR:0)
Block(4,2,3,PURPUR_PILLAR:0)
Block(4,3,-3,PURPUR_PILLAR:0)
Block(4,3,-2,PURPUR_PILLAR:0)
Block(4,3,2,PURPUR_PILLAR:0)
Block(4,3,3,PURPUR_PILLAR:0)
Block(4,4,-3,PURPUR_BLOCK)
Block(4,4,-2,PURPUR_BLOCK)
Block(4,4,2,PURPUR_BLOCK)
Block(4,4,3,PURPUR_BLOCK)
Block(4,5,-3,PURPUR_PILLAR:0)
Block(4,5,-2,PURPUR_PILLAR:0)
Block(4,5,2,PURPUR_PILLAR:0)
Block(4,5,3,PURPUR_PILLAR:0)
Block(4,6,-3,PURPUR_PILLAR:0)
Block(4,6,-2,PURPUR_PILLAR:0)
Block(4,6,2,PURPUR_PILLAR:0)
Block(4,6,3,PURPUR_PILLAR:0)
Block(4,7,-3,PURPUR_PILLAR:0)
Block(4,7,-2,PURPUR_PILLAR:0)
Block(4,7,2,PURPUR_PILLAR:0)
Block(4,7,3,PURPUR_PILLAR:0)
Block(4,8,-3,PURPUR_BLOCK)
Block(4,8,-2,PURPUR_BLOCK)
Block(4,8,-1,PURPUR_SLAB)
Block(4,8,2,PURPUR_BLOCK)
Block(4,8,3,PURPUR_BLOCK)
Block(4,9,-3,PURPUR_PILLAR:0)
Block(4,9,-2,PURPUR_PILLAR:0)
Block(4,9,1,PURPUR_SLAB)
Block(4,9,2,PURPUR_PILLAR:0)
Block(4,9,3,PURPUR_PILLAR:0)
Block(4,10,-3,PURPUR_PILLAR:0)
Block(4,10,-2,PURPUR_PILLAR:0)
Block(4,10,2,PURPUR_PILLAR:0)
Block(4,10,3,PURPUR_PILLAR:0)
Block(4,11,-3,PURPUR_PILLAR:0)
Block(4,11,-2,PURPUR_PILLAR:0)
Block(4,11,2,PURPUR_PILLAR:0)
Block(4,11,3,PURPUR_PILLAR:0)
Block(4,12,-3,PURPUR_BLOCK)
Block(4,12,-2,PURPUR_BLOCK)
Block(4,12,2,PURPUR_BLOCK)
Block(4,12,3,PURPUR_BLOCK)
Block(4,13,-3,PURPUR_PILLAR:0)
Block(4,13,-2,PURPUR_PILLAR:0)
Block(4,13,2,PURPUR_PILLAR:0)
Block(4,13,3,PURPUR_PILLAR:0)
Block(4,14,-3,PURPUR_PILLAR:0)
Block(4,14,-2,PURPUR_PILLAR:0)
Block(4,14,2,PURPUR_PILLAR:0)
Block(4,14,3,PURPUR_PILLAR:0)
Block(4,15,-3,PURPUR_PILLAR:0)
Block(4,15,-2,PURPUR_PILLAR:0)
Block(4,15,2,PURPUR_PILLAR:0)
Block(4,15,3,PURPUR_PILLAR:0)
Block(4,16,-7,PURPUR_STAIRS:2)
Block(4,16,-6,PURPUR_BLOCK)
Block(4,16,-5,PURPUR_BLOCK)
Block(4,16,-4,PURPUR_BLOCK)
Block(4,16,-3,PURPUR_BLOCK)
Block(4,16,-2,PURPUR_BLOCK)
Block(4,16,-1,PURPUR_SLAB)
Block(4,16,1,PURPUR_BLOCK)
Block(4,16,2,PURPUR_BLOCK)
Block(4,16,3,PURPUR_BLOCK)
Block(4,16,4,PURPUR_BLOCK)
Block(4,16,5,PURPUR_BLOCK)
Block(4,16,6,PURPUR_BLOCK)
Block(4,16,7,PURPUR_STAIRS:0)
Block(4,17,-6,END_BRICKS)
Block(4,17,6,END_BRICKS)
Block(4,18,-6,STAINED_GLASS:2)
Block(4,18,6,STAINED_GLASS:2)
Block(4,19,-6,STAINED_GLASS:2)
Block(4,19,6,STAINED_GLASS:2)
Block(4,20,-8,PURPUR_STAIRS:6)
Block(4,20,-7,PURPUR_BLOCK)
Block(4,20,-6,PURPUR_BLOCK)
Block(4,20,-5,PURPUR_BLOCK)
Block(4,20,-4,PURPUR_BLOCK)
Block(4,20,-3,PURPUR_BLOCK)
Block(4,20,-2,PURPUR_BLOCK)
Block(4,20,-1,PURPUR_BLOCK)
Block(4,20,0,PURPUR_BLOCK)
Block(4,20,1,PURPUR_BLOCK)
Block(4,20,2,PURPUR_BLOCK)
Block(4,20,3,PURPUR_BLOCK)
Block(4,20,4,PURPUR_BLOCK)
Block(4,20,5,PURPUR_BLOCK)
Block(4,20,6,PURPUR_BLOCK)
Block(4,20,7,PURPUR_BLOCK)
Block(4,20,8,PURPUR_STAIRS:7)
Block(5,0,-1,PURPUR_BLOCK)
Block(5,0,0,PURPUR_BLOCK)
Block(5,0,1,PURPUR_BLOCK)
Block(5,1,-1,PURPUR_PILLAR:0)
Block(5,1,0,PURPUR_PILLAR:0)
Block(5,1,1,PURPUR_PILLAR:0)
Block(5,2,-1,PURPUR_PILLAR:0)
Block(5,2,0,PURPUR_PILLAR)
Block(5,2,1,PURPUR_PILLAR:0)
Block(5,3,-1,PURPUR_PILLAR:0)
Block(5,3,0,PURPUR_PILLAR:0)
Block(5,3,1,PURPUR_PILLAR:0)
Block(5,4,-1,PURPUR_BLOCK)
Block(5,4,0,PURPUR_BLOCK)
Block(5,4,1,PURPUR_BLOCK)
Block(5,5,-1,PURPUR_PILLAR:0)
Block(5,5,0,PURPUR_PILLAR:0)
Block(5,5,1,PURPUR_PILLAR:0)
Block(5,6,-1,PURPUR_PILLAR:0)
Block(5,6,0,PURPUR_PILLAR)
Block(5,6,1,PURPUR_PILLAR:0)
Block(5,7,-1,PURPUR_PILLAR:0)
Block(5,7,0,PURPUR_PILLAR:0)
Block(5,7,1,PURPUR_PILLAR:0)
Block(5,8,-1,PURPUR_BLOCK)
Block(5,8,0,PURPUR_BLOCK)
Block(5,8,1,PURPUR_BLOCK)
Block(5,9,-1,PURPUR_PILLAR:0)
Block(5,9,0,PURPUR_PILLAR:0)
Block(5,9,1,PURPUR_PILLAR:0)
Block(5,10,-1,PURPUR_PILLAR:0)
Block(5,10,0,PURPUR_PILLAR)
Block(5,10,1,PURPUR_PILLAR:0)
Block(5,11,-1,PURPUR_PILLAR:0)
Block(5,11,0,PURPUR_PILLAR:0)
Block(5,11,1,PURPUR_PILLAR:0)
Block(5,12,-1,PURPUR_BLOCK)
Block(5,12,0,PURPUR_BLOCK)
Block(5,12,1,PURPUR_BLOCK)
Block(5,13,-1,PURPUR_PILLAR:0)
Block(5,13,0,PURPUR_PILLAR:0)
Block(5,13,1,PURPUR_PILLAR:0)
Block(5,14,-1,PURPUR_PILLAR:0)
Block(5,14,0,PURPUR_PILLAR)
Block(5,14,1,PURPUR_PILLAR:0)
Block(5,15,-1,PURPUR_PILLAR:0)
Block(5,15,0,PURPUR_PILLAR:0)
Block(5,15,1,PURPUR_PILLAR:0)
Block(5,16,-7,PURPUR_STAIRS:2)
Block(5,16,-6,PURPUR_BLOCK)
Block(5,16,-5,PURPUR_BLOCK)
Block(5,16,-4,PURPUR_BLOCK)
Block(5,16,-3,PURPUR_BLOCK)
Block(5,16,-2,PURPUR_BLOCK)
Block(5,16,-1,PURPUR_BLOCK)
Block(5,16,0,PURPUR_BLOCK)
Block(5,16,1,PURPUR_BLOCK)
Block(5,16,2,PURPUR_BLOCK)
Block(5,16,3,PURPUR_BLOCK)
Block(5,16,4,PURPUR_BLOCK)
Block(5,16,5,PURPUR_BLOCK)
Block(5,16,6,PURPUR_BLOCK)
Block(5,16,7,PURPUR_STAIRS:0)
Block(5,17,-6,END_BRICKS)
Block(5,17,6,END_BRICKS)
Block(5,18,-6,END_BRICKS)
Block(5,18,6,END_BRICKS)
Block(5,19,-6,END_BRICKS)
Block(5,19,6,END_BRICKS)
Block(5,20,-8,PURPUR_STAIRS:2)
Block(5,20,-7,PURPUR_BLOCK)
Block(5,20,-6,PURPUR_BLOCK)
Block(5,20,-5,PURPUR_BLOCK)
Block(5,20,-4,PURPUR_BLOCK)
Block(5,20,-3,PURPUR_BLOCK)
Block(5,20,-2,PURPUR_BLOCK)
Block(5,20,-1,PURPUR_BLOCK)
Block(5,20,0,PURPUR_BLOCK)
Block(5,20,1,PURPUR_BLOCK)
Block(5,20,2,PURPUR_BLOCK)
Block(5,20,3,PURPUR_BLOCK)
Block(5,20,4,PURPUR_BLOCK)
Block(5,20,5,PURPUR_BLOCK)
Block(5,20,6,PURPUR_BLOCK)
Block(5,20,7,PURPUR_BLOCK)
Block(5,20,8,PURPUR_STAIRS:0)
Block(6,2,0,PURPUR_STAIRS:5)
Block(6,6,0,PURPUR_STAIRS:5)
Block(6,10,0,PURPUR_STAIRS:5)
Block(6,14,0,PURPUR_STAIRS:5)
Block(6,16,-7,PURPUR_STAIRS:6)
Block(6,16,-6,PURPUR_BLOCK)
Block(6,16,-5,PURPUR_BLOCK)
Block(6,16,-4,PURPUR_BLOCK)
Block(6,16,-3,PURPUR_BLOCK)
Block(6,16,-2,PURPUR_BLOCK)
Block(6,16,-1,PURPUR_BLOCK)
Block(6,16,0,PURPUR_BLOCK)
Block(6,16,1,PURPUR_BLOCK)
Block(6,16,2,PURPUR_BLOCK)
Block(6,16,3,PURPUR_BLOCK)
Block(6,16,4,PURPUR_BLOCK)
Block(6,16,5,PURPUR_BLOCK)
Block(6,16,6,PURPUR_BLOCK)
Block(6,16,7,PURPUR_STAIRS:7)
Block(6,17,-6,PURPUR_PILLAR:0)
Block(6,17,-5,END_BRICKS)
Block(6,17,-4,END_BRICKS)
Block(6,17,-3,END_BRICKS)
Block(6,17,-2,END_BRICKS)
Block(6,17,-1,END_BRICKS)
Block(6,17,0,END_BRICKS)
Block(6,17,1,END_BRICKS)
Block(6,17,2,END_BRICKS)
Block(6,17,3,END_BRICKS)
Block(6,17,4,END_BRICKS)
Block(6,17,5,END_BRICKS)
Block(6,17,6,PURPUR_PILLAR:0)
Block(6,18,-6,PURPUR_PILLAR:0)
Block(6,18,-5,END_BRICKS)
Block(6,18,-4,STAINED_GLASS:2)
Block(6,18,-3,END_BRICKS)
Block(6,18,-2,END_BRICKS)
Block(6,18,-1,STAINED_GLASS:2)
Block(6,18,0,END_BRICKS)
Block(6,18,1,STAINED_GLASS:2)
Block(6,18,2,END_BRICKS)
Block(6,18,3,END_BRICKS)
Block(6,18,4,STAINED_GLASS:2)
Block(6,18,5,END_BRICKS)
Block(6,18,6,PURPUR_PILLAR:0)
Block(6,19,-6,PURPUR_PILLAR:0)
Block(6,19,-5,END_BRICKS)
Block(6,19,-4,STAINED_GLASS:2)
Block(6,19,-3,END_BRICKS)
Block(6,19,-2,END_BRICKS)
Block(6,19,-1,STAINED_GLASS:2)
Block(6,19,0,END_BRICKS)
Block(6,19,1,STAINED_GLASS:2)
Block(6,19,2,END_BRICKS)
Block(6,19,3,END_BRICKS)
Block(6,19,4,STAINED_GLASS:2)
Block(6,19,5,END_BRICKS)
Block(6,19,6,PURPUR_PILLAR:0)
Block(6,20,-8,PURPUR_STAIRS:2)
Block(6,20,-7,PURPUR_BLOCK)
Block(6,20,-6,PURPUR_BLOCK)
Block(6,20,-5,PURPUR_BLOCK)
Block(6,20,-4,PURPUR_BLOCK)
Block(6,20,-3,PURPUR_BLOCK)
Block(6,20,-2,PURPUR_BLOCK)
Block(6,20,-1,PURPUR_BLOCK)
Block(6,20,0,PURPUR_BLOCK)
Block(6,20,1,PURPUR_BLOCK)
Block(6,20,2,PURPUR_BLOCK)
Block(6,20,3,PURPUR_BLOCK)
Block(6,20,4,PURPUR_BLOCK)
Block(6,20,5,PURPUR_BLOCK)
Block(6,20,6,PURPUR_BLOCK)
Block(6,20,7,PURPUR_BLOCK)
Block(6,20,8,PURPUR_STAIRS:0)
Block(7,16,-7,PURPUR_STAIRS:6)
Block(7,16,-6,PURPUR_STAIRS:5)
Block(7,16,-5,PURPUR_STAIRS:1)
Block(7,16,-4,PURPUR_STAIRS:1)
Block(7,16,-3,PURPUR_STAIRS:5)
Block(7,16,-2,PURPUR_STAIRS:5)
Block(7,16,-1,PURPUR_STAIRS:1)
Block(7,16,0,PURPUR_STAIRS:1)
Block(7,16,1,PURPUR_STAIRS:1)
Block(7,16,2,PURPUR_STAIRS:5)
Block(7,16,3,PURPUR_STAIRS:5)
Block(7,16,4,PURPUR_STAIRS:1)
Block(7,16,5,PURPUR_STAIRS:1)
Block(7,16,6,PURPUR_STAIRS:5)
Block(7,16,7,PURPUR_STAIRS:5)
Block(7,17,-7,END_ROD)
Block(7,17,7,END_ROD)
Block(7,20,-8,PURPUR_STAIRS:6)
Block(7,20,-7,PURPUR_BLOCK)
Block(7,20,-6,PURPUR_BLOCK)
Block(7,20,-5,PURPUR_BLOCK)
Block(7,20,-4,PURPUR_BLOCK)
Block(7,20,-3,PURPUR_BLOCK)
Block(7,20,-2,PURPUR_BLOCK)
Block(7,20,-1,PURPUR_BLOCK)
Block(7,20,0,PURPUR_BLOCK)
Block(7,20,1,PURPUR_BLOCK)
Block(7,20,2,PURPUR_BLOCK)
Block(7,20,3,PURPUR_BLOCK)
Block(7,20,4,PURPUR_BLOCK)
Block(7,20,5,PURPUR_BLOCK)
Block(7,20,6,PURPUR_BLOCK)
Block(7,20,7,PURPUR_BLOCK)
Block(7,20,8,PURPUR_STAIRS:7)
Block(8,20,-8,PURPUR_STAIRS:6)
Block(8,20,-7,PURPUR_STAIRS:5)
Block(8,20,-6,PURPUR_STAIRS:1)
Block(8,20,-5,PURPUR_STAIRS:1)
Block(8,20,-4,PURPUR_STAIRS:5)
Block(8,20,-3,PURPUR_STAIRS:5)
Block(8,20,-2,PURPUR_STAIRS:1)
Block(8,20,-1,PURPUR_STAIRS:1)
Block(8,20,0,PURPUR_STAIRS:5)
Block(8,20,1,PURPUR_STAIRS:1)
Block(8,20,2,PURPUR_STAIRS:1)
Block(8,20,3,PURPUR_STAIRS:5)
Block(8,20,4,PURPUR_STAIRS:5)
Block(8,20,5,PURPUR_STAIRS:1)
Block(8,20,6,PURPUR_STAIRS:1)
Block(8,20,7,PURPUR_STAIRS:5)
Block(8,20,8,PURPUR_STAIRS:5)

#######################################################################
# +-----------------------------------------------------------------+ #
# |                            BO3 checks                           | #
# +-----------------------------------------------------------------+ #
#######################################################################


#######################################################################
# +-----------------------------------------------------------------+ #
# |                             Branches                            | #
# +-----------------------------------------------------------------+ #
#######################################################################


#######################################################################
# +-----------------------------------------------------------------+ #
# |                             Entities                            | #
# +-----------------------------------------------------------------+ #
#######################################################################

Entity(-5,9,0,SHULKER,1)
Entity(-4,6,0,SHULKER,1)
Entity(-4,14,0,SHULKER,1)
Entity(-4,17,-5,SHULKER,1)
Entity(-3,21,-5,SHULKER,1)
Entity(3,17,3,SHULKER,1)
Entity(4,6,0,SHULKER,1)
Entity(4,14,0,SHULKER,1)

#######################################################################
# +-----------------------------------------------------------------+ #
# |                            Particles                            | #
# +-----------------------------------------------------------------+ #
#######################################################################


#######################################################################
# +-----------------------------------------------------------------+ #
# |                             Spawners                            | #
# +-----------------------------------------------------------------+ #
#######################################################################


#######################################################################
# +-----------------------------------------------------------------+ #
# |                             ModData                             | #
# +-----------------------------------------------------------------+ #
#######################################################################

