
#######################################################################
# +-----------------------------------------------------------------+ #
# |                            BO3 object                           | #
# +-----------------------------------------------------------------+ #
#######################################################################

Author: totemo

Description: No description given

Version: 3

SettingsMode: WriteWithoutComments


#######################################################################
# +-----------------------------------------------------------------+ #
# |                          Main settings                          | #
# +-----------------------------------------------------------------+ #
#######################################################################

Tree: false

Frequency: 0

Rarity: 100.0

RotateRandomly: true

SpawnHeight: highestBlock

SpawnHeightOffset: 0

SpawnHeightVariance: 0

##############################
# Height Limits for the BO3. #
##############################

MinHeight: 0

MaxHeight: 256

######################
# Extrusion settings #
######################

ExtrudeMode: None

ExtrudeThroughBlocks: AIR

MaxBranchDepth: 10

ExcludedBiomes: All


#######################################################################
# +-----------------------------------------------------------------+ #
# |                      Source block settings                      | #
# +-----------------------------------------------------------------+ #
#######################################################################

SourceBlocks: AIR

MaxPercentageOutsideSourceBlock: 10

OutsideSourceBlock: placeAnyway

IsOTGPlus: false


#######################################################################
# +-----------------------------------------------------------------+ #
# |                              Blocks                             | #
# +-----------------------------------------------------------------+ #
#######################################################################

Block(-9,28,-10,PURPUR_STAIRS:4)
Block(-9,28,-9,PURPUR_STAIRS:4)
Block(-9,28,-8,PURPUR_STAIRS:0)
Block(-9,28,-7,PURPUR_STAIRS:0)
Block(-9,28,-6,PURPUR_STAIRS:4)
Block(-9,28,-5,PURPUR_STAIRS:4)
Block(-9,28,-4,PURPUR_STAIRS:0)
Block(-9,28,-3,PURPUR_STAIRS:0)
Block(-9,28,-2,PURPUR_STAIRS:4)
Block(-9,28,-1,PURPUR_STAIRS:0)
Block(-9,28,0,PURPUR_STAIRS:0)
Block(-9,28,1,PURPUR_STAIRS:4)
Block(-9,28,2,PURPUR_STAIRS:4)
Block(-9,28,3,PURPUR_STAIRS:0)
Block(-9,28,4,PURPUR_STAIRS:0)
Block(-9,28,5,PURPUR_STAIRS:4)
Block(-9,28,6,PURPUR_STAIRS:7)
Block(-8,24,-9,PURPUR_STAIRS:4)
Block(-8,24,-8,PURPUR_STAIRS:4)
Block(-8,24,-7,PURPUR_STAIRS:0)
Block(-8,24,-6,PURPUR_STAIRS:0)
Block(-8,24,-5,PURPUR_STAIRS:4)
Block(-8,24,-4,PURPUR_STAIRS:4)
Block(-8,24,-3,PURPUR_STAIRS:0)
Block(-8,24,-2,PURPUR_STAIRS:0)
Block(-8,24,-1,PURPUR_STAIRS:0)
Block(-8,24,0,PURPUR_STAIRS:4)
Block(-8,24,1,PURPUR_STAIRS:4)
Block(-8,24,2,PURPUR_STAIRS:0)
Block(-8,24,3,PURPUR_STAIRS:0)
Block(-8,24,4,PURPUR_STAIRS:4)
Block(-8,24,5,PURPUR_STAIRS:7)
Block(-8,25,-9,END_ROD)
Block(-8,25,5,END_ROD)
Block(-8,28,-10,PURPUR_STAIRS:6)
Block(-8,28,-9,PURPUR_BLOCK)
Block(-8,28,-8,PURPUR_BLOCK)
Block(-8,28,-7,PURPUR_BLOCK)
Block(-8,28,-6,PURPUR_BLOCK)
Block(-8,28,-5,PURPUR_BLOCK)
Block(-8,28,-4,PURPUR_BLOCK)
Block(-8,28,-3,PURPUR_BLOCK)
Block(-8,28,-2,PURPUR_BLOCK)
Block(-8,28,-1,PURPUR_BLOCK)
Block(-8,28,0,PURPUR_BLOCK)
Block(-8,28,1,PURPUR_BLOCK)
Block(-8,28,2,PURPUR_BLOCK)
Block(-8,28,3,PURPUR_BLOCK)
Block(-8,28,4,PURPUR_BLOCK)
Block(-8,28,5,PURPUR_BLOCK)
Block(-8,28,6,PURPUR_STAIRS:7)
Block(-7,12,-8,PURPUR_STAIRS:4)
Block(-7,12,-7,PURPUR_STAIRS:4)
Block(-7,12,-6,PURPUR_STAIRS:0)
Block(-7,12,-5,PURPUR_STAIRS:0)
Block(-7,12,-4,PURPUR_STAIRS:4)
Block(-7,12,-3,PURPUR_STAIRS:4)
Block(-7,12,-2,PURPUR_STAIRS:0)
Block(-7,12,-1,PURPUR_STAIRS:4)
Block(-7,12,0,PURPUR_STAIRS:4)
Block(-7,12,1,PURPUR_STAIRS:0)
Block(-7,12,2,PURPUR_STAIRS:4)
Block(-7,12,3,PURPUR_STAIRS:4)
Block(-7,12,4,PURPUR_STAIRS:0)
Block(-7,12,5,PURPUR_STAIRS:0)
Block(-7,12,6,PURPUR_STAIRS:4)
Block(-7,12,7,PURPUR_STAIRS:4)
Block(-7,18,-2,PURPUR_STAIRS:4)
Block(-7,22,-2,PURPUR_STAIRS:4)
Block(-7,23,-2,PURPUR_PILLAR)
Block(-7,24,-9,PURPUR_STAIRS:6)
Block(-7,24,-8,PURPUR_BLOCK)
Block(-7,24,-7,PURPUR_BLOCK)
Block(-7,24,-6,PURPUR_BLOCK)
Block(-7,24,-5,PURPUR_BLOCK)
Block(-7,24,-4,PURPUR_BLOCK)
Block(-7,24,-3,PURPUR_BLOCK)
Block(-7,24,-2,PURPUR_BLOCK)
Block(-7,24,-1,PURPUR_BLOCK)
Block(-7,24,0,PURPUR_BLOCK)
Block(-7,24,1,PURPUR_BLOCK)
Block(-7,24,2,PURPUR_BLOCK)
Block(-7,24,3,PURPUR_BLOCK)
Block(-7,24,4,PURPUR_BLOCK)
Block(-7,24,5,PURPUR_STAIRS:7)
Block(-7,25,-8,PURPUR_PILLAR:0)
Block(-7,25,-7,END_BRICKS)
Block(-7,25,-6,END_BRICKS)
Block(-7,25,-5,END_BRICKS)
Block(-7,25,-4,END_BRICKS)
Block(-7,25,-3,END_BRICKS)
Block(-7,25,-2,END_BRICKS)
Block(-7,25,-1,END_BRICKS)
Block(-7,25,0,END_BRICKS)
Block(-7,25,1,END_BRICKS)
Block(-7,25,2,END_BRICKS)
Block(-7,25,3,END_BRICKS)
Block(-7,25,4,PURPUR_PILLAR:0)
Block(-7,26,-8,PURPUR_PILLAR:0)
Block(-7,26,-7,END_BRICKS)
Block(-7,26,-6,STAINED_GLASS:2)
Block(-7,26,-5,END_BRICKS)
Block(-7,26,-4,END_BRICKS)
Block(-7,26,-3,STAINED_GLASS:2)
Block(-7,26,-2,END_BRICKS)
Block(-7,26,-1,STAINED_GLASS:2)
Block(-7,26,0,END_BRICKS)
Block(-7,26,1,END_BRICKS)
Block(-7,26,2,STAINED_GLASS:2)
Block(-7,26,3,END_BRICKS)
Block(-7,26,4,PURPUR_PILLAR:0)
Block(-7,27,-8,PURPUR_PILLAR:0)
Block(-7,27,-7,END_BRICKS)
Block(-7,27,-6,STAINED_GLASS:2)
Block(-7,27,-5,END_BRICKS)
Block(-7,27,-4,END_BRICKS)
Block(-7,27,-3,STAINED_GLASS:2)
Block(-7,27,-2,END_BRICKS)
Block(-7,27,-1,STAINED_GLASS:2)
Block(-7,27,0,END_BRICKS)
Block(-7,27,1,END_BRICKS)
Block(-7,27,2,STAINED_GLASS:2)
Block(-7,27,3,END_BRICKS)
Block(-7,27,4,PURPUR_PILLAR:0)
Block(-7,28,-10,PURPUR_STAIRS:2)
Block(-7,28,-9,PURPUR_BLOCK)
Block(-7,28,-8,PURPUR_BLOCK)
Block(-7,28,-7,PURPUR_BLOCK)
Block(-7,28,-6,PURPUR_BLOCK)
Block(-7,28,-5,PURPUR_BLOCK)
Block(-7,28,-4,PURPUR_BLOCK)
Block(-7,28,-3,PURPUR_BLOCK)
Block(-7,28,-2,PURPUR_BLOCK)
Block(-7,28,-1,PURPUR_BLOCK)
Block(-7,28,0,PURPUR_BLOCK)
Block(-7,28,1,PURPUR_BLOCK)
Block(-7,28,2,PURPUR_BLOCK)
Block(-7,28,3,PURPUR_BLOCK)
Block(-7,28,4,PURPUR_BLOCK)
Block(-7,28,5,PURPUR_BLOCK)
Block(-7,28,6,PURPUR_STAIRS:0)
Block(-6,8,-7,PURPUR_STAIRS:4)
Block(-6,8,-6,PURPUR_STAIRS:4)
Block(-6,8,-5,PURPUR_STAIRS:0)
Block(-6,8,-4,PURPUR_STAIRS:0)
Block(-6,8,-3,PURPUR_STAIRS:4)
Block(-6,8,-2,PURPUR_STAIRS:4)
Block(-6,8,-1,PURPUR_STAIRS:0)
Block(-6,8,0,PURPUR_STAIRS:0)
Block(-6,8,1,PURPUR_STAIRS:4)
Block(-6,8,2,PURPUR_STAIRS:4)
Block(-6,8,3,PURPUR_STAIRS:0)
Block(-6,8,4,PURPUR_STAIRS:0)
Block(-6,8,5,PURPUR_STAIRS:4)
Block(-6,8,6,PURPUR_STAIRS:7)
Block(-6,9,-7,END_ROD)
Block(-6,9,6,END_ROD)
Block(-6,12,-8,PURPUR_STAIRS:6)
Block(-6,12,-7,PURPUR_BLOCK)
Block(-6,12,-6,PURPUR_BLOCK)
Block(-6,12,-5,PURPUR_BLOCK)
Block(-6,12,-4,PURPUR_BLOCK)
Block(-6,12,-3,PURPUR_BLOCK)
Block(-6,12,-2,PURPUR_BLOCK)
Block(-6,12,-1,PURPUR_BLOCK)
Block(-6,12,0,PURPUR_BLOCK)
Block(-6,12,1,PURPUR_BLOCK)
Block(-6,12,2,PURPUR_BLOCK)
Block(-6,12,3,PURPUR_BLOCK)
Block(-6,12,4,PURPUR_BLOCK)
Block(-6,12,5,PURPUR_BLOCK)
Block(-6,12,6,PURPUR_BLOCK)
Block(-6,12,7,PURPUR_STAIRS:7)
Block(-6,13,-7,END_ROD)
Block(-6,13,6,END_ROD)
Block(-6,16,-3,PURPUR_BLOCK)
Block(-6,16,-2,PURPUR_BLOCK)
Block(-6,16,-1,PURPUR_BLOCK)
Block(-6,17,-3,PURPUR_PILLAR:0)
Block(-6,17,-2,PURPUR_PILLAR:0)
Block(-6,17,-1,PURPUR_PILLAR:0)
Block(-6,18,-3,PURPUR_PILLAR:0)
Block(-6,18,-2,PURPUR_PILLAR)
Block(-6,18,-1,PURPUR_PILLAR:0)
Block(-6,19,-3,PURPUR_PILLAR:0)
Block(-6,19,-2,PURPUR_PILLAR:0)
Block(-6,19,-1,PURPUR_PILLAR:0)
Block(-6,20,-3,PURPUR_BLOCK)
Block(-6,20,-2,PURPUR_BLOCK)
Block(-6,20,-1,PURPUR_BLOCK)
Block(-6,21,-3,PURPUR_PILLAR:0)
Block(-6,21,-2,PURPUR_PILLAR:0)
Block(-6,21,-1,PURPUR_PILLAR:0)
Block(-6,22,-3,PURPUR_PILLAR:0)
Block(-6,22,-2,PURPUR_PILLAR)
Block(-6,22,-1,PURPUR_PILLAR:0)
Block(-6,23,-3,PURPUR_BLOCK)
Block(-6,23,-2,PURPUR_BLOCK)
Block(-6,23,-1,PURPUR_BLOCK)
Block(-6,24,-9,PURPUR_STAIRS:2)
Block(-6,24,-8,PURPUR_BLOCK)
Block(-6,24,-7,PURPUR_BLOCK)
Block(-6,24,-6,PURPUR_BLOCK)
Block(-6,24,-5,PURPUR_BLOCK)
Block(-6,24,-4,PURPUR_BLOCK)
Block(-6,24,-3,PURPUR_BLOCK)
Block(-6,24,-2,PURPUR_BLOCK)
Block(-6,24,-1,PURPUR_BLOCK)
Block(-6,24,0,PURPUR_BLOCK)
Block(-6,24,1,PURPUR_BLOCK)
Block(-6,24,2,PURPUR_BLOCK)
Block(-6,24,3,PURPUR_BLOCK)
Block(-6,24,4,PURPUR_BLOCK)
Block(-6,24,5,PURPUR_STAIRS:0)
Block(-6,25,-8,END_BRICKS)
Block(-6,25,3,CHEST,EndTowerC/1-chest.nbt)
Block(-6,25,4,END_BRICKS)
Block(-6,26,-8,END_BRICKS)
Block(-6,26,4,END_BRICKS)
Block(-6,27,-8,END_BRICKS)
Block(-6,27,4,END_BRICKS)
Block(-6,28,-10,PURPUR_STAIRS:2)
Block(-6,28,-9,PURPUR_BLOCK)
Block(-6,28,-8,PURPUR_BLOCK)
Block(-6,28,-7,PURPUR_BLOCK)
Block(-6,28,-6,PURPUR_BLOCK)
Block(-6,28,-5,PURPUR_BLOCK)
Block(-6,28,-4,PURPUR_BLOCK)
Block(-6,28,-3,PURPUR_BLOCK)
Block(-6,28,-2,PURPUR_BLOCK)
Block(-6,28,-1,PURPUR_BLOCK)
Block(-6,28,0,PURPUR_BLOCK)
Block(-6,28,1,PURPUR_BLOCK)
Block(-6,28,2,PURPUR_BLOCK)
Block(-6,28,3,PURPUR_BLOCK)
Block(-6,28,4,PURPUR_BLOCK)
Block(-6,28,5,PURPUR_BLOCK)
Block(-6,28,6,PURPUR_STAIRS:0)
Block(-5,4,-6,PURPUR_STAIRS:4)
Block(-5,4,-5,PURPUR_STAIRS:4)
Block(-5,4,-4,PURPUR_STAIRS:0)
Block(-5,4,-3,PURPUR_STAIRS:4)
Block(-5,4,-2,PURPUR_STAIRS:4)
Block(-5,4,-1,PURPUR_STAIRS:0)
Block(-5,4,0,PURPUR_STAIRS:0)
Block(-5,4,1,PURPUR_STAIRS:4)
Block(-5,4,2,PURPUR_STAIRS:4)
Block(-5,4,3,PURPUR_STAIRS:0)
Block(-5,4,4,PURPUR_STAIRS:4)
Block(-5,4,5,PURPUR_STAIRS:7)
Block(-5,5,-6,END_ROD)
Block(-5,5,5,END_ROD)
Block(-5,8,-7,PURPUR_STAIRS:6)
Block(-5,8,-6,PURPUR_BLOCK)
Block(-5,8,-5,PURPUR_BLOCK)
Block(-5,8,-4,PURPUR_BLOCK)
Block(-5,8,-3,PURPUR_BLOCK)
Block(-5,8,-2,PURPUR_BLOCK)
Block(-5,8,-1,PURPUR_BLOCK)
Block(-5,8,0,PURPUR_BLOCK)
Block(-5,8,1,PURPUR_BLOCK)
Block(-5,8,2,PURPUR_BLOCK)
Block(-5,8,3,PURPUR_BLOCK)
Block(-5,8,4,PURPUR_BLOCK)
Block(-5,8,5,PURPUR_BLOCK)
Block(-5,8,6,PURPUR_STAIRS:7)
Block(-5,9,-6,PURPUR_PILLAR:0)
Block(-5,9,-5,END_BRICKS)
Block(-5,9,-4,END_BRICKS)
Block(-5,9,-3,END_BRICKS)
Block(-5,9,-2,END_BRICKS)
Block(-5,9,-1,END_BRICKS)
Block(-5,9,0,END_BRICKS)
Block(-5,9,1,END_BRICKS)
Block(-5,9,2,END_BRICKS)
Block(-5,9,3,END_BRICKS)
Block(-5,9,4,END_BRICKS)
Block(-5,9,5,PURPUR_PILLAR:0)
Block(-5,10,-6,PURPUR_PILLAR:0)
Block(-5,10,-5,END_BRICKS)
Block(-5,10,-4,STAINED_GLASS:2)
Block(-5,10,-3,END_BRICKS)
Block(-5,10,-2,STAINED_GLASS:2)
Block(-5,10,-1,END_BRICKS)
Block(-5,10,0,END_BRICKS)
Block(-5,10,1,END_BRICKS)
Block(-5,10,2,END_BRICKS)
Block(-5,10,3,END_BRICKS)
Block(-5,10,4,END_BRICKS)
Block(-5,10,5,PURPUR_PILLAR:0)
Block(-5,11,-6,PURPUR_PILLAR:0)
Block(-5,11,-5,END_BRICKS)
Block(-5,11,-4,STAINED_GLASS:2)
Block(-5,11,-3,END_BRICKS)
Block(-5,11,-2,STAINED_GLASS:2)
Block(-5,11,-1,END_BRICKS)
Block(-5,11,0,END_BRICKS)
Block(-5,11,1,END_BRICKS)
Block(-5,11,2,END_BRICKS)
Block(-5,11,3,END_BRICKS)
Block(-5,11,4,END_BRICKS)
Block(-5,11,5,PURPUR_PILLAR:0)
Block(-5,12,-8,PURPUR_STAIRS:2)
Block(-5,12,-7,PURPUR_BLOCK)
Block(-5,12,-6,PURPUR_BLOCK)
Block(-5,12,-5,PURPUR_BLOCK)
Block(-5,12,-4,PURPUR_BLOCK)
Block(-5,12,-3,PURPUR_BLOCK)
Block(-5,12,-2,PURPUR_BLOCK)
Block(-5,12,-1,PURPUR_BLOCK)
Block(-5,12,0,PURPUR_BLOCK)
Block(-5,12,1,PURPUR_BLOCK)
Block(-5,12,2,PURPUR_BLOCK)
Block(-5,12,3,PURPUR_BLOCK)
Block(-5,12,4,PURPUR_BLOCK)
Block(-5,12,5,PURPUR_BLOCK)
Block(-5,12,6,PURPUR_BLOCK)
Block(-5,12,7,PURPUR_STAIRS:0)
Block(-5,16,-5,PURPUR_BLOCK)
Block(-5,16,-4,PURPUR_BLOCK)
Block(-5,16,-3,PURPUR_BLOCK)
Block(-5,16,-2,PURPUR_BLOCK)
Block(-5,16,-1,PURPUR_BLOCK)
Block(-5,16,0,PURPUR_BLOCK)
Block(-5,16,1,PURPUR_BLOCK)
Block(-5,17,-5,PURPUR_PILLAR:0)
Block(-5,17,-4,PURPUR_PILLAR:0)
Block(-5,17,0,PURPUR_PILLAR:0)
Block(-5,17,1,PURPUR_PILLAR:0)
Block(-5,18,-5,PURPUR_PILLAR:0)
Block(-5,18,-4,PURPUR_PILLAR:0)
Block(-5,18,0,PURPUR_PILLAR:0)
Block(-5,18,1,PURPUR_PILLAR:0)
Block(-5,19,-5,PURPUR_PILLAR:0)
Block(-5,19,-4,PURPUR_PILLAR:0)
Block(-5,19,0,PURPUR_PILLAR:0)
Block(-5,19,1,PURPUR_PILLAR:0)
Block(-5,20,-5,PURPUR_BLOCK)
Block(-5,20,-4,PURPUR_BLOCK)
Block(-5,20,-1,PURPUR_SLAB)
Block(-5,20,0,PURPUR_BLOCK)
Block(-5,20,1,PURPUR_BLOCK)
Block(-5,21,-5,PURPUR_PILLAR:0)
Block(-5,21,-4,PURPUR_PILLAR:0)
Block(-5,21,-3,PURPUR_SLAB)
Block(-5,21,0,PURPUR_PILLAR:0)
Block(-5,21,1,PURPUR_PILLAR:0)
Block(-5,22,-5,PURPUR_PILLAR:0)
Block(-5,22,-4,PURPUR_PILLAR:0)
Block(-5,22,0,PURPUR_PILLAR:0)
Block(-5,22,1,PURPUR_PILLAR:0)
Block(-5,23,-5,PURPUR_PILLAR:0)
Block(-5,23,-4,PURPUR_PILLAR:0)
Block(-5,23,0,PURPUR_PILLAR:0)
Block(-5,23,1,PURPUR_PILLAR:0)
Block(-5,24,-9,PURPUR_STAIRS:2)
Block(-5,24,-8,PURPUR_BLOCK)
Block(-5,24,-7,PURPUR_BLOCK)
Block(-5,24,-6,PURPUR_BLOCK)
Block(-5,24,-5,PURPUR_BLOCK)
Block(-5,24,-4,PURPUR_BLOCK)
Block(-5,24,-1,PURPUR_BLOCK)
Block(-5,24,0,PURPUR_BLOCK)
Block(-5,24,1,PURPUR_BLOCK)
Block(-5,24,2,PURPUR_BLOCK)
Block(-5,24,3,PURPUR_BLOCK)
Block(-5,24,4,PURPUR_BLOCK)
Block(-5,24,5,PURPUR_STAIRS:0)
Block(-5,25,-8,END_BRICKS)
Block(-5,25,4,END_BRICKS)
Block(-5,26,-8,STAINED_GLASS:2)
Block(-5,26,4,STAINED_GLASS:2)
Block(-5,27,-8,STAINED_GLASS:2)
Block(-5,27,4,STAINED_GLASS:2)
Block(-5,28,-10,PURPUR_STAIRS:6)
Block(-5,28,-9,PURPUR_BLOCK)
Block(-5,28,-8,PURPUR_BLOCK)
Block(-5,28,-7,PURPUR_BLOCK)
Block(-5,28,-6,PURPUR_BLOCK)
Block(-5,28,-5,PURPUR_BLOCK)
Block(-5,28,-4,PURPUR_BLOCK)
Block(-5,28,-3,PURPUR_BLOCK)
Block(-5,28,-2,PURPUR_BLOCK)
Block(-5,28,-1,PURPUR_BLOCK)
Block(-5,28,0,PURPUR_BLOCK)
Block(-5,28,1,PURPUR_BLOCK)
Block(-5,28,2,PURPUR_BLOCK)
Block(-5,28,3,PURPUR_BLOCK)
Block(-5,28,4,PURPUR_BLOCK)
Block(-5,28,5,PURPUR_BLOCK)
Block(-5,28,6,PURPUR_STAIRS:7)
Block(-4,4,-6,PURPUR_STAIRS:6)
Block(-4,4,-5,PURPUR_BLOCK)
Block(-4,4,-4,PURPUR_BLOCK)
Block(-4,4,-3,PURPUR_BLOCK)
Block(-4,4,-2,PURPUR_BLOCK)
Block(-4,4,-1,PURPUR_BLOCK)
Block(-4,4,0,PURPUR_BLOCK)
Block(-4,4,1,PURPUR_BLOCK)
Block(-4,4,2,PURPUR_BLOCK)
Block(-4,4,3,PURPUR_BLOCK)
Block(-4,4,4,PURPUR_BLOCK)
Block(-4,4,5,PURPUR_STAIRS:7)
Block(-4,5,-5,PURPUR_PILLAR:0)
Block(-4,5,-4,END_BRICKS)
Block(-4,5,-3,END_BRICKS)
Block(-4,5,-2,END_BRICKS)
Block(-4,5,-1,END_BRICKS)
Block(-4,5,0,END_BRICKS)
Block(-4,5,1,END_BRICKS)
Block(-4,5,2,END_BRICKS)
Block(-4,5,3,END_BRICKS)
Block(-4,5,4,PURPUR_PILLAR:0)
Block(-4,6,-5,PURPUR_PILLAR:0)
Block(-4,6,-4,END_BRICKS)
Block(-4,6,-3,STAINED_GLASS:2)
Block(-4,6,-2,END_BRICKS)
Block(-4,6,-1,END_BRICKS)
Block(-4,6,0,END_BRICKS)
Block(-4,6,1,END_BRICKS)
Block(-4,6,2,STAINED_GLASS:2)
Block(-4,6,3,END_BRICKS)
Block(-4,6,4,PURPUR_PILLAR:0)
Block(-4,7,-5,PURPUR_PILLAR:0)
Block(-4,7,-4,END_BRICKS)
Block(-4,7,-3,STAINED_GLASS:2)
Block(-4,7,-2,END_BRICKS)
Block(-4,7,-1,END_BRICKS)
Block(-4,7,0,END_BRICKS)
Block(-4,7,1,END_BRICKS)
Block(-4,7,2,STAINED_GLASS:2)
Block(-4,7,3,END_BRICKS)
Block(-4,7,4,PURPUR_PILLAR:0)
Block(-4,8,-7,PURPUR_STAIRS:2)
Block(-4,8,-6,PURPUR_BLOCK)
Block(-4,8,-5,PURPUR_BLOCK)
Block(-4,8,-4,PURPUR_BLOCK)
Block(-4,8,-3,PURPUR_BLOCK)
Block(-4,8,-2,PURPUR_BLOCK)
Block(-4,8,-1,PURPUR_BLOCK)
Block(-4,8,0,PURPUR_BLOCK)
Block(-4,8,1,PURPUR_BLOCK)
Block(-4,8,2,PURPUR_BLOCK)
Block(-4,8,3,PURPUR_BLOCK)
Block(-4,8,4,PURPUR_BLOCK)
Block(-4,8,5,PURPUR_BLOCK)
Block(-4,8,6,PURPUR_STAIRS:0)
Block(-4,9,-6,END_BRICKS)
Block(-4,9,3,PURPUR_BLOCK)
Block(-4,9,5,END_BRICKS)
Block(-4,10,-6,END_BRICKS)
Block(-4,10,3,PURPUR_BLOCK)
Block(-4,10,5,END_BRICKS)
Block(-4,11,-6,END_BRICKS)
Block(-4,11,3,PURPUR_BLOCK)
Block(-4,11,5,END_BRICKS)
Block(-4,12,-8,PURPUR_STAIRS:2)
Block(-4,12,-7,PURPUR_BLOCK)
Block(-4,12,-6,PURPUR_BLOCK)
Block(-4,12,-5,PURPUR_BLOCK)
Block(-4,12,-4,PURPUR_BLOCK)
Block(-4,12,-3,PURPUR_BLOCK)
Block(-4,12,-2,PURPUR_BLOCK)
Block(-4,12,-1,PURPUR_BLOCK)
Block(-4,12,0,PURPUR_BLOCK)
Block(-4,12,1,PURPUR_BLOCK)
Block(-4,12,2,PURPUR_BLOCK)
Block(-4,12,3,PURPUR_BLOCK)
Block(-4,12,4,PURPUR_BLOCK)
Block(-4,12,5,PURPUR_BLOCK)
Block(-4,12,6,PURPUR_BLOCK)
Block(-4,12,7,PURPUR_STAIRS:0)
Block(-4,14,-2,PURPUR_STAIRS:4)
Block(-4,16,-6,PURPUR_BLOCK)
Block(-4,16,-5,PURPUR_BLOCK)
Block(-4,16,-4,PURPUR_BLOCK)
Block(-4,16,-3,PURPUR_BLOCK)
Block(-4,16,-2,PURPUR_BLOCK)
Block(-4,16,-1,PURPUR_BLOCK)
Block(-4,16,0,PURPUR_BLOCK)
Block(-4,16,1,PURPUR_BLOCK)
Block(-4,16,2,PURPUR_BLOCK)
Block(-4,17,-6,PURPUR_PILLAR:0)
Block(-4,17,2,PURPUR_PILLAR:0)
Block(-4,18,-6,PURPUR_PILLAR:0)
Block(-4,18,2,PURPUR_PILLAR:0)
Block(-4,19,-6,PURPUR_PILLAR:0)
Block(-4,19,0,END_ROD:5)
Block(-4,19,2,PURPUR_PILLAR:0)
Block(-4,20,-6,PURPUR_BLOCK)
Block(-4,20,2,PURPUR_BLOCK)
Block(-4,21,-6,PURPUR_PILLAR:0)
Block(-4,21,2,PURPUR_PILLAR:0)
Block(-4,22,-6,PURPUR_PILLAR:0)
Block(-4,22,-4,END_ROD:5)
Block(-4,22,2,PURPUR_PILLAR:0)
Block(-4,23,-6,PURPUR_PILLAR:0)
Block(-4,23,2,PURPUR_PILLAR:0)
Block(-4,24,-9,PURPUR_STAIRS:6)
Block(-4,24,-8,PURPUR_BLOCK)
Block(-4,24,-7,PURPUR_BLOCK)
Block(-4,24,-6,PURPUR_BLOCK)
Block(-4,24,-1,PURPUR_BLOCK)
Block(-4,24,0,PURPUR_BLOCK)
Block(-4,24,1,PURPUR_BLOCK)
Block(-4,24,2,PURPUR_BLOCK)
Block(-4,24,3,PURPUR_BLOCK)
Block(-4,24,4,PURPUR_BLOCK)
Block(-4,24,5,PURPUR_STAIRS:7)
Block(-4,25,-8,END_BRICKS)
Block(-4,25,4,END_BRICKS)
Block(-4,26,-8,END_BRICKS)
Block(-4,26,4,END_BRICKS)
Block(-4,27,-8,END_BRICKS)
Block(-4,27,4,END_BRICKS)
Block(-4,28,-10,PURPUR_STAIRS:6)
Block(-4,28,-9,PURPUR_BLOCK)
Block(-4,28,-8,PURPUR_BLOCK)
Block(-4,28,-7,PURPUR_BLOCK)
Block(-4,28,-6,PURPUR_BLOCK)
Block(-4,28,-5,PURPUR_BLOCK)
Block(-4,28,-4,PURPUR_BLOCK)
Block(-4,28,-3,PURPUR_BLOCK)
Block(-4,28,-2,PURPUR_BLOCK)
Block(-4,28,-1,PURPUR_BLOCK)
Block(-4,28,0,PURPUR_BLOCK)
Block(-4,28,1,PURPUR_BLOCK)
Block(-4,28,2,PURPUR_BLOCK)
Block(-4,28,3,PURPUR_BLOCK)
Block(-4,28,4,PURPUR_BLOCK)
Block(-4,28,5,PURPUR_BLOCK)
Block(-4,28,6,PURPUR_STAIRS:7)
Block(-3,0,-4,PURPUR_BLOCK)
Block(-3,0,-3,PURPUR_BLOCK)
Block(-3,0,-2,PURPUR_BLOCK)
Block(-3,0,-1,PURPUR_BLOCK)
Block(-3,0,0,PURPUR_BLOCK)
Block(-3,0,1,PURPUR_BLOCK)
Block(-3,0,2,PURPUR_BLOCK)
Block(-3,0,3,PURPUR_BLOCK)
Block(-3,1,-4,PURPUR_PILLAR:0)
Block(-3,1,-3,END_BRICKS)
Block(-3,1,-2,END_BRICKS)
Block(-3,1,-1,END_BRICKS)
Block(-3,1,0,END_BRICKS)
Block(-3,1,1,END_BRICKS)
Block(-3,1,2,END_BRICKS)
Block(-3,1,3,PURPUR_PILLAR:0)
Block(-3,2,-4,PURPUR_PILLAR:0)
Block(-3,2,-3,END_BRICKS)
Block(-3,2,-2,STAINED_GLASS:2)
Block(-3,2,-1,END_BRICKS)
Block(-3,2,0,END_BRICKS)
Block(-3,2,1,STAINED_GLASS:2)
Block(-3,2,2,END_BRICKS)
Block(-3,2,3,PURPUR_PILLAR:0)
Block(-3,3,-4,PURPUR_PILLAR:0)
Block(-3,3,-3,END_BRICKS)
Block(-3,3,-2,STAINED_GLASS:2)
Block(-3,3,-1,END_BRICKS)
Block(-3,3,0,END_BRICKS)
Block(-3,3,1,STAINED_GLASS:2)
Block(-3,3,2,END_BRICKS)
Block(-3,3,3,PURPUR_PILLAR:0)
Block(-3,4,-6,PURPUR_STAIRS:2)
Block(-3,4,-5,PURPUR_BLOCK)
Block(-3,4,-4,PURPUR_BLOCK)
Block(-3,4,-3,PURPUR_BLOCK)
Block(-3,4,-2,PURPUR_BLOCK)
Block(-3,4,-1,PURPUR_BLOCK)
Block(-3,4,0,PURPUR_BLOCK)
Block(-3,4,1,PURPUR_BLOCK)
Block(-3,4,2,PURPUR_BLOCK)
Block(-3,4,3,PURPUR_BLOCK)
Block(-3,4,4,PURPUR_BLOCK)
Block(-3,4,5,PURPUR_STAIRS:0)
Block(-3,5,-5,END_BRICKS)
Block(-3,5,4,END_BRICKS)
Block(-3,6,-5,END_BRICKS)
Block(-3,6,4,END_BRICKS)
Block(-3,7,-5,END_BRICKS)
Block(-3,7,4,END_BRICKS)
Block(-3,8,-7,PURPUR_STAIRS:2)
Block(-3,8,-6,PURPUR_BLOCK)
Block(-3,8,-5,PURPUR_BLOCK)
Block(-3,8,4,PURPUR_BLOCK)
Block(-3,8,5,PURPUR_BLOCK)
Block(-3,8,6,PURPUR_STAIRS:0)
Block(-3,9,-6,END_BRICKS)
Block(-3,9,5,END_BRICKS)
Block(-3,10,-6,STAINED_GLASS:2)
Block(-3,10,5,STAINED_GLASS:2)
Block(-3,11,-6,STAINED_GLASS:2)
Block(-3,11,5,STAINED_GLASS:2)
Block(-3,12,-8,PURPUR_STAIRS:6)
Block(-3,12,-7,PURPUR_BLOCK)
Block(-3,12,-6,PURPUR_BLOCK)
Block(-3,12,-5,PURPUR_BLOCK)
Block(-3,12,-4,PURPUR_BLOCK)
Block(-3,12,-3,PURPUR_BLOCK)
Block(-3,12,-2,PURPUR_BLOCK)
Block(-3,12,-1,PURPUR_BLOCK)
Block(-3,12,0,PURPUR_BLOCK)
Block(-3,12,1,PURPUR_BLOCK)
Block(-3,12,2,PURPUR_BLOCK)
Block(-3,12,3,PURPUR_BLOCK)
Block(-3,12,4,PURPUR_BLOCK)
Block(-3,12,5,PURPUR_BLOCK)
Block(-3,12,6,PURPUR_BLOCK)
Block(-3,12,7,PURPUR_STAIRS:7)
Block(-3,13,-3,PURPUR_PILLAR:0)
Block(-3,13,-2,PURPUR_PILLAR:0)
Block(-3,13,-1,PURPUR_PILLAR:0)
Block(-3,14,-3,PURPUR_PILLAR:0)
Block(-3,14,-2,PURPUR_PILLAR)
Block(-3,14,-1,PURPUR_PILLAR:0)
Block(-3,15,-3,PURPUR_PILLAR:0)
Block(-3,15,-2,PURPUR_PILLAR:0)
Block(-3,15,-1,PURPUR_PILLAR:0)
Block(-3,16,-6,PURPUR_BLOCK)
Block(-3,16,-5,PURPUR_BLOCK)
Block(-3,16,-4,PURPUR_BLOCK)
Block(-3,16,-3,PURPUR_BLOCK)
Block(-3,16,-2,PURPUR_BLOCK)
Block(-3,16,-1,PURPUR_BLOCK)
Block(-3,16,0,PURPUR_BLOCK)
Block(-3,16,1,PURPUR_BLOCK)
Block(-3,16,2,PURPUR_BLOCK)
Block(-3,17,-6,PURPUR_PILLAR:0)
Block(-3,17,2,PURPUR_PILLAR:0)
Block(-3,18,-6,PURPUR_PILLAR:0)
Block(-3,18,1,END_ROD:2)
Block(-3,18,2,PURPUR_PILLAR:0)
Block(-3,19,-6,PURPUR_PILLAR:0)
Block(-3,19,2,PURPUR_PILLAR:0)
Block(-3,20,-6,PURPUR_BLOCK)
Block(-3,20,2,PURPUR_BLOCK)
Block(-3,21,-6,PURPUR_PILLAR:0)
Block(-3,21,2,PURPUR_PILLAR:0)
Block(-3,22,-6,PURPUR_PILLAR:0)
Block(-3,22,2,PURPUR_PILLAR:0)
Block(-3,23,-6,PURPUR_PILLAR:0)
Block(-3,23,-5,END_ROD:3)
Block(-3,23,2,PURPUR_PILLAR:0)
Block(-3,24,-9,PURPUR_STAIRS:6)
Block(-3,24,-8,PURPUR_BLOCK)
Block(-3,24,-7,PURPUR_BLOCK)
Block(-3,24,-6,PURPUR_BLOCK)
Block(-3,24,-1,PURPUR_BLOCK)
Block(-3,24,0,PURPUR_BLOCK)
Block(-3,24,1,PURPUR_BLOCK)
Block(-3,24,2,PURPUR_BLOCK)
Block(-3,24,3,PURPUR_BLOCK)
Block(-3,24,4,PURPUR_BLOCK)
Block(-3,24,5,PURPUR_STAIRS:7)
Block(-3,25,-8,END_BRICKS)
Block(-3,25,4,END_BRICKS)
Block(-3,26,-8,END_BRICKS)
Block(-3,26,4,END_BRICKS)
Block(-3,27,-8,END_BRICKS)
Block(-3,27,4,END_BRICKS)
Block(-3,28,-10,PURPUR_STAIRS:2)
Block(-3,28,-9,PURPUR_BLOCK)
Block(-3,28,-8,PURPUR_BLOCK)
Block(-3,28,-7,PURPUR_BLOCK)
Block(-3,28,-6,PURPUR_BLOCK)
Block(-3,28,-5,PURPUR_BLOCK)
Block(-3,28,-4,PURPUR_BLOCK)
Block(-3,28,-3,PURPUR_BLOCK)
Block(-3,28,-2,PURPUR_BLOCK)
Block(-3,28,-1,PURPUR_BLOCK)
Block(-3,28,0,PURPUR_BLOCK)
Block(-3,28,1,PURPUR_BLOCK)
Block(-3,28,2,PURPUR_BLOCK)
Block(-3,28,3,PURPUR_BLOCK)
Block(-3,28,4,PURPUR_BLOCK)
Block(-3,28,5,PURPUR_BLOCK)
Block(-3,28,6,PURPUR_STAIRS:0)
Block(-2,0,-4,PURPUR_BLOCK)
Block(-2,0,-3,PURPUR_BLOCK)
Block(-2,0,-2,PURPUR_BLOCK)
Block(-2,0,-1,PURPUR_BLOCK)
Block(-2,0,0,PURPUR_BLOCK)
Block(-2,0,1,PURPUR_BLOCK)
Block(-2,0,2,PURPUR_BLOCK)
Block(-2,0,3,PURPUR_BLOCK)
Block(-2,0,4,PURPUR_STAIRS:0)
Block(-2,1,-4,END_BRICKS)
Block(-2,1,3,END_BRICKS)
Block(-2,2,-4,END_BRICKS)
Block(-2,2,3,END_BRICKS)
Block(-2,3,-4,END_BRICKS)
Block(-2,3,3,END_BRICKS)
Block(-2,4,-6,PURPUR_STAIRS:6)
Block(-2,4,-5,PURPUR_BLOCK)
Block(-2,4,-4,PURPUR_BLOCK)
Block(-2,4,2,PURPUR_BLOCK)
Block(-2,4,3,PURPUR_BLOCK)
Block(-2,4,4,PURPUR_BLOCK)
Block(-2,4,5,PURPUR_STAIRS:7)
Block(-2,5,-5,END_BRICKS)
Block(-2,5,2,PURPUR_STAIRS:0)
Block(-2,5,4,END_BRICKS)
Block(-2,6,-5,STAINED_GLASS:2)
Block(-2,6,4,STAINED_GLASS:2)
Block(-2,7,-5,STAINED_GLASS:2)
Block(-2,7,4,STAINED_GLASS:2)
Block(-2,8,-7,PURPUR_STAIRS:6)
Block(-2,8,-6,PURPUR_BLOCK)
Block(-2,8,-5,PURPUR_BLOCK)
Block(-2,8,4,PURPUR_BLOCK)
Block(-2,8,5,PURPUR_BLOCK)
Block(-2,8,6,PURPUR_STAIRS:7)
Block(-2,9,-6,END_BRICKS)
Block(-2,9,5,END_BRICKS)
Block(-2,10,-6,END_BRICKS)
Block(-2,10,5,END_BRICKS)
Block(-2,11,-6,END_BRICKS)
Block(-2,11,5,END_BRICKS)
Block(-2,12,-8,PURPUR_STAIRS:6)
Block(-2,12,-7,PURPUR_BLOCK)
Block(-2,12,-6,PURPUR_BLOCK)
Block(-2,12,-5,PURPUR_BLOCK)
Block(-2,12,-4,PURPUR_BLOCK)
Block(-2,12,-2,PURPUR_SLAB)
Block(-2,12,0,PURPUR_BLOCK)
Block(-2,12,1,PURPUR_BLOCK)
Block(-2,12,2,PURPUR_BLOCK)
Block(-2,12,3,PURPUR_BLOCK)
Block(-2,12,4,PURPUR_BLOCK)
Block(-2,12,5,PURPUR_BLOCK)
Block(-2,12,6,PURPUR_BLOCK)
Block(-2,12,7,PURPUR_STAIRS:7)
Block(-2,13,-4,PURPUR_PILLAR:0)
Block(-2,13,0,PURPUR_PILLAR:0)
Block(-2,14,-4,PURPUR_PILLAR:0)
Block(-2,14,0,PURPUR_PILLAR:0)
Block(-2,15,-4,PURPUR_PILLAR:0)
Block(-2,15,0,PURPUR_PILLAR:0)
Block(-2,16,-7,PURPUR_BLOCK)
Block(-2,16,-6,PURPUR_BLOCK)
Block(-2,16,-5,PURPUR_BLOCK)
Block(-2,16,-4,PURPUR_BLOCK)
Block(-2,16,0,PURPUR_BLOCK)
Block(-2,16,1,PURPUR_BLOCK)
Block(-2,16,2,PURPUR_BLOCK)
Block(-2,16,3,PURPUR_BLOCK)
Block(-2,17,-7,PURPUR_PILLAR:0)
Block(-2,17,2,PURPUR_SLAB)
Block(-2,17,3,PURPUR_PILLAR:0)
Block(-2,18,-7,PURPUR_PILLAR:0)
Block(-2,18,3,PURPUR_PILLAR:0)
Block(-2,19,-7,PURPUR_PILLAR:0)
Block(-2,19,3,PURPUR_PILLAR:0)
Block(-2,20,-7,PURPUR_BLOCK)
Block(-2,20,3,PURPUR_BLOCK)
Block(-2,21,-7,PURPUR_PILLAR:0)
Block(-2,21,3,PURPUR_PILLAR:0)
Block(-2,22,-7,PURPUR_PILLAR:0)
Block(-2,22,3,PURPUR_PILLAR:0)
Block(-2,23,-7,PURPUR_BLOCK)
Block(-2,23,3,PURPUR_PILLAR:0)
Block(-2,24,-9,PURPUR_STAIRS:2)
Block(-2,24,-8,PURPUR_BLOCK)
Block(-2,24,-7,PURPUR_BLOCK)
Block(-2,24,-6,PURPUR_SLAB)
Block(-2,24,-1,PURPUR_BLOCK)
Block(-2,24,0,PURPUR_BLOCK)
Block(-2,24,1,PURPUR_BLOCK)
Block(-2,24,2,PURPUR_BLOCK)
Block(-2,24,3,PURPUR_BLOCK)
Block(-2,24,4,PURPUR_BLOCK)
Block(-2,24,5,PURPUR_STAIRS:0)
Block(-2,25,-8,END_BRICKS)
Block(-2,25,-7,PURPUR_SLAB)
Block(-2,25,-1,PURPUR_PILLAR:0)
Block(-2,25,4,END_BRICKS)
Block(-2,26,-8,STAINED_GLASS:2)
Block(-2,26,-1,PURPUR_PILLAR:0)
Block(-2,26,4,STAINED_GLASS:2)
Block(-2,27,-8,STAINED_GLASS:2)
Block(-2,27,-1,PURPUR_PILLAR:0)
Block(-2,27,4,STAINED_GLASS:2)
Block(-2,28,-10,PURPUR_STAIRS:2)
Block(-2,28,-9,PURPUR_BLOCK)
Block(-2,28,-8,PURPUR_BLOCK)
Block(-2,28,-7,PURPUR_BLOCK)
Block(-2,28,-6,PURPUR_BLOCK)
Block(-2,28,-5,PURPUR_BLOCK)
Block(-2,28,-4,PURPUR_BLOCK)
Block(-2,28,-3,PURPUR_BLOCK)
Block(-2,28,-2,PURPUR_BLOCK)
Block(-2,28,-1,PURPUR_BLOCK)
Block(-2,28,0,PURPUR_BLOCK)
Block(-2,28,1,PURPUR_BLOCK)
Block(-2,28,2,PURPUR_BLOCK)
Block(-2,28,3,PURPUR_BLOCK)
Block(-2,28,4,PURPUR_BLOCK)
Block(-2,28,5,PURPUR_BLOCK)
Block(-2,28,6,PURPUR_STAIRS:0)
Block(-2,29,-8,PURPUR_STAIRS:0)
Block(-2,29,-7,PURPUR_STAIRS:0)
Block(-2,29,-6,PURPUR_STAIRS:0)
Block(-1,0,-4,PURPUR_BLOCK)
Block(-1,0,-3,PURPUR_BLOCK)
Block(-1,0,-2,PURPUR_BLOCK)
Block(-1,0,-1,PURPUR_BLOCK)
Block(-1,0,0,PURPUR_BLOCK)
Block(-1,0,1,PURPUR_BLOCK)
Block(-1,0,2,PURPUR_BLOCK)
Block(-1,0,3,PURPUR_BLOCK)
Block(-1,0,4,PURPUR_BLOCK)
Block(-1,1,-4,END_BRICKS)
Block(-1,1,3,END_BRICKS)
Block(-1,2,-4,STAINED_GLASS:2)
Block(-1,2,3,END_BRICKS)
Block(-1,3,-4,STAINED_GLASS:2)
Block(-1,3,0,PURPUR_SLAB:8)
Block(-1,3,3,END_BRICKS)
Block(-1,4,-6,PURPUR_STAIRS:6)
Block(-1,4,-5,PURPUR_BLOCK)
Block(-1,4,-4,PURPUR_BLOCK)
Block(-1,4,2,PURPUR_BLOCK)
Block(-1,4,3,PURPUR_BLOCK)
Block(-1,4,4,PURPUR_BLOCK)
Block(-1,5,-5,END_BRICKS)
Block(-1,5,2,PURPUR_BLOCK)
Block(-1,5,4,END_BRICKS)
Block(-1,6,-5,END_BRICKS)
Block(-1,6,2,PURPUR_STAIRS:0)
Block(-1,6,4,END_BRICKS)
Block(-1,7,-5,END_BRICKS)
Block(-1,7,4,END_BRICKS)
Block(-1,8,-7,PURPUR_STAIRS:6)
Block(-1,8,-6,PURPUR_BLOCK)
Block(-1,8,-5,PURPUR_BLOCK)
Block(-1,8,1,PURPUR_BLOCK)
Block(-1,8,4,PURPUR_BLOCK)
Block(-1,8,5,PURPUR_BLOCK)
Block(-1,8,6,PURPUR_STAIRS:7)
Block(-1,9,-6,END_BRICKS)
Block(-1,9,-1,LADDER)
Block(-1,9,0,PURPUR_PILLAR:0)
Block(-1,9,5,END_BRICKS)
Block(-1,10,-6,STAINED_GLASS:2)
Block(-1,10,-1,LADDER)
Block(-1,10,0,PURPUR_PILLAR:0)
Block(-1,10,5,STAINED_GLASS:2)
Block(-1,11,-6,STAINED_GLASS:2)
Block(-1,11,-1,LADDER)
Block(-1,11,0,PURPUR_PILLAR:0)
Block(-1,11,5,STAINED_GLASS:2)
Block(-1,12,-8,PURPUR_STAIRS:2)
Block(-1,12,-7,PURPUR_BLOCK)
Block(-1,12,-6,PURPUR_BLOCK)
Block(-1,12,-5,PURPUR_BLOCK)
Block(-1,12,-4,PURPUR_BLOCK)
Block(-1,12,0,PURPUR_BLOCK)
Block(-1,12,1,PURPUR_BLOCK)
Block(-1,12,2,PURPUR_BLOCK)
Block(-1,12,3,PURPUR_BLOCK)
Block(-1,12,4,PURPUR_BLOCK)
Block(-1,12,5,PURPUR_BLOCK)
Block(-1,12,6,PURPUR_BLOCK)
Block(-1,12,7,PURPUR_STAIRS:0)
Block(-1,13,-4,PURPUR_PILLAR:0)
Block(-1,13,-3,PURPUR_SLAB)
Block(-1,13,0,PURPUR_PILLAR:0)
Block(-1,14,-5,PURPUR_STAIRS:6)
Block(-1,14,-4,PURPUR_PILLAR:8)
Block(-1,14,0,PURPUR_PILLAR:8)
Block(-1,14,1,PURPUR_STAIRS:7)
Block(-1,15,-4,PURPUR_PILLAR:0)
Block(-1,15,-1,PURPUR_SLAB)
Block(-1,15,0,PURPUR_PILLAR:0)
Block(-1,16,-7,PURPUR_BLOCK)
Block(-1,16,-6,PURPUR_BLOCK)
Block(-1,16,-5,PURPUR_BLOCK)
Block(-1,16,-4,PURPUR_BLOCK)
Block(-1,16,-1,PURPUR_SLAB)
Block(-1,16,0,PURPUR_BLOCK)
Block(-1,16,1,PURPUR_BLOCK)
Block(-1,16,2,PURPUR_BLOCK)
Block(-1,16,3,PURPUR_BLOCK)
Block(-1,17,-7,PURPUR_PILLAR:0)
Block(-1,17,3,PURPUR_PILLAR:0)
Block(-1,18,-8,PURPUR_STAIRS:6)
Block(-1,18,-7,PURPUR_PILLAR:8)
Block(-1,18,3,PURPUR_PILLAR:8)
Block(-1,18,4,PURPUR_STAIRS:7)
Block(-1,19,-7,PURPUR_PILLAR:0)
Block(-1,19,3,PURPUR_PILLAR:0)
Block(-1,20,-7,PURPUR_BLOCK)
Block(-1,20,3,PURPUR_BLOCK)
Block(-1,21,-7,PURPUR_PILLAR:0)
Block(-1,21,3,PURPUR_PILLAR:0)
Block(-1,22,-8,PURPUR_STAIRS:6)
Block(-1,22,-7,PURPUR_PILLAR:8)
Block(-1,22,3,PURPUR_PILLAR:8)
Block(-1,22,4,PURPUR_STAIRS:7)
Block(-1,23,-8,PURPUR_PILLAR:8)
Block(-1,23,-7,PURPUR_BLOCK)
Block(-1,23,3,PURPUR_PILLAR:0)
Block(-1,24,-9,PURPUR_STAIRS:2)
Block(-1,24,-8,PURPUR_BLOCK)
Block(-1,24,-7,PURPUR_BLOCK)
Block(-1,24,3,PURPUR_BLOCK)
Block(-1,24,4,PURPUR_BLOCK)
Block(-1,24,5,PURPUR_STAIRS:0)
Block(-1,25,-8,END_BRICKS)
Block(-1,25,-7,PURPUR_BLOCK)
Block(-1,25,4,END_BRICKS)
Block(-1,26,-8,END_BRICKS)
Block(-1,26,4,END_BRICKS)
Block(-1,27,-8,END_BRICKS)
Block(-1,27,4,END_BRICKS)
Block(-1,28,-10,PURPUR_STAIRS:6)
Block(-1,28,-9,PURPUR_BLOCK)
Block(-1,28,-8,PURPUR_BLOCK)
Block(-1,28,-6,PURPUR_BLOCK)
Block(-1,28,-5,PURPUR_BLOCK)
Block(-1,28,-4,PURPUR_BLOCK)
Block(-1,28,-3,PURPUR_BLOCK)
Block(-1,28,-2,PURPUR_BLOCK)
Block(-1,28,-1,PURPUR_BLOCK)
Block(-1,28,0,PURPUR_BLOCK)
Block(-1,28,1,PURPUR_BLOCK)
Block(-1,28,2,PURPUR_BLOCK)
Block(-1,28,3,PURPUR_BLOCK)
Block(-1,28,4,PURPUR_BLOCK)
Block(-1,28,5,PURPUR_BLOCK)
Block(-1,28,6,PURPUR_STAIRS:7)
Block(-1,29,-8,PURPUR_STAIRS:2)
Block(-1,29,-6,PURPUR_STAIRS:0)
Block(0,0,-4,PURPUR_BLOCK)
Block(0,0,-3,PURPUR_BLOCK)
Block(0,0,-2,PURPUR_BLOCK)
Block(0,0,-1,PURPUR_BLOCK)
Block(0,0,0,PURPUR_BLOCK)
Block(0,0,1,PURPUR_BLOCK)
Block(0,0,2,PURPUR_BLOCK)
Block(0,0,3,PURPUR_BLOCK)
Block(0,0,4,PURPUR_BLOCK)
Block(0,1,-4,END_BRICKS)
Block(0,1,-1,PURPUR_BLOCK)
Block(0,1,0,PURPUR_BLOCK)
Block(0,2,-4,END_BRICKS)
Block(0,2,-1,PURPUR_BLOCK)
Block(0,2,0,PURPUR_BLOCK)
Block(0,3,-4,END_BRICKS)
Block(0,3,-2,PURPUR_SLAB)
Block(0,3,-1,PURPUR_STAIRS:2)
Block(0,3,0,PURPUR_BLOCK)
Block(0,4,-6,PURPUR_STAIRS:2)
Block(0,4,-5,PURPUR_BLOCK)
Block(0,4,-4,PURPUR_BLOCK)
Block(0,4,0,PURPUR_STAIRS:0)
Block(0,4,2,PURPUR_BLOCK)
Block(0,4,3,PURPUR_BLOCK)
Block(0,4,4,PURPUR_BLOCK)
Block(0,5,-5,END_BRICKS)
Block(0,5,2,PURPUR_BLOCK)
Block(0,5,3,PURPUR_BLOCK)
Block(0,5,4,END_BRICKS)
Block(0,6,-5,END_BRICKS)
Block(0,6,2,PURPUR_BLOCK)
Block(0,6,3,PURPUR_BLOCK)
Block(0,6,4,END_BRICKS)
Block(0,7,-5,END_BRICKS)
Block(0,7,4,END_BRICKS)
Block(0,8,-7,PURPUR_STAIRS:2)
Block(0,8,-6,PURPUR_BLOCK)
Block(0,8,-5,PURPUR_BLOCK)
Block(0,8,-4,PURPUR_BLOCK)
Block(0,8,-3,END_ROD:3)
Block(0,8,1,PURPUR_BLOCK)
Block(0,8,4,PURPUR_BLOCK)
Block(0,8,5,PURPUR_BLOCK)
Block(0,8,6,PURPUR_STAIRS:0)
Block(0,9,-6,END_BRICKS)
Block(0,9,5,END_BRICKS)
Block(0,10,-6,END_BRICKS)
Block(0,10,5,END_BRICKS)
Block(0,11,-6,END_BRICKS)
Block(0,11,5,END_BRICKS)
Block(0,12,-8,PURPUR_STAIRS:6)
Block(0,12,-7,PURPUR_BLOCK)
Block(0,12,-6,PURPUR_BLOCK)
Block(0,12,-5,PURPUR_BLOCK)
Block(0,12,-4,PURPUR_BLOCK)
Block(0,12,0,PURPUR_BLOCK)
Block(0,12,1,PURPUR_BLOCK)
Block(0,12,2,PURPUR_BLOCK)
Block(0,12,3,PURPUR_BLOCK)
Block(0,12,4,PURPUR_BLOCK)
Block(0,12,5,PURPUR_BLOCK)
Block(0,12,6,PURPUR_BLOCK)
Block(0,12,7,PURPUR_STAIRS:7)
Block(0,13,-4,PURPUR_PILLAR:0)
Block(0,13,0,PURPUR_PILLAR:0)
Block(0,14,-4,PURPUR_PILLAR:0)
Block(0,14,-2,PURPUR_SLAB)
Block(0,14,0,PURPUR_PILLAR:0)
Block(0,15,-4,PURPUR_PILLAR:0)
Block(0,15,0,PURPUR_PILLAR:0)
Block(0,16,-7,PURPUR_BLOCK)
Block(0,16,-6,PURPUR_BLOCK)
Block(0,16,-5,PURPUR_BLOCK)
Block(0,16,-4,PURPUR_BLOCK)
Block(0,16,0,PURPUR_BLOCK)
Block(0,16,1,PURPUR_BLOCK)
Block(0,16,2,PURPUR_BLOCK)
Block(0,16,3,PURPUR_BLOCK)
Block(0,17,-7,PURPUR_PILLAR:0)
Block(0,17,-6,PURPUR_SLAB)
Block(0,17,3,PURPUR_PILLAR:0)
Block(0,18,-7,PURPUR_PILLAR:0)
Block(0,18,3,PURPUR_PILLAR:0)
Block(0,19,-7,PURPUR_PILLAR:0)
Block(0,19,3,PURPUR_PILLAR:0)
Block(0,20,-7,PURPUR_BLOCK)
Block(0,20,3,PURPUR_BLOCK)
Block(0,21,-7,PURPUR_PILLAR:0)
Block(0,21,3,PURPUR_PILLAR:0)
Block(0,22,-7,PURPUR_PILLAR:0)
Block(0,22,3,PURPUR_PILLAR:0)
Block(0,23,-7,PURPUR_BLOCK)
Block(0,23,3,PURPUR_PILLAR:0)
Block(0,24,-9,PURPUR_STAIRS:2)
Block(0,24,-8,PURPUR_BLOCK)
Block(0,24,-7,PURPUR_BLOCK)
Block(0,24,-6,PURPUR_BLOCK)
Block(0,24,-5,PURPUR_BLOCK)
Block(0,24,-4,PURPUR_BLOCK)
Block(0,24,-3,PURPUR_BLOCK)
Block(0,24,2,PURPUR_SLAB)
Block(0,24,3,PURPUR_BLOCK)
Block(0,24,4,PURPUR_BLOCK)
Block(0,24,5,PURPUR_STAIRS:0)
Block(0,25,-8,END_BRICKS)
Block(0,25,-7,PURPUR_SLAB:8)
Block(0,25,-3,PURPUR_PILLAR:0)
Block(0,25,4,END_BRICKS)
Block(0,26,-8,END_BRICKS)
Block(0,26,-7,PURPUR_SLAB)
Block(0,26,-3,PURPUR_PILLAR:0)
Block(0,26,4,STAINED_GLASS:2)
Block(0,27,-8,END_BRICKS)
Block(0,27,-3,PURPUR_PILLAR:0)
Block(0,27,4,STAINED_GLASS:2)
Block(0,28,-10,PURPUR_STAIRS:2)
Block(0,28,-9,PURPUR_BLOCK)
Block(0,28,-8,PURPUR_BLOCK)
Block(0,28,-6,PURPUR_BLOCK)
Block(0,28,-5,PURPUR_BLOCK)
Block(0,28,-4,PURPUR_BLOCK)
Block(0,28,-3,PURPUR_BLOCK)
Block(0,28,-2,PURPUR_BLOCK)
Block(0,28,-1,PURPUR_BLOCK)
Block(0,28,0,PURPUR_BLOCK)
Block(0,28,1,PURPUR_BLOCK)
Block(0,28,2,PURPUR_BLOCK)
Block(0,28,3,PURPUR_BLOCK)
Block(0,28,4,PURPUR_BLOCK)
Block(0,28,5,PURPUR_BLOCK)
Block(0,28,6,PURPUR_STAIRS:0)
Block(0,29,-8,PURPUR_STAIRS:2)
Block(0,29,-6,PURPUR_STAIRS:0)
Block(1,0,-4,PURPUR_BLOCK)
Block(1,0,-3,PURPUR_BLOCK)
Block(1,0,-2,PURPUR_BLOCK)
Block(1,0,-1,PURPUR_BLOCK)
Block(1,0,0,PURPUR_BLOCK)
Block(1,0,1,PURPUR_BLOCK)
Block(1,0,2,PURPUR_BLOCK)
Block(1,0,3,PURPUR_BLOCK)
Block(1,0,4,PURPUR_BLOCK)
Block(1,1,-4,END_BRICKS)
Block(1,1,-1,PURPUR_BLOCK)
Block(1,1,0,PURPUR_STAIRS:0)
Block(1,1,1,PURPUR_SLAB)
Block(1,2,-4,END_BRICKS)
Block(1,2,-1,PURPUR_STAIRS:1)
Block(1,3,-4,END_BRICKS)
Block(1,4,-6,PURPUR_STAIRS:2)
Block(1,4,-5,PURPUR_BLOCK)
Block(1,4,-4,PURPUR_BLOCK)
Block(1,4,0,PURPUR_SLAB:8)
Block(1,4,3,PURPUR_BLOCK)
Block(1,4,4,PURPUR_BLOCK)
Block(1,5,-5,END_BRICKS)
Block(1,5,3,PURPUR_BLOCK)
Block(1,5,4,END_BRICKS)
Block(1,6,-5,END_BRICKS)
Block(1,6,3,PURPUR_BLOCK)
Block(1,6,4,END_BRICKS)
Block(1,7,-5,END_BRICKS)
Block(1,7,4,END_BRICKS)
Block(1,8,-7,PURPUR_STAIRS:2)
Block(1,8,-6,PURPUR_BLOCK)
Block(1,8,-5,PURPUR_BLOCK)
Block(1,8,-4,PURPUR_BLOCK)
Block(1,8,-3,END_ROD:3)
Block(1,8,1,PURPUR_BLOCK)
Block(1,8,4,PURPUR_BLOCK)
Block(1,8,5,PURPUR_BLOCK)
Block(1,8,6,PURPUR_STAIRS:0)
Block(1,9,-6,END_BRICKS)
Block(1,9,-5,ENDER_CHEST:3,EndTowerC/2-ender_chest.nbt)
Block(1,9,5,END_BRICKS)
Block(1,10,-6,END_BRICKS)
Block(1,10,5,END_BRICKS)
Block(1,11,-6,END_BRICKS)
Block(1,11,5,END_BRICKS)
Block(1,12,-8,PURPUR_STAIRS:6)
Block(1,12,-7,PURPUR_BLOCK)
Block(1,12,-6,PURPUR_BLOCK)
Block(1,12,-5,PURPUR_BLOCK)
Block(1,12,-4,PURPUR_BLOCK)
Block(1,12,-3,PURPUR_BLOCK)
Block(1,12,-2,PURPUR_BLOCK)
Block(1,12,-1,PURPUR_BLOCK)
Block(1,12,0,PURPUR_BLOCK)
Block(1,12,1,PURPUR_BLOCK)
Block(1,12,2,PURPUR_BLOCK)
Block(1,12,3,PURPUR_BLOCK)
Block(1,12,4,PURPUR_BLOCK)
Block(1,12,5,PURPUR_BLOCK)
Block(1,12,6,PURPUR_BLOCK)
Block(1,12,7,PURPUR_STAIRS:7)
Block(1,13,-3,PURPUR_PILLAR:0)
Block(1,13,-2,PURPUR_PILLAR:0)
Block(1,13,-1,PURPUR_PILLAR:0)
Block(1,14,-3,PURPUR_PILLAR:0)
Block(1,14,-2,PURPUR_PILLAR)
Block(1,14,-1,PURPUR_PILLAR:0)
Block(1,15,-3,PURPUR_PILLAR:0)
Block(1,15,-2,PURPUR_PILLAR:0)
Block(1,15,-1,PURPUR_PILLAR:0)
Block(1,16,-6,PURPUR_BLOCK)
Block(1,16,-5,PURPUR_BLOCK)
Block(1,16,-4,PURPUR_BLOCK)
Block(1,16,-3,PURPUR_BLOCK)
Block(1,16,-2,PURPUR_BLOCK)
Block(1,16,-1,PURPUR_BLOCK)
Block(1,16,0,PURPUR_BLOCK)
Block(1,16,1,PURPUR_BLOCK)
Block(1,16,2,PURPUR_BLOCK)
Block(1,17,-6,PURPUR_PILLAR:0)
Block(1,17,2,PURPUR_PILLAR:0)
Block(1,18,-6,PURPUR_PILLAR:0)
Block(1,18,-5,END_ROD:3)
Block(1,18,2,PURPUR_PILLAR:0)
Block(1,19,-6,PURPUR_PILLAR:0)
Block(1,19,2,PURPUR_PILLAR:0)
Block(1,20,-6,PURPUR_BLOCK)
Block(1,20,2,PURPUR_BLOCK)
Block(1,21,-6,PURPUR_PILLAR:0)
Block(1,21,2,PURPUR_PILLAR:0)
Block(1,22,-6,PURPUR_PILLAR:0)
Block(1,22,2,PURPUR_PILLAR:0)
Block(1,23,-6,PURPUR_PILLAR:0)
Block(1,23,1,END_ROD:2)
Block(1,23,2,PURPUR_PILLAR:0)
Block(1,24,-9,PURPUR_STAIRS:6)
Block(1,24,-8,PURPUR_BLOCK)
Block(1,24,-7,PURPUR_BLOCK)
Block(1,24,-6,PURPUR_BLOCK)
Block(1,24,-5,PURPUR_BLOCK)
Block(1,24,-4,PURPUR_BLOCK)
Block(1,24,-3,PURPUR_BLOCK)
Block(1,24,2,PURPUR_BLOCK)
Block(1,24,3,PURPUR_BLOCK)
Block(1,24,4,PURPUR_BLOCK)
Block(1,24,5,PURPUR_STAIRS:7)
Block(1,25,-8,END_BRICKS)
Block(1,25,4,END_BRICKS)
Block(1,26,-8,END_BRICKS)
Block(1,26,-7,PURPUR_BLOCK)
Block(1,26,4,END_BRICKS)
Block(1,27,-8,END_BRICKS)
Block(1,27,4,END_BRICKS)
Block(1,28,-10,PURPUR_STAIRS:2)
Block(1,28,-9,PURPUR_BLOCK)
Block(1,28,-8,PURPUR_BLOCK)
Block(1,28,-6,PURPUR_BLOCK)
Block(1,28,-5,PURPUR_BLOCK)
Block(1,28,-4,PURPUR_BLOCK)
Block(1,28,-3,PURPUR_BLOCK)
Block(1,28,-2,PURPUR_BLOCK)
Block(1,28,-1,PURPUR_BLOCK)
Block(1,28,0,PURPUR_BLOCK)
Block(1,28,1,PURPUR_BLOCK)
Block(1,28,2,PURPUR_BLOCK)
Block(1,28,3,PURPUR_BLOCK)
Block(1,28,4,PURPUR_BLOCK)
Block(1,28,5,PURPUR_BLOCK)
Block(1,28,6,PURPUR_STAIRS:0)
Block(1,29,-8,PURPUR_STAIRS:2)
Block(1,29,-6,PURPUR_STAIRS:0)
Block(2,0,-4,PURPUR_BLOCK)
Block(2,0,-3,PURPUR_BLOCK)
Block(2,0,-2,PURPUR_BLOCK)
Block(2,0,-1,PURPUR_BLOCK)
Block(2,0,0,PURPUR_BLOCK)
Block(2,0,1,PURPUR_BLOCK)
Block(2,0,2,PURPUR_BLOCK)
Block(2,0,3,PURPUR_BLOCK)
Block(2,0,4,PURPUR_BLOCK)
Block(2,1,-4,END_BRICKS)
Block(2,1,3,END_BRICKS)
Block(2,2,-4,STAINED_GLASS:2)
Block(2,2,-1,PURPUR_SLAB)
Block(2,2,3,END_BRICKS)
Block(2,3,-4,STAINED_GLASS:2)
Block(2,3,3,END_BRICKS)
Block(2,4,-6,PURPUR_STAIRS:6)
Block(2,4,-5,PURPUR_BLOCK)
Block(2,4,-4,PURPUR_BLOCK)
Block(2,4,0,PURPUR_SLAB:8)
Block(2,4,3,PURPUR_BLOCK)
Block(2,4,4,PURPUR_BLOCK)
Block(2,5,-5,END_BRICKS)
Block(2,5,3,PURPUR_BLOCK)
Block(2,5,4,END_BRICKS)
Block(2,6,-5,END_BRICKS)
Block(2,6,3,PURPUR_BLOCK)
Block(2,6,4,END_BRICKS)
Block(2,7,-5,END_BRICKS)
Block(2,7,3,PURPUR_STAIRS:0)
Block(2,7,4,END_BRICKS)
Block(2,8,-7,PURPUR_STAIRS:6)
Block(2,8,-6,PURPUR_BLOCK)
Block(2,8,-5,PURPUR_BLOCK)
Block(2,8,1,PURPUR_BLOCK)
Block(2,8,4,PURPUR_BLOCK)
Block(2,8,5,PURPUR_BLOCK)
Block(2,8,6,PURPUR_STAIRS:7)
Block(2,9,-6,END_BRICKS)
Block(2,9,5,END_BRICKS)
Block(2,10,-6,STAINED_GLASS:2)
Block(2,10,5,STAINED_GLASS:2)
Block(2,11,-6,STAINED_GLASS:2)
Block(2,11,5,STAINED_GLASS:2)
Block(2,12,-8,PURPUR_STAIRS:2)
Block(2,12,-7,PURPUR_BLOCK)
Block(2,12,-6,PURPUR_BLOCK)
Block(2,12,-5,PURPUR_BLOCK)
Block(2,12,-4,PURPUR_BLOCK)
Block(2,12,-3,PURPUR_BLOCK)
Block(2,12,-2,PURPUR_BLOCK)
Block(2,12,-1,PURPUR_BLOCK)
Block(2,12,0,PURPUR_BLOCK)
Block(2,12,1,PURPUR_BLOCK)
Block(2,12,2,PURPUR_BLOCK)
Block(2,12,3,PURPUR_BLOCK)
Block(2,12,4,PURPUR_BLOCK)
Block(2,12,5,PURPUR_BLOCK)
Block(2,12,6,PURPUR_BLOCK)
Block(2,12,7,PURPUR_STAIRS:0)
Block(2,14,-2,PURPUR_STAIRS:5)
Block(2,16,-6,PURPUR_BLOCK)
Block(2,16,-5,PURPUR_BLOCK)
Block(2,16,-4,PURPUR_BLOCK)
Block(2,16,-3,PURPUR_BLOCK)
Block(2,16,-2,PURPUR_BLOCK)
Block(2,16,-1,PURPUR_BLOCK)
Block(2,16,0,PURPUR_BLOCK)
Block(2,16,1,PURPUR_BLOCK)
Block(2,16,2,PURPUR_BLOCK)
Block(2,17,-6,PURPUR_PILLAR:0)
Block(2,17,2,PURPUR_PILLAR:0)
Block(2,18,-6,PURPUR_PILLAR:0)
Block(2,18,2,PURPUR_PILLAR:0)
Block(2,19,-6,PURPUR_PILLAR:0)
Block(2,19,-4,END_ROD:4)
Block(2,19,2,PURPUR_PILLAR:0)
Block(2,20,-6,PURPUR_BLOCK)
Block(2,20,2,PURPUR_BLOCK)
Block(2,21,-6,PURPUR_PILLAR:0)
Block(2,21,2,PURPUR_PILLAR:0)
Block(2,22,-6,PURPUR_PILLAR:0)
Block(2,22,0,END_ROD:4)
Block(2,22,2,PURPUR_PILLAR:0)
Block(2,23,-6,PURPUR_PILLAR:0)
Block(2,23,2,PURPUR_PILLAR:0)
Block(2,24,-9,PURPUR_STAIRS:6)
Block(2,24,-8,PURPUR_BLOCK)
Block(2,24,-7,PURPUR_BLOCK)
Block(2,24,-6,PURPUR_BLOCK)
Block(2,24,-5,PURPUR_BLOCK)
Block(2,24,-4,PURPUR_BLOCK)
Block(2,24,-3,PURPUR_BLOCK)
Block(2,24,2,PURPUR_BLOCK)
Block(2,24,3,PURPUR_BLOCK)
Block(2,24,4,PURPUR_BLOCK)
Block(2,24,5,PURPUR_STAIRS:7)
Block(2,25,-8,END_BRICKS)
Block(2,25,4,END_BRICKS)
Block(2,26,-8,END_BRICKS)
Block(2,26,-7,PURPUR_SLAB:8)
Block(2,26,4,END_BRICKS)
Block(2,27,-8,END_BRICKS)
Block(2,27,-7,PURPUR_SLAB)
Block(2,27,4,END_BRICKS)
Block(2,28,-10,PURPUR_STAIRS:6)
Block(2,28,-9,PURPUR_BLOCK)
Block(2,28,-8,PURPUR_BLOCK)
Block(2,28,-6,PURPUR_BLOCK)
Block(2,28,-5,PURPUR_BLOCK)
Block(2,28,-4,PURPUR_BLOCK)
Block(2,28,-3,PURPUR_BLOCK)
Block(2,28,-2,PURPUR_BLOCK)
Block(2,28,-1,PURPUR_BLOCK)
Block(2,28,0,PURPUR_BLOCK)
Block(2,28,1,PURPUR_BLOCK)
Block(2,28,2,PURPUR_BLOCK)
Block(2,28,3,PURPUR_BLOCK)
Block(2,28,4,PURPUR_BLOCK)
Block(2,28,5,PURPUR_BLOCK)
Block(2,28,6,PURPUR_STAIRS:7)
Block(2,29,-8,PURPUR_STAIRS:2)
Block(2,29,-6,PURPUR_STAIRS:0)
Block(3,0,-4,PURPUR_BLOCK)
Block(3,0,-3,PURPUR_BLOCK)
Block(3,0,-2,PURPUR_BLOCK)
Block(3,0,-1,PURPUR_BLOCK)
Block(3,0,0,PURPUR_BLOCK)
Block(3,0,1,PURPUR_BLOCK)
Block(3,0,2,PURPUR_BLOCK)
Block(3,0,3,PURPUR_BLOCK)
Block(3,0,4,PURPUR_STAIRS:0)
Block(3,1,-4,END_BRICKS)
Block(3,1,3,END_BRICKS)
Block(3,2,-4,END_BRICKS)
Block(3,2,3,END_BRICKS)
Block(3,3,-4,END_BRICKS)
Block(3,3,3,END_BRICKS)
Block(3,4,-6,PURPUR_STAIRS:6)
Block(3,4,-5,PURPUR_BLOCK)
Block(3,4,-4,PURPUR_BLOCK)
Block(3,4,0,PURPUR_SLAB:8)
Block(3,4,3,PURPUR_BLOCK)
Block(3,4,4,PURPUR_BLOCK)
Block(3,5,-5,END_BRICKS)
Block(3,5,3,PURPUR_BLOCK)
Block(3,5,4,END_BRICKS)
Block(3,6,-5,STAINED_GLASS:2)
Block(3,6,3,PURPUR_BLOCK)
Block(3,6,4,END_BRICKS)
Block(3,7,-5,STAINED_GLASS:2)
Block(3,7,1,PURPUR_SLAB:8)
Block(3,7,2,PURPUR_SLAB:8)
Block(3,7,3,PURPUR_BLOCK)
Block(3,7,4,END_BRICKS)
Block(3,8,-7,PURPUR_STAIRS:6)
Block(3,8,-6,PURPUR_BLOCK)
Block(3,8,-5,PURPUR_BLOCK)
Block(3,8,3,PURPUR_STAIRS:0)
Block(3,8,4,PURPUR_BLOCK)
Block(3,8,5,PURPUR_BLOCK)
Block(3,8,6,PURPUR_STAIRS:7)
Block(3,9,-6,END_BRICKS)
Block(3,9,5,END_BRICKS)
Block(3,10,-6,END_BRICKS)
Block(3,10,1,PURPUR_BLOCK)
Block(3,10,5,END_BRICKS)
Block(3,11,-6,END_BRICKS)
Block(3,11,5,END_BRICKS)
Block(3,12,-8,PURPUR_STAIRS:6)
Block(3,12,-7,PURPUR_BLOCK)
Block(3,12,-6,PURPUR_BLOCK)
Block(3,12,-5,PURPUR_BLOCK)
Block(3,12,-4,PURPUR_BLOCK)
Block(3,12,-3,PURPUR_BLOCK)
Block(3,12,-2,PURPUR_BLOCK)
Block(3,12,-1,PURPUR_BLOCK)
Block(3,12,0,PURPUR_BLOCK)
Block(3,12,1,PURPUR_BLOCK)
Block(3,12,2,PURPUR_BLOCK)
Block(3,12,3,PURPUR_BLOCK)
Block(3,12,4,PURPUR_BLOCK)
Block(3,12,5,PURPUR_BLOCK)
Block(3,12,6,PURPUR_BLOCK)
Block(3,12,7,PURPUR_STAIRS:7)
Block(3,16,-5,PURPUR_BLOCK)
Block(3,16,-4,PURPUR_BLOCK)
Block(3,16,-3,PURPUR_BLOCK)
Block(3,16,-2,PURPUR_BLOCK)
Block(3,16,-1,PURPUR_BLOCK)
Block(3,16,0,PURPUR_BLOCK)
Block(3,16,1,PURPUR_BLOCK)
Block(3,17,-5,PURPUR_PILLAR:0)
Block(3,17,-4,PURPUR_PILLAR:0)
Block(3,17,0,PURPUR_PILLAR:0)
Block(3,17,1,PURPUR_PILLAR:0)
Block(3,18,-5,PURPUR_PILLAR:0)
Block(3,18,-4,PURPUR_PILLAR:0)
Block(3,18,0,PURPUR_PILLAR:0)
Block(3,18,1,PURPUR_PILLAR:0)
Block(3,19,-5,PURPUR_PILLAR:0)
Block(3,19,-4,PURPUR_PILLAR:0)
Block(3,19,0,PURPUR_PILLAR:0)
Block(3,19,1,PURPUR_PILLAR:0)
Block(3,20,-5,PURPUR_BLOCK)
Block(3,20,-4,PURPUR_BLOCK)
Block(3,20,-3,PURPUR_SLAB)
Block(3,20,0,PURPUR_BLOCK)
Block(3,20,1,PURPUR_BLOCK)
Block(3,21,-5,PURPUR_PILLAR:0)
Block(3,21,-4,PURPUR_PILLAR:0)
Block(3,21,-1,PURPUR_SLAB)
Block(3,21,0,PURPUR_PILLAR:0)
Block(3,21,1,PURPUR_PILLAR:0)
Block(3,22,-5,PURPUR_PILLAR:0)
Block(3,22,-4,PURPUR_PILLAR:0)
Block(3,22,0,PURPUR_PILLAR:0)
Block(3,22,1,PURPUR_PILLAR:0)
Block(3,23,-5,PURPUR_PILLAR:0)
Block(3,23,-4,PURPUR_PILLAR:0)
Block(3,23,0,PURPUR_PILLAR:0)
Block(3,23,1,PURPUR_PILLAR:0)
Block(3,24,-9,PURPUR_STAIRS:2)
Block(3,24,-8,PURPUR_BLOCK)
Block(3,24,-7,PURPUR_BLOCK)
Block(3,24,-6,PURPUR_BLOCK)
Block(3,24,-5,PURPUR_BLOCK)
Block(3,24,-4,PURPUR_BLOCK)
Block(3,24,-3,PURPUR_BLOCK)
Block(3,24,0,PURPUR_BLOCK)
Block(3,24,1,PURPUR_BLOCK)
Block(3,24,2,PURPUR_BLOCK)
Block(3,24,3,PURPUR_BLOCK)
Block(3,24,4,PURPUR_BLOCK)
Block(3,24,5,PURPUR_STAIRS:0)
Block(3,25,-8,END_BRICKS)
Block(3,25,4,END_BRICKS)
Block(3,26,-8,END_BRICKS)
Block(3,26,4,STAINED_GLASS:2)
Block(3,27,-8,END_BRICKS)
Block(3,27,-7,PURPUR_BLOCK)
Block(3,27,4,STAINED_GLASS:2)
Block(3,28,-10,PURPUR_STAIRS:6)
Block(3,28,-9,PURPUR_BLOCK)
Block(3,28,-8,PURPUR_BLOCK)
Block(3,28,-6,PURPUR_BLOCK)
Block(3,28,-5,PURPUR_BLOCK)
Block(3,28,-4,PURPUR_BLOCK)
Block(3,28,-3,PURPUR_BLOCK)
Block(3,28,-2,PURPUR_BLOCK)
Block(3,28,-1,PURPUR_BLOCK)
Block(3,28,0,PURPUR_BLOCK)
Block(3,28,1,PURPUR_BLOCK)
Block(3,28,2,PURPUR_BLOCK)
Block(3,28,3,PURPUR_BLOCK)
Block(3,28,4,PURPUR_BLOCK)
Block(3,28,5,PURPUR_BLOCK)
Block(3,28,6,PURPUR_STAIRS:7)
Block(4,0,-4,PURPUR_BLOCK)
Block(4,0,-3,PURPUR_BLOCK)
Block(4,0,-2,PURPUR_BLOCK)
Block(4,0,-1,PURPUR_BLOCK)
Block(4,0,0,PURPUR_BLOCK)
Block(4,0,1,PURPUR_BLOCK)
Block(4,0,2,PURPUR_BLOCK)
Block(4,0,3,PURPUR_BLOCK)
Block(4,1,-4,PURPUR_PILLAR:0)
Block(4,1,-3,END_BRICKS)
Block(4,1,-2,END_BRICKS)
Block(4,1,-1,END_BRICKS)
Block(4,1,0,END_BRICKS)
Block(4,1,1,END_BRICKS)
Block(4,1,2,END_BRICKS)
Block(4,1,3,PURPUR_PILLAR:0)
Block(4,2,-4,PURPUR_PILLAR:0)
Block(4,2,-3,END_BRICKS)
Block(4,2,-2,STAINED_GLASS:2)
Block(4,2,-1,END_BRICKS)
Block(4,2,0,END_BRICKS)
Block(4,2,1,STAINED_GLASS:2)
Block(4,2,2,END_BRICKS)
Block(4,2,3,PURPUR_PILLAR:0)
Block(4,3,-4,PURPUR_PILLAR:0)
Block(4,3,-3,END_BRICKS)
Block(4,3,-2,STAINED_GLASS:2)
Block(4,3,-1,END_BRICKS)
Block(4,3,0,END_BRICKS)
Block(4,3,1,STAINED_GLASS:2)
Block(4,3,2,END_BRICKS)
Block(4,3,3,PURPUR_PILLAR:0)
Block(4,4,-6,PURPUR_STAIRS:2)
Block(4,4,-5,PURPUR_BLOCK)
Block(4,4,-4,PURPUR_BLOCK)
Block(4,4,-3,PURPUR_BLOCK)
Block(4,4,-2,PURPUR_BLOCK)
Block(4,4,-1,PURPUR_BLOCK)
Block(4,4,0,PURPUR_BLOCK)
Block(4,4,1,PURPUR_BLOCK)
Block(4,4,2,PURPUR_BLOCK)
Block(4,4,3,PURPUR_BLOCK)
Block(4,4,4,PURPUR_BLOCK)
Block(4,4,5,PURPUR_STAIRS:0)
Block(4,5,-5,END_BRICKS)
Block(4,5,1,PURPUR_STAIRS:4)
Block(4,5,2,PURPUR_STAIRS:4)
Block(4,5,4,END_BRICKS)
Block(4,6,-5,END_BRICKS)
Block(4,6,1,PURPUR_STAIRS:0)
Block(4,6,2,PURPUR_STAIRS:0)
Block(4,6,4,END_BRICKS)
Block(4,7,-5,END_BRICKS)
Block(4,7,1,PURPUR_STAIRS:4)
Block(4,7,2,PURPUR_STAIRS:4)
Block(4,7,4,END_BRICKS)
Block(4,8,-7,PURPUR_STAIRS:2)
Block(4,8,-6,PURPUR_BLOCK)
Block(4,8,-5,PURPUR_BLOCK)
Block(4,8,3,PURPUR_BLOCK)
Block(4,8,4,PURPUR_BLOCK)
Block(4,8,5,PURPUR_BLOCK)
Block(4,8,6,PURPUR_STAIRS:0)
Block(4,9,-6,END_BRICKS)
Block(4,9,5,END_BRICKS)
Block(4,10,-6,STAINED_GLASS:2)
Block(4,10,1,PURPUR_BLOCK)
Block(4,10,5,STAINED_GLASS:2)
Block(4,11,-6,STAINED_GLASS:2)
Block(4,11,5,STAINED_GLASS:2)
Block(4,12,-8,PURPUR_STAIRS:6)
Block(4,12,-7,PURPUR_BLOCK)
Block(4,12,-6,PURPUR_BLOCK)
Block(4,12,-5,PURPUR_BLOCK)
Block(4,12,-4,PURPUR_BLOCK)
Block(4,12,-3,PURPUR_BLOCK)
Block(4,12,-2,PURPUR_BLOCK)
Block(4,12,-1,PURPUR_BLOCK)
Block(4,12,0,PURPUR_BLOCK)
Block(4,12,1,PURPUR_BLOCK)
Block(4,12,2,PURPUR_BLOCK)
Block(4,12,3,PURPUR_BLOCK)
Block(4,12,4,PURPUR_BLOCK)
Block(4,12,5,PURPUR_BLOCK)
Block(4,12,6,PURPUR_BLOCK)
Block(4,12,7,PURPUR_STAIRS:7)
Block(4,16,-3,PURPUR_BLOCK)
Block(4,16,-2,PURPUR_BLOCK)
Block(4,16,-1,PURPUR_BLOCK)
Block(4,17,-3,PURPUR_PILLAR:0)
Block(4,17,-2,PURPUR_PILLAR:0)
Block(4,17,-1,PURPUR_PILLAR:0)
Block(4,18,-3,PURPUR_PILLAR:0)
Block(4,18,-2,PURPUR_PILLAR)
Block(4,18,-1,PURPUR_PILLAR:0)
Block(4,19,-3,PURPUR_PILLAR:0)
Block(4,19,-2,PURPUR_PILLAR:0)
Block(4,19,-1,PURPUR_PILLAR:0)
Block(4,20,-3,PURPUR_BLOCK)
Block(4,20,-2,PURPUR_BLOCK)
Block(4,20,-1,PURPUR_BLOCK)
Block(4,21,-3,PURPUR_PILLAR:0)
Block(4,21,-2,PURPUR_PILLAR:0)
Block(4,21,-1,PURPUR_PILLAR:0)
Block(4,22,-3,PURPUR_PILLAR:0)
Block(4,22,-2,PURPUR_PILLAR)
Block(4,22,-1,PURPUR_PILLAR:0)
Block(4,23,-3,PURPUR_PILLAR:0)
Block(4,23,-2,PURPUR_PILLAR:0)
Block(4,23,-1,PURPUR_PILLAR:0)
Block(4,24,-9,PURPUR_STAIRS:2)
Block(4,24,-8,PURPUR_BLOCK)
Block(4,24,-7,PURPUR_BLOCK)
Block(4,24,-6,PURPUR_BLOCK)
Block(4,24,-5,PURPUR_BLOCK)
Block(4,24,-4,PURPUR_BLOCK)
Block(4,24,-3,PURPUR_BLOCK)
Block(4,24,-2,PURPUR_BLOCK)
Block(4,24,-1,PURPUR_BLOCK)
Block(4,24,0,PURPUR_BLOCK)
Block(4,24,1,PURPUR_BLOCK)
Block(4,24,2,PURPUR_BLOCK)
Block(4,24,3,PURPUR_BLOCK)
Block(4,24,4,PURPUR_BLOCK)
Block(4,24,5,PURPUR_STAIRS:0)
Block(4,25,-8,END_BRICKS)
Block(4,25,4,END_BRICKS)
Block(4,26,-8,END_BRICKS)
Block(4,26,4,END_BRICKS)
Block(4,27,-8,END_BRICKS)
Block(4,27,-7,PURPUR_SLAB:8)
Block(4,27,4,END_BRICKS)
Block(4,28,-10,PURPUR_STAIRS:2)
Block(4,28,-9,PURPUR_BLOCK)
Block(4,28,-8,PURPUR_BLOCK)
Block(4,28,-7,PURPUR_SLAB)
Block(4,28,-6,PURPUR_BLOCK)
Block(4,28,-5,PURPUR_BLOCK)
Block(4,28,-4,PURPUR_BLOCK)
Block(4,28,-3,PURPUR_BLOCK)
Block(4,28,-2,PURPUR_BLOCK)
Block(4,28,-1,PURPUR_BLOCK)
Block(4,28,0,PURPUR_BLOCK)
Block(4,28,1,PURPUR_BLOCK)
Block(4,28,2,PURPUR_BLOCK)
Block(4,28,3,PURPUR_BLOCK)
Block(4,28,4,PURPUR_BLOCK)
Block(4,28,5,PURPUR_BLOCK)
Block(4,28,6,PURPUR_STAIRS:0)
Block(5,4,-6,PURPUR_STAIRS:6)
Block(5,4,-5,PURPUR_BLOCK)
Block(5,4,-4,PURPUR_BLOCK)
Block(5,4,-3,PURPUR_BLOCK)
Block(5,4,-2,PURPUR_BLOCK)
Block(5,4,-1,PURPUR_BLOCK)
Block(5,4,0,PURPUR_BLOCK)
Block(5,4,1,PURPUR_BLOCK)
Block(5,4,2,PURPUR_BLOCK)
Block(5,4,3,PURPUR_BLOCK)
Block(5,4,4,PURPUR_BLOCK)
Block(5,4,5,PURPUR_STAIRS:7)
Block(5,5,-5,PURPUR_PILLAR:0)
Block(5,5,-4,END_BRICKS)
Block(5,5,-3,END_BRICKS)
Block(5,5,-2,END_BRICKS)
Block(5,5,-1,END_BRICKS)
Block(5,5,0,END_BRICKS)
Block(5,5,1,END_BRICKS)
Block(5,5,2,END_BRICKS)
Block(5,5,3,END_BRICKS)
Block(5,5,4,PURPUR_PILLAR:0)
Block(5,6,-5,PURPUR_PILLAR:0)
Block(5,6,-4,END_BRICKS)
Block(5,6,-3,STAINED_GLASS:2)
Block(5,6,-2,END_BRICKS)
Block(5,6,-1,END_BRICKS)
Block(5,6,0,END_BRICKS)
Block(5,6,1,END_BRICKS)
Block(5,6,2,END_BRICKS)
Block(5,6,3,END_BRICKS)
Block(5,6,4,PURPUR_PILLAR:0)
Block(5,7,-5,PURPUR_PILLAR:0)
Block(5,7,-4,END_BRICKS)
Block(5,7,-3,STAINED_GLASS:2)
Block(5,7,-2,END_BRICKS)
Block(5,7,-1,END_BRICKS)
Block(5,7,0,END_BRICKS)
Block(5,7,1,END_BRICKS)
Block(5,7,2,END_BRICKS)
Block(5,7,3,END_BRICKS)
Block(5,7,4,PURPUR_PILLAR:0)
Block(5,8,-7,PURPUR_STAIRS:2)
Block(5,8,-6,PURPUR_BLOCK)
Block(5,8,-5,PURPUR_BLOCK)
Block(5,8,-4,PURPUR_BLOCK)
Block(5,8,-3,PURPUR_BLOCK)
Block(5,8,-2,PURPUR_BLOCK)
Block(5,8,-1,PURPUR_BLOCK)
Block(5,8,0,PURPUR_BLOCK)
Block(5,8,1,PURPUR_BLOCK)
Block(5,8,2,PURPUR_BLOCK)
Block(5,8,3,PURPUR_BLOCK)
Block(5,8,4,PURPUR_BLOCK)
Block(5,8,5,PURPUR_BLOCK)
Block(5,8,6,PURPUR_STAIRS:0)
Block(5,9,-6,END_BRICKS)
Block(5,9,-1,PURPUR_BLOCK)
Block(5,9,1,PURPUR_BLOCK)
Block(5,9,3,PURPUR_BLOCK)
Block(5,9,5,END_BRICKS)
Block(5,10,-6,END_BRICKS)
Block(5,10,-1,PURPUR_BLOCK)
Block(5,10,1,PURPUR_BLOCK)
Block(5,10,3,PURPUR_BLOCK)
Block(5,10,5,END_BRICKS)
Block(5,11,-6,END_BRICKS)
Block(5,11,-1,PURPUR_BLOCK)
Block(5,11,1,PURPUR_BLOCK)
Block(5,11,3,PURPUR_BLOCK)
Block(5,11,5,END_BRICKS)
Block(5,12,-8,PURPUR_STAIRS:2)
Block(5,12,-7,PURPUR_BLOCK)
Block(5,12,-6,PURPUR_BLOCK)
Block(5,12,-5,PURPUR_BLOCK)
Block(5,12,-4,PURPUR_BLOCK)
Block(5,12,-3,PURPUR_BLOCK)
Block(5,12,-2,PURPUR_BLOCK)
Block(5,12,-1,PURPUR_BLOCK)
Block(5,12,0,PURPUR_BLOCK)
Block(5,12,1,PURPUR_BLOCK)
Block(5,12,2,PURPUR_BLOCK)
Block(5,12,3,PURPUR_BLOCK)
Block(5,12,4,PURPUR_BLOCK)
Block(5,12,5,PURPUR_BLOCK)
Block(5,12,6,PURPUR_BLOCK)
Block(5,12,7,PURPUR_STAIRS:0)
Block(5,18,-2,PURPUR_STAIRS:5)
Block(5,22,-2,PURPUR_STAIRS:5)
Block(5,24,-9,PURPUR_STAIRS:6)
Block(5,24,-8,PURPUR_BLOCK)
Block(5,24,-7,PURPUR_BLOCK)
Block(5,24,-6,PURPUR_BLOCK)
Block(5,24,-5,PURPUR_BLOCK)
Block(5,24,-4,PURPUR_BLOCK)
Block(5,24,-3,PURPUR_BLOCK)
Block(5,24,-2,PURPUR_BLOCK)
Block(5,24,-1,PURPUR_BLOCK)
Block(5,24,0,PURPUR_BLOCK)
Block(5,24,1,PURPUR_BLOCK)
Block(5,24,2,PURPUR_BLOCK)
Block(5,24,3,PURPUR_BLOCK)
Block(5,24,4,PURPUR_BLOCK)
Block(5,24,5,PURPUR_STAIRS:7)
Block(5,25,-8,PURPUR_PILLAR:0)
Block(5,25,-7,END_BRICKS)
Block(5,25,-6,END_BRICKS)
Block(5,25,-5,END_BRICKS)
Block(5,25,-4,END_BRICKS)
Block(5,25,-3,END_BRICKS)
Block(5,25,-2,END_BRICKS)
Block(5,25,-1,END_BRICKS)
Block(5,25,0,END_BRICKS)
Block(5,25,1,END_BRICKS)
Block(5,25,2,END_BRICKS)
Block(5,25,3,END_BRICKS)
Block(5,25,4,PURPUR_PILLAR:0)
Block(5,26,-8,PURPUR_PILLAR:0)
Block(5,26,-7,END_BRICKS)
Block(5,26,-6,END_BRICKS)
Block(5,26,-5,END_BRICKS)
Block(5,26,-4,END_BRICKS)
Block(5,26,-3,STAINED_GLASS:2)
Block(5,26,-2,END_BRICKS)
Block(5,26,-1,STAINED_GLASS:2)
Block(5,26,0,END_BRICKS)
Block(5,26,1,END_BRICKS)
Block(5,26,2,STAINED_GLASS:2)
Block(5,26,3,END_BRICKS)
Block(5,26,4,PURPUR_PILLAR:0)
Block(5,27,-8,PURPUR_PILLAR:0)
Block(5,27,-7,END_BRICKS)
Block(5,27,-6,END_BRICKS)
Block(5,27,-5,END_BRICKS)
Block(5,27,-4,END_BRICKS)
Block(5,27,-3,STAINED_GLASS:2)
Block(5,27,-2,END_BRICKS)
Block(5,27,-1,STAINED_GLASS:2)
Block(5,27,0,END_BRICKS)
Block(5,27,1,END_BRICKS)
Block(5,27,2,STAINED_GLASS:2)
Block(5,27,3,END_BRICKS)
Block(5,27,4,PURPUR_PILLAR:0)
Block(5,28,-10,PURPUR_STAIRS:2)
Block(5,28,-9,PURPUR_BLOCK)
Block(5,28,-8,PURPUR_BLOCK)
Block(5,28,-7,PURPUR_BLOCK)
Block(5,28,-6,PURPUR_BLOCK)
Block(5,28,-5,PURPUR_BLOCK)
Block(5,28,-4,PURPUR_BLOCK)
Block(5,28,-3,PURPUR_BLOCK)
Block(5,28,-2,PURPUR_BLOCK)
Block(5,28,-1,PURPUR_BLOCK)
Block(5,28,0,PURPUR_BLOCK)
Block(5,28,1,PURPUR_BLOCK)
Block(5,28,2,PURPUR_BLOCK)
Block(5,28,3,PURPUR_BLOCK)
Block(5,28,4,PURPUR_BLOCK)
Block(5,28,5,PURPUR_BLOCK)
Block(5,28,6,PURPUR_STAIRS:0)
Block(6,4,-6,PURPUR_STAIRS:6)
Block(6,4,-5,PURPUR_STAIRS:5)
Block(6,4,-4,PURPUR_STAIRS:1)
Block(6,4,-3,PURPUR_STAIRS:5)
Block(6,4,-2,PURPUR_STAIRS:5)
Block(6,4,-1,PURPUR_STAIRS:1)
Block(6,4,0,PURPUR_STAIRS:1)
Block(6,4,1,PURPUR_STAIRS:5)
Block(6,4,2,PURPUR_STAIRS:5)
Block(6,4,3,PURPUR_STAIRS:1)
Block(6,4,4,PURPUR_STAIRS:5)
Block(6,4,5,PURPUR_STAIRS:5)
Block(6,5,-6,END_ROD)
Block(6,5,5,END_ROD)
Block(6,8,-7,PURPUR_STAIRS:6)
Block(6,8,-6,PURPUR_BLOCK)
Block(6,8,-5,PURPUR_BLOCK)
Block(6,8,-4,PURPUR_BLOCK)
Block(6,8,-3,PURPUR_BLOCK)
Block(6,8,-2,PURPUR_BLOCK)
Block(6,8,-1,PURPUR_BLOCK)
Block(6,8,0,PURPUR_BLOCK)
Block(6,8,1,PURPUR_BLOCK)
Block(6,8,2,PURPUR_BLOCK)
Block(6,8,3,PURPUR_BLOCK)
Block(6,8,4,PURPUR_BLOCK)
Block(6,8,5,PURPUR_BLOCK)
Block(6,8,6,PURPUR_STAIRS:7)
Block(6,9,-6,PURPUR_PILLAR:0)
Block(6,9,-5,END_BRICKS)
Block(6,9,-4,END_BRICKS)
Block(6,9,-3,END_BRICKS)
Block(6,9,-2,END_BRICKS)
Block(6,9,-1,END_BRICKS)
Block(6,9,0,END_BRICKS)
Block(6,9,1,END_BRICKS)
Block(6,9,2,END_BRICKS)
Block(6,9,3,END_BRICKS)
Block(6,9,4,END_BRICKS)
Block(6,9,5,PURPUR_PILLAR:0)
Block(6,10,-6,PURPUR_PILLAR:0)
Block(6,10,-5,END_BRICKS)
Block(6,10,-4,STAINED_GLASS:2)
Block(6,10,-3,END_BRICKS)
Block(6,10,-2,STAINED_GLASS:2)
Block(6,10,-1,END_BRICKS)
Block(6,10,0,END_BRICKS)
Block(6,10,1,END_BRICKS)
Block(6,10,2,END_BRICKS)
Block(6,10,3,END_BRICKS)
Block(6,10,4,END_BRICKS)
Block(6,10,5,PURPUR_PILLAR:0)
Block(6,11,-6,PURPUR_PILLAR:0)
Block(6,11,-5,END_BRICKS)
Block(6,11,-4,STAINED_GLASS:2)
Block(6,11,-3,END_BRICKS)
Block(6,11,-2,STAINED_GLASS:2)
Block(6,11,-1,END_BRICKS)
Block(6,11,0,END_BRICKS)
Block(6,11,1,END_BRICKS)
Block(6,11,2,END_BRICKS)
Block(6,11,3,END_BRICKS)
Block(6,11,4,END_BRICKS)
Block(6,11,5,PURPUR_PILLAR:0)
Block(6,12,-8,PURPUR_STAIRS:2)
Block(6,12,-7,PURPUR_BLOCK)
Block(6,12,-6,PURPUR_BLOCK)
Block(6,12,-5,PURPUR_BLOCK)
Block(6,12,-4,PURPUR_BLOCK)
Block(6,12,-3,PURPUR_BLOCK)
Block(6,12,-2,PURPUR_BLOCK)
Block(6,12,-1,PURPUR_BLOCK)
Block(6,12,0,PURPUR_BLOCK)
Block(6,12,1,PURPUR_BLOCK)
Block(6,12,2,PURPUR_BLOCK)
Block(6,12,3,PURPUR_BLOCK)
Block(6,12,4,PURPUR_BLOCK)
Block(6,12,5,PURPUR_BLOCK)
Block(6,12,6,PURPUR_BLOCK)
Block(6,12,7,PURPUR_STAIRS:0)
Block(6,24,-9,PURPUR_STAIRS:6)
Block(6,24,-8,PURPUR_STAIRS:5)
Block(6,24,-7,PURPUR_STAIRS:1)
Block(6,24,-6,PURPUR_STAIRS:1)
Block(6,24,-5,PURPUR_STAIRS:5)
Block(6,24,-4,PURPUR_STAIRS:5)
Block(6,24,-3,PURPUR_STAIRS:1)
Block(6,24,-2,PURPUR_STAIRS:1)
Block(6,24,-1,PURPUR_STAIRS:1)
Block(6,24,0,PURPUR_STAIRS:5)
Block(6,24,1,PURPUR_STAIRS:5)
Block(6,24,2,PURPUR_STAIRS:1)
Block(6,24,3,PURPUR_STAIRS:1)
Block(6,24,4,PURPUR_STAIRS:5)
Block(6,24,5,PURPUR_STAIRS:5)
Block(6,25,-9,END_ROD)
Block(6,25,5,END_ROD)
Block(6,28,-10,PURPUR_STAIRS:6)
Block(6,28,-9,PURPUR_BLOCK)
Block(6,28,-8,PURPUR_BLOCK)
Block(6,28,-7,PURPUR_BLOCK)
Block(6,28,-6,PURPUR_BLOCK)
Block(6,28,-5,PURPUR_BLOCK)
Block(6,28,-4,PURPUR_BLOCK)
Block(6,28,-3,PURPUR_BLOCK)
Block(6,28,-2,PURPUR_BLOCK)
Block(6,28,-1,PURPUR_BLOCK)
Block(6,28,0,PURPUR_BLOCK)
Block(6,28,1,PURPUR_BLOCK)
Block(6,28,2,PURPUR_BLOCK)
Block(6,28,3,PURPUR_BLOCK)
Block(6,28,4,PURPUR_BLOCK)
Block(6,28,5,PURPUR_BLOCK)
Block(6,28,6,PURPUR_STAIRS:7)
Block(7,8,-7,PURPUR_STAIRS:6)
Block(7,8,-6,PURPUR_STAIRS:5)
Block(7,8,-5,PURPUR_STAIRS:1)
Block(7,8,-4,PURPUR_STAIRS:1)
Block(7,8,-3,PURPUR_STAIRS:5)
Block(7,8,-2,PURPUR_STAIRS:5)
Block(7,8,-1,PURPUR_STAIRS:1)
Block(7,8,0,PURPUR_STAIRS:1)
Block(7,8,1,PURPUR_STAIRS:5)
Block(7,8,2,PURPUR_STAIRS:5)
Block(7,8,3,PURPUR_STAIRS:1)
Block(7,8,4,PURPUR_STAIRS:1)
Block(7,8,5,PURPUR_STAIRS:5)
Block(7,8,6,PURPUR_STAIRS:5)
Block(7,9,-7,END_ROD)
Block(7,9,6,END_ROD)
Block(7,12,-8,PURPUR_STAIRS:6)
Block(7,12,-7,PURPUR_BLOCK)
Block(7,12,-6,PURPUR_BLOCK)
Block(7,12,-5,PURPUR_BLOCK)
Block(7,12,-4,PURPUR_BLOCK)
Block(7,12,-3,PURPUR_BLOCK)
Block(7,12,-2,PURPUR_BLOCK)
Block(7,12,-1,PURPUR_BLOCK)
Block(7,12,0,PURPUR_BLOCK)
Block(7,12,1,PURPUR_BLOCK)
Block(7,12,2,PURPUR_BLOCK)
Block(7,12,3,PURPUR_BLOCK)
Block(7,12,4,PURPUR_BLOCK)
Block(7,12,5,PURPUR_BLOCK)
Block(7,12,6,PURPUR_BLOCK)
Block(7,12,7,PURPUR_STAIRS:7)
Block(7,13,-7,END_ROD)
Block(7,13,6,END_ROD)
Block(7,28,-10,PURPUR_STAIRS:6)
Block(7,28,-9,PURPUR_STAIRS:5)
Block(7,28,-8,PURPUR_STAIRS:1)
Block(7,28,-7,PURPUR_STAIRS:1)
Block(7,28,-6,PURPUR_STAIRS:5)
Block(7,28,-5,PURPUR_STAIRS:5)
Block(7,28,-4,PURPUR_STAIRS:1)
Block(7,28,-3,PURPUR_STAIRS:1)
Block(7,28,-2,PURPUR_STAIRS:5)
Block(7,28,-1,PURPUR_STAIRS:1)
Block(7,28,0,PURPUR_STAIRS:1)
Block(7,28,1,PURPUR_STAIRS:5)
Block(7,28,2,PURPUR_STAIRS:5)
Block(7,28,3,PURPUR_STAIRS:1)
Block(7,28,4,PURPUR_STAIRS:1)
Block(7,28,5,PURPUR_STAIRS:5)
Block(7,28,6,PURPUR_STAIRS:5)
Block(8,12,-8,PURPUR_STAIRS:5)
Block(8,12,-7,PURPUR_STAIRS:5)
Block(8,12,-6,PURPUR_STAIRS:1)
Block(8,12,-5,PURPUR_STAIRS:1)
Block(8,12,-4,PURPUR_STAIRS:5)
Block(8,12,-3,PURPUR_STAIRS:5)
Block(8,12,-2,PURPUR_STAIRS:1)
Block(8,12,-1,PURPUR_STAIRS:5)
Block(8,12,0,PURPUR_STAIRS:5)
Block(8,12,1,PURPUR_STAIRS:1)
Block(8,12,2,PURPUR_STAIRS:5)
Block(8,12,3,PURPUR_STAIRS:5)
Block(8,12,4,PURPUR_STAIRS:1)
Block(8,12,5,PURPUR_STAIRS:1)
Block(8,12,6,PURPUR_STAIRS:5)
Block(8,12,7,PURPUR_STAIRS:7)

#######################################################################
# +-----------------------------------------------------------------+ #
# |                            BO3 checks                           | #
# +-----------------------------------------------------------------+ #
#######################################################################


#######################################################################
# +-----------------------------------------------------------------+ #
# |                             Branches                            | #
# +-----------------------------------------------------------------+ #
#######################################################################


#######################################################################
# +-----------------------------------------------------------------+ #
# |                             Entities                            | #
# +-----------------------------------------------------------------+ #
#######################################################################

Entity(-6,25,2,SHULKER,1)
Entity(-5,22,-2,SHULKER,1)
Entity(-4,9,-5,SHULKER,1)
Entity(-3,25,-7,SHULKER,1)
Entity(-1,2,4,SHULKER,1)
Entity(-1,12,-3,SHULKER,1)
Entity(-1,22,-6,SHULKER,1)
Entity(-1,22,2,SHULKER,1)
Entity(2,2,4,SHULKER,1)
Entity(2,10,1,SHULKER,1)
Entity(3,22,-2,SHULKER,1)
Entity(5,9,-5,SHULKER,1)

#######################################################################
# +-----------------------------------------------------------------+ #
# |                            Particles                            | #
# +-----------------------------------------------------------------+ #
#######################################################################


#######################################################################
# +-----------------------------------------------------------------+ #
# |                             Spawners                            | #
# +-----------------------------------------------------------------+ #
#######################################################################


#######################################################################
# +-----------------------------------------------------------------+ #
# |                             ModData                             | #
# +-----------------------------------------------------------------+ #
#######################################################################

