
#######################################################################
# +-----------------------------------------------------------------+ #
# |                            BO3 object                           | #
# +-----------------------------------------------------------------+ #
#######################################################################

Author: totemo

Description: No description given

Version: 3

SettingsMode: WriteWithoutComments


#######################################################################
# +-----------------------------------------------------------------+ #
# |                          Main settings                          | #
# +-----------------------------------------------------------------+ #
#######################################################################

Tree: false

Frequency: 0

Rarity: 100.0

RotateRandomly: true

SpawnHeight: highestBlock

SpawnHeightOffset: 0

SpawnHeightVariance: 0

##############################
# Height Limits for the BO3. #
##############################

MinHeight: 0

MaxHeight: 256

######################
# Extrusion settings #
######################

ExtrudeMode: None

ExtrudeThroughBlocks: AIR

MaxBranchDepth: 10

ExcludedBiomes: All


#######################################################################
# +-----------------------------------------------------------------+ #
# |                      Source block settings                      | #
# +-----------------------------------------------------------------+ #
#######################################################################

SourceBlocks: AIR

MaxPercentageOutsideSourceBlock: 10

OutsideSourceBlock: placeAnyway

IsOTGPlus: false


#######################################################################
# +-----------------------------------------------------------------+ #
# |                              Blocks                             | #
# +-----------------------------------------------------------------+ #
#######################################################################

Block(-8,12,-8,PURPUR_STAIRS:6)
Block(-8,12,-7,PURPUR_STAIRS:4)
Block(-8,12,-6,PURPUR_STAIRS:0)
Block(-8,12,-5,PURPUR_STAIRS:0)
Block(-8,12,-4,PURPUR_STAIRS:4)
Block(-8,12,-3,PURPUR_STAIRS:4)
Block(-8,12,-2,PURPUR_STAIRS:0)
Block(-8,12,-1,PURPUR_STAIRS:4)
Block(-8,12,0,PURPUR_STAIRS:4)
Block(-8,12,1,PURPUR_STAIRS:0)
Block(-8,12,2,PURPUR_STAIRS:4)
Block(-8,12,3,PURPUR_STAIRS:4)
Block(-8,12,4,PURPUR_STAIRS:0)
Block(-8,12,5,PURPUR_STAIRS:0)
Block(-8,12,6,PURPUR_STAIRS:4)
Block(-8,12,7,PURPUR_STAIRS:7)
Block(-7,8,-7,PURPUR_STAIRS:4)
Block(-7,8,-6,PURPUR_STAIRS:4)
Block(-7,8,-5,PURPUR_STAIRS:0)
Block(-7,8,-4,PURPUR_STAIRS:0)
Block(-7,8,-3,PURPUR_STAIRS:4)
Block(-7,8,-2,PURPUR_STAIRS:4)
Block(-7,8,-1,PURPUR_STAIRS:0)
Block(-7,8,0,PURPUR_STAIRS:0)
Block(-7,8,1,PURPUR_STAIRS:4)
Block(-7,8,2,PURPUR_STAIRS:4)
Block(-7,8,3,PURPUR_STAIRS:0)
Block(-7,8,4,PURPUR_STAIRS:0)
Block(-7,8,5,PURPUR_STAIRS:4)
Block(-7,8,6,PURPUR_STAIRS:7)
Block(-7,9,-7,END_ROD)
Block(-7,9,6,END_ROD)
Block(-7,12,-8,PURPUR_STAIRS:6)
Block(-7,12,-7,PURPUR_BLOCK)
Block(-7,12,-6,PURPUR_BLOCK)
Block(-7,12,-5,PURPUR_BLOCK)
Block(-7,12,-4,PURPUR_BLOCK)
Block(-7,12,-3,PURPUR_BLOCK)
Block(-7,12,-2,PURPUR_BLOCK)
Block(-7,12,-1,PURPUR_BLOCK)
Block(-7,12,0,PURPUR_BLOCK)
Block(-7,12,1,PURPUR_BLOCK)
Block(-7,12,2,PURPUR_BLOCK)
Block(-7,12,3,PURPUR_BLOCK)
Block(-7,12,4,PURPUR_BLOCK)
Block(-7,12,5,PURPUR_BLOCK)
Block(-7,12,6,PURPUR_BLOCK)
Block(-7,12,7,PURPUR_STAIRS:7)
Block(-7,13,-7,END_ROD)
Block(-7,13,6,END_ROD)
Block(-6,4,-6,PURPUR_STAIRS:4)
Block(-6,4,-5,PURPUR_STAIRS:4)
Block(-6,4,-4,PURPUR_STAIRS:0)
Block(-6,4,-3,PURPUR_STAIRS:4)
Block(-6,4,-2,PURPUR_STAIRS:4)
Block(-6,4,-1,PURPUR_STAIRS:0)
Block(-6,4,0,PURPUR_STAIRS:0)
Block(-6,4,1,PURPUR_STAIRS:4)
Block(-6,4,2,PURPUR_STAIRS:4)
Block(-6,4,3,PURPUR_STAIRS:0)
Block(-6,4,4,PURPUR_STAIRS:4)
Block(-6,4,5,PURPUR_STAIRS:7)
Block(-6,5,-6,END_ROD)
Block(-6,5,5,END_ROD)
Block(-6,8,-7,PURPUR_STAIRS:6)
Block(-6,8,-6,PURPUR_BLOCK)
Block(-6,8,-5,PURPUR_BLOCK)
Block(-6,8,-4,PURPUR_BLOCK)
Block(-6,8,-3,PURPUR_BLOCK)
Block(-6,8,-2,PURPUR_BLOCK)
Block(-6,8,-1,PURPUR_BLOCK)
Block(-6,8,0,PURPUR_BLOCK)
Block(-6,8,1,PURPUR_BLOCK)
Block(-6,8,2,PURPUR_BLOCK)
Block(-6,8,3,PURPUR_BLOCK)
Block(-6,8,4,PURPUR_BLOCK)
Block(-6,8,5,PURPUR_BLOCK)
Block(-6,8,6,PURPUR_STAIRS:7)
Block(-6,9,-6,PURPUR_PILLAR:0)
Block(-6,9,-5,END_BRICKS)
Block(-6,9,-4,END_BRICKS)
Block(-6,9,-3,END_BRICKS)
Block(-6,9,-2,END_BRICKS)
Block(-6,9,-1,END_BRICKS)
Block(-6,9,0,END_BRICKS)
Block(-6,9,1,END_BRICKS)
Block(-6,9,2,END_BRICKS)
Block(-6,9,3,END_BRICKS)
Block(-6,9,4,END_BRICKS)
Block(-6,9,5,PURPUR_PILLAR:0)
Block(-6,10,-6,PURPUR_PILLAR:0)
Block(-6,10,-5,END_BRICKS)
Block(-6,10,-4,STAINED_GLASS:2)
Block(-6,10,-3,END_BRICKS)
Block(-6,10,-2,STAINED_GLASS:2)
Block(-6,10,-1,END_BRICKS)
Block(-6,10,0,END_BRICKS)
Block(-6,10,1,STAINED_GLASS:2)
Block(-6,10,2,END_BRICKS)
Block(-6,10,3,STAINED_GLASS:2)
Block(-6,10,4,END_BRICKS)
Block(-6,10,5,PURPUR_PILLAR:0)
Block(-6,11,-6,PURPUR_PILLAR:0)
Block(-6,11,-5,END_BRICKS)
Block(-6,11,-4,STAINED_GLASS:2)
Block(-6,11,-3,END_BRICKS)
Block(-6,11,-2,STAINED_GLASS:2)
Block(-6,11,-1,END_BRICKS)
Block(-6,11,0,END_BRICKS)
Block(-6,11,1,STAINED_GLASS:2)
Block(-6,11,2,END_BRICKS)
Block(-6,11,3,STAINED_GLASS:2)
Block(-6,11,4,END_BRICKS)
Block(-6,11,5,PURPUR_PILLAR:0)
Block(-6,12,-8,PURPUR_STAIRS:2)
Block(-6,12,-7,PURPUR_BLOCK)
Block(-6,12,-6,PURPUR_BLOCK)
Block(-6,12,-5,PURPUR_BLOCK)
Block(-6,12,-4,PURPUR_BLOCK)
Block(-6,12,-3,PURPUR_BLOCK)
Block(-6,12,-2,PURPUR_BLOCK)
Block(-6,12,-1,PURPUR_BLOCK)
Block(-6,12,0,PURPUR_BLOCK)
Block(-6,12,1,PURPUR_BLOCK)
Block(-6,12,2,PURPUR_BLOCK)
Block(-6,12,3,PURPUR_BLOCK)
Block(-6,12,4,PURPUR_BLOCK)
Block(-6,12,5,PURPUR_BLOCK)
Block(-6,12,6,PURPUR_BLOCK)
Block(-6,12,7,PURPUR_STAIRS:0)
Block(-5,4,-6,PURPUR_STAIRS:6)
Block(-5,4,-5,PURPUR_BLOCK)
Block(-5,4,-4,PURPUR_BLOCK)
Block(-5,4,-3,PURPUR_BLOCK)
Block(-5,4,-2,PURPUR_BLOCK)
Block(-5,4,-1,PURPUR_BLOCK)
Block(-5,4,0,PURPUR_BLOCK)
Block(-5,4,1,PURPUR_BLOCK)
Block(-5,4,2,PURPUR_BLOCK)
Block(-5,4,3,PURPUR_BLOCK)
Block(-5,4,4,PURPUR_BLOCK)
Block(-5,4,5,PURPUR_STAIRS:7)
Block(-5,5,-5,PURPUR_PILLAR:0)
Block(-5,5,-4,END_BRICKS)
Block(-5,5,-3,END_BRICKS)
Block(-5,5,-2,END_BRICKS)
Block(-5,5,-1,END_BRICKS)
Block(-5,5,0,END_BRICKS)
Block(-5,5,1,END_BRICKS)
Block(-5,5,2,END_BRICKS)
Block(-5,5,3,END_BRICKS)
Block(-5,5,4,PURPUR_PILLAR:0)
Block(-5,6,-5,PURPUR_PILLAR:0)
Block(-5,6,-4,END_BRICKS)
Block(-5,6,-3,STAINED_GLASS:2)
Block(-5,6,-2,END_BRICKS)
Block(-5,6,-1,END_BRICKS)
Block(-5,6,0,END_BRICKS)
Block(-5,6,1,END_BRICKS)
Block(-5,6,2,STAINED_GLASS:2)
Block(-5,6,3,END_BRICKS)
Block(-5,6,4,PURPUR_PILLAR:0)
Block(-5,7,-5,PURPUR_PILLAR:0)
Block(-5,7,-4,END_BRICKS)
Block(-5,7,-3,STAINED_GLASS:2)
Block(-5,7,-2,END_BRICKS)
Block(-5,7,-1,END_BRICKS)
Block(-5,7,0,END_BRICKS)
Block(-5,7,1,END_BRICKS)
Block(-5,7,2,STAINED_GLASS:2)
Block(-5,7,3,END_BRICKS)
Block(-5,7,4,PURPUR_PILLAR:0)
Block(-5,8,-7,PURPUR_STAIRS:2)
Block(-5,8,-6,PURPUR_BLOCK)
Block(-5,8,-5,PURPUR_BLOCK)
Block(-5,8,-4,PURPUR_BLOCK)
Block(-5,8,-3,PURPUR_BLOCK)
Block(-5,8,-2,PURPUR_BLOCK)
Block(-5,8,-1,PURPUR_BLOCK)
Block(-5,8,0,PURPUR_BLOCK)
Block(-5,8,1,PURPUR_BLOCK)
Block(-5,8,2,PURPUR_BLOCK)
Block(-5,8,3,PURPUR_BLOCK)
Block(-5,8,4,PURPUR_BLOCK)
Block(-5,8,5,PURPUR_BLOCK)
Block(-5,8,6,PURPUR_STAIRS:0)
Block(-5,9,-6,END_BRICKS)
Block(-5,9,-1,ENDER_CHEST:5,EndTowerF/1-ender_chest.nbt)
Block(-5,9,0,CHEST:5,EndTowerF/2-chest.nbt)
Block(-5,9,5,END_BRICKS)
Block(-5,10,-6,END_BRICKS)
Block(-5,10,5,END_BRICKS)
Block(-5,11,-6,END_BRICKS)
Block(-5,11,5,END_BRICKS)
Block(-5,12,-8,PURPUR_STAIRS:2)
Block(-5,12,-7,PURPUR_BLOCK)
Block(-5,12,-6,PURPUR_BLOCK)
Block(-5,12,-5,PURPUR_BLOCK)
Block(-5,12,-4,PURPUR_BLOCK)
Block(-5,12,-3,PURPUR_BLOCK)
Block(-5,12,-2,PURPUR_BLOCK)
Block(-5,12,-1,PURPUR_BLOCK)
Block(-5,12,0,PURPUR_BLOCK)
Block(-5,12,1,PURPUR_BLOCK)
Block(-5,12,2,PURPUR_BLOCK)
Block(-5,12,3,PURPUR_BLOCK)
Block(-5,12,4,PURPUR_BLOCK)
Block(-5,12,5,PURPUR_BLOCK)
Block(-5,12,6,PURPUR_BLOCK)
Block(-5,12,7,PURPUR_STAIRS:0)
Block(-4,0,-4,PURPUR_BLOCK)
Block(-4,0,-3,PURPUR_BLOCK)
Block(-4,0,-2,PURPUR_BLOCK)
Block(-4,0,-1,PURPUR_BLOCK)
Block(-4,0,0,PURPUR_BLOCK)
Block(-4,0,1,PURPUR_BLOCK)
Block(-4,0,2,PURPUR_BLOCK)
Block(-4,0,3,PURPUR_BLOCK)
Block(-4,1,-4,PURPUR_PILLAR:0)
Block(-4,1,-3,END_BRICKS)
Block(-4,1,-2,END_BRICKS)
Block(-4,1,-1,END_BRICKS)
Block(-4,1,0,END_BRICKS)
Block(-4,1,1,END_BRICKS)
Block(-4,1,2,END_BRICKS)
Block(-4,1,3,PURPUR_PILLAR:0)
Block(-4,2,-4,PURPUR_PILLAR:0)
Block(-4,2,-3,END_BRICKS)
Block(-4,2,-2,STAINED_GLASS:2)
Block(-4,2,-1,END_BRICKS)
Block(-4,2,0,END_BRICKS)
Block(-4,2,1,STAINED_GLASS:2)
Block(-4,2,2,END_BRICKS)
Block(-4,2,3,PURPUR_PILLAR:0)
Block(-4,3,-4,PURPUR_PILLAR:0)
Block(-4,3,-3,END_BRICKS)
Block(-4,3,-2,STAINED_GLASS:2)
Block(-4,3,-1,END_BRICKS)
Block(-4,3,0,END_BRICKS)
Block(-4,3,1,STAINED_GLASS:2)
Block(-4,3,2,END_BRICKS)
Block(-4,3,3,PURPUR_PILLAR:0)
Block(-4,4,-6,PURPUR_STAIRS:2)
Block(-4,4,-5,PURPUR_BLOCK)
Block(-4,4,-4,PURPUR_BLOCK)
Block(-4,4,-3,PURPUR_BLOCK)
Block(-4,4,-2,PURPUR_BLOCK)
Block(-4,4,-1,PURPUR_BLOCK)
Block(-4,4,0,PURPUR_BLOCK)
Block(-4,4,1,PURPUR_BLOCK)
Block(-4,4,2,PURPUR_BLOCK)
Block(-4,4,3,PURPUR_BLOCK)
Block(-4,4,4,PURPUR_BLOCK)
Block(-4,4,5,PURPUR_STAIRS:0)
Block(-4,5,-5,END_BRICKS)
Block(-4,5,4,END_BRICKS)
Block(-4,6,-5,END_BRICKS)
Block(-4,6,4,END_BRICKS)
Block(-4,7,-5,END_BRICKS)
Block(-4,7,4,END_BRICKS)
Block(-4,8,-7,PURPUR_STAIRS:2)
Block(-4,8,-6,PURPUR_BLOCK)
Block(-4,8,-5,PURPUR_BLOCK)
Block(-4,8,-1,PURPUR_BLOCK)
Block(-4,8,0,PURPUR_BLOCK)
Block(-4,8,4,PURPUR_BLOCK)
Block(-4,8,5,PURPUR_BLOCK)
Block(-4,8,6,PURPUR_STAIRS:0)
Block(-4,9,-6,END_BRICKS)
Block(-4,9,5,END_BRICKS)
Block(-4,10,-6,STAINED_GLASS:2)
Block(-4,10,5,STAINED_GLASS:2)
Block(-4,11,-6,STAINED_GLASS:2)
Block(-4,11,5,STAINED_GLASS:2)
Block(-4,12,-8,PURPUR_STAIRS:6)
Block(-4,12,-7,PURPUR_BLOCK)
Block(-4,12,-6,PURPUR_BLOCK)
Block(-4,12,-5,PURPUR_BLOCK)
Block(-4,12,-4,PURPUR_BLOCK)
Block(-4,12,-3,PURPUR_BLOCK)
Block(-4,12,-2,PURPUR_BLOCK)
Block(-4,12,-1,PURPUR_BLOCK)
Block(-4,12,0,PURPUR_BLOCK)
Block(-4,12,1,PURPUR_BLOCK)
Block(-4,12,2,PURPUR_BLOCK)
Block(-4,12,3,PURPUR_BLOCK)
Block(-4,12,4,PURPUR_BLOCK)
Block(-4,12,5,PURPUR_BLOCK)
Block(-4,12,6,PURPUR_BLOCK)
Block(-4,12,7,PURPUR_STAIRS:7)
Block(-3,0,-4,PURPUR_BLOCK)
Block(-3,0,-3,PURPUR_BLOCK)
Block(-3,0,-2,PURPUR_BLOCK)
Block(-3,0,-1,PURPUR_BLOCK)
Block(-3,0,0,PURPUR_BLOCK)
Block(-3,0,1,PURPUR_BLOCK)
Block(-3,0,2,PURPUR_BLOCK)
Block(-3,0,3,PURPUR_BLOCK)
Block(-3,1,-4,END_BRICKS)
Block(-3,1,3,END_BRICKS)
Block(-3,2,-4,END_BRICKS)
Block(-3,2,3,END_BRICKS)
Block(-3,3,-4,END_BRICKS)
Block(-3,3,3,END_BRICKS)
Block(-3,4,-6,PURPUR_STAIRS:6)
Block(-3,4,-5,PURPUR_BLOCK)
Block(-3,4,-4,PURPUR_BLOCK)
Block(-3,4,3,PURPUR_BLOCK)
Block(-3,4,4,PURPUR_BLOCK)
Block(-3,4,5,PURPUR_STAIRS:7)
Block(-3,5,-5,END_BRICKS)
Block(-3,5,4,END_BRICKS)
Block(-3,6,-5,STAINED_GLASS:2)
Block(-3,6,4,STAINED_GLASS:2)
Block(-3,7,-5,STAINED_GLASS:2)
Block(-3,7,4,STAINED_GLASS:2)
Block(-3,8,-7,PURPUR_STAIRS:6)
Block(-3,8,-6,PURPUR_BLOCK)
Block(-3,8,-5,PURPUR_BLOCK)
Block(-3,8,-1,END_ROD:5)
Block(-3,8,0,END_ROD:5)
Block(-3,8,4,PURPUR_BLOCK)
Block(-3,8,5,PURPUR_BLOCK)
Block(-3,8,6,PURPUR_STAIRS:7)
Block(-3,9,-6,END_BRICKS)
Block(-3,9,5,END_BRICKS)
Block(-3,10,-6,END_BRICKS)
Block(-3,10,5,END_BRICKS)
Block(-3,11,-6,END_BRICKS)
Block(-3,11,5,END_BRICKS)
Block(-3,12,-8,PURPUR_STAIRS:6)
Block(-3,12,-7,PURPUR_BLOCK)
Block(-3,12,-6,PURPUR_BLOCK)
Block(-3,12,-5,PURPUR_BLOCK)
Block(-3,12,-4,PURPUR_BLOCK)
Block(-3,12,-3,PURPUR_BLOCK)
Block(-3,12,-2,PURPUR_BLOCK)
Block(-3,12,-1,PURPUR_BLOCK)
Block(-3,12,0,PURPUR_BLOCK)
Block(-3,12,1,PURPUR_BLOCK)
Block(-3,12,2,PURPUR_BLOCK)
Block(-3,12,3,PURPUR_BLOCK)
Block(-3,12,4,PURPUR_BLOCK)
Block(-3,12,5,PURPUR_BLOCK)
Block(-3,12,6,PURPUR_BLOCK)
Block(-3,12,7,PURPUR_STAIRS:7)
Block(-2,0,-4,PURPUR_BLOCK)
Block(-2,0,-3,PURPUR_BLOCK)
Block(-2,0,-2,PURPUR_BLOCK)
Block(-2,0,-1,PURPUR_BLOCK)
Block(-2,0,0,PURPUR_BLOCK)
Block(-2,0,1,PURPUR_BLOCK)
Block(-2,0,2,PURPUR_BLOCK)
Block(-2,0,3,PURPUR_BLOCK)
Block(-2,1,-4,END_BRICKS)
Block(-2,1,3,END_BRICKS)
Block(-2,2,-4,STAINED_GLASS:2)
Block(-2,2,3,STAINED_GLASS:2)
Block(-2,3,-4,STAINED_GLASS:2)
Block(-2,3,0,PURPUR_SLAB)
Block(-2,3,3,STAINED_GLASS:2)
Block(-2,4,-6,PURPUR_STAIRS:6)
Block(-2,4,-5,PURPUR_BLOCK)
Block(-2,4,-4,PURPUR_BLOCK)
Block(-2,4,3,PURPUR_BLOCK)
Block(-2,4,4,PURPUR_BLOCK)
Block(-2,4,5,PURPUR_STAIRS:7)
Block(-2,5,-5,END_BRICKS)
Block(-2,5,4,END_BRICKS)
Block(-2,6,-5,END_BRICKS)
Block(-2,6,4,END_BRICKS)
Block(-2,7,-5,END_BRICKS)
Block(-2,7,4,END_BRICKS)
Block(-2,8,-7,PURPUR_STAIRS:6)
Block(-2,8,-6,PURPUR_BLOCK)
Block(-2,8,-5,PURPUR_BLOCK)
Block(-2,8,4,PURPUR_BLOCK)
Block(-2,8,5,PURPUR_BLOCK)
Block(-2,8,6,PURPUR_STAIRS:7)
Block(-2,9,-6,END_BRICKS)
Block(-2,9,5,END_BRICKS)
Block(-2,10,-6,STAINED_GLASS:2)
Block(-2,10,5,STAINED_GLASS:2)
Block(-2,11,-6,STAINED_GLASS:2)
Block(-2,11,5,STAINED_GLASS:2)
Block(-2,12,-8,PURPUR_STAIRS:2)
Block(-2,12,-7,PURPUR_BLOCK)
Block(-2,12,-6,PURPUR_BLOCK)
Block(-2,12,-5,PURPUR_BLOCK)
Block(-2,12,-4,PURPUR_BLOCK)
Block(-2,12,-3,PURPUR_BLOCK)
Block(-2,12,-2,PURPUR_BLOCK)
Block(-2,12,-1,PURPUR_BLOCK)
Block(-2,12,0,PURPUR_BLOCK)
Block(-2,12,1,PURPUR_BLOCK)
Block(-2,12,2,PURPUR_BLOCK)
Block(-2,12,3,PURPUR_BLOCK)
Block(-2,12,4,PURPUR_BLOCK)
Block(-2,12,5,PURPUR_BLOCK)
Block(-2,12,6,PURPUR_BLOCK)
Block(-2,12,7,PURPUR_STAIRS:0)
Block(-1,0,-4,PURPUR_BLOCK)
Block(-1,0,-3,PURPUR_BLOCK)
Block(-1,0,-2,PURPUR_BLOCK)
Block(-1,0,-1,PURPUR_BLOCK)
Block(-1,0,0,PURPUR_BLOCK)
Block(-1,0,1,PURPUR_BLOCK)
Block(-1,0,2,PURPUR_BLOCK)
Block(-1,0,3,PURPUR_BLOCK)
Block(-1,1,-4,END_BRICKS)
Block(-1,1,-1,PURPUR_BLOCK)
Block(-1,1,0,PURPUR_BLOCK)
Block(-1,1,3,END_BRICKS)
Block(-1,2,-4,END_BRICKS)
Block(-1,2,-2,PURPUR_SLAB)
Block(-1,2,-1,PURPUR_STAIRS:2)
Block(-1,2,0,PURPUR_BLOCK)
Block(-1,2,3,END_BRICKS)
Block(-1,3,-4,END_BRICKS)
Block(-1,3,0,PURPUR_STAIRS:0)
Block(-1,3,3,END_BRICKS)
Block(-1,4,-6,PURPUR_STAIRS:2)
Block(-1,4,-5,PURPUR_BLOCK)
Block(-1,4,-4,PURPUR_BLOCK)
Block(-1,4,3,PURPUR_BLOCK)
Block(-1,4,4,PURPUR_BLOCK)
Block(-1,4,5,PURPUR_STAIRS:0)
Block(-1,5,-5,END_BRICKS)
Block(-1,5,4,END_BRICKS)
Block(-1,6,-5,END_BRICKS)
Block(-1,6,4,END_BRICKS)
Block(-1,7,-5,END_BRICKS)
Block(-1,7,4,END_BRICKS)
Block(-1,8,-7,PURPUR_STAIRS:2)
Block(-1,8,-6,PURPUR_BLOCK)
Block(-1,8,-5,PURPUR_BLOCK)
Block(-1,8,4,PURPUR_BLOCK)
Block(-1,8,5,PURPUR_BLOCK)
Block(-1,8,6,PURPUR_STAIRS:0)
Block(-1,9,-6,END_BRICKS)
Block(-1,9,-5,PURPUR_BLOCK)
Block(-1,9,4,PURPUR_BLOCK)
Block(-1,9,5,END_BRICKS)
Block(-1,10,-6,END_BRICKS)
Block(-1,10,-5,PURPUR_BLOCK)
Block(-1,10,4,PURPUR_BLOCK)
Block(-1,10,5,END_BRICKS)
Block(-1,11,-6,END_BRICKS)
Block(-1,11,-5,PURPUR_BLOCK)
Block(-1,11,4,PURPUR_BLOCK)
Block(-1,11,5,END_BRICKS)
Block(-1,12,-8,PURPUR_STAIRS:6)
Block(-1,12,-7,PURPUR_BLOCK)
Block(-1,12,-6,PURPUR_BLOCK)
Block(-1,12,-5,PURPUR_BLOCK)
Block(-1,12,-4,PURPUR_BLOCK)
Block(-1,12,-3,PURPUR_BLOCK)
Block(-1,12,-2,PURPUR_BLOCK)
Block(-1,12,-1,PURPUR_BLOCK)
Block(-1,12,0,PURPUR_BLOCK)
Block(-1,12,1,PURPUR_BLOCK)
Block(-1,12,2,PURPUR_BLOCK)
Block(-1,12,3,PURPUR_BLOCK)
Block(-1,12,4,PURPUR_BLOCK)
Block(-1,12,5,PURPUR_BLOCK)
Block(-1,12,6,PURPUR_BLOCK)
Block(-1,12,7,PURPUR_STAIRS:7)
Block(0,0,-4,PURPUR_BLOCK)
Block(0,0,-3,PURPUR_BLOCK)
Block(0,0,-2,PURPUR_BLOCK)
Block(0,0,-1,PURPUR_BLOCK)
Block(0,0,0,PURPUR_BLOCK)
Block(0,0,1,PURPUR_BLOCK)
Block(0,0,2,PURPUR_BLOCK)
Block(0,0,3,PURPUR_BLOCK)
Block(0,1,-4,END_BRICKS)
Block(0,1,-1,PURPUR_STAIRS:1)
Block(0,1,0,PURPUR_BLOCK)
Block(0,1,3,END_BRICKS)
Block(0,2,-4,END_BRICKS)
Block(0,2,0,PURPUR_BLOCK)
Block(0,2,3,END_BRICKS)
Block(0,3,-4,END_BRICKS)
Block(0,3,0,PURPUR_BLOCK)
Block(0,3,1,PURPUR_SLAB:8)
Block(0,3,3,END_BRICKS)
Block(0,4,-6,PURPUR_STAIRS:2)
Block(0,4,-5,PURPUR_BLOCK)
Block(0,4,-4,PURPUR_BLOCK)
Block(0,4,-3,PURPUR_SLAB:8)
Block(0,4,-2,PURPUR_SLAB:8)
Block(0,4,-1,PURPUR_SLAB:8)
Block(0,4,0,PURPUR_STAIRS:0)
Block(0,4,3,PURPUR_BLOCK)
Block(0,4,4,PURPUR_BLOCK)
Block(0,4,5,PURPUR_STAIRS:0)
Block(0,5,-5,END_BRICKS)
Block(0,5,4,END_BRICKS)
Block(0,6,-5,END_BRICKS)
Block(0,6,4,END_BRICKS)
Block(0,7,-5,END_BRICKS)
Block(0,7,4,END_BRICKS)
Block(0,8,-7,PURPUR_STAIRS:2)
Block(0,8,-6,PURPUR_BLOCK)
Block(0,8,-5,PURPUR_BLOCK)
Block(0,8,4,PURPUR_BLOCK)
Block(0,8,5,PURPUR_BLOCK)
Block(0,8,6,PURPUR_STAIRS:0)
Block(0,9,-6,END_BRICKS)
Block(0,9,5,END_BRICKS)
Block(0,10,-6,END_BRICKS)
Block(0,10,5,END_BRICKS)
Block(0,11,-6,END_BRICKS)
Block(0,11,5,END_BRICKS)
Block(0,12,-8,PURPUR_STAIRS:6)
Block(0,12,-7,PURPUR_BLOCK)
Block(0,12,-6,PURPUR_BLOCK)
Block(0,12,-5,PURPUR_BLOCK)
Block(0,12,-4,PURPUR_BLOCK)
Block(0,12,-3,PURPUR_BLOCK)
Block(0,12,-2,PURPUR_BLOCK)
Block(0,12,-1,PURPUR_BLOCK)
Block(0,12,0,PURPUR_BLOCK)
Block(0,12,1,PURPUR_BLOCK)
Block(0,12,2,PURPUR_BLOCK)
Block(0,12,3,PURPUR_BLOCK)
Block(0,12,4,PURPUR_BLOCK)
Block(0,12,5,PURPUR_BLOCK)
Block(0,12,6,PURPUR_BLOCK)
Block(0,12,7,PURPUR_STAIRS:7)
Block(1,0,-4,PURPUR_BLOCK)
Block(1,0,-3,PURPUR_BLOCK)
Block(1,0,-2,PURPUR_BLOCK)
Block(1,0,-1,PURPUR_BLOCK)
Block(1,0,0,PURPUR_BLOCK)
Block(1,0,1,PURPUR_BLOCK)
Block(1,0,2,PURPUR_BLOCK)
Block(1,0,3,PURPUR_BLOCK)
Block(1,1,-4,END_BRICKS)
Block(1,1,-1,PURPUR_SLAB)
Block(1,1,3,END_BRICKS)
Block(1,2,-4,STAINED_GLASS:2)
Block(1,2,3,STAINED_GLASS:2)
Block(1,3,-4,STAINED_GLASS:2)
Block(1,3,3,STAINED_GLASS:2)
Block(1,4,-6,PURPUR_STAIRS:6)
Block(1,4,-5,PURPUR_BLOCK)
Block(1,4,-4,PURPUR_BLOCK)
Block(1,4,3,PURPUR_BLOCK)
Block(1,4,4,PURPUR_BLOCK)
Block(1,4,5,PURPUR_STAIRS:7)
Block(1,5,-5,END_BRICKS)
Block(1,5,-4,PURPUR_STAIRS:7)
Block(1,5,4,END_BRICKS)
Block(1,6,-5,END_BRICKS)
Block(1,6,-4,PURPUR_STAIRS:0)
Block(1,6,4,END_BRICKS)
Block(1,7,-5,END_BRICKS)
Block(1,7,-4,PURPUR_STAIRS:7)
Block(1,7,-3,PURPUR_SLAB:8)
Block(1,7,4,END_BRICKS)
Block(1,8,-7,PURPUR_STAIRS:6)
Block(1,8,-6,PURPUR_BLOCK)
Block(1,8,-5,PURPUR_BLOCK)
Block(1,8,-2,PURPUR_BLOCK)
Block(1,8,-1,PURPUR_BLOCK)
Block(1,8,0,PURPUR_BLOCK)
Block(1,8,1,PURPUR_BLOCK)
Block(1,8,4,PURPUR_BLOCK)
Block(1,8,5,PURPUR_BLOCK)
Block(1,8,6,PURPUR_STAIRS:7)
Block(1,9,-6,END_BRICKS)
Block(1,9,-5,PURPUR_BLOCK)
Block(1,9,-2,PURPUR_BLOCK)
Block(1,9,1,PURPUR_BLOCK)
Block(1,9,4,PURPUR_BLOCK)
Block(1,9,5,END_BRICKS)
Block(1,10,-6,END_BRICKS)
Block(1,10,-5,PURPUR_BLOCK)
Block(1,10,-4,PURPUR_BLOCK)
Block(1,10,-3,PURPUR_BLOCK)
Block(1,10,-2,PURPUR_BLOCK)
Block(1,10,1,PURPUR_BLOCK)
Block(1,10,2,PURPUR_BLOCK)
Block(1,10,3,PURPUR_BLOCK)
Block(1,10,4,PURPUR_BLOCK)
Block(1,10,5,END_BRICKS)
Block(1,11,-6,END_BRICKS)
Block(1,11,-5,PURPUR_BLOCK)
Block(1,11,4,PURPUR_BLOCK)
Block(1,11,5,END_BRICKS)
Block(1,12,-8,PURPUR_STAIRS:2)
Block(1,12,-7,PURPUR_BLOCK)
Block(1,12,-6,PURPUR_BLOCK)
Block(1,12,-5,PURPUR_BLOCK)
Block(1,12,-4,PURPUR_BLOCK)
Block(1,12,-3,PURPUR_BLOCK)
Block(1,12,-2,PURPUR_BLOCK)
Block(1,12,-1,PURPUR_BLOCK)
Block(1,12,0,PURPUR_BLOCK)
Block(1,12,1,PURPUR_BLOCK)
Block(1,12,2,PURPUR_BLOCK)
Block(1,12,3,PURPUR_BLOCK)
Block(1,12,4,PURPUR_BLOCK)
Block(1,12,5,PURPUR_BLOCK)
Block(1,12,6,PURPUR_BLOCK)
Block(1,12,7,PURPUR_STAIRS:0)
Block(2,0,-4,PURPUR_BLOCK)
Block(2,0,-3,PURPUR_BLOCK)
Block(2,0,-2,PURPUR_BLOCK)
Block(2,0,-1,PURPUR_BLOCK)
Block(2,0,0,PURPUR_BLOCK)
Block(2,0,1,PURPUR_BLOCK)
Block(2,0,2,PURPUR_BLOCK)
Block(2,0,3,PURPUR_BLOCK)
Block(2,1,-4,END_BRICKS)
Block(2,1,3,END_BRICKS)
Block(2,2,-4,END_BRICKS)
Block(2,2,3,END_BRICKS)
Block(2,3,-4,END_BRICKS)
Block(2,3,3,END_BRICKS)
Block(2,4,-6,PURPUR_STAIRS:6)
Block(2,4,-5,PURPUR_BLOCK)
Block(2,4,-4,PURPUR_BLOCK)
Block(2,4,0,PURPUR_BLOCK)
Block(2,4,1,PURPUR_BLOCK)
Block(2,4,2,PURPUR_BLOCK)
Block(2,4,3,PURPUR_BLOCK)
Block(2,4,4,PURPUR_BLOCK)
Block(2,4,5,PURPUR_STAIRS:7)
Block(2,5,-5,END_BRICKS)
Block(2,5,-4,PURPUR_STAIRS:7)
Block(2,5,0,PURPUR_BLOCK)
Block(2,5,1,PURPUR_BLOCK)
Block(2,5,2,PURPUR_STAIRS:0)
Block(2,5,4,END_BRICKS)
Block(2,6,-5,END_BRICKS)
Block(2,6,-4,PURPUR_STAIRS:0)
Block(2,6,0,PURPUR_BLOCK)
Block(2,6,1,PURPUR_STAIRS:0)
Block(2,6,4,STAINED_GLASS:2)
Block(2,7,-5,END_BRICKS)
Block(2,7,-4,PURPUR_STAIRS:7)
Block(2,7,-3,PURPUR_SLAB:8)
Block(2,7,4,STAINED_GLASS:2)
Block(2,8,-7,PURPUR_STAIRS:6)
Block(2,8,-6,PURPUR_BLOCK)
Block(2,8,-5,PURPUR_BLOCK)
Block(2,8,4,PURPUR_BLOCK)
Block(2,8,5,PURPUR_BLOCK)
Block(2,8,6,PURPUR_STAIRS:7)
Block(2,9,-6,END_BRICKS)
Block(2,9,5,END_BRICKS)
Block(2,10,-6,END_BRICKS)
Block(2,10,5,END_BRICKS)
Block(2,11,-6,END_BRICKS)
Block(2,11,5,END_BRICKS)
Block(2,12,-8,PURPUR_STAIRS:6)
Block(2,12,-7,PURPUR_BLOCK)
Block(2,12,-6,PURPUR_BLOCK)
Block(2,12,-5,PURPUR_BLOCK)
Block(2,12,-4,PURPUR_BLOCK)
Block(2,12,-3,PURPUR_BLOCK)
Block(2,12,-2,PURPUR_BLOCK)
Block(2,12,-1,PURPUR_BLOCK)
Block(2,12,0,PURPUR_BLOCK)
Block(2,12,1,PURPUR_BLOCK)
Block(2,12,2,PURPUR_BLOCK)
Block(2,12,3,PURPUR_BLOCK)
Block(2,12,4,PURPUR_BLOCK)
Block(2,12,5,PURPUR_BLOCK)
Block(2,12,6,PURPUR_BLOCK)
Block(2,12,7,PURPUR_STAIRS:7)
Block(3,0,-4,PURPUR_BLOCK)
Block(3,0,-3,PURPUR_BLOCK)
Block(3,0,-2,PURPUR_BLOCK)
Block(3,0,-1,PURPUR_BLOCK)
Block(3,0,0,PURPUR_BLOCK)
Block(3,0,1,PURPUR_BLOCK)
Block(3,0,2,PURPUR_BLOCK)
Block(3,0,3,PURPUR_BLOCK)
Block(3,1,-4,PURPUR_PILLAR:0)
Block(3,1,-3,END_BRICKS)
Block(3,1,-2,END_BRICKS)
Block(3,1,1,END_BRICKS)
Block(3,1,2,END_BRICKS)
Block(3,1,3,PURPUR_PILLAR:0)
Block(3,2,-4,PURPUR_PILLAR:0)
Block(3,2,-3,END_BRICKS)
Block(3,2,-2,END_BRICKS)
Block(3,2,1,END_BRICKS)
Block(3,2,2,END_BRICKS)
Block(3,2,3,PURPUR_PILLAR:0)
Block(3,3,-4,PURPUR_PILLAR:0)
Block(3,3,-3,END_BRICKS)
Block(3,3,-2,END_BRICKS)
Block(3,3,1,END_BRICKS)
Block(3,3,2,END_BRICKS)
Block(3,3,3,PURPUR_PILLAR:0)
Block(3,4,-6,PURPUR_STAIRS:2)
Block(3,4,-5,PURPUR_BLOCK)
Block(3,4,-4,PURPUR_BLOCK)
Block(3,4,-3,PURPUR_BLOCK)
Block(3,4,-2,PURPUR_BLOCK)
Block(3,4,-1,PURPUR_BLOCK)
Block(3,4,0,PURPUR_BLOCK)
Block(3,4,1,PURPUR_BLOCK)
Block(3,4,2,PURPUR_BLOCK)
Block(3,4,3,PURPUR_BLOCK)
Block(3,4,4,PURPUR_BLOCK)
Block(3,4,5,PURPUR_STAIRS:0)
Block(3,5,-5,END_BRICKS)
Block(3,5,-3,PURPUR_BLOCK)
Block(3,5,-2,PURPUR_BLOCK)
Block(3,5,-1,PURPUR_BLOCK)
Block(3,5,0,PURPUR_BLOCK)
Block(3,5,4,END_BRICKS)
Block(3,6,-5,END_BRICKS)
Block(3,6,-3,PURPUR_BLOCK)
Block(3,6,-2,PURPUR_BLOCK)
Block(3,6,-1,PURPUR_BLOCK)
Block(3,6,0,PURPUR_BLOCK)
Block(3,6,4,END_BRICKS)
Block(3,7,-5,END_BRICKS)
Block(3,7,-3,PURPUR_BLOCK)
Block(3,7,-2,PURPUR_STAIRS:0)
Block(3,7,4,END_BRICKS)
Block(3,8,-7,PURPUR_STAIRS:2)
Block(3,8,-6,PURPUR_BLOCK)
Block(3,8,-5,PURPUR_BLOCK)
Block(3,8,-4,PURPUR_BLOCK)
Block(3,8,-3,PURPUR_STAIRS:0)
Block(3,8,4,PURPUR_BLOCK)
Block(3,8,5,PURPUR_BLOCK)
Block(3,8,6,PURPUR_STAIRS:0)
Block(3,9,-6,END_BRICKS)
Block(3,9,-5,PURPUR_BLOCK)
Block(3,9,4,PURPUR_BLOCK)
Block(3,9,5,END_BRICKS)
Block(3,10,-6,END_BRICKS)
Block(3,10,-5,PURPUR_BLOCK)
Block(3,10,4,PURPUR_BLOCK)
Block(3,10,5,END_BRICKS)
Block(3,11,-6,END_BRICKS)
Block(3,11,-5,PURPUR_BLOCK)
Block(3,11,4,PURPUR_BLOCK)
Block(3,11,5,END_BRICKS)
Block(3,12,-8,PURPUR_STAIRS:6)
Block(3,12,-7,PURPUR_BLOCK)
Block(3,12,-6,PURPUR_BLOCK)
Block(3,12,-5,PURPUR_BLOCK)
Block(3,12,-4,PURPUR_BLOCK)
Block(3,12,-3,PURPUR_BLOCK)
Block(3,12,-2,PURPUR_BLOCK)
Block(3,12,-1,PURPUR_BLOCK)
Block(3,12,0,PURPUR_BLOCK)
Block(3,12,1,PURPUR_BLOCK)
Block(3,12,2,PURPUR_BLOCK)
Block(3,12,3,PURPUR_BLOCK)
Block(3,12,4,PURPUR_BLOCK)
Block(3,12,5,PURPUR_BLOCK)
Block(3,12,6,PURPUR_BLOCK)
Block(3,12,7,PURPUR_STAIRS:7)
Block(4,0,-3,PURPUR_STAIRS:1)
Block(4,0,-2,PURPUR_BLOCK)
Block(4,0,-1,PURPUR_BLOCK)
Block(4,0,0,PURPUR_BLOCK)
Block(4,0,1,PURPUR_BLOCK)
Block(4,0,2,PURPUR_STAIRS:1)
Block(4,4,-6,PURPUR_STAIRS:6)
Block(4,4,-5,PURPUR_BLOCK)
Block(4,4,-4,PURPUR_BLOCK)
Block(4,4,-3,PURPUR_BLOCK)
Block(4,4,-2,PURPUR_BLOCK)
Block(4,4,-1,PURPUR_BLOCK)
Block(4,4,0,PURPUR_BLOCK)
Block(4,4,1,PURPUR_BLOCK)
Block(4,4,2,PURPUR_BLOCK)
Block(4,4,3,PURPUR_BLOCK)
Block(4,4,4,PURPUR_BLOCK)
Block(4,4,5,PURPUR_STAIRS:7)
Block(4,5,-5,PURPUR_PILLAR:0)
Block(4,5,-4,END_BRICKS)
Block(4,5,-3,END_BRICKS)
Block(4,5,-2,END_BRICKS)
Block(4,5,-1,END_BRICKS)
Block(4,5,0,END_BRICKS)
Block(4,5,1,END_BRICKS)
Block(4,5,2,END_BRICKS)
Block(4,5,3,END_BRICKS)
Block(4,5,4,PURPUR_PILLAR:0)
Block(4,6,-5,PURPUR_PILLAR:0)
Block(4,6,-4,END_BRICKS)
Block(4,6,-3,END_BRICKS)
Block(4,6,-2,END_BRICKS)
Block(4,6,-1,END_BRICKS)
Block(4,6,0,END_BRICKS)
Block(4,6,1,END_BRICKS)
Block(4,6,2,STAINED_GLASS:2)
Block(4,6,3,END_BRICKS)
Block(4,6,4,PURPUR_PILLAR:0)
Block(4,7,-5,PURPUR_PILLAR:0)
Block(4,7,-4,END_BRICKS)
Block(4,7,-3,END_BRICKS)
Block(4,7,-2,END_BRICKS)
Block(4,7,-1,END_BRICKS)
Block(4,7,0,END_BRICKS)
Block(4,7,1,END_BRICKS)
Block(4,7,2,STAINED_GLASS:2)
Block(4,7,3,END_BRICKS)
Block(4,7,4,PURPUR_PILLAR:0)
Block(4,8,-7,PURPUR_STAIRS:2)
Block(4,8,-6,PURPUR_BLOCK)
Block(4,8,-5,PURPUR_BLOCK)
Block(4,8,-4,PURPUR_BLOCK)
Block(4,8,-3,PURPUR_BLOCK)
Block(4,8,-2,PURPUR_BLOCK)
Block(4,8,-1,PURPUR_BLOCK)
Block(4,8,0,PURPUR_BLOCK)
Block(4,8,1,PURPUR_BLOCK)
Block(4,8,2,PURPUR_BLOCK)
Block(4,8,3,PURPUR_BLOCK)
Block(4,8,4,PURPUR_BLOCK)
Block(4,8,5,PURPUR_BLOCK)
Block(4,8,6,PURPUR_STAIRS:0)
Block(4,9,-6,END_BRICKS)
Block(4,9,5,END_BRICKS)
Block(4,10,-6,END_BRICKS)
Block(4,10,5,END_BRICKS)
Block(4,11,-6,END_BRICKS)
Block(4,11,5,END_BRICKS)
Block(4,12,-8,PURPUR_STAIRS:2)
Block(4,12,-7,PURPUR_BLOCK)
Block(4,12,-6,PURPUR_BLOCK)
Block(4,12,-5,PURPUR_BLOCK)
Block(4,12,-4,PURPUR_BLOCK)
Block(4,12,-3,PURPUR_BLOCK)
Block(4,12,-2,PURPUR_BLOCK)
Block(4,12,-1,PURPUR_BLOCK)
Block(4,12,0,PURPUR_BLOCK)
Block(4,12,1,PURPUR_BLOCK)
Block(4,12,2,PURPUR_BLOCK)
Block(4,12,3,PURPUR_BLOCK)
Block(4,12,4,PURPUR_BLOCK)
Block(4,12,5,PURPUR_BLOCK)
Block(4,12,6,PURPUR_BLOCK)
Block(4,12,7,PURPUR_STAIRS:0)
Block(5,4,-6,PURPUR_STAIRS:6)
Block(5,4,-5,PURPUR_STAIRS:5)
Block(5,4,-4,PURPUR_STAIRS:1)
Block(5,4,-3,PURPUR_STAIRS:5)
Block(5,4,-2,PURPUR_STAIRS:5)
Block(5,4,-1,PURPUR_STAIRS:1)
Block(5,4,0,PURPUR_STAIRS:1)
Block(5,4,1,PURPUR_STAIRS:5)
Block(5,4,2,PURPUR_STAIRS:5)
Block(5,4,3,PURPUR_STAIRS:1)
Block(5,4,4,PURPUR_STAIRS:5)
Block(5,4,5,PURPUR_STAIRS:5)
Block(5,5,-6,END_ROD)
Block(5,5,5,END_ROD)
Block(5,8,-7,PURPUR_STAIRS:6)
Block(5,8,-6,PURPUR_BLOCK)
Block(5,8,-5,PURPUR_BLOCK)
Block(5,8,-4,PURPUR_BLOCK)
Block(5,8,-3,PURPUR_BLOCK)
Block(5,8,-2,PURPUR_BLOCK)
Block(5,8,-1,PURPUR_BLOCK)
Block(5,8,0,PURPUR_BLOCK)
Block(5,8,1,PURPUR_BLOCK)
Block(5,8,2,PURPUR_BLOCK)
Block(5,8,3,PURPUR_BLOCK)
Block(5,8,4,PURPUR_BLOCK)
Block(5,8,5,PURPUR_BLOCK)
Block(5,8,6,PURPUR_STAIRS:7)
Block(5,9,-6,PURPUR_PILLAR:0)
Block(5,9,-5,END_BRICKS)
Block(5,9,-4,END_BRICKS)
Block(5,9,-3,END_BRICKS)
Block(5,9,-2,END_BRICKS)
Block(5,9,-1,END_BRICKS)
Block(5,9,0,END_BRICKS)
Block(5,9,1,END_BRICKS)
Block(5,9,2,END_BRICKS)
Block(5,9,3,END_BRICKS)
Block(5,9,4,END_BRICKS)
Block(5,9,5,PURPUR_PILLAR:0)
Block(5,10,-6,PURPUR_PILLAR:0)
Block(5,10,-5,END_BRICKS)
Block(5,10,-4,STAINED_GLASS:2)
Block(5,10,-3,END_BRICKS)
Block(5,10,-2,STAINED_GLASS:2)
Block(5,10,-1,END_BRICKS)
Block(5,10,0,END_BRICKS)
Block(5,10,1,STAINED_GLASS:2)
Block(5,10,2,END_BRICKS)
Block(5,10,3,STAINED_GLASS:2)
Block(5,10,4,END_BRICKS)
Block(5,10,5,PURPUR_PILLAR:0)
Block(5,11,-6,PURPUR_PILLAR:0)
Block(5,11,-5,END_BRICKS)
Block(5,11,-4,STAINED_GLASS:2)
Block(5,11,-3,END_BRICKS)
Block(5,11,-2,STAINED_GLASS:2)
Block(5,11,-1,END_BRICKS)
Block(5,11,0,END_BRICKS)
Block(5,11,1,STAINED_GLASS:2)
Block(5,11,2,END_BRICKS)
Block(5,11,3,STAINED_GLASS:2)
Block(5,11,4,END_BRICKS)
Block(5,11,5,PURPUR_PILLAR:0)
Block(5,12,-8,PURPUR_STAIRS:2)
Block(5,12,-7,PURPUR_BLOCK)
Block(5,12,-6,PURPUR_BLOCK)
Block(5,12,-5,PURPUR_BLOCK)
Block(5,12,-4,PURPUR_BLOCK)
Block(5,12,-3,PURPUR_BLOCK)
Block(5,12,-2,PURPUR_BLOCK)
Block(5,12,-1,PURPUR_BLOCK)
Block(5,12,0,PURPUR_BLOCK)
Block(5,12,1,PURPUR_BLOCK)
Block(5,12,2,PURPUR_BLOCK)
Block(5,12,3,PURPUR_BLOCK)
Block(5,12,4,PURPUR_BLOCK)
Block(5,12,5,PURPUR_BLOCK)
Block(5,12,6,PURPUR_BLOCK)
Block(5,12,7,PURPUR_STAIRS:0)
Block(6,8,-7,PURPUR_STAIRS:6)
Block(6,8,-6,PURPUR_STAIRS:5)
Block(6,8,-5,PURPUR_STAIRS:1)
Block(6,8,-4,PURPUR_STAIRS:1)
Block(6,8,-3,PURPUR_STAIRS:5)
Block(6,8,-2,PURPUR_STAIRS:5)
Block(6,8,-1,PURPUR_STAIRS:1)
Block(6,8,0,PURPUR_STAIRS:1)
Block(6,8,1,PURPUR_STAIRS:5)
Block(6,8,2,PURPUR_STAIRS:5)
Block(6,8,3,PURPUR_STAIRS:1)
Block(6,8,4,PURPUR_STAIRS:1)
Block(6,8,5,PURPUR_STAIRS:5)
Block(6,8,6,PURPUR_STAIRS:5)
Block(6,9,-7,END_ROD)
Block(6,9,6,END_ROD)
Block(6,12,-8,PURPUR_STAIRS:6)
Block(6,12,-7,PURPUR_BLOCK)
Block(6,12,-6,PURPUR_BLOCK)
Block(6,12,-5,PURPUR_BLOCK)
Block(6,12,-4,PURPUR_BLOCK)
Block(6,12,-3,PURPUR_BLOCK)
Block(6,12,-2,PURPUR_BLOCK)
Block(6,12,-1,PURPUR_BLOCK)
Block(6,12,0,PURPUR_BLOCK)
Block(6,12,1,PURPUR_BLOCK)
Block(6,12,2,PURPUR_BLOCK)
Block(6,12,3,PURPUR_BLOCK)
Block(6,12,4,PURPUR_BLOCK)
Block(6,12,5,PURPUR_BLOCK)
Block(6,12,6,PURPUR_BLOCK)
Block(6,12,7,PURPUR_STAIRS:7)
Block(6,13,-7,END_ROD)
Block(6,13,6,END_ROD)
Block(7,12,-8,PURPUR_STAIRS:5)
Block(7,12,-7,PURPUR_STAIRS:5)
Block(7,12,-6,PURPUR_STAIRS:1)
Block(7,12,-5,PURPUR_STAIRS:1)
Block(7,12,-4,PURPUR_STAIRS:5)
Block(7,12,-3,PURPUR_STAIRS:5)
Block(7,12,-2,PURPUR_STAIRS:1)
Block(7,12,-1,PURPUR_STAIRS:5)
Block(7,12,0,PURPUR_STAIRS:5)
Block(7,12,1,PURPUR_STAIRS:1)
Block(7,12,2,PURPUR_STAIRS:5)
Block(7,12,3,PURPUR_STAIRS:5)
Block(7,12,4,PURPUR_STAIRS:1)
Block(7,12,5,PURPUR_STAIRS:1)
Block(7,12,6,PURPUR_STAIRS:5)
Block(7,12,7,PURPUR_STAIRS:7)

#######################################################################
# +-----------------------------------------------------------------+ #
# |                            BO3 checks                           | #
# +-----------------------------------------------------------------+ #
#######################################################################


#######################################################################
# +-----------------------------------------------------------------+ #
# |                             Branches                            | #
# +-----------------------------------------------------------------+ #
#######################################################################


#######################################################################
# +-----------------------------------------------------------------+ #
# |                             Entities                            | #
# +-----------------------------------------------------------------+ #
#######################################################################

Entity(-5,9,-5,SHULKER,1)
Entity(-5,9,4,SHULKER,1)
Entity(-4,5,3,SHULKER,1)
Entity(0,10,-2,SHULKER,1)
Entity(1,6,0,SHULKER,1)
Entity(3,13,0,SHULKER,1)
Entity(4,2,-2,SHULKER,1)
Entity(4,2,1,SHULKER,1)

#######################################################################
# +-----------------------------------------------------------------+ #
# |                            Particles                            | #
# +-----------------------------------------------------------------+ #
#######################################################################


#######################################################################
# +-----------------------------------------------------------------+ #
# |                             Spawners                            | #
# +-----------------------------------------------------------------+ #
#######################################################################


#######################################################################
# +-----------------------------------------------------------------+ #
# |                             ModData                             | #
# +-----------------------------------------------------------------+ #
#######################################################################

