
#######################################################################
# +-----------------------------------------------------------------+ #
# |                            BO3 object                           | #
# +-----------------------------------------------------------------+ #
#######################################################################

Author: totemo

Description: No description given

Version: 3

SettingsMode: WriteWithoutComments


#######################################################################
# +-----------------------------------------------------------------+ #
# |                          Main settings                          | #
# +-----------------------------------------------------------------+ #
#######################################################################

Tree: false

Frequency: 0

Rarity: 100.0

RotateRandomly: true

SpawnHeight: highestBlock

SpawnHeightOffset: 0

SpawnHeightVariance: 0

##############################
# Height Limits for the BO3. #
##############################

MinHeight: 0

MaxHeight: 256

######################
# Extrusion settings #
######################

ExtrudeMode: None

ExtrudeThroughBlocks: AIR

MaxBranchDepth: 10

ExcludedBiomes: All


#######################################################################
# +-----------------------------------------------------------------+ #
# |                      Source block settings                      | #
# +-----------------------------------------------------------------+ #
#######################################################################

SourceBlocks: AIR

MaxPercentageOutsideSourceBlock: 10

OutsideSourceBlock: placeAnyway

IsOTGPlus: false


#######################################################################
# +-----------------------------------------------------------------+ #
# |                              Blocks                             | #
# +-----------------------------------------------------------------+ #
#######################################################################

Block(-13,19,0,PURPUR_BLOCK)
Block(-13,19,1,PURPUR_BLOCK)
Block(-13,19,2,PURPUR_BLOCK)
Block(-13,20,-1,PURPUR_BLOCK)
Block(-13,20,0,PURPUR_BLOCK)
Block(-13,20,1,PURPUR_BLOCK)
Block(-13,20,2,PURPUR_BLOCK)
Block(-13,20,3,PURPUR_BLOCK)
Block(-13,21,-1,PURPUR_BLOCK)
Block(-13,21,3,PURPUR_BLOCK)
Block(-13,22,-1,PURPUR_BLOCK)
Block(-13,22,3,PURPUR_BLOCK)
Block(-13,23,-1,PURPUR_BLOCK)
Block(-13,23,0,PURPUR_SLAB:8)
Block(-13,23,2,PURPUR_SLAB:8)
Block(-13,23,3,PURPUR_BLOCK)
Block(-13,24,-1,PURPUR_SLAB)
Block(-13,24,0,PURPUR_BLOCK)
Block(-13,24,1,PURPUR_BLOCK)
Block(-13,24,2,PURPUR_BLOCK)
Block(-13,24,3,PURPUR_SLAB)
Block(-12,19,1,PURPUR_PILLAR)
Block(-12,20,-1,PURPUR_BLOCK)
Block(-12,20,0,PURPUR_STAIRS:1)
Block(-12,20,1,PURPUR_STAIRS:1)
Block(-12,20,2,PURPUR_STAIRS:1)
Block(-12,20,3,PURPUR_BLOCK)
Block(-12,21,-1,PURPUR_BLOCK)
Block(-12,21,3,PURPUR_BLOCK)
Block(-12,22,-1,END_ROD)
Block(-12,22,3,END_ROD)
Block(-11,19,1,PURPUR_PILLAR)
Block(-11,20,-1,PURPUR_BLOCK)
Block(-11,20,0,PURPUR_BLOCK)
Block(-11,20,1,PURPUR_BLOCK)
Block(-11,20,2,PURPUR_BLOCK)
Block(-11,20,3,PURPUR_BLOCK)
Block(-11,21,-1,PURPUR_STAIRS:2)
Block(-11,21,3,PURPUR_STAIRS:0)
Block(-10,19,1,PURPUR_PILLAR)
Block(-10,20,-1,PURPUR_BLOCK)
Block(-10,20,0,PURPUR_BLOCK)
Block(-10,20,1,PURPUR_BLOCK)
Block(-10,20,2,PURPUR_BLOCK)
Block(-10,20,3,PURPUR_BLOCK)
Block(-10,21,-1,PURPUR_STAIRS:2)
Block(-10,21,3,PURPUR_STAIRS:0)
Block(-9,19,0,PURPUR_STAIRS:6)
Block(-9,19,1,PURPUR_PILLAR)
Block(-9,19,2,PURPUR_STAIRS:7)
Block(-9,20,-1,PURPUR_BLOCK)
Block(-9,20,0,PURPUR_STAIRS:1)
Block(-9,20,1,PURPUR_STAIRS:1)
Block(-9,20,2,PURPUR_STAIRS:1)
Block(-9,20,3,PURPUR_BLOCK)
Block(-9,21,-1,PURPUR_BLOCK)
Block(-9,21,3,PURPUR_BLOCK)
Block(-8,18,0,PURPUR_STAIRS:6)
Block(-8,18,1,PURPUR_BLOCK)
Block(-8,18,2,PURPUR_STAIRS:7)
Block(-8,19,-1,PURPUR_BLOCK)
Block(-8,19,0,PURPUR_STAIRS:1)
Block(-8,19,1,PURPUR_STAIRS:1)
Block(-8,19,2,PURPUR_STAIRS:1)
Block(-8,19,3,PURPUR_BLOCK)
Block(-8,20,-1,PURPUR_STAIRS:2)
Block(-8,20,3,PURPUR_STAIRS:0)
Block(-7,17,0,PURPUR_STAIRS:6)
Block(-7,17,1,PURPUR_BLOCK)
Block(-7,17,2,PURPUR_STAIRS:7)
Block(-7,18,-1,PURPUR_BLOCK)
Block(-7,18,0,PURPUR_STAIRS:1)
Block(-7,18,1,PURPUR_STAIRS:1)
Block(-7,18,2,PURPUR_STAIRS:1)
Block(-7,18,3,PURPUR_BLOCK)
Block(-7,19,-1,PURPUR_STAIRS:2)
Block(-7,19,3,PURPUR_STAIRS:0)
Block(-6,8,-6,PURPUR_STAIRS:4)
Block(-6,8,-5,PURPUR_STAIRS:4)
Block(-6,8,-4,PURPUR_STAIRS:0)
Block(-6,8,-3,PURPUR_STAIRS:0)
Block(-6,8,-2,PURPUR_STAIRS:4)
Block(-6,8,-1,PURPUR_STAIRS:4)
Block(-6,8,0,PURPUR_STAIRS:0)
Block(-6,8,1,PURPUR_STAIRS:0)
Block(-6,8,2,PURPUR_STAIRS:4)
Block(-6,8,3,PURPUR_STAIRS:4)
Block(-6,8,4,PURPUR_STAIRS:0)
Block(-6,8,5,PURPUR_STAIRS:0)
Block(-6,8,6,PURPUR_STAIRS:4)
Block(-6,8,7,PURPUR_STAIRS:7)
Block(-6,15,1,PURPUR_PILLAR)
Block(-6,16,0,PURPUR_BLOCK)
Block(-6,16,1,PURPUR_BLOCK)
Block(-6,16,2,PURPUR_BLOCK)
Block(-6,17,-1,PURPUR_BLOCK)
Block(-6,17,0,PURPUR_STAIRS:1)
Block(-6,17,1,PURPUR_STAIRS:1)
Block(-6,17,2,PURPUR_STAIRS:1)
Block(-6,17,3,PURPUR_BLOCK)
Block(-6,18,-1,PURPUR_STAIRS:2)
Block(-6,18,3,PURPUR_STAIRS:0)
Block(-5,4,-5,PURPUR_STAIRS:4)
Block(-5,4,-4,PURPUR_STAIRS:4)
Block(-5,4,-3,PURPUR_STAIRS:0)
Block(-5,4,-2,PURPUR_STAIRS:4)
Block(-5,4,-1,PURPUR_STAIRS:4)
Block(-5,4,0,PURPUR_STAIRS:0)
Block(-5,4,1,PURPUR_STAIRS:0)
Block(-5,4,2,PURPUR_STAIRS:4)
Block(-5,4,3,PURPUR_STAIRS:4)
Block(-5,4,4,PURPUR_STAIRS:0)
Block(-5,4,5,PURPUR_STAIRS:4)
Block(-5,4,6,PURPUR_STAIRS:7)
Block(-5,5,-5,END_ROD)
Block(-5,5,6,END_ROD)
Block(-5,8,-6,PURPUR_STAIRS:6)
Block(-5,8,-5,PURPUR_BLOCK)
Block(-5,8,-4,PURPUR_BLOCK)
Block(-5,8,-3,PURPUR_BLOCK)
Block(-5,8,-2,PURPUR_BLOCK)
Block(-5,8,-1,PURPUR_BLOCK)
Block(-5,8,0,PURPUR_BLOCK)
Block(-5,8,1,PURPUR_BLOCK)
Block(-5,8,2,PURPUR_BLOCK)
Block(-5,8,3,PURPUR_BLOCK)
Block(-5,8,4,PURPUR_BLOCK)
Block(-5,8,5,PURPUR_BLOCK)
Block(-5,8,6,PURPUR_BLOCK)
Block(-5,8,7,PURPUR_STAIRS:7)
Block(-5,9,-5,END_ROD)
Block(-5,9,6,END_ROD)
Block(-5,15,0,PURPUR_STAIRS:6)
Block(-5,15,1,PURPUR_PILLAR)
Block(-5,15,2,PURPUR_STAIRS:7)
Block(-5,16,-1,PURPUR_STAIRS:6)
Block(-5,16,0,PURPUR_BLOCK)
Block(-5,16,1,PURPUR_BLOCK)
Block(-5,16,2,PURPUR_BLOCK)
Block(-5,16,3,PURPUR_STAIRS:7)
Block(-5,17,-1,PURPUR_BLOCK)
Block(-5,17,3,PURPUR_BLOCK)
Block(-5,20,-18,PURPUR_STAIRS:4)
Block(-5,20,-17,PURPUR_STAIRS:4)
Block(-5,20,-16,PURPUR_STAIRS:0)
Block(-5,20,-15,PURPUR_STAIRS:0)
Block(-5,20,-14,PURPUR_STAIRS:4)
Block(-5,20,-13,PURPUR_STAIRS:0)
Block(-5,20,-12,PURPUR_STAIRS:0)
Block(-5,20,-11,PURPUR_STAIRS:4)
Block(-5,20,-10,PURPUR_STAIRS:0)
Block(-5,20,-9,PURPUR_STAIRS:0)
Block(-5,20,-8,PURPUR_STAIRS:4)
Block(-5,20,-7,PURPUR_STAIRS:7)
Block(-4,0,-2,PURPUR_STAIRS:0)
Block(-4,0,-1,PURPUR_BLOCK)
Block(-4,0,0,PURPUR_BLOCK)
Block(-4,0,1,PURPUR_BLOCK)
Block(-4,0,2,PURPUR_BLOCK)
Block(-4,0,3,PURPUR_STAIRS:0)
Block(-4,4,-5,PURPUR_STAIRS:6)
Block(-4,4,-4,PURPUR_BLOCK)
Block(-4,4,-3,PURPUR_BLOCK)
Block(-4,4,-2,PURPUR_BLOCK)
Block(-4,4,-1,PURPUR_BLOCK)
Block(-4,4,0,PURPUR_BLOCK)
Block(-4,4,1,PURPUR_BLOCK)
Block(-4,4,2,PURPUR_BLOCK)
Block(-4,4,3,PURPUR_BLOCK)
Block(-4,4,4,PURPUR_BLOCK)
Block(-4,4,5,PURPUR_BLOCK)
Block(-4,4,6,PURPUR_STAIRS:7)
Block(-4,5,-4,PURPUR_PILLAR:0)
Block(-4,5,-3,END_BRICKS)
Block(-4,5,-2,END_BRICKS)
Block(-4,5,-1,END_BRICKS)
Block(-4,5,0,END_BRICKS)
Block(-4,5,1,END_BRICKS)
Block(-4,5,2,END_BRICKS)
Block(-4,5,3,END_BRICKS)
Block(-4,5,4,END_BRICKS)
Block(-4,5,5,PURPUR_PILLAR:0)
Block(-4,6,-4,PURPUR_PILLAR:0)
Block(-4,6,-3,END_BRICKS)
Block(-4,6,-2,STAINED_GLASS:2)
Block(-4,6,-1,END_BRICKS)
Block(-4,6,0,END_BRICKS)
Block(-4,6,1,END_BRICKS)
Block(-4,6,2,END_BRICKS)
Block(-4,6,3,STAINED_GLASS:2)
Block(-4,6,4,END_BRICKS)
Block(-4,6,5,PURPUR_PILLAR:0)
Block(-4,7,-4,PURPUR_PILLAR:0)
Block(-4,7,-3,END_BRICKS)
Block(-4,7,-2,STAINED_GLASS:2)
Block(-4,7,-1,END_BRICKS)
Block(-4,7,0,END_BRICKS)
Block(-4,7,1,END_BRICKS)
Block(-4,7,2,END_BRICKS)
Block(-4,7,3,STAINED_GLASS:2)
Block(-4,7,4,END_BRICKS)
Block(-4,7,5,PURPUR_PILLAR:0)
Block(-4,8,-6,PURPUR_STAIRS:2)
Block(-4,8,-5,PURPUR_BLOCK)
Block(-4,8,-4,PURPUR_BLOCK)
Block(-4,8,-3,PURPUR_BLOCK)
Block(-4,8,-2,PURPUR_BLOCK)
Block(-4,8,-1,PURPUR_BLOCK)
Block(-4,8,0,PURPUR_BLOCK)
Block(-4,8,1,PURPUR_BLOCK)
Block(-4,8,2,PURPUR_BLOCK)
Block(-4,8,3,PURPUR_BLOCK)
Block(-4,8,4,PURPUR_BLOCK)
Block(-4,8,5,PURPUR_BLOCK)
Block(-4,8,6,PURPUR_BLOCK)
Block(-4,8,7,PURPUR_STAIRS:0)
Block(-4,15,1,PURPUR_PILLAR)
Block(-4,16,-1,PURPUR_BLOCK)
Block(-4,16,0,PURPUR_BLOCK)
Block(-4,16,1,PURPUR_BLOCK)
Block(-4,16,2,PURPUR_BLOCK)
Block(-4,16,3,PURPUR_BLOCK)
Block(-4,17,-1,PURPUR_STAIRS:2)
Block(-4,17,3,PURPUR_STAIRS:0)
Block(-4,20,-18,PURPUR_STAIRS:6)
Block(-4,20,-17,PURPUR_BLOCK)
Block(-4,20,-16,PURPUR_BLOCK)
Block(-4,20,-15,PURPUR_BLOCK)
Block(-4,20,-14,PURPUR_BLOCK)
Block(-4,20,-13,PURPUR_BLOCK)
Block(-4,20,-12,PURPUR_BLOCK)
Block(-4,20,-11,PURPUR_BLOCK)
Block(-4,20,-10,PURPUR_BLOCK)
Block(-4,20,-9,PURPUR_BLOCK)
Block(-4,20,-8,PURPUR_BLOCK)
Block(-4,20,-7,PURPUR_STAIRS:7)
Block(-4,21,-17,END_ROD)
Block(-4,21,-8,END_ROD)
Block(-3,0,-3,PURPUR_BLOCK)
Block(-3,0,-2,PURPUR_BLOCK)
Block(-3,0,-1,PURPUR_BLOCK)
Block(-3,0,0,PURPUR_BLOCK)
Block(-3,0,1,PURPUR_BLOCK)
Block(-3,0,2,PURPUR_BLOCK)
Block(-3,0,3,PURPUR_BLOCK)
Block(-3,0,4,PURPUR_BLOCK)
Block(-3,1,-3,PURPUR_PILLAR:0)
Block(-3,1,-2,END_BRICKS)
Block(-3,1,-1,END_BRICKS)
Block(-3,1,2,END_BRICKS)
Block(-3,1,3,END_BRICKS)
Block(-3,1,4,PURPUR_PILLAR:0)
Block(-3,2,-3,PURPUR_PILLAR:0)
Block(-3,2,-2,END_BRICKS)
Block(-3,2,-1,END_BRICKS)
Block(-3,2,2,END_BRICKS)
Block(-3,2,3,END_BRICKS)
Block(-3,2,4,PURPUR_PILLAR:0)
Block(-3,3,-3,PURPUR_PILLAR:0)
Block(-3,3,-2,END_BRICKS)
Block(-3,3,-1,END_BRICKS)
Block(-3,3,2,END_BRICKS)
Block(-3,3,3,END_BRICKS)
Block(-3,3,4,PURPUR_PILLAR:0)
Block(-3,4,-5,PURPUR_STAIRS:2)
Block(-3,4,-4,PURPUR_BLOCK)
Block(-3,4,-3,PURPUR_BLOCK)
Block(-3,4,-2,PURPUR_BLOCK)
Block(-3,4,-1,PURPUR_BLOCK)
Block(-3,4,0,PURPUR_BLOCK)
Block(-3,4,1,PURPUR_BLOCK)
Block(-3,4,2,PURPUR_BLOCK)
Block(-3,4,3,PURPUR_BLOCK)
Block(-3,4,4,PURPUR_BLOCK)
Block(-3,4,5,PURPUR_BLOCK)
Block(-3,4,6,PURPUR_STAIRS:0)
Block(-3,5,-4,END_BRICKS)
Block(-3,5,5,END_BRICKS)
Block(-3,6,-4,END_BRICKS)
Block(-3,6,5,END_BRICKS)
Block(-3,7,-4,END_BRICKS)
Block(-3,7,5,END_BRICKS)
Block(-3,8,-6,PURPUR_STAIRS:2)
Block(-3,8,-5,PURPUR_BLOCK)
Block(-3,8,-4,PURPUR_BLOCK)
Block(-3,8,-3,PURPUR_BLOCK)
Block(-3,8,-2,PURPUR_BLOCK)
Block(-3,8,-1,PURPUR_BLOCK)
Block(-3,8,0,PURPUR_BLOCK)
Block(-3,8,1,PURPUR_BLOCK)
Block(-3,8,2,PURPUR_BLOCK)
Block(-3,8,3,PURPUR_BLOCK)
Block(-3,8,4,PURPUR_BLOCK)
Block(-3,8,5,PURPUR_BLOCK)
Block(-3,8,6,PURPUR_BLOCK)
Block(-3,8,7,PURPUR_STAIRS:0)
Block(-3,15,1,PURPUR_PILLAR)
Block(-3,16,-16,PURPUR_BLOCK)
Block(-3,16,-15,PURPUR_BLOCK)
Block(-3,16,-14,PURPUR_BLOCK)
Block(-3,16,-13,PURPUR_BLOCK)
Block(-3,16,-12,PURPUR_BLOCK)
Block(-3,16,-11,PURPUR_BLOCK)
Block(-3,16,-10,PURPUR_BLOCK)
Block(-3,16,-9,PURPUR_BLOCK)
Block(-3,16,-1,PURPUR_BLOCK)
Block(-3,16,0,PURPUR_BLOCK)
Block(-3,16,1,PURPUR_BLOCK)
Block(-3,16,2,PURPUR_BLOCK)
Block(-3,16,3,PURPUR_BLOCK)
Block(-3,17,-16,PURPUR_PILLAR:0)
Block(-3,17,-15,END_BRICKS)
Block(-3,17,-14,END_BRICKS)
Block(-3,17,-13,END_BRICKS)
Block(-3,17,-12,END_BRICKS)
Block(-3,17,-11,END_BRICKS)
Block(-3,17,-10,END_BRICKS)
Block(-3,17,-9,PURPUR_PILLAR:0)
Block(-3,17,-1,PURPUR_STAIRS:2)
Block(-3,17,3,PURPUR_STAIRS:0)
Block(-3,18,-16,PURPUR_PILLAR:0)
Block(-3,18,-15,END_BRICKS)
Block(-3,18,-14,STAINED_GLASS:2)
Block(-3,18,-13,END_BRICKS)
Block(-3,18,-12,END_BRICKS)
Block(-3,18,-11,STAINED_GLASS:2)
Block(-3,18,-10,END_BRICKS)
Block(-3,18,-9,PURPUR_PILLAR:0)
Block(-3,19,-16,PURPUR_PILLAR:0)
Block(-3,19,-15,END_BRICKS)
Block(-3,19,-14,STAINED_GLASS:2)
Block(-3,19,-13,END_BRICKS)
Block(-3,19,-12,END_BRICKS)
Block(-3,19,-11,STAINED_GLASS:2)
Block(-3,19,-10,END_BRICKS)
Block(-3,19,-9,PURPUR_PILLAR:0)
Block(-3,20,-18,PURPUR_STAIRS:2)
Block(-3,20,-17,PURPUR_BLOCK)
Block(-3,20,-16,PURPUR_BLOCK)
Block(-3,20,-15,PURPUR_BLOCK)
Block(-3,20,-14,PURPUR_BLOCK)
Block(-3,20,-13,PURPUR_BLOCK)
Block(-3,20,-12,PURPUR_BLOCK)
Block(-3,20,-11,PURPUR_BLOCK)
Block(-3,20,-10,PURPUR_BLOCK)
Block(-3,20,-9,PURPUR_BLOCK)
Block(-3,20,-8,PURPUR_BLOCK)
Block(-3,20,-7,PURPUR_STAIRS:0)
Block(-3,24,-1,WALL_BANNER:4,EndTowerD/1-banner.nbt)
Block(-3,24,3,WALL_BANNER:4,EndTowerD/2-banner.nbt)
Block(-3,28,-3,PURPUR_STAIRS:4)
Block(-3,28,-2,PURPUR_STAIRS:4)
Block(-3,28,-1,PURPUR_STAIRS:0)
Block(-3,28,0,PURPUR_STAIRS:0)
Block(-3,28,1,PURPUR_STAIRS:4)
Block(-3,28,2,PURPUR_STAIRS:0)
Block(-3,28,3,PURPUR_STAIRS:0)
Block(-3,28,4,PURPUR_STAIRS:4)
Block(-3,28,5,PURPUR_STAIRS:7)
Block(-2,0,-3,PURPUR_BLOCK)
Block(-2,0,-2,PURPUR_BLOCK)
Block(-2,0,-1,PURPUR_BLOCK)
Block(-2,0,0,PURPUR_BLOCK)
Block(-2,0,1,PURPUR_BLOCK)
Block(-2,0,2,PURPUR_BLOCK)
Block(-2,0,3,PURPUR_BLOCK)
Block(-2,0,4,PURPUR_BLOCK)
Block(-2,1,-3,END_BRICKS)
Block(-2,1,4,END_BRICKS)
Block(-2,2,-3,END_BRICKS)
Block(-2,2,4,END_BRICKS)
Block(-2,3,-3,END_BRICKS)
Block(-2,3,4,END_BRICKS)
Block(-2,4,-5,PURPUR_STAIRS:6)
Block(-2,4,-4,PURPUR_BLOCK)
Block(-2,4,-3,PURPUR_BLOCK)
Block(-2,4,4,PURPUR_BLOCK)
Block(-2,4,5,PURPUR_BLOCK)
Block(-2,4,6,PURPUR_STAIRS:7)
Block(-2,5,-4,END_BRICKS)
Block(-2,5,5,END_BRICKS)
Block(-2,6,-4,STAINED_GLASS:2)
Block(-2,6,5,END_BRICKS)
Block(-2,7,-4,STAINED_GLASS:2)
Block(-2,7,5,END_BRICKS)
Block(-2,8,-6,PURPUR_STAIRS:6)
Block(-2,8,-5,PURPUR_BLOCK)
Block(-2,8,-4,PURPUR_BLOCK)
Block(-2,8,-3,PURPUR_BLOCK)
Block(-2,8,-2,PURPUR_BLOCK)
Block(-2,8,-1,PURPUR_BLOCK)
Block(-2,8,0,PURPUR_BLOCK)
Block(-2,8,1,PURPUR_BLOCK)
Block(-2,8,2,PURPUR_BLOCK)
Block(-2,8,3,PURPUR_BLOCK)
Block(-2,8,4,PURPUR_BLOCK)
Block(-2,8,5,PURPUR_BLOCK)
Block(-2,8,6,PURPUR_BLOCK)
Block(-2,8,7,PURPUR_STAIRS:7)
Block(-2,10,1,PURPUR_STAIRS:4)
Block(-2,14,1,PURPUR_STAIRS:4)
Block(-2,15,1,PURPUR_PILLAR)
Block(-2,16,-16,PURPUR_BLOCK)
Block(-2,16,-15,PURPUR_BLOCK)
Block(-2,16,-14,PURPUR_BLOCK)
Block(-2,16,-13,PURPUR_BLOCK)
Block(-2,16,-12,PURPUR_BLOCK)
Block(-2,16,-11,PURPUR_BLOCK)
Block(-2,16,-10,PURPUR_BLOCK)
Block(-2,16,-9,PURPUR_BLOCK)
Block(-2,16,-8,PURPUR_STAIRS:0)
Block(-2,16,-1,PURPUR_BLOCK)
Block(-2,16,0,PURPUR_STAIRS:0)
Block(-2,16,1,PURPUR_STAIRS:0)
Block(-2,16,2,PURPUR_STAIRS:0)
Block(-2,16,3,PURPUR_BLOCK)
Block(-2,17,-16,END_BRICKS)
Block(-2,17,-9,END_BRICKS)
Block(-2,17,-1,PURPUR_BLOCK)
Block(-2,17,3,PURPUR_BLOCK)
Block(-2,18,-16,END_BRICKS)
Block(-2,18,-9,END_BRICKS)
Block(-2,18,-1,END_ROD)
Block(-2,18,3,END_ROD)
Block(-2,19,-16,END_BRICKS)
Block(-2,19,-9,END_BRICKS)
Block(-2,20,-18,PURPUR_STAIRS:2)
Block(-2,20,-17,PURPUR_BLOCK)
Block(-2,20,-16,PURPUR_BLOCK)
Block(-2,20,-15,PURPUR_BLOCK)
Block(-2,20,-14,PURPUR_BLOCK)
Block(-2,20,-13,PURPUR_BLOCK)
Block(-2,20,-12,PURPUR_BLOCK)
Block(-2,20,-11,PURPUR_BLOCK)
Block(-2,20,-10,PURPUR_BLOCK)
Block(-2,20,-9,PURPUR_BLOCK)
Block(-2,20,-8,PURPUR_BLOCK)
Block(-2,20,-7,PURPUR_STAIRS:0)
Block(-2,22,1,PURPUR_STAIRS:4)
Block(-2,24,-2,PURPUR_STAIRS:6)
Block(-2,24,-1,PURPUR_STAIRS:4)
Block(-2,24,0,PURPUR_STAIRS:0)
Block(-2,24,1,PURPUR_STAIRS:4)
Block(-2,24,2,PURPUR_STAIRS:0)
Block(-2,24,3,PURPUR_STAIRS:4)
Block(-2,24,4,PURPUR_STAIRS:4)
Block(-2,25,-2,END_ROD)
Block(-2,25,4,END_ROD)
Block(-2,28,-3,PURPUR_STAIRS:6)
Block(-2,28,-2,PURPUR_BLOCK)
Block(-2,28,-1,PURPUR_BLOCK)
Block(-2,28,0,PURPUR_BLOCK)
Block(-2,28,1,PURPUR_BLOCK)
Block(-2,28,2,PURPUR_BLOCK)
Block(-2,28,3,PURPUR_BLOCK)
Block(-2,28,4,PURPUR_BLOCK)
Block(-2,28,5,PURPUR_STAIRS:7)
Block(-1,0,-3,PURPUR_BLOCK)
Block(-1,0,-2,PURPUR_BLOCK)
Block(-1,0,-1,PURPUR_BLOCK)
Block(-1,0,0,PURPUR_BLOCK)
Block(-1,0,1,PURPUR_BLOCK)
Block(-1,0,2,PURPUR_BLOCK)
Block(-1,0,3,PURPUR_BLOCK)
Block(-1,0,4,PURPUR_BLOCK)
Block(-1,1,-3,END_BRICKS)
Block(-1,1,1,PURPUR_SLAB)
Block(-1,1,4,END_BRICKS)
Block(-1,2,-3,STAINED_GLASS:2)
Block(-1,2,4,STAINED_GLASS:2)
Block(-1,3,-3,STAINED_GLASS:2)
Block(-1,3,4,STAINED_GLASS:2)
Block(-1,4,-5,PURPUR_STAIRS:6)
Block(-1,4,-4,PURPUR_BLOCK)
Block(-1,4,-3,PURPUR_BLOCK)
Block(-1,4,4,PURPUR_BLOCK)
Block(-1,4,5,PURPUR_BLOCK)
Block(-1,4,6,PURPUR_STAIRS:7)
Block(-1,5,-4,END_BRICKS)
Block(-1,5,1,PURPUR_PILLAR:0)
Block(-1,5,5,END_BRICKS)
Block(-1,6,-4,END_BRICKS)
Block(-1,6,1,PURPUR_PILLAR:0)
Block(-1,6,5,END_BRICKS)
Block(-1,7,-4,END_BRICKS)
Block(-1,7,1,PURPUR_PILLAR:0)
Block(-1,7,5,END_BRICKS)
Block(-1,8,-6,PURPUR_STAIRS:6)
Block(-1,8,-5,PURPUR_BLOCK)
Block(-1,8,-4,PURPUR_BLOCK)
Block(-1,8,-3,PURPUR_BLOCK)
Block(-1,8,-2,PURPUR_BLOCK)
Block(-1,8,-1,PURPUR_BLOCK)
Block(-1,8,0,PURPUR_BLOCK)
Block(-1,8,1,PURPUR_BLOCK)
Block(-1,8,2,PURPUR_BLOCK)
Block(-1,8,3,PURPUR_BLOCK)
Block(-1,8,4,PURPUR_BLOCK)
Block(-1,8,5,PURPUR_BLOCK)
Block(-1,8,6,PURPUR_BLOCK)
Block(-1,8,7,PURPUR_STAIRS:7)
Block(-1,9,0,PURPUR_PILLAR:0)
Block(-1,9,1,PURPUR_PILLAR:0)
Block(-1,9,2,PURPUR_PILLAR:0)
Block(-1,10,0,PURPUR_PILLAR:0)
Block(-1,10,1,PURPUR_PILLAR)
Block(-1,10,2,PURPUR_PILLAR:0)
Block(-1,11,0,PURPUR_PILLAR:0)
Block(-1,11,1,PURPUR_PILLAR:0)
Block(-1,11,2,PURPUR_PILLAR:0)
Block(-1,12,0,PURPUR_BLOCK)
Block(-1,12,1,PURPUR_BLOCK)
Block(-1,12,2,PURPUR_BLOCK)
Block(-1,13,0,PURPUR_PILLAR:0)
Block(-1,13,1,PURPUR_PILLAR:0)
Block(-1,13,2,PURPUR_PILLAR:0)
Block(-1,14,0,PURPUR_PILLAR:0)
Block(-1,14,1,PURPUR_PILLAR)
Block(-1,14,2,PURPUR_PILLAR:0)
Block(-1,15,0,PURPUR_BLOCK)
Block(-1,15,1,PURPUR_BLOCK)
Block(-1,15,2,PURPUR_BLOCK)
Block(-1,16,-16,PURPUR_BLOCK)
Block(-1,16,-15,PURPUR_BLOCK)
Block(-1,16,-14,PURPUR_BLOCK)
Block(-1,16,-13,PURPUR_BLOCK)
Block(-1,16,-12,PURPUR_BLOCK)
Block(-1,16,-11,PURPUR_BLOCK)
Block(-1,16,-10,PURPUR_BLOCK)
Block(-1,16,-9,PURPUR_BLOCK)
Block(-1,16,-8,PURPUR_BLOCK)
Block(-1,16,-7,PURPUR_BLOCK)
Block(-1,16,-6,PURPUR_BLOCK)
Block(-1,16,-5,PURPUR_BLOCK)
Block(-1,16,-4,PURPUR_BLOCK)
Block(-1,16,-3,PURPUR_BLOCK)
Block(-1,16,-2,PURPUR_BLOCK)
Block(-1,16,-1,PURPUR_BLOCK)
Block(-1,16,0,PURPUR_BLOCK)
Block(-1,16,1,PURPUR_BLOCK)
Block(-1,16,2,PURPUR_BLOCK)
Block(-1,16,3,PURPUR_BLOCK)
Block(-1,17,-16,END_BRICKS)
Block(-1,17,-9,END_BRICKS)
Block(-1,17,-7,PURPUR_BLOCK)
Block(-1,17,-6,PURPUR_BLOCK)
Block(-1,17,-5,PURPUR_STAIRS:0)
Block(-1,17,-4,PURPUR_STAIRS:0)
Block(-1,17,-3,PURPUR_STAIRS:0)
Block(-1,17,-2,PURPUR_BLOCK)
Block(-1,17,-1,PURPUR_BLOCK)
Block(-1,17,3,PURPUR_BLOCK)
Block(-1,18,-16,STAINED_GLASS:2)
Block(-1,18,-9,END_BRICKS)
Block(-1,18,-7,PURPUR_BLOCK)
Block(-1,18,-6,END_ROD)
Block(-1,18,-2,END_ROD)
Block(-1,18,-1,PURPUR_BLOCK)
Block(-1,18,3,PURPUR_BLOCK)
Block(-1,19,-16,STAINED_GLASS:2)
Block(-1,19,-9,END_BRICKS)
Block(-1,19,-7,PURPUR_BLOCK)
Block(-1,19,-1,PURPUR_BLOCK)
Block(-1,19,0,PURPUR_SLAB:8)
Block(-1,19,2,PURPUR_SLAB:8)
Block(-1,19,3,PURPUR_BLOCK)
Block(-1,20,-18,PURPUR_STAIRS:6)
Block(-1,20,-17,PURPUR_BLOCK)
Block(-1,20,-16,PURPUR_BLOCK)
Block(-1,20,-15,PURPUR_BLOCK)
Block(-1,20,-14,PURPUR_BLOCK)
Block(-1,20,-13,PURPUR_BLOCK)
Block(-1,20,-12,PURPUR_BLOCK)
Block(-1,20,-11,PURPUR_BLOCK)
Block(-1,20,-10,PURPUR_BLOCK)
Block(-1,20,-9,PURPUR_BLOCK)
Block(-1,20,-8,PURPUR_BLOCK)
Block(-1,20,-7,PURPUR_SLAB)
Block(-1,20,-1,PURPUR_SLAB)
Block(-1,20,0,PURPUR_BLOCK)
Block(-1,20,1,PURPUR_BLOCK)
Block(-1,20,2,PURPUR_BLOCK)
Block(-1,20,3,PURPUR_SLAB)
Block(-1,21,0,PURPUR_PILLAR:0)
Block(-1,21,1,PURPUR_PILLAR:0)
Block(-1,21,2,PURPUR_PILLAR:0)
Block(-1,22,0,PURPUR_PILLAR:0)
Block(-1,22,1,PURPUR_PILLAR)
Block(-1,22,2,PURPUR_PILLAR:0)
Block(-1,23,0,PURPUR_PILLAR:0)
Block(-1,23,1,PURPUR_PILLAR:0)
Block(-1,23,2,PURPUR_PILLAR:0)
Block(-1,24,-3,WALL_BANNER,EndTowerD/3-banner.nbt)
Block(-1,24,-2,PURPUR_STAIRS:6)
Block(-1,24,-1,PURPUR_BLOCK)
Block(-1,24,0,PURPUR_BLOCK)
Block(-1,24,1,PURPUR_BLOCK)
Block(-1,24,2,PURPUR_BLOCK)
Block(-1,24,3,PURPUR_BLOCK)
Block(-1,24,4,PURPUR_STAIRS:7)
Block(-1,24,5,WALL_BANNER:3,EndTowerD/4-banner.nbt)
Block(-1,25,-1,PURPUR_PILLAR:0)
Block(-1,25,0,END_BRICKS)
Block(-1,25,1,END_BRICKS)
Block(-1,25,2,END_BRICKS)
Block(-1,25,3,PURPUR_PILLAR:0)
Block(-1,26,-1,PURPUR_PILLAR:0)
Block(-1,26,0,END_BRICKS)
Block(-1,26,1,STAINED_GLASS:2)
Block(-1,26,2,END_BRICKS)
Block(-1,26,3,PURPUR_PILLAR:0)
Block(-1,27,-1,PURPUR_PILLAR:0)
Block(-1,27,0,END_BRICKS)
Block(-1,27,1,STAINED_GLASS:2)
Block(-1,27,2,END_BRICKS)
Block(-1,27,3,PURPUR_PILLAR:0)
Block(-1,28,-3,PURPUR_STAIRS:2)
Block(-1,28,-2,PURPUR_BLOCK)
Block(-1,28,-1,PURPUR_BLOCK)
Block(-1,28,0,PURPUR_BLOCK)
Block(-1,28,1,PURPUR_BLOCK)
Block(-1,28,2,PURPUR_BLOCK)
Block(-1,28,3,PURPUR_BLOCK)
Block(-1,28,4,PURPUR_BLOCK)
Block(-1,28,5,PURPUR_STAIRS:0)
Block(0,0,-3,PURPUR_BLOCK)
Block(0,0,-2,PURPUR_BLOCK)
Block(0,0,-1,PURPUR_BLOCK)
Block(0,0,0,PURPUR_BLOCK)
Block(0,0,1,PURPUR_BLOCK)
Block(0,0,2,PURPUR_BLOCK)
Block(0,0,3,PURPUR_BLOCK)
Block(0,0,4,PURPUR_BLOCK)
Block(0,1,-3,END_BRICKS)
Block(0,1,0,PURPUR_BLOCK)
Block(0,1,1,PURPUR_STAIRS:0)
Block(0,1,4,END_BRICKS)
Block(0,2,-3,END_BRICKS)
Block(0,2,0,PURPUR_BLOCK)
Block(0,2,4,END_BRICKS)
Block(0,3,-3,END_BRICKS)
Block(0,3,-1,PURPUR_SLAB:8)
Block(0,3,0,PURPUR_BLOCK)
Block(0,3,4,END_BRICKS)
Block(0,4,-5,PURPUR_STAIRS:2)
Block(0,4,-4,PURPUR_BLOCK)
Block(0,4,-3,PURPUR_BLOCK)
Block(0,4,0,PURPUR_STAIRS:2)
Block(0,4,1,PURPUR_SLAB:8)
Block(0,4,2,PURPUR_SLAB:8)
Block(0,4,3,PURPUR_SLAB:8)
Block(0,4,4,PURPUR_BLOCK)
Block(0,4,5,PURPUR_BLOCK)
Block(0,4,6,PURPUR_STAIRS:0)
Block(0,5,-4,END_BRICKS)
Block(0,5,1,LADDER:5)
Block(0,5,5,END_BRICKS)
Block(0,6,-4,END_BRICKS)
Block(0,6,1,LADDER:5)
Block(0,6,5,END_BRICKS)
Block(0,7,-4,END_BRICKS)
Block(0,7,1,LADDER:5)
Block(0,7,5,END_BRICKS)
Block(0,8,-6,PURPUR_STAIRS:2)
Block(0,8,-5,PURPUR_BLOCK)
Block(0,8,-4,PURPUR_BLOCK)
Block(0,8,-3,PURPUR_BLOCK)
Block(0,8,-2,PURPUR_BLOCK)
Block(0,8,-1,PURPUR_BLOCK)
Block(0,8,3,PURPUR_BLOCK)
Block(0,8,4,PURPUR_BLOCK)
Block(0,8,5,PURPUR_BLOCK)
Block(0,8,6,PURPUR_BLOCK)
Block(0,8,7,PURPUR_STAIRS:0)
Block(0,9,-1,PURPUR_PILLAR:0)
Block(0,9,3,PURPUR_PILLAR:0)
Block(0,10,-1,PURPUR_PILLAR:0)
Block(0,10,3,PURPUR_PILLAR:0)
Block(0,11,-1,PURPUR_PILLAR:0)
Block(0,11,1,PURPUR_SLAB)
Block(0,11,3,PURPUR_PILLAR:0)
Block(0,12,-1,PURPUR_BLOCK)
Block(0,12,3,PURPUR_BLOCK)
Block(0,13,-1,PURPUR_PILLAR:0)
Block(0,13,3,PURPUR_PILLAR:0)
Block(0,14,-1,PURPUR_PILLAR:0)
Block(0,14,3,PURPUR_PILLAR:0)
Block(0,15,-11,PURPUR_BLOCK)
Block(0,15,-6,PURPUR_STAIRS:4)
Block(0,15,-1,PURPUR_BLOCK)
Block(0,15,1,PURPUR_SLAB)
Block(0,15,3,PURPUR_PILLAR:0)
Block(0,16,-16,PURPUR_BLOCK)
Block(0,16,-15,PURPUR_BLOCK)
Block(0,16,-14,PURPUR_BLOCK)
Block(0,16,-13,PURPUR_BLOCK)
Block(0,16,-12,PURPUR_BLOCK)
Block(0,16,-11,PURPUR_BLOCK)
Block(0,16,-10,PURPUR_BLOCK)
Block(0,16,-9,PURPUR_BLOCK)
Block(0,16,-8,PURPUR_BLOCK)
Block(0,16,-7,PURPUR_BLOCK)
Block(0,16,-6,PURPUR_STAIRS:0)
Block(0,16,-5,PURPUR_BLOCK)
Block(0,16,-4,PURPUR_BLOCK)
Block(0,16,-3,PURPUR_BLOCK)
Block(0,16,-2,PURPUR_STAIRS:2)
Block(0,16,-1,PURPUR_BLOCK)
Block(0,16,3,PURPUR_BLOCK)
Block(0,17,-16,END_BRICKS)
Block(0,17,-15,CHEST:3,EndTowerD/5-chest.nbt)
Block(0,17,3,PURPUR_PILLAR:0)
Block(0,18,-16,END_BRICKS)
Block(0,18,3,PURPUR_PILLAR:0)
Block(0,19,-16,END_BRICKS)
Block(0,19,-7,PURPUR_SLAB:8)
Block(0,19,-1,PURPUR_SLAB:8)
Block(0,19,1,PURPUR_SLAB)
Block(0,19,3,PURPUR_PILLAR:0)
Block(0,20,-18,PURPUR_STAIRS:2)
Block(0,20,-17,PURPUR_BLOCK)
Block(0,20,-16,PURPUR_BLOCK)
Block(0,20,-15,PURPUR_BLOCK)
Block(0,20,-14,PURPUR_BLOCK)
Block(0,20,-13,PURPUR_BLOCK)
Block(0,20,-12,PURPUR_BLOCK)
Block(0,20,-11,PURPUR_BLOCK)
Block(0,20,-10,PURPUR_BLOCK)
Block(0,20,-9,PURPUR_BLOCK)
Block(0,20,-8,PURPUR_BLOCK)
Block(0,20,-7,PURPUR_BLOCK)
Block(0,20,-1,PURPUR_BLOCK)
Block(0,20,3,PURPUR_BLOCK)
Block(0,21,-1,PURPUR_PILLAR:0)
Block(0,21,3,PURPUR_PILLAR:0)
Block(0,22,-1,PURPUR_PILLAR:0)
Block(0,22,3,PURPUR_PILLAR:0)
Block(0,23,-1,PURPUR_PILLAR:0)
Block(0,23,1,PURPUR_SLAB)
Block(0,23,3,PURPUR_PILLAR:0)
Block(0,24,-2,PURPUR_STAIRS:2)
Block(0,24,-1,PURPUR_BLOCK)
Block(0,24,3,PURPUR_BLOCK)
Block(0,24,4,PURPUR_STAIRS:0)
Block(0,25,-1,END_BRICKS)
Block(0,25,3,END_BRICKS)
Block(0,26,-1,END_BRICKS)
Block(0,26,3,END_BRICKS)
Block(0,27,-1,END_BRICKS)
Block(0,27,3,END_BRICKS)
Block(0,28,-3,PURPUR_STAIRS:2)
Block(0,28,-2,PURPUR_BLOCK)
Block(0,28,-1,PURPUR_BLOCK)
Block(0,28,0,PURPUR_BLOCK)
Block(0,28,1,PURPUR_BLOCK)
Block(0,28,2,PURPUR_BLOCK)
Block(0,28,3,PURPUR_BLOCK)
Block(0,28,4,PURPUR_BLOCK)
Block(0,28,5,PURPUR_STAIRS:0)
Block(1,0,-3,PURPUR_BLOCK)
Block(1,0,-2,PURPUR_BLOCK)
Block(1,0,-1,PURPUR_BLOCK)
Block(1,0,0,PURPUR_BLOCK)
Block(1,0,1,PURPUR_BLOCK)
Block(1,0,2,PURPUR_BLOCK)
Block(1,0,3,PURPUR_BLOCK)
Block(1,0,4,PURPUR_BLOCK)
Block(1,1,-3,END_BRICKS)
Block(1,1,0,PURPUR_BLOCK)
Block(1,1,1,PURPUR_BLOCK)
Block(1,1,4,END_BRICKS)
Block(1,2,-3,END_BRICKS)
Block(1,2,0,PURPUR_BLOCK)
Block(1,2,1,PURPUR_STAIRS:0)
Block(1,2,2,PURPUR_SLAB)
Block(1,2,4,END_BRICKS)
Block(1,3,-3,END_BRICKS)
Block(1,3,0,PURPUR_STAIRS:1)
Block(1,3,4,END_BRICKS)
Block(1,4,-5,PURPUR_STAIRS:2)
Block(1,4,-4,PURPUR_BLOCK)
Block(1,4,-3,PURPUR_BLOCK)
Block(1,4,4,PURPUR_BLOCK)
Block(1,4,5,PURPUR_BLOCK)
Block(1,4,6,PURPUR_STAIRS:0)
Block(1,5,-4,END_BRICKS)
Block(1,5,5,END_BRICKS)
Block(1,6,-4,END_BRICKS)
Block(1,6,5,END_BRICKS)
Block(1,7,-4,END_BRICKS)
Block(1,7,5,END_BRICKS)
Block(1,8,-6,PURPUR_STAIRS:2)
Block(1,8,-5,PURPUR_BLOCK)
Block(1,8,-4,PURPUR_BLOCK)
Block(1,8,-3,PURPUR_BLOCK)
Block(1,8,-2,PURPUR_BLOCK)
Block(1,8,-1,PURPUR_BLOCK)
Block(1,8,0,PURPUR_SLAB)
Block(1,8,3,PURPUR_BLOCK)
Block(1,8,4,PURPUR_BLOCK)
Block(1,8,5,PURPUR_BLOCK)
Block(1,8,6,PURPUR_BLOCK)
Block(1,8,7,PURPUR_STAIRS:0)
Block(1,9,-1,PURPUR_PILLAR:0)
Block(1,9,3,PURPUR_PILLAR:0)
Block(1,10,-2,PURPUR_STAIRS:6)
Block(1,10,-1,PURPUR_PILLAR:8)
Block(1,10,2,PURPUR_SLAB)
Block(1,10,3,PURPUR_PILLAR:8)
Block(1,10,4,PURPUR_STAIRS:7)
Block(1,11,-1,PURPUR_PILLAR:0)
Block(1,11,3,PURPUR_PILLAR:0)
Block(1,12,-1,PURPUR_BLOCK)
Block(1,12,0,PURPUR_SLAB)
Block(1,12,3,PURPUR_BLOCK)
Block(1,13,-1,PURPUR_PILLAR:0)
Block(1,13,3,PURPUR_PILLAR:0)
Block(1,14,-2,PURPUR_STAIRS:6)
Block(1,14,-1,PURPUR_PILLAR:8)
Block(1,14,2,PURPUR_SLAB)
Block(1,14,3,PURPUR_PILLAR:8)
Block(1,14,4,PURPUR_STAIRS:7)
Block(1,15,-11,PURPUR_BLOCK)
Block(1,15,-10,PURPUR_PILLAR:8)
Block(1,15,-9,PURPUR_PILLAR:8)
Block(1,15,-8,PURPUR_PILLAR:8)
Block(1,15,-7,PURPUR_PILLAR:8)
Block(1,15,-6,PURPUR_PILLAR:8)
Block(1,15,-5,PURPUR_PILLAR:8)
Block(1,15,-4,PURPUR_PILLAR:8)
Block(1,15,-3,PURPUR_PILLAR:8)
Block(1,15,-2,PURPUR_PILLAR:8)
Block(1,15,-1,PURPUR_BLOCK)
Block(1,15,3,PURPUR_PILLAR:0)
Block(1,16,-16,PURPUR_BLOCK)
Block(1,16,-15,PURPUR_BLOCK)
Block(1,16,-14,PURPUR_BLOCK)
Block(1,16,-13,PURPUR_BLOCK)
Block(1,16,-12,PURPUR_BLOCK)
Block(1,16,-11,PURPUR_BLOCK)
Block(1,16,-10,PURPUR_BLOCK)
Block(1,16,-9,PURPUR_BLOCK)
Block(1,16,-8,PURPUR_BLOCK)
Block(1,16,-7,PURPUR_BLOCK)
Block(1,16,-6,PURPUR_STAIRS:0)
Block(1,16,-5,PURPUR_BLOCK)
Block(1,16,-4,PURPUR_BLOCK)
Block(1,16,-3,PURPUR_BLOCK)
Block(1,16,-2,PURPUR_STAIRS:2)
Block(1,16,-1,PURPUR_BLOCK)
Block(1,16,0,PURPUR_SLAB)
Block(1,16,3,PURPUR_BLOCK)
Block(1,17,-16,END_BRICKS)
Block(1,17,3,PURPUR_PILLAR:0)
Block(1,18,-16,END_BRICKS)
Block(1,18,2,PURPUR_SLAB)
Block(1,18,3,PURPUR_PILLAR:8)
Block(1,18,4,PURPUR_STAIRS:7)
Block(1,19,-16,END_BRICKS)
Block(1,19,3,PURPUR_PILLAR:0)
Block(1,20,-18,PURPUR_STAIRS:2)
Block(1,20,-17,PURPUR_BLOCK)
Block(1,20,-16,PURPUR_BLOCK)
Block(1,20,-15,PURPUR_BLOCK)
Block(1,20,-14,PURPUR_BLOCK)
Block(1,20,-13,PURPUR_BLOCK)
Block(1,20,-12,PURPUR_BLOCK)
Block(1,20,-11,PURPUR_BLOCK)
Block(1,20,-10,PURPUR_BLOCK)
Block(1,20,-9,PURPUR_BLOCK)
Block(1,20,-8,PURPUR_BLOCK)
Block(1,20,-7,PURPUR_BLOCK)
Block(1,20,-1,PURPUR_BLOCK)
Block(1,20,0,PURPUR_SLAB)
Block(1,20,3,PURPUR_BLOCK)
Block(1,21,-1,PURPUR_PILLAR:0)
Block(1,21,3,PURPUR_PILLAR:0)
Block(1,22,-2,PURPUR_STAIRS:6)
Block(1,22,-1,PURPUR_PILLAR:8)
Block(1,22,2,PURPUR_SLAB)
Block(1,22,3,PURPUR_PILLAR:8)
Block(1,22,4,PURPUR_STAIRS:7)
Block(1,23,-1,PURPUR_PILLAR:0)
Block(1,23,3,PURPUR_PILLAR:0)
Block(1,24,-2,PURPUR_STAIRS:6)
Block(1,24,-1,PURPUR_BLOCK)
Block(1,24,3,PURPUR_BLOCK)
Block(1,24,4,PURPUR_STAIRS:7)
Block(1,25,-1,END_BRICKS)
Block(1,26,-1,STAINED_GLASS:2)
Block(1,27,-1,STAINED_GLASS:2)
Block(1,27,3,END_BRICKS)
Block(1,28,-3,PURPUR_STAIRS:6)
Block(1,28,-2,PURPUR_BLOCK)
Block(1,28,-1,PURPUR_BLOCK)
Block(1,28,0,PURPUR_BLOCK)
Block(1,28,1,PURPUR_BLOCK)
Block(1,28,2,PURPUR_BLOCK)
Block(1,28,3,PURPUR_BLOCK)
Block(1,28,4,PURPUR_BLOCK)
Block(1,28,5,PURPUR_STAIRS:7)
Block(2,0,-3,PURPUR_BLOCK)
Block(2,0,-2,PURPUR_BLOCK)
Block(2,0,-1,PURPUR_BLOCK)
Block(2,0,0,PURPUR_BLOCK)
Block(2,0,1,PURPUR_BLOCK)
Block(2,0,2,PURPUR_BLOCK)
Block(2,0,3,PURPUR_BLOCK)
Block(2,0,4,PURPUR_BLOCK)
Block(2,1,-3,END_BRICKS)
Block(2,1,4,END_BRICKS)
Block(2,2,-3,STAINED_GLASS:2)
Block(2,2,4,STAINED_GLASS:2)
Block(2,3,-3,STAINED_GLASS:2)
Block(2,3,0,PURPUR_SLAB)
Block(2,3,4,STAINED_GLASS:2)
Block(2,4,-5,PURPUR_STAIRS:6)
Block(2,4,-4,PURPUR_BLOCK)
Block(2,4,-3,PURPUR_BLOCK)
Block(2,4,4,PURPUR_BLOCK)
Block(2,4,5,PURPUR_BLOCK)
Block(2,4,6,PURPUR_STAIRS:7)
Block(2,5,-4,END_BRICKS)
Block(2,5,5,END_BRICKS)
Block(2,6,-4,END_BRICKS)
Block(2,6,5,END_BRICKS)
Block(2,7,-4,END_BRICKS)
Block(2,7,5,END_BRICKS)
Block(2,8,-6,PURPUR_STAIRS:6)
Block(2,8,-5,PURPUR_BLOCK)
Block(2,8,-4,PURPUR_BLOCK)
Block(2,8,-3,PURPUR_BLOCK)
Block(2,8,-2,PURPUR_BLOCK)
Block(2,8,-1,PURPUR_BLOCK)
Block(2,8,3,PURPUR_BLOCK)
Block(2,8,4,PURPUR_BLOCK)
Block(2,8,5,PURPUR_BLOCK)
Block(2,8,6,PURPUR_BLOCK)
Block(2,8,7,PURPUR_STAIRS:7)
Block(2,9,-1,PURPUR_PILLAR:0)
Block(2,9,1,PURPUR_SLAB)
Block(2,9,3,PURPUR_PILLAR:0)
Block(2,10,-1,PURPUR_PILLAR:0)
Block(2,10,3,PURPUR_PILLAR:0)
Block(2,11,-1,PURPUR_PILLAR:0)
Block(2,11,3,PURPUR_PILLAR:0)
Block(2,12,-1,PURPUR_BLOCK)
Block(2,12,3,PURPUR_BLOCK)
Block(2,13,-1,PURPUR_PILLAR:0)
Block(2,13,1,PURPUR_SLAB)
Block(2,13,3,PURPUR_PILLAR:0)
Block(2,14,-1,PURPUR_PILLAR:0)
Block(2,14,3,PURPUR_PILLAR:0)
Block(2,15,-11,PURPUR_BLOCK)
Block(2,15,-6,PURPUR_STAIRS:5)
Block(2,15,-1,PURPUR_BLOCK)
Block(2,15,3,PURPUR_PILLAR:0)
Block(2,16,-16,PURPUR_BLOCK)
Block(2,16,-15,PURPUR_BLOCK)
Block(2,16,-14,PURPUR_BLOCK)
Block(2,16,-13,PURPUR_BLOCK)
Block(2,16,-12,PURPUR_BLOCK)
Block(2,16,-11,PURPUR_BLOCK)
Block(2,16,-10,PURPUR_BLOCK)
Block(2,16,-9,PURPUR_BLOCK)
Block(2,16,-8,PURPUR_BLOCK)
Block(2,16,-7,PURPUR_BLOCK)
Block(2,16,-6,PURPUR_STAIRS:0)
Block(2,16,-5,PURPUR_BLOCK)
Block(2,16,-4,PURPUR_BLOCK)
Block(2,16,-3,PURPUR_BLOCK)
Block(2,16,-2,PURPUR_STAIRS:2)
Block(2,16,-1,PURPUR_BLOCK)
Block(2,16,3,PURPUR_BLOCK)
Block(2,17,-16,END_BRICKS)
Block(2,17,-9,END_BRICKS)
Block(2,17,1,PURPUR_SLAB)
Block(2,17,3,PURPUR_PILLAR:0)
Block(2,18,-16,STAINED_GLASS:2)
Block(2,18,-9,END_BRICKS)
Block(2,18,3,PURPUR_PILLAR:0)
Block(2,19,-16,STAINED_GLASS:2)
Block(2,19,-9,END_BRICKS)
Block(2,19,-7,PURPUR_SLAB:8)
Block(2,19,-1,PURPUR_SLAB:8)
Block(2,19,3,PURPUR_PILLAR:0)
Block(2,20,-18,PURPUR_STAIRS:6)
Block(2,20,-17,PURPUR_BLOCK)
Block(2,20,-16,PURPUR_BLOCK)
Block(2,20,-15,PURPUR_BLOCK)
Block(2,20,-14,PURPUR_BLOCK)
Block(2,20,-13,PURPUR_BLOCK)
Block(2,20,-12,PURPUR_BLOCK)
Block(2,20,-11,PURPUR_BLOCK)
Block(2,20,-10,PURPUR_BLOCK)
Block(2,20,-9,PURPUR_BLOCK)
Block(2,20,-8,PURPUR_BLOCK)
Block(2,20,-7,PURPUR_BLOCK)
Block(2,20,-1,PURPUR_BLOCK)
Block(2,20,3,PURPUR_BLOCK)
Block(2,21,-1,PURPUR_PILLAR:0)
Block(2,21,1,PURPUR_SLAB)
Block(2,21,3,PURPUR_PILLAR:0)
Block(2,22,-1,PURPUR_PILLAR:0)
Block(2,22,3,PURPUR_PILLAR:0)
Block(2,23,-1,PURPUR_PILLAR:0)
Block(2,23,3,PURPUR_PILLAR:0)
Block(2,24,-2,PURPUR_STAIRS:2)
Block(2,24,-1,PURPUR_BLOCK)
Block(2,24,0,PURPUR_SLAB)
Block(2,24,1,PURPUR_SLAB)
Block(2,24,2,PURPUR_BLOCK)
Block(2,24,3,PURPUR_BLOCK)
Block(2,24,4,PURPUR_STAIRS:0)
Block(2,25,-1,END_BRICKS)
Block(2,26,-1,END_BRICKS)
Block(2,27,-1,END_BRICKS)
Block(2,27,3,END_BRICKS)
Block(2,28,-3,PURPUR_STAIRS:2)
Block(2,28,-2,PURPUR_BLOCK)
Block(2,28,-1,PURPUR_BLOCK)
Block(2,28,0,PURPUR_BLOCK)
Block(2,28,1,PURPUR_BLOCK)
Block(2,28,2,PURPUR_BLOCK)
Block(2,28,3,PURPUR_BLOCK)
Block(2,28,4,PURPUR_BLOCK)
Block(2,28,5,PURPUR_STAIRS:0)
Block(3,0,-3,PURPUR_BLOCK)
Block(3,0,-2,PURPUR_BLOCK)
Block(3,0,-1,PURPUR_BLOCK)
Block(3,0,0,PURPUR_BLOCK)
Block(3,0,1,PURPUR_BLOCK)
Block(3,0,2,PURPUR_BLOCK)
Block(3,0,3,PURPUR_BLOCK)
Block(3,0,4,PURPUR_BLOCK)
Block(3,1,-3,END_BRICKS)
Block(3,1,4,END_BRICKS)
Block(3,2,-3,END_BRICKS)
Block(3,2,4,END_BRICKS)
Block(3,3,-3,END_BRICKS)
Block(3,3,4,END_BRICKS)
Block(3,4,-5,PURPUR_STAIRS:6)
Block(3,4,-4,PURPUR_BLOCK)
Block(3,4,-3,PURPUR_BLOCK)
Block(3,4,4,PURPUR_BLOCK)
Block(3,4,5,PURPUR_BLOCK)
Block(3,4,6,PURPUR_STAIRS:7)
Block(3,5,-4,END_BRICKS)
Block(3,5,5,END_BRICKS)
Block(3,6,-4,STAINED_GLASS:2)
Block(3,6,5,STAINED_GLASS:2)
Block(3,7,-4,STAINED_GLASS:2)
Block(3,7,5,STAINED_GLASS:2)
Block(3,8,-6,PURPUR_STAIRS:6)
Block(3,8,-5,PURPUR_BLOCK)
Block(3,8,-4,PURPUR_BLOCK)
Block(3,8,-3,PURPUR_BLOCK)
Block(3,8,-2,PURPUR_BLOCK)
Block(3,8,-1,PURPUR_BLOCK)
Block(3,8,0,PURPUR_BLOCK)
Block(3,8,1,PURPUR_BLOCK)
Block(3,8,2,PURPUR_BLOCK)
Block(3,8,3,PURPUR_BLOCK)
Block(3,8,4,PURPUR_BLOCK)
Block(3,8,5,PURPUR_BLOCK)
Block(3,8,6,PURPUR_BLOCK)
Block(3,8,7,PURPUR_STAIRS:7)
Block(3,9,0,PURPUR_PILLAR:0)
Block(3,9,1,PURPUR_PILLAR:0)
Block(3,9,2,PURPUR_PILLAR:0)
Block(3,10,0,PURPUR_PILLAR:0)
Block(3,10,1,PURPUR_PILLAR)
Block(3,10,2,PURPUR_PILLAR:0)
Block(3,11,0,PURPUR_PILLAR:0)
Block(3,11,1,PURPUR_PILLAR:0)
Block(3,11,2,PURPUR_PILLAR:0)
Block(3,12,0,PURPUR_BLOCK)
Block(3,12,1,PURPUR_BLOCK)
Block(3,12,2,PURPUR_BLOCK)
Block(3,13,0,PURPUR_PILLAR:0)
Block(3,13,1,PURPUR_PILLAR:0)
Block(3,13,2,PURPUR_PILLAR:0)
Block(3,14,0,PURPUR_PILLAR:0)
Block(3,14,1,PURPUR_PILLAR)
Block(3,14,2,PURPUR_PILLAR:0)
Block(3,15,0,PURPUR_BLOCK)
Block(3,15,1,PURPUR_BLOCK)
Block(3,15,2,PURPUR_BLOCK)
Block(3,16,-16,PURPUR_BLOCK)
Block(3,16,-15,PURPUR_BLOCK)
Block(3,16,-14,PURPUR_BLOCK)
Block(3,16,-13,PURPUR_BLOCK)
Block(3,16,-12,PURPUR_BLOCK)
Block(3,16,-11,PURPUR_BLOCK)
Block(3,16,-10,PURPUR_BLOCK)
Block(3,16,-9,PURPUR_BLOCK)
Block(3,16,-8,PURPUR_STAIRS:0)
Block(3,16,-7,PURPUR_BLOCK)
Block(3,16,-6,PURPUR_BLOCK)
Block(3,16,-5,PURPUR_BLOCK)
Block(3,16,-4,PURPUR_BLOCK)
Block(3,16,-3,PURPUR_BLOCK)
Block(3,16,-2,PURPUR_BLOCK)
Block(3,16,-1,PURPUR_BLOCK)
Block(3,16,0,PURPUR_BLOCK)
Block(3,16,1,PURPUR_BLOCK)
Block(3,16,2,PURPUR_BLOCK)
Block(3,16,3,PURPUR_BLOCK)
Block(3,17,-16,END_BRICKS)
Block(3,17,-9,END_BRICKS)
Block(3,17,-7,PURPUR_BLOCK)
Block(3,17,-6,PURPUR_BLOCK)
Block(3,17,-5,PURPUR_STAIRS:1)
Block(3,17,-4,PURPUR_STAIRS:1)
Block(3,17,-3,PURPUR_STAIRS:1)
Block(3,17,-2,PURPUR_BLOCK)
Block(3,17,-1,PURPUR_BLOCK)
Block(3,17,3,PURPUR_BLOCK)
Block(3,18,-16,END_BRICKS)
Block(3,18,-9,END_BRICKS)
Block(3,18,-7,PURPUR_BLOCK)
Block(3,18,-6,END_ROD)
Block(3,18,-2,END_ROD)
Block(3,18,-1,PURPUR_BLOCK)
Block(3,18,3,PURPUR_BLOCK)
Block(3,19,-16,END_BRICKS)
Block(3,19,-9,END_BRICKS)
Block(3,19,-7,PURPUR_BLOCK)
Block(3,19,-1,PURPUR_BLOCK)
Block(3,19,0,PURPUR_SLAB:8)
Block(3,19,2,PURPUR_SLAB:8)
Block(3,19,3,PURPUR_BLOCK)
Block(3,20,-18,PURPUR_STAIRS:2)
Block(3,20,-17,PURPUR_BLOCK)
Block(3,20,-16,PURPUR_BLOCK)
Block(3,20,-15,PURPUR_BLOCK)
Block(3,20,-14,PURPUR_BLOCK)
Block(3,20,-13,PURPUR_BLOCK)
Block(3,20,-12,PURPUR_BLOCK)
Block(3,20,-11,PURPUR_BLOCK)
Block(3,20,-10,PURPUR_BLOCK)
Block(3,20,-9,PURPUR_BLOCK)
Block(3,20,-8,PURPUR_BLOCK)
Block(3,20,-7,PURPUR_SLAB)
Block(3,20,-1,PURPUR_SLAB)
Block(3,20,0,PURPUR_BLOCK)
Block(3,20,1,PURPUR_BLOCK)
Block(3,20,2,PURPUR_BLOCK)
Block(3,20,3,PURPUR_SLAB)
Block(3,21,0,PURPUR_PILLAR:0)
Block(3,21,1,PURPUR_PILLAR:0)
Block(3,21,2,PURPUR_PILLAR:0)
Block(3,22,0,PURPUR_PILLAR:0)
Block(3,22,1,PURPUR_PILLAR)
Block(3,22,2,PURPUR_PILLAR:0)
Block(3,23,0,PURPUR_PILLAR:0)
Block(3,23,1,PURPUR_PILLAR:0)
Block(3,23,2,PURPUR_PILLAR:0)
Block(3,24,-3,WALL_BANNER,EndTowerD/6-banner.nbt)
Block(3,24,-2,PURPUR_STAIRS:6)
Block(3,24,-1,PURPUR_BLOCK)
Block(3,24,0,PURPUR_BLOCK)
Block(3,24,1,PURPUR_BLOCK)
Block(3,24,2,PURPUR_BLOCK)
Block(3,24,3,PURPUR_BLOCK)
Block(3,24,4,PURPUR_STAIRS:7)
Block(3,24,5,WALL_BANNER:3,EndTowerD/7-banner.nbt)
Block(3,25,-1,PURPUR_PILLAR:0)
Block(3,25,0,END_BRICKS)
Block(3,25,1,END_BRICKS)
Block(3,25,2,END_BRICKS)
Block(3,25,3,PURPUR_PILLAR:0)
Block(3,26,-1,PURPUR_PILLAR:0)
Block(3,26,0,END_BRICKS)
Block(3,26,1,STAINED_GLASS:2)
Block(3,26,2,END_BRICKS)
Block(3,26,3,PURPUR_PILLAR:0)
Block(3,27,-1,PURPUR_PILLAR:0)
Block(3,27,0,END_BRICKS)
Block(3,27,1,STAINED_GLASS:2)
Block(3,27,2,END_BRICKS)
Block(3,27,3,PURPUR_PILLAR:0)
Block(3,28,-3,PURPUR_STAIRS:2)
Block(3,28,-2,PURPUR_BLOCK)
Block(3,28,-1,PURPUR_BLOCK)
Block(3,28,0,PURPUR_BLOCK)
Block(3,28,1,PURPUR_BLOCK)
Block(3,28,2,PURPUR_BLOCK)
Block(3,28,3,PURPUR_BLOCK)
Block(3,28,4,PURPUR_BLOCK)
Block(3,28,5,PURPUR_STAIRS:0)
Block(4,0,-3,PURPUR_BLOCK)
Block(4,0,-2,PURPUR_BLOCK)
Block(4,0,-1,PURPUR_BLOCK)
Block(4,0,0,PURPUR_BLOCK)
Block(4,0,1,PURPUR_BLOCK)
Block(4,0,2,PURPUR_BLOCK)
Block(4,0,3,PURPUR_BLOCK)
Block(4,0,4,PURPUR_BLOCK)
Block(4,1,-3,PURPUR_PILLAR:0)
Block(4,1,-2,END_BRICKS)
Block(4,1,-1,END_BRICKS)
Block(4,1,0,END_BRICKS)
Block(4,1,1,END_BRICKS)
Block(4,1,2,END_BRICKS)
Block(4,1,3,END_BRICKS)
Block(4,1,4,PURPUR_PILLAR:0)
Block(4,2,-3,PURPUR_PILLAR:0)
Block(4,2,-2,END_BRICKS)
Block(4,2,-1,STAINED_GLASS:2)
Block(4,2,0,END_BRICKS)
Block(4,2,1,END_BRICKS)
Block(4,2,2,STAINED_GLASS:2)
Block(4,2,3,END_BRICKS)
Block(4,2,4,PURPUR_PILLAR:0)
Block(4,3,-3,PURPUR_PILLAR:0)
Block(4,3,-2,END_BRICKS)
Block(4,3,-1,STAINED_GLASS:2)
Block(4,3,0,END_BRICKS)
Block(4,3,1,END_BRICKS)
Block(4,3,2,STAINED_GLASS:2)
Block(4,3,3,END_BRICKS)
Block(4,3,4,PURPUR_PILLAR:0)
Block(4,4,-5,PURPUR_STAIRS:2)
Block(4,4,-4,PURPUR_BLOCK)
Block(4,4,-3,PURPUR_BLOCK)
Block(4,4,-2,PURPUR_BLOCK)
Block(4,4,-1,PURPUR_BLOCK)
Block(4,4,0,PURPUR_BLOCK)
Block(4,4,1,PURPUR_BLOCK)
Block(4,4,2,PURPUR_BLOCK)
Block(4,4,3,PURPUR_BLOCK)
Block(4,4,4,PURPUR_BLOCK)
Block(4,4,5,PURPUR_BLOCK)
Block(4,4,6,PURPUR_STAIRS:0)
Block(4,5,-4,END_BRICKS)
Block(4,5,5,END_BRICKS)
Block(4,6,-4,END_BRICKS)
Block(4,6,5,END_BRICKS)
Block(4,7,-4,END_BRICKS)
Block(4,7,5,END_BRICKS)
Block(4,8,-6,PURPUR_STAIRS:2)
Block(4,8,-5,PURPUR_BLOCK)
Block(4,8,-4,PURPUR_BLOCK)
Block(4,8,-3,PURPUR_BLOCK)
Block(4,8,-2,PURPUR_BLOCK)
Block(4,8,-1,PURPUR_BLOCK)
Block(4,8,0,PURPUR_BLOCK)
Block(4,8,1,PURPUR_BLOCK)
Block(4,8,2,PURPUR_BLOCK)
Block(4,8,3,PURPUR_BLOCK)
Block(4,8,4,PURPUR_BLOCK)
Block(4,8,5,PURPUR_BLOCK)
Block(4,8,6,PURPUR_BLOCK)
Block(4,8,7,PURPUR_STAIRS:0)
Block(4,10,1,PURPUR_STAIRS:5)
Block(4,14,1,PURPUR_STAIRS:5)
Block(4,15,1,PURPUR_PILLAR)
Block(4,16,-16,PURPUR_BLOCK)
Block(4,16,-15,PURPUR_BLOCK)
Block(4,16,-14,PURPUR_BLOCK)
Block(4,16,-13,PURPUR_BLOCK)
Block(4,16,-12,PURPUR_BLOCK)
Block(4,16,-11,PURPUR_BLOCK)
Block(4,16,-10,PURPUR_BLOCK)
Block(4,16,-9,PURPUR_BLOCK)
Block(4,16,-1,PURPUR_BLOCK)
Block(4,16,0,PURPUR_STAIRS:1)
Block(4,16,1,PURPUR_STAIRS:1)
Block(4,16,2,PURPUR_STAIRS:1)
Block(4,16,3,PURPUR_BLOCK)
Block(4,17,-16,PURPUR_PILLAR:0)
Block(4,17,-15,END_BRICKS)
Block(4,17,-14,END_BRICKS)
Block(4,17,-13,END_BRICKS)
Block(4,17,-12,END_BRICKS)
Block(4,17,-11,END_BRICKS)
Block(4,17,-10,END_BRICKS)
Block(4,17,-9,PURPUR_PILLAR:0)
Block(4,17,-1,PURPUR_BLOCK)
Block(4,17,3,PURPUR_BLOCK)
Block(4,18,-16,PURPUR_PILLAR:0)
Block(4,18,-15,END_BRICKS)
Block(4,18,-14,STAINED_GLASS:2)
Block(4,18,-13,END_BRICKS)
Block(4,18,-12,END_BRICKS)
Block(4,18,-11,STAINED_GLASS:2)
Block(4,18,-10,END_BRICKS)
Block(4,18,-9,PURPUR_PILLAR:0)
Block(4,18,-1,END_ROD)
Block(4,18,3,END_ROD)
Block(4,19,-16,PURPUR_PILLAR:0)
Block(4,19,-15,END_BRICKS)
Block(4,19,-14,STAINED_GLASS:2)
Block(4,19,-13,END_BRICKS)
Block(4,19,-12,END_BRICKS)
Block(4,19,-11,STAINED_GLASS:2)
Block(4,19,-10,END_BRICKS)
Block(4,19,-9,PURPUR_PILLAR:0)
Block(4,20,-18,PURPUR_STAIRS:2)
Block(4,20,-17,PURPUR_BLOCK)
Block(4,20,-16,PURPUR_BLOCK)
Block(4,20,-15,PURPUR_BLOCK)
Block(4,20,-14,PURPUR_BLOCK)
Block(4,20,-13,PURPUR_BLOCK)
Block(4,20,-12,PURPUR_BLOCK)
Block(4,20,-11,PURPUR_BLOCK)
Block(4,20,-10,PURPUR_BLOCK)
Block(4,20,-9,PURPUR_BLOCK)
Block(4,20,-8,PURPUR_BLOCK)
Block(4,20,-7,PURPUR_STAIRS:0)
Block(4,22,1,PURPUR_STAIRS:5)
Block(4,24,-2,PURPUR_STAIRS:6)
Block(4,24,-1,PURPUR_STAIRS:5)
Block(4,24,0,PURPUR_STAIRS:1)
Block(4,24,1,PURPUR_STAIRS:5)
Block(4,24,2,PURPUR_STAIRS:1)
Block(4,24,3,PURPUR_STAIRS:5)
Block(4,24,4,PURPUR_STAIRS:7)
Block(4,25,-2,END_ROD)
Block(4,25,4,END_ROD)
Block(4,28,-3,PURPUR_STAIRS:6)
Block(4,28,-2,PURPUR_BLOCK)
Block(4,28,-1,PURPUR_BLOCK)
Block(4,28,0,PURPUR_BLOCK)
Block(4,28,1,PURPUR_BLOCK)
Block(4,28,2,PURPUR_BLOCK)
Block(4,28,3,PURPUR_BLOCK)
Block(4,28,4,PURPUR_BLOCK)
Block(4,28,5,PURPUR_STAIRS:7)
Block(5,4,-5,PURPUR_STAIRS:6)
Block(5,4,-4,PURPUR_BLOCK)
Block(5,4,-3,PURPUR_BLOCK)
Block(5,4,-2,PURPUR_BLOCK)
Block(5,4,-1,PURPUR_BLOCK)
Block(5,4,0,PURPUR_BLOCK)
Block(5,4,1,PURPUR_BLOCK)
Block(5,4,2,PURPUR_BLOCK)
Block(5,4,3,PURPUR_BLOCK)
Block(5,4,4,PURPUR_BLOCK)
Block(5,4,5,PURPUR_BLOCK)
Block(5,4,6,PURPUR_STAIRS:7)
Block(5,5,-4,PURPUR_PILLAR:0)
Block(5,5,-3,END_BRICKS)
Block(5,5,-2,END_BRICKS)
Block(5,5,-1,END_BRICKS)
Block(5,5,0,END_BRICKS)
Block(5,5,1,END_BRICKS)
Block(5,5,2,END_BRICKS)
Block(5,5,3,END_BRICKS)
Block(5,5,4,END_BRICKS)
Block(5,5,5,PURPUR_PILLAR:0)
Block(5,6,-4,PURPUR_PILLAR:0)
Block(5,6,-3,END_BRICKS)
Block(5,6,-2,STAINED_GLASS:2)
Block(5,6,-1,END_BRICKS)
Block(5,6,0,END_BRICKS)
Block(5,6,1,END_BRICKS)
Block(5,6,2,END_BRICKS)
Block(5,6,3,STAINED_GLASS:2)
Block(5,6,4,END_BRICKS)
Block(5,6,5,PURPUR_PILLAR:0)
Block(5,7,-4,PURPUR_PILLAR:0)
Block(5,7,-3,END_BRICKS)
Block(5,7,-2,STAINED_GLASS:2)
Block(5,7,-1,END_BRICKS)
Block(5,7,0,END_BRICKS)
Block(5,7,1,END_BRICKS)
Block(5,7,2,END_BRICKS)
Block(5,7,3,STAINED_GLASS:2)
Block(5,7,4,END_BRICKS)
Block(5,7,5,PURPUR_PILLAR:0)
Block(5,8,-6,PURPUR_STAIRS:2)
Block(5,8,-5,PURPUR_BLOCK)
Block(5,8,-4,PURPUR_BLOCK)
Block(5,8,-3,PURPUR_BLOCK)
Block(5,8,-2,PURPUR_BLOCK)
Block(5,8,-1,PURPUR_BLOCK)
Block(5,8,0,PURPUR_BLOCK)
Block(5,8,1,PURPUR_BLOCK)
Block(5,8,2,PURPUR_BLOCK)
Block(5,8,3,PURPUR_BLOCK)
Block(5,8,4,PURPUR_BLOCK)
Block(5,8,5,PURPUR_BLOCK)
Block(5,8,6,PURPUR_BLOCK)
Block(5,8,7,PURPUR_STAIRS:0)
Block(5,15,1,PURPUR_PILLAR)
Block(5,16,-1,PURPUR_BLOCK)
Block(5,16,0,PURPUR_BLOCK)
Block(5,16,1,PURPUR_BLOCK)
Block(5,16,2,PURPUR_BLOCK)
Block(5,16,3,PURPUR_BLOCK)
Block(5,17,-1,PURPUR_STAIRS:2)
Block(5,17,3,PURPUR_STAIRS:0)
Block(5,20,-18,PURPUR_STAIRS:6)
Block(5,20,-17,PURPUR_BLOCK)
Block(5,20,-16,PURPUR_BLOCK)
Block(5,20,-15,PURPUR_BLOCK)
Block(5,20,-14,PURPUR_BLOCK)
Block(5,20,-13,PURPUR_BLOCK)
Block(5,20,-12,PURPUR_BLOCK)
Block(5,20,-11,PURPUR_BLOCK)
Block(5,20,-10,PURPUR_BLOCK)
Block(5,20,-9,PURPUR_BLOCK)
Block(5,20,-8,PURPUR_BLOCK)
Block(5,20,-7,PURPUR_STAIRS:7)
Block(5,21,-17,END_ROD)
Block(5,21,-8,END_ROD)
Block(5,24,-1,WALL_BANNER:5,EndTowerD/8-banner.nbt)
Block(5,24,3,WALL_BANNER:5,EndTowerD/9-banner.nbt)
Block(5,28,-3,PURPUR_STAIRS:6)
Block(5,28,-2,PURPUR_STAIRS:5)
Block(5,28,-1,PURPUR_STAIRS:1)
Block(5,28,0,PURPUR_STAIRS:1)
Block(5,28,1,PURPUR_STAIRS:5)
Block(5,28,2,PURPUR_STAIRS:1)
Block(5,28,3,PURPUR_STAIRS:1)
Block(5,28,4,PURPUR_STAIRS:5)
Block(5,28,5,PURPUR_STAIRS:5)
Block(6,4,-5,PURPUR_STAIRS:6)
Block(6,4,-4,PURPUR_STAIRS:5)
Block(6,4,-3,PURPUR_STAIRS:1)
Block(6,4,-2,PURPUR_STAIRS:5)
Block(6,4,-1,PURPUR_STAIRS:5)
Block(6,4,0,PURPUR_STAIRS:1)
Block(6,4,1,PURPUR_STAIRS:1)
Block(6,4,2,PURPUR_STAIRS:5)
Block(6,4,3,PURPUR_STAIRS:5)
Block(6,4,4,PURPUR_STAIRS:1)
Block(6,4,5,PURPUR_STAIRS:5)
Block(6,4,6,PURPUR_STAIRS:5)
Block(6,5,-5,END_ROD)
Block(6,5,6,END_ROD)
Block(6,8,-6,PURPUR_STAIRS:6)
Block(6,8,-5,PURPUR_BLOCK)
Block(6,8,-4,PURPUR_BLOCK)
Block(6,8,-3,PURPUR_BLOCK)
Block(6,8,-2,PURPUR_BLOCK)
Block(6,8,-1,PURPUR_BLOCK)
Block(6,8,0,PURPUR_BLOCK)
Block(6,8,1,PURPUR_BLOCK)
Block(6,8,2,PURPUR_BLOCK)
Block(6,8,3,PURPUR_BLOCK)
Block(6,8,4,PURPUR_BLOCK)
Block(6,8,5,PURPUR_BLOCK)
Block(6,8,6,PURPUR_BLOCK)
Block(6,8,7,PURPUR_STAIRS:7)
Block(6,9,-5,END_ROD)
Block(6,9,6,END_ROD)
Block(6,15,1,PURPUR_PILLAR)
Block(6,16,-1,PURPUR_BLOCK)
Block(6,16,0,PURPUR_BLOCK)
Block(6,16,1,PURPUR_BLOCK)
Block(6,16,2,PURPUR_BLOCK)
Block(6,16,3,PURPUR_BLOCK)
Block(6,17,-1,PURPUR_STAIRS:2)
Block(6,17,3,PURPUR_STAIRS:0)
Block(6,20,-18,PURPUR_STAIRS:6)
Block(6,20,-17,PURPUR_STAIRS:5)
Block(6,20,-16,PURPUR_STAIRS:1)
Block(6,20,-15,PURPUR_STAIRS:1)
Block(6,20,-14,PURPUR_STAIRS:5)
Block(6,20,-13,PURPUR_STAIRS:1)
Block(6,20,-12,PURPUR_STAIRS:1)
Block(6,20,-11,PURPUR_STAIRS:5)
Block(6,20,-10,PURPUR_STAIRS:1)
Block(6,20,-9,PURPUR_STAIRS:1)
Block(6,20,-8,PURPUR_STAIRS:5)
Block(6,20,-7,PURPUR_STAIRS:5)
Block(7,8,-6,PURPUR_STAIRS:6)
Block(7,8,-5,PURPUR_STAIRS:5)
Block(7,8,-4,PURPUR_STAIRS:1)
Block(7,8,-3,PURPUR_STAIRS:1)
Block(7,8,-2,PURPUR_STAIRS:5)
Block(7,8,-1,PURPUR_STAIRS:5)
Block(7,8,0,PURPUR_STAIRS:1)
Block(7,8,1,PURPUR_STAIRS:1)
Block(7,8,2,PURPUR_STAIRS:5)
Block(7,8,3,PURPUR_STAIRS:5)
Block(7,8,4,PURPUR_STAIRS:1)
Block(7,8,5,PURPUR_STAIRS:1)
Block(7,8,6,PURPUR_STAIRS:5)
Block(7,8,7,PURPUR_STAIRS:5)
Block(7,15,0,PURPUR_STAIRS:6)
Block(7,15,1,PURPUR_PILLAR)
Block(7,15,2,PURPUR_STAIRS:7)
Block(7,16,-1,PURPUR_STAIRS:6)
Block(7,16,0,PURPUR_BLOCK)
Block(7,16,1,PURPUR_BLOCK)
Block(7,16,2,PURPUR_BLOCK)
Block(7,16,3,PURPUR_STAIRS:7)
Block(7,17,-1,PURPUR_BLOCK)
Block(7,17,3,PURPUR_BLOCK)
Block(8,15,1,PURPUR_PILLAR)
Block(8,16,0,PURPUR_BLOCK)
Block(8,16,1,PURPUR_BLOCK)
Block(8,16,2,PURPUR_BLOCK)
Block(8,17,-1,PURPUR_BLOCK)
Block(8,17,0,PURPUR_STAIRS:0)
Block(8,17,1,PURPUR_STAIRS:0)
Block(8,17,2,PURPUR_STAIRS:0)
Block(8,17,3,PURPUR_BLOCK)
Block(8,18,-1,PURPUR_STAIRS:2)
Block(8,18,3,PURPUR_STAIRS:0)
Block(9,17,0,PURPUR_STAIRS:6)
Block(9,17,1,PURPUR_BLOCK)
Block(9,17,2,PURPUR_STAIRS:7)
Block(9,18,-1,PURPUR_BLOCK)
Block(9,18,0,PURPUR_STAIRS:0)
Block(9,18,1,PURPUR_STAIRS:0)
Block(9,18,2,PURPUR_STAIRS:0)
Block(9,18,3,PURPUR_BLOCK)
Block(9,19,-1,PURPUR_STAIRS:2)
Block(9,19,3,PURPUR_STAIRS:0)
Block(10,18,0,PURPUR_STAIRS:6)
Block(10,18,1,PURPUR_BLOCK)
Block(10,18,2,PURPUR_STAIRS:7)
Block(10,19,-1,PURPUR_BLOCK)
Block(10,19,0,PURPUR_STAIRS:0)
Block(10,19,1,PURPUR_STAIRS:0)
Block(10,19,2,PURPUR_STAIRS:0)
Block(10,19,3,PURPUR_BLOCK)
Block(10,20,-1,PURPUR_STAIRS:2)
Block(10,20,3,PURPUR_STAIRS:0)
Block(11,19,0,PURPUR_STAIRS:6)
Block(11,19,1,PURPUR_PILLAR)
Block(11,19,2,PURPUR_STAIRS:7)
Block(11,20,-1,PURPUR_BLOCK)
Block(11,20,0,PURPUR_STAIRS:0)
Block(11,20,1,PURPUR_STAIRS:0)
Block(11,20,2,PURPUR_STAIRS:0)
Block(11,20,3,PURPUR_BLOCK)
Block(11,21,-1,PURPUR_BLOCK)
Block(11,21,3,PURPUR_BLOCK)
Block(12,19,1,PURPUR_PILLAR)
Block(12,20,-1,PURPUR_BLOCK)
Block(12,20,0,PURPUR_BLOCK)
Block(12,20,1,PURPUR_BLOCK)
Block(12,20,2,PURPUR_BLOCK)
Block(12,20,3,PURPUR_BLOCK)
Block(12,21,-1,PURPUR_STAIRS:2)
Block(12,21,3,PURPUR_STAIRS:0)
Block(13,19,1,PURPUR_PILLAR)
Block(13,20,-1,PURPUR_BLOCK)
Block(13,20,0,PURPUR_BLOCK)
Block(13,20,1,PURPUR_BLOCK)
Block(13,20,2,PURPUR_BLOCK)
Block(13,20,3,PURPUR_BLOCK)
Block(13,21,-1,PURPUR_STAIRS:2)
Block(13,21,3,PURPUR_STAIRS:0)
Block(14,19,1,PURPUR_PILLAR)
Block(14,20,-1,PURPUR_BLOCK)
Block(14,20,0,PURPUR_STAIRS:0)
Block(14,20,1,PURPUR_STAIRS:0)
Block(14,20,2,PURPUR_STAIRS:0)
Block(14,20,3,PURPUR_BLOCK)
Block(14,21,-1,PURPUR_BLOCK)
Block(14,21,3,PURPUR_BLOCK)
Block(14,22,-1,END_ROD)
Block(14,22,3,END_ROD)
Block(15,19,0,PURPUR_BLOCK)
Block(15,19,1,PURPUR_BLOCK)
Block(15,19,2,PURPUR_BLOCK)
Block(15,20,-1,PURPUR_BLOCK)
Block(15,20,0,PURPUR_BLOCK)
Block(15,20,1,PURPUR_BLOCK)
Block(15,20,2,PURPUR_BLOCK)
Block(15,20,3,PURPUR_BLOCK)
Block(15,21,-1,PURPUR_BLOCK)
Block(15,21,3,PURPUR_BLOCK)
Block(15,22,-1,PURPUR_BLOCK)
Block(15,22,3,PURPUR_BLOCK)
Block(15,23,-1,PURPUR_BLOCK)
Block(15,23,0,PURPUR_SLAB:8)
Block(15,23,2,PURPUR_SLAB:8)
Block(15,23,3,PURPUR_BLOCK)
Block(15,24,-1,PURPUR_SLAB)
Block(15,24,0,PURPUR_BLOCK)
Block(15,24,1,PURPUR_BLOCK)
Block(15,24,2,PURPUR_BLOCK)
Block(15,24,3,PURPUR_SLAB)

#######################################################################
# +-----------------------------------------------------------------+ #
# |                            BO3 checks                           | #
# +-----------------------------------------------------------------+ #
#######################################################################


#######################################################################
# +-----------------------------------------------------------------+ #
# |                             Branches                            | #
# +-----------------------------------------------------------------+ #
#######################################################################


#######################################################################
# +-----------------------------------------------------------------+ #
# |                             Entities                            | #
# +-----------------------------------------------------------------+ #
#######################################################################

Entity(-11,19,2,SHULKER,1)
Entity(-4,2,-1,SHULKER,1)
Entity(-4,2,2,SHULKER,1)
Entity(0,5,4,SHULKER,1)
Entity(0,10,1,SHULKER,1)
Entity(1,19,-13,SHULKER,1)
Entity(1,27,1,SHULKER,1)
Entity(2,18,-8,SHULKER,1)
Entity(4,5,-3,SHULKER,1)

#######################################################################
# +-----------------------------------------------------------------+ #
# |                            Particles                            | #
# +-----------------------------------------------------------------+ #
#######################################################################


#######################################################################
# +-----------------------------------------------------------------+ #
# |                             Spawners                            | #
# +-----------------------------------------------------------------+ #
#######################################################################


#######################################################################
# +-----------------------------------------------------------------+ #
# |                             ModData                             | #
# +-----------------------------------------------------------------+ #
#######################################################################

