
#######################################################################
# +-----------------------------------------------------------------+ #
# |                            BO3 object                           | #
# +-----------------------------------------------------------------+ #
#######################################################################

Author: totemo

Description: No description given

Version: 3

SettingsMode: WriteWithoutComments


#######################################################################
# +-----------------------------------------------------------------+ #
# |                          Main settings                          | #
# +-----------------------------------------------------------------+ #
#######################################################################

Tree: false

Frequency: 0

Rarity: 100.0

RotateRandomly: true

SpawnHeight: highestBlock

SpawnHeightOffset: 0

SpawnHeightVariance: 0

##############################
# Height Limits for the BO3. #
##############################

MinHeight: 0

MaxHeight: 256

######################
# Extrusion settings #
######################

ExtrudeMode: None

ExtrudeThroughBlocks: AIR

MaxBranchDepth: 10

ExcludedBiomes: All


#######################################################################
# +-----------------------------------------------------------------+ #
# |                      Source block settings                      | #
# +-----------------------------------------------------------------+ #
#######################################################################

SourceBlocks: AIR

MaxPercentageOutsideSourceBlock: 10

OutsideSourceBlock: placeAnyway

IsOTGPlus: false


#######################################################################
# +-----------------------------------------------------------------+ #
# |                              Blocks                             | #
# +-----------------------------------------------------------------+ #
#######################################################################

Block(-7,8,-6,PURPUR_STAIRS:4)
Block(-7,8,-5,PURPUR_STAIRS:4)
Block(-7,8,-4,PURPUR_STAIRS:0)
Block(-7,8,-3,PURPUR_STAIRS:0)
Block(-7,8,-2,PURPUR_STAIRS:4)
Block(-7,8,-1,PURPUR_STAIRS:4)
Block(-7,8,0,PURPUR_STAIRS:0)
Block(-7,8,1,PURPUR_STAIRS:0)
Block(-7,8,2,PURPUR_STAIRS:4)
Block(-7,8,3,PURPUR_STAIRS:4)
Block(-7,8,4,PURPUR_STAIRS:0)
Block(-7,8,5,PURPUR_STAIRS:0)
Block(-7,8,6,PURPUR_STAIRS:4)
Block(-7,8,7,PURPUR_STAIRS:7)
Block(-6,4,-5,PURPUR_STAIRS:4)
Block(-6,4,-4,PURPUR_STAIRS:4)
Block(-6,4,-3,PURPUR_STAIRS:0)
Block(-6,4,-2,PURPUR_STAIRS:4)
Block(-6,4,-1,PURPUR_STAIRS:4)
Block(-6,4,0,PURPUR_STAIRS:0)
Block(-6,4,1,PURPUR_STAIRS:0)
Block(-6,4,2,PURPUR_STAIRS:4)
Block(-6,4,3,PURPUR_STAIRS:4)
Block(-6,4,4,PURPUR_STAIRS:0)
Block(-6,4,5,PURPUR_STAIRS:4)
Block(-6,4,6,PURPUR_STAIRS:7)
Block(-6,5,-5,END_ROD)
Block(-6,5,6,END_ROD)
Block(-6,8,-6,PURPUR_STAIRS:6)
Block(-6,8,-5,PURPUR_BLOCK)
Block(-6,8,-4,PURPUR_BLOCK)
Block(-6,8,-3,PURPUR_BLOCK)
Block(-6,8,-2,PURPUR_BLOCK)
Block(-6,8,-1,PURPUR_BLOCK)
Block(-6,8,0,PURPUR_BLOCK)
Block(-6,8,1,PURPUR_BLOCK)
Block(-6,8,2,PURPUR_BLOCK)
Block(-6,8,3,PURPUR_BLOCK)
Block(-6,8,4,PURPUR_BLOCK)
Block(-6,8,5,PURPUR_BLOCK)
Block(-6,8,6,PURPUR_BLOCK)
Block(-6,8,7,PURPUR_STAIRS:7)
Block(-6,9,-5,END_ROD)
Block(-6,9,6,END_ROD)
Block(-5,4,-5,PURPUR_STAIRS:6)
Block(-5,4,-4,PURPUR_BLOCK)
Block(-5,4,-3,PURPUR_BLOCK)
Block(-5,4,-2,PURPUR_BLOCK)
Block(-5,4,-1,PURPUR_BLOCK)
Block(-5,4,0,PURPUR_BLOCK)
Block(-5,4,1,PURPUR_BLOCK)
Block(-5,4,2,PURPUR_BLOCK)
Block(-5,4,3,PURPUR_BLOCK)
Block(-5,4,4,PURPUR_BLOCK)
Block(-5,4,5,PURPUR_BLOCK)
Block(-5,4,6,PURPUR_STAIRS:7)
Block(-5,5,-4,PURPUR_PILLAR:0)
Block(-5,5,-3,END_BRICKS)
Block(-5,5,-2,END_BRICKS)
Block(-5,5,-1,END_BRICKS)
Block(-5,5,0,END_BRICKS)
Block(-5,5,1,END_BRICKS)
Block(-5,5,2,END_BRICKS)
Block(-5,5,3,END_BRICKS)
Block(-5,5,4,END_BRICKS)
Block(-5,5,5,PURPUR_PILLAR:0)
Block(-5,6,-4,PURPUR_PILLAR:0)
Block(-5,6,-3,END_BRICKS)
Block(-5,6,-2,STAINED_GLASS:2)
Block(-5,6,-1,END_BRICKS)
Block(-5,6,0,END_BRICKS)
Block(-5,6,1,END_BRICKS)
Block(-5,6,2,END_BRICKS)
Block(-5,6,3,STAINED_GLASS:2)
Block(-5,6,4,END_BRICKS)
Block(-5,6,5,PURPUR_PILLAR:0)
Block(-5,7,-4,PURPUR_PILLAR:0)
Block(-5,7,-3,END_BRICKS)
Block(-5,7,-2,STAINED_GLASS:2)
Block(-5,7,-1,END_BRICKS)
Block(-5,7,0,END_BRICKS)
Block(-5,7,1,END_BRICKS)
Block(-5,7,2,END_BRICKS)
Block(-5,7,3,STAINED_GLASS:2)
Block(-5,7,4,END_BRICKS)
Block(-5,7,5,PURPUR_PILLAR:0)
Block(-5,8,-6,PURPUR_STAIRS:2)
Block(-5,8,-5,PURPUR_BLOCK)
Block(-5,8,-4,PURPUR_BLOCK)
Block(-5,8,-3,PURPUR_BLOCK)
Block(-5,8,-2,PURPUR_BLOCK)
Block(-5,8,-1,PURPUR_BLOCK)
Block(-5,8,0,PURPUR_BLOCK)
Block(-5,8,1,PURPUR_BLOCK)
Block(-5,8,2,PURPUR_BLOCK)
Block(-5,8,3,PURPUR_BLOCK)
Block(-5,8,4,PURPUR_BLOCK)
Block(-5,8,5,PURPUR_BLOCK)
Block(-5,8,6,PURPUR_BLOCK)
Block(-5,8,7,PURPUR_STAIRS:0)
Block(-4,0,-3,PURPUR_BLOCK)
Block(-4,0,-2,PURPUR_BLOCK)
Block(-4,0,-1,PURPUR_BLOCK)
Block(-4,0,0,PURPUR_BLOCK)
Block(-4,0,1,PURPUR_BLOCK)
Block(-4,0,2,PURPUR_BLOCK)
Block(-4,0,3,PURPUR_BLOCK)
Block(-4,0,4,PURPUR_BLOCK)
Block(-4,1,-3,PURPUR_PILLAR:0)
Block(-4,1,-2,END_BRICKS)
Block(-4,1,-1,END_BRICKS)
Block(-4,1,0,END_BRICKS)
Block(-4,1,1,END_BRICKS)
Block(-4,1,2,END_BRICKS)
Block(-4,1,3,END_BRICKS)
Block(-4,1,4,PURPUR_PILLAR:0)
Block(-4,2,-3,PURPUR_PILLAR:0)
Block(-4,2,-2,END_BRICKS)
Block(-4,2,-1,STAINED_GLASS:2)
Block(-4,2,0,END_BRICKS)
Block(-4,2,1,END_BRICKS)
Block(-4,2,2,STAINED_GLASS:2)
Block(-4,2,3,END_BRICKS)
Block(-4,2,4,PURPUR_PILLAR:0)
Block(-4,3,-3,PURPUR_PILLAR:0)
Block(-4,3,-2,END_BRICKS)
Block(-4,3,-1,STAINED_GLASS:2)
Block(-4,3,0,END_BRICKS)
Block(-4,3,1,END_BRICKS)
Block(-4,3,2,STAINED_GLASS:2)
Block(-4,3,3,END_BRICKS)
Block(-4,3,4,PURPUR_PILLAR:0)
Block(-4,4,-5,PURPUR_STAIRS:2)
Block(-4,4,-4,PURPUR_BLOCK)
Block(-4,4,-3,PURPUR_BLOCK)
Block(-4,4,-2,PURPUR_BLOCK)
Block(-4,4,-1,PURPUR_BLOCK)
Block(-4,4,0,PURPUR_BLOCK)
Block(-4,4,1,PURPUR_BLOCK)
Block(-4,4,2,PURPUR_BLOCK)
Block(-4,4,3,PURPUR_BLOCK)
Block(-4,4,4,PURPUR_BLOCK)
Block(-4,4,5,PURPUR_BLOCK)
Block(-4,4,6,PURPUR_STAIRS:0)
Block(-4,5,-4,END_BRICKS)
Block(-4,5,5,END_BRICKS)
Block(-4,6,-4,END_BRICKS)
Block(-4,6,5,END_BRICKS)
Block(-4,7,-4,END_BRICKS)
Block(-4,7,5,END_BRICKS)
Block(-4,8,-6,PURPUR_STAIRS:2)
Block(-4,8,-5,PURPUR_BLOCK)
Block(-4,8,-4,PURPUR_BLOCK)
Block(-4,8,-3,PURPUR_BLOCK)
Block(-4,8,-2,PURPUR_BLOCK)
Block(-4,8,-1,PURPUR_BLOCK)
Block(-4,8,0,PURPUR_BLOCK)
Block(-4,8,1,PURPUR_BLOCK)
Block(-4,8,2,PURPUR_BLOCK)
Block(-4,8,3,PURPUR_BLOCK)
Block(-4,8,4,PURPUR_BLOCK)
Block(-4,8,5,PURPUR_BLOCK)
Block(-4,8,6,PURPUR_BLOCK)
Block(-4,8,7,PURPUR_STAIRS:0)
Block(-3,0,-3,PURPUR_BLOCK)
Block(-3,0,-2,PURPUR_BLOCK)
Block(-3,0,-1,PURPUR_BLOCK)
Block(-3,0,0,PURPUR_BLOCK)
Block(-3,0,1,PURPUR_BLOCK)
Block(-3,0,2,PURPUR_BLOCK)
Block(-3,0,3,PURPUR_BLOCK)
Block(-3,0,4,PURPUR_BLOCK)
Block(-3,0,5,PURPUR_STAIRS:0)
Block(-3,1,-3,END_BRICKS)
Block(-3,1,4,END_BRICKS)
Block(-3,2,-3,END_BRICKS)
Block(-3,2,4,END_BRICKS)
Block(-3,3,-3,END_BRICKS)
Block(-3,3,4,END_BRICKS)
Block(-3,4,-5,PURPUR_STAIRS:6)
Block(-3,4,-4,PURPUR_BLOCK)
Block(-3,4,-3,PURPUR_BLOCK)
Block(-3,4,4,PURPUR_BLOCK)
Block(-3,4,5,PURPUR_BLOCK)
Block(-3,4,6,PURPUR_STAIRS:7)
Block(-3,5,-4,END_BRICKS)
Block(-3,5,5,END_BRICKS)
Block(-3,6,-4,STAINED_GLASS:2)
Block(-3,6,5,STAINED_GLASS:2)
Block(-3,7,-4,STAINED_GLASS:2)
Block(-3,7,5,STAINED_GLASS:2)
Block(-3,8,-6,PURPUR_STAIRS:6)
Block(-3,8,-5,PURPUR_BLOCK)
Block(-3,8,-4,PURPUR_BLOCK)
Block(-3,8,-3,PURPUR_BLOCK)
Block(-3,8,-2,PURPUR_BLOCK)
Block(-3,8,-1,PURPUR_BLOCK)
Block(-3,8,0,PURPUR_BLOCK)
Block(-3,8,1,PURPUR_BLOCK)
Block(-3,8,2,PURPUR_BLOCK)
Block(-3,8,3,PURPUR_BLOCK)
Block(-3,8,4,PURPUR_BLOCK)
Block(-3,8,5,PURPUR_BLOCK)
Block(-3,8,6,PURPUR_BLOCK)
Block(-3,8,7,PURPUR_STAIRS:7)
Block(-2,0,-3,PURPUR_BLOCK)
Block(-2,0,-2,PURPUR_BLOCK)
Block(-2,0,-1,PURPUR_BLOCK)
Block(-2,0,0,PURPUR_BLOCK)
Block(-2,0,1,PURPUR_BLOCK)
Block(-2,0,2,PURPUR_BLOCK)
Block(-2,0,3,PURPUR_BLOCK)
Block(-2,0,4,PURPUR_BLOCK)
Block(-2,0,5,PURPUR_BLOCK)
Block(-2,1,-3,END_BRICKS)
Block(-2,1,4,END_BRICKS)
Block(-2,2,-3,STAINED_GLASS:2)
Block(-2,2,4,END_BRICKS)
Block(-2,3,-3,STAINED_GLASS:2)
Block(-2,3,1,PURPUR_SLAB:8)
Block(-2,3,4,END_BRICKS)
Block(-2,4,-5,PURPUR_STAIRS:6)
Block(-2,4,-4,PURPUR_BLOCK)
Block(-2,4,-3,PURPUR_BLOCK)
Block(-2,4,4,PURPUR_BLOCK)
Block(-2,4,5,PURPUR_BLOCK)
Block(-2,5,-4,END_BRICKS)
Block(-2,5,5,END_BRICKS)
Block(-2,6,-4,END_BRICKS)
Block(-2,6,5,END_BRICKS)
Block(-2,7,-4,END_BRICKS)
Block(-2,7,5,END_BRICKS)
Block(-2,8,-6,PURPUR_STAIRS:6)
Block(-2,8,-5,PURPUR_BLOCK)
Block(-2,8,-4,PURPUR_BLOCK)
Block(-2,8,-3,PURPUR_BLOCK)
Block(-2,8,-2,PURPUR_BLOCK)
Block(-2,8,-1,PURPUR_BLOCK)
Block(-2,8,0,PURPUR_BLOCK)
Block(-2,8,1,PURPUR_BLOCK)
Block(-2,8,2,PURPUR_BLOCK)
Block(-2,8,3,PURPUR_BLOCK)
Block(-2,8,4,PURPUR_BLOCK)
Block(-2,8,5,PURPUR_BLOCK)
Block(-2,8,6,PURPUR_BLOCK)
Block(-2,8,7,PURPUR_STAIRS:7)
Block(-1,0,-3,PURPUR_BLOCK)
Block(-1,0,-2,PURPUR_BLOCK)
Block(-1,0,-1,PURPUR_BLOCK)
Block(-1,0,0,PURPUR_BLOCK)
Block(-1,0,1,PURPUR_BLOCK)
Block(-1,0,2,PURPUR_BLOCK)
Block(-1,0,3,PURPUR_BLOCK)
Block(-1,0,4,PURPUR_BLOCK)
Block(-1,0,5,PURPUR_BLOCK)
Block(-1,1,-3,END_BRICKS)
Block(-1,1,0,PURPUR_BLOCK)
Block(-1,1,1,PURPUR_BLOCK)
Block(-1,2,-3,END_BRICKS)
Block(-1,2,0,PURPUR_BLOCK)
Block(-1,2,1,PURPUR_BLOCK)
Block(-1,3,-3,END_BRICKS)
Block(-1,3,-1,PURPUR_SLAB)
Block(-1,3,0,PURPUR_STAIRS:2)
Block(-1,3,1,PURPUR_BLOCK)
Block(-1,4,-5,PURPUR_STAIRS:2)
Block(-1,4,-4,PURPUR_BLOCK)
Block(-1,4,-3,PURPUR_BLOCK)
Block(-1,4,1,PURPUR_STAIRS:0)
Block(-1,4,4,PURPUR_BLOCK)
Block(-1,4,5,PURPUR_BLOCK)
Block(-1,5,-4,END_BRICKS)
Block(-1,5,5,END_BRICKS)
Block(-1,6,-4,END_BRICKS)
Block(-1,6,5,END_BRICKS)
Block(-1,7,-4,END_BRICKS)
Block(-1,7,5,END_BRICKS)
Block(-1,8,-6,PURPUR_STAIRS:2)
Block(-1,8,-5,PURPUR_BLOCK)
Block(-1,8,-4,PURPUR_BLOCK)
Block(-1,8,-3,PURPUR_BLOCK)
Block(-1,8,-2,PURPUR_BLOCK)
Block(-1,8,-1,PURPUR_BLOCK)
Block(-1,8,0,PURPUR_BLOCK)
Block(-1,8,1,PURPUR_BLOCK)
Block(-1,8,2,PURPUR_BLOCK)
Block(-1,8,3,PURPUR_BLOCK)
Block(-1,8,4,PURPUR_BLOCK)
Block(-1,8,5,PURPUR_BLOCK)
Block(-1,8,6,PURPUR_BLOCK)
Block(-1,8,7,PURPUR_STAIRS:0)
Block(0,0,-3,PURPUR_BLOCK)
Block(0,0,-2,PURPUR_BLOCK)
Block(0,0,-1,PURPUR_BLOCK)
Block(0,0,0,PURPUR_BLOCK)
Block(0,0,1,PURPUR_BLOCK)
Block(0,0,2,PURPUR_BLOCK)
Block(0,0,3,PURPUR_BLOCK)
Block(0,0,4,PURPUR_BLOCK)
Block(0,0,5,PURPUR_BLOCK)
Block(0,1,-3,END_BRICKS)
Block(0,1,0,PURPUR_BLOCK)
Block(0,1,1,PURPUR_STAIRS:0)
Block(0,1,2,PURPUR_SLAB)
Block(0,2,-3,END_BRICKS)
Block(0,2,0,PURPUR_STAIRS:1)
Block(0,3,-3,END_BRICKS)
Block(0,4,-5,PURPUR_STAIRS:2)
Block(0,4,-4,PURPUR_BLOCK)
Block(0,4,-3,PURPUR_BLOCK)
Block(0,4,1,PURPUR_SLAB:8)
Block(0,4,4,PURPUR_BLOCK)
Block(0,4,5,PURPUR_BLOCK)
Block(0,5,-4,END_BRICKS)
Block(0,5,5,END_BRICKS)
Block(0,6,-4,END_BRICKS)
Block(0,6,5,END_BRICKS)
Block(0,7,-4,END_BRICKS)
Block(0,7,5,END_BRICKS)
Block(0,8,-6,PURPUR_STAIRS:2)
Block(0,8,-5,PURPUR_BLOCK)
Block(0,8,-4,PURPUR_BLOCK)
Block(0,8,-3,PURPUR_BLOCK)
Block(0,8,-2,PURPUR_BLOCK)
Block(0,8,-1,PURPUR_BLOCK)
Block(0,8,0,PURPUR_BLOCK)
Block(0,8,1,PURPUR_BLOCK)
Block(0,8,2,PURPUR_BLOCK)
Block(0,8,3,PURPUR_BLOCK)
Block(0,8,4,PURPUR_BLOCK)
Block(0,8,5,PURPUR_BLOCK)
Block(0,8,6,PURPUR_BLOCK)
Block(0,8,7,PURPUR_STAIRS:0)
Block(1,0,-3,PURPUR_BLOCK)
Block(1,0,-2,PURPUR_BLOCK)
Block(1,0,-1,PURPUR_BLOCK)
Block(1,0,0,PURPUR_BLOCK)
Block(1,0,1,PURPUR_BLOCK)
Block(1,0,2,PURPUR_BLOCK)
Block(1,0,3,PURPUR_BLOCK)
Block(1,0,4,PURPUR_BLOCK)
Block(1,0,5,PURPUR_BLOCK)
Block(1,1,-3,END_BRICKS)
Block(1,1,4,END_BRICKS)
Block(1,2,-3,STAINED_GLASS:2)
Block(1,2,0,PURPUR_SLAB)
Block(1,2,4,END_BRICKS)
Block(1,3,-3,STAINED_GLASS:2)
Block(1,3,4,END_BRICKS)
Block(1,4,-5,PURPUR_STAIRS:6)
Block(1,4,-4,PURPUR_BLOCK)
Block(1,4,-3,PURPUR_BLOCK)
Block(1,4,1,PURPUR_SLAB:8)
Block(1,4,4,PURPUR_BLOCK)
Block(1,4,5,PURPUR_BLOCK)
Block(1,5,-4,END_BRICKS)
Block(1,5,5,END_BRICKS)
Block(1,6,-4,END_BRICKS)
Block(1,6,5,END_BRICKS)
Block(1,7,-4,END_BRICKS)
Block(1,7,5,END_BRICKS)
Block(1,8,-6,PURPUR_STAIRS:6)
Block(1,8,-5,PURPUR_BLOCK)
Block(1,8,-4,PURPUR_BLOCK)
Block(1,8,-3,PURPUR_BLOCK)
Block(1,8,-2,PURPUR_BLOCK)
Block(1,8,-1,PURPUR_BLOCK)
Block(1,8,0,PURPUR_BLOCK)
Block(1,8,1,PURPUR_BLOCK)
Block(1,8,2,PURPUR_BLOCK)
Block(1,8,3,PURPUR_BLOCK)
Block(1,8,4,PURPUR_BLOCK)
Block(1,8,5,PURPUR_BLOCK)
Block(1,8,6,PURPUR_BLOCK)
Block(1,8,7,PURPUR_STAIRS:7)
Block(2,0,-3,PURPUR_BLOCK)
Block(2,0,-2,PURPUR_BLOCK)
Block(2,0,-1,PURPUR_BLOCK)
Block(2,0,0,PURPUR_BLOCK)
Block(2,0,1,PURPUR_BLOCK)
Block(2,0,2,PURPUR_BLOCK)
Block(2,0,3,PURPUR_BLOCK)
Block(2,0,4,PURPUR_BLOCK)
Block(2,0,5,PURPUR_STAIRS:0)
Block(2,1,-3,END_BRICKS)
Block(2,1,4,END_BRICKS)
Block(2,2,-3,END_BRICKS)
Block(2,2,4,END_BRICKS)
Block(2,3,-3,END_BRICKS)
Block(2,3,4,END_BRICKS)
Block(2,4,-5,PURPUR_STAIRS:6)
Block(2,4,-4,PURPUR_BLOCK)
Block(2,4,-3,PURPUR_BLOCK)
Block(2,4,1,PURPUR_SLAB:8)
Block(2,4,4,PURPUR_BLOCK)
Block(2,4,5,PURPUR_BLOCK)
Block(2,5,-4,END_BRICKS)
Block(2,5,5,END_BRICKS)
Block(2,6,-4,STAINED_GLASS:2)
Block(2,6,5,STAINED_GLASS:2)
Block(2,7,-4,STAINED_GLASS:2)
Block(2,7,2,PURPUR_SLAB:8)
Block(2,7,3,PURPUR_SLAB:8)
Block(2,7,5,STAINED_GLASS:2)
Block(2,8,-6,PURPUR_STAIRS:6)
Block(2,8,-5,PURPUR_BLOCK)
Block(2,8,-4,PURPUR_BLOCK)
Block(2,8,-3,PURPUR_BLOCK)
Block(2,8,-2,PURPUR_BLOCK)
Block(2,8,-1,PURPUR_BLOCK)
Block(2,8,0,PURPUR_BLOCK)
Block(2,8,1,PURPUR_BLOCK)
Block(2,8,2,PURPUR_BLOCK)
Block(2,8,3,PURPUR_BLOCK)
Block(2,8,4,PURPUR_BLOCK)
Block(2,8,5,PURPUR_BLOCK)
Block(2,8,6,PURPUR_BLOCK)
Block(2,8,7,PURPUR_STAIRS:7)
Block(3,0,-3,PURPUR_BLOCK)
Block(3,0,-2,PURPUR_BLOCK)
Block(3,0,-1,PURPUR_BLOCK)
Block(3,0,0,PURPUR_BLOCK)
Block(3,0,1,PURPUR_BLOCK)
Block(3,0,2,PURPUR_BLOCK)
Block(3,0,3,PURPUR_BLOCK)
Block(3,0,4,PURPUR_BLOCK)
Block(3,1,-3,PURPUR_PILLAR:0)
Block(3,1,-2,END_BRICKS)
Block(3,1,-1,END_BRICKS)
Block(3,1,0,END_BRICKS)
Block(3,1,1,END_BRICKS)
Block(3,1,2,END_BRICKS)
Block(3,1,3,END_BRICKS)
Block(3,1,4,PURPUR_PILLAR:0)
Block(3,2,-3,PURPUR_PILLAR:0)
Block(3,2,-2,END_BRICKS)
Block(3,2,-1,STAINED_GLASS:2)
Block(3,2,0,END_BRICKS)
Block(3,2,1,END_BRICKS)
Block(3,2,2,STAINED_GLASS:2)
Block(3,2,3,END_BRICKS)
Block(3,2,4,PURPUR_PILLAR:0)
Block(3,3,-3,PURPUR_PILLAR:0)
Block(3,3,-2,END_BRICKS)
Block(3,3,-1,STAINED_GLASS:2)
Block(3,3,0,END_BRICKS)
Block(3,3,1,END_BRICKS)
Block(3,3,2,STAINED_GLASS:2)
Block(3,3,3,END_BRICKS)
Block(3,3,4,PURPUR_PILLAR:0)
Block(3,4,-5,PURPUR_STAIRS:2)
Block(3,4,-4,PURPUR_BLOCK)
Block(3,4,-3,PURPUR_BLOCK)
Block(3,4,-2,PURPUR_BLOCK)
Block(3,4,-1,PURPUR_BLOCK)
Block(3,4,0,PURPUR_BLOCK)
Block(3,4,1,PURPUR_BLOCK)
Block(3,4,2,PURPUR_BLOCK)
Block(3,4,3,PURPUR_BLOCK)
Block(3,4,4,PURPUR_BLOCK)
Block(3,4,5,PURPUR_BLOCK)
Block(3,4,6,PURPUR_STAIRS:0)
Block(3,5,-4,END_BRICKS)
Block(3,5,1,ENDER_CHEST:4,EndTowerG/1-ender_chest.nbt)
Block(3,5,2,PURPUR_STAIRS:4)
Block(3,5,3,PURPUR_STAIRS:4)
Block(3,5,5,END_BRICKS)
Block(3,6,-4,END_BRICKS)
Block(3,6,2,PURPUR_STAIRS:0)
Block(3,6,3,PURPUR_STAIRS:0)
Block(3,6,5,END_BRICKS)
Block(3,7,-4,END_BRICKS)
Block(3,7,2,PURPUR_STAIRS:4)
Block(3,7,3,PURPUR_STAIRS:4)
Block(3,7,5,END_BRICKS)
Block(3,8,-6,PURPUR_STAIRS:2)
Block(3,8,-5,PURPUR_BLOCK)
Block(3,8,-4,PURPUR_BLOCK)
Block(3,8,-3,PURPUR_BLOCK)
Block(3,8,-2,PURPUR_BLOCK)
Block(3,8,-1,PURPUR_BLOCK)
Block(3,8,0,PURPUR_BLOCK)
Block(3,8,1,PURPUR_BLOCK)
Block(3,8,2,PURPUR_BLOCK)
Block(3,8,3,PURPUR_BLOCK)
Block(3,8,4,PURPUR_BLOCK)
Block(3,8,5,PURPUR_BLOCK)
Block(3,8,6,PURPUR_BLOCK)
Block(3,8,7,PURPUR_STAIRS:0)
Block(4,4,-5,PURPUR_STAIRS:6)
Block(4,4,-4,PURPUR_BLOCK)
Block(4,4,-3,PURPUR_BLOCK)
Block(4,4,-2,PURPUR_BLOCK)
Block(4,4,-1,PURPUR_BLOCK)
Block(4,4,0,PURPUR_BLOCK)
Block(4,4,1,PURPUR_BLOCK)
Block(4,4,2,PURPUR_BLOCK)
Block(4,4,3,PURPUR_BLOCK)
Block(4,4,4,PURPUR_BLOCK)
Block(4,4,5,PURPUR_BLOCK)
Block(4,4,6,PURPUR_STAIRS:7)
Block(4,5,-4,PURPUR_PILLAR:0)
Block(4,5,-3,END_BRICKS)
Block(4,5,-2,END_BRICKS)
Block(4,5,-1,END_BRICKS)
Block(4,5,0,END_BRICKS)
Block(4,5,1,END_BRICKS)
Block(4,5,2,END_BRICKS)
Block(4,5,3,END_BRICKS)
Block(4,5,4,END_BRICKS)
Block(4,5,5,PURPUR_PILLAR:0)
Block(4,6,-4,PURPUR_PILLAR:0)
Block(4,6,-3,END_BRICKS)
Block(4,6,-2,STAINED_GLASS:2)
Block(4,6,-1,END_BRICKS)
Block(4,6,0,END_BRICKS)
Block(4,6,1,END_BRICKS)
Block(4,6,2,END_BRICKS)
Block(4,6,3,END_BRICKS)
Block(4,6,4,END_BRICKS)
Block(4,6,5,PURPUR_PILLAR:0)
Block(4,7,-4,PURPUR_PILLAR:0)
Block(4,7,-3,END_BRICKS)
Block(4,7,-2,STAINED_GLASS:2)
Block(4,7,-1,END_BRICKS)
Block(4,7,0,END_BRICKS)
Block(4,7,1,END_BRICKS)
Block(4,7,2,END_BRICKS)
Block(4,7,3,END_BRICKS)
Block(4,7,4,END_BRICKS)
Block(4,7,5,PURPUR_PILLAR:0)
Block(4,8,-6,PURPUR_STAIRS:2)
Block(4,8,-5,PURPUR_BLOCK)
Block(4,8,-4,PURPUR_BLOCK)
Block(4,8,-3,PURPUR_BLOCK)
Block(4,8,-2,PURPUR_BLOCK)
Block(4,8,-1,PURPUR_BLOCK)
Block(4,8,0,PURPUR_BLOCK)
Block(4,8,1,PURPUR_BLOCK)
Block(4,8,2,PURPUR_BLOCK)
Block(4,8,3,PURPUR_BLOCK)
Block(4,8,4,PURPUR_BLOCK)
Block(4,8,5,PURPUR_BLOCK)
Block(4,8,6,PURPUR_BLOCK)
Block(4,8,7,PURPUR_STAIRS:0)
Block(5,4,-5,PURPUR_STAIRS:6)
Block(5,4,-4,PURPUR_STAIRS:5)
Block(5,4,-3,PURPUR_STAIRS:1)
Block(5,4,-2,PURPUR_STAIRS:5)
Block(5,4,-1,PURPUR_STAIRS:5)
Block(5,4,0,PURPUR_STAIRS:1)
Block(5,4,1,PURPUR_STAIRS:1)
Block(5,4,2,PURPUR_STAIRS:5)
Block(5,4,3,PURPUR_STAIRS:5)
Block(5,4,4,PURPUR_STAIRS:1)
Block(5,4,5,PURPUR_STAIRS:5)
Block(5,4,6,PURPUR_STAIRS:5)
Block(5,5,-5,END_ROD)
Block(5,5,6,END_ROD)
Block(5,8,-6,PURPUR_STAIRS:6)
Block(5,8,-5,PURPUR_BLOCK)
Block(5,8,-4,PURPUR_BLOCK)
Block(5,8,-3,PURPUR_BLOCK)
Block(5,8,-2,PURPUR_BLOCK)
Block(5,8,-1,PURPUR_BLOCK)
Block(5,8,0,PURPUR_BLOCK)
Block(5,8,1,PURPUR_BLOCK)
Block(5,8,2,PURPUR_BLOCK)
Block(5,8,3,PURPUR_BLOCK)
Block(5,8,4,PURPUR_BLOCK)
Block(5,8,5,PURPUR_BLOCK)
Block(5,8,6,PURPUR_BLOCK)
Block(5,8,7,PURPUR_STAIRS:7)
Block(5,9,-5,END_ROD)
Block(5,9,6,END_ROD)
Block(6,8,-6,PURPUR_STAIRS:6)
Block(6,8,-5,PURPUR_STAIRS:5)
Block(6,8,-4,PURPUR_STAIRS:1)
Block(6,8,-3,PURPUR_STAIRS:1)
Block(6,8,-2,PURPUR_STAIRS:5)
Block(6,8,-1,PURPUR_STAIRS:5)
Block(6,8,0,PURPUR_STAIRS:1)
Block(6,8,1,PURPUR_STAIRS:1)
Block(6,8,2,PURPUR_STAIRS:5)
Block(6,8,3,PURPUR_STAIRS:5)
Block(6,8,4,PURPUR_STAIRS:1)
Block(6,8,5,PURPUR_STAIRS:1)
Block(6,8,6,PURPUR_STAIRS:5)
Block(6,8,7,PURPUR_STAIRS:5)

#######################################################################
# +-----------------------------------------------------------------+ #
# |                            BO3 checks                           | #
# +-----------------------------------------------------------------+ #
#######################################################################


#######################################################################
# +-----------------------------------------------------------------+ #
# |                             Branches                            | #
# +-----------------------------------------------------------------+ #
#######################################################################


#######################################################################
# +-----------------------------------------------------------------+ #
# |                             Entities                            | #
# +-----------------------------------------------------------------+ #
#######################################################################

Entity(-4,5,4,SHULKER,1)
Entity(-2,2,5,SHULKER,1)
Entity(-2,9,1,SHULKER,1)
Entity(0,7,1,SHULKER,1)
Entity(1,2,5,SHULKER,1)
Entity(3,5,-3,SHULKER,1)

#######################################################################
# +-----------------------------------------------------------------+ #
# |                            Particles                            | #
# +-----------------------------------------------------------------+ #
#######################################################################


#######################################################################
# +-----------------------------------------------------------------+ #
# |                             Spawners                            | #
# +-----------------------------------------------------------------+ #
#######################################################################


#######################################################################
# +-----------------------------------------------------------------+ #
# |                             ModData                             | #
# +-----------------------------------------------------------------+ #
#######################################################################

