
#######################################################################
# +-----------------------------------------------------------------+ #
# |                            BO3 object                           | #
# +-----------------------------------------------------------------+ #
#######################################################################

Author: totemo

Description: A wither in an obsidian tweety-bird cage.

Version: 3

SettingsMode: WriteWithoutComments


#######################################################################
# +-----------------------------------------------------------------+ #
# |                          Main settings                          | #
# +-----------------------------------------------------------------+ #
#######################################################################

Tree: false

Frequency: 25

Rarity: 100.0

RotateRandomly: true

SpawnHeight: highestBlock

SpawnHeightOffset: 0

SpawnHeightVariance: 0

##############################
# Height Limits for the BO3. #
##############################

MinHeight: 0

MaxHeight: 256

######################
# Extrusion settings #
######################

ExtrudeMode: None

ExtrudeThroughBlocks: AIR

MaxBranchDepth: 10

ExcludedBiomes: All


#######################################################################
# +-----------------------------------------------------------------+ #
# |                      Source block settings                      | #
# +-----------------------------------------------------------------+ #
#######################################################################

SourceBlocks: AIR

MaxPercentageOutsideSourceBlock: 10

OutsideSourceBlock: placeAnyway

IsOTGPlus: false

InheritBO3: 

InheritBO3Rotation: NORTH

OverrideChildSettings: true

OverrideParentHeight: false

CanOverride: false

BranchFrequency: 0

BranchFrequencyGroup: 

MustBeBelowOther: false

MustBeInside: 

CannotBeInside: 

ReplacesBO3: 

CanSpawnOnWater: true

SpawnOnWaterOnly: false

SpawnUnderWater: false

SpawnAtWaterLevel: false

HeightOffset: 0

RemoveAir: true

ReplaceAbove: 

ReplaceBelow: 

ReplaceWithBiomeBlocks: true

ReplaceWithGroundBlock: DIRT

ReplaceWithSurfaceBlock: GRASS

SmoothRadius: 0

SmoothHeightOffset: 0

SmoothStartTop: false

SmoothStartWood: false

SmoothingSurfaceBlock: 

SmoothingGroundBlock: 

BO3Group: 

IsSpawnPoint: false


#######################################################################
# +-----------------------------------------------------------------+ #
# |                              Blocks                             | #
# +-----------------------------------------------------------------+ #
#######################################################################

Block(-5,-26,-1,OBSIDIAN)
Block(-5,-26,0,OBSIDIAN)
Block(-5,-26,1,OBSIDIAN)
Block(-5,-20,-1,OBSIDIAN)
Block(-5,-20,0,OBSIDIAN)
Block(-5,-20,1,OBSIDIAN)
Block(-4,-28,-2,OBSIDIAN)
Block(-4,-28,-1,OBSIDIAN)
Block(-4,-28,0,OBSIDIAN)
Block(-4,-28,1,OBSIDIAN)
Block(-4,-28,2,OBSIDIAN)
Block(-4,-27,-1,OBSIDIAN)
Block(-4,-27,1,OBSIDIAN)
Block(-4,-26,-3,OBSIDIAN)
Block(-4,-26,-2,OBSIDIAN)
Block(-4,-26,-1,OBSIDIAN)
Block(-4,-26,1,OBSIDIAN)
Block(-4,-26,2,OBSIDIAN)
Block(-4,-26,3,OBSIDIAN)
Block(-4,-25,-1,OBSIDIAN)
Block(-4,-25,1,OBSIDIAN)
Block(-4,-24,-3,IRON_FENCE)
Block(-4,-24,-2,IRON_FENCE)
Block(-4,-24,-1,OBSIDIAN)
Block(-4,-24,0,IRON_FENCE)
Block(-4,-24,1,OBSIDIAN)
Block(-4,-24,2,IRON_FENCE)
Block(-4,-24,3,IRON_FENCE)
Block(-4,-23,-1,OBSIDIAN)
Block(-4,-23,1,OBSIDIAN)
Block(-4,-22,-3,IRON_FENCE)
Block(-4,-22,-2,IRON_FENCE)
Block(-4,-22,-1,OBSIDIAN)
Block(-4,-22,0,IRON_FENCE)
Block(-4,-22,1,OBSIDIAN)
Block(-4,-22,2,IRON_FENCE)
Block(-4,-22,3,IRON_FENCE)
Block(-4,-21,-1,OBSIDIAN)
Block(-4,-21,1,OBSIDIAN)
Block(-4,-20,-3,OBSIDIAN)
Block(-4,-20,-2,OBSIDIAN)
Block(-4,-20,-1,OBSIDIAN)
Block(-4,-20,1,OBSIDIAN)
Block(-4,-20,2,OBSIDIAN)
Block(-4,-20,3,OBSIDIAN)
Block(-4,-19,-1,OBSIDIAN)
Block(-4,-19,1,OBSIDIAN)
Block(-4,-18,-3,IRON_FENCE)
Block(-4,-18,-2,IRON_FENCE)
Block(-4,-18,-1,OBSIDIAN)
Block(-4,-18,0,IRON_FENCE)
Block(-4,-18,1,OBSIDIAN)
Block(-4,-18,2,IRON_FENCE)
Block(-4,-18,3,IRON_FENCE)
Block(-3,-29,-1,OBSIDIAN)
Block(-3,-29,0,OBSIDIAN)
Block(-3,-29,1,OBSIDIAN)
Block(-3,-28,-3,OBSIDIAN)
Block(-3,-28,-2,OBSIDIAN)
Block(-3,-28,-1,OBSIDIAN)
Block(-3,-28,0,OBSIDIAN)
Block(-3,-28,1,OBSIDIAN)
Block(-3,-28,2,OBSIDIAN)
Block(-3,-28,3,OBSIDIAN)
Block(-3,-27,-3,OBSIDIAN)
Block(-3,-27,3,OBSIDIAN)
Block(-3,-26,-4,OBSIDIAN)
Block(-3,-26,-3,OBSIDIAN)
Block(-3,-26,3,OBSIDIAN)
Block(-3,-26,4,OBSIDIAN)
Block(-3,-25,-3,OBSIDIAN)
Block(-3,-25,3,OBSIDIAN)
Block(-3,-24,-4,IRON_FENCE)
Block(-3,-24,-3,OBSIDIAN)
Block(-3,-24,3,OBSIDIAN)
Block(-3,-23,-3,OBSIDIAN)
Block(-3,-23,3,OBSIDIAN)
Block(-3,-22,-4,IRON_FENCE)
Block(-3,-22,-3,OBSIDIAN)
Block(-3,-22,3,OBSIDIAN)
Block(-3,-21,-3,OBSIDIAN)
Block(-3,-21,3,OBSIDIAN)
Block(-3,-20,-4,OBSIDIAN)
Block(-3,-20,-3,OBSIDIAN)
Block(-3,-20,3,OBSIDIAN)
Block(-3,-20,4,OBSIDIAN)
Block(-3,-19,-3,OBSIDIAN)
Block(-3,-19,3,OBSIDIAN)
Block(-3,-18,-4,IRON_FENCE)
Block(-3,-18,-3,OBSIDIAN)
Block(-3,-18,3,OBSIDIAN)
Block(-3,-18,4,IRON_FENCE)
Block(-3,-17,-2,OBSIDIAN)
Block(-3,-17,-1,OBSIDIAN)
Block(-3,-17,0,OBSIDIAN)
Block(-3,-17,1,OBSIDIAN)
Block(-3,-17,2,OBSIDIAN)
Block(-2,-29,-2,OBSIDIAN)
Block(-2,-29,-1,OBSIDIAN)
Block(-2,-29,0,OBSIDIAN)
Block(-2,-29,1,OBSIDIAN)
Block(-2,-29,2,OBSIDIAN)
Block(-2,-28,-4,OBSIDIAN)
Block(-2,-28,-3,OBSIDIAN)
Block(-2,-28,-2,OBSIDIAN)
Block(-2,-28,-1,OBSIDIAN)
Block(-2,-28,0,OBSIDIAN)
Block(-2,-28,1,OBSIDIAN)
Block(-2,-28,2,OBSIDIAN)
Block(-2,-28,3,OBSIDIAN)
Block(-2,-28,4,OBSIDIAN)
Block(-2,-27,4,OBSIDIAN)
Block(-2,-26,-4,OBSIDIAN)
Block(-2,-26,4,OBSIDIAN)
Block(-2,-25,4,OBSIDIAN)
Block(-2,-24,-4,IRON_FENCE)
Block(-2,-24,4,OBSIDIAN)
Block(-2,-23,4,OBSIDIAN)
Block(-2,-22,-4,IRON_FENCE)
Block(-2,-22,4,OBSIDIAN)
Block(-2,-20,-4,OBSIDIAN)
Block(-2,-20,4,OBSIDIAN)
Block(-2,-18,-4,IRON_FENCE)
Block(-2,-18,4,IRON_FENCE)
Block(-2,-17,-3,OBSIDIAN)
Block(-2,-17,-2,OBSIDIAN)
Block(-2,-17,-1,OBSIDIAN)
Block(-2,-17,0,OBSIDIAN)
Block(-2,-17,1,OBSIDIAN)
Block(-2,-17,2,OBSIDIAN)
Block(-2,-17,3,OBSIDIAN)
Block(-2,-16,-1,OBSIDIAN)
Block(-2,-16,0,OBSIDIAN)
Block(-2,-16,1,OBSIDIAN)
Block(-2,-3,-1,OBSIDIAN)
Block(-2,-3,0,OBSIDIAN)
Block(-2,-3,1,OBSIDIAN)
Block(-2,-2,-1,ENDER_STONE)
Block(-2,-2,0,ENDER_STONE)
Block(-2,-2,1,ENDER_STONE)
Block(-1,-29,-3,OBSIDIAN)
Block(-1,-29,-2,OBSIDIAN)
Block(-1,-29,-1,OBSIDIAN)
Block(-1,-29,0,OBSIDIAN)
Block(-1,-29,1,OBSIDIAN)
Block(-1,-29,2,OBSIDIAN)
Block(-1,-29,3,OBSIDIAN)
Block(-1,-28,-4,OBSIDIAN)
Block(-1,-28,-3,OBSIDIAN)
Block(-1,-28,-2,OBSIDIAN)
Block(-1,-28,-1,OBSIDIAN)
Block(-1,-28,0,OBSIDIAN)
Block(-1,-28,1,OBSIDIAN)
Block(-1,-28,2,OBSIDIAN)
Block(-1,-28,3,OBSIDIAN)
Block(-1,-28,4,OBSIDIAN)
Block(-1,-27,-4,OBSIDIAN)
Block(-1,-27,4,IRON_FENCE)
Block(-1,-26,-5,OBSIDIAN)
Block(-1,-26,-4,OBSIDIAN)
Block(-1,-26,4,IRON_FENCE)
Block(-1,-25,-4,OBSIDIAN)
Block(-1,-25,4,IRON_FENCE)
Block(-1,-24,-4,OBSIDIAN)
Block(-1,-24,4,IRON_FENCE)
Block(-1,-23,-4,OBSIDIAN)
Block(-1,-23,4,IRON_FENCE)
Block(-1,-22,-4,OBSIDIAN)
Block(-1,-22,4,OBSIDIAN)
Block(-1,-21,-4,OBSIDIAN)
Block(-1,-21,4,OBSIDIAN)
Block(-1,-20,-5,OBSIDIAN)
Block(-1,-20,-4,OBSIDIAN)
Block(-1,-20,4,OBSIDIAN)
Block(-1,-20,5,OBSIDIAN)
Block(-1,-19,-4,OBSIDIAN)
Block(-1,-19,4,OBSIDIAN)
Block(-1,-18,-4,OBSIDIAN)
Block(-1,-18,4,OBSIDIAN)
Block(-1,-17,-3,OBSIDIAN)
Block(-1,-17,-2,OBSIDIAN)
Block(-1,-17,-1,OBSIDIAN)
Block(-1,-17,0,OBSIDIAN)
Block(-1,-17,1,OBSIDIAN)
Block(-1,-17,2,OBSIDIAN)
Block(-1,-17,3,OBSIDIAN)
Block(-1,-16,-2,OBSIDIAN)
Block(-1,-16,-1,OBSIDIAN)
Block(-1,-16,0,OBSIDIAN)
Block(-1,-16,1,OBSIDIAN)
Block(-1,-16,2,OBSIDIAN)
Block(-1,-15,0,SMOOTH_STAIRS:0)
Block(-1,-14,0,SMOOTH_STAIRS:4)
Block(-1,-13,0,SMOOTH_BRICK)
Block(-1,-12,0,SMOOTH_BRICK)
Block(-1,-11,0,SMOOTH_STAIRS:0)
Block(-1,-8,0,SMOOTH_STAIRS:4)
Block(-1,-7,0,SMOOTH_BRICK)
Block(-1,-6,0,SMOOTH_BRICK)
Block(-1,-5,0,SMOOTH_STAIRS:0)
Block(-1,-3,-2,OBSIDIAN)
Block(-1,-3,-1,OBSIDIAN)
Block(-1,-3,0,OBSIDIAN)
Block(-1,-3,1,OBSIDIAN)
Block(-1,-3,2,OBSIDIAN)
Block(-1,-2,-2,ENDER_STONE)
Block(-1,-2,-1,ENDER_STONE)
Block(-1,-2,0,ENDER_STONE)
Block(-1,-2,1,ENDER_STONE)
Block(-1,-2,2,ENDER_STONE)
Block(0,-32,0,IRON_FENCE)
Block(0,-31,0,COBBLE_WALL)
Block(0,-30,0,OBSIDIAN)
Block(0,-29,-3,OBSIDIAN)
Block(0,-29,-2,OBSIDIAN)
Block(0,-29,-1,OBSIDIAN)
Block(0,-29,0,OBSIDIAN)
Block(0,-29,1,OBSIDIAN)
Block(0,-29,2,OBSIDIAN)
Block(0,-29,3,OBSIDIAN)
Block(0,-28,-4,OBSIDIAN)
Block(0,-28,-3,OBSIDIAN)
Block(0,-28,-2,OBSIDIAN)
Block(0,-28,-1,OBSIDIAN)
Block(0,-28,0,OBSIDIAN)
Block(0,-28,1,OBSIDIAN)
Block(0,-28,2,OBSIDIAN)
Block(0,-28,3,OBSIDIAN)
Block(0,-28,4,OBSIDIAN)
Block(0,-27,4,IRON_FENCE)
Block(0,-26,-5,OBSIDIAN)
Block(0,-25,4,IRON_FENCE)
Block(0,-24,-4,IRON_FENCE)
Block(0,-23,4,IRON_FENCE)
Block(0,-22,-4,IRON_FENCE)
Block(0,-22,4,OBSIDIAN)
Block(0,-20,-5,OBSIDIAN)
Block(0,-20,5,OBSIDIAN)
Block(0,-18,-4,IRON_FENCE)
Block(0,-18,4,IRON_FENCE)
Block(0,-17,-3,OBSIDIAN)
Block(0,-17,-2,OBSIDIAN)
Block(0,-17,-1,OBSIDIAN)
Block(0,-17,0,OBSIDIAN)
Block(0,-17,1,OBSIDIAN)
Block(0,-17,2,OBSIDIAN)
Block(0,-17,3,OBSIDIAN)
Block(0,-16,-2,OBSIDIAN)
Block(0,-16,-1,OBSIDIAN)
Block(0,-16,0,OBSIDIAN)
Block(0,-16,1,OBSIDIAN)
Block(0,-16,2,OBSIDIAN)
Block(0,-15,-1,SMOOTH_STAIRS:2)
Block(0,-15,0,SMOOTH_BRICK)
Block(0,-15,1,SMOOTH_STAIRS)
Block(0,-14,0,SMOOTH_BRICK)
Block(0,-11,-1,SMOOTH_STAIRS:6)
Block(0,-11,0,SMOOTH_BRICK)
Block(0,-11,1,SMOOTH_STAIRS:7)
Block(0,-10,-1,SMOOTH_BRICK)
Block(0,-10,1,SMOOTH_BRICK)
Block(0,-9,-1,SMOOTH_BRICK)
Block(0,-9,1,SMOOTH_BRICK)
Block(0,-8,-1,SMOOTH_STAIRS:2)
Block(0,-8,0,SMOOTH_BRICK)
Block(0,-8,1,SMOOTH_STAIRS)
Block(0,-5,-1,SMOOTH_STAIRS:6)
Block(0,-5,0,SMOOTH_BRICK)
Block(0,-5,1,SMOOTH_STAIRS:7)
Block(0,-4,-1,SMOOTH_BRICK)
Block(0,-4,1,SMOOTH_BRICK)
Block(0,-3,-2,OBSIDIAN)
Block(0,-3,-1,OBSIDIAN)
Block(0,-3,0,OBSIDIAN)
Block(0,-3,1,OBSIDIAN)
Block(0,-3,2,OBSIDIAN)
Block(0,-2,-2,ENDER_STONE)
Block(0,-2,-1,ENDER_STONE)
Block(0,-2,0,ENDER_STONE)
Block(0,-2,1,ENDER_STONE)
Block(0,-2,2,ENDER_STONE)
Block(1,-29,-3,OBSIDIAN)
Block(1,-29,-2,OBSIDIAN)
Block(1,-29,-1,OBSIDIAN)
Block(1,-29,0,OBSIDIAN)
Block(1,-29,1,OBSIDIAN)
Block(1,-29,2,OBSIDIAN)
Block(1,-29,3,OBSIDIAN)
Block(1,-28,-4,OBSIDIAN)
Block(1,-28,-3,OBSIDIAN)
Block(1,-28,-2,OBSIDIAN)
Block(1,-28,-1,OBSIDIAN)
Block(1,-28,0,OBSIDIAN)
Block(1,-28,1,OBSIDIAN)
Block(1,-28,2,OBSIDIAN)
Block(1,-28,3,OBSIDIAN)
Block(1,-28,4,OBSIDIAN)
Block(1,-27,-4,OBSIDIAN)
Block(1,-27,4,IRON_FENCE)
Block(1,-26,-5,OBSIDIAN)
Block(1,-26,-4,OBSIDIAN)
Block(1,-26,4,IRON_FENCE)
Block(1,-25,-4,OBSIDIAN)
Block(1,-25,4,IRON_FENCE)
Block(1,-24,-4,OBSIDIAN)
Block(1,-24,4,IRON_FENCE)
Block(1,-23,-4,OBSIDIAN)
Block(1,-23,4,IRON_FENCE)
Block(1,-22,-4,OBSIDIAN)
Block(1,-22,4,OBSIDIAN)
Block(1,-21,-4,OBSIDIAN)
Block(1,-21,4,OBSIDIAN)
Block(1,-20,-5,OBSIDIAN)
Block(1,-20,-4,OBSIDIAN)
Block(1,-20,4,OBSIDIAN)
Block(1,-20,5,OBSIDIAN)
Block(1,-19,-4,OBSIDIAN)
Block(1,-19,4,OBSIDIAN)
Block(1,-18,-4,OBSIDIAN)
Block(1,-18,4,OBSIDIAN)
Block(1,-17,-3,OBSIDIAN)
Block(1,-17,-2,OBSIDIAN)
Block(1,-17,-1,OBSIDIAN)
Block(1,-17,0,OBSIDIAN)
Block(1,-17,1,OBSIDIAN)
Block(1,-17,2,OBSIDIAN)
Block(1,-17,3,OBSIDIAN)
Block(1,-16,-2,OBSIDIAN)
Block(1,-16,-1,OBSIDIAN)
Block(1,-16,0,OBSIDIAN)
Block(1,-16,1,OBSIDIAN)
Block(1,-16,2,OBSIDIAN)
Block(1,-15,0,SMOOTH_STAIRS:1)
Block(1,-14,0,SMOOTH_STAIRS:5)
Block(1,-13,0,SMOOTH_BRICK)
Block(1,-12,0,SMOOTH_BRICK)
Block(1,-11,0,SMOOTH_STAIRS:1)
Block(1,-8,0,SMOOTH_STAIRS:5)
Block(1,-7,0,SMOOTH_BRICK)
Block(1,-6,0,SMOOTH_BRICK)
Block(1,-5,0,SMOOTH_STAIRS:1)
Block(1,-3,-2,OBSIDIAN)
Block(1,-3,-1,OBSIDIAN)
Block(1,-3,0,OBSIDIAN)
Block(1,-3,1,OBSIDIAN)
Block(1,-3,2,OBSIDIAN)
Block(1,-2,-2,ENDER_STONE)
Block(1,-2,-1,ENDER_STONE)
Block(1,-2,0,ENDER_STONE)
Block(1,-2,1,ENDER_STONE)
Block(1,-2,2,ENDER_STONE)
Block(2,-29,-2,OBSIDIAN)
Block(2,-29,-1,OBSIDIAN)
Block(2,-29,0,OBSIDIAN)
Block(2,-29,1,OBSIDIAN)
Block(2,-29,2,OBSIDIAN)
Block(2,-28,-4,OBSIDIAN)
Block(2,-28,-3,OBSIDIAN)
Block(2,-28,-2,OBSIDIAN)
Block(2,-28,-1,OBSIDIAN)
Block(2,-28,0,OBSIDIAN)
Block(2,-28,1,OBSIDIAN)
Block(2,-28,2,OBSIDIAN)
Block(2,-28,3,OBSIDIAN)
Block(2,-28,4,OBSIDIAN)
Block(2,-27,4,OBSIDIAN)
Block(2,-26,-4,OBSIDIAN)
Block(2,-26,4,OBSIDIAN)
Block(2,-25,4,OBSIDIAN)
Block(2,-25,5,COBBLE_WALL)
Block(2,-24,-4,IRON_FENCE)
Block(2,-24,4,OBSIDIAN)
Block(2,-23,4,OBSIDIAN)
Block(2,-22,-4,IRON_FENCE)
Block(2,-22,4,OBSIDIAN)
Block(2,-20,-4,OBSIDIAN)
Block(2,-20,4,OBSIDIAN)
Block(2,-18,-4,IRON_FENCE)
Block(2,-18,4,IRON_FENCE)
Block(2,-17,-3,OBSIDIAN)
Block(2,-17,-2,OBSIDIAN)
Block(2,-17,-1,OBSIDIAN)
Block(2,-17,0,OBSIDIAN)
Block(2,-17,1,OBSIDIAN)
Block(2,-17,2,OBSIDIAN)
Block(2,-17,3,OBSIDIAN)
Block(2,-16,-1,OBSIDIAN)
Block(2,-16,0,OBSIDIAN)
Block(2,-16,1,OBSIDIAN)
Block(2,-3,-1,OBSIDIAN)
Block(2,-3,0,OBSIDIAN)
Block(2,-3,1,OBSIDIAN)
Block(2,-2,-1,ENDER_STONE)
Block(2,-2,0,ENDER_STONE)
Block(2,-2,1,ENDER_STONE)
Block(3,-29,-1,OBSIDIAN)
Block(3,-29,0,OBSIDIAN)
Block(3,-29,1,OBSIDIAN)
Block(3,-28,-3,OBSIDIAN)
Block(3,-28,-2,OBSIDIAN)
Block(3,-28,-1,OBSIDIAN)
Block(3,-28,0,OBSIDIAN)
Block(3,-28,1,OBSIDIAN)
Block(3,-28,2,OBSIDIAN)
Block(3,-28,3,OBSIDIAN)
Block(3,-27,-3,OBSIDIAN)
Block(3,-27,3,OBSIDIAN)
Block(3,-26,-4,OBSIDIAN)
Block(3,-26,-3,OBSIDIAN)
Block(3,-26,3,OBSIDIAN)
Block(3,-26,4,OBSIDIAN)
Block(3,-25,-3,OBSIDIAN)
Block(3,-25,3,OBSIDIAN)
Block(3,-24,-4,IRON_FENCE)
Block(3,-24,-3,OBSIDIAN)
Block(3,-24,3,OBSIDIAN)
Block(3,-23,-3,OBSIDIAN)
Block(3,-23,3,OBSIDIAN)
Block(3,-22,-4,IRON_FENCE)
Block(3,-22,-3,OBSIDIAN)
Block(3,-22,3,OBSIDIAN)
Block(3,-21,-3,OBSIDIAN)
Block(3,-21,3,OBSIDIAN)
Block(3,-20,-4,OBSIDIAN)
Block(3,-20,-3,OBSIDIAN)
Block(3,-20,3,OBSIDIAN)
Block(3,-20,4,OBSIDIAN)
Block(3,-19,-3,OBSIDIAN)
Block(3,-19,3,OBSIDIAN)
Block(3,-18,-4,IRON_FENCE)
Block(3,-18,-3,OBSIDIAN)
Block(3,-18,3,OBSIDIAN)
Block(3,-18,4,IRON_FENCE)
Block(3,-17,-2,OBSIDIAN)
Block(3,-17,-1,OBSIDIAN)
Block(3,-17,0,OBSIDIAN)
Block(3,-17,1,OBSIDIAN)
Block(3,-17,2,OBSIDIAN)
Block(4,-28,-2,OBSIDIAN)
Block(4,-28,-1,OBSIDIAN)
Block(4,-28,0,OBSIDIAN)
Block(4,-28,1,OBSIDIAN)
Block(4,-28,2,OBSIDIAN)
Block(4,-27,-1,OBSIDIAN)
Block(4,-27,1,OBSIDIAN)
Block(4,-26,-3,OBSIDIAN)
Block(4,-26,-2,OBSIDIAN)
Block(4,-26,-1,OBSIDIAN)
Block(4,-26,1,OBSIDIAN)
Block(4,-26,2,OBSIDIAN)
Block(4,-26,3,OBSIDIAN)
Block(4,-25,-1,OBSIDIAN)
Block(4,-25,1,OBSIDIAN)
Block(4,-24,-3,IRON_FENCE)
Block(4,-24,-2,IRON_FENCE)
Block(4,-24,-1,OBSIDIAN)
Block(4,-24,0,IRON_FENCE)
Block(4,-24,1,OBSIDIAN)
Block(4,-24,2,IRON_FENCE)
Block(4,-24,3,IRON_FENCE)
Block(4,-23,-1,OBSIDIAN)
Block(4,-23,1,OBSIDIAN)
Block(4,-22,-3,IRON_FENCE)
Block(4,-22,-2,IRON_FENCE)
Block(4,-22,-1,OBSIDIAN)
Block(4,-22,0,IRON_FENCE)
Block(4,-22,1,OBSIDIAN)
Block(4,-22,2,IRON_FENCE)
Block(4,-22,3,IRON_FENCE)
Block(4,-21,-1,OBSIDIAN)
Block(4,-21,1,OBSIDIAN)
Block(4,-20,-3,OBSIDIAN)
Block(4,-20,-2,OBSIDIAN)
Block(4,-20,-1,OBSIDIAN)
Block(4,-20,1,OBSIDIAN)
Block(4,-20,2,OBSIDIAN)
Block(4,-20,3,OBSIDIAN)
Block(4,-19,-1,OBSIDIAN)
Block(4,-19,1,OBSIDIAN)
Block(4,-18,-3,IRON_FENCE)
Block(4,-18,-2,IRON_FENCE)
Block(4,-18,-1,OBSIDIAN)
Block(4,-18,0,IRON_FENCE)
Block(4,-18,1,OBSIDIAN)
Block(4,-18,2,IRON_FENCE)
Block(4,-18,3,IRON_FENCE)
Block(5,-26,-1,OBSIDIAN)
Block(5,-26,0,OBSIDIAN)
Block(5,-26,1,OBSIDIAN)
Block(5,-20,-1,OBSIDIAN)
Block(5,-20,0,OBSIDIAN)
Block(5,-20,1,OBSIDIAN)

#######################################################################
# +-----------------------------------------------------------------+ #
# |                            BO3 checks                           | #
# +-----------------------------------------------------------------+ #
#######################################################################

BlockCheck(0,-1,0,ENDER_STONE)

#######################################################################
# +-----------------------------------------------------------------+ #
# |                             Branches                            | #
# +-----------------------------------------------------------------+ #
#######################################################################


#######################################################################
# +-----------------------------------------------------------------+ #
# |                             Entities                            | #
# +-----------------------------------------------------------------+ #
#######################################################################

Entity(0,-27,0,WITHER,1)

#######################################################################
# +-----------------------------------------------------------------+ #
# |                            Particles                            | #
# +-----------------------------------------------------------------+ #
#######################################################################


#######################################################################
# +-----------------------------------------------------------------+ #
# |                             Spawners                            | #
# +-----------------------------------------------------------------+ #
#######################################################################


#######################################################################
# +-----------------------------------------------------------------+ #
# |                             ModData                             | #
# +-----------------------------------------------------------------+ #
#######################################################################

