
#######################################################################
# +-----------------------------------------------------------------+ #
# |                            BO3 object                           | #
# +-----------------------------------------------------------------+ #
#######################################################################

Author: totemo

Description: A villager survival pod.

Version: 3

SettingsMode: WriteWithoutComments


#######################################################################
# +-----------------------------------------------------------------+ #
# |                          Main settings                          | #
# +-----------------------------------------------------------------+ #
#######################################################################

Tree: false

Frequency: 100

Rarity: 100.0

RotateRandomly: false

SpawnHeight: highestBlock

SpawnHeightOffset: 0

SpawnHeightVariance: 0

##############################
# Height Limits for the BO3. #
##############################

MinHeight: 0

MaxHeight: 256

######################
# Extrusion settings #
######################

ExtrudeMode: BottomDown

ExtrudeThroughBlocks: AIR,DEAD_BUSH,CACTUS,BROWN_MUSHROOM,RED_MUSHROOM

MaxBranchDepth: 10

ExcludedBiomes: All


#######################################################################
# +-----------------------------------------------------------------+ #
# |                      Source block settings                      | #
# +-----------------------------------------------------------------+ #
#######################################################################

SourceBlocks: AIR

MaxPercentageOutsideSourceBlock: 30

OutsideSourceBlock: placeAnyway

IsOTGPlus: false


#######################################################################
# +-----------------------------------------------------------------+ #
# |                              Blocks                             | #
# +-----------------------------------------------------------------+ #
#######################################################################

Block(-7,-1,-12,CONCRETE)
Block(-7,-1,-11,CONCRETE)
Block(-7,-1,-10,CONCRETE)
Block(-7,-1,-9,CONCRETE)
Block(-7,-1,-8,CONCRETE)
Block(-7,-1,-7,CONCRETE)
Block(-7,0,-10,IRON_DOOR_BLOCK:2)
Block(-7,1,-10,IRON_DOOR_BLOCK:9)
Block(-7,1,-9,STONE_BUTTON:2)
Block(-6,-1,-14,CONCRETE)
Block(-6,-1,-13,CONCRETE)
Block(-6,-1,-12,CONCRETE)
Block(-6,-1,-11,CONCRETE)
Block(-6,-1,-10,CONCRETE)
Block(-6,-1,-9,CONCRETE)
Block(-6,-1,-8,CONCRETE)
Block(-6,-1,-7,CONCRETE)
Block(-6,-1,-6,CONCRETE)
Block(-6,-1,0,CONCRETE)
Block(-6,-1,1,CONCRETE)
Block(-6,-1,2,CONCRETE)
Block(-6,-1,3,CONCRETE)
Block(-6,-1,4,CONCRETE)
Block(-6,-1,5,CONCRETE)
Block(-6,-1,6,CONCRETE)
Block(-6,-1,7,CONCRETE)
Block(-6,-1,8,CONCRETE)
Block(-6,-1,9,CONCRETE)
Block(-6,-1,10,CONCRETE)
Block(-6,-1,11,CONCRETE)
Block(-6,-1,12,CONCRETE)
Block(-6,-1,13,CONCRETE)
Block(-6,0,-11,CONCRETE:8)
Block(-6,0,-9,CONCRETE:8)
Block(-6,0,4,CONCRETE)
Block(-6,0,9,CONCRETE)
Block(-6,1,-11,CONCRETE)
Block(-6,1,-10,STONE_BUTTON)
Block(-6,1,-9,CONCRETE)
Block(-6,1,4,CONCRETE)
Block(-6,1,9,CONCRETE)
Block(-6,2,-11,CONCRETE)
Block(-6,2,-10,STAINED_GLASS)
Block(-6,2,-9,CONCRETE)
Block(-6,2,4,CONCRETE)
Block(-6,2,9,CONCRETE)
Block(-6,3,-11,CONCRETE)
Block(-6,3,-10,CONCRETE)
Block(-6,3,-9,CONCRETE)
Block(-6,3,4,CONCRETE)
Block(-6,3,9,CONCRETE)
Block(-6,4,-11,CONCRETE)
Block(-6,4,-10,CONCRETE:13)
Block(-6,4,-9,CONCRETE)
Block(-6,5,-11,CONCRETE)
Block(-6,5,-10,CONCRETE:5)
Block(-6,5,-9,CONCRETE)
Block(-6,6,-10,CONCRETE)
Block(-5,-1,-15,CONCRETE)
Block(-5,-1,-14,CONCRETE)
Block(-5,-1,-13,CONCRETE)
Block(-5,-1,-12,CONCRETE)
Block(-5,-1,-11,CONCRETE)
Block(-5,-1,-10,CONCRETE)
Block(-5,-1,-9,CONCRETE)
Block(-5,-1,-8,CONCRETE)
Block(-5,-1,-7,CONCRETE)
Block(-5,-1,-6,CONCRETE)
Block(-5,-1,-5,CONCRETE)
Block(-5,-1,-1,CONCRETE)
Block(-5,-1,0,CONCRETE)
Block(-5,-1,1,CONCRETE)
Block(-5,-1,2,CONCRETE)
Block(-5,-1,3,CONCRETE)
Block(-5,-1,4,CONCRETE)
Block(-5,-1,5,CONCRETE)
Block(-5,-1,6,CONCRETE)
Block(-5,-1,7,CONCRETE)
Block(-5,-1,8,CONCRETE)
Block(-5,-1,9,CONCRETE)
Block(-5,-1,10,CONCRETE)
Block(-5,-1,11,CONCRETE)
Block(-5,-1,12,CONCRETE)
Block(-5,-1,13,CONCRETE)
Block(-5,-1,14,CONCRETE)
Block(-5,0,-13,CONCRETE:8)
Block(-5,0,-12,CONCRETE:8)
Block(-5,0,-11,IRON_TRAPDOOR:2)
Block(-5,0,-10,IRON_DOOR_BLOCK:0)
Block(-5,0,-9,IRON_TRAPDOOR:2)
Block(-5,0,-8,CONCRETE:8)
Block(-5,0,-7,CONCRETE:8)
Block(-5,0,1,CONCRETE:8)
Block(-5,0,2,CONCRETE:8)
Block(-5,0,3,CONCRETE:8)
Block(-5,0,4,CONCRETE:8)
Block(-5,0,5,CONCRETE:8)
Block(-5,0,6,CONCRETE:8)
Block(-5,0,7,CONCRETE:8)
Block(-5,0,8,CONCRETE:8)
Block(-5,0,9,CONCRETE:8)
Block(-5,0,10,CONCRETE:8)
Block(-5,0,11,CONCRETE:8)
Block(-5,0,12,CONCRETE:8)
Block(-5,1,-13,STAINED_GLASS)
Block(-5,1,-12,CONCRETE)
Block(-5,1,-10,IRON_DOOR_BLOCK:8)
Block(-5,1,-9,STONE_BUTTON:1)
Block(-5,1,-8,CONCRETE)
Block(-5,1,-7,STAINED_GLASS)
Block(-5,1,1,CONCRETE:8)
Block(-5,1,2,CONCRETE:8)
Block(-5,1,3,STAINED_GLASS)
Block(-5,1,4,STAINED_GLASS)
Block(-5,1,5,STAINED_GLASS)
Block(-5,1,6,STAINED_GLASS)
Block(-5,1,7,STAINED_GLASS)
Block(-5,1,8,STAINED_GLASS)
Block(-5,1,9,STAINED_GLASS)
Block(-5,1,10,STAINED_GLASS)
Block(-5,1,11,CONCRETE:8)
Block(-5,1,12,CONCRETE:8)
Block(-5,2,-13,STAINED_GLASS)
Block(-5,2,-12,CONCRETE)
Block(-5,2,-8,CONCRETE)
Block(-5,2,-7,STAINED_GLASS)
Block(-5,2,1,STAINED_GLASS)
Block(-5,2,2,STAINED_GLASS)
Block(-5,2,3,STAINED_GLASS)
Block(-5,2,4,STAINED_GLASS)
Block(-5,2,5,STAINED_GLASS)
Block(-5,2,6,STAINED_GLASS)
Block(-5,2,7,STAINED_GLASS)
Block(-5,2,8,STAINED_GLASS)
Block(-5,2,9,STAINED_GLASS)
Block(-5,2,10,STAINED_GLASS)
Block(-5,2,11,STAINED_GLASS)
Block(-5,2,12,STAINED_GLASS)
Block(-5,3,-13,CONCRETE)
Block(-5,3,-12,CONCRETE)
Block(-5,3,-11,IRON_TRAPDOOR:11)
Block(-5,3,-10,IRON_TRAPDOOR:11)
Block(-5,3,-9,IRON_TRAPDOOR:11)
Block(-5,3,-8,CONCRETE)
Block(-5,3,-7,CONCRETE)
Block(-5,3,2,STAINED_GLASS)
Block(-5,3,3,STAINED_GLASS)
Block(-5,3,4,STAINED_GLASS)
Block(-5,3,5,STAINED_GLASS)
Block(-5,3,6,STAINED_GLASS)
Block(-5,3,7,STAINED_GLASS)
Block(-5,3,8,STAINED_GLASS)
Block(-5,3,9,STAINED_GLASS)
Block(-5,3,10,STAINED_GLASS)
Block(-5,3,11,STAINED_GLASS)
Block(-5,4,-13,CONCRETE)
Block(-5,4,-12,CONCRETE)
Block(-5,4,-8,CONCRETE)
Block(-5,4,-7,CONCRETE)
Block(-5,4,4,CONCRETE)
Block(-5,4,5,STAINED_GLASS)
Block(-5,4,6,STAINED_GLASS)
Block(-5,4,7,STAINED_GLASS)
Block(-5,4,8,STAINED_GLASS)
Block(-5,4,9,CONCRETE)
Block(-5,5,-13,CONCRETE)
Block(-5,5,-12,CONCRETE)
Block(-5,5,-8,CONCRETE)
Block(-5,5,-7,CONCRETE)
Block(-5,6,-13,CONCRETE)
Block(-5,6,-12,CONCRETE)
Block(-5,6,-11,CONCRETE)
Block(-5,6,-10,END_ROD:2)
Block(-5,6,-9,CONCRETE)
Block(-5,6,-8,CONCRETE)
Block(-5,6,-7,CONCRETE)
Block(-5,7,-12,CONCRETE)
Block(-5,7,-11,CONCRETE)
Block(-5,7,-10,CONCRETE)
Block(-5,7,-9,CONCRETE)
Block(-5,7,-8,CONCRETE)
Block(-5,8,-11,CONCRETE)
Block(-5,8,-10,CONCRETE)
Block(-5,8,-9,CONCRETE)
Block(-4,-1,-16,CONCRETE)
Block(-4,-1,-15,CONCRETE)
Block(-4,-1,-14,CONCRETE)
Block(-4,-1,-13,CONCRETE)
Block(-4,-1,-12,CONCRETE)
Block(-4,-1,-11,CONCRETE)
Block(-4,-1,-10,CONCRETE)
Block(-4,-1,-9,CONCRETE)
Block(-4,-1,-8,CONCRETE)
Block(-4,-1,-7,CONCRETE)
Block(-4,-1,-6,CONCRETE)
Block(-4,-1,-5,CONCRETE)
Block(-4,-1,-4,CONCRETE)
Block(-4,-1,-2,CONCRETE)
Block(-4,-1,-1,CONCRETE)
Block(-4,-1,0,CONCRETE)
Block(-4,-1,1,CONCRETE)
Block(-4,-1,2,CONCRETE)
Block(-4,-1,3,CONCRETE)
Block(-4,-1,4,CONCRETE)
Block(-4,-1,5,CONCRETE)
Block(-4,-1,6,CONCRETE)
Block(-4,-1,7,CONCRETE)
Block(-4,-1,8,CONCRETE)
Block(-4,-1,9,CONCRETE)
Block(-4,-1,10,CONCRETE)
Block(-4,-1,11,CONCRETE)
Block(-4,-1,12,CONCRETE)
Block(-4,-1,13,CONCRETE)
Block(-4,-1,14,CONCRETE)
Block(-4,-1,15,CONCRETE)
Block(-4,0,-14,CONCRETE:8)
Block(-4,0,-13,IRON_TRAPDOOR:2)
Block(-4,0,-12,IRON_TRAPDOOR:2)
Block(-4,0,-11,IRON_TRAPDOOR:2)
Block(-4,0,-10,IRON_TRAPDOOR:2)
Block(-4,0,-9,IRON_TRAPDOOR:2)
Block(-4,0,-8,IRON_TRAPDOOR:2)
Block(-4,0,-7,IRON_TRAPDOOR:2)
Block(-4,0,-6,CONCRETE:8)
Block(-4,0,0,CONCRETE:8)
Block(-4,0,2,PRISMARINE:2)
Block(-4,0,3,STATIONARY_LAVA)
Block(-4,0,4,SOIL:7)
Block(-4,0,5,SOIL:7)
Block(-4,0,6,SOIL:7)
Block(-4,0,7,SOIL:7)
Block(-4,0,8,SOIL:7)
Block(-4,0,9,SOIL:7)
Block(-4,0,10,STATIONARY_LAVA)
Block(-4,0,11,PRISMARINE:2)
Block(-4,0,13,CONCRETE:8)
Block(-4,1,-14,STAINED_GLASS)
Block(-4,1,-6,STAINED_GLASS)
Block(-4,1,0,CONCRETE:8)
Block(-4,1,3,IRON_TRAPDOOR:3)
Block(-4,1,4,POTATO:7)
Block(-4,1,5,POTATO:7)
Block(-4,1,6,POTATO:7)
Block(-4,1,7,POTATO:7)
Block(-4,1,8,POTATO:7)
Block(-4,1,9,POTATO:7)
Block(-4,1,10,IRON_TRAPDOOR:3)
Block(-4,1,13,CONCRETE:8)
Block(-4,2,-14,STAINED_GLASS)
Block(-4,2,-6,STAINED_GLASS)
Block(-4,2,0,STAINED_GLASS)
Block(-4,2,2,QUARTZ_STAIRS:2)
Block(-4,2,3,END_ROD:3)
Block(-4,2,4,END_ROD:2)
Block(-4,2,5,END_ROD:3)
Block(-4,2,6,END_ROD:2)
Block(-4,2,7,END_ROD:3)
Block(-4,2,8,END_ROD:2)
Block(-4,2,9,END_ROD:3)
Block(-4,2,10,END_ROD:2)
Block(-4,2,11,QUARTZ_STAIRS:0)
Block(-4,2,13,STAINED_GLASS)
Block(-4,3,-14,CONCRETE)
Block(-4,3,-6,CONCRETE)
Block(-4,3,1,STAINED_GLASS)
Block(-4,3,2,QUARTZ_STAIRS:6)
Block(-4,3,11,QUARTZ_STAIRS:7)
Block(-4,3,12,STAINED_GLASS)
Block(-4,4,-14,CONCRETE)
Block(-4,4,-6,CONCRETE)
Block(-4,4,2,STAINED_GLASS)
Block(-4,4,3,STAINED_GLASS)
Block(-4,4,4,STAINED_GLASS)
Block(-4,4,9,STAINED_GLASS)
Block(-4,4,10,STAINED_GLASS)
Block(-4,4,11,STAINED_GLASS)
Block(-4,5,-14,CONCRETE)
Block(-4,5,-6,CONCRETE)
Block(-4,5,4,CONCRETE)
Block(-4,5,5,STAINED_GLASS)
Block(-4,5,6,STAINED_GLASS)
Block(-4,5,7,STAINED_GLASS)
Block(-4,5,8,STAINED_GLASS)
Block(-4,5,9,CONCRETE)
Block(-4,6,-14,CONCRETE)
Block(-4,6,-6,CONCRETE)
Block(-4,7,-14,CONCRETE)
Block(-4,7,-13,CONCRETE)
Block(-4,7,-7,CONCRETE)
Block(-4,7,-6,CONCRETE)
Block(-4,8,-13,CONCRETE)
Block(-4,8,-12,CONCRETE)
Block(-4,8,-8,CONCRETE)
Block(-4,8,-7,CONCRETE)
Block(-4,9,-12,CONCRETE)
Block(-4,9,-11,CONCRETE)
Block(-4,9,-10,CONCRETE)
Block(-4,9,-9,CONCRETE)
Block(-4,9,-8,CONCRETE)
Block(-3,-1,-16,CONCRETE)
Block(-3,-1,-15,CONCRETE)
Block(-3,-1,-14,CONCRETE)
Block(-3,-1,-13,CONCRETE)
Block(-3,-1,-12,CONCRETE)
Block(-3,-1,-11,CONCRETE)
Block(-3,-1,-10,CONCRETE)
Block(-3,-1,-9,CONCRETE)
Block(-3,-1,-8,CONCRETE)
Block(-3,-1,-7,CONCRETE)
Block(-3,-1,-6,CONCRETE)
Block(-3,-1,-5,CONCRETE)
Block(-3,-1,-4,CONCRETE)
Block(-3,-1,-3,CONCRETE)
Block(-3,-1,-2,CONCRETE)
Block(-3,-1,-1,CONCRETE)
Block(-3,-1,0,CONCRETE)
Block(-3,-1,1,CONCRETE)
Block(-3,-1,2,CONCRETE)
Block(-3,-1,3,CONCRETE)
Block(-3,-1,4,CONCRETE)
Block(-3,-1,5,CONCRETE)
Block(-3,-1,6,CONCRETE)
Block(-3,-1,7,CONCRETE)
Block(-3,-1,8,CONCRETE)
Block(-3,-1,9,CONCRETE)
Block(-3,-1,10,CONCRETE)
Block(-3,-1,11,CONCRETE)
Block(-3,-1,12,CONCRETE)
Block(-3,-1,13,CONCRETE)
Block(-3,-1,14,CONCRETE)
Block(-3,-1,15,CONCRETE)
Block(-3,0,-15,CONCRETE:8)
Block(-3,0,-14,IRON_TRAPDOOR:2)
Block(-3,0,-13,IRON_TRAPDOOR:2)
Block(-3,0,-12,IRON_TRAPDOOR:2)
Block(-3,0,-11,IRON_TRAPDOOR:2)
Block(-3,0,-10,IRON_TRAPDOOR:2)
Block(-3,0,-9,IRON_TRAPDOOR:2)
Block(-3,0,-8,IRON_TRAPDOOR:2)
Block(-3,0,-7,IRON_TRAPDOOR:2)
Block(-3,0,-6,IRON_TRAPDOOR:2)
Block(-3,0,-5,CONCRETE:8)
Block(-3,0,-1,CONCRETE:8)
Block(-3,0,2,PRISMARINE:2)
Block(-3,0,3,PRISMARINE:2)
Block(-3,0,4,PRISMARINE:2)
Block(-3,0,5,PRISMARINE:2)
Block(-3,0,6,PRISMARINE:2)
Block(-3,0,7,PRISMARINE:2)
Block(-3,0,8,PRISMARINE:2)
Block(-3,0,9,PRISMARINE:2)
Block(-3,0,10,PRISMARINE:2)
Block(-3,0,11,PRISMARINE:2)
Block(-3,0,14,CONCRETE:8)
Block(-3,1,-15,STAINED_GLASS)
Block(-3,1,-5,STAINED_GLASS)
Block(-3,1,-1,CONCRETE:8)
Block(-3,1,14,CONCRETE:8)
Block(-3,2,-15,STAINED_GLASS)
Block(-3,2,-5,STAINED_GLASS)
Block(-3,2,-1,STAINED_GLASS)
Block(-3,2,14,STAINED_GLASS)
Block(-3,3,-15,CONCRETE)
Block(-3,3,-5,CONCRETE)
Block(-3,3,0,STAINED_GLASS)
Block(-3,3,13,STAINED_GLASS)
Block(-3,4,-15,CONCRETE)
Block(-3,4,-5,CONCRETE)
Block(-3,4,1,STAINED_GLASS)
Block(-3,4,12,STAINED_GLASS)
Block(-3,5,-15,CONCRETE)
Block(-3,5,-5,CONCRETE)
Block(-3,5,2,STAINED_GLASS)
Block(-3,5,3,STAINED_GLASS)
Block(-3,5,4,STAINED_GLASS)
Block(-3,5,9,STAINED_GLASS)
Block(-3,5,10,STAINED_GLASS)
Block(-3,5,11,STAINED_GLASS)
Block(-3,6,-15,CONCRETE)
Block(-3,6,-5,CONCRETE)
Block(-3,6,4,CONCRETE)
Block(-3,6,5,STAINED_GLASS)
Block(-3,6,6,STAINED_GLASS)
Block(-3,6,7,STAINED_GLASS)
Block(-3,6,8,STAINED_GLASS)
Block(-3,6,9,CONCRETE)
Block(-3,7,-14,CONCRETE)
Block(-3,7,-6,CONCRETE)
Block(-3,8,-14,CONCRETE)
Block(-3,8,-6,CONCRETE)
Block(-3,9,-13,CONCRETE)
Block(-3,9,-7,CONCRETE)
Block(-3,10,-12,CONCRETE:8)
Block(-3,10,-11,CONCRETE:8)
Block(-3,10,-10,CONCRETE:8)
Block(-3,10,-9,CONCRETE:8)
Block(-3,10,-8,CONCRETE:8)
Block(-2,-1,-16,CONCRETE)
Block(-2,-1,-15,CONCRETE)
Block(-2,-1,-14,CONCRETE)
Block(-2,-1,-13,CONCRETE)
Block(-2,-1,-12,CONCRETE)
Block(-2,-1,-11,CONCRETE)
Block(-2,-1,-10,CONCRETE)
Block(-2,-1,-9,CONCRETE)
Block(-2,-1,-8,CONCRETE)
Block(-2,-1,-7,CONCRETE)
Block(-2,-1,-6,CONCRETE)
Block(-2,-1,-5,CONCRETE)
Block(-2,-1,-4,CONCRETE)
Block(-2,-1,-3,CONCRETE)
Block(-2,-1,-2,CONCRETE)
Block(-2,-1,-1,CONCRETE)
Block(-2,-1,0,CONCRETE)
Block(-2,-1,1,CONCRETE)
Block(-2,-1,2,CONCRETE)
Block(-2,-1,3,CONCRETE)
Block(-2,-1,4,CONCRETE)
Block(-2,-1,5,CONCRETE)
Block(-2,-1,6,CONCRETE)
Block(-2,-1,7,CONCRETE)
Block(-2,-1,8,CONCRETE)
Block(-2,-1,9,CONCRETE)
Block(-2,-1,10,CONCRETE)
Block(-2,-1,11,CONCRETE)
Block(-2,-1,12,CONCRETE)
Block(-2,-1,13,CONCRETE)
Block(-2,-1,14,CONCRETE)
Block(-2,-1,15,CONCRETE)
Block(-2,0,-15,CONCRETE:8)
Block(-2,0,-14,IRON_TRAPDOOR:2)
Block(-2,0,-13,IRON_TRAPDOOR:2)
Block(-2,0,-12,IRON_TRAPDOOR:2)
Block(-2,0,-11,IRON_TRAPDOOR:2)
Block(-2,0,-10,IRON_TRAPDOOR:2)
Block(-2,0,-9,IRON_TRAPDOOR:2)
Block(-2,0,-8,IRON_TRAPDOOR:2)
Block(-2,0,-7,IRON_TRAPDOOR:2)
Block(-2,0,-6,IRON_TRAPDOOR:2)
Block(-2,0,-5,IRON_TRAPDOOR:2)
Block(-2,0,-4,CONCRETE)
Block(-2,0,-3,STAINED_GLASS)
Block(-2,0,-2,CONCRETE)
Block(-2,0,-1,CONCRETE:8)
Block(-2,0,13,CONCRETE)
Block(-2,0,14,CONCRETE:8)
Block(-2,0,15,CONCRETE)
Block(-2,1,-15,CONCRETE)
Block(-2,1,-4,CONCRETE)
Block(-2,1,-3,STAINED_GLASS)
Block(-2,1,-2,CONCRETE)
Block(-2,1,-1,CONCRETE:8)
Block(-2,1,13,CONCRETE)
Block(-2,1,14,CONCRETE:8)
Block(-2,1,15,CONCRETE)
Block(-2,2,-15,CONCRETE)
Block(-2,2,-4,CONCRETE)
Block(-2,2,-3,STAINED_GLASS)
Block(-2,2,-2,CONCRETE)
Block(-2,2,-1,STAINED_GLASS)
Block(-2,2,13,CONCRETE)
Block(-2,2,14,STAINED_GLASS)
Block(-2,2,15,CONCRETE)
Block(-2,3,-15,CONCRETE)
Block(-2,3,-5,IRON_TRAPDOOR:8)
Block(-2,3,-4,CONCRETE)
Block(-2,3,-3,STAINED_GLASS)
Block(-2,3,-2,CONCRETE)
Block(-2,3,-1,STAINED_GLASS)
Block(-2,3,13,CONCRETE)
Block(-2,3,14,STAINED_GLASS)
Block(-2,3,15,CONCRETE)
Block(-2,4,-15,CONCRETE)
Block(-2,4,-5,CONCRETE)
Block(-2,4,-1,CONCRETE)
Block(-2,4,0,STAINED_GLASS)
Block(-2,4,13,STAINED_GLASS)
Block(-2,4,14,CONCRETE)
Block(-2,5,-15,CONCRETE)
Block(-2,5,-5,CONCRETE)
Block(-2,5,0,CONCRETE)
Block(-2,5,1,STAINED_GLASS)
Block(-2,5,2,STAINED_GLASS)
Block(-2,5,3,STAINED_GLASS)
Block(-2,5,10,STAINED_GLASS)
Block(-2,5,11,STAINED_GLASS)
Block(-2,5,12,STAINED_GLASS)
Block(-2,5,13,CONCRETE)
Block(-2,6,-15,CONCRETE)
Block(-2,6,-5,CONCRETE)
Block(-2,6,1,CONCRETE)
Block(-2,6,2,CONCRETE)
Block(-2,6,3,CONCRETE)
Block(-2,6,4,STAINED_GLASS)
Block(-2,6,5,STAINED_GLASS)
Block(-2,6,6,STAINED_GLASS)
Block(-2,6,7,STAINED_GLASS)
Block(-2,6,8,STAINED_GLASS)
Block(-2,6,9,STAINED_GLASS)
Block(-2,6,10,CONCRETE)
Block(-2,6,11,CONCRETE)
Block(-2,6,12,CONCRETE)
Block(-2,7,-15,CONCRETE)
Block(-2,7,-5,CONCRETE)
Block(-2,7,4,CONCRETE)
Block(-2,7,5,CONCRETE)
Block(-2,7,6,CONCRETE)
Block(-2,7,7,CONCRETE)
Block(-2,7,8,CONCRETE)
Block(-2,7,9,CONCRETE)
Block(-2,8,-14,CONCRETE)
Block(-2,8,-6,CONCRETE)
Block(-2,9,-14,CONCRETE)
Block(-2,9,-6,CONCRETE)
Block(-2,10,-13,CONCRETE:8)
Block(-2,10,-12,CONCRETE:8)
Block(-2,10,-8,CONCRETE:8)
Block(-2,10,-7,CONCRETE:8)
Block(-2,11,-11,STAINED_GLASS)
Block(-2,11,-10,STAINED_GLASS)
Block(-2,11,-9,STAINED_GLASS)
Block(-1,-1,-16,CONCRETE)
Block(-1,-1,-15,CONCRETE)
Block(-1,-1,-14,CONCRETE)
Block(-1,-1,-13,CONCRETE)
Block(-1,-1,-12,CONCRETE)
Block(-1,-1,-11,CONCRETE)
Block(-1,-1,-10,CONCRETE)
Block(-1,-1,-9,CONCRETE)
Block(-1,-1,-8,CONCRETE)
Block(-1,-1,-7,CONCRETE)
Block(-1,-1,-6,CONCRETE)
Block(-1,-1,-5,CONCRETE)
Block(-1,-1,-4,CONCRETE)
Block(-1,-1,-3,CONCRETE)
Block(-1,-1,-2,CONCRETE)
Block(-1,-1,-1,CONCRETE)
Block(-1,-1,0,CONCRETE)
Block(-1,-1,1,CONCRETE)
Block(-1,-1,2,CONCRETE)
Block(-1,-1,3,CONCRETE)
Block(-1,-1,4,CONCRETE)
Block(-1,-1,5,CONCRETE)
Block(-1,-1,6,CONCRETE)
Block(-1,-1,7,CONCRETE)
Block(-1,-1,8,CONCRETE)
Block(-1,-1,9,CONCRETE)
Block(-1,-1,10,CONCRETE)
Block(-1,-1,11,CONCRETE)
Block(-1,-1,12,CONCRETE)
Block(-1,-1,13,CONCRETE)
Block(-1,-1,14,CONCRETE)
Block(-1,-1,15,CONCRETE)
Block(-1,0,-16,CONCRETE:8)
Block(-1,0,-15,CARPET)
Block(-1,0,-14,QUARTZ_STAIRS:0)
Block(-1,0,-13,IRON_TRAPDOOR:2)
Block(-1,0,-12,IRON_TRAPDOOR:2)
Block(-1,0,-11,IRON_TRAPDOOR:2)
Block(-1,0,-10,IRON_TRAPDOOR:2)
Block(-1,0,-9,IRON_TRAPDOOR:2)
Block(-1,0,-8,IRON_TRAPDOOR:2)
Block(-1,0,-7,IRON_TRAPDOOR:2)
Block(-1,0,-6,IRON_TRAPDOOR:2)
Block(-1,0,-5,IRON_TRAPDOOR:2)
Block(-1,0,-4,STAINED_GLASS)
Block(-1,0,-1,STAINED_GLASS)
Block(-1,0,0,IRON_TRAPDOOR)
Block(-1,0,1,IRON_TRAPDOOR)
Block(-1,0,2,IRON_TRAPDOOR)
Block(-1,0,3,IRON_TRAPDOOR)
Block(-1,0,4,IRON_TRAPDOOR)
Block(-1,0,5,IRON_TRAPDOOR)
Block(-1,0,6,IRON_TRAPDOOR)
Block(-1,0,7,IRON_TRAPDOOR)
Block(-1,0,8,IRON_TRAPDOOR)
Block(-1,0,9,IRON_TRAPDOOR)
Block(-1,0,10,IRON_TRAPDOOR)
Block(-1,0,13,STEP:15)
Block(-1,0,14,CONCRETE:8)
Block(-1,1,-16,CONCRETE)
Block(-1,1,-15,IRON_TRAPDOOR:5)
Block(-1,1,-4,STAINED_GLASS)
Block(-1,1,-1,STAINED_GLASS)
Block(-1,1,13,CHEST,NetherVillagerPodA/1-chest.nbt)
Block(-1,1,14,STAINED_GLASS)
Block(-1,2,-16,CONCRETE)
Block(-1,2,-15,LEVER:9)
Block(-1,2,-4,STAINED_GLASS)
Block(-1,2,-1,STAINED_GLASS)
Block(-1,2,13,STEP:15)
Block(-1,2,14,STAINED_GLASS)
Block(-1,3,-16,CONCRETE)
Block(-1,3,-15,STEP:15)
Block(-1,3,-5,IRON_TRAPDOOR:8)
Block(-1,3,-4,STAINED_GLASS)
Block(-1,3,-1,STAINED_GLASS)
Block(-1,3,13,FLOWER_POT,NetherVillagerPodA/2-flower_pot.nbt)
Block(-1,3,14,STAINED_GLASS)
Block(-1,4,-16,CONCRETE)
Block(-1,4,-4,CONCRETE)
Block(-1,4,-3,STAINED_GLASS)
Block(-1,4,-2,CONCRETE)
Block(-1,4,-1,STAINED_GLASS)
Block(-1,4,14,STAINED_GLASS)
Block(-1,5,-16,CONCRETE)
Block(-1,5,-4,CONCRETE)
Block(-1,5,0,STAINED_GLASS)
Block(-1,5,1,STAINED_GLASS)
Block(-1,5,12,STAINED_GLASS)
Block(-1,5,13,STAINED_GLASS)
Block(-1,6,-15,CONCRETE)
Block(-1,6,-5,CONCRETE)
Block(-1,6,2,STAINED_GLASS)
Block(-1,6,3,STAINED_GLASS)
Block(-1,6,4,STAINED_GLASS)
Block(-1,6,5,STAINED_GLASS)
Block(-1,6,6,STAINED_GLASS)
Block(-1,6,7,STAINED_GLASS)
Block(-1,6,8,STAINED_GLASS)
Block(-1,6,9,STAINED_GLASS)
Block(-1,6,10,STAINED_GLASS)
Block(-1,6,11,STAINED_GLASS)
Block(-1,7,-15,CONCRETE)
Block(-1,7,-5,CONCRETE)
Block(-1,7,4,CONCRETE)
Block(-1,7,9,CONCRETE)
Block(-1,8,-15,CONCRETE)
Block(-1,8,-5,CONCRETE)
Block(-1,9,-14,CONCRETE)
Block(-1,9,-6,CONCRETE)
Block(-1,10,-13,CONCRETE:8)
Block(-1,10,-7,CONCRETE:8)
Block(-1,11,-12,STAINED_GLASS)
Block(-1,11,-11,STAINED_GLASS)
Block(-1,11,-10,STAINED_GLASS)
Block(-1,11,-9,STAINED_GLASS)
Block(-1,11,-8,STAINED_GLASS)
Block(0,-1,-16,CONCRETE)
Block(0,-1,-15,CONCRETE)
Block(0,-1,-14,CONCRETE)
Block(0,-1,-13,CONCRETE)
Block(0,-1,-12,CONCRETE)
Block(0,-1,-11,CONCRETE)
Block(0,-1,-10,CONCRETE)
Block(0,-1,-9,CONCRETE)
Block(0,-1,-8,CONCRETE)
Block(0,-1,-7,CONCRETE)
Block(0,-1,-6,CONCRETE)
Block(0,-1,-5,CONCRETE)
Block(0,-1,-4,CONCRETE)
Block(0,-1,-3,CONCRETE)
Block(0,-1,-2,CONCRETE)
Block(0,-1,-1,CONCRETE)
Block(0,-1,0,CONCRETE)
Block(0,-1,1,CONCRETE)
Block(0,-1,2,CONCRETE)
Block(0,-1,3,CONCRETE)
Block(0,-1,4,CONCRETE)
Block(0,-1,5,CONCRETE)
Block(0,-1,6,CONCRETE)
Block(0,-1,7,CONCRETE)
Block(0,-1,8,CONCRETE)
Block(0,-1,9,CONCRETE)
Block(0,-1,10,CONCRETE)
Block(0,-1,11,CONCRETE)
Block(0,-1,12,CONCRETE)
Block(0,-1,13,CONCRETE)
Block(0,-1,14,CONCRETE)
Block(0,-1,15,CONCRETE)
Block(0,0,-16,CONCRETE:8)
Block(0,0,-15,CARPET:8)
Block(0,0,-14,QUARTZ_STAIRS:0)
Block(0,0,-13,IRON_TRAPDOOR:2)
Block(0,0,-12,IRON_TRAPDOOR:2)
Block(0,0,-11,IRON_TRAPDOOR:2)
Block(0,0,-10,IRON_TRAPDOOR:2)
Block(0,0,-9,IRON_TRAPDOOR:2)
Block(0,0,-8,IRON_TRAPDOOR:2)
Block(0,0,-7,IRON_TRAPDOOR:2)
Block(0,0,-6,IRON_TRAPDOOR:2)
Block(0,0,-5,IRON_TRAPDOOR:2)
Block(0,0,-4,IRON_DOOR_BLOCK)
Block(0,0,-3,IRON_TRAPDOOR)
Block(0,0,-2,IRON_TRAPDOOR)
Block(0,0,-1,IRON_DOOR_BLOCK:1)
Block(0,0,0,IRON_TRAPDOOR)
Block(0,0,1,IRON_TRAPDOOR)
Block(0,0,2,IRON_TRAPDOOR)
Block(0,0,3,IRON_TRAPDOOR)
Block(0,0,4,IRON_TRAPDOOR)
Block(0,0,5,IRON_TRAPDOOR)
Block(0,0,6,IRON_TRAPDOOR)
Block(0,0,7,IRON_TRAPDOOR)
Block(0,0,8,IRON_TRAPDOOR)
Block(0,0,9,IRON_TRAPDOOR)
Block(0,0,10,IRON_TRAPDOOR)
Block(0,0,13,STEP:15)
Block(0,0,14,CONCRETE:8)
Block(0,1,-16,CONCRETE)
Block(0,1,-15,IRON_TRAPDOOR:1)
Block(0,1,-4,IRON_DOOR_BLOCK:9)
Block(0,1,-1,IRON_DOOR_BLOCK:8)
Block(0,1,13,FLOWER_POT,NetherVillagerPodA/3-flower_pot.nbt)
Block(0,1,14,STAINED_GLASS)
Block(0,2,-16,CONCRETE)
Block(0,2,-5,STONE_BUTTON)
Block(0,2,-4,CONCRETE)
Block(0,2,-3,STONE_BUTTON:3)
Block(0,2,-2,STONE_BUTTON)
Block(0,2,-1,CONCRETE)
Block(0,2,0,STONE_BUTTON:3)
Block(0,2,13,STEP:15)
Block(0,2,14,STAINED_GLASS)
Block(0,3,-16,CONCRETE)
Block(0,3,-15,IRON_TRAPDOOR:9)
Block(0,3,-5,IRON_TRAPDOOR:8)
Block(0,3,-4,STAINED_GLASS)
Block(0,3,-1,STAINED_GLASS)
Block(0,3,14,STAINED_GLASS)
Block(0,4,-16,CONCRETE:13)
Block(0,4,-4,CONCRETE)
Block(0,4,-3,STAINED_GLASS)
Block(0,4,-2,CONCRETE)
Block(0,4,-1,STAINED_GLASS)
Block(0,4,14,STAINED_GLASS)
Block(0,5,-16,CONCRETE:5)
Block(0,5,-4,CONCRETE)
Block(0,5,0,STAINED_GLASS)
Block(0,5,1,STAINED_GLASS)
Block(0,5,12,STAINED_GLASS)
Block(0,5,13,STAINED_GLASS)
Block(0,6,-16,CONCRETE)
Block(0,6,-15,END_ROD:5)
Block(0,6,-5,END_ROD:4)
Block(0,6,-4,CONCRETE)
Block(0,6,2,STAINED_GLASS)
Block(0,6,3,STAINED_GLASS)
Block(0,6,4,STAINED_GLASS)
Block(0,6,5,STAINED_GLASS)
Block(0,6,6,STAINED_GLASS)
Block(0,6,7,STAINED_GLASS)
Block(0,6,8,STAINED_GLASS)
Block(0,6,9,STAINED_GLASS)
Block(0,6,10,STAINED_GLASS)
Block(0,6,11,STAINED_GLASS)
Block(0,7,-15,CONCRETE)
Block(0,7,-5,CONCRETE)
Block(0,7,4,CONCRETE)
Block(0,7,9,CONCRETE)
Block(0,8,-15,CONCRETE)
Block(0,8,-5,CONCRETE)
Block(0,9,-14,CONCRETE)
Block(0,9,-6,CONCRETE)
Block(0,10,-13,CONCRETE:8)
Block(0,10,-7,CONCRETE:8)
Block(0,11,-12,STAINED_GLASS)
Block(0,11,-11,STAINED_GLASS)
Block(0,11,-10,STAINED_GLASS)
Block(0,11,-9,STAINED_GLASS)
Block(0,11,-8,STAINED_GLASS)
Block(1,-1,-16,CONCRETE)
Block(1,-1,-15,CONCRETE)
Block(1,-1,-14,CONCRETE)
Block(1,-1,-13,CONCRETE)
Block(1,-1,-12,CONCRETE)
Block(1,-1,-11,CONCRETE)
Block(1,-1,-10,CONCRETE)
Block(1,-1,-9,CONCRETE)
Block(1,-1,-8,CONCRETE)
Block(1,-1,-7,CONCRETE)
Block(1,-1,-6,CONCRETE)
Block(1,-1,-5,CONCRETE)
Block(1,-1,-4,CONCRETE)
Block(1,-1,-3,CONCRETE)
Block(1,-1,-2,CONCRETE)
Block(1,-1,-1,CONCRETE)
Block(1,-1,0,CONCRETE)
Block(1,-1,1,CONCRETE)
Block(1,-1,2,CONCRETE)
Block(1,-1,3,CONCRETE)
Block(1,-1,4,CONCRETE)
Block(1,-1,5,CONCRETE)
Block(1,-1,6,CONCRETE)
Block(1,-1,7,CONCRETE)
Block(1,-1,8,CONCRETE)
Block(1,-1,9,CONCRETE)
Block(1,-1,10,CONCRETE)
Block(1,-1,11,CONCRETE)
Block(1,-1,12,CONCRETE)
Block(1,-1,13,CONCRETE)
Block(1,-1,14,CONCRETE)
Block(1,-1,15,CONCRETE)
Block(1,0,-16,CONCRETE:8)
Block(1,0,-15,CARPET:8)
Block(1,0,-14,QUARTZ_STAIRS:0)
Block(1,0,-13,IRON_TRAPDOOR:2)
Block(1,0,-12,IRON_TRAPDOOR:2)
Block(1,0,-11,IRON_TRAPDOOR:2)
Block(1,0,-10,IRON_TRAPDOOR:2)
Block(1,0,-9,IRON_TRAPDOOR:2)
Block(1,0,-8,IRON_TRAPDOOR:2)
Block(1,0,-7,IRON_TRAPDOOR:2)
Block(1,0,-6,IRON_TRAPDOOR:2)
Block(1,0,-5,IRON_TRAPDOOR:2)
Block(1,0,-4,STAINED_GLASS)
Block(1,0,-1,STAINED_GLASS)
Block(1,0,0,IRON_TRAPDOOR:2)
Block(1,0,1,IRON_TRAPDOOR)
Block(1,0,2,IRON_TRAPDOOR)
Block(1,0,3,IRON_TRAPDOOR)
Block(1,0,4,IRON_TRAPDOOR)
Block(1,0,5,IRON_TRAPDOOR)
Block(1,0,6,IRON_TRAPDOOR)
Block(1,0,7,IRON_TRAPDOOR)
Block(1,0,8,IRON_TRAPDOOR)
Block(1,0,9,IRON_TRAPDOOR)
Block(1,0,10,IRON_TRAPDOOR)
Block(1,0,13,STEP:15)
Block(1,0,14,CONCRETE:8)
Block(1,1,-16,CONCRETE)
Block(1,1,-15,IRON_TRAPDOOR:1)
Block(1,1,-4,STAINED_GLASS)
Block(1,1,-1,STAINED_GLASS)
Block(1,1,13,FLOWER_POT,NetherVillagerPodA/4-flower_pot.nbt)
Block(1,1,14,STAINED_GLASS)
Block(1,2,-16,CONCRETE)
Block(1,2,-4,STAINED_GLASS)
Block(1,2,-1,STAINED_GLASS)
Block(1,2,13,STEP:15)
Block(1,2,14,STAINED_GLASS)
Block(1,3,-16,CONCRETE)
Block(1,3,-15,IRON_TRAPDOOR:9)
Block(1,3,-5,IRON_TRAPDOOR:8)
Block(1,3,-4,STAINED_GLASS)
Block(1,3,-1,STAINED_GLASS)
Block(1,3,13,FLOWER_POT,NetherVillagerPodA/5-flower_pot.nbt)
Block(1,3,14,STAINED_GLASS)
Block(1,4,-16,CONCRETE)
Block(1,4,-15,CHEST:3,NetherVillagerPodA/6-chest.nbt)
Block(1,4,-4,CONCRETE)
Block(1,4,-3,STAINED_GLASS)
Block(1,4,-2,CONCRETE)
Block(1,4,-1,STAINED_GLASS)
Block(1,4,14,STAINED_GLASS)
Block(1,5,-16,CONCRETE)
Block(1,5,-4,CONCRETE)
Block(1,5,0,STAINED_GLASS)
Block(1,5,1,STAINED_GLASS)
Block(1,5,12,STAINED_GLASS)
Block(1,5,13,STAINED_GLASS)
Block(1,6,-15,CONCRETE)
Block(1,6,-5,CONCRETE)
Block(1,6,2,STAINED_GLASS)
Block(1,6,3,STAINED_GLASS)
Block(1,6,4,STAINED_GLASS)
Block(1,6,5,STAINED_GLASS)
Block(1,6,6,STAINED_GLASS)
Block(1,6,7,STAINED_GLASS)
Block(1,6,8,STAINED_GLASS)
Block(1,6,9,STAINED_GLASS)
Block(1,6,10,STAINED_GLASS)
Block(1,6,11,STAINED_GLASS)
Block(1,7,-15,CONCRETE)
Block(1,7,-5,CONCRETE)
Block(1,7,4,CONCRETE)
Block(1,7,9,CONCRETE)
Block(1,8,-15,CONCRETE)
Block(1,8,-5,CONCRETE)
Block(1,9,-14,CONCRETE)
Block(1,9,-6,CONCRETE)
Block(1,10,-13,CONCRETE:8)
Block(1,10,-7,CONCRETE:8)
Block(1,11,-12,STAINED_GLASS)
Block(1,11,-11,STAINED_GLASS)
Block(1,11,-10,STAINED_GLASS)
Block(1,11,-9,STAINED_GLASS)
Block(1,11,-8,STAINED_GLASS)
Block(2,-1,-16,CONCRETE)
Block(2,-1,-15,CONCRETE)
Block(2,-1,-14,CONCRETE)
Block(2,-1,-13,CONCRETE)
Block(2,-1,-12,CONCRETE)
Block(2,-1,-11,CONCRETE)
Block(2,-1,-10,CONCRETE)
Block(2,-1,-9,CONCRETE)
Block(2,-1,-8,CONCRETE)
Block(2,-1,-7,CONCRETE)
Block(2,-1,-6,CONCRETE)
Block(2,-1,-5,CONCRETE)
Block(2,-1,-4,CONCRETE)
Block(2,-1,-3,CONCRETE)
Block(2,-1,-2,CONCRETE)
Block(2,-1,-1,CONCRETE)
Block(2,-1,0,CONCRETE)
Block(2,-1,1,CONCRETE)
Block(2,-1,2,CONCRETE)
Block(2,-1,3,CONCRETE)
Block(2,-1,4,CONCRETE)
Block(2,-1,5,CONCRETE)
Block(2,-1,6,CONCRETE)
Block(2,-1,7,CONCRETE)
Block(2,-1,8,CONCRETE)
Block(2,-1,9,CONCRETE)
Block(2,-1,10,CONCRETE)
Block(2,-1,11,CONCRETE)
Block(2,-1,12,CONCRETE)
Block(2,-1,13,CONCRETE)
Block(2,-1,14,CONCRETE)
Block(2,-1,15,CONCRETE)
Block(2,0,-15,CONCRETE:8)
Block(2,0,-14,IRON_TRAPDOOR:2)
Block(2,0,-13,IRON_TRAPDOOR:2)
Block(2,0,-12,IRON_TRAPDOOR:2)
Block(2,0,-11,IRON_TRAPDOOR:2)
Block(2,0,-10,IRON_TRAPDOOR:2)
Block(2,0,-9,IRON_TRAPDOOR:2)
Block(2,0,-8,IRON_TRAPDOOR:2)
Block(2,0,-7,IRON_TRAPDOOR:2)
Block(2,0,-6,IRON_TRAPDOOR:2)
Block(2,0,-5,IRON_TRAPDOOR:2)
Block(2,0,-4,CONCRETE)
Block(2,0,-3,STAINED_GLASS)
Block(2,0,-2,CONCRETE)
Block(2,0,-1,CONCRETE:8)
Block(2,0,13,CONCRETE)
Block(2,0,14,CONCRETE:8)
Block(2,0,15,CONCRETE)
Block(2,1,-15,CONCRETE)
Block(2,1,-14,STONE_BUTTON:3)
Block(2,1,-4,CONCRETE)
Block(2,1,-3,STAINED_GLASS)
Block(2,1,-2,CONCRETE)
Block(2,1,-1,CONCRETE:8)
Block(2,1,13,CONCRETE)
Block(2,1,14,CONCRETE:8)
Block(2,1,15,CONCRETE)
Block(2,2,-15,CONCRETE)
Block(2,2,-4,CONCRETE)
Block(2,2,-3,STAINED_GLASS)
Block(2,2,-2,CONCRETE)
Block(2,2,-1,STAINED_GLASS)
Block(2,2,13,CONCRETE)
Block(2,2,14,STAINED_GLASS)
Block(2,2,15,CONCRETE)
Block(2,3,-15,CONCRETE)
Block(2,3,-5,IRON_TRAPDOOR:8)
Block(2,3,-4,CONCRETE)
Block(2,3,-3,STAINED_GLASS)
Block(2,3,-2,CONCRETE)
Block(2,3,-1,STAINED_GLASS)
Block(2,3,13,CONCRETE)
Block(2,3,14,STAINED_GLASS)
Block(2,3,15,CONCRETE)
Block(2,4,-15,CONCRETE)
Block(2,4,-5,CONCRETE)
Block(2,4,-1,CONCRETE)
Block(2,4,0,STAINED_GLASS)
Block(2,4,13,STAINED_GLASS)
Block(2,4,14,CONCRETE)
Block(2,5,-15,CONCRETE)
Block(2,5,-5,CONCRETE)
Block(2,5,0,CONCRETE)
Block(2,5,1,STAINED_GLASS)
Block(2,5,2,STAINED_GLASS)
Block(2,5,3,STAINED_GLASS)
Block(2,5,10,STAINED_GLASS)
Block(2,5,11,STAINED_GLASS)
Block(2,5,12,STAINED_GLASS)
Block(2,5,13,CONCRETE)
Block(2,6,-15,CONCRETE)
Block(2,6,-5,CONCRETE)
Block(2,6,1,CONCRETE)
Block(2,6,2,CONCRETE)
Block(2,6,3,CONCRETE)
Block(2,6,4,STAINED_GLASS)
Block(2,6,5,STAINED_GLASS)
Block(2,6,6,STAINED_GLASS)
Block(2,6,7,STAINED_GLASS)
Block(2,6,8,STAINED_GLASS)
Block(2,6,9,STAINED_GLASS)
Block(2,6,10,CONCRETE)
Block(2,6,11,CONCRETE)
Block(2,6,12,CONCRETE)
Block(2,7,-15,CONCRETE)
Block(2,7,-5,CONCRETE)
Block(2,7,4,CONCRETE)
Block(2,7,5,CONCRETE)
Block(2,7,6,CONCRETE)
Block(2,7,7,CONCRETE)
Block(2,7,8,CONCRETE)
Block(2,7,9,CONCRETE)
Block(2,8,-14,CONCRETE)
Block(2,8,-6,CONCRETE)
Block(2,9,-14,CONCRETE)
Block(2,9,-6,CONCRETE)
Block(2,10,-13,CONCRETE:8)
Block(2,10,-12,CONCRETE:8)
Block(2,10,-8,CONCRETE:8)
Block(2,10,-7,CONCRETE:8)
Block(2,11,-11,STAINED_GLASS)
Block(2,11,-10,STAINED_GLASS)
Block(2,11,-9,STAINED_GLASS)
Block(3,-1,-16,CONCRETE)
Block(3,-1,-15,CONCRETE)
Block(3,-1,-14,CONCRETE)
Block(3,-1,-13,CONCRETE)
Block(3,-1,-12,CONCRETE)
Block(3,-1,-11,CONCRETE)
Block(3,-1,-10,CONCRETE)
Block(3,-1,-9,CONCRETE)
Block(3,-1,-8,CONCRETE)
Block(3,-1,-7,CONCRETE)
Block(3,-1,-6,CONCRETE)
Block(3,-1,-5,CONCRETE)
Block(3,-1,-4,CONCRETE)
Block(3,-1,-3,CONCRETE)
Block(3,-1,-2,CONCRETE)
Block(3,-1,-1,CONCRETE)
Block(3,-1,0,CONCRETE)
Block(3,-1,1,CONCRETE)
Block(3,-1,2,CONCRETE)
Block(3,-1,3,CONCRETE)
Block(3,-1,4,CONCRETE)
Block(3,-1,5,CONCRETE)
Block(3,-1,6,CONCRETE)
Block(3,-1,7,CONCRETE)
Block(3,-1,8,CONCRETE)
Block(3,-1,9,CONCRETE)
Block(3,-1,10,CONCRETE)
Block(3,-1,11,CONCRETE)
Block(3,-1,12,CONCRETE)
Block(3,-1,13,CONCRETE)
Block(3,-1,14,CONCRETE)
Block(3,-1,15,CONCRETE)
Block(3,0,-15,CONCRETE:12)
Block(3,0,-14,CAULDRON:1)
Block(3,0,-13,IRON_TRAPDOOR:2)
Block(3,0,-12,IRON_TRAPDOOR:2)
Block(3,0,-11,QUARTZ_STAIRS:1)
Block(3,0,-10,IRON_TRAPDOOR:2)
Block(3,0,-9,IRON_TRAPDOOR:2)
Block(3,0,-8,IRON_TRAPDOOR:2)
Block(3,0,-7,IRON_TRAPDOOR:2)
Block(3,0,-6,IRON_TRAPDOOR:2)
Block(3,0,-5,CONCRETE:8)
Block(3,0,-1,CONCRETE:8)
Block(3,0,2,PRISMARINE:2)
Block(3,0,3,PRISMARINE:2)
Block(3,0,4,PRISMARINE:2)
Block(3,0,5,PRISMARINE:2)
Block(3,0,6,PRISMARINE:2)
Block(3,0,7,PRISMARINE:2)
Block(3,0,8,PRISMARINE:2)
Block(3,0,9,PRISMARINE:2)
Block(3,0,10,PRISMARINE:2)
Block(3,0,11,PRISMARINE:2)
Block(3,0,14,CONCRETE:8)
Block(3,1,-15,STAINED_GLASS)
Block(3,1,-14,IRON_TRAPDOOR:1)
Block(3,1,-5,STAINED_GLASS)
Block(3,1,-1,CONCRETE:8)
Block(3,1,14,CONCRETE:8)
Block(3,2,-15,STAINED_GLASS)
Block(3,2,-5,STAINED_GLASS)
Block(3,2,-1,STAINED_GLASS)
Block(3,2,14,STAINED_GLASS)
Block(3,3,-15,CONCRETE)
Block(3,3,-5,CONCRETE)
Block(3,3,0,STAINED_GLASS)
Block(3,3,13,STAINED_GLASS)
Block(3,4,-15,CONCRETE)
Block(3,4,-5,CONCRETE)
Block(3,4,1,STAINED_GLASS)
Block(3,4,12,STAINED_GLASS)
Block(3,5,-15,CONCRETE)
Block(3,5,-5,CONCRETE)
Block(3,5,2,STAINED_GLASS)
Block(3,5,3,STAINED_GLASS)
Block(3,5,4,STAINED_GLASS)
Block(3,5,9,STAINED_GLASS)
Block(3,5,10,STAINED_GLASS)
Block(3,5,11,STAINED_GLASS)
Block(3,6,-15,CONCRETE)
Block(3,6,-5,CONCRETE)
Block(3,6,4,CONCRETE)
Block(3,6,5,STAINED_GLASS)
Block(3,6,6,STAINED_GLASS)
Block(3,6,7,STAINED_GLASS)
Block(3,6,8,STAINED_GLASS)
Block(3,6,9,CONCRETE)
Block(3,7,-14,CONCRETE)
Block(3,7,-6,CONCRETE)
Block(3,8,-14,CONCRETE)
Block(3,8,-6,CONCRETE)
Block(3,9,-13,CONCRETE)
Block(3,9,-7,CONCRETE)
Block(3,10,-12,CONCRETE:8)
Block(3,10,-11,CONCRETE:8)
Block(3,10,-10,CONCRETE:8)
Block(3,10,-9,CONCRETE:8)
Block(3,10,-8,CONCRETE:8)
Block(4,-1,-16,CONCRETE)
Block(4,-1,-15,CONCRETE)
Block(4,-1,-14,CONCRETE)
Block(4,-1,-13,CONCRETE)
Block(4,-1,-12,CONCRETE)
Block(4,-1,-11,CONCRETE)
Block(4,-1,-10,CONCRETE)
Block(4,-1,-9,CONCRETE)
Block(4,-1,-8,CONCRETE)
Block(4,-1,-7,CONCRETE)
Block(4,-1,-6,CONCRETE)
Block(4,-1,-5,CONCRETE)
Block(4,-1,-4,CONCRETE)
Block(4,-1,-2,CONCRETE)
Block(4,-1,-1,CONCRETE)
Block(4,-1,0,CONCRETE)
Block(4,-1,1,CONCRETE)
Block(4,-1,2,CONCRETE)
Block(4,-1,3,CONCRETE)
Block(4,-1,4,CONCRETE)
Block(4,-1,5,CONCRETE)
Block(4,-1,6,CONCRETE)
Block(4,-1,7,CONCRETE)
Block(4,-1,8,CONCRETE)
Block(4,-1,9,CONCRETE)
Block(4,-1,10,CONCRETE)
Block(4,-1,11,CONCRETE)
Block(4,-1,12,CONCRETE)
Block(4,-1,13,CONCRETE)
Block(4,-1,14,CONCRETE)
Block(4,-1,15,CONCRETE)
Block(4,0,-15,CONCRETE:12)
Block(4,0,-14,CONCRETE:8)
Block(4,0,-13,STEP:15)
Block(4,0,-12,STEP:15)
Block(4,0,-11,STEP:15)
Block(4,0,-10,STEP:15)
Block(4,0,-9,STEP:15)
Block(4,0,-8,STEP:15)
Block(4,0,-7,STEP:15)
Block(4,0,-6,CONCRETE:8)
Block(4,0,0,CONCRETE:8)
Block(4,0,2,PRISMARINE:2)
Block(4,0,3,STATIONARY_LAVA)
Block(4,0,4,SOIL:7)
Block(4,0,5,SOIL:7)
Block(4,0,6,SOIL:7)
Block(4,0,7,SOIL:7)
Block(4,0,8,SOIL:7)
Block(4,0,9,SOIL:7)
Block(4,0,10,STATIONARY_LAVA)
Block(4,0,11,PRISMARINE:2)
Block(4,0,13,CONCRETE:8)
Block(4,1,-14,STAINED_GLASS)
Block(4,1,-6,STAINED_GLASS)
Block(4,1,0,CONCRETE:8)
Block(4,1,3,IRON_TRAPDOOR:2)
Block(4,1,4,POTATO:7)
Block(4,1,5,POTATO:7)
Block(4,1,6,POTATO:7)
Block(4,1,7,POTATO:7)
Block(4,1,8,POTATO:7)
Block(4,1,9,POTATO:7)
Block(4,1,10,IRON_TRAPDOOR:2)
Block(4,1,13,CONCRETE:8)
Block(4,2,-14,STAINED_GLASS)
Block(4,2,-6,STAINED_GLASS)
Block(4,2,0,STAINED_GLASS)
Block(4,2,2,QUARTZ_STAIRS:2)
Block(4,2,3,END_ROD:3)
Block(4,2,4,END_ROD:2)
Block(4,2,5,END_ROD:3)
Block(4,2,6,END_ROD:2)
Block(4,2,7,END_ROD:3)
Block(4,2,8,END_ROD:2)
Block(4,2,9,END_ROD:3)
Block(4,2,10,END_ROD:2)
Block(4,2,11,QUARTZ_STAIRS:0)
Block(4,2,13,STAINED_GLASS)
Block(4,3,-14,CONCRETE)
Block(4,3,-6,CONCRETE)
Block(4,3,1,STAINED_GLASS)
Block(4,3,2,QUARTZ_STAIRS:6)
Block(4,3,11,QUARTZ_STAIRS:7)
Block(4,3,12,STAINED_GLASS)
Block(4,4,-14,CONCRETE)
Block(4,4,-6,CONCRETE)
Block(4,4,2,STAINED_GLASS)
Block(4,4,3,STAINED_GLASS)
Block(4,4,4,STAINED_GLASS)
Block(4,4,9,STAINED_GLASS)
Block(4,4,10,STAINED_GLASS)
Block(4,4,11,STAINED_GLASS)
Block(4,5,-14,CONCRETE)
Block(4,5,-6,CONCRETE)
Block(4,5,4,CONCRETE)
Block(4,5,5,STAINED_GLASS)
Block(4,5,6,STAINED_GLASS)
Block(4,5,7,STAINED_GLASS)
Block(4,5,8,STAINED_GLASS)
Block(4,5,9,CONCRETE)
Block(4,6,-14,CONCRETE)
Block(4,6,-6,CONCRETE)
Block(4,7,-14,CONCRETE)
Block(4,7,-13,CONCRETE)
Block(4,7,-7,CONCRETE)
Block(4,7,-6,CONCRETE)
Block(4,8,-13,CONCRETE)
Block(4,8,-12,CONCRETE)
Block(4,8,-8,CONCRETE)
Block(4,8,-7,CONCRETE)
Block(4,9,-12,CONCRETE)
Block(4,9,-11,CONCRETE)
Block(4,9,-10,CONCRETE)
Block(4,9,-9,CONCRETE)
Block(4,9,-8,CONCRETE)
Block(5,-1,-16,CONCRETE)
Block(5,-1,-15,CONCRETE)
Block(5,-1,-14,CONCRETE)
Block(5,-1,-13,CONCRETE)
Block(5,-1,-12,CONCRETE)
Block(5,-1,-11,CONCRETE)
Block(5,-1,-10,CONCRETE)
Block(5,-1,-9,CONCRETE)
Block(5,-1,-8,CONCRETE)
Block(5,-1,-7,CONCRETE)
Block(5,-1,-6,CONCRETE)
Block(5,-1,-5,CONCRETE)
Block(5,-1,-1,CONCRETE)
Block(5,-1,0,CONCRETE)
Block(5,-1,1,CONCRETE)
Block(5,-1,2,CONCRETE)
Block(5,-1,3,CONCRETE)
Block(5,-1,4,CONCRETE)
Block(5,-1,5,CONCRETE)
Block(5,-1,6,CONCRETE)
Block(5,-1,7,CONCRETE)
Block(5,-1,8,CONCRETE)
Block(5,-1,9,CONCRETE)
Block(5,-1,10,CONCRETE)
Block(5,-1,11,CONCRETE)
Block(5,-1,12,CONCRETE)
Block(5,-1,13,CONCRETE)
Block(5,-1,14,CONCRETE)
Block(5,0,-15,CONCRETE:12)
Block(5,0,-13,CONCRETE:8)
Block(5,0,-12,CONCRETE:8)
Block(5,0,-11,SOUL_SAND)
Block(5,0,-10,STEP:15)
Block(5,0,-9,STEP:15)
Block(5,0,-8,CONCRETE:8)
Block(5,0,-7,CONCRETE:8)
Block(5,0,1,CONCRETE:8)
Block(5,0,2,CONCRETE:8)
Block(5,0,3,CONCRETE:8)
Block(5,0,4,CONCRETE:8)
Block(5,0,5,CONCRETE:8)
Block(5,0,6,CONCRETE:8)
Block(5,0,7,CONCRETE:8)
Block(5,0,8,CONCRETE:8)
Block(5,0,9,CONCRETE:8)
Block(5,0,10,CONCRETE:8)
Block(5,0,11,CONCRETE:8)
Block(5,0,12,CONCRETE:8)
Block(5,1,-13,STAINED_GLASS)
Block(5,1,-12,CONCRETE)
Block(5,1,-11,NETHER_WARTS)
Block(5,1,-8,CONCRETE)
Block(5,1,-7,STAINED_GLASS)
Block(5,1,1,CONCRETE:8)
Block(5,1,2,CONCRETE:8)
Block(5,1,3,STAINED_GLASS)
Block(5,1,4,STAINED_GLASS)
Block(5,1,5,STAINED_GLASS)
Block(5,1,6,STAINED_GLASS)
Block(5,1,7,STAINED_GLASS)
Block(5,1,8,STAINED_GLASS)
Block(5,1,9,STAINED_GLASS)
Block(5,1,10,STAINED_GLASS)
Block(5,1,11,CONCRETE:8)
Block(5,1,12,CONCRETE:8)
Block(5,2,-13,STAINED_GLASS)
Block(5,2,-12,CONCRETE)
Block(5,2,-11,IRON_TRAPDOOR:10)
Block(5,2,-10,IRON_TRAPDOOR:10)
Block(5,2,-9,IRON_TRAPDOOR:10)
Block(5,2,-8,CONCRETE)
Block(5,2,-7,STAINED_GLASS)
Block(5,2,1,STAINED_GLASS)
Block(5,2,2,STAINED_GLASS)
Block(5,2,3,STAINED_GLASS)
Block(5,2,4,STAINED_GLASS)
Block(5,2,5,STAINED_GLASS)
Block(5,2,6,STAINED_GLASS)
Block(5,2,7,STAINED_GLASS)
Block(5,2,8,STAINED_GLASS)
Block(5,2,9,STAINED_GLASS)
Block(5,2,10,STAINED_GLASS)
Block(5,2,11,STAINED_GLASS)
Block(5,2,12,STAINED_GLASS)
Block(5,3,-13,CONCRETE)
Block(5,3,-12,CONCRETE)
Block(5,3,-10,RED_NETHER_BRICK)
Block(5,3,-9,MAGMA)
Block(5,3,-8,CONCRETE)
Block(5,3,-7,CONCRETE)
Block(5,3,2,STAINED_GLASS)
Block(5,3,3,STAINED_GLASS)
Block(5,3,4,STAINED_GLASS)
Block(5,3,5,STAINED_GLASS)
Block(5,3,6,STAINED_GLASS)
Block(5,3,7,STAINED_GLASS)
Block(5,3,8,STAINED_GLASS)
Block(5,3,9,STAINED_GLASS)
Block(5,3,10,STAINED_GLASS)
Block(5,3,11,STAINED_GLASS)
Block(5,4,-13,CONCRETE)
Block(5,4,-12,CONCRETE)
Block(5,4,-11,IRON_TRAPDOOR:10)
Block(5,4,-10,IRON_TRAPDOOR:10)
Block(5,4,-9,IRON_TRAPDOOR:10)
Block(5,4,-8,CONCRETE)
Block(5,4,-7,CONCRETE)
Block(5,4,4,CONCRETE)
Block(5,4,5,STAINED_GLASS)
Block(5,4,6,STAINED_GLASS)
Block(5,4,7,STAINED_GLASS)
Block(5,4,8,STAINED_GLASS)
Block(5,4,9,CONCRETE)
Block(5,5,-13,CONCRETE)
Block(5,5,-12,CONCRETE)
Block(5,5,-8,CONCRETE)
Block(5,5,-7,CONCRETE)
Block(5,6,-13,CONCRETE)
Block(5,6,-12,CONCRETE)
Block(5,6,-11,CONCRETE)
Block(5,6,-10,END_ROD:3)
Block(5,6,-9,CONCRETE)
Block(5,6,-8,CONCRETE)
Block(5,6,-7,CONCRETE)
Block(5,7,-12,CONCRETE)
Block(5,7,-11,CONCRETE)
Block(5,7,-10,CONCRETE)
Block(5,7,-9,CONCRETE)
Block(5,7,-8,CONCRETE)
Block(5,8,-11,CONCRETE)
Block(5,8,-10,CONCRETE)
Block(5,8,-9,CONCRETE)
Block(6,-1,-16,CONCRETE)
Block(6,-1,-15,CONCRETE)
Block(6,-1,-14,CONCRETE)
Block(6,-1,-13,CONCRETE)
Block(6,-1,-12,CONCRETE)
Block(6,-1,-11,CONCRETE)
Block(6,-1,-10,CONCRETE)
Block(6,-1,-9,CONCRETE)
Block(6,-1,-8,CONCRETE)
Block(6,-1,-7,CONCRETE)
Block(6,-1,-6,CONCRETE)
Block(6,-1,0,CONCRETE)
Block(6,-1,1,CONCRETE)
Block(6,-1,2,CONCRETE)
Block(6,-1,3,CONCRETE)
Block(6,-1,4,CONCRETE)
Block(6,-1,5,CONCRETE)
Block(6,-1,6,CONCRETE)
Block(6,-1,7,CONCRETE)
Block(6,-1,8,CONCRETE)
Block(6,-1,9,CONCRETE)
Block(6,-1,10,CONCRETE)
Block(6,-1,11,CONCRETE)
Block(6,-1,12,CONCRETE)
Block(6,-1,13,CONCRETE)
Block(6,0,-15,CONCRETE:12)
Block(6,0,-14,CONCRETE:12)
Block(6,0,-11,CONCRETE:8)
Block(6,0,-10,CONCRETE:8)
Block(6,0,-9,CONCRETE:8)
Block(6,0,4,CONCRETE)
Block(6,0,9,CONCRETE)
Block(6,1,-11,CONCRETE)
Block(6,1,-10,CONCRETE)
Block(6,1,-9,CONCRETE)
Block(6,1,4,CONCRETE)
Block(6,1,9,CONCRETE)
Block(6,2,-11,CONCRETE)
Block(6,2,-10,CONCRETE)
Block(6,2,-9,CONCRETE)
Block(6,2,4,CONCRETE)
Block(6,2,9,CONCRETE)
Block(6,3,-11,CONCRETE)
Block(6,3,-10,CONCRETE)
Block(6,3,-9,CONCRETE)
Block(6,3,4,CONCRETE)
Block(6,3,9,CONCRETE)
Block(6,4,-11,CONCRETE)
Block(6,4,-10,CONCRETE:13)
Block(6,4,-9,CONCRETE)
Block(6,5,-11,CONCRETE)
Block(6,5,-10,CONCRETE:5)
Block(6,5,-9,CONCRETE)
Block(6,6,-10,CONCRETE)
Block(7,-1,-16,CONCRETE)
Block(7,-1,-15,CONCRETE)
Block(7,-1,-14,CONCRETE)
Block(7,-1,-13,CONCRETE)
Block(7,-1,-12,CONCRETE)
Block(7,-1,-11,CONCRETE)
Block(7,-1,-10,CONCRETE)
Block(7,-1,-9,CONCRETE)
Block(7,-1,-8,CONCRETE)
Block(7,0,-14,CONCRETE:12)
Block(7,0,-13,CONCRETE:12)
Block(7,0,-12,CONCRETE:12)
Block(7,0,-11,QUARTZ_BLOCK)
Block(7,0,-10,AIR)
Block(7,0,-9,QUARTZ_BLOCK)
Block(7,1,-11,QUARTZ_BLOCK)
Block(7,1,-9,QUARTZ_BLOCK)
Block(7,2,-11,STEP)
Block(7,2,-10,STEP)
Block(7,2,-9,STEP)
Block(8,-1,-16,CONCRETE)
Block(8,-1,-15,CONCRETE)
Block(8,-1,-14,CONCRETE)
Block(8,-1,-13,CONCRETE)
Block(8,-1,-12,CONCRETE)
Block(8,-1,-11,CONCRETE)
Block(8,-1,-10,CONCRETE)
Block(8,-1,-9,CONCRETE)
Block(8,-1,-8,CONCRETE)
Block(8,0,-11,QUARTZ_BLOCK)
Block(8,0,-10,AIR)
Block(8,0,-9,QUARTZ_BLOCK)
Block(8,1,-11,CONCRETE:12)
Block(8,1,-9,QUARTZ_BLOCK)
Block(8,2,-11,STEP)
Block(8,2,-10,IRON_TRAPDOOR:3)
Block(8,2,-9,STEP)
Block(9,-1,-16,CONCRETE)
Block(9,-1,-15,CONCRETE)
Block(9,-1,-14,CONCRETE)
Block(9,-1,-13,CONCRETE)
Block(9,-1,-12,CONCRETE)
Block(9,-1,-11,CONCRETE)
Block(9,-1,-10,CONCRETE)
Block(9,-1,-9,CONCRETE)
Block(9,-1,-8,CONCRETE)
Block(9,0,-12,TRIPWIRE_HOOK)
Block(9,0,-11,QUARTZ_BLOCK)
Block(9,0,-10,AIR)
Block(9,0,-9,QUARTZ_BLOCK)
Block(9,1,-12,WALL_SIGN,NetherVillagerPodA/7-sign.nbt)
Block(9,1,-11,QUARTZ_BLOCK)
Block(9,1,-9,QUARTZ_BLOCK)
Block(9,2,-11,STEP)
Block(9,2,-10,STEP)
Block(9,2,-9,STEP)
Block(10,-1,-16,CONCRETE)
Block(10,-1,-15,CONCRETE)
Block(10,-1,-14,CONCRETE)
Block(10,-1,-13,CONCRETE)
Block(10,-1,-12,CONCRETE)
Block(10,-1,-11,CONCRETE)
Block(10,-1,-10,CONCRETE)
Block(10,-1,-9,CONCRETE)
Block(10,-1,-8,CONCRETE)
Block(10,0,-12,LEVER)
Block(10,0,-11,QUARTZ_BLOCK)
Block(10,0,-10,QUARTZ_BLOCK)
Block(10,0,-9,QUARTZ_BLOCK)
Block(10,1,-11,QUARTZ_BLOCK)
Block(10,1,-10,QUARTZ_BLOCK)
Block(10,1,-9,QUARTZ_BLOCK)
Block(10,2,-11,STEP)
Block(10,2,-10,STEP)
Block(10,2,-9,STEP)
Block(11,-1,-16,CONCRETE)
Block(11,-1,-15,CONCRETE)
Block(11,-1,-14,CONCRETE)
Block(11,-1,-13,CONCRETE)
Block(11,-1,-12,CONCRETE)
Block(11,-1,-11,CONCRETE)
Block(11,-1,-10,CONCRETE)
Block(11,-1,-9,CONCRETE)
Block(11,-1,-8,CONCRETE)
Block(4,1,-8,AIR)

#######################################################################
# +-----------------------------------------------------------------+ #
# |                            BO3 checks                           | #
# +-----------------------------------------------------------------+ #
#######################################################################

BlockCheck(0,-2,5,NETHERRACK,SAND,HARD_CLAY,STAINED_CLAY,CONCRETE_POWDER)
BlockCheck(0,-2,-5,NETHERRACK,SAND,HARD_CLAY,STAINED_CLAY,CONCRETE_POWDER)

#######################################################################
# +-----------------------------------------------------------------+ #
# |                             Branches                            | #
# +-----------------------------------------------------------------+ #
#######################################################################


#######################################################################
# +-----------------------------------------------------------------+ #
# |                             Entities                            | #
# +-----------------------------------------------------------------+ #
#######################################################################

Entity(4,1,-8,Villager,1,NetherVillagerPodA/villager.txt)

#######################################################################
# +-----------------------------------------------------------------+ #
# |                            Particles                            | #
# +-----------------------------------------------------------------+ #
#######################################################################


#######################################################################
# +-----------------------------------------------------------------+ #
# |                             Spawners                            | #
# +-----------------------------------------------------------------+ #
#######################################################################


#######################################################################
# +-----------------------------------------------------------------+ #
# |                             ModData                             | #
# +-----------------------------------------------------------------+ #
#######################################################################

