
#######################################################################
# +-----------------------------------------------------------------+ #
# |                            BO3 object                           | #
# +-----------------------------------------------------------------+ #
#######################################################################

Author: totemo

Description: A purpur spike with chest and silverfish spawner.

Version: 3

SettingsMode: WriteWithoutComments


#######################################################################
# +-----------------------------------------------------------------+ #
# |                          Main settings                          | #
# +-----------------------------------------------------------------+ #
#######################################################################

Tree: false

Frequency: 0

Rarity: 100.0

RotateRandomly: true

SpawnHeight: highestBlock

SpawnHeightOffset: 0

SpawnHeightVariance: 0

##############################
# Height Limits for the BO3. #
##############################

MinHeight: 0

MaxHeight: 256

######################
# Extrusion settings #
######################

ExtrudeMode: None

ExtrudeThroughBlocks: AIR

MaxBranchDepth: 10

ExcludedBiomes: All


#######################################################################
# +-----------------------------------------------------------------+ #
# |                      Source block settings                      | #
# +-----------------------------------------------------------------+ #
#######################################################################

SourceBlocks: AIR

MaxPercentageOutsideSourceBlock: 20

OutsideSourceBlock: placeAnyway

IsOTGPlus: false


#######################################################################
# +-----------------------------------------------------------------+ #
# |                              Blocks                             | #
# +-----------------------------------------------------------------+ #
#######################################################################

Block(-8,2,0,PURPUR_STAIRS:4)
Block(-8,3,0,PURPUR_BLOCK)
Block(-8,4,0,PURPUR_BLOCK)
Block(-8,5,0,PURPUR_BLOCK)
Block(-8,6,0,PURPUR_BLOCK)
Block(-8,7,0,PURPUR_BLOCK)
Block(-8,8,0,PURPUR_BLOCK)
Block(-8,9,0,PURPUR_BLOCK)
Block(-8,10,0,PURPUR_BLOCK)
Block(-8,11,0,PURPUR_STAIRS:0)
Block(-7,1,0,PURPUR_STAIRS:4)
Block(-7,2,0,PURPUR_STAIRS:1)
Block(-7,3,0,PURPUR_SLAB)
Block(-7,4,0,PURPUR_SLAB:8)
Block(-7,7,0,PURPUR_SLAB:8)
Block(-7,8,0,PURPUR_SLAB)
Block(-7,11,0,PURPUR_STAIRS:5)
Block(-7,12,0,PURPUR_BLOCK)
Block(-7,13,0,PURPUR_BLOCK)
Block(-7,14,0,PURPUR_BLOCK)
Block(-7,15,0,PURPUR_BLOCK)
Block(-7,16,0,PURPUR_STAIRS:0)
Block(-6,1,0,PURPUR_BLOCK)
Block(-6,3,0,PURPUR_SLAB)
Block(-6,4,0,PURPUR_SLAB:8)
Block(-6,7,0,PURPUR_STAIRS:4)
Block(-6,8,0,PURPUR_SLAB)
Block(-6,13,0,PURPUR_SLAB)
Block(-6,15,0,PURPUR_SLAB:8)
Block(-6,16,0,PURPUR_STAIRS:5)
Block(-6,17,0,PURPUR_BLOCK)
Block(-6,18,0,PURPUR_BLOCK)
Block(-6,19,0,PURPUR_BLOCK)
Block(-6,20,0,PURPUR_BLOCK)
Block(-6,21,0,PURPUR_BLOCK)
Block(-6,22,0,PURPUR_BLOCK)
Block(-6,23,0,PURPUR_BLOCK)
Block(-6,24,0,PURPUR_STAIRS:0)
Block(-6,25,0,END_ROD)
Block(-6,26,0,END_ROD:0)
Block(-6,27,0,END_ROD)
Block(-5,0,0,PURPUR_STAIRS:4)
Block(-5,1,0,PURPUR_STAIRS:1)
Block(-5,3,0,PURPUR_SLAB)
Block(-5,4,0,PURPUR_SLAB:8)
Block(-5,6,0,PURPUR_STAIRS:4)
Block(-5,7,0,PURPUR_STAIRS:1)
Block(-5,13,0,PURPUR_SLAB)
Block(-5,15,0,PURPUR_SLAB:8)
Block(-5,20,0,PURPUR_SLAB)
Block(-5,21,0,PURPUR_SLAB)
Block(-4,0,-2,PURPUR_SLAB)
Block(-4,0,-1,PURPUR_SLAB)
Block(-4,0,0,PURPUR_BLOCK)
Block(-4,0,1,PURPUR_SLAB)
Block(-4,0,2,PURPUR_SLAB)
Block(-4,3,0,PURPUR_SLAB)
Block(-4,4,0,PURPUR_SLAB:8)
Block(-4,5,0,PURPUR_STAIRS:4)
Block(-4,6,0,PURPUR_STAIRS:1)
Block(-4,13,0,PURPUR_BLOCK)
Block(-4,15,0,PURPUR_SLAB:8)
Block(-4,20,0,PURPUR_SLAB)
Block(-4,21,0,PURPUR_SLAB)
Block(-3,0,-3,PURPUR_SLAB)
Block(-3,0,-2,PURPUR_SLAB)
Block(-3,0,-1,PURPUR_BLOCK)
Block(-3,0,0,PURPUR_BLOCK)
Block(-3,0,1,PURPUR_BLOCK)
Block(-3,0,2,PURPUR_SLAB)
Block(-3,0,3,PURPUR_SLAB)
Block(-3,1,0,PURPUR_BLOCK)
Block(-3,2,0,PURPUR_BLOCK)
Block(-3,3,0,PURPUR_BLOCK)
Block(-3,4,0,PURPUR_BLOCK)
Block(-3,5,0,PURPUR_STAIRS:1)
Block(-3,13,0,PURPUR_SLAB:8)
Block(-3,14,0,PURPUR_BLOCK)
Block(-3,15,-2,PURPUR_SLAB:8)
Block(-3,15,-1,PURPUR_SLAB:8)
Block(-3,15,0,PURPUR_BLOCK)
Block(-3,15,1,PURPUR_SLAB:8)
Block(-3,15,2,PURPUR_SLAB:8)
Block(-3,20,0,PURPUR_SLAB)
Block(-3,21,0,PURPUR_SLAB)
Block(-2,0,-4,PURPUR_SLAB)
Block(-2,0,-3,PURPUR_SLAB)
Block(-2,0,-2,PURPUR_BLOCK)
Block(-2,0,-1,PURPUR_BLOCK)
Block(-2,0,0,PURPUR_BLOCK)
Block(-2,0,1,PURPUR_BLOCK)
Block(-2,0,2,PURPUR_BLOCK)
Block(-2,0,3,PURPUR_SLAB)
Block(-2,0,4,PURPUR_SLAB)
Block(-2,15,-3,PURPUR_SLAB:8)
Block(-2,15,-2,PURPUR_SLAB:8)
Block(-2,15,2,PURPUR_SLAB:8)
Block(-2,15,3,PURPUR_SLAB:8)
Block(-2,19,0,PURPUR_STAIRS:4)
Block(-2,20,0,PURPUR_SLAB)
Block(-2,21,0,PURPUR_STAIRS:0)
Block(-1,0,-4,PURPUR_SLAB)
Block(-1,0,-3,PURPUR_BLOCK)
Block(-1,0,-2,PURPUR_BLOCK)
Block(-1,0,-1,PURPUR_BLOCK)
Block(-1,0,0,PURPUR_BLOCK)
Block(-1,0,1,PURPUR_BLOCK)
Block(-1,0,2,PURPUR_BLOCK)
Block(-1,0,3,PURPUR_BLOCK)
Block(-1,0,4,PURPUR_SLAB)
Block(-1,1,-1,PURPUR_SLAB)
Block(-1,1,0,PURPUR_STAIRS:4)
Block(-1,1,1,PURPUR_SLAB)
Block(-1,15,-3,PURPUR_SLAB:8)
Block(-1,15,3,PURPUR_SLAB:8)
Block(-1,18,0,PURPUR_STAIRS:4)
Block(-1,19,0,PURPUR_STAIRS:1)
Block(-1,21,0,PURPUR_STAIRS:5)
Block(-1,22,0,PURPUR_STAIRS:0)
Block(-1,24,0,SANDSTONE_STAIRS:4)
Block(-1,25,0,SANDSTONE_STAIRS:0)
Block(0,0,-5,PURPUR_STAIRS:6)
Block(0,0,-4,PURPUR_BLOCK)
Block(0,0,-3,PURPUR_BLOCK)
Block(0,0,-2,PURPUR_BLOCK)
Block(0,0,-1,PURPUR_BLOCK)
Block(0,0,0,PURPUR_BLOCK)
Block(0,0,1,PURPUR_BLOCK)
Block(0,0,2,PURPUR_BLOCK)
Block(0,0,3,PURPUR_BLOCK)
Block(0,0,4,PURPUR_BLOCK)
Block(0,0,5,PURPUR_STAIRS:7)
Block(0,1,-7,PURPUR_STAIRS:6)
Block(0,1,-6,PURPUR_BLOCK)
Block(0,1,-5,PURPUR_STAIRS:0)
Block(0,1,-3,PURPUR_BLOCK)
Block(0,1,-1,PURPUR_STAIRS:6)
Block(0,1,0,MOB_SPAWNER,EndSpikeSilverfish/1-mob_spawner.nbt)
Block(0,1,1,PURPUR_STAIRS:7)
Block(0,1,3,PURPUR_BLOCK)
Block(0,1,5,PURPUR_STAIRS:2)
Block(0,1,6,PURPUR_BLOCK)
Block(0,1,7,PURPUR_STAIRS:7)
Block(0,2,-8,PURPUR_STAIRS:6)
Block(0,2,-7,PURPUR_STAIRS:0)
Block(0,2,-3,PURPUR_BLOCK)
Block(0,2,0,CHEST,EndSpikeSilverfish/2-chest.nbt)
Block(0,2,3,PURPUR_BLOCK)
Block(0,2,7,PURPUR_STAIRS:2)
Block(0,2,8,PURPUR_STAIRS:7)
Block(0,3,-8,PURPUR_BLOCK)
Block(0,3,-7,PURPUR_SLAB)
Block(0,3,-6,PURPUR_SLAB)
Block(0,3,-5,PURPUR_SLAB)
Block(0,3,-4,PURPUR_SLAB)
Block(0,3,-3,PURPUR_BLOCK)
Block(0,3,3,PURPUR_BLOCK)
Block(0,3,4,PURPUR_SLAB)
Block(0,3,5,PURPUR_SLAB)
Block(0,3,6,PURPUR_SLAB)
Block(0,3,7,PURPUR_SLAB)
Block(0,3,8,PURPUR_BLOCK)
Block(0,4,-8,PURPUR_BLOCK)
Block(0,4,-7,PURPUR_SLAB:8)
Block(0,4,-6,PURPUR_SLAB:8)
Block(0,4,-5,PURPUR_SLAB:8)
Block(0,4,-4,PURPUR_SLAB:8)
Block(0,4,-3,PURPUR_BLOCK)
Block(0,4,3,PURPUR_BLOCK)
Block(0,4,4,PURPUR_SLAB:8)
Block(0,4,5,PURPUR_SLAB:8)
Block(0,4,6,PURPUR_SLAB:8)
Block(0,4,7,PURPUR_SLAB:8)
Block(0,4,8,PURPUR_BLOCK)
Block(0,5,-8,PURPUR_BLOCK)
Block(0,5,-4,PURPUR_STAIRS:6)
Block(0,5,-3,PURPUR_STAIRS:0)
Block(0,5,3,PURPUR_STAIRS:2)
Block(0,5,4,PURPUR_STAIRS:7)
Block(0,5,8,PURPUR_BLOCK)
Block(0,6,-8,PURPUR_BLOCK)
Block(0,6,-5,PURPUR_STAIRS:6)
Block(0,6,-4,PURPUR_STAIRS:0)
Block(0,6,4,PURPUR_STAIRS:2)
Block(0,6,5,PURPUR_STAIRS:7)
Block(0,6,8,PURPUR_BLOCK)
Block(0,7,-8,PURPUR_BLOCK)
Block(0,7,-7,PURPUR_SLAB:8)
Block(0,7,-6,PURPUR_STAIRS:6)
Block(0,7,-5,PURPUR_STAIRS:0)
Block(0,7,5,PURPUR_STAIRS:2)
Block(0,7,6,PURPUR_STAIRS:7)
Block(0,7,7,PURPUR_SLAB:8)
Block(0,7,8,PURPUR_BLOCK)
Block(0,8,-8,PURPUR_BLOCK)
Block(0,8,-7,PURPUR_SLAB)
Block(0,8,-6,PURPUR_SLAB)
Block(0,8,0,END_ROD:0)
Block(0,8,6,PURPUR_SLAB)
Block(0,8,7,PURPUR_SLAB)
Block(0,8,8,PURPUR_BLOCK)
Block(0,9,-8,PURPUR_BLOCK)
Block(0,9,0,END_ROD:0)
Block(0,9,8,PURPUR_BLOCK)
Block(0,10,-8,PURPUR_BLOCK)
Block(0,10,0,STAINED_GLASS_PANE:2)
Block(0,10,8,PURPUR_BLOCK)
Block(0,11,-8,PURPUR_STAIRS:2)
Block(0,11,-7,PURPUR_STAIRS:7)
Block(0,11,0,STAINED_GLASS_PANE:10)
Block(0,11,7,PURPUR_STAIRS:6)
Block(0,11,8,PURPUR_STAIRS:0)
Block(0,12,-7,PURPUR_BLOCK)
Block(0,12,0,END_ROD:0)
Block(0,12,7,PURPUR_BLOCK)
Block(0,13,-7,PURPUR_BLOCK)
Block(0,13,-6,PURPUR_SLAB)
Block(0,13,-5,PURPUR_SLAB)
Block(0,13,-4,PURPUR_BLOCK)
Block(0,13,-3,PURPUR_SLAB:8)
Block(0,13,0,END_ROD:0)
Block(0,13,3,PURPUR_SLAB:8)
Block(0,13,4,PURPUR_BLOCK)
Block(0,13,5,PURPUR_SLAB)
Block(0,13,6,PURPUR_SLAB)
Block(0,13,7,PURPUR_BLOCK)
Block(0,14,-7,PURPUR_BLOCK)
Block(0,14,-3,PURPUR_BLOCK)
Block(0,14,0,END_ROD:0)
Block(0,14,3,PURPUR_BLOCK)
Block(0,14,7,PURPUR_BLOCK)
Block(0,15,-7,PURPUR_BLOCK)
Block(0,15,-6,PURPUR_SLAB:8)
Block(0,15,-5,PURPUR_SLAB:8)
Block(0,15,-4,PURPUR_SLAB:8)
Block(0,15,-3,PURPUR_BLOCK)
Block(0,15,0,STAINED_GLASS_PANE:10)
Block(0,15,3,PURPUR_BLOCK)
Block(0,15,4,PURPUR_SLAB:8)
Block(0,15,5,PURPUR_SLAB:8)
Block(0,15,6,PURPUR_SLAB:8)
Block(0,15,7,PURPUR_BLOCK)
Block(0,16,-7,PURPUR_STAIRS:2)
Block(0,16,-6,PURPUR_STAIRS:7)
Block(0,16,0,END_ROD:0)
Block(0,16,6,PURPUR_STAIRS:6)
Block(0,16,7,PURPUR_STAIRS:0)
Block(0,17,-6,PURPUR_BLOCK)
Block(0,17,0,STAINED_GLASS:2)
Block(0,17,6,PURPUR_BLOCK)
Block(0,18,-6,PURPUR_BLOCK)
Block(0,18,-1,PURPUR_STAIRS:6)
Block(0,18,0,STAINED_GLASS:10)
Block(0,18,1,PURPUR_STAIRS:7)
Block(0,18,6,PURPUR_BLOCK)
Block(0,19,-6,PURPUR_BLOCK)
Block(0,19,-2,PURPUR_STAIRS:6)
Block(0,19,-1,PURPUR_STAIRS:0)
Block(0,19,0,STAINED_GLASS:2)
Block(0,19,1,PURPUR_STAIRS:2)
Block(0,19,2,PURPUR_STAIRS:7)
Block(0,19,6,PURPUR_BLOCK)
Block(0,20,-6,PURPUR_BLOCK)
Block(0,20,-5,PURPUR_SLAB)
Block(0,20,-4,PURPUR_SLAB)
Block(0,20,-3,PURPUR_SLAB)
Block(0,20,-2,PURPUR_SLAB)
Block(0,20,0,STAINED_GLASS:2)
Block(0,20,2,PURPUR_SLAB)
Block(0,20,3,PURPUR_SLAB)
Block(0,20,4,PURPUR_SLAB)
Block(0,20,5,PURPUR_SLAB)
Block(0,20,6,PURPUR_BLOCK)
Block(0,21,-6,PURPUR_BLOCK)
Block(0,21,-5,PURPUR_SLAB)
Block(0,21,-4,PURPUR_SLAB)
Block(0,21,-3,PURPUR_SLAB)
Block(0,21,-2,PURPUR_STAIRS:2)
Block(0,21,-1,PURPUR_STAIRS:7)
Block(0,21,0,STAINED_GLASS:10)
Block(0,21,1,PURPUR_STAIRS:6)
Block(0,21,2,PURPUR_STAIRS:0)
Block(0,21,3,PURPUR_SLAB)
Block(0,21,4,PURPUR_SLAB)
Block(0,21,5,PURPUR_SLAB)
Block(0,21,6,PURPUR_BLOCK)
Block(0,22,-6,PURPUR_BLOCK)
Block(0,22,-1,PURPUR_STAIRS:2)
Block(0,22,0,STAINED_GLASS:2)
Block(0,22,1,PURPUR_STAIRS:0)
Block(0,22,6,PURPUR_BLOCK)
Block(0,23,-6,PURPUR_BLOCK)
Block(0,23,0,STAINED_GLASS:10)
Block(0,23,6,PURPUR_BLOCK)
Block(0,24,-6,PURPUR_STAIRS:2)
Block(0,24,-1,SANDSTONE_STAIRS:6)
Block(0,24,0,END_BRICKS)
Block(0,24,1,SANDSTONE_STAIRS:7)
Block(0,24,6,PURPUR_STAIRS:0)
Block(0,25,-6,END_ROD)
Block(0,25,-1,SANDSTONE_STAIRS:2)
Block(0,25,0,END_BRICKS)
Block(0,25,1,SANDSTONE_STAIRS:0)
Block(0,25,6,END_ROD)
Block(0,26,-6,END_ROD:0)
Block(0,26,6,END_ROD:0)
Block(0,27,-6,END_ROD)
Block(0,27,6,END_ROD)
Block(1,0,-4,PURPUR_SLAB)
Block(1,0,-3,PURPUR_BLOCK)
Block(1,0,-2,PURPUR_BLOCK)
Block(1,0,-1,PURPUR_BLOCK)
Block(1,0,0,PURPUR_BLOCK)
Block(1,0,1,PURPUR_BLOCK)
Block(1,0,2,PURPUR_BLOCK)
Block(1,0,3,PURPUR_BLOCK)
Block(1,0,4,PURPUR_SLAB)
Block(1,1,-1,PURPUR_SLAB)
Block(1,1,0,PURPUR_STAIRS:5)
Block(1,1,1,PURPUR_SLAB)
Block(1,15,-3,PURPUR_SLAB:8)
Block(1,15,3,PURPUR_SLAB:8)
Block(1,18,0,PURPUR_STAIRS:5)
Block(1,19,0,PURPUR_STAIRS:0)
Block(1,21,0,PURPUR_STAIRS:4)
Block(1,22,0,PURPUR_STAIRS:1)
Block(1,24,0,SANDSTONE_STAIRS:5)
Block(1,25,0,SANDSTONE_STAIRS:1)
Block(2,0,-4,PURPUR_SLAB)
Block(2,0,-3,PURPUR_SLAB)
Block(2,0,-2,PURPUR_BLOCK)
Block(2,0,-1,PURPUR_BLOCK)
Block(2,0,0,PURPUR_BLOCK)
Block(2,0,1,PURPUR_BLOCK)
Block(2,0,2,PURPUR_BLOCK)
Block(2,0,3,PURPUR_SLAB)
Block(2,0,4,PURPUR_SLAB)
Block(2,15,-3,PURPUR_SLAB:8)
Block(2,15,-2,PURPUR_SLAB:8)
Block(2,15,2,PURPUR_SLAB:8)
Block(2,15,3,PURPUR_SLAB:8)
Block(2,19,0,PURPUR_STAIRS:5)
Block(2,20,0,PURPUR_SLAB)
Block(2,21,0,PURPUR_STAIRS:1)
Block(3,0,-3,PURPUR_SLAB)
Block(3,0,-2,PURPUR_SLAB)
Block(3,0,-1,PURPUR_BLOCK)
Block(3,0,0,PURPUR_BLOCK)
Block(3,0,1,PURPUR_BLOCK)
Block(3,0,2,PURPUR_SLAB)
Block(3,0,3,PURPUR_SLAB)
Block(3,1,0,PURPUR_BLOCK)
Block(3,2,0,PURPUR_BLOCK)
Block(3,3,0,PURPUR_BLOCK)
Block(3,4,0,PURPUR_BLOCK)
Block(3,5,0,PURPUR_STAIRS:0)
Block(3,13,0,PURPUR_SLAB:8)
Block(3,14,0,PURPUR_BLOCK)
Block(3,15,-2,PURPUR_SLAB:8)
Block(3,15,-1,PURPUR_SLAB:8)
Block(3,15,0,PURPUR_BLOCK)
Block(3,15,1,PURPUR_SLAB:8)
Block(3,15,2,PURPUR_SLAB:8)
Block(3,20,0,PURPUR_SLAB)
Block(3,21,0,PURPUR_SLAB)
Block(4,0,-2,PURPUR_SLAB)
Block(4,0,-1,PURPUR_SLAB)
Block(4,0,0,PURPUR_BLOCK)
Block(4,0,1,PURPUR_SLAB)
Block(4,0,2,PURPUR_SLAB)
Block(4,3,0,PURPUR_SLAB)
Block(4,4,0,PURPUR_SLAB:8)
Block(4,5,0,PURPUR_STAIRS:5)
Block(4,6,0,PURPUR_STAIRS:0)
Block(4,13,0,PURPUR_BLOCK)
Block(4,15,0,PURPUR_SLAB:8)
Block(4,20,0,PURPUR_SLAB)
Block(4,21,0,PURPUR_SLAB)
Block(5,0,0,PURPUR_STAIRS:5)
Block(5,1,0,PURPUR_STAIRS:0)
Block(5,3,0,PURPUR_SLAB)
Block(5,4,0,PURPUR_SLAB:8)
Block(5,6,0,PURPUR_STAIRS:5)
Block(5,7,0,PURPUR_STAIRS:0)
Block(5,13,0,PURPUR_SLAB)
Block(5,15,0,PURPUR_SLAB:8)
Block(5,20,0,PURPUR_SLAB)
Block(5,21,0,PURPUR_SLAB)
Block(6,1,0,PURPUR_BLOCK)
Block(6,3,0,PURPUR_SLAB)
Block(6,4,0,PURPUR_SLAB:8)
Block(6,7,0,PURPUR_STAIRS:5)
Block(6,8,0,PURPUR_SLAB)
Block(6,13,0,PURPUR_SLAB)
Block(6,15,0,PURPUR_SLAB:8)
Block(6,16,0,PURPUR_STAIRS:4)
Block(6,17,0,PURPUR_BLOCK)
Block(6,18,0,PURPUR_BLOCK)
Block(6,19,0,PURPUR_BLOCK)
Block(6,20,0,PURPUR_BLOCK)
Block(6,21,0,PURPUR_BLOCK)
Block(6,22,0,PURPUR_BLOCK)
Block(6,23,0,PURPUR_BLOCK)
Block(6,24,0,PURPUR_STAIRS:1)
Block(6,25,0,END_ROD)
Block(6,26,0,END_ROD:0)
Block(6,27,0,END_ROD)
Block(7,1,0,PURPUR_STAIRS:5)
Block(7,2,0,PURPUR_STAIRS:0)
Block(7,3,0,PURPUR_SLAB)
Block(7,4,0,PURPUR_SLAB:8)
Block(7,7,0,PURPUR_SLAB:8)
Block(7,8,0,PURPUR_SLAB)
Block(7,11,0,PURPUR_STAIRS:4)
Block(7,12,0,PURPUR_BLOCK)
Block(7,13,0,PURPUR_BLOCK)
Block(7,14,0,PURPUR_BLOCK)
Block(7,15,0,PURPUR_BLOCK)
Block(7,16,0,PURPUR_STAIRS:1)
Block(8,2,0,PURPUR_STAIRS:5)
Block(8,3,0,PURPUR_BLOCK)
Block(8,4,0,PURPUR_BLOCK)
Block(8,5,0,PURPUR_BLOCK)
Block(8,6,0,PURPUR_BLOCK)
Block(8,7,0,PURPUR_BLOCK)
Block(8,8,0,PURPUR_BLOCK)
Block(8,9,0,PURPUR_BLOCK)
Block(8,10,0,PURPUR_BLOCK)
Block(8,11,0,PURPUR_STAIRS:1)

#######################################################################
# +-----------------------------------------------------------------+ #
# |                            BO3 checks                           | #
# +-----------------------------------------------------------------+ #
#######################################################################


#######################################################################
# +-----------------------------------------------------------------+ #
# |                             Branches                            | #
# +-----------------------------------------------------------------+ #
#######################################################################


#######################################################################
# +-----------------------------------------------------------------+ #
# |                             Entities                            | #
# +-----------------------------------------------------------------+ #
#######################################################################

Entity(-1,4,-1,SHULKER,1)
Entity(-1,4,1,SHULKER,1)
Entity(0,4,0,SHULKER,1)
Entity(1,4,1,SHULKER,1)
Entity(1,4,-1,SHULKER,1)

#######################################################################
# +-----------------------------------------------------------------+ #
# |                            Particles                            | #
# +-----------------------------------------------------------------+ #
#######################################################################


#######################################################################
# +-----------------------------------------------------------------+ #
# |                             Spawners                            | #
# +-----------------------------------------------------------------+ #
#######################################################################


#######################################################################
# +-----------------------------------------------------------------+ #
# |                             ModData                             | #
# +-----------------------------------------------------------------+ #
#######################################################################

