
#######################################################################
# +-----------------------------------------------------------------+ #
# |                            BO3 object                           | #
# +-----------------------------------------------------------------+ #
#######################################################################

Author: kumquatmay

Description: No description given

Version: 3

SettingsMode: WriteWithoutComments


#######################################################################
# +-----------------------------------------------------------------+ #
# |                          Main settings                          | #
# +-----------------------------------------------------------------+ #
#######################################################################

Tree: false

Frequency: 0

Rarity: 100.0

RotateRandomly: true

SpawnHeight: highestBlock

SpawnHeightOffset: 0

SpawnHeightVariance: 0

##############################
# Height Limits for the BO3. #
##############################

MinHeight: 0

MaxHeight: 256

######################
# Extrusion settings #
######################

ExtrudeMode: BottomDown

ExtrudeThroughBlocks: AIR,DEAD_BUSH,CACTUS,BROWN_MUSHROOM,RED_MUSHROOM

MaxBranchDepth: 10

ExcludedBiomes: All


#######################################################################
# +-----------------------------------------------------------------+ #
# |                      Source block settings                      | #
# +-----------------------------------------------------------------+ #
#######################################################################

SourceBlocks: AIR

MaxPercentageOutsideSourceBlock: 30

OutsideSourceBlock: placeAnyway

IsOTGPlus: false


#######################################################################
# +-----------------------------------------------------------------+ #
# |                              Blocks                             | #
# +-----------------------------------------------------------------+ #
#######################################################################

Block(-14,0,6,BONE_BLOCK:0)
Block(-14,0,7,BONE_BLOCK:0)
Block(-14,0,8,BONE_BLOCK:0)
Block(-14,0,9,BONE_BLOCK:0)
Block(-14,1,6,BONE_BLOCK:0)
Block(-14,1,8,BONE_BLOCK:0)
Block(-14,1,9,BONE_BLOCK:0)
Block(-14,2,6,BONE_BLOCK:0)
Block(-14,2,8,BONE_BLOCK:0)
Block(-14,3,6,BONE_BLOCK:0)
Block(-14,3,8,NETHER_FENCE)
Block(-14,4,6,NETHER_FENCE)
Block(-13,0,-5,BONE_BLOCK:0)
Block(-13,0,-4,BONE_BLOCK:0)
Block(-13,0,-3,BONE_BLOCK:0)
Block(-13,0,-2,BONE_BLOCK:0)
Block(-13,0,-1,BONE_BLOCK:0)
Block(-13,0,4,BONE_BLOCK:0)
Block(-13,0,5,BONE_BLOCK:0)
Block(-13,0,9,BONE_BLOCK:0)
Block(-13,0,10,BONE_BLOCK:0)
Block(-13,0,11,BONE_BLOCK:0)
Block(-13,0,12,BONE_BLOCK:0)
Block(-13,0,13,BONE_BLOCK:0)
Block(-13,1,-5,BONE_BLOCK:0)
Block(-13,1,-4,BONE_BLOCK:0)
Block(-13,1,-3,BONE_BLOCK:0)
Block(-13,1,-2,BONE_BLOCK:0)
Block(-13,1,-1,BONE_BLOCK:0)
Block(-13,1,4,BONE_BLOCK:0)
Block(-13,1,5,BONE_BLOCK:0)
Block(-13,1,10,BONE_BLOCK:0)
Block(-13,1,11,BONE_BLOCK:0)
Block(-13,1,12,BONE_BLOCK:0)
Block(-13,1,13,BONE_BLOCK:0)
Block(-13,2,-5,BONE_BLOCK:0)
Block(-13,2,-4,BONE_BLOCK:0)
Block(-13,2,-3,BONE_BLOCK:0)
Block(-13,2,-1,BONE_BLOCK:0)
Block(-13,2,4,BONE_BLOCK:0)
Block(-13,2,10,BONE_BLOCK:0)
Block(-13,2,11,BONE_BLOCK:0)
Block(-13,2,12,NETHER_FENCE)
Block(-13,2,13,BONE_BLOCK:0)
Block(-13,3,-5,BONE_BLOCK:0)
Block(-13,3,-4,BONE_BLOCK:0)
Block(-13,3,-1,NETHER_FENCE)
Block(-13,3,4,NETHER_FENCE)
Block(-13,3,10,BONE_BLOCK:0)
Block(-13,3,11,BONE_BLOCK:0)
Block(-13,3,13,BONE_BLOCK:0)
Block(-13,4,-4,BONE_BLOCK:0)
Block(-13,4,-1,NETHER_FENCE)
Block(-13,4,4,NETHER_FENCE)
Block(-13,4,10,NETHER_FENCE)
Block(-13,4,13,BONE_BLOCK:0)
Block(-13,5,-4,NETHER_FENCE)
Block(-13,5,13,NETHER_FENCE)
Block(-13,6,-4,NETHER_FENCE)
Block(-12,0,-6,BONE_BLOCK:0)
Block(-12,0,0,BONE_BLOCK:0)
Block(-12,0,1,BONE_BLOCK:0)
Block(-12,0,3,BONE_BLOCK:0)
Block(-12,0,4,BONE_BLOCK:0)
Block(-12,0,13,BONE_BLOCK:0)
Block(-12,1,-6,BONE_BLOCK:0)
Block(-12,1,0,BONE_BLOCK:0)
Block(-12,1,1,BONE_BLOCK:0)
Block(-12,1,3,BONE_BLOCK:0)
Block(-12,2,-6,BONE_BLOCK:0)
Block(-12,2,1,BONE_BLOCK:0)
Block(-12,2,3,BONE_BLOCK:0)
Block(-12,3,-6,NETHER_FENCE)
Block(-12,3,1,BONE_BLOCK:0)
Block(-12,4,1,NETHER_FENCE)
Block(-12,5,1,NETHER_FENCE)
Block(-11,0,-7,BONE_BLOCK:0)
Block(-11,0,2,BONE_BLOCK:0)
Block(-11,0,9,BONE_BLOCK:0)
Block(-11,0,10,BONE_BLOCK:0)
Block(-11,0,11,BONE_BLOCK:0)
Block(-11,0,14,BONE_BLOCK:0)
Block(-11,1,-7,BONE_BLOCK:0)
Block(-11,1,2,BONE_BLOCK:0)
Block(-11,1,9,BONE_BLOCK:0)
Block(-11,1,10,BONE_BLOCK:0)
Block(-11,1,14,BONE_BLOCK:0)
Block(-11,2,-7,NETHER_FENCE)
Block(-11,2,9,BONE_BLOCK:0)
Block(-11,2,10,BONE_BLOCK:0)
Block(-11,2,14,BONE_BLOCK:0)
Block(-11,3,9,BONE_BLOCK:0)
Block(-11,3,10,BONE_BLOCK:0)
Block(-11,3,14,BONE_BLOCK:0)
Block(-11,4,10,BONE_BLOCK:0)
Block(-11,4,14,NETHER_FENCE)
Block(-10,0,-8,BONE_BLOCK:0)
Block(-10,0,-5,BONE_BLOCK:0)
Block(-10,0,-4,BONE_BLOCK:0)
Block(-10,0,7,BONE_BLOCK:0)
Block(-10,0,8,BONE_BLOCK:0)
Block(-10,0,9,BONE_BLOCK)
Block(-10,0,10,NETHERRACK)
Block(-10,0,11,BONE_BLOCK:0)
Block(-10,0,12,BONE_BLOCK:0)
Block(-10,0,14,BONE_BLOCK:0)
Block(-10,1,-8,BONE_BLOCK:0)
Block(-10,1,-5,BONE_BLOCK:0)
Block(-10,1,-4,BONE_BLOCK:0)
Block(-10,1,8,BONE_BLOCK:0)
Block(-10,1,10,FIRE:15)
Block(-10,1,11,BONE_BLOCK:8)
Block(-10,1,12,BONE_BLOCK:0)
Block(-10,1,14,BONE_BLOCK:0)
Block(-10,2,-5,BONE_BLOCK:0)
Block(-10,2,-4,BONE_BLOCK:0)
Block(-10,2,8,BONE_BLOCK:0)
Block(-10,2,11,BONE_BLOCK:0)
Block(-10,3,-5,BONE_BLOCK:0)
Block(-10,3,-4,BONE_BLOCK:0)
Block(-10,3,9,BONE_BLOCK)
Block(-10,3,11,BONE_BLOCK:0)
Block(-10,4,-5,BONE_BLOCK:0)
Block(-10,4,-4,BONE_BLOCK:0)
Block(-10,4,9,BONE_BLOCK:0)
Block(-10,4,11,BONE_BLOCK:0)
Block(-10,5,-4,BONE_BLOCK:0)
Block(-9,0,-11,BONE_BLOCK:0)
Block(-9,0,-10,BONE_BLOCK:0)
Block(-9,0,-9,BONE_BLOCK:0)
Block(-9,0,-6,BONE_BLOCK:8)
Block(-9,0,-5,BONE_BLOCK)
Block(-9,0,-4,BONE_BLOCK)
Block(-9,0,-3,BONE_BLOCK:0)
Block(-9,0,-2,BONE_BLOCK:0)
Block(-9,0,7,BONE_BLOCK:0)
Block(-9,0,8,BONE_BLOCK:8)
Block(-9,0,9,BONE_BLOCK:8)
Block(-9,0,10,BONE_BLOCK:0)
Block(-9,0,11,BONE_BLOCK:0)
Block(-9,0,12,BONE_BLOCK:0)
Block(-9,0,14,BONE_BLOCK:0)
Block(-9,1,-10,BONE_BLOCK:0)
Block(-9,1,-9,BONE_BLOCK:0)
Block(-9,1,-6,BONE_BLOCK:0)
Block(-9,1,-3,BONE_BLOCK:0)
Block(-9,1,-2,BONE_BLOCK:0)
Block(-9,1,7,BONE_BLOCK:0)
Block(-9,1,8,CHEST:3,NetherVerulCamp/1-chest.nbt)
Block(-9,1,11,CARPET:7)
Block(-9,1,12,BONE_BLOCK:0)
Block(-9,1,14,BONE_BLOCK:0)
Block(-9,2,-10,BONE_BLOCK:0)
Block(-9,2,-9,BONE_BLOCK:0)
Block(-9,2,-6,BONE_BLOCK:0)
Block(-9,2,-3,NETHER_FENCE)
Block(-9,2,-2,BONE_BLOCK:0)
Block(-9,2,7,BONE_BLOCK:0)
Block(-9,2,12,BONE_BLOCK:0)
Block(-9,3,-10,NETHER_FENCE)
Block(-9,3,-9,BONE_BLOCK:0)
Block(-9,3,-6,BONE_BLOCK:0)
Block(-9,3,-4,STEP:6)
Block(-9,3,-3,BONE_BLOCK:0)
Block(-9,3,-2,BONE_BLOCK:0)
Block(-9,3,7,BONE_BLOCK:0)
Block(-9,3,8,BONE_BLOCK:8)
Block(-9,3,11,BONE_BLOCK:8)
Block(-9,3,12,BONE_BLOCK:0)
Block(-9,4,-9,NETHER_FENCE)
Block(-9,4,-5,BONE_BLOCK)
Block(-9,4,-3,BONE_BLOCK:0)
Block(-9,4,-2,BONE_BLOCK:0)
Block(-9,4,8,BONE_BLOCK:0)
Block(-9,4,10,BONE_BLOCK:8)
Block(-9,4,11,BONE_BLOCK:0)
Block(-9,4,12,BONE_BLOCK:8)
Block(-9,5,-5,BONE_BLOCK:8)
Block(-9,5,-4,BONE_BLOCK)
Block(-9,5,-3,BONE_BLOCK:0)
Block(-9,5,8,BONE_BLOCK:0)
Block(-9,5,9,BONE_BLOCK:8)
Block(-9,6,-5,BONE_BLOCK:8)
Block(-9,6,-4,BONE_BLOCK:0)
Block(-8,0,-13,BONE_BLOCK:0)
Block(-8,0,-12,BONE_BLOCK:0)
Block(-8,0,-7,BONE_BLOCK:0)
Block(-8,0,-6,BONE_BLOCK:8)
Block(-8,0,-5,BONE_BLOCK:8)
Block(-8,0,-4,BONE_BLOCK:8)
Block(-8,0,-3,BONE_BLOCK)
Block(-8,0,-2,BONE_BLOCK:8)
Block(-8,0,-1,BONE_BLOCK:0)
Block(-8,0,0,BONE_BLOCK:0)
Block(-8,0,7,BONE_BLOCK:0)
Block(-8,0,8,BONE_BLOCK:8)
Block(-8,0,9,BONE_BLOCK:0)
Block(-8,0,10,BONE_BLOCK)
Block(-8,0,11,BONE_BLOCK:0)
Block(-8,0,12,BONE_BLOCK:0)
Block(-8,0,14,BONE_BLOCK:0)
Block(-8,1,-13,BONE_BLOCK:0)
Block(-8,1,-12,BONE_BLOCK:0)
Block(-8,1,-7,BONE_BLOCK:0)
Block(-8,1,-1,BONE_BLOCK:0)
Block(-8,1,7,BONE_BLOCK:0)
Block(-8,1,11,CARPET:7)
Block(-8,1,12,BONE_BLOCK)
Block(-8,1,14,BONE_BLOCK:0)
Block(-8,2,-13,BONE_BLOCK:0)
Block(-8,2,-12,BONE_BLOCK:0)
Block(-8,2,-7,BONE_BLOCK:0)
Block(-8,2,-6,BONE_BLOCK)
Block(-8,2,-5,STEP:14)
Block(-8,2,-1,BONE_BLOCK:0)
Block(-8,2,7,BONE_BLOCK:0)
Block(-8,2,14,BONE_BLOCK:0)
Block(-8,3,-13,BONE_BLOCK:0)
Block(-8,3,-12,BONE_BLOCK:0)
Block(-8,3,-6,BONE_BLOCK:0)
Block(-8,3,-3,STEP:6)
Block(-8,3,-2,BONE_BLOCK)
Block(-8,3,-1,BONE_BLOCK:0)
Block(-8,3,8,BONE_BLOCK)
Block(-8,3,11,BONE_BLOCK:0)
Block(-8,3,12,BONE_BLOCK)
Block(-8,3,14,NETHER_FENCE)
Block(-8,4,-13,BONE_BLOCK:0)
Block(-8,4,-6,BONE_BLOCK:0)
Block(-8,4,-5,BONE_BLOCK)
Block(-8,4,-2,BONE_BLOCK)
Block(-8,4,8,BONE_BLOCK:0)
Block(-8,4,11,BONE_BLOCK:0)
Block(-8,5,-13,NETHER_FENCE)
Block(-8,5,-6,BONE_BLOCK:0)
Block(-8,5,-4,BONE_BLOCK)
Block(-8,5,-3,BONE_BLOCK)
Block(-8,5,8,BONE_BLOCK:0)
Block(-8,5,9,BONE_BLOCK:8)
Block(-8,5,10,BONE_BLOCK:8)
Block(-8,6,-13,NETHER_FENCE)
Block(-8,6,-6,BONE_BLOCK:0)
Block(-8,6,-5,BONE_BLOCK)
Block(-8,6,-4,BONE_BLOCK)
Block(-8,7,-5,BONE_BLOCK:0)
Block(-7,0,-14,BONE_BLOCK:8)
Block(-7,0,-13,BONE_BLOCK:0)
Block(-7,0,-8,BONE_BLOCK:0)
Block(-7,0,-7,BONE_BLOCK)
Block(-7,0,-6,BONE_BLOCK)
Block(-7,0,-5,BONE_BLOCK)
Block(-7,0,-4,BONE_BLOCK:8)
Block(-7,0,-3,BONE_BLOCK)
Block(-7,0,-2,BONE_BLOCK:8)
Block(-7,0,-1,BONE_BLOCK:0)
Block(-7,0,0,BONE_BLOCK:0)
Block(-7,0,8,BONE_BLOCK:0)
Block(-7,0,9,BONE_BLOCK:0)
Block(-7,0,10,BONE_BLOCK:0)
Block(-7,1,11,MOB_SPAWNER,NetherVerulCamp/2-mob_spawner.nbt)
Block(-7,0,11,BONE_BLOCK:0)
Block(-7,0,12,BONE_BLOCK:0)
Block(-7,0,14,BONE_BLOCK:0)
Block(-7,1,-14,BONE_BLOCK:0)
Block(-7,1,-13,BONE_BLOCK:0)
Block(-7,1,-10,BONE_BLOCK:8)
Block(-7,1,-9,BONE_BLOCK:8)
Block(-7,1,-8,BONE_BLOCK:0)
Block(-7,1,-5,STEP:6)
Block(-7,1,-4,STEP:6)
Block(-7,1,0,BONE_BLOCK:0)
Block(-7,1,8,BONE_BLOCK:0)
Block(-7,1,12,BONE_BLOCK:0)
Block(-7,1,14,BONE_BLOCK:0)
Block(-7,2,-13,BONE_BLOCK:0)
Block(-7,2,-8,BONE_BLOCK:0)
Block(-7,2,-7,BONE_BLOCK:8)
Block(-7,2,0,BONE_BLOCK:0)
Block(-7,2,8,BONE_BLOCK:0)
Block(-7,2,12,BONE_BLOCK:0)
Block(-7,2,14,NETHER_FENCE)
Block(-7,3,-13,NETHER_FENCE)
Block(-7,3,-7,NETHER_FENCE)
Block(-7,3,-1,BONE_BLOCK)
Block(-7,3,0,BONE_BLOCK:0)
Block(-7,3,8,BONE_BLOCK:0)
Block(-7,3,9,BONE_BLOCK:0)
Block(-7,3,10,BONE_BLOCK:0)
Block(-7,3,12,BONE_BLOCK:0)
Block(-7,4,-7,BONE_BLOCK:0)
Block(-7,4,-5,STEP:14)
Block(-7,4,-2,BONE_BLOCK)
Block(-7,4,-1,BONE_BLOCK:0)
Block(-7,4,9,BONE_BLOCK:0)
Block(-7,4,10,BONE_BLOCK:8)
Block(-7,4,11,BONE_BLOCK:8)
Block(-7,5,-7,BONE_BLOCK:0)
Block(-7,5,-6,BONE_BLOCK)
Block(-7,5,-4,STEP:6)
Block(-7,5,-2,BONE_BLOCK:0)
Block(-7,5,-1,BONE_BLOCK:8)
Block(-7,6,-6,BONE_BLOCK:0)
Block(-7,6,-5,BONE_BLOCK)
Block(-7,6,-4,BONE_BLOCK)
Block(-7,6,-3,BONE_BLOCK:8)
Block(-7,7,-6,BONE_BLOCK:8)
Block(-7,7,-5,BONE_BLOCK:0)
Block(-7,7,-4,BONE_BLOCK:0)
Block(-7,8,-5,BONE_BLOCK:0)
Block(-7,9,-5,BONE_BLOCK:0)
Block(-7,10,-5,BONE_BLOCK:0)
Block(-7,11,-5,BONE_BLOCK:0)
Block(-7,12,-5,NETHER_FENCE)
Block(-6,0,-14,BONE_BLOCK:0)
Block(-6,0,-10,BONE_BLOCK:0)
Block(-6,0,-9,BONE_BLOCK:8)
Block(-6,0,-8,BONE_BLOCK:0)
Block(-6,0,-7,BONE_BLOCK:0)
Block(-6,0,-6,BONE_BLOCK:8)
Block(-6,0,-5,BONE_BLOCK)
Block(-6,0,-4,BONE_BLOCK:0)
Block(-6,0,-3,BONE_BLOCK)
Block(-6,0,-2,BONE_BLOCK:8)
Block(-6,0,-1,BONE_BLOCK:0)
Block(-6,0,0,BONE_BLOCK:0)
Block(-6,0,9,STEP)
Block(-6,0,10,BONE_BLOCK:0)
Block(-6,0,11,BONE_BLOCK:0)
Block(-6,0,14,BONE_BLOCK:0)
Block(-6,1,-14,NETHER_FENCE)
Block(-6,1,-10,NETHER_FENCE)
Block(-6,1,-9,BONE_BLOCK:0)
Block(-6,1,-2,STEP:6)
Block(-6,1,0,BONE_BLOCK:0)
Block(-6,1,10,BONE_BLOCK:0)
Block(-6,1,11,BONE_BLOCK:0)
Block(-6,1,14,BONE_BLOCK:0)
Block(-6,2,-9,BONE_BLOCK:0)
Block(-6,2,-8,BONE_BLOCK:8)
Block(-6,2,0,BONE_BLOCK:0)
Block(-6,2,10,BONE_BLOCK:0)
Block(-6,2,11,BONE_BLOCK:0)
Block(-6,2,14,BONE_BLOCK:0)
Block(-6,3,-9,BONE_BLOCK:0)
Block(-6,3,-8,BONE_BLOCK:0)
Block(-6,3,0,NETHER_FENCE)
Block(-6,3,11,BONE_BLOCK:0)
Block(-6,4,-9,BONE_BLOCK:0)
Block(-6,4,-8,BONE_BLOCK:0)
Block(-6,4,-7,BONE_BLOCK)
Block(-6,4,-2,BONE_BLOCK)
Block(-6,4,-1,BONE_BLOCK:8)
Block(-6,4,0,BONE_BLOCK)
Block(-6,5,-7,BONE_BLOCK)
Block(-6,5,-6,STEP:6)
Block(-6,5,-2,BONE_BLOCK:0)
Block(-6,5,-1,BONE_BLOCK:0)
Block(-6,5,0,BONE_BLOCK:8)
Block(-6,6,-7,BONE_BLOCK)
Block(-6,6,-2,BONE_BLOCK:0)
Block(-6,7,-6,BONE_BLOCK)
Block(-6,7,-4,BONE_BLOCK)
Block(-6,7,-3,BONE_BLOCK)
Block(-5,0,-14,BONE_BLOCK:0)
Block(-5,0,-11,BONE_BLOCK:8)
Block(-5,0,-10,BONE_BLOCK:0)
Block(-5,0,-9,BONE_BLOCK:0)
Block(-5,0,-8,BONE_BLOCK:8)
Block(-5,0,-7,BONE_BLOCK:8)
Block(-5,0,-6,BONE_BLOCK:0)
Block(-5,0,-5,NETHERRACK)
Block(-5,0,-4,COAL_BLOCK)
Block(-5,0,-3,BONE_BLOCK:8)
Block(-5,0,-2,BONE_BLOCK)
Block(-5,0,-1,BONE_BLOCK)
Block(-5,0,0,BONE_BLOCK:0)
Block(-5,0,1,STEP)
Block(-5,0,5,STEP)
Block(-5,0,13,BONE_BLOCK:0)
Block(-5,1,-14,BONE_BLOCK:0)
Block(-5,1,-11,BONE_BLOCK:0)
Block(-5,1,-7,STEP:6)
Block(-5,1,13,BONE_BLOCK:0)
Block(-5,2,-11,BONE_BLOCK:0)
Block(-5,2,-10,BONE_BLOCK:8)
Block(-5,2,-9,BONE_BLOCK:8)
Block(-5,3,-9,BONE_BLOCK:0)
Block(-5,4,-9,BONE_BLOCK:0)
Block(-5,4,-8,BONE_BLOCK:8)
Block(-5,4,-1,BONE_BLOCK)
Block(-5,4,0,BONE_BLOCK)
Block(-5,5,-9,BONE_BLOCK:0)
Block(-5,5,-8,BONE_BLOCK:0)
Block(-5,5,-7,STEP:6)
Block(-5,5,-2,BONE_BLOCK)
Block(-5,5,-1,BONE_BLOCK:8)
Block(-5,6,-8,BONE_BLOCK:0)
Block(-5,6,-7,BONE_BLOCK:8)
Block(-5,6,-2,BONE_BLOCK:0)
Block(-5,7,-7,BONE_BLOCK:0)
Block(-5,7,-3,BONE_BLOCK)
Block(-5,8,-7,BONE_BLOCK:0)
Block(-5,8,-3,BONE_BLOCK:0)
Block(-5,9,-7,BONE_BLOCK:0)
Block(-5,9,-3,BONE_BLOCK:0)
Block(-5,10,-7,BONE_BLOCK:0)
Block(-5,10,-3,BONE_BLOCK:0)
Block(-5,11,-3,BONE_BLOCK:0)
Block(-5,12,-3,NETHER_FENCE)
Block(-5,13,-3,NETHER_FENCE)
Block(-4,0,-14,BONE_BLOCK:0)
Block(-4,0,-11,BONE_BLOCK:0)
Block(-4,0,-10,BONE_BLOCK)
Block(-4,0,-9,BONE_BLOCK)
Block(-4,0,-8,BONE_BLOCK:0)
Block(-4,0,-7,BONE_BLOCK:8)
Block(-4,0,-6,BONE_BLOCK:8)
Block(-4,0,-5,NETHERRACK)
Block(-4,1,-4,MOB_SPAWNER,NetherVerulCamp/3-mob_spawner.nbt)
Block(-4,0,-4,BONE_BLOCK:0)
Block(-4,0,-3,COAL_BLOCK)
Block(-4,0,-2,BONE_BLOCK:8)
Block(-4,0,-1,BONE_BLOCK:0)
Block(-4,0,0,STEP)
Block(-4,0,4,STEP)
Block(-4,0,5,NETHERRACK)
Block(-4,0,6,STEP)
Block(-4,0,7,BONE_BLOCK:0)
Block(-4,0,12,BONE_BLOCK:0)
Block(-4,1,-14,BONE_BLOCK:0)
Block(-4,1,-11,BONE_BLOCK:0)
Block(-4,1,-7,STEP:6)
Block(-4,1,5,FIRE:15)
Block(-4,1,12,BONE_BLOCK:0)
Block(-4,2,-14,BONE_BLOCK:0)
Block(-4,2,-11,BONE_BLOCK:0)
Block(-4,2,-10,BONE_BLOCK:8)
Block(-4,2,12,BONE_BLOCK:0)
Block(-4,3,-14,BONE_BLOCK:0)
Block(-4,3,-9,BONE_BLOCK)
Block(-4,3,12,BONE_BLOCK:0)
Block(-4,4,-9,BONE_BLOCK:0)
Block(-4,4,-2,BONE_BLOCK)
Block(-4,4,-1,BONE_BLOCK:8)
Block(-4,4,12,NETHER_FENCE)
Block(-4,5,-9,BONE_BLOCK:0)
Block(-4,5,-2,BONE_BLOCK:0)
Block(-4,6,-8,BONE_BLOCK)
Block(-4,6,-3,BONE_BLOCK:8)
Block(-4,6,-2,BONE_BLOCK:0)
Block(-4,7,-8,BONE_BLOCK:0)
Block(-4,7,-7,BONE_BLOCK:8)
Block(-4,7,-3,BONE_BLOCK:0)
Block(-4,8,-3,NETHER_FENCE)
Block(-3,0,-14,BONE_BLOCK:0)
Block(-3,0,-11,BONE_BLOCK:0)
Block(-3,0,-10,BONE_BLOCK:8)
Block(-3,0,-9,BONE_BLOCK:8)
Block(-3,0,-8,BONE_BLOCK)
Block(-3,0,-7,BONE_BLOCK)
Block(-3,0,-6,BONE_BLOCK:0)
Block(-3,0,-5,BONE_BLOCK:0)
Block(-3,0,-4,BONE_BLOCK:0)
Block(-3,0,-3,COAL_BLOCK)
Block(-3,0,-2,BONE_BLOCK)
Block(-3,0,-1,BONE_BLOCK:0)
Block(-3,0,4,STEP)
Block(-3,0,5,NETHERRACK)
Block(-3,0,6,NETHERRACK)
Block(-3,0,7,BONE_BLOCK:0)
Block(-3,0,8,STEP)
Block(-3,0,12,BONE_BLOCK:0)
Block(-3,1,-14,BONE_BLOCK:0)
Block(-3,1,-11,BONE_BLOCK:0)
Block(-3,1,-10,BONE_BLOCK:8)
Block(-3,1,-7,STEP:6)
Block(-3,1,6,FIRE:15)
Block(-3,1,12,NETHER_FENCE)
Block(-3,2,-14,NETHER_FENCE)
Block(-3,2,-10,BONE_BLOCK:0)
Block(-3,2,12,NETHER_FENCE)
Block(-3,3,-14,NETHER_FENCE)
Block(-3,3,-10,BONE_BLOCK:0)
Block(-3,3,-2,BONE_BLOCK)
Block(-3,4,-14,NETHER_FENCE)
Block(-3,4,-9,BONE_BLOCK)
Block(-3,4,-2,BONE_BLOCK:0)
Block(-3,5,-9,BONE_BLOCK)
Block(-3,5,-2,BONE_BLOCK)
Block(-3,6,-8,BONE_BLOCK)
Block(-3,6,-7,BONE_BLOCK:8)
Block(-3,6,-4,BONE_BLOCK)
Block(-3,6,-3,BONE_BLOCK)
Block(-3,7,-8,BONE_BLOCK:0)
Block(-3,7,-7,BONE_BLOCK:0)
Block(-3,7,-6,BONE_BLOCK)
Block(-3,7,-4,BONE_BLOCK:0)
Block(-3,8,-6,BONE_BLOCK:0)
Block(-3,8,-4,BONE_BLOCK:0)
Block(-3,9,-4,BONE_BLOCK:0)
Block(-3,10,-4,NETHER_FENCE)
Block(-2,0,-14,BONE_BLOCK:0)
Block(-2,0,-10,BONE_BLOCK:0)
Block(-2,0,-9,BONE_BLOCK:8)
Block(-2,0,-8,BONE_BLOCK:8)
Block(-2,0,-7,BONE_BLOCK:8)
Block(-2,0,-6,BONE_BLOCK:8)
Block(-2,0,-5,BONE_BLOCK:0)
Block(-2,0,-4,BONE_BLOCK)
Block(-2,0,-3,BONE_BLOCK)
Block(-2,0,-2,BONE_BLOCK:0)
Block(-2,0,-1,STEP)
Block(-2,0,3,STEP)
Block(-2,0,6,NETHERRACK)
Block(-2,0,7,NETHERRACK)
Block(-2,0,8,STEP)
Block(-2,0,12,BONE_BLOCK:0)
Block(-2,1,-14,BONE_BLOCK:0)
Block(-2,1,-10,BONE_BLOCK:0)
Block(-2,1,-9,BONE_BLOCK:8)
Block(-2,1,-6,STEP:6)
Block(-2,1,-5,STEP:6)
Block(-2,1,-2,NETHER_FENCE)
Block(-2,1,6,FIRE:15)
Block(-2,1,12,BONE_BLOCK:0)
Block(-2,2,-10,BONE_BLOCK:0)
Block(-2,2,-9,NETHER_FENCE)
Block(-2,2,-2,BONE_BLOCK)
Block(-2,2,12,BONE_BLOCK:0)
Block(-2,3,-14,NETHER_FENCE)
Block(-2,3,-10,BONE_BLOCK:0)
Block(-2,3,-9,BONE_BLOCK:8)
Block(-2,3,-2,BONE_BLOCK:0)
Block(-2,3,12,BONE_BLOCK:0)
Block(-2,4,-9,BONE_BLOCK:0)
Block(-2,4,-8,BONE_BLOCK:8)
Block(-2,4,-7,STEP:14)
Block(-2,4,-2,BONE_BLOCK:0)
Block(-2,4,12,BONE_BLOCK:0)
Block(-2,5,-8,BONE_BLOCK:0)
Block(-2,5,-7,CHEST:4,NetherVerulCamp/4-chest.nbt)
Block(-2,5,-6,STEP:6)
Block(-2,5,-5,STEP:6)
Block(-2,5,-4,BONE_BLOCK)
Block(-2,5,-3,BONE_BLOCK)
Block(-2,5,12,NETHER_FENCE)
Block(-2,6,-8,BONE_BLOCK:0)
Block(-2,6,-5,BONE_BLOCK)
Block(-2,6,-4,BONE_BLOCK:8)
Block(-2,6,-3,BONE_BLOCK:0)
Block(-2,6,12,NETHER_FENCE)
Block(-2,7,-6,BONE_BLOCK)
Block(-1,0,-14,BONE_BLOCK:0)
Block(-1,0,-9,BONE_BLOCK:0)
Block(-1,0,-8,BONE_BLOCK:0)
Block(-1,0,-7,BONE_BLOCK)
Block(-1,0,-6,BONE_BLOCK:8)
Block(-1,0,-5,BONE_BLOCK)
Block(-1,0,-4,BONE_BLOCK)
Block(-1,0,-3,BONE_BLOCK:0)
Block(-1,0,-2,BONE_BLOCK:0)
Block(-1,0,4,BONE_BLOCK)
Block(-1,0,6,NETHERRACK)
Block(-1,0,7,BONE_BLOCK:8)
Block(-1,0,11,BONE_BLOCK:0)
Block(-1,1,-14,BONE_BLOCK:0)
Block(-1,1,-8,BONE_BLOCK:0)
Block(-1,1,-2,BONE_BLOCK:0)
Block(-1,1,6,FIRE:15)
Block(-1,2,-14,BONE_BLOCK:0)
Block(-1,2,-8,BONE_BLOCK:0)
Block(-1,2,-2,BONE_BLOCK:0)
Block(-1,3,-14,BONE_BLOCK:0)
Block(-1,3,-8,BONE_BLOCK:0)
Block(-1,3,-7,BONE_BLOCK:8)
Block(-1,3,-3,BONE_BLOCK)
Block(-1,4,-7,BONE_BLOCK:0)
Block(-1,4,-3,BONE_BLOCK:0)
Block(-1,5,-7,BONE_BLOCK:0)
Block(-1,5,-6,BONE_BLOCK:8)
Block(-1,5,-5,BONE_BLOCK)
Block(-1,5,-4,BONE_BLOCK:8)
Block(-1,5,-3,BONE_BLOCK:0)
Block(-1,6,-7,BONE_BLOCK:0)
Block(-1,6,-6,BONE_BLOCK:8)
Block(-1,6,-5,BONE_BLOCK:0)
Block(-1,7,-6,BONE_BLOCK:0)
Block(0,0,-13,BONE_BLOCK:0)
Block(0,0,-8,BONE_BLOCK:0)
Block(0,0,-7,BONE_BLOCK)
Block(0,0,-6,BONE_BLOCK:8)
Block(0,0,-5,BONE_BLOCK)
Block(0,0,-4,BONE_BLOCK:0)
Block(0,0,-3,BONE_BLOCK:0)
Block(0,0,-2,BONE_BLOCK)
Block(0,0,6,BONE_BLOCK:0)
Block(0,1,-13,BONE_BLOCK:0)
Block(0,1,-8,BONE_BLOCK:0)
Block(0,1,-4,BONE_BLOCK:0)
Block(0,1,-3,BONE_BLOCK:0)
Block(0,2,-13,NETHER_FENCE)
Block(0,2,-7,BONE_BLOCK)
Block(0,2,-4,BONE_BLOCK:8)
Block(0,2,-3,BONE_BLOCK:0)
Block(0,3,-7,BONE_BLOCK:0)
Block(0,3,-6,BONE_BLOCK:0)
Block(0,3,-4,BONE_BLOCK:0)
Block(0,3,-3,BONE_BLOCK:0)
Block(0,4,-7,BONE_BLOCK:0)
Block(0,4,-6,BONE_BLOCK:8)
Block(0,4,-5,BONE_BLOCK:8)
Block(0,4,-4,BONE_BLOCK:0)
Block(0,5,-6,BONE_BLOCK:0)
Block(0,5,-5,BONE_BLOCK:0)
Block(1,0,-12,BONE_BLOCK:0)
Block(1,0,-7,BONE_BLOCK:0)
Block(1,0,-6,BONE_BLOCK:0)
Block(1,0,-5,BONE_BLOCK:0)
Block(1,0,-3,BONE_BLOCK:0)
Block(1,0,11,BONE_BLOCK:0)
Block(1,0,12,BONE_BLOCK:0)
Block(1,1,-12,BONE_BLOCK:0)
Block(1,1,-7,BONE_BLOCK:0)
Block(1,1,-6,BONE_BLOCK:8)
Block(1,1,-5,BONE_BLOCK:0)
Block(1,2,-12,BONE_BLOCK:0)
Block(1,2,-7,BONE_BLOCK:0)
Block(1,2,-6,BONE_BLOCK:8)
Block(1,2,-5,NETHER_FENCE)
Block(1,3,-12,BONE_BLOCK:0)
Block(1,3,-7,BONE_BLOCK:0)
Block(1,3,-5,BONE_BLOCK:0)
Block(1,4,-12,NETHER_FENCE)
Block(2,0,-11,BONE_BLOCK:0)
Block(2,0,-10,BONE_BLOCK:0)
Block(2,0,12,BONE_BLOCK)
Block(2,1,-11,BONE_BLOCK:0)
Block(3,0,-11,BONE_BLOCK:0)
Block(3,0,-10,BONE_BLOCK:0)
Block(3,0,12,BONE_BLOCK:0)
Block(3,1,-10,BONE_BLOCK:0)
Block(3,1,12,BONE_BLOCK:0)
Block(3,2,-10,BONE_BLOCK:0)
Block(3,2,12,BONE_BLOCK:0)
Block(3,3,-10,BONE_BLOCK:0)
Block(3,3,12,NETHER_FENCE)
Block(3,4,-10,NETHER_FENCE)
Block(3,4,12,NETHER_FENCE)
Block(4,0,-11,BONE_BLOCK:0)
Block(4,0,2,BONE_BLOCK:0)
Block(4,0,3,BONE_BLOCK:0)
Block(4,0,4,BONE_BLOCK:0)
Block(4,0,5,BONE_BLOCK:0)
Block(4,0,6,NETHER_FENCE)
Block(4,0,8,NETHER_FENCE)
Block(4,0,13,BONE_BLOCK:0)
Block(4,1,-11,BONE_BLOCK:0)
Block(4,1,2,BONE_BLOCK:0)
Block(4,1,3,NETHER_FENCE)
Block(4,1,4,BONE_BLOCK:0)
Block(4,1,5,NETHER_FENCE)
Block(4,1,6,BONE_BLOCK:8)
Block(4,1,8,BONE_BLOCK:8)
Block(4,2,-11,BONE_BLOCK:0)
Block(4,2,3,BONE_BLOCK:0)
Block(4,2,5,BONE_BLOCK:0)
Block(4,2,6,BONE_BLOCK:0)
Block(4,2,7,BONE_BLOCK:0)
Block(4,2,8,NETHER_FENCE)
Block(4,3,5,BONE_BLOCK:0)
Block(4,3,7,BONE_BLOCK:0)
Block(5,0,-12,BONE_BLOCK:0)
Block(5,0,0,BONE_BLOCK:0)
Block(5,0,1,BONE_BLOCK:0)
Block(5,0,2,CARPET:7)
Block(5,0,3,CARPET:12)
Block(5,0,4,CARPET:12)
Block(5,0,8,BONE_BLOCK)
Block(5,0,13,BONE_BLOCK:0)
Block(5,1,-12,BONE_BLOCK:0)
Block(5,1,1,BONE_BLOCK:0)
Block(5,1,4,BONE_BLOCK)
Block(5,1,8,BONE_BLOCK:0)
Block(5,1,13,BONE_BLOCK:0)
Block(5,2,1,BONE_BLOCK:0)
Block(5,2,2,BONE_BLOCK:8)
Block(5,2,3,BONE_BLOCK)
Block(5,2,4,BONE_BLOCK:0)
Block(5,2,8,BONE_BLOCK:0)
Block(5,2,13,BONE_BLOCK:0)
Block(5,3,1,BONE_BLOCK:0)
Block(5,3,3,BONE_BLOCK:0)
Block(5,3,5,BONE_BLOCK)
Block(5,3,6,BONE_BLOCK:8)
Block(5,3,13,BONE_BLOCK:0)
Block(5,4,13,NETHER_FENCE)
Block(6,0,-12,BONE_BLOCK:0)
Block(6,0,-11,BONE_BLOCK:0)
Block(6,0,-10,BONE_BLOCK:0)
Block(6,0,0,BONE_BLOCK:0)
Block(6,0,6,BONE_BLOCK:0)
Block(6,0,7,BONE_BLOCK:0)
Block(6,0,8,BONE_BLOCK:0)
Block(6,0,13,BONE_BLOCK:0)
Block(6,1,-11,BONE_BLOCK:0)
Block(6,1,-10,BONE_BLOCK:0)
Block(6,1,0,BONE_BLOCK:0)
Block(6,1,6,CHEST:4,NetherVerulCamp/5-chest.nbt)
Block(6,1,7,BONE_BLOCK:0)
Block(6,1,8,NETHER_FENCE)
Block(6,1,13,BONE_BLOCK:0)
Block(6,2,-11,BONE_BLOCK:0)
Block(6,2,-10,BONE_BLOCK:0)
Block(6,2,0,BONE_BLOCK:0)
Block(6,2,7,BONE_BLOCK:0)
Block(6,2,8,NETHER_FENCE)
Block(6,2,13,BONE_BLOCK:0)
Block(6,3,-11,NETHER_FENCE)
Block(6,3,-10,BONE_BLOCK:0)
Block(6,3,1,BONE_BLOCK)
Block(6,3,3,BONE_BLOCK:8)
Block(6,3,4,BONE_BLOCK)
Block(6,3,5,BONE_BLOCK:8)
Block(6,3,6,BONE_BLOCK)
Block(6,3,7,BONE_BLOCK:0)
Block(6,4,-10,NETHER_FENCE)
Block(6,4,1,BONE_BLOCK)
Block(7,0,-9,BONE_BLOCK:0)
Block(7,0,0,BONE_BLOCK:0)
Block(7,0,3,CARPET:7)
Block(7,1,4,MOB_SPAWNER,NetherVerulCamp/6-mob_spawner.nbt)
Block(7,0,4,BONE_BLOCK:0)
Block(7,0,5,BONE_BLOCK:0)
Block(7,0,6,BONE_BLOCK:0)
Block(7,0,7,BONE_BLOCK:8)
Block(7,0,13,BONE_BLOCK:0)
Block(7,1,-9,NETHER_FENCE)
Block(7,1,0,BONE_BLOCK)
Block(7,1,5,BONE_BLOCK:0)
Block(7,1,6,BONE_BLOCK:0)
Block(7,1,13,BONE_BLOCK:0)
Block(7,2,-9,BONE_BLOCK:0)
Block(7,2,0,BONE_BLOCK)
Block(7,2,4,BONE_BLOCK)
Block(7,2,5,BONE_BLOCK:0)
Block(7,2,6,BONE_BLOCK:0)
Block(7,2,13,BONE_BLOCK:0)
Block(7,3,-9,NETHER_FENCE)
Block(7,3,0,BONE_BLOCK:0)
Block(7,3,1,BONE_BLOCK:8)
Block(7,3,4,BONE_BLOCK:0)
Block(7,3,13,NETHER_FENCE)
Block(7,4,1,BONE_BLOCK:8)
Block(7,4,2,BONE_BLOCK:0)
Block(8,0,-9,BONE_BLOCK)
Block(8,0,-8,BONE_BLOCK:0)
Block(8,0,0,BONE_BLOCK:0)
Block(8,0,1,BONE_BLOCK:0)
Block(8,0,2,CARPET:12)
Block(8,0,3,CARPET:12)
Block(8,0,4,BONE_BLOCK:0)
Block(8,0,6,BONE_BLOCK)
Block(8,0,13,BONE_BLOCK:0)
Block(8,1,-8,BONE_BLOCK:0)
Block(8,1,1,BONE_BLOCK:0)
Block(8,1,4,BONE_BLOCK:0)
Block(8,1,6,BONE_BLOCK:0)
Block(8,1,13,BONE_BLOCK:0)
Block(8,2,-8,BONE_BLOCK:0)
Block(8,2,1,NETHER_FENCE)
Block(8,2,3,BONE_BLOCK)
Block(8,2,4,BONE_BLOCK:0)
Block(8,2,13,BONE_BLOCK:0)
Block(8,3,-8,NETHER_FENCE)
Block(8,3,2,BONE_BLOCK:8)
Block(8,3,3,BONE_BLOCK:0)
Block(9,0,-7,BONE_BLOCK:0)
Block(9,0,2,BONE_BLOCK:0)
Block(9,0,3,BONE_BLOCK:0)
Block(9,0,12,BONE_BLOCK:0)
Block(9,1,-7,BONE_BLOCK:0)
Block(9,1,1,BONE_BLOCK)
Block(9,1,2,BONE_BLOCK:0)
Block(9,1,3,BONE_BLOCK:0)
Block(9,2,2,BONE_BLOCK:0)
Block(9,2,3,BONE_BLOCK:0)
Block(10,0,-7,BONE_BLOCK:0)
Block(10,0,7,BONE_BLOCK:0)
Block(10,0,8,BONE_BLOCK:0)
Block(10,0,9,BONE_BLOCK:0)
Block(10,0,10,BONE_BLOCK:0)
Block(10,0,11,BONE_BLOCK:0)
Block(10,0,12,BONE_BLOCK:0)
Block(10,1,-7,BONE_BLOCK:0)
Block(10,1,7,BONE_BLOCK:0)
Block(10,1,9,BONE_BLOCK:0)
Block(10,1,10,BONE_BLOCK:0)
Block(10,1,11,BONE_BLOCK:0)
Block(10,1,12,BONE_BLOCK:0)
Block(10,2,-7,BONE_BLOCK:0)
Block(10,2,7,BONE_BLOCK:0)
Block(10,2,9,BONE_BLOCK:0)
Block(10,2,11,BONE_BLOCK:0)
Block(10,2,12,BONE_BLOCK:0)
Block(10,3,-7,NETHER_FENCE)
Block(10,3,7,NETHER_FENCE)
Block(10,3,9,BONE_BLOCK:0)
Block(10,3,11,BONE_BLOCK:0)
Block(10,3,12,NETHER_FENCE)
Block(10,4,-7,NETHER_FENCE)
Block(10,4,7,NETHER_FENCE)
Block(10,4,11,NETHER_FENCE)
Block(11,0,-6,BONE_BLOCK:0)
Block(11,0,-5,BONE_BLOCK:0)
Block(11,0,-4,BONE_BLOCK:0)
Block(11,0,-3,BONE_BLOCK:0)
Block(11,0,-1,BONE_BLOCK:0)
Block(11,0,0,BONE_BLOCK:0)
Block(11,0,6,BONE_BLOCK:0)
Block(11,1,-5,BONE_BLOCK:0)
Block(11,1,-4,BONE_BLOCK:0)
Block(11,1,-3,BONE_BLOCK:0)
Block(11,1,-1,BONE_BLOCK:0)
Block(11,1,0,BONE_BLOCK:0)
Block(11,1,5,BONE_BLOCK:8)
Block(11,1,6,BONE_BLOCK:0)
Block(11,2,-5,NETHER_FENCE)
Block(11,2,-4,BONE_BLOCK:0)
Block(11,2,-1,BONE_BLOCK:0)
Block(11,2,6,BONE_BLOCK:0)
Block(11,3,-1,NETHER_FENCE)
Block(12,0,1,BONE_BLOCK:0)
Block(12,0,5,BONE_BLOCK:0)
Block(12,1,1,BONE_BLOCK:0)
Block(12,1,5,BONE_BLOCK:0)
Block(12,2,1,BONE_BLOCK:0)
Block(12,2,5,BONE_BLOCK:0)
Block(12,3,1,NETHER_FENCE)
Block(12,3,5,NETHER_FENCE)
Block(12,4,1,NETHER_FENCE)
Block(13,0,2,BONE_BLOCK:0)
Block(13,0,3,BONE_BLOCK:0)
Block(13,0,4,BONE_BLOCK:0)
Block(13,0,5,BONE_BLOCK:0)
Block(13,1,3,BONE_BLOCK:0)
Block(13,1,4,BONE_BLOCK:0)
Block(13,1,5,BONE_BLOCK:0)
Block(13,2,4,BONE_BLOCK:0)

#######################################################################
# +-----------------------------------------------------------------+ #
# |                            BO3 checks                           | #
# +-----------------------------------------------------------------+ #
#######################################################################


#######################################################################
# +-----------------------------------------------------------------+ #
# |                             Branches                            | #
# +-----------------------------------------------------------------+ #
#######################################################################


#######################################################################
# +-----------------------------------------------------------------+ #
# |                             Entities                            | #
# +-----------------------------------------------------------------+ #
#######################################################################


#######################################################################
# +-----------------------------------------------------------------+ #
# |                            Particles                            | #
# +-----------------------------------------------------------------+ #
#######################################################################


#######################################################################
# +-----------------------------------------------------------------+ #
# |                             Spawners                            | #
# +-----------------------------------------------------------------+ #
#######################################################################


#######################################################################
# +-----------------------------------------------------------------+ #
# |                             ModData                             | #
# +-----------------------------------------------------------------+ #
#######################################################################

