
#######################################################################
# +-----------------------------------------------------------------+ #
# |                            BO3 object                           | #
# +-----------------------------------------------------------------+ #
#######################################################################

Author: kumquatmay

Description: No description given

Version: 3

SettingsMode: WriteWithoutComments


#######################################################################
# +-----------------------------------------------------------------+ #
# |                          Main settings                          | #
# +-----------------------------------------------------------------+ #
#######################################################################

Tree: false

Frequency: 0

Rarity: 100.0

RotateRandomly: true

SpawnHeight: highestBlock

SpawnHeightOffset: 0

SpawnHeightVariance: 0

##############################
# Height Limits for the BO3. #
##############################

MinHeight: 0

MaxHeight: 256

######################
# Extrusion settings #
######################

ExtrudeMode: BottomDown

ExtrudeThroughBlocks: AIR,DEAD_BUSH,CACTUS,BROWN_MUSHROOM,RED_MUSHROOM

MaxBranchDepth: 10

ExcludedBiomes: All


#######################################################################
# +-----------------------------------------------------------------+ #
# |                      Source block settings                      | #
# +-----------------------------------------------------------------+ #
#######################################################################

SourceBlocks: AIR

MaxPercentageOutsideSourceBlock: 30

OutsideSourceBlock: placeAnyway

IsOTGPlus: false


#######################################################################
# +-----------------------------------------------------------------+ #
# |                              Blocks                             | #
# +-----------------------------------------------------------------+ #
#######################################################################

Block(-13,0,5,RED_SANDSTONE)
Block(-13,0,6,RED_SANDSTONE)
Block(-12,0,-7,RED_SANDSTONE)
Block(-12,0,-6,RED_SANDSTONE)
Block(-12,0,-5,RED_SANDSTONE)
Block(-12,0,-4,RED_SANDSTONE)
Block(-12,0,-3,RED_SANDSTONE)
Block(-12,0,1,RED_SANDSTONE)
Block(-12,0,2,RED_SANDSTONE)
Block(-12,0,3,RED_SANDSTONE)
Block(-12,0,5,RED_SANDSTONE)
Block(-12,0,6,RED_SANDSTONE)
Block(-12,0,7,RED_SANDSTONE)
Block(-12,1,-5,RED_SANDSTONE)
Block(-12,1,2,STAINED_GLASS:1)
Block(-12,1,5,STAINED_GLASS:1)
Block(-11,0,-7,RED_SANDSTONE)
Block(-11,0,-6,RED_SANDSTONE)
Block(-11,0,-5,RED_SANDSTONE)
Block(-11,0,-4,RED_SANDSTONE)
Block(-11,0,-3,RED_SANDSTONE)
Block(-11,0,-2,RED_SANDSTONE)
Block(-11,0,1,RED_SANDSTONE)
Block(-11,0,2,RED_SANDSTONE)
Block(-11,0,3,RED_SANDSTONE)
Block(-11,0,4,RED_SANDSTONE)
Block(-11,0,5,RED_SANDSTONE)
Block(-11,0,6,RED_SANDSTONE)
Block(-11,0,7,RED_SANDSTONE)
Block(-11,0,11,RED_SANDSTONE)
Block(-11,1,-6,RED_SANDSTONE)
Block(-11,1,-5,RED_SANDSTONE)
Block(-11,1,-4,RED_SANDSTONE)
Block(-11,1,-3,RED_SANDSTONE)
Block(-11,1,-2,RED_SANDSTONE)
Block(-11,1,3,STAINED_GLASS:1)
Block(-11,1,4,STAINED_GLASS:1)
Block(-11,1,5,STAINED_GLASS:1)
Block(-11,2,-5,RED_SANDSTONE)
Block(-11,2,-4,SAND:1)
Block(-11,2,-3,SAND:1)
Block(-10,0,-7,RED_SANDSTONE)
Block(-10,0,-6,RED_SANDSTONE)
Block(-10,0,-5,RED_SANDSTONE)
Block(-10,0,-4,RED_SANDSTONE)
Block(-10,0,-3,RED_SANDSTONE)
Block(-10,0,-2,RED_SANDSTONE)
Block(-10,0,-1,RED_SANDSTONE)
Block(-10,0,1,RED_SANDSTONE)
Block(-10,0,2,RED_SANDSTONE)
Block(-10,0,3,RED_SANDSTONE)
Block(-10,0,4,RED_SANDSTONE)
Block(-10,0,5,RED_SANDSTONE)
Block(-10,0,6,RED_SANDSTONE)
Block(-10,0,7,RED_SANDSTONE)
Block(-10,0,8,RED_SANDSTONE)
Block(-10,0,9,RED_SANDSTONE)
Block(-10,0,10,RED_SANDSTONE)
Block(-10,0,11,RED_SANDSTONE)
Block(-10,1,-7,RED_SANDSTONE)
Block(-10,1,-6,RED_SANDSTONE)
Block(-10,1,-5,RED_SANDSTONE)
Block(-10,1,-4,RED_SANDSTONE)
Block(-10,1,-3,RED_SANDSTONE)
Block(-10,1,-2,RED_SANDSTONE)
Block(-10,1,-1,RED_SANDSTONE)
Block(-10,1,3,STAINED_GLASS:1)
Block(-10,1,4,STAINED_GLASS:1)
Block(-10,1,5,STAINED_GLASS:1)
Block(-10,1,6,RED_SANDSTONE)
Block(-10,1,7,RED_SANDSTONE)
Block(-10,1,8,RED_SANDSTONE)
Block(-10,1,9,RED_SANDSTONE)
Block(-10,1,10,RED_SANDSTONE)
Block(-10,2,-6,RED_SANDSTONE)
Block(-10,2,-5,RED_SANDSTONE)
Block(-10,2,-4,SAND:1)
Block(-10,2,-3,RED_SANDSTONE)
Block(-10,2,-2,RED_SANDSTONE)
Block(-10,2,-1,RED_SANDSTONE)
Block(-10,2,4,STAINED_GLASS:1)
Block(-10,2,5,STAINED_GLASS:1)
Block(-10,2,6,STAINED_GLASS:1)
Block(-10,2,7,RED_SANDSTONE)
Block(-10,2,8,SAND:1)
Block(-10,2,9,SAND:1)
Block(-10,3,-6,RED_SANDSTONE)
Block(-10,3,-5,SAND:1)
Block(-10,3,-4,SAND:1)
Block(-10,3,-3,SAND:1)
Block(-10,3,-2,SAND:1)
Block(-9,0,-9,RED_SANDSTONE)
Block(-9,0,-8,RED_SANDSTONE)
Block(-9,0,-7,RED_SANDSTONE)
Block(-9,0,-6,RED_SANDSTONE)
Block(-9,0,-5,RED_SANDSTONE)
Block(-9,0,-4,RED_SANDSTONE)
Block(-9,0,-3,RED_SANDSTONE)
Block(-9,0,-2,RED_SANDSTONE)
Block(-9,0,-1,RED_SANDSTONE)
Block(-9,0,0,RED_SANDSTONE)
Block(-9,0,1,RED_SANDSTONE)
Block(-9,0,2,RED_SANDSTONE)
Block(-9,0,3,RED_SANDSTONE)
Block(-9,0,4,RED_SANDSTONE)
Block(-9,0,5,RED_SANDSTONE)
Block(-9,0,6,RED_SANDSTONE)
Block(-9,0,7,RED_SANDSTONE)
Block(-9,0,8,RED_SANDSTONE)
Block(-9,0,9,RED_SANDSTONE)
Block(-9,0,10,RED_SANDSTONE)
Block(-9,0,11,RED_SANDSTONE)
Block(-9,0,12,RED_SANDSTONE)
Block(-9,1,-8,SAND:1)
Block(-9,1,-7,RED_SANDSTONE)
Block(-9,1,-6,RED_SANDSTONE)
Block(-9,1,-5,RED_SANDSTONE)
Block(-9,1,-4,RED_SANDSTONE)
Block(-9,1,-3,RED_SANDSTONE)
Block(-9,1,-2,RED_SANDSTONE)
Block(-9,1,-1,RED_SANDSTONE)
Block(-9,1,0,RED_SANDSTONE)
Block(-9,1,2,STAINED_GLASS:1)
Block(-9,1,3,STAINED_GLASS:1)
Block(-9,1,4,STAINED_GLASS:1)
Block(-9,1,5,RED_SANDSTONE)
Block(-9,1,6,RED_SANDSTONE)
Block(-9,1,7,RED_SANDSTONE)
Block(-9,1,8,RED_SANDSTONE)
Block(-9,1,9,RED_SANDSTONE)
Block(-9,1,10,RED_SANDSTONE)
Block(-9,1,11,RED_SANDSTONE)
Block(-9,2,-7,RED_SANDSTONE)
Block(-9,2,-6,RED_SANDSTONE)
Block(-9,2,-5,RED_SANDSTONE)
Block(-9,2,-4,RED_SANDSTONE)
Block(-9,2,-3,RED_SANDSTONE)
Block(-9,2,-2,RED_SANDSTONE)
Block(-9,2,-1,RED_SANDSTONE)
Block(-9,2,0,RED_SANDSTONE)
Block(-9,2,3,STAINED_GLASS:1)
Block(-9,2,4,STAINED_GLASS:1)
Block(-9,2,5,RED_SANDSTONE)
Block(-9,2,6,RED_SANDSTONE)
Block(-9,2,7,RED_SANDSTONE)
Block(-9,2,8,RED_SANDSTONE)
Block(-9,2,9,SAND:1)
Block(-9,2,10,SAND:1)
Block(-9,2,11,SAND:1)
Block(-9,3,-6,RED_SANDSTONE)
Block(-9,3,-5,RED_SANDSTONE)
Block(-9,3,-4,RED_SANDSTONE)
Block(-9,3,-3,RED_SANDSTONE)
Block(-9,3,-2,RED_SANDSTONE)
Block(-9,3,-1,RED_SANDSTONE)
Block(-9,3,0,RED_SANDSTONE)
Block(-9,3,5,STAINED_GLASS:1)
Block(-9,3,7,SAND:1)
Block(-9,3,8,SAND:1)
Block(-9,4,-6,RED_SANDSTONE)
Block(-9,4,-5,SAND:1)
Block(-9,4,-4,SAND:1)
Block(-9,4,-3,SAND:1)
Block(-9,4,-2,SAND:1)
Block(-9,4,-1,RED_SANDSTONE)
Block(-9,5,-5,STAINED_GLASS:1)
Block(-9,5,-3,SAND:1)
Block(-9,5,-2,SAND:1)
Block(-8,0,-10,RED_SANDSTONE)
Block(-8,0,-9,RED_SANDSTONE)
Block(-8,0,-8,RED_SANDSTONE)
Block(-8,0,-7,RED_SANDSTONE)
Block(-8,0,-6,RED_SANDSTONE)
Block(-8,0,-5,RED_SANDSTONE)
Block(-8,0,-4,RED_SANDSTONE)
Block(-8,0,-3,RED_SANDSTONE)
Block(-8,0,-2,RED_SANDSTONE)
Block(-8,0,-1,RED_SANDSTONE)
Block(-8,0,0,RED_SANDSTONE)
Block(-8,0,1,RED_SANDSTONE)
Block(-8,0,2,RED_SANDSTONE)
Block(-8,0,3,RED_SANDSTONE)
Block(-8,0,4,RED_SANDSTONE)
Block(-8,0,5,RED_SANDSTONE)
Block(-8,0,6,RED_SANDSTONE)
Block(-8,0,7,RED_SANDSTONE)
Block(-8,0,8,RED_SANDSTONE)
Block(-8,0,9,RED_SANDSTONE)
Block(-8,0,10,RED_SANDSTONE)
Block(-8,0,11,RED_SANDSTONE)
Block(-8,0,12,RED_SANDSTONE)
Block(-8,1,-9,RED_SANDSTONE)
Block(-8,1,-8,SAND:1)
Block(-8,1,-7,RED_SANDSTONE)
Block(-8,1,-6,RED_SANDSTONE)
Block(-8,1,-5,RED_SANDSTONE)
Block(-8,1,-4,RED_SANDSTONE)
Block(-8,1,-3,RED_SANDSTONE)
Block(-8,1,-2,RED_SANDSTONE)
Block(-8,1,1,RED_SANDSTONE)
Block(-8,1,2,RED_SANDSTONE)
Block(-8,1,3,RED_SANDSTONE)
Block(-8,1,4,RED_SANDSTONE)
Block(-8,1,5,RED_SANDSTONE)
Block(-8,1,6,RED_SANDSTONE)
Block(-8,1,7,RED_SANDSTONE)
Block(-8,1,8,RED_SANDSTONE)
Block(-8,1,9,RED_SANDSTONE)
Block(-8,1,10,RED_SANDSTONE)
Block(-8,1,11,RED_SANDSTONE)
Block(-8,1,12,RED_SANDSTONE)
Block(-8,2,-7,SAND:1)
Block(-8,2,-6,RED_SANDSTONE)
Block(-8,2,-5,RED_SANDSTONE)
Block(-8,2,-4,RED_SANDSTONE)
Block(-8,2,-3,RED_SANDSTONE)
Block(-8,2,1,RED_SANDSTONE)
Block(-8,2,2,RED_SANDSTONE)
Block(-8,2,3,RED_SANDSTONE)
Block(-8,2,4,RED_SANDSTONE)
Block(-8,2,5,RED_SANDSTONE)
Block(-8,2,6,RED_SANDSTONE)
Block(-8,2,8,RED_SANDSTONE)
Block(-8,2,9,RED_SANDSTONE)
Block(-8,2,10,RED_SANDSTONE)
Block(-8,2,11,SAND:1)
Block(-8,2,12,RED_SANDSTONE)
Block(-8,3,-6,RED_SANDSTONE)
Block(-8,3,-5,RED_SANDSTONE)
Block(-8,3,-4,RED_SANDSTONE)
Block(-8,3,-3,RED_SANDSTONE)
Block(-8,3,-2,RED_SANDSTONE)
Block(-8,3,0,RED_SANDSTONE)
Block(-8,3,1,RED_SANDSTONE)
Block(-8,3,2,RED_SANDSTONE)
Block(-8,3,4,STAINED_GLASS:1)
Block(-8,3,5,RED_SANDSTONE)
Block(-8,3,6,RED_SANDSTONE)
Block(-8,3,7,RED_SANDSTONE)
Block(-8,3,8,SAND:1)
Block(-8,3,9,SAND:1)
Block(-8,3,10,SAND:1)
Block(-8,4,-6,RED_SANDSTONE)
Block(-8,4,-5,RED_SANDSTONE)
Block(-8,4,-4,RED_SANDSTONE)
Block(-8,4,-3,RED_SANDSTONE)
Block(-8,4,-2,RED_SANDSTONE)
Block(-8,4,-1,RED_SANDSTONE)
Block(-8,4,0,RED_SANDSTONE)
Block(-8,4,1,RED_SANDSTONE)
Block(-8,4,4,STAINED_GLASS:1)
Block(-8,4,5,STAINED_GLASS:1)
Block(-8,4,6,STAINED_GLASS:1)
Block(-8,4,7,SAND:1)
Block(-8,5,-6,STAINED_GLASS:1)
Block(-8,5,-5,RED_SANDSTONE)
Block(-8,5,-4,RED_SANDSTONE)
Block(-8,5,-3,RED_SANDSTONE)
Block(-8,5,-2,RED_SANDSTONE)
Block(-8,5,-1,SAND:1)
Block(-8,6,-5,STAINED_GLASS:1)
Block(-8,6,-4,RED_SANDSTONE)
Block(-8,6,-3,RED_SANDSTONE)
Block(-8,6,-2,SAND:1)
Block(-8,7,-5,STAINED_GLASS:1)
Block(-8,7,-4,STAINED_GLASS:1)
Block(-8,8,-4,STAINED_GLASS:1)
Block(-7,0,-10,RED_SANDSTONE)
Block(-7,0,-9,RED_SANDSTONE)
Block(-7,0,-8,RED_SANDSTONE)
Block(-7,0,-7,RED_SANDSTONE)
Block(-7,0,-6,RED_SANDSTONE)
Block(-7,0,-5,RED_SANDSTONE)
Block(-7,0,-4,RED_SANDSTONE)
Block(-7,0,-3,RED_SANDSTONE)
Block(-7,0,-2,RED_SANDSTONE)
Block(-7,0,-1,RED_SANDSTONE)
Block(-7,0,0,RED_SANDSTONE)
Block(-7,0,1,RED_SANDSTONE)
Block(-7,0,2,RED_SANDSTONE)
Block(-7,0,3,RED_SANDSTONE)
Block(-7,0,4,RED_SANDSTONE)
Block(-7,0,5,RED_SANDSTONE)
Block(-7,0,6,RED_SANDSTONE)
Block(-7,0,7,RED_SANDSTONE)
Block(-7,0,8,RED_SANDSTONE)
Block(-7,0,9,RED_SANDSTONE)
Block(-7,0,10,RED_SANDSTONE)
Block(-7,0,11,RED_SANDSTONE)
Block(-7,0,12,RED_SANDSTONE)
Block(-7,0,13,RED_SANDSTONE)
Block(-7,1,-9,SAND:1)
Block(-7,1,-8,SAND:1)
Block(-7,1,-7,RED_SANDSTONE)
Block(-7,1,-6,RED_SANDSTONE)
Block(-7,1,-5,RED_SANDSTONE)
Block(-7,1,-4,RED_SANDSTONE)
Block(-7,1,-3,RED_SANDSTONE)
Block(-7,1,-2,RED_SANDSTONE_STAIRS:1)
Block(-7,1,3,RED_SANDSTONE)
Block(-7,1,4,RED_SANDSTONE)
Block(-7,1,7,RED_SANDSTONE)
Block(-7,1,8,RED_SANDSTONE)
Block(-7,1,9,RED_SANDSTONE)
Block(-7,1,10,RED_SANDSTONE)
Block(-7,1,11,RED_SANDSTONE)
Block(-7,1,12,RED_SANDSTONE)
Block(-7,1,13,RED_SANDSTONE)
Block(-7,2,-7,SAND:1)
Block(-7,2,-6,RED_SANDSTONE)
Block(-7,2,-5,RED_SANDSTONE)
Block(-7,2,-4,RED_SANDSTONE)
Block(-7,2,2,RED_SANDSTONE)
Block(-7,2,3,RED_SANDSTONE)
Block(-7,2,4,RED_SANDSTONE)
Block(-7,2,8,RED_SANDSTONE)
Block(-7,2,9,RED_SANDSTONE)
Block(-7,2,10,RED_SANDSTONE)
Block(-7,2,11,RED_SANDSTONE)
Block(-7,2,12,SAND:1)
Block(-7,3,-6,RED_SANDSTONE)
Block(-7,3,-5,RED_SANDSTONE)
Block(-7,3,2,RED_SANDSTONE)
Block(-7,3,3,RED_SANDSTONE)
Block(-7,3,4,RED_SANDSTONE)
Block(-7,3,5,RED_SANDSTONE)
Block(-7,3,6,RED_SANDSTONE)
Block(-7,3,8,RED_SANDSTONE)
Block(-7,3,9,SAND:1)
Block(-7,3,10,SAND:1)
Block(-7,3,11,SAND:1)
Block(-7,4,-6,RED_SANDSTONE)
Block(-7,4,-5,RED_SANDSTONE)
Block(-7,4,0,RED_SANDSTONE)
Block(-7,4,1,RED_SANDSTONE)
Block(-7,4,2,RED_SANDSTONE)
Block(-7,4,3,RED_SANDSTONE)
Block(-7,4,4,RED_SANDSTONE)
Block(-7,4,5,RED_SANDSTONE)
Block(-7,4,6,RED_SANDSTONE)
Block(-7,4,7,RED_SANDSTONE)
Block(-7,4,8,SAND:1)
Block(-7,5,-6,RED_SANDSTONE)
Block(-7,5,-5,RED_SANDSTONE)
Block(-7,5,-4,RED_SANDSTONE)
Block(-7,5,-1,RED_SANDSTONE)
Block(-7,5,0,RED_SANDSTONE)
Block(-7,5,1,RED_SANDSTONE)
Block(-7,5,2,RED_SANDSTONE)
Block(-7,5,3,RED_SANDSTONE)
Block(-7,5,4,RED_SANDSTONE)
Block(-7,5,5,STAINED_GLASS:1)
Block(-7,5,6,STAINED_GLASS:1)
Block(-7,5,7,RED_SANDSTONE)
Block(-7,6,-5,RED_SANDSTONE)
Block(-7,6,-4,RED_SANDSTONE)
Block(-7,6,-3,RED_SANDSTONE)
Block(-7,6,-1,SAND:1)
Block(-7,6,0,SAND:1)
Block(-7,6,1,SAND:1)
Block(-7,6,4,STAINED_GLASS:1)
Block(-7,6,5,STAINED_GLASS:1)
Block(-7,6,7,RED_SANDSTONE)
Block(-7,7,-5,STAINED_GLASS:1)
Block(-7,7,-4,RED_SANDSTONE)
Block(-7,7,-3,RED_SANDSTONE)
Block(-7,7,-2,RED_SANDSTONE)
Block(-7,7,4,STAINED_GLASS:1)
Block(-7,8,-5,STAINED_GLASS:1)
Block(-7,8,-4,STAINED_GLASS:1)
Block(-7,8,5,STAINED_GLASS:1)
Block(-7,9,-4,STAINED_GLASS:1)
Block(-7,10,4,STAINED_GLASS:1)
Block(-6,0,-10,RED_SANDSTONE)
Block(-6,0,-9,RED_SANDSTONE)
Block(-6,0,-8,RED_SANDSTONE)
Block(-6,0,-7,RED_SANDSTONE)
Block(-6,0,-6,RED_SANDSTONE)
Block(-6,0,-5,RED_SANDSTONE)
Block(-6,0,-4,RED_SANDSTONE)
Block(-6,0,-3,RED_SANDSTONE)
Block(-6,0,-2,RED_SANDSTONE)
Block(-6,0,-1,RED_SANDSTONE)
Block(-6,0,0,RED_SANDSTONE)
Block(-6,0,1,RED_SANDSTONE)
Block(-6,0,2,RED_SANDSTONE)
Block(-6,0,3,RED_SANDSTONE)
Block(-6,0,4,RED_SANDSTONE)
Block(-6,0,5,RED_SANDSTONE)
Block(-6,0,6,RED_SANDSTONE)
Block(-6,0,7,RED_SANDSTONE)
Block(-6,0,8,RED_SANDSTONE)
Block(-6,0,9,RED_SANDSTONE)
Block(-6,0,10,RED_SANDSTONE)
Block(-6,0,11,RED_SANDSTONE)
Block(-6,0,12,RED_SANDSTONE)
Block(-6,0,13,RED_SANDSTONE)
Block(-6,0,14,RED_SANDSTONE)
Block(-6,1,-9,RED_SANDSTONE)
Block(-6,1,-8,SAND:1)
Block(-6,1,-7,RED_SANDSTONE)
Block(-6,1,-6,RED_SANDSTONE)
Block(-6,1,-5,RED_SANDSTONE)
Block(-6,1,-4,RED_SANDSTONE)
Block(-6,1,-3,RED_SANDSTONE)
Block(-6,1,7,RED_SANDSTONE)
Block(-6,1,8,RED_SANDSTONE)
Block(-6,1,9,RED_SANDSTONE)
Block(-6,1,10,RED_SANDSTONE)
Block(-6,1,11,RED_SANDSTONE)
Block(-6,1,12,RED_SANDSTONE)
Block(-6,1,13,RED_SANDSTONE)
Block(-6,2,-7,RED_SANDSTONE)
Block(-6,2,-6,RED_SANDSTONE)
Block(-6,2,-5,RED_SANDSTONE)
Block(-6,2,-4,STAINED_GLASS:1)
Block(-6,2,8,RED_SANDSTONE)
Block(-6,2,9,RED_SANDSTONE)
Block(-6,2,10,RED_SANDSTONE)
Block(-6,2,11,RED_SANDSTONE)
Block(-6,2,12,RED_SANDSTONE)
Block(-6,2,13,RED_SANDSTONE)
Block(-6,3,-7,RED_SANDSTONE)
Block(-6,3,-6,RED_SANDSTONE)
Block(-6,3,-5,STAINED_GLASS:1)
Block(-6,3,3,RED_SANDSTONE)
Block(-6,3,4,RED_SANDSTONE)
Block(-6,3,9,RED_SANDSTONE)
Block(-6,3,10,RED_SANDSTONE)
Block(-6,3,11,RED_SANDSTONE)
Block(-6,3,12,RED_SANDSTONE)
Block(-6,4,-7,RED_SANDSTONE)
Block(-6,4,-6,RED_SANDSTONE)
Block(-6,4,-5,STAINED_GLASS:1)
Block(-6,4,2,RED_SANDSTONE)
Block(-6,4,3,RED_SANDSTONE)
Block(-6,4,4,RED_SANDSTONE)
Block(-6,4,5,RED_SANDSTONE)
Block(-6,4,6,RED_SANDSTONE)
Block(-6,4,8,RED_SANDSTONE)
Block(-6,4,9,RED_SANDSTONE)
Block(-6,4,10,RED_SANDSTONE)
Block(-6,4,11,RED_SANDSTONE)
Block(-6,5,-6,RED_SANDSTONE)
Block(-6,5,-5,RED_SANDSTONE)
Block(-6,5,0,RED_SANDSTONE)
Block(-6,5,1,RED_SANDSTONE)
Block(-6,5,2,RED_SANDSTONE)
Block(-6,5,3,RED_SANDSTONE)
Block(-6,5,4,RED_SANDSTONE)
Block(-6,5,5,RED_SANDSTONE)
Block(-6,5,6,RED_SANDSTONE)
Block(-6,5,7,RED_SANDSTONE)
Block(-6,5,8,RED_SANDSTONE)
Block(-6,5,9,RED_SANDSTONE)
Block(-6,5,10,RED_SANDSTONE)
Block(-6,6,-5,RED_SANDSTONE)
Block(-6,6,-4,RED_SANDSTONE)
Block(-6,6,-1,RED_SANDSTONE)
Block(-6,6,0,SAND:1)
Block(-6,6,1,SAND:1)
Block(-6,6,3,STAINED_GLASS:1)
Block(-6,6,4,STAINED_GLASS:1)
Block(-6,6,5,RED_SANDSTONE)
Block(-6,6,6,RED_SANDSTONE)
Block(-6,6,7,RED_SANDSTONE)
Block(-6,6,8,RED_SANDSTONE)
Block(-6,6,9,RED_SANDSTONE)
Block(-6,7,-5,RED_SANDSTONE)
Block(-6,7,-4,RED_SANDSTONE)
Block(-6,7,-3,RED_SANDSTONE)
Block(-6,7,-2,RED_SANDSTONE)
Block(-6,7,-1,RED_SANDSTONE)
Block(-6,7,5,RED_SANDSTONE)
Block(-6,7,6,RED_SANDSTONE)
Block(-6,7,7,RED_SANDSTONE)
Block(-6,7,8,RED_SANDSTONE)
Block(-6,8,-4,RED_SANDSTONE)
Block(-6,8,-3,RED_SANDSTONE)
Block(-6,8,-2,RED_SANDSTONE)
Block(-6,8,-1,RED_SANDSTONE)
Block(-6,8,4,STAINED_GLASS:1)
Block(-6,8,5,STAINED_GLASS:1)
Block(-6,8,6,STAINED_GLASS:1)
Block(-6,9,-4,STAINED_GLASS:1)
Block(-6,9,-3,RED_SANDSTONE)
Block(-6,9,-2,RED_SANDSTONE)
Block(-6,9,-1,RED_SANDSTONE)
Block(-6,9,3,RED_SANDSTONE)
Block(-6,9,4,RED_SANDSTONE)
Block(-6,9,5,STAINED_GLASS:1)
Block(-6,10,-4,STAINED_GLASS:1)
Block(-6,10,-3,RED_SANDSTONE)
Block(-6,10,-2,RED_SANDSTONE)
Block(-6,10,-1,RED_SANDSTONE)
Block(-6,10,0,RED_SANDSTONE)
Block(-6,10,1,RED_SANDSTONE)
Block(-6,10,2,RED_SANDSTONE)
Block(-6,10,3,RED_SANDSTONE)
Block(-6,10,4,RED_SANDSTONE)
Block(-6,10,5,STAINED_GLASS:1)
Block(-6,11,-2,RED_SANDSTONE)
Block(-6,11,-1,RED_SANDSTONE)
Block(-6,11,0,RED_SANDSTONE)
Block(-6,11,1,RED_SANDSTONE)
Block(-6,11,2,RED_SANDSTONE)
Block(-6,11,3,RED_SANDSTONE)
Block(-6,12,2,RED_SANDSTONE)
Block(-5,0,-9,RED_SANDSTONE)
Block(-5,0,-8,RED_SANDSTONE)
Block(-5,0,-7,RED_SANDSTONE)
Block(-5,0,-6,RED_SANDSTONE)
Block(-5,0,-5,RED_SANDSTONE)
Block(-5,0,-4,RED_SANDSTONE)
Block(-5,0,-3,RED_SANDSTONE)
Block(-5,0,-2,RED_SANDSTONE)
Block(-5,0,-1,RED_SANDSTONE)
Block(-5,0,0,RED_SANDSTONE)
Block(-5,0,1,RED_SANDSTONE)
Block(-5,0,2,RED_SANDSTONE)
Block(-5,0,3,RED_SANDSTONE)
Block(-5,0,4,RED_SANDSTONE)
Block(-5,0,5,RED_SANDSTONE)
Block(-5,0,6,RED_SANDSTONE)
Block(-5,0,7,RED_SANDSTONE)
Block(-5,0,8,RED_SANDSTONE)
Block(-5,0,9,RED_SANDSTONE)
Block(-5,0,10,RED_SANDSTONE)
Block(-5,0,11,RED_SANDSTONE)
Block(-5,0,12,RED_SANDSTONE)
Block(-5,0,13,RED_SANDSTONE)
Block(-5,0,14,RED_SANDSTONE)
Block(-5,1,-9,RED_SANDSTONE)
Block(-5,1,-8,RED_SANDSTONE)
Block(-5,1,-7,RED_SANDSTONE)
Block(-5,1,-6,RED_SANDSTONE)
Block(-5,1,-5,RED_SANDSTONE)
Block(-5,1,-4,RED_SANDSTONE)
Block(-5,1,2,SAND:1)
Block(-5,1,8,RED_SANDSTONE)
Block(-5,1,9,RED_SANDSTONE)
Block(-5,1,10,RED_SANDSTONE)
Block(-5,1,11,RED_SANDSTONE)
Block(-5,1,12,RED_SANDSTONE)
Block(-5,1,13,RED_SANDSTONE)
Block(-5,1,14,RED_SANDSTONE)
Block(-5,2,-8,STAINED_GLASS:1)
Block(-5,2,-7,RED_SANDSTONE)
Block(-5,2,-6,RED_SANDSTONE)
Block(-5,2,-5,STAINED_GLASS:1)
Block(-5,2,10,RED_SANDSTONE)
Block(-5,2,11,RED_SANDSTONE)
Block(-5,2,12,RED_SANDSTONE)
Block(-5,2,13,RED_SANDSTONE)
Block(-5,3,-7,RED_SANDSTONE)
Block(-5,3,-6,RED_SANDSTONE)
Block(-5,3,10,RED_SANDSTONE)
Block(-5,3,11,RED_SANDSTONE)
Block(-5,3,12,RED_SANDSTONE)
Block(-5,4,-7,RED_SANDSTONE)
Block(-5,4,-6,RED_SANDSTONE)
Block(-5,4,4,RED_SANDSTONE)
Block(-5,4,5,RED_SANDSTONE)
Block(-5,4,9,RED_SANDSTONE)
Block(-5,4,10,RED_SANDSTONE)
Block(-5,4,11,RED_SANDSTONE)
Block(-5,5,-6,RED_SANDSTONE)
Block(-5,5,-5,RED_SANDSTONE)
Block(-5,5,3,RED_SANDSTONE)
Block(-5,5,4,RED_SANDSTONE)
Block(-5,5,5,RED_SANDSTONE)
Block(-5,5,6,RED_SANDSTONE)
Block(-5,5,8,RED_SANDSTONE)
Block(-5,5,9,RED_SANDSTONE)
Block(-5,5,10,RED_SANDSTONE)
Block(-5,6,-6,RED_SANDSTONE)
Block(-5,6,-5,RED_SANDSTONE)
Block(-5,6,0,RED_SANDSTONE)
Block(-5,6,1,RED_SANDSTONE)
Block(-5,6,2,RED_SANDSTONE)
Block(-5,6,3,MOB_SPAWNER,NetherKirlidNest/1-mob_spawner.nbt)
Block(-5,6,4,RED_SANDSTONE)
Block(-5,6,5,RED_SANDSTONE)
Block(-5,6,6,RED_SANDSTONE)
Block(-5,6,8,RED_SANDSTONE)
Block(-5,6,9,RED_SANDSTONE)
Block(-5,6,10,RED_SANDSTONE)
Block(-5,7,-5,RED_SANDSTONE)
Block(-5,7,-4,RED_SANDSTONE)
Block(-5,7,-1,RED_SANDSTONE)
Block(-5,7,0,SAND:1)
Block(-5,7,1,RED_SANDSTONE_STAIRS:0)
Block(-5,7,4,STAINED_GLASS:1)
Block(-5,7,5,RED_SANDSTONE)
Block(-5,7,6,RED_SANDSTONE)
Block(-5,7,7,RED_SANDSTONE)
Block(-5,7,8,RED_SANDSTONE)
Block(-5,7,9,RED_SANDSTONE)
Block(-5,8,-5,STAINED_GLASS:1)
Block(-5,8,-4,RED_SANDSTONE)
Block(-5,8,-3,RED_SANDSTONE)
Block(-5,8,-2,RED_SANDSTONE)
Block(-5,8,-1,RED_SANDSTONE)
Block(-5,8,3,RED_SANDSTONE_STAIRS:6)
Block(-5,8,4,RED_SANDSTONE)
Block(-5,8,5,RED_SANDSTONE)
Block(-5,8,6,RED_SANDSTONE)
Block(-5,8,7,RED_SANDSTONE)
Block(-5,8,8,RED_SANDSTONE)
Block(-5,9,-4,RED_SANDSTONE)
Block(-5,9,-3,RED_SANDSTONE)
Block(-5,9,-2,RED_SANDSTONE)
Block(-5,9,-1,RED_SANDSTONE)
Block(-5,9,0,RED_SANDSTONE)
Block(-5,9,3,RED_SANDSTONE)
Block(-5,9,4,RED_SANDSTONE)
Block(-5,9,5,RED_SANDSTONE)
Block(-5,9,6,RED_SANDSTONE)
Block(-5,9,7,RED_SANDSTONE)
Block(-5,10,-4,STAINED_GLASS:1)
Block(-5,10,-3,RED_SANDSTONE)
Block(-5,10,-2,RED_SANDSTONE)
Block(-5,10,-1,RED_SANDSTONE)
Block(-5,10,0,RED_SANDSTONE)
Block(-5,10,1,RED_SANDSTONE)
Block(-5,10,2,RED_SANDSTONE_STAIRS:5)
Block(-5,10,3,RED_SANDSTONE)
Block(-5,10,4,RED_SANDSTONE)
Block(-5,10,5,RED_SANDSTONE)
Block(-5,10,6,RED_SANDSTONE)
Block(-5,11,-4,SAND:1)
Block(-5,11,-3,RED_SANDSTONE)
Block(-5,11,-2,RED_SANDSTONE)
Block(-5,11,-1,RED_SANDSTONE)
Block(-5,11,0,RED_SANDSTONE)
Block(-5,11,1,RED_SANDSTONE)
Block(-5,11,2,RED_SANDSTONE)
Block(-5,11,3,RED_SANDSTONE)
Block(-5,11,4,RED_SANDSTONE)
Block(-5,11,5,RED_SANDSTONE)
Block(-5,11,6,RED_SANDSTONE)
Block(-5,12,-2,SAND:1)
Block(-5,12,-1,RED_SANDSTONE)
Block(-5,12,0,RED_SANDSTONE)
Block(-5,12,1,RED_SANDSTONE)
Block(-5,12,2,RED_SANDSTONE)
Block(-5,12,3,RED_SANDSTONE)
Block(-5,12,4,RED_SANDSTONE)
Block(-5,12,5,RED_SANDSTONE)
Block(-5,13,-1,RED_SANDSTONE)
Block(-5,13,1,RED_SANDSTONE)
Block(-5,13,2,RED_SANDSTONE)
Block(-5,13,3,RED_SANDSTONE)
Block(-5,13,4,RED_SANDSTONE)
Block(-5,14,-1,RED_SANDSTONE)
Block(-5,14,0,RED_SANDSTONE)
Block(-5,14,2,RED_SANDSTONE)
Block(-5,14,3,RED_SANDSTONE)
Block(-5,14,4,RED_SANDSTONE)
Block(-5,15,-1,RED_SANDSTONE)
Block(-4,0,-11,RED_SANDSTONE)
Block(-4,0,-10,RED_SANDSTONE)
Block(-4,0,-9,RED_SANDSTONE)
Block(-4,0,-8,RED_SANDSTONE)
Block(-4,0,-7,RED_SANDSTONE)
Block(-4,0,-6,RED_SANDSTONE)
Block(-4,0,-5,RED_SANDSTONE)
Block(-4,0,-4,RED_SANDSTONE)
Block(-4,0,-3,RED_SANDSTONE)
Block(-4,0,-2,RED_SANDSTONE)
Block(-4,0,-1,RED_SANDSTONE)
Block(-4,0,0,RED_SANDSTONE)
Block(-4,0,1,RED_SANDSTONE)
Block(-4,0,2,RED_SANDSTONE)
Block(-4,0,3,RED_SANDSTONE)
Block(-4,0,4,RED_SANDSTONE)
Block(-4,0,5,RED_SANDSTONE)
Block(-4,0,6,RED_SANDSTONE)
Block(-4,0,7,RED_SANDSTONE)
Block(-4,0,8,RED_SANDSTONE)
Block(-4,0,9,RED_SANDSTONE)
Block(-4,0,10,RED_SANDSTONE)
Block(-4,0,11,RED_SANDSTONE)
Block(-4,0,12,RED_SANDSTONE)
Block(-4,0,13,RED_SANDSTONE)
Block(-4,1,-9,RED_SANDSTONE)
Block(-4,1,-8,RED_SANDSTONE)
Block(-4,1,-7,RED_SANDSTONE)
Block(-4,1,-6,RED_SANDSTONE)
Block(-4,1,-5,RED_SANDSTONE)
Block(-4,1,-4,RED_SANDSTONE_STAIRS:0)
Block(-4,1,4,SAND:1)
Block(-4,1,10,RED_SANDSTONE)
Block(-4,1,11,RED_SANDSTONE)
Block(-4,1,12,RED_SANDSTONE)
Block(-4,1,13,RED_SANDSTONE)
Block(-4,2,-8,STAINED_GLASS:1)
Block(-4,2,-7,RED_SANDSTONE)
Block(-4,2,-6,STAINED_GLASS:1)
Block(-4,2,-5,STAINED_GLASS:1)
Block(-4,2,11,RED_SANDSTONE)
Block(-4,2,12,RED_SANDSTONE)
Block(-4,2,13,RED_SANDSTONE)
Block(-4,3,-7,STAINED_GLASS:1)
Block(-4,3,-6,STAINED_GLASS:1)
Block(-4,3,11,RED_SANDSTONE)
Block(-4,3,12,RED_SANDSTONE)
Block(-4,4,-7,RED_SANDSTONE)
Block(-4,4,-6,STAINED_GLASS:1)
Block(-4,4,3,RED_SANDSTONE)
Block(-4,4,10,RED_SANDSTONE)
Block(-4,4,11,RED_SANDSTONE)
Block(-4,5,-6,RED_SANDSTONE)
Block(-4,5,-5,RED_SANDSTONE)
Block(-4,5,2,RED_SANDSTONE)
Block(-4,5,3,RED_SANDSTONE)
Block(-4,5,10,RED_SANDSTONE)
Block(-4,5,11,RED_SANDSTONE)
Block(-4,6,-6,RED_SANDSTONE)
Block(-4,6,-5,RED_SANDSTONE)
Block(-4,6,1,RED_SANDSTONE)
Block(-4,6,2,RED_SANDSTONE)
Block(-4,6,3,RED_SANDSTONE)
Block(-4,6,4,RED_SANDSTONE)
Block(-4,6,9,RED_SANDSTONE)
Block(-4,6,10,RED_SANDSTONE)
Block(-4,7,-5,RED_SANDSTONE)
Block(-4,7,-4,RED_SANDSTONE)
Block(-4,7,9,RED_SANDSTONE)
Block(-4,7,10,RED_SANDSTONE)
Block(-4,8,-5,RED_SANDSTONE)
Block(-4,8,-4,RED_SANDSTONE)
Block(-4,8,-3,RED_SANDSTONE)
Block(-4,8,6,RED_SANDSTONE)
Block(-4,8,7,RED_SANDSTONE)
Block(-4,8,8,RED_SANDSTONE)
Block(-4,8,9,RED_SANDSTONE)
Block(-4,9,-5,STAINED_GLASS:1)
Block(-4,9,-4,RED_SANDSTONE)
Block(-4,9,-3,RED_SANDSTONE)
Block(-4,9,-2,RED_SANDSTONE)
Block(-4,9,-1,RED_SANDSTONE)
Block(-4,9,5,RED_SANDSTONE)
Block(-4,9,6,RED_SANDSTONE)
Block(-4,9,7,RED_SANDSTONE)
Block(-4,9,8,RED_SANDSTONE)
Block(-4,10,-5,SAND:1)
Block(-4,10,-4,RED_SANDSTONE)
Block(-4,10,-3,RED_SANDSTONE)
Block(-4,10,-2,RED_SANDSTONE)
Block(-4,10,-1,RED_SANDSTONE)
Block(-4,10,0,RED_SANDSTONE)
Block(-4,10,1,RED_SANDSTONE)
Block(-4,10,5,RED_SANDSTONE)
Block(-4,10,6,RED_SANDSTONE)
Block(-4,10,7,RED_SANDSTONE)
Block(-4,10,8,RED_SANDSTONE)
Block(-4,11,-4,SAND:1)
Block(-4,11,-3,SAND:1)
Block(-4,11,-2,STAINED_GLASS:1)
Block(-4,11,-1,RED_SANDSTONE)
Block(-4,11,0,RED_SANDSTONE)
Block(-4,11,1,RED_SANDSTONE)
Block(-4,11,4,RED_SANDSTONE)
Block(-4,11,5,RED_SANDSTONE)
Block(-4,11,6,RED_SANDSTONE)
Block(-4,11,7,RED_SANDSTONE_STAIRS:0)
Block(-4,12,-2,STAINED_GLASS:1)
Block(-4,12,-1,RED_SANDSTONE)
Block(-4,12,0,RED_SANDSTONE)
Block(-4,12,1,RED_SANDSTONE)
Block(-4,12,3,RED_SANDSTONE)
Block(-4,12,4,RED_SANDSTONE)
Block(-4,13,-1,RED_SANDSTONE)
Block(-4,13,0,RED_SANDSTONE)
Block(-4,13,1,RED_SANDSTONE)
Block(-4,13,2,RED_SANDSTONE)
Block(-4,13,3,RED_SANDSTONE)
Block(-4,13,4,RED_SANDSTONE)
Block(-4,14,-1,RED_SANDSTONE)
Block(-4,14,0,RED_SANDSTONE)
Block(-4,14,1,RED_SANDSTONE)
Block(-4,14,2,RED_SANDSTONE)
Block(-4,14,3,RED_SANDSTONE)
Block(-4,14,4,RED_SANDSTONE)
Block(-4,15,-2,RED_SANDSTONE)
Block(-4,15,-1,RED_SANDSTONE)
Block(-4,15,0,RED_SANDSTONE)
Block(-4,15,1,RED_SANDSTONE)
Block(-4,15,2,RED_SANDSTONE)
Block(-4,15,3,RED_SANDSTONE)
Block(-4,15,4,SAND:1)
Block(-4,16,-1,RED_SANDSTONE)
Block(-4,16,0,RED_SANDSTONE)
Block(-4,16,3,SAND:1)
Block(-4,17,-1,RED_SANDSTONE)
Block(-3,0,-11,RED_SANDSTONE)
Block(-3,0,-10,RED_SANDSTONE)
Block(-3,0,-9,RED_SANDSTONE)
Block(-3,0,-8,RED_SANDSTONE)
Block(-3,0,-7,RED_SANDSTONE)
Block(-3,0,-6,RED_SANDSTONE)
Block(-3,0,-5,RED_SANDSTONE)
Block(-3,0,-4,RED_SANDSTONE)
Block(-3,0,-3,RED_SANDSTONE)
Block(-3,0,-2,RED_SANDSTONE)
Block(-3,0,-1,RED_SANDSTONE)
Block(-3,0,0,RED_SANDSTONE)
Block(-3,0,1,RED_SANDSTONE)
Block(-3,0,2,RED_SANDSTONE)
Block(-3,0,3,RED_SANDSTONE)
Block(-3,0,4,RED_SANDSTONE)
Block(-3,0,5,RED_SANDSTONE)
Block(-3,0,6,RED_SANDSTONE)
Block(-3,0,7,RED_SANDSTONE)
Block(-3,0,8,RED_SANDSTONE)
Block(-3,0,9,RED_SANDSTONE)
Block(-3,0,10,RED_SANDSTONE)
Block(-3,0,11,RED_SANDSTONE)
Block(-3,0,12,RED_SANDSTONE)
Block(-3,0,13,RED_SANDSTONE)
Block(-3,1,-9,STAINED_GLASS:1)
Block(-3,1,-8,RED_SANDSTONE)
Block(-3,1,-7,RED_SANDSTONE)
Block(-3,1,-6,RED_SANDSTONE)
Block(-3,1,-5,RED_SANDSTONE)
Block(-3,1,-4,RED_SANDSTONE)
Block(-3,1,-3,RED_SANDSTONE_STAIRS:0)
Block(-3,1,3,SAND:1)
Block(-3,1,4,RED_SANDSTONE)
Block(-3,1,5,SAND:1)
Block(-3,1,10,STAINED_GLASS:1)
Block(-3,1,11,RED_SANDSTONE)
Block(-3,1,12,RED_SANDSTONE)
Block(-3,1,13,RED_SANDSTONE)
Block(-3,2,-7,STAINED_GLASS:1)
Block(-3,2,-6,STAINED_GLASS:1)
Block(-3,2,4,RED_SANDSTONE)
Block(-3,2,11,RED_SANDSTONE)
Block(-3,2,12,RED_SANDSTONE)
Block(-3,3,11,RED_SANDSTONE)
Block(-3,3,12,RED_SANDSTONE)
Block(-3,4,10,RED_SANDSTONE)
Block(-3,4,11,RED_SANDSTONE)
Block(-3,5,-6,RED_SANDSTONE)
Block(-3,5,10,RED_SANDSTONE)
Block(-3,5,11,RED_SANDSTONE)
Block(-3,6,-6,RED_SANDSTONE)
Block(-3,6,-5,RED_SANDSTONE)
Block(-3,6,10,RED_SANDSTONE)
Block(-3,6,11,RED_SANDSTONE)
Block(-3,7,-6,RED_SANDSTONE)
Block(-3,7,-5,RED_SANDSTONE)
Block(-3,7,-4,RED_SANDSTONE)
Block(-3,7,9,RED_SANDSTONE)
Block(-3,7,10,RED_SANDSTONE)
Block(-3,8,-6,RED_SANDSTONE)
Block(-3,8,-5,RED_SANDSTONE)
Block(-3,8,-4,RED_SANDSTONE)
Block(-3,8,-3,RED_SANDSTONE)
Block(-3,8,8,RED_SANDSTONE)
Block(-3,8,9,RED_SANDSTONE)
Block(-3,9,-5,RED_SANDSTONE)
Block(-3,9,-4,RED_SANDSTONE)
Block(-3,9,-3,RED_SANDSTONE)
Block(-3,9,-2,RED_SANDSTONE)
Block(-3,9,-1,STAINED_GLASS:1)
Block(-3,9,6,RED_SANDSTONE)
Block(-3,9,8,RED_SANDSTONE)
Block(-3,9,9,RED_SANDSTONE)
Block(-3,10,-5,SAND:1)
Block(-3,10,-4,SAND:1)
Block(-3,10,-3,RED_SANDSTONE)
Block(-3,10,-2,RED_SANDSTONE)
Block(-3,10,-1,RED_SANDSTONE)
Block(-3,10,0,STAINED_GLASS:1)
Block(-3,10,5,RED_SANDSTONE)
Block(-3,10,6,RED_SANDSTONE)
Block(-3,10,7,RED_SANDSTONE)
Block(-3,10,8,RED_SANDSTONE)
Block(-3,10,9,STAINED_GLASS:1)
Block(-3,11,-3,RED_SANDSTONE_STAIRS:1)
Block(-3,11,-2,STAINED_GLASS:1)
Block(-3,11,-1,STAINED_GLASS:1)
Block(-3,11,0,RED_SANDSTONE)
Block(-3,11,8,STAINED_GLASS:1)
Block(-3,12,-2,STAINED_GLASS:1)
Block(-3,12,-1,RED_SANDSTONE)
Block(-3,12,0,RED_SANDSTONE)
Block(-3,13,-1,RED_SANDSTONE_STAIRS:1)
Block(-3,13,0,RED_SANDSTONE)
Block(-3,14,-2,RED_SANDSTONE)
Block(-3,14,1,RED_SANDSTONE)
Block(-3,14,5,RED_SANDSTONE)
Block(-3,15,-2,RED_SANDSTONE)
Block(-3,15,0,RED_SANDSTONE)
Block(-3,15,1,RED_SANDSTONE)
Block(-3,15,2,RED_SANDSTONE)
Block(-3,15,3,RED_SANDSTONE)
Block(-3,15,4,RED_SANDSTONE)
Block(-3,15,5,RED_SANDSTONE)
Block(-3,15,6,RED_SANDSTONE)
Block(-3,16,-3,RED_SANDSTONE)
Block(-3,16,-2,RED_SANDSTONE)
Block(-3,16,-1,RED_SANDSTONE)
Block(-3,16,0,RED_SANDSTONE)
Block(-3,16,1,RED_SANDSTONE)
Block(-3,16,2,RED_SANDSTONE)
Block(-3,16,3,RED_SANDSTONE)
Block(-3,16,4,RED_SANDSTONE)
Block(-3,16,5,SAND:1)
Block(-3,16,6,STAINED_GLASS:1)
Block(-3,17,-1,RED_SANDSTONE)
Block(-3,17,0,RED_SANDSTONE)
Block(-3,17,1,RED_SANDSTONE)
Block(-3,17,2,RED_SANDSTONE)
Block(-3,17,3,SAND:1)
Block(-3,17,4,SAND:1)
Block(-3,18,-1,RED_SANDSTONE)
Block(-3,18,0,RED_SANDSTONE)
Block(-3,18,1,RED_SANDSTONE)
Block(-3,19,0,RED_SANDSTONE)
Block(-2,0,-9,RED_SANDSTONE)
Block(-2,0,-8,RED_SANDSTONE)
Block(-2,0,-7,RED_SANDSTONE)
Block(-2,0,-6,RED_SANDSTONE)
Block(-2,0,-5,RED_SANDSTONE)
Block(-2,0,-4,RED_SANDSTONE)
Block(-2,0,-3,RED_SANDSTONE)
Block(-2,0,-2,RED_SANDSTONE)
Block(-2,0,-1,RED_SANDSTONE)
Block(-2,0,0,RED_SANDSTONE)
Block(-2,0,1,RED_SANDSTONE)
Block(-2,0,2,RED_SANDSTONE)
Block(-2,0,3,RED_SANDSTONE)
Block(-2,0,4,RED_SANDSTONE)
Block(-2,0,5,RED_SANDSTONE)
Block(-2,0,6,RED_SANDSTONE)
Block(-2,0,7,RED_SANDSTONE)
Block(-2,0,8,RED_SANDSTONE)
Block(-2,0,9,RED_SANDSTONE)
Block(-2,0,10,RED_SANDSTONE)
Block(-2,0,11,RED_SANDSTONE)
Block(-2,0,12,RED_SANDSTONE)
Block(-2,0,13,RED_SANDSTONE)
Block(-2,0,14,RED_SANDSTONE)
Block(-2,1,-8,STAINED_GLASS:1)
Block(-2,1,-7,STAINED_GLASS:1)
Block(-2,1,-6,SAND:1)
Block(-2,1,-5,SAND:1)
Block(-2,1,-4,RED_SANDSTONE)
Block(-2,1,-3,RED_SANDSTONE_STAIRS:0)
Block(-2,1,2,RED_SANDSTONE_STAIRS:0)
Block(-2,1,3,RED_SANDSTONE)
Block(-2,1,4,RED_SANDSTONE)
Block(-2,1,5,RED_SANDSTONE)
Block(-2,1,6,SAND:1)
Block(-2,1,9,STAINED_GLASS:1)
Block(-2,1,10,STAINED_GLASS:1)
Block(-2,1,11,RED_SANDSTONE)
Block(-2,1,12,RED_SANDSTONE)
Block(-2,2,3,RED_SANDSTONE)
Block(-2,2,4,RED_SANDSTONE_STAIRS:0)
Block(-2,2,9,STAINED_GLASS:1)
Block(-2,2,11,RED_SANDSTONE)
Block(-2,2,12,RED_SANDSTONE)
Block(-2,3,9,STAINED_GLASS:1)
Block(-2,3,10,RED_SANDSTONE)
Block(-2,3,11,RED_SANDSTONE)
Block(-2,4,9,STAINED_GLASS:1)
Block(-2,4,10,RED_SANDSTONE)
Block(-2,4,11,RED_SANDSTONE)
Block(-2,5,-1,STAINED_GLASS_PANE:1)
Block(-2,5,9,STAINED_GLASS_PANE:1)
Block(-2,5,10,RED_SANDSTONE)
Block(-2,5,11,RED_SANDSTONE)
Block(-2,6,-6,RED_SANDSTONE)
Block(-2,6,-5,RED_SANDSTONE)
Block(-2,6,-4,RED_SANDSTONE)
Block(-2,6,-1,STAINED_GLASS_PANE:1)
Block(-2,6,10,RED_SANDSTONE)
Block(-2,6,11,RED_SANDSTONE)
Block(-2,7,-6,RED_SANDSTONE)
Block(-2,7,-5,RED_SANDSTONE)
Block(-2,7,-1,STAINED_GLASS:1)
Block(-2,7,9,RED_SANDSTONE)
Block(-2,7,10,RED_SANDSTONE)
Block(-2,8,-6,RED_SANDSTONE)
Block(-2,8,-5,RED_SANDSTONE)
Block(-2,8,-4,RED_SANDSTONE_STAIRS:7)
Block(-2,8,-1,STAINED_GLASS:1)
Block(-2,8,0,STAINED_GLASS_PANE:1)
Block(-2,8,8,RED_SANDSTONE)
Block(-2,8,9,RED_SANDSTONE)
Block(-2,9,-6,RED_SANDSTONE)
Block(-2,9,-5,RED_SANDSTONE)
Block(-2,9,-4,RED_SANDSTONE)
Block(-2,9,-3,RED_SANDSTONE)
Block(-2,9,-2,RED_SANDSTONE_STAIRS:7)
Block(-2,9,-1,STAINED_GLASS:1)
Block(-2,9,0,STAINED_GLASS_PANE:1)
Block(-2,9,6,RED_SANDSTONE_STAIRS:6)
Block(-2,9,7,RED_SANDSTONE)
Block(-2,9,8,RED_SANDSTONE)
Block(-2,9,9,STAINED_GLASS:1)
Block(-2,10,-6,RED_SANDSTONE)
Block(-2,10,-5,SAND:1)
Block(-2,10,-4,SAND:1)
Block(-2,10,-3,MOB_SPAWNER,NetherKirlidNest/2-mob_spawner.nbt)
Block(-2,10,-2,STAINED_GLASS:1)
Block(-2,10,-1,STAINED_GLASS:1)
Block(-2,10,0,STAINED_GLASS_PANE:1)
Block(-2,10,5,RED_SANDSTONE_STAIRS:5)
Block(-2,10,6,MOB_SPAWNER,NetherKirlidNest/3-mob_spawner.nbt)
Block(-2,10,7,RED_SANDSTONE)
Block(-2,10,8,RED_SANDSTONE)
Block(-2,10,9,STAINED_GLASS:1)
Block(-2,11,-6,RED_SANDSTONE)
Block(-2,11,-1,STAINED_GLASS:1)
Block(-2,11,7,RED_SANDSTONE_STAIRS:2)
Block(-2,11,8,RED_SANDSTONE)
Block(-2,11,9,STAINED_GLASS:1)
Block(-2,12,7,STAINED_GLASS:1)
Block(-2,12,8,STAINED_GLASS:1)
Block(-2,13,7,STAINED_GLASS_PANE:1)
Block(-2,15,-3,RED_SANDSTONE)
Block(-2,15,0,STAINED_GLASS_PANE:1)
Block(-2,15,1,STAINED_GLASS:1)
Block(-2,15,5,RED_SANDSTONE)
Block(-2,15,6,RED_SANDSTONE)
Block(-2,15,7,STAINED_GLASS:1)
Block(-2,16,-3,RED_SANDSTONE)
Block(-2,16,-2,RED_SANDSTONE)
Block(-2,16,0,STAINED_GLASS:1)
Block(-2,16,1,RED_SANDSTONE)
Block(-2,16,2,RED_SANDSTONE)
Block(-2,16,4,RED_SANDSTONE)
Block(-2,16,5,RED_SANDSTONE)
Block(-2,16,6,RED_SANDSTONE)
Block(-2,16,7,STAINED_GLASS:1)
Block(-2,17,-3,RED_SANDSTONE)
Block(-2,17,-2,RED_SANDSTONE)
Block(-2,17,-1,RED_SANDSTONE)
Block(-2,17,0,RED_SANDSTONE)
Block(-2,17,1,RED_SANDSTONE)
Block(-2,17,2,RED_SANDSTONE)
Block(-2,17,3,RED_SANDSTONE)
Block(-2,17,4,SAND:1)
Block(-2,17,5,SAND:1)
Block(-2,17,6,STAINED_GLASS:1)
Block(-2,18,-1,RED_SANDSTONE)
Block(-2,18,0,RED_SANDSTONE)
Block(-2,18,1,RED_SANDSTONE)
Block(-2,18,2,RED_SANDSTONE)
Block(-2,18,3,SAND:1)
Block(-2,19,-1,RED_SANDSTONE)
Block(-2,19,0,RED_SANDSTONE)
Block(-2,19,1,RED_SANDSTONE)
Block(-2,19,2,SAND:1)
Block(-2,20,-1,RED_SANDSTONE)
Block(-2,20,0,RED_SANDSTONE)
Block(-2,20,1,RED_SANDSTONE)
Block(-2,20,2,STAINED_GLASS:1)
Block(-2,21,-1,RED_SANDSTONE)
Block(-2,21,0,RED_SANDSTONE)
Block(-2,21,1,RED_SANDSTONE)
Block(-2,21,2,STAINED_GLASS:1)
Block(-2,22,-1,RED_SANDSTONE)
Block(-2,22,0,RED_SANDSTONE)
Block(-2,22,1,RED_SANDSTONE)
Block(-2,22,2,STAINED_GLASS:1)
Block(-2,23,1,STAINED_GLASS:1)
Block(-1,0,-7,RED_SANDSTONE)
Block(-1,0,-6,RED_SANDSTONE)
Block(-1,0,-5,RED_SANDSTONE)
Block(-1,0,-4,RED_SANDSTONE)
Block(-1,0,-3,RED_SANDSTONE)
Block(-1,0,-2,RED_SANDSTONE)
Block(-1,0,-1,RED_SANDSTONE)
Block(-1,0,0,RED_SANDSTONE)
Block(-1,0,1,RED_SANDSTONE)
Block(-1,0,2,RED_SANDSTONE)
Block(-1,0,3,RED_SANDSTONE)
Block(-1,0,4,RED_SANDSTONE)
Block(-1,0,5,RED_SANDSTONE)
Block(-1,0,6,RED_SANDSTONE)
Block(-1,0,7,RED_SANDSTONE)
Block(-1,0,8,RED_SANDSTONE)
Block(-1,0,9,RED_SANDSTONE)
Block(-1,0,10,RED_SANDSTONE)
Block(-1,0,11,RED_SANDSTONE)
Block(-1,0,12,RED_SANDSTONE)
Block(-1,0,13,RED_SANDSTONE)
Block(-1,1,-6,SAND:1)
Block(-1,1,-5,SAND:1)
Block(-1,1,-4,SAND:1)
Block(-1,1,-3,RED_SANDSTONE_STAIRS:1)
Block(-1,1,0,RED_SANDSTONE_STAIRS:2)
Block(-1,1,1,RED_SANDSTONE)
Block(-1,1,2,RED_SANDSTONE)
Block(-1,1,3,RED_SANDSTONE)
Block(-1,1,4,RED_SANDSTONE)
Block(-1,1,5,RED_SANDSTONE)
Block(-1,1,6,RED_SANDSTONE)
Block(-1,1,12,RED_SANDSTONE)
Block(-1,2,1,RED_SANDSTONE)
Block(-1,2,2,RED_SANDSTONE)
Block(-1,2,3,RED_SANDSTONE)
Block(-1,2,4,RED_SANDSTONE)
Block(-1,2,5,RED_SANDSTONE)
Block(-1,2,6,STAINED_GLASS:1)
Block(-1,3,2,RED_SANDSTONE)
Block(-1,3,4,RED_SANDSTONE)
Block(-1,3,5,STAINED_GLASS:1)
Block(-1,3,10,STAINED_GLASS:1)
Block(-1,4,2,RED_SANDSTONE)
Block(-1,4,4,RED_SANDSTONE_STAIRS:0)
Block(-1,4,10,STAINED_GLASS:1)
Block(-1,5,8,STAINED_GLASS_PANE:1)
Block(-1,5,9,STAINED_GLASS:1)
Block(-1,5,10,RED_SANDSTONE)
Block(-1,6,-7,RED_SANDSTONE)
Block(-1,6,-6,RED_SANDSTONE)
Block(-1,6,-5,RED_SANDSTONE)
Block(-1,6,-1,STAINED_GLASS_PANE:1)
Block(-1,6,10,RED_SANDSTONE)
Block(-1,6,11,RED_SANDSTONE)
Block(-1,7,-6,RED_SANDSTONE)
Block(-1,7,-5,RED_SANDSTONE)
Block(-1,7,-1,STAINED_GLASS_PANE:1)
Block(-1,7,9,RED_SANDSTONE)
Block(-1,7,10,RED_SANDSTONE)
Block(-1,8,-6,RED_SANDSTONE)
Block(-1,8,-5,RED_SANDSTONE)
Block(-1,8,7,RED_SANDSTONE_STAIRS:6)
Block(-1,8,8,RED_SANDSTONE)
Block(-1,8,9,RED_SANDSTONE)
Block(-1,9,-6,RED_SANDSTONE)
Block(-1,9,-5,RED_SANDSTONE)
Block(-1,9,-1,STAINED_GLASS_PANE:1)
Block(-1,9,7,RED_SANDSTONE)
Block(-1,9,8,RED_SANDSTONE)
Block(-1,9,9,RED_SANDSTONE)
Block(-1,10,-6,RED_SANDSTONE)
Block(-1,10,-5,RED_SANDSTONE)
Block(-1,10,-4,RED_SANDSTONE)
Block(-1,10,-3,RED_SANDSTONE)
Block(-1,10,-2,RED_SANDSTONE)
Block(-1,10,-1,STAINED_GLASS:1)
Block(-1,10,6,RED_SANDSTONE)
Block(-1,10,7,RED_SANDSTONE)
Block(-1,10,8,STAINED_GLASS:1)
Block(-1,10,9,RED_SANDSTONE)
Block(-1,11,-6,RED_SANDSTONE)
Block(-1,11,-5,SAND:1)
Block(-1,11,-4,SAND:1)
Block(-1,11,-2,STAINED_GLASS:1)
Block(-1,11,-1,STAINED_GLASS_PANE:1)
Block(-1,11,4,STAINED_GLASS_PANE:1)
Block(-1,11,5,STAINED_GLASS:1)
Block(-1,11,6,RED_SANDSTONE)
Block(-1,11,7,RED_SANDSTONE)
Block(-1,11,8,STAINED_GLASS:1)
Block(-1,11,9,RED_SANDSTONE)
Block(-1,12,-6,RED_SANDSTONE)
Block(-1,12,-5,SAND:1)
Block(-1,12,1,STAINED_GLASS_PANE:1)
Block(-1,12,5,STAINED_GLASS_PANE:1)
Block(-1,12,6,RED_SANDSTONE_STAIRS:0)
Block(-1,12,7,RED_SANDSTONE)
Block(-1,12,8,RED_SANDSTONE)
Block(-1,13,-6,SAND:1)
Block(-1,13,-5,SAND:1)
Block(-1,13,-4,RED_SANDSTONE)
Block(-1,13,1,STAINED_GLASS:1)
Block(-1,13,6,STAINED_GLASS:1)
Block(-1,13,7,STAINED_GLASS:1)
Block(-1,13,8,STAINED_GLASS:1)
Block(-1,14,-5,SAND:1)
Block(-1,14,-4,RED_SANDSTONE)
Block(-1,14,1,STAINED_GLASS:1)
Block(-1,14,2,STAINED_GLASS:1)
Block(-1,14,6,STAINED_GLASS:1)
Block(-1,14,7,RED_SANDSTONE)
Block(-1,15,-5,SAND:1)
Block(-1,15,-4,RED_SANDSTONE)
Block(-1,15,-3,RED_SANDSTONE)
Block(-1,15,1,STAINED_GLASS:1)
Block(-1,15,2,STAINED_GLASS:1)
Block(-1,15,6,RED_SANDSTONE)
Block(-1,15,7,RED_SANDSTONE)
Block(-1,16,-5,RED_SANDSTONE)
Block(-1,16,-4,RED_SANDSTONE)
Block(-1,16,-3,RED_SANDSTONE)
Block(-1,16,0,STAINED_GLASS_PANE:1)
Block(-1,16,1,STAINED_GLASS:1)
Block(-1,16,2,STAINED_GLASS:1)
Block(-1,16,5,RED_SANDSTONE)
Block(-1,16,6,RED_SANDSTONE)
Block(-1,16,7,STAINED_GLASS:1)
Block(-1,17,-4,RED_SANDSTONE)
Block(-1,17,-3,RED_SANDSTONE)
Block(-1,17,-2,RED_SANDSTONE)
Block(-1,17,0,STAINED_GLASS_PANE:1)
Block(-1,17,1,STAINED_GLASS:1)
Block(-1,17,2,STAINED_GLASS:1)
Block(-1,17,4,RED_SANDSTONE)
Block(-1,17,5,SAND:1)
Block(-1,17,6,SAND:1)
Block(-1,18,-2,RED_SANDSTONE)
Block(-1,18,-1,RED_SANDSTONE)
Block(-1,18,0,STAINED_GLASS:1)
Block(-1,18,2,RED_SANDSTONE)
Block(-1,18,3,RED_SANDSTONE)
Block(-1,18,4,SAND:1)
Block(-1,19,-1,RED_SANDSTONE)
Block(-1,19,0,RED_SANDSTONE)
Block(-1,19,1,RED_SANDSTONE)
Block(-1,19,2,RED_SANDSTONE)
Block(-1,19,3,SAND:1)
Block(-1,20,-1,RED_SANDSTONE)
Block(-1,20,0,RED_SANDSTONE)
Block(-1,20,1,RED_SANDSTONE)
Block(-1,20,2,RED_SANDSTONE)
Block(-1,21,-2,STAINED_GLASS:1)
Block(-1,21,-1,RED_SANDSTONE)
Block(-1,21,0,RED_SANDSTONE)
Block(-1,21,1,RED_SANDSTONE)
Block(-1,21,2,STAINED_GLASS:1)
Block(-1,22,-2,STAINED_GLASS:1)
Block(-1,22,-1,RED_SANDSTONE)
Block(-1,22,0,SAND:1)
Block(-1,22,1,RED_SANDSTONE)
Block(-1,22,2,STAINED_GLASS:1)
Block(-1,22,3,STAINED_GLASS:1)
Block(-1,23,-2,STAINED_GLASS:1)
Block(-1,23,-1,RED_SANDSTONE)
Block(-1,23,0,RED_SANDSTONE)
Block(-1,23,1,RED_SANDSTONE)
Block(-1,23,2,STAINED_GLASS:1)
Block(-1,24,-1,RED_SANDSTONE)
Block(-1,24,0,RED_SANDSTONE)
Block(-1,24,1,STAINED_GLASS:1)
Block(-1,24,2,STAINED_GLASS:1)
Block(-1,25,-1,RED_SANDSTONE)
Block(-1,25,0,RED_SANDSTONE)
Block(0,0,-8,RED_SANDSTONE)
Block(0,0,-7,RED_SANDSTONE)
Block(0,0,-6,RED_SANDSTONE)
Block(0,0,-5,RED_SANDSTONE)
Block(0,0,-4,RED_SANDSTONE)
Block(0,0,-3,RED_SANDSTONE)
Block(0,0,-2,RED_SANDSTONE)
Block(0,0,-1,RED_SANDSTONE)
Block(0,0,0,RED_SANDSTONE)
Block(0,0,1,RED_SANDSTONE)
Block(0,0,2,RED_SANDSTONE)
Block(0,0,3,RED_SANDSTONE)
Block(0,0,4,RED_SANDSTONE)
Block(0,0,5,RED_SANDSTONE)
Block(0,0,6,RED_SANDSTONE)
Block(0,0,7,RED_SANDSTONE)
Block(0,0,8,RED_SANDSTONE)
Block(0,0,9,RED_SANDSTONE)
Block(0,0,10,RED_SANDSTONE)
Block(0,0,11,RED_SANDSTONE)
Block(0,0,12,RED_SANDSTONE)
Block(0,0,13,RED_SANDSTONE)
Block(0,1,-8,RED_SANDSTONE)
Block(0,1,-7,RED_SANDSTONE)
Block(0,1,-6,RED_SANDSTONE)
Block(0,1,-5,SAND:1)
Block(0,1,-4,SAND:1)
Block(0,1,1,RED_SANDSTONE)
Block(0,1,2,RED_SANDSTONE)
Block(0,1,3,RED_SANDSTONE)
Block(0,1,4,RED_SANDSTONE)
Block(0,1,5,RED_SANDSTONE)
Block(0,1,6,RED_SANDSTONE)
Block(0,1,7,RED_SANDSTONE)
Block(0,2,-8,RED_SANDSTONE)
Block(0,2,-7,RED_SANDSTONE)
Block(0,2,2,MOB_SPAWNER,NetherKirlidNest/4-mob_spawner.nbt)
Block(0,2,3,RED_SANDSTONE)
Block(0,2,4,RED_SANDSTONE)
Block(0,2,5,MOB_SPAWNER,NetherKirlidNest/5-mob_spawner.nbt)
Block(0,2,6,STAINED_GLASS:1)
Block(0,3,-8,RED_SANDSTONE)
Block(0,3,2,RED_SANDSTONE)
Block(0,3,3,RED_SANDSTONE)
Block(0,3,4,RED_SANDSTONE)
Block(0,4,2,RED_SANDSTONE)
Block(0,4,3,RED_SANDSTONE)
Block(0,4,4,STAINED_GLASS:1)
Block(0,5,-6,RED_SANDSTONE)
Block(0,5,2,RED_SANDSTONE)
Block(0,5,3,RED_SANDSTONE)
Block(0,5,8,STAINED_GLASS_PANE:1)
Block(0,5,9,STAINED_GLASS:1)
Block(0,5,10,STAINED_GLASS:1)
Block(0,6,-7,RED_SANDSTONE)
Block(0,6,-6,RED_SANDSTONE)
Block(0,6,2,CHEST,NetherKirlidNest/6-chest.nbt)
Block(0,6,3,RED_SANDSTONE_STAIRS:0)
Block(0,6,5,STAINED_GLASS_PANE:1)
Block(0,6,7,STAINED_GLASS_PANE:1)
Block(0,6,8,STAINED_GLASS:1)
Block(0,6,9,RED_SANDSTONE)
Block(0,6,10,RED_SANDSTONE)
Block(0,7,-7,RED_SANDSTONE)
Block(0,7,-6,RED_SANDSTONE)
Block(0,7,5,STAINED_GLASS:1)
Block(0,7,7,STAINED_GLASS_PANE:1)
Block(0,7,8,RED_SANDSTONE)
Block(0,7,9,RED_SANDSTONE)
Block(0,8,-6,RED_SANDSTONE)
Block(0,8,-5,RED_SANDSTONE)
Block(0,8,5,STAINED_GLASS:1)
Block(0,8,7,RED_SANDSTONE)
Block(0,8,8,RED_SANDSTONE)
Block(0,8,9,STAINED_GLASS:1)
Block(0,9,-6,SAND:1)
Block(0,9,-5,RED_SANDSTONE)
Block(0,9,4,STAINED_GLASS_PANE:1)
Block(0,9,5,STAINED_GLASS:1)
Block(0,9,6,RED_SANDSTONE)
Block(0,9,7,RED_SANDSTONE)
Block(0,9,8,STAINED_GLASS:1)
Block(0,9,9,STAINED_GLASS:1)
Block(0,10,-6,SAND:1)
Block(0,10,-5,RED_SANDSTONE)
Block(0,10,-4,RED_SANDSTONE)
Block(0,10,-3,RED_SANDSTONE)
Block(0,10,-2,RED_SANDSTONE_STAIRS:5)
Block(0,10,4,STAINED_GLASS_PANE:1)
Block(0,10,5,STAINED_GLASS:1)
Block(0,10,6,RED_SANDSTONE)
Block(0,10,7,RED_SANDSTONE)
Block(0,10,8,STAINED_GLASS:1)
Block(0,10,9,STAINED_GLASS:1)
Block(0,11,-6,SAND:1)
Block(0,11,-5,RED_SANDSTONE)
Block(0,11,-4,RED_SANDSTONE)
Block(0,11,-3,RED_SANDSTONE_STAIRS:0)
Block(0,11,4,STAINED_GLASS_PANE:1)
Block(0,11,5,STAINED_GLASS:1)
Block(0,11,6,STAINED_GLASS:1)
Block(0,11,7,RED_SANDSTONE)
Block(0,11,8,STAINED_GLASS:1)
Block(0,12,-6,SAND:1)
Block(0,12,-5,RED_SANDSTONE)
Block(0,12,-4,RED_SANDSTONE)
Block(0,12,5,STAINED_GLASS_PANE:1)
Block(0,12,6,STAINED_GLASS:1)
Block(0,12,7,RED_SANDSTONE)
Block(0,12,8,STAINED_GLASS:1)
Block(0,13,-6,SAND:1)
Block(0,13,-5,RED_SANDSTONE)
Block(0,13,5,STAINED_GLASS_PANE:1)
Block(0,13,6,RED_SANDSTONE)
Block(0,13,7,RED_SANDSTONE)
Block(0,14,-5,RED_SANDSTONE)
Block(0,14,6,RED_SANDSTONE)
Block(0,14,7,RED_SANDSTONE)
Block(0,15,-5,RED_SANDSTONE)
Block(0,15,-4,RED_SANDSTONE)
Block(0,15,1,STAINED_GLASS_PANE:1)
Block(0,15,6,RED_SANDSTONE)
Block(0,15,7,RED_SANDSTONE)
Block(0,16,-5,RED_SANDSTONE)
Block(0,16,-4,RED_SANDSTONE)
Block(0,16,0,STAINED_GLASS_PANE:1)
Block(0,16,1,STAINED_GLASS:1)
Block(0,16,6,RED_SANDSTONE)
Block(0,16,7,RED_SANDSTONE)
Block(0,17,-5,RED_SANDSTONE)
Block(0,17,-4,RED_SANDSTONE)
Block(0,17,-3,RED_SANDSTONE)
Block(0,17,0,STAINED_GLASS:1)
Block(0,17,1,STAINED_GLASS:1)
Block(0,17,4,RED_SANDSTONE)
Block(0,17,5,RED_SANDSTONE)
Block(0,17,6,RED_SANDSTONE)
Block(0,18,-4,RED_SANDSTONE)
Block(0,18,-3,RED_SANDSTONE)
Block(0,18,-2,RED_SANDSTONE)
Block(0,18,0,STAINED_GLASS:1)
Block(0,18,1,STAINED_GLASS:1)
Block(0,18,2,RED_SANDSTONE_STAIRS:6)
Block(0,18,3,RED_SANDSTONE)
Block(0,18,4,RED_SANDSTONE)
Block(0,18,5,SAND:1)
Block(0,19,-3,RED_SANDSTONE)
Block(0,19,-2,RED_SANDSTONE)
Block(0,19,-1,RED_SANDSTONE)
Block(0,19,0,STAINED_GLASS:1)
Block(0,19,2,RED_SANDSTONE)
Block(0,19,3,RED_SANDSTONE)
Block(0,19,4,STAINED_GLASS:1)
Block(0,20,-3,RED_SANDSTONE)
Block(0,20,-2,RED_SANDSTONE)
Block(0,20,-1,RED_SANDSTONE)
Block(0,20,0,STAINED_GLASS:1)
Block(0,20,1,STAINED_GLASS:1)
Block(0,20,2,RED_SANDSTONE)
Block(0,20,3,RED_SANDSTONE)
Block(0,21,-3,RED_SANDSTONE)
Block(0,21,-2,RED_SANDSTONE)
Block(0,21,-1,GLOWSTONE)
Block(0,21,0,STAINED_GLASS:1)
Block(0,21,1,RED_SANDSTONE)
Block(0,21,2,RED_SANDSTONE)
Block(0,21,3,RED_SANDSTONE)
Block(0,21,4,STAINED_GLASS:1)
Block(0,22,-2,RED_SANDSTONE)
Block(0,22,-1,GLOWSTONE)
Block(0,22,0,GLOWSTONE)
Block(0,22,1,RED_SANDSTONE)
Block(0,22,2,RED_SANDSTONE)
Block(0,22,3,STAINED_GLASS:1)
Block(0,23,-3,STAINED_GLASS:1)
Block(0,23,-2,RED_SANDSTONE)
Block(0,23,-1,RED_SANDSTONE)
Block(0,23,0,RED_SANDSTONE)
Block(0,23,1,RED_SANDSTONE)
Block(0,23,2,RED_SANDSTONE)
Block(0,24,-2,STAINED_GLASS:1)
Block(0,24,-1,RED_SANDSTONE)
Block(0,24,0,STAINED_GLASS:1)
Block(0,24,1,STAINED_GLASS:1)
Block(0,24,2,STAINED_GLASS:1)
Block(0,25,1,STAINED_GLASS:1)
Block(1,0,-11,RED_SANDSTONE)
Block(1,0,-10,RED_SANDSTONE)
Block(1,0,-9,RED_SANDSTONE)
Block(1,0,-8,RED_SANDSTONE)
Block(1,0,-7,RED_SANDSTONE)
Block(1,0,-6,RED_SANDSTONE)
Block(1,0,-5,RED_SANDSTONE)
Block(1,0,-4,RED_SANDSTONE)
Block(1,0,-3,RED_SANDSTONE)
Block(1,0,-2,RED_SANDSTONE)
Block(1,0,-1,RED_SANDSTONE)
Block(1,0,0,RED_SANDSTONE)
Block(1,0,1,RED_SANDSTONE)
Block(1,0,2,RED_SANDSTONE)
Block(1,0,3,RED_SANDSTONE)
Block(1,0,4,RED_SANDSTONE)
Block(1,0,5,RED_SANDSTONE)
Block(1,0,6,RED_SANDSTONE)
Block(1,0,7,RED_SANDSTONE)
Block(1,0,8,RED_SANDSTONE)
Block(1,0,9,RED_SANDSTONE)
Block(1,0,10,RED_SANDSTONE)
Block(1,0,11,RED_SANDSTONE)
Block(1,0,12,RED_SANDSTONE)
Block(1,0,13,RED_SANDSTONE)
Block(1,1,-9,RED_SANDSTONE)
Block(1,1,-8,RED_SANDSTONE)
Block(1,1,-7,RED_SANDSTONE)
Block(1,1,-6,RED_SANDSTONE)
Block(1,1,-5,RED_SANDSTONE)
Block(1,1,-4,SAND:1)
Block(1,1,1,RED_SANDSTONE)
Block(1,1,2,RED_SANDSTONE)
Block(1,1,3,RED_SANDSTONE)
Block(1,1,4,RED_SANDSTONE)
Block(1,1,5,RED_SANDSTONE)
Block(1,1,6,RED_SANDSTONE)
Block(1,1,7,RED_SANDSTONE)
Block(1,2,-8,RED_SANDSTONE)
Block(1,2,-7,RED_SANDSTONE)
Block(1,2,2,RED_SANDSTONE)
Block(1,2,3,RED_SANDSTONE)
Block(1,2,4,STAINED_GLASS:1)
Block(1,2,5,STAINED_GLASS:1)
Block(1,2,6,STAINED_GLASS:1)
Block(1,2,7,STAINED_GLASS:1)
Block(1,3,-8,RED_SANDSTONE)
Block(1,3,-7,RED_SANDSTONE)
Block(1,3,3,RED_SANDSTONE_STAIRS:1)
Block(1,3,4,STAINED_GLASS:1)
Block(1,3,10,STAINED_GLASS:1)
Block(1,4,-8,RED_SANDSTONE)
Block(1,4,-7,RED_SANDSTONE)
Block(1,4,4,STAINED_GLASS_PANE:1)
Block(1,4,9,STAINED_GLASS:1)
Block(1,4,10,STAINED_GLASS:1)
Block(1,5,-7,RED_SANDSTONE)
Block(1,5,-6,RED_SANDSTONE)
Block(1,5,8,STAINED_GLASS:1)
Block(1,5,9,RED_SANDSTONE)
Block(1,5,10,RED_SANDSTONE)
Block(1,6,-7,RED_SANDSTONE)
Block(1,6,-6,RED_SANDSTONE)
Block(1,6,7,STAINED_GLASS:1)
Block(1,6,8,RED_SANDSTONE)
Block(1,6,9,RED_SANDSTONE)
Block(1,7,-7,SAND:1)
Block(1,7,-6,RED_SANDSTONE)
Block(1,7,6,STAINED_GLASS_PANE:1)
Block(1,7,7,STAINED_GLASS:1)
Block(1,7,8,RED_SANDSTONE)
Block(1,7,9,RED_SANDSTONE)
Block(1,8,-7,SAND:1)
Block(1,8,-6,RED_SANDSTONE)
Block(1,8,7,RED_SANDSTONE)
Block(1,8,8,RED_SANDSTONE)
Block(1,9,-6,SAND:1)
Block(1,9,-5,RED_SANDSTONE)
Block(1,9,6,RED_SANDSTONE)
Block(1,9,7,RED_SANDSTONE)
Block(1,9,8,STAINED_GLASS:1)
Block(1,10,-6,SAND:1)
Block(1,10,-5,RED_SANDSTONE)
Block(1,10,-4,RED_SANDSTONE)
Block(1,10,-3,RED_SANDSTONE)
Block(1,10,6,RED_SANDSTONE)
Block(1,10,7,RED_SANDSTONE)
Block(1,11,-6,SAND:1)
Block(1,11,-5,RED_SANDSTONE)
Block(1,11,-4,RED_SANDSTONE)
Block(1,11,-3,STAINED_GLASS:1)
Block(1,11,2,STAINED_GLASS_PANE:1)
Block(1,11,5,STAINED_GLASS_PANE:1)
Block(1,11,6,STAINED_GLASS:1)
Block(1,11,7,RED_SANDSTONE)
Block(1,11,8,STAINED_GLASS:1)
Block(1,12,-6,SAND:1)
Block(1,12,-5,RED_SANDSTONE)
Block(1,12,-4,RED_SANDSTONE)
Block(1,12,1,STAINED_GLASS_PANE:1)
Block(1,12,2,STAINED_GLASS_PANE:1)
Block(1,12,5,STAINED_GLASS:1)
Block(1,12,6,STAINED_GLASS:1)
Block(1,12,7,RED_SANDSTONE)
Block(1,13,-6,RED_SANDSTONE)
Block(1,13,-5,RED_SANDSTONE)
Block(1,13,-4,RED_SANDSTONE)
Block(1,13,1,STAINED_GLASS_PANE:1)
Block(1,13,2,STAINED_GLASS:1)
Block(1,13,5,STAINED_GLASS_PANE:1)
Block(1,13,6,STAINED_GLASS:1)
Block(1,13,7,RED_SANDSTONE)
Block(1,14,-6,RED_SANDSTONE)
Block(1,14,-5,RED_SANDSTONE)
Block(1,14,1,STAINED_GLASS_PANE:1)
Block(1,14,2,STAINED_GLASS:1)
Block(1,14,3,STAINED_GLASS:1)
Block(1,14,6,RED_SANDSTONE)
Block(1,14,7,RED_SANDSTONE)
Block(1,15,-5,RED_SANDSTONE)
Block(1,15,-4,RED_SANDSTONE)
Block(1,15,2,STAINED_GLASS_PANE:1)
Block(1,15,3,STAINED_GLASS_PANE:1)
Block(1,15,5,RED_SANDSTONE_STAIRS:4)
Block(1,15,6,RED_SANDSTONE)
Block(1,15,7,RED_SANDSTONE)
Block(1,16,-5,RED_SANDSTONE)
Block(1,16,-4,RED_SANDSTONE)
Block(1,16,3,STAINED_GLASS_PANE:1)
Block(1,16,5,RED_SANDSTONE)
Block(1,16,6,RED_SANDSTONE)
Block(1,17,-4,RED_SANDSTONE)
Block(1,17,-3,RED_SANDSTONE)
Block(1,17,4,RED_SANDSTONE)
Block(1,17,5,RED_SANDSTONE)
Block(1,17,6,RED_SANDSTONE)
Block(1,18,-4,RED_SANDSTONE)
Block(1,18,-3,RED_SANDSTONE)
Block(1,18,1,STAINED_GLASS_PANE:1)
Block(1,18,2,STAINED_GLASS:1)
Block(1,18,3,RED_SANDSTONE)
Block(1,18,4,RED_SANDSTONE)
Block(1,18,5,STAINED_GLASS:1)
Block(1,19,-4,RED_SANDSTONE)
Block(1,19,-3,RED_SANDSTONE)
Block(1,19,-2,RED_SANDSTONE)
Block(1,19,0,STAINED_GLASS_PANE:1)
Block(1,19,1,STAINED_GLASS_PANE:1)
Block(1,19,2,STAINED_GLASS:1)
Block(1,19,3,RED_SANDSTONE)
Block(1,19,4,RED_SANDSTONE)
Block(1,19,5,STAINED_GLASS:1)
Block(1,20,-3,RED_SANDSTONE)
Block(1,20,-2,RED_SANDSTONE)
Block(1,20,0,STAINED_GLASS:1)
Block(1,20,1,STAINED_GLASS:1)
Block(1,20,2,RED_SANDSTONE)
Block(1,20,3,RED_SANDSTONE)
Block(1,20,4,STAINED_GLASS:1)
Block(1,21,-3,RED_SANDSTONE)
Block(1,21,-2,RED_SANDSTONE)
Block(1,21,-1,STAINED_GLASS:1)
Block(1,21,0,STAINED_GLASS:1)
Block(1,21,1,STAINED_GLASS:1)
Block(1,21,2,RED_SANDSTONE)
Block(1,21,3,RED_SANDSTONE)
Block(1,21,4,STAINED_GLASS:1)
Block(1,22,-3,RED_SANDSTONE)
Block(1,22,-2,RED_SANDSTONE)
Block(1,22,-1,STAINED_GLASS:1)
Block(1,22,0,STAINED_GLASS:1)
Block(1,22,1,RED_SANDSTONE)
Block(1,22,2,RED_SANDSTONE)
Block(1,22,3,RED_SANDSTONE)
Block(1,23,-3,RED_SANDSTONE)
Block(1,23,-2,RED_SANDSTONE)
Block(1,23,-1,STAINED_GLASS:1)
Block(1,23,0,STAINED_GLASS:1)
Block(1,23,2,RED_SANDSTONE)
Block(1,24,-3,RED_SANDSTONE)
Block(1,24,-2,RED_SANDSTONE)
Block(1,24,-1,RED_SANDSTONE)
Block(1,24,0,STAINED_GLASS:1)
Block(1,24,1,STAINED_GLASS:1)
Block(1,25,-3,RED_SANDSTONE)
Block(1,25,-2,RED_SANDSTONE)
Block(1,25,-1,STAINED_GLASS:1)
Block(1,25,0,STAINED_GLASS:1)
Block(1,25,1,STAINED_GLASS:1)
Block(1,26,-2,RED_SANDSTONE)
Block(1,26,0,STAINED_GLASS:1)
Block(2,0,-11,RED_SANDSTONE)
Block(2,0,-10,RED_SANDSTONE)
Block(2,0,-9,RED_SANDSTONE)
Block(2,0,-8,RED_SANDSTONE)
Block(2,0,-7,RED_SANDSTONE)
Block(2,0,-6,RED_SANDSTONE)
Block(2,0,-5,RED_SANDSTONE)
Block(2,0,-4,RED_SANDSTONE)
Block(2,0,-3,RED_SANDSTONE)
Block(2,0,-2,RED_SANDSTONE)
Block(2,0,-1,RED_SANDSTONE)
Block(2,0,0,RED_SANDSTONE)
Block(2,0,1,RED_SANDSTONE)
Block(2,0,2,RED_SANDSTONE)
Block(2,0,3,RED_SANDSTONE)
Block(2,0,4,RED_SANDSTONE)
Block(2,0,5,RED_SANDSTONE)
Block(2,0,6,RED_SANDSTONE)
Block(2,0,7,RED_SANDSTONE)
Block(2,0,8,RED_SANDSTONE)
Block(2,0,9,RED_SANDSTONE)
Block(2,0,10,RED_SANDSTONE)
Block(2,0,11,RED_SANDSTONE)
Block(2,0,12,RED_SANDSTONE)
Block(2,0,13,RED_SANDSTONE)
Block(2,1,-9,RED_SANDSTONE)
Block(2,1,-8,RED_SANDSTONE)
Block(2,1,-7,RED_SANDSTONE)
Block(2,1,-6,RED_SANDSTONE)
Block(2,1,-5,RED_SANDSTONE)
Block(2,1,-4,RED_SANDSTONE)
Block(2,1,1,RED_SANDSTONE_STAIRS:2)
Block(2,1,2,RED_SANDSTONE)
Block(2,1,3,RED_SANDSTONE)
Block(2,1,4,RED_SANDSTONE)
Block(2,1,5,RED_SANDSTONE)
Block(2,1,6,STAINED_GLASS:1)
Block(2,1,7,STAINED_GLASS:1)
Block(2,1,8,STAINED_GLASS:1)
Block(2,2,-8,RED_SANDSTONE)
Block(2,2,-7,RED_SANDSTONE)
Block(2,2,-6,RED_SANDSTONE)
Block(2,2,5,STAINED_GLASS_PANE:1)
Block(2,2,6,STAINED_GLASS_PANE:1)
Block(2,2,7,STAINED_GLASS:1)
Block(2,3,-8,RED_SANDSTONE)
Block(2,3,-7,RED_SANDSTONE)
Block(2,4,-8,RED_SANDSTONE)
Block(2,4,-7,RED_SANDSTONE)
Block(2,4,8,RED_SANDSTONE)
Block(2,4,9,RED_SANDSTONE)
Block(2,5,-8,RED_SANDSTONE)
Block(2,5,-7,RED_SANDSTONE)
Block(2,5,7,STAINED_GLASS:1)
Block(2,5,8,RED_SANDSTONE)
Block(2,5,9,RED_SANDSTONE)
Block(2,6,-7,RED_SANDSTONE)
Block(2,6,-6,RED_SANDSTONE)
Block(2,6,7,STAINED_GLASS:1)
Block(2,6,8,RED_SANDSTONE)
Block(2,6,9,RED_SANDSTONE)
Block(2,7,-7,RED_SANDSTONE)
Block(2,7,-6,RED_SANDSTONE)
Block(2,7,-5,STAINED_GLASS:1)
Block(2,7,6,RED_SANDSTONE_STAIRS:6)
Block(2,7,7,RED_SANDSTONE)
Block(2,7,8,RED_SANDSTONE)
Block(2,8,-7,SAND:1)
Block(2,8,-6,RED_SANDSTONE)
Block(2,8,-5,STAINED_GLASS:1)
Block(2,8,-4,STAINED_GLASS:1)
Block(2,8,6,RED_SANDSTONE)
Block(2,8,7,RED_SANDSTONE)
Block(2,9,-7,SAND:1)
Block(2,9,-6,RED_SANDSTONE)
Block(2,9,-5,RED_SANDSTONE)
Block(2,9,-4,STAINED_GLASS:1)
Block(2,9,-3,STAINED_GLASS:1)
Block(2,9,6,RED_SANDSTONE)
Block(2,9,7,RED_SANDSTONE)
Block(2,10,-6,SAND:1)
Block(2,10,-5,RED_SANDSTONE)
Block(2,10,-4,RED_SANDSTONE)
Block(2,10,-3,STAINED_GLASS:1)
Block(2,10,-2,STAINED_GLASS:1)
Block(2,10,6,RED_SANDSTONE)
Block(2,10,7,RED_SANDSTONE)
Block(2,11,-6,SAND:1)
Block(2,11,-5,RED_SANDSTONE)
Block(2,11,-4,RED_SANDSTONE)
Block(2,11,-3,STAINED_GLASS:1)
Block(2,11,-2,STAINED_GLASS_PANE:1)
Block(2,11,6,RED_SANDSTONE)
Block(2,11,7,RED_SANDSTONE)
Block(2,12,-6,SAND:1)
Block(2,12,-5,RED_SANDSTONE)
Block(2,12,-4,RED_SANDSTONE)
Block(2,12,-3,STAINED_GLASS_PANE:1)
Block(2,12,2,RED_SANDSTONE_STAIRS:4)
Block(2,12,6,RED_SANDSTONE)
Block(2,12,7,RED_SANDSTONE)
Block(2,13,-5,RED_SANDSTONE)
Block(2,13,-4,RED_SANDSTONE)
Block(2,13,-3,STAINED_GLASS_PANE:1)
Block(2,13,2,RED_SANDSTONE)
Block(2,13,6,RED_SANDSTONE)
Block(2,13,7,RED_SANDSTONE)
Block(2,14,-5,RED_SANDSTONE)
Block(2,14,-4,RED_SANDSTONE)
Block(2,14,1,RED_SANDSTONE)
Block(2,14,2,RED_SANDSTONE)
Block(2,14,3,RED_SANDSTONE)
Block(2,14,6,RED_SANDSTONE)
Block(2,14,7,RED_SANDSTONE)
Block(2,15,-5,RED_SANDSTONE)
Block(2,15,-4,RED_SANDSTONE)
Block(2,15,2,STAINED_GLASS:1)
Block(2,15,3,STAINED_GLASS_PANE:1)
Block(2,15,5,RED_SANDSTONE)
Block(2,15,6,RED_SANDSTONE)
Block(2,16,-4,RED_SANDSTONE)
Block(2,16,-3,RED_SANDSTONE)
Block(2,16,2,STAINED_GLASS_PANE:1)
Block(2,16,3,STAINED_GLASS:1)
Block(2,16,4,RED_SANDSTONE)
Block(2,16,5,RED_SANDSTONE)
Block(2,16,6,RED_SANDSTONE)
Block(2,17,-4,RED_SANDSTONE)
Block(2,17,-3,RED_SANDSTONE)
Block(2,17,0,STAINED_GLASS_PANE:1)
Block(2,17,2,STAINED_GLASS_PANE:1)
Block(2,17,3,STAINED_GLASS:1)
Block(2,17,4,RED_SANDSTONE)
Block(2,17,5,RED_SANDSTONE)
Block(2,18,-4,SAND:1)
Block(2,18,-3,RED_SANDSTONE)
Block(2,18,0,STAINED_GLASS_PANE:1)
Block(2,18,2,STAINED_GLASS:1)
Block(2,18,3,RED_SANDSTONE)
Block(2,18,4,RED_SANDSTONE)
Block(2,19,-3,SAND:1)
Block(2,19,-2,RED_SANDSTONE)
Block(2,19,0,STAINED_GLASS_PANE:1)
Block(2,19,1,STAINED_GLASS:1)
Block(2,19,2,RED_SANDSTONE)
Block(2,19,3,RED_SANDSTONE)
Block(2,20,-3,SAND:1)
Block(2,20,-2,RED_SANDSTONE)
Block(2,20,0,STAINED_GLASS:1)
Block(2,20,2,RED_SANDSTONE)
Block(2,20,3,RED_SANDSTONE)
Block(2,21,-3,RED_SANDSTONE)
Block(2,21,-2,RED_SANDSTONE)
Block(2,21,0,STAINED_GLASS:1)
Block(2,21,1,GLOWSTONE)
Block(2,21,2,RED_SANDSTONE)
Block(2,21,3,RED_SANDSTONE)
Block(2,22,-3,RED_SANDSTONE)
Block(2,22,-2,RED_SANDSTONE)
Block(2,22,-1,STAINED_GLASS:1)
Block(2,22,0,STAINED_GLASS:1)
Block(2,22,1,STAINED_GLASS:1)
Block(2,22,2,RED_SANDSTONE)
Block(2,22,3,RED_SANDSTONE)
Block(2,23,-2,RED_SANDSTONE)
Block(2,23,-1,RED_SANDSTONE)
Block(2,23,0,RED_SANDSTONE)
Block(2,23,1,RED_SANDSTONE)
Block(2,23,2,RED_SANDSTONE)
Block(2,24,-2,RED_SANDSTONE)
Block(2,24,-1,RED_SANDSTONE)
Block(2,24,0,RED_SANDSTONE)
Block(2,24,1,RED_SANDSTONE)
Block(2,25,-1,RED_SANDSTONE)
Block(2,25,0,RED_SANDSTONE)
Block(2,25,1,RED_SANDSTONE)
Block(2,26,0,RED_SANDSTONE)
Block(2,26,1,STAINED_GLASS:1)
Block(2,27,0,STAINED_GLASS:1)
Block(3,0,-12,RED_SANDSTONE)
Block(3,0,-11,RED_SANDSTONE)
Block(3,0,-10,RED_SANDSTONE)
Block(3,0,-9,RED_SANDSTONE)
Block(3,0,-8,RED_SANDSTONE)
Block(3,0,-7,RED_SANDSTONE)
Block(3,0,-6,RED_SANDSTONE)
Block(3,0,-5,RED_SANDSTONE)
Block(3,0,-4,RED_SANDSTONE)
Block(3,0,-3,RED_SANDSTONE)
Block(3,0,-2,RED_SANDSTONE)
Block(3,0,-1,RED_SANDSTONE)
Block(3,0,0,RED_SANDSTONE)
Block(3,0,1,RED_SANDSTONE)
Block(3,0,2,RED_SANDSTONE)
Block(3,0,3,RED_SANDSTONE)
Block(3,0,4,RED_SANDSTONE)
Block(3,0,5,RED_SANDSTONE)
Block(3,0,6,RED_SANDSTONE)
Block(3,0,7,RED_SANDSTONE)
Block(3,0,8,RED_SANDSTONE)
Block(3,0,9,RED_SANDSTONE)
Block(3,0,10,RED_SANDSTONE)
Block(3,0,11,RED_SANDSTONE)
Block(3,0,12,RED_SANDSTONE)
Block(3,1,-11,STAINED_GLASS:1)
Block(3,1,-10,RED_SANDSTONE)
Block(3,1,-9,RED_SANDSTONE)
Block(3,1,-8,RED_SANDSTONE)
Block(3,1,-7,RED_SANDSTONE)
Block(3,1,-6,RED_SANDSTONE)
Block(3,1,-5,RED_SANDSTONE)
Block(3,1,-4,RED_SANDSTONE)
Block(3,1,-3,RED_SANDSTONE)
Block(3,1,2,RED_SANDSTONE)
Block(3,1,3,RED_SANDSTONE)
Block(3,1,4,STAINED_GLASS:1)
Block(3,1,5,STAINED_GLASS:1)
Block(3,1,6,STAINED_GLASS:1)
Block(3,1,9,RED_SANDSTONE)
Block(3,1,10,RED_SANDSTONE)
Block(3,2,-9,RED_SANDSTONE)
Block(3,2,-8,RED_SANDSTONE)
Block(3,2,-7,RED_SANDSTONE)
Block(3,2,-6,RED_SANDSTONE)
Block(3,2,-5,RED_SANDSTONE)
Block(3,3,-8,RED_SANDSTONE)
Block(3,3,-7,RED_SANDSTONE)
Block(3,3,-6,RED_SANDSTONE)
Block(3,3,10,RED_SANDSTONE)
Block(3,4,-7,RED_SANDSTONE)
Block(3,4,8,RED_SANDSTONE)
Block(3,4,9,RED_SANDSTONE)
Block(3,5,7,RED_SANDSTONE)
Block(3,5,8,RED_SANDSTONE)
Block(3,6,-7,RED_SANDSTONE)
Block(3,6,-6,STAINED_GLASS:1)
Block(3,6,7,RED_SANDSTONE)
Block(3,6,8,RED_SANDSTONE)
Block(3,7,-8,RED_SANDSTONE)
Block(3,7,-7,RED_SANDSTONE)
Block(3,7,-6,STAINED_GLASS:1)
Block(3,7,-5,STAINED_GLASS:1)
Block(3,7,6,RED_SANDSTONE)
Block(3,7,7,RED_SANDSTONE)
Block(3,8,-8,RED_SANDSTONE)
Block(3,8,-7,RED_SANDSTONE)
Block(3,8,-6,RED_SANDSTONE)
Block(3,8,-4,RED_SANDSTONE_STAIRS:7)
Block(3,8,-3,STAINED_GLASS:1)
Block(3,8,6,RED_SANDSTONE)
Block(3,8,7,RED_SANDSTONE)
Block(3,9,-8,SAND:1)
Block(3,9,-7,RED_SANDSTONE)
Block(3,9,-6,RED_SANDSTONE)
Block(3,9,-5,RED_SANDSTONE)
Block(3,9,-4,RED_SANDSTONE)
Block(3,9,-3,STAINED_GLASS:1)
Block(3,9,6,RED_SANDSTONE)
Block(3,9,7,RED_SANDSTONE)
Block(3,10,-7,SAND:1)
Block(3,10,-6,SAND:1)
Block(3,10,-5,RED_SANDSTONE)
Block(3,10,-4,RED_SANDSTONE)
Block(3,10,-3,RED_SANDSTONE)
Block(3,10,-2,RED_SANDSTONE_STAIRS:4)
Block(3,10,6,RED_SANDSTONE)
Block(3,10,7,RED_SANDSTONE)
Block(3,11,-5,STAINED_GLASS:1)
Block(3,11,-4,STAINED_GLASS:1)
Block(3,11,-3,STAINED_GLASS:1)
Block(3,11,-2,STAINED_GLASS:1)
Block(3,11,6,RED_SANDSTONE)
Block(3,11,7,RED_SANDSTONE)
Block(3,12,-5,RED_SANDSTONE)
Block(3,12,-4,STAINED_GLASS_PANE:1)
Block(3,12,-3,STAINED_GLASS:1)
Block(3,12,-2,STAINED_GLASS_PANE:1)
Block(3,12,3,RED_SANDSTONE_STAIRS:6)
Block(3,12,6,RED_SANDSTONE)
Block(3,12,7,SAND:1)
Block(3,13,-5,RED_SANDSTONE)
Block(3,13,-4,RED_SANDSTONE)
Block(3,13,-3,STAINED_GLASS:1)
Block(3,13,1,RED_SANDSTONE)
Block(3,13,2,RED_SANDSTONE)
Block(3,13,3,RED_SANDSTONE)
Block(3,13,4,RED_SANDSTONE)
Block(3,13,5,RED_SANDSTONE)
Block(3,13,6,RED_SANDSTONE)
Block(3,14,-5,RED_SANDSTONE)
Block(3,14,-4,RED_SANDSTONE)
Block(3,14,0,RED_SANDSTONE)
Block(3,14,1,RED_SANDSTONE)
Block(3,14,2,RED_SANDSTONE)
Block(3,14,3,RED_SANDSTONE)
Block(3,14,4,RED_SANDSTONE)
Block(3,14,5,RED_SANDSTONE)
Block(3,14,6,RED_SANDSTONE)
Block(3,15,-4,RED_SANDSTONE)
Block(3,15,-3,RED_SANDSTONE)
Block(3,15,1,STAINED_GLASS:1)
Block(3,15,2,STAINED_GLASS:1)
Block(3,15,3,RED_SANDSTONE)
Block(3,15,4,RED_SANDSTONE)
Block(3,15,5,RED_SANDSTONE)
Block(3,15,6,RED_SANDSTONE)
Block(3,16,-4,SAND:1)
Block(3,16,-3,RED_SANDSTONE)
Block(3,16,2,STAINED_GLASS:1)
Block(3,16,3,SAND:1)
Block(3,16,4,SAND:1)
Block(3,16,5,RED_SANDSTONE)
Block(3,17,-4,SAND:1)
Block(3,17,-3,RED_SANDSTONE)
Block(3,17,3,STAINED_GLASS:1)
Block(3,17,4,SAND:1)
Block(3,18,-3,SAND:1)
Block(3,18,-2,RED_SANDSTONE)
Block(3,18,2,RED_SANDSTONE_STAIRS:6)
Block(3,18,3,RED_SANDSTONE)
Block(3,19,-3,SAND:1)
Block(3,19,-2,RED_SANDSTONE)
Block(3,19,-1,RED_SANDSTONE)
Block(3,19,1,RED_SANDSTONE)
Block(3,19,2,RED_SANDSTONE)
Block(3,19,3,RED_SANDSTONE)
Block(3,20,-2,SAND:1)
Block(3,20,-1,RED_SANDSTONE)
Block(3,20,0,RED_SANDSTONE)
Block(3,20,1,RED_SANDSTONE)
Block(3,20,2,RED_SANDSTONE)
Block(3,21,-2,RED_SANDSTONE)
Block(3,21,-1,RED_SANDSTONE)
Block(3,21,0,GLOWSTONE)
Block(3,21,1,RED_SANDSTONE)
Block(3,21,2,RED_SANDSTONE)
Block(3,22,-2,RED_SANDSTONE)
Block(3,22,-1,RED_SANDSTONE)
Block(3,22,0,GLOWSTONE)
Block(3,22,1,GLOWSTONE)
Block(3,22,2,RED_SANDSTONE)
Block(3,23,-2,RED_SANDSTONE)
Block(3,23,-1,RED_SANDSTONE)
Block(3,23,0,RED_SANDSTONE)
Block(3,23,1,RED_SANDSTONE)
Block(3,23,2,RED_SANDSTONE)
Block(3,24,-1,RED_SANDSTONE)
Block(3,24,0,RED_SANDSTONE)
Block(3,24,1,STAINED_GLASS:1)
Block(3,25,-1,STAINED_GLASS:1)
Block(3,25,0,RED_SANDSTONE)
Block(3,25,1,STAINED_GLASS:1)
Block(4,0,-11,RED_SANDSTONE)
Block(4,0,-10,RED_SANDSTONE)
Block(4,0,-9,RED_SANDSTONE)
Block(4,0,-8,RED_SANDSTONE)
Block(4,0,-7,RED_SANDSTONE)
Block(4,0,-6,RED_SANDSTONE)
Block(4,0,-5,RED_SANDSTONE)
Block(4,0,-4,RED_SANDSTONE)
Block(4,0,-3,RED_SANDSTONE)
Block(4,0,-2,RED_SANDSTONE)
Block(4,0,-1,RED_SANDSTONE)
Block(4,0,0,RED_SANDSTONE)
Block(4,0,1,RED_SANDSTONE)
Block(4,0,2,RED_SANDSTONE)
Block(4,0,3,RED_SANDSTONE)
Block(4,0,4,RED_SANDSTONE)
Block(4,0,5,RED_SANDSTONE)
Block(4,0,6,RED_SANDSTONE)
Block(4,0,7,RED_SANDSTONE)
Block(4,0,8,RED_SANDSTONE)
Block(4,0,9,RED_SANDSTONE)
Block(4,0,10,RED_SANDSTONE)
Block(4,0,11,RED_SANDSTONE)
Block(4,0,12,RED_SANDSTONE)
Block(4,1,-11,STAINED_GLASS:1)
Block(4,1,-10,RED_SANDSTONE)
Block(4,1,-9,RED_SANDSTONE)
Block(4,1,-8,RED_SANDSTONE)
Block(4,1,-7,RED_SANDSTONE)
Block(4,1,-6,RED_SANDSTONE)
Block(4,1,-5,RED_SANDSTONE)
Block(4,1,-4,RED_SANDSTONE)
Block(4,1,-3,RED_SANDSTONE)
Block(4,1,5,STAINED_GLASS:1)
Block(4,1,7,RED_SANDSTONE_STAIRS:0)
Block(4,1,8,RED_SANDSTONE)
Block(4,1,9,RED_SANDSTONE)
Block(4,1,10,RED_SANDSTONE)
Block(4,1,11,RED_SANDSTONE)
Block(4,2,-11,STAINED_GLASS:1)
Block(4,2,-9,RED_SANDSTONE)
Block(4,2,-8,RED_SANDSTONE)
Block(4,2,-7,RED_SANDSTONE)
Block(4,2,-6,RED_SANDSTONE)
Block(4,2,-5,RED_SANDSTONE)
Block(4,2,-4,RED_SANDSTONE)
Block(4,2,9,SAND:1)
Block(4,2,10,RED_SANDSTONE)
Block(4,2,11,RED_SANDSTONE)
Block(4,3,-8,RED_SANDSTONE)
Block(4,3,-7,RED_SANDSTONE)
Block(4,3,-6,RED_SANDSTONE)
Block(4,3,9,SAND:1)
Block(4,3,10,RED_SANDSTONE)
Block(4,4,7,RED_SANDSTONE)
Block(4,4,8,RED_SANDSTONE)
Block(4,5,7,RED_SANDSTONE)
Block(4,5,8,RED_SANDSTONE)
Block(4,6,6,RED_SANDSTONE)
Block(4,6,7,RED_SANDSTONE)
Block(4,7,-8,RED_SANDSTONE)
Block(4,7,-7,RED_SANDSTONE)
Block(4,7,-3,RED_SANDSTONE_STAIRS:4)
Block(4,7,6,RED_SANDSTONE)
Block(4,7,7,RED_SANDSTONE)
Block(4,8,-8,SAND:1)
Block(4,8,-7,RED_SANDSTONE)
Block(4,8,-3,RED_SANDSTONE)
Block(4,8,5,STAINED_GLASS:1)
Block(4,8,6,RED_SANDSTONE)
Block(4,8,7,RED_SANDSTONE)
Block(4,9,-8,SAND:1)
Block(4,9,-7,RED_SANDSTONE)
Block(4,9,-6,RED_SANDSTONE)
Block(4,9,-5,RED_SANDSTONE)
Block(4,9,-4,RED_SANDSTONE)
Block(4,9,-3,RED_SANDSTONE)
Block(4,9,6,RED_SANDSTONE)
Block(4,9,7,RED_SANDSTONE)
Block(4,10,-7,SAND:1)
Block(4,10,-6,SAND:1)
Block(4,10,-5,STAINED_GLASS:1)
Block(4,10,-4,RED_SANDSTONE)
Block(4,10,-3,RED_SANDSTONE)
Block(4,10,-2,RED_SANDSTONE)
Block(4,10,5,STAINED_GLASS:1)
Block(4,10,6,RED_SANDSTONE)
Block(4,10,7,RED_SANDSTONE)
Block(4,11,-5,STAINED_GLASS_PANE:1)
Block(4,11,-4,STAINED_GLASS:1)
Block(4,11,4,RED_SANDSTONE_STAIRS:4)
Block(4,11,5,STAINED_GLASS:1)
Block(4,11,6,STAINED_GLASS:1)
Block(4,11,7,SAND:1)
Block(4,12,1,RED_SANDSTONE_STAIRS:4)
Block(4,12,2,RED_SANDSTONE_STAIRS:4)
Block(4,12,4,RED_SANDSTONE)
Block(4,12,5,RED_SANDSTONE)
Block(4,12,6,SAND:1)
Block(4,12,7,SAND:1)
Block(4,13,-5,RED_SANDSTONE)
Block(4,13,-4,RED_SANDSTONE)
Block(4,13,0,RED_SANDSTONE)
Block(4,13,1,RED_SANDSTONE)
Block(4,13,2,RED_SANDSTONE)
Block(4,13,3,RED_SANDSTONE)
Block(4,13,4,RED_SANDSTONE)
Block(4,13,5,RED_SANDSTONE)
Block(4,14,-4,RED_SANDSTONE)
Block(4,14,-3,RED_SANDSTONE)
Block(4,14,-1,RED_SANDSTONE)
Block(4,14,0,RED_SANDSTONE)
Block(4,14,1,MOB_SPAWNER,NetherKirlidNest/7-mob_spawner.nbt)
Block(4,14,2,RED_SANDSTONE)
Block(4,14,3,SAND:1)
Block(4,14,4,RED_SANDSTONE)
Block(4,14,5,RED_SANDSTONE)
Block(4,15,-4,RED_SANDSTONE)
Block(4,15,-3,RED_SANDSTONE)
Block(4,15,2,SAND:1)
Block(4,15,3,SAND:1)
Block(4,15,4,RED_SANDSTONE)
Block(4,16,-3,RED_SANDSTONE)
Block(4,16,-2,RED_SANDSTONE)
Block(4,17,-3,SAND:1)
Block(4,17,-2,RED_SANDSTONE)
Block(4,18,-3,SAND:1)
Block(4,18,-2,RED_SANDSTONE)
Block(4,19,-2,SAND:1)
Block(4,19,-1,RED_SANDSTONE)
Block(4,19,0,RED_SANDSTONE)
Block(4,19,2,RED_SANDSTONE)
Block(4,20,-1,RED_SANDSTONE)
Block(4,20,0,RED_SANDSTONE)
Block(4,20,1,RED_SANDSTONE)
Block(4,20,2,STAINED_GLASS:1)
Block(4,21,-1,RED_SANDSTONE)
Block(4,21,0,RED_SANDSTONE)
Block(4,21,1,RED_SANDSTONE)
Block(4,21,2,STAINED_GLASS:1)
Block(4,22,-1,RED_SANDSTONE)
Block(4,22,0,RED_SANDSTONE)
Block(4,22,1,RED_SANDSTONE)
Block(4,22,2,STAINED_GLASS:1)
Block(4,23,-1,STAINED_GLASS:1)
Block(4,23,0,STAINED_GLASS:1)
Block(4,23,1,STAINED_GLASS:1)
Block(4,23,2,STAINED_GLASS:1)
Block(4,24,0,STAINED_GLASS:1)
Block(4,24,1,STAINED_GLASS:1)
Block(5,0,-12,RED_SANDSTONE)
Block(5,0,-11,RED_SANDSTONE)
Block(5,0,-10,RED_SANDSTONE)
Block(5,0,-9,RED_SANDSTONE)
Block(5,0,-8,RED_SANDSTONE)
Block(5,0,-7,RED_SANDSTONE)
Block(5,0,-6,RED_SANDSTONE)
Block(5,0,-5,RED_SANDSTONE)
Block(5,0,-4,RED_SANDSTONE)
Block(5,0,-3,RED_SANDSTONE)
Block(5,0,-2,RED_SANDSTONE)
Block(5,0,-1,RED_SANDSTONE)
Block(5,0,0,RED_SANDSTONE)
Block(5,0,1,RED_SANDSTONE)
Block(5,0,2,RED_SANDSTONE)
Block(5,0,3,RED_SANDSTONE)
Block(5,0,4,RED_SANDSTONE)
Block(5,0,5,RED_SANDSTONE)
Block(5,0,6,RED_SANDSTONE)
Block(5,0,7,RED_SANDSTONE)
Block(5,0,8,RED_SANDSTONE)
Block(5,0,9,RED_SANDSTONE)
Block(5,0,10,RED_SANDSTONE)
Block(5,0,11,RED_SANDSTONE)
Block(5,1,-12,STAINED_GLASS:1)
Block(5,1,-11,RED_SANDSTONE)
Block(5,1,-10,RED_SANDSTONE)
Block(5,1,-9,RED_SANDSTONE)
Block(5,1,-8,RED_SANDSTONE)
Block(5,1,-7,RED_SANDSTONE)
Block(5,1,-6,RED_SANDSTONE)
Block(5,1,-5,RED_SANDSTONE)
Block(5,1,-4,RED_SANDSTONE)
Block(5,1,-3,RED_SANDSTONE)
Block(5,1,-2,RED_SANDSTONE)
Block(5,1,-1,RED_SANDSTONE)
Block(5,1,6,RED_SANDSTONE)
Block(5,1,7,SAND:1)
Block(5,1,8,RED_SANDSTONE)
Block(5,1,9,RED_SANDSTONE)
Block(5,1,10,RED_SANDSTONE)
Block(5,1,11,RED_SANDSTONE)
Block(5,2,-11,STAINED_GLASS:1)
Block(5,2,-10,RED_SANDSTONE)
Block(5,2,-9,RED_SANDSTONE)
Block(5,2,-8,RED_SANDSTONE)
Block(5,2,-7,RED_SANDSTONE)
Block(5,2,-6,RED_SANDSTONE)
Block(5,2,-5,RED_SANDSTONE)
Block(5,2,-4,RED_SANDSTONE)
Block(5,2,-3,RED_SANDSTONE)
Block(5,2,9,SAND:1)
Block(5,2,10,RED_SANDSTONE)
Block(5,3,-10,STAINED_GLASS:1)
Block(5,3,-9,STAINED_GLASS:1)
Block(5,3,-8,STAINED_GLASS:1)
Block(5,3,-7,RED_SANDSTONE)
Block(5,3,-6,RED_SANDSTONE)
Block(5,3,9,RED_SANDSTONE)
Block(5,4,6,RED_SANDSTONE_STAIRS:4)
Block(5,4,7,RED_SANDSTONE)
Block(5,4,8,RED_SANDSTONE)
Block(5,5,5,STAINED_GLASS:1)
Block(5,5,6,RED_SANDSTONE)
Block(5,5,7,RED_SANDSTONE)
Block(5,6,5,STAINED_GLASS:1)
Block(5,6,6,RED_SANDSTONE)
Block(5,6,7,RED_SANDSTONE)
Block(5,7,-7,RED_SANDSTONE)
Block(5,7,6,STAINED_GLASS:1)
Block(5,7,7,RED_SANDSTONE)
Block(5,8,-8,RED_SANDSTONE)
Block(5,8,-7,RED_SANDSTONE)
Block(5,8,6,RED_SANDSTONE)
Block(5,8,7,RED_SANDSTONE)
Block(5,9,-8,RED_SANDSTONE)
Block(5,9,-7,RED_SANDSTONE)
Block(5,9,-6,RED_SANDSTONE)
Block(5,9,-5,RED_SANDSTONE)
Block(5,9,-4,RED_SANDSTONE)
Block(5,9,-2,RED_SANDSTONE)
Block(5,9,5,STAINED_GLASS:1)
Block(5,9,6,RED_SANDSTONE)
Block(5,9,7,SAND:1)
Block(5,10,-8,STAINED_GLASS:1)
Block(5,10,-7,STAINED_GLASS:1)
Block(5,10,-6,STAINED_GLASS:1)
Block(5,10,-5,STAINED_GLASS:1)
Block(5,10,-3,RED_SANDSTONE)
Block(5,10,-2,RED_SANDSTONE)
Block(5,10,-1,RED_SANDSTONE)
Block(5,10,4,STAINED_GLASS:1)
Block(5,10,5,RED_SANDSTONE)
Block(5,10,6,RED_SANDSTONE)
Block(5,10,7,SAND:1)
Block(5,11,-2,RED_SANDSTONE_STAIRS:0)
Block(5,11,1,RED_SANDSTONE)
Block(5,11,2,RED_SANDSTONE)
Block(5,11,3,RED_SANDSTONE)
Block(5,11,4,RED_SANDSTONE)
Block(5,11,5,RED_SANDSTONE)
Block(5,11,6,RED_SANDSTONE)
Block(5,11,7,SAND:1)
Block(5,12,0,RED_SANDSTONE)
Block(5,12,1,RED_SANDSTONE)
Block(5,12,2,RED_SANDSTONE)
Block(5,12,3,RED_SANDSTONE)
Block(5,12,4,SAND:1)
Block(5,12,5,SAND:1)
Block(5,12,6,SAND:1)
Block(5,13,-3,RED_SANDSTONE)
Block(5,13,-1,RED_SANDSTONE)
Block(5,13,0,RED_SANDSTONE)
Block(5,13,1,RED_SANDSTONE)
Block(5,13,2,RED_SANDSTONE)
Block(5,14,-4,RED_SANDSTONE)
Block(5,14,-3,RED_SANDSTONE)
Block(5,14,-2,RED_SANDSTONE)
Block(5,14,-1,RED_SANDSTONE)
Block(5,14,0,RED_SANDSTONE)
Block(5,14,1,SAND:1)
Block(5,14,2,SAND:1)
Block(5,15,-3,RED_SANDSTONE)
Block(5,15,-2,RED_SANDSTONE)
Block(5,15,-1,SAND:1)
Block(5,15,0,SAND:1)
Block(5,16,-3,SAND:1)
Block(5,16,-2,RED_SANDSTONE)
Block(5,17,-2,SAND:1)
Block(5,18,-1,RED_SANDSTONE)
Block(5,20,1,STAINED_GLASS:1)
Block(5,21,0,STAINED_GLASS:1)
Block(5,22,1,STAINED_GLASS:1)
Block(5,23,1,STAINED_GLASS:1)
Block(6,0,-13,RED_SANDSTONE)
Block(6,0,-12,RED_SANDSTONE)
Block(6,0,-11,RED_SANDSTONE)
Block(6,0,-10,RED_SANDSTONE)
Block(6,0,-9,RED_SANDSTONE)
Block(6,0,-8,RED_SANDSTONE)
Block(6,0,-7,RED_SANDSTONE)
Block(6,0,-6,RED_SANDSTONE)
Block(6,0,-5,RED_SANDSTONE)
Block(6,0,-4,RED_SANDSTONE)
Block(6,0,-3,RED_SANDSTONE)
Block(6,0,-2,RED_SANDSTONE)
Block(6,0,-1,RED_SANDSTONE)
Block(6,0,0,RED_SANDSTONE)
Block(6,0,1,RED_SANDSTONE)
Block(6,0,2,RED_SANDSTONE)
Block(6,0,3,RED_SANDSTONE)
Block(6,0,4,RED_SANDSTONE)
Block(6,0,5,RED_SANDSTONE)
Block(6,0,6,RED_SANDSTONE)
Block(6,0,7,RED_SANDSTONE)
Block(6,0,8,RED_SANDSTONE)
Block(6,0,9,RED_SANDSTONE)
Block(6,0,10,RED_SANDSTONE)
Block(6,0,11,RED_SANDSTONE)
Block(6,1,-13,STAINED_GLASS:1)
Block(6,1,-12,STAINED_GLASS:1)
Block(6,1,-11,RED_SANDSTONE)
Block(6,1,-10,RED_SANDSTONE)
Block(6,1,-9,RED_SANDSTONE)
Block(6,1,-8,RED_SANDSTONE)
Block(6,1,-7,RED_SANDSTONE)
Block(6,1,-6,RED_SANDSTONE)
Block(6,1,-5,RED_SANDSTONE)
Block(6,1,-4,RED_SANDSTONE)
Block(6,1,-3,RED_SANDSTONE)
Block(6,1,-2,RED_SANDSTONE)
Block(6,1,-1,RED_SANDSTONE)
Block(6,1,0,STAINED_GLASS:1)
Block(6,1,5,RED_SANDSTONE_STAIRS:2)
Block(6,1,6,RED_SANDSTONE)
Block(6,1,7,RED_SANDSTONE)
Block(6,1,8,RED_SANDSTONE)
Block(6,1,9,RED_SANDSTONE)
Block(6,1,10,RED_SANDSTONE)
Block(6,2,-12,STAINED_GLASS:1)
Block(6,2,-11,RED_SANDSTONE)
Block(6,2,-10,RED_SANDSTONE)
Block(6,2,-9,RED_SANDSTONE)
Block(6,2,-8,RED_SANDSTONE)
Block(6,2,-7,RED_SANDSTONE)
Block(6,2,-6,RED_SANDSTONE)
Block(6,2,-5,RED_SANDSTONE)
Block(6,2,-4,RED_SANDSTONE)
Block(6,2,-3,RED_SANDSTONE)
Block(6,2,-2,STAINED_GLASS:1)
Block(6,2,6,RED_SANDSTONE_STAIRS:4)
Block(6,2,7,SAND:1)
Block(6,2,8,SAND:1)
Block(6,2,9,RED_SANDSTONE)
Block(6,2,10,RED_SANDSTONE)
Block(6,3,-11,STAINED_GLASS:1)
Block(6,3,-10,STAINED_GLASS:1)
Block(6,3,-9,RED_SANDSTONE)
Block(6,3,-8,RED_SANDSTONE)
Block(6,3,-7,RED_SANDSTONE)
Block(6,3,-6,RED_SANDSTONE)
Block(6,3,-5,RED_SANDSTONE)
Block(6,3,5,RED_SANDSTONE_STAIRS:6)
Block(6,3,6,RED_SANDSTONE)
Block(6,3,7,SAND:1)
Block(6,3,8,RED_SANDSTONE)
Block(6,3,9,RED_SANDSTONE)
Block(6,4,-10,STAINED_GLASS:1)
Block(6,4,-9,STAINED_GLASS:1)
Block(6,4,5,RED_SANDSTONE)
Block(6,4,7,RED_SANDSTONE)
Block(6,5,5,RED_SANDSTONE_STAIRS:2)
Block(6,6,-9,STAINED_GLASS_PANE:1)
Block(6,6,6,STAINED_GLASS:1)
Block(6,6,7,STAINED_GLASS:1)
Block(6,7,-9,STAINED_GLASS:1)
Block(6,7,7,STAINED_GLASS:1)
Block(6,8,-9,STAINED_GLASS:1)
Block(6,8,-8,RED_SANDSTONE)
Block(6,8,-7,RED_SANDSTONE)
Block(6,8,6,STAINED_GLASS:1)
Block(6,9,-9,STAINED_GLASS:1)
Block(6,9,-8,STAINED_GLASS:1)
Block(6,9,-7,RED_SANDSTONE)
Block(6,9,-6,RED_SANDSTONE)
Block(6,9,-5,RED_SANDSTONE)
Block(6,9,-4,RED_SANDSTONE)
Block(6,9,4,RED_SANDSTONE)
Block(6,9,5,RED_SANDSTONE)
Block(6,9,6,RED_SANDSTONE)
Block(6,10,-9,STAINED_GLASS_PANE:1)
Block(6,10,-8,STAINED_GLASS:1)
Block(6,10,-7,STAINED_GLASS:1)
Block(6,10,-3,RED_SANDSTONE)
Block(6,10,1,RED_SANDSTONE)
Block(6,10,2,RED_SANDSTONE)
Block(6,10,3,RED_SANDSTONE)
Block(6,10,4,RED_SANDSTONE)
Block(6,10,5,RED_SANDSTONE)
Block(6,10,6,SAND:1)
Block(6,11,-2,RED_SANDSTONE)
Block(6,11,-1,RED_SANDSTONE)
Block(6,11,0,RED_SANDSTONE)
Block(6,11,1,RED_SANDSTONE)
Block(6,11,2,RED_SANDSTONE)
Block(6,11,3,RED_SANDSTONE)
Block(6,11,4,SAND:1)
Block(6,11,5,SAND:1)
Block(6,12,-2,RED_SANDSTONE)
Block(6,12,-1,RED_SANDSTONE)
Block(6,12,0,RED_SANDSTONE)
Block(6,12,1,RED_SANDSTONE)
Block(6,12,2,RED_SANDSTONE)
Block(6,13,-2,RED_SANDSTONE)
Block(6,13,-1,RED_SANDSTONE)
Block(6,13,0,RED_SANDSTONE)
Block(6,13,1,RED_SANDSTONE)
Block(6,13,2,RED_SANDSTONE)
Block(6,14,-3,RED_SANDSTONE)
Block(6,14,-2,RED_SANDSTONE)
Block(6,14,-1,RED_SANDSTONE)
Block(6,14,0,RED_SANDSTONE)
Block(6,14,1,SAND:1)
Block(6,15,-2,RED_SANDSTONE)
Block(6,15,-1,SAND:1)
Block(6,15,0,SAND:1)
Block(7,0,-14,RED_SANDSTONE)
Block(7,0,-13,RED_SANDSTONE)
Block(7,0,-12,RED_SANDSTONE)
Block(7,0,-11,RED_SANDSTONE)
Block(7,0,-10,RED_SANDSTONE)
Block(7,0,-9,RED_SANDSTONE)
Block(7,0,-8,RED_SANDSTONE)
Block(7,0,-7,RED_SANDSTONE)
Block(7,0,-6,RED_SANDSTONE)
Block(7,0,-5,RED_SANDSTONE)
Block(7,0,-4,RED_SANDSTONE)
Block(7,0,-3,RED_SANDSTONE)
Block(7,0,-2,RED_SANDSTONE)
Block(7,0,-1,RED_SANDSTONE)
Block(7,0,0,RED_SANDSTONE)
Block(7,0,1,RED_SANDSTONE)
Block(7,0,2,RED_SANDSTONE)
Block(7,0,3,RED_SANDSTONE)
Block(7,0,4,RED_SANDSTONE)
Block(7,0,5,RED_SANDSTONE)
Block(7,0,6,RED_SANDSTONE)
Block(7,0,7,RED_SANDSTONE)
Block(7,0,8,RED_SANDSTONE)
Block(7,0,9,RED_SANDSTONE)
Block(7,0,10,RED_SANDSTONE)
Block(7,0,11,RED_SANDSTONE)
Block(7,1,-14,STAINED_GLASS:1)
Block(7,1,-13,STAINED_GLASS:1)
Block(7,1,-12,STAINED_GLASS:1)
Block(7,1,-11,RED_SANDSTONE)
Block(7,1,-10,RED_SANDSTONE)
Block(7,1,-9,RED_SANDSTONE)
Block(7,1,-8,RED_SANDSTONE)
Block(7,1,-7,RED_SANDSTONE)
Block(7,1,-6,RED_SANDSTONE)
Block(7,1,-5,RED_SANDSTONE)
Block(7,1,-4,RED_SANDSTONE)
Block(7,1,-3,RED_SANDSTONE)
Block(7,1,-2,RED_SANDSTONE)
Block(7,1,-1,STAINED_GLASS:1)
Block(7,1,0,STAINED_GLASS:1)
Block(7,1,2,RED_SANDSTONE_STAIRS:0)
Block(7,1,3,RED_SANDSTONE_STAIRS:0)
Block(7,1,4,SAND:1)
Block(7,1,5,RED_SANDSTONE)
Block(7,1,6,RED_SANDSTONE)
Block(7,1,7,RED_SANDSTONE)
Block(7,1,8,RED_SANDSTONE)
Block(7,1,9,RED_SANDSTONE)
Block(7,2,-11,RED_SANDSTONE)
Block(7,2,-10,RED_SANDSTONE)
Block(7,2,-9,RED_SANDSTONE)
Block(7,2,-8,RED_SANDSTONE)
Block(7,2,-7,RED_SANDSTONE)
Block(7,2,-6,RED_SANDSTONE)
Block(7,2,-5,RED_SANDSTONE)
Block(7,2,-4,RED_SANDSTONE)
Block(7,2,-3,RED_SANDSTONE)
Block(7,2,-2,RED_SANDSTONE)
Block(7,2,0,STAINED_GLASS:1)
Block(7,2,6,RED_SANDSTONE)
Block(7,2,7,RED_SANDSTONE)
Block(7,2,8,RED_SANDSTONE)
Block(7,2,9,RED_SANDSTONE)
Block(7,3,-11,STAINED_GLASS:1)
Block(7,3,-10,RED_SANDSTONE)
Block(7,3,-9,RED_SANDSTONE)
Block(7,3,-8,RED_SANDSTONE)
Block(7,3,-7,RED_SANDSTONE)
Block(7,3,-6,RED_SANDSTONE)
Block(7,3,-5,RED_SANDSTONE)
Block(7,3,4,RED_SANDSTONE_STAIRS:4)
Block(7,3,5,RED_SANDSTONE)
Block(7,3,6,RED_SANDSTONE)
Block(7,3,7,RED_SANDSTONE)
Block(7,4,-10,STAINED_GLASS:1)
Block(7,4,-9,RED_SANDSTONE)
Block(7,4,-8,RED_SANDSTONE)
Block(7,4,-7,RED_SANDSTONE)
Block(7,5,-7,RED_SANDSTONE)
Block(7,5,-6,RED_SANDSTONE)
Block(7,6,-7,RED_SANDSTONE:2)
Block(7,6,-6,RED_SANDSTONE)
Block(7,6,-5,RED_SANDSTONE)
Block(7,7,-7,RED_SANDSTONE)
Block(7,7,-6,RED_SANDSTONE)
Block(7,7,-5,RED_SANDSTONE)
Block(7,7,-4,RED_SANDSTONE)
Block(7,7,-3,RED_SANDSTONE)
Block(7,7,2,RED_SANDSTONE)
Block(7,7,3,RED_SANDSTONE)
Block(7,7,4,RED_SANDSTONE_STAIRS:5)
Block(7,8,-8,STAINED_GLASS_PANE:1)
Block(7,8,-7,RED_SANDSTONE)
Block(7,8,-6,RED_SANDSTONE)
Block(7,8,-5,RED_SANDSTONE)
Block(7,8,-4,RED_SANDSTONE)
Block(7,8,-3,RED_SANDSTONE)
Block(7,8,-2,RED_SANDSTONE)
Block(7,8,1,RED_SANDSTONE_STAIRS:4)
Block(7,8,2,RED_SANDSTONE)
Block(7,8,3,RED_SANDSTONE)
Block(7,8,4,RED_SANDSTONE)
Block(7,9,-8,STAINED_GLASS:1)
Block(7,9,-6,RED_SANDSTONE)
Block(7,9,-5,RED_SANDSTONE)
Block(7,9,-4,RED_SANDSTONE)
Block(7,9,-3,RED_SANDSTONE)
Block(7,9,-2,RED_SANDSTONE)
Block(7,9,-1,RED_SANDSTONE_STAIRS:7)
Block(7,9,1,RED_SANDSTONE)
Block(7,9,2,RED_SANDSTONE)
Block(7,9,3,RED_SANDSTONE)
Block(7,9,4,RED_SANDSTONE)
Block(7,9,5,RED_SANDSTONE)
Block(7,10,-3,RED_SANDSTONE)
Block(7,10,-2,RED_SANDSTONE)
Block(7,10,-1,RED_SANDSTONE)
Block(7,10,0,RED_SANDSTONE)
Block(7,10,1,RED_SANDSTONE)
Block(7,10,2,RED_SANDSTONE)
Block(7,10,3,RED_SANDSTONE)
Block(7,10,4,SAND:1)
Block(7,11,-3,RED_SANDSTONE)
Block(7,11,-2,RED_SANDSTONE)
Block(7,11,-1,RED_SANDSTONE)
Block(7,11,0,RED_SANDSTONE)
Block(7,12,-2,RED_SANDSTONE)
Block(7,12,-1,RED_SANDSTONE)
Block(7,12,0,RED_SANDSTONE)
Block(7,12,1,RED_SANDSTONE)
Block(7,13,-2,RED_SANDSTONE)
Block(7,13,-1,RED_SANDSTONE)
Block(7,13,0,RED_SANDSTONE)
Block(7,14,-1,SAND:1)
Block(8,0,-13,RED_SANDSTONE)
Block(8,0,-12,RED_SANDSTONE)
Block(8,0,-11,RED_SANDSTONE)
Block(8,0,-10,RED_SANDSTONE)
Block(8,0,-9,RED_SANDSTONE)
Block(8,0,-8,RED_SANDSTONE)
Block(8,0,-7,RED_SANDSTONE)
Block(8,0,-6,RED_SANDSTONE)
Block(8,0,-5,RED_SANDSTONE)
Block(8,0,-4,RED_SANDSTONE)
Block(8,0,-3,RED_SANDSTONE)
Block(8,0,-2,RED_SANDSTONE)
Block(8,0,-1,RED_SANDSTONE)
Block(8,0,0,RED_SANDSTONE)
Block(8,0,1,RED_SANDSTONE)
Block(8,0,2,RED_SANDSTONE)
Block(8,0,3,RED_SANDSTONE)
Block(8,0,4,RED_SANDSTONE)
Block(8,0,5,RED_SANDSTONE)
Block(8,0,6,RED_SANDSTONE)
Block(8,0,7,RED_SANDSTONE)
Block(8,0,8,RED_SANDSTONE)
Block(8,0,9,RED_SANDSTONE)
Block(8,1,-13,STAINED_GLASS:1)
Block(8,1,-12,STAINED_GLASS:1)
Block(8,1,-11,RED_SANDSTONE)
Block(8,1,-10,RED_SANDSTONE)
Block(8,1,-9,RED_SANDSTONE)
Block(8,1,-8,RED_SANDSTONE)
Block(8,1,-7,RED_SANDSTONE)
Block(8,1,-6,RED_SANDSTONE)
Block(8,1,-5,RED_SANDSTONE)
Block(8,1,-4,RED_SANDSTONE)
Block(8,1,-3,RED_SANDSTONE)
Block(8,1,-2,RED_SANDSTONE)
Block(8,1,-1,STAINED_GLASS:1)
Block(8,1,0,STAINED_GLASS:1)
Block(8,1,1,RED_SANDSTONE_STAIRS:2)
Block(8,1,2,SAND:1)
Block(8,1,3,SAND:1)
Block(8,1,4,SAND:1)
Block(8,1,5,RED_SANDSTONE)
Block(8,1,6,RED_SANDSTONE)
Block(8,1,7,RED_SANDSTONE)
Block(8,1,8,RED_SANDSTONE)
Block(8,2,-11,RED_SANDSTONE)
Block(8,2,-10,RED_SANDSTONE)
Block(8,2,-9,RED_SANDSTONE)
Block(8,2,-8,RED_SANDSTONE)
Block(8,2,-7,RED_SANDSTONE)
Block(8,2,-6,RED_SANDSTONE)
Block(8,2,-5,RED_SANDSTONE)
Block(8,2,-4,RED_SANDSTONE)
Block(8,2,-3,RED_SANDSTONE)
Block(8,2,-2,STAINED_GLASS:1)
Block(8,2,-1,STAINED_GLASS:1)
Block(8,2,5,RED_SANDSTONE)
Block(8,2,6,RED_SANDSTONE)
Block(8,3,-10,RED_SANDSTONE)
Block(8,3,-9,RED_SANDSTONE)
Block(8,3,-8,RED_SANDSTONE)
Block(8,3,-7,RED_SANDSTONE)
Block(8,3,-6,RED_SANDSTONE)
Block(8,3,-5,RED_SANDSTONE)
Block(8,3,-4,RED_SANDSTONE)
Block(8,3,-3,STAINED_GLASS:1)
Block(8,3,-1,STAINED_GLASS:1)
Block(8,3,4,RED_SANDSTONE)
Block(8,3,5,RED_SANDSTONE)
Block(8,4,-8,RED_SANDSTONE)
Block(8,4,-7,RED_SANDSTONE)
Block(8,4,-6,RED_SANDSTONE)
Block(8,4,3,RED_SANDSTONE)
Block(8,5,-8,RED_SANDSTONE)
Block(8,5,-7,RED_SANDSTONE)
Block(8,5,-6,RED_SANDSTONE)
Block(8,5,-5,RED_SANDSTONE)
Block(8,5,-4,RED_SANDSTONE)
Block(8,5,-3,RED_SANDSTONE)
Block(8,5,-2,RED_SANDSTONE)
Block(8,6,-7,RED_SANDSTONE)
Block(8,6,-6,RED_SANDSTONE)
Block(8,6,-5,RED_SANDSTONE)
Block(8,6,-4,RED_SANDSTONE)
Block(8,6,-3,RED_SANDSTONE)
Block(8,6,-2,RED_SANDSTONE)
Block(8,6,-1,RED_SANDSTONE)
Block(8,6,0,RED_SANDSTONE)
Block(8,6,1,RED_SANDSTONE)
Block(8,6,2,RED_SANDSTONE)
Block(8,6,3,RED_SANDSTONE)
Block(8,7,-7,RED_SANDSTONE)
Block(8,7,-6,RED_SANDSTONE)
Block(8,7,-5,RED_SANDSTONE)
Block(8,7,-4,RED_SANDSTONE)
Block(8,7,-3,RED_SANDSTONE)
Block(8,7,-2,RED_SANDSTONE)
Block(8,7,-1,RED_SANDSTONE)
Block(8,7,0,RED_SANDSTONE)
Block(8,7,1,RED_SANDSTONE)
Block(8,7,2,RED_SANDSTONE)
Block(8,7,3,RED_SANDSTONE)
Block(8,8,-6,RED_SANDSTONE)
Block(8,8,-5,RED_SANDSTONE)
Block(8,8,-4,RED_SANDSTONE)
Block(8,8,-3,RED_SANDSTONE)
Block(8,8,-2,RED_SANDSTONE)
Block(8,8,-1,RED_SANDSTONE)
Block(8,8,0,RED_SANDSTONE)
Block(8,8,1,RED_SANDSTONE)
Block(8,8,2,RED_SANDSTONE)
Block(8,8,3,RED_SANDSTONE)
Block(8,9,-5,RED_SANDSTONE)
Block(8,9,-4,RED_SANDSTONE)
Block(8,9,-3,RED_SANDSTONE)
Block(8,9,-2,RED_SANDSTONE)
Block(8,9,-1,RED_SANDSTONE)
Block(8,9,0,RED_SANDSTONE)
Block(8,9,1,RED_SANDSTONE)
Block(8,9,2,RED_SANDSTONE)
Block(8,9,3,RED_SANDSTONE)
Block(8,10,-4,RED_SANDSTONE)
Block(8,10,-3,RED_SANDSTONE)
Block(8,10,-2,RED_SANDSTONE)
Block(8,10,-1,RED_SANDSTONE)
Block(8,10,0,RED_SANDSTONE)
Block(8,11,-3,STAINED_GLASS_PANE:1)
Block(8,11,-2,STAINED_GLASS:1)
Block(8,12,-2,STAINED_GLASS_PANE:1)
Block(9,0,-12,RED_SANDSTONE)
Block(9,0,-11,RED_SANDSTONE)
Block(9,0,-10,RED_SANDSTONE)
Block(9,0,-9,RED_SANDSTONE)
Block(9,0,-8,RED_SANDSTONE)
Block(9,0,-7,RED_SANDSTONE)
Block(9,0,-6,RED_SANDSTONE)
Block(9,0,-5,RED_SANDSTONE)
Block(9,0,-4,RED_SANDSTONE)
Block(9,0,-3,RED_SANDSTONE)
Block(9,0,-2,RED_SANDSTONE)
Block(9,0,-1,RED_SANDSTONE)
Block(9,0,0,RED_SANDSTONE)
Block(9,0,1,RED_SANDSTONE)
Block(9,0,2,RED_SANDSTONE)
Block(9,0,3,RED_SANDSTONE)
Block(9,0,4,RED_SANDSTONE)
Block(9,0,5,RED_SANDSTONE)
Block(9,0,6,RED_SANDSTONE)
Block(9,0,7,RED_SANDSTONE)
Block(9,0,8,RED_SANDSTONE)
Block(9,0,9,RED_SANDSTONE)
Block(9,1,-11,RED_SANDSTONE)
Block(9,1,-10,RED_SANDSTONE)
Block(9,1,-9,RED_SANDSTONE)
Block(9,1,-8,RED_SANDSTONE)
Block(9,1,-7,RED_SANDSTONE)
Block(9,1,-6,RED_SANDSTONE)
Block(9,1,-5,RED_SANDSTONE)
Block(9,1,-4,RED_SANDSTONE)
Block(9,1,-3,RED_SANDSTONE)
Block(9,1,-2,RED_SANDSTONE)
Block(9,1,-1,RED_SANDSTONE)
Block(9,1,0,RED_SANDSTONE_STAIRS:0)
Block(9,1,1,RED_SANDSTONE_STAIRS:0)
Block(9,1,2,SAND:1)
Block(9,1,3,SAND:1)
Block(9,1,4,RED_SANDSTONE)
Block(9,1,5,RED_SANDSTONE)
Block(9,1,6,RED_SANDSTONE)
Block(9,2,-10,RED_SANDSTONE)
Block(9,2,-9,RED_SANDSTONE)
Block(9,2,-8,RED_SANDSTONE)
Block(9,2,-7,RED_SANDSTONE)
Block(9,2,-6,RED_SANDSTONE)
Block(9,2,-5,RED_SANDSTONE)
Block(9,2,-4,RED_SANDSTONE)
Block(9,2,-3,RED_SANDSTONE)
Block(9,2,-2,STAINED_GLASS:1)
Block(9,2,-1,STAINED_GLASS:1)
Block(9,2,4,RED_SANDSTONE)
Block(9,2,5,SAND:1)
Block(9,2,6,RED_SANDSTONE)
Block(9,3,-8,RED_SANDSTONE)
Block(9,3,-7,RED_SANDSTONE)
Block(9,3,-6,RED_SANDSTONE)
Block(9,3,-5,RED_SANDSTONE)
Block(9,3,-4,RED_SANDSTONE)
Block(9,3,-3,RED_SANDSTONE)
Block(9,3,-2,STAINED_GLASS:1)
Block(9,3,-1,STAINED_GLASS:1)
Block(9,3,3,RED_SANDSTONE)
Block(9,3,4,SAND:1)
Block(9,4,-6,RED_SANDSTONE)
Block(9,4,-5,RED_SANDSTONE)
Block(9,4,-4,RED_SANDSTONE)
Block(9,4,-3,RED_SANDSTONE)
Block(9,4,-2,RED_SANDSTONE)
Block(9,4,-1,STAINED_GLASS:1)
Block(9,4,2,RED_SANDSTONE)
Block(9,4,3,RED_SANDSTONE)
Block(9,5,-5,RED_SANDSTONE)
Block(9,5,-4,RED_SANDSTONE)
Block(9,5,-3,RED_SANDSTONE)
Block(9,5,-2,RED_SANDSTONE)
Block(9,5,-1,RED_SANDSTONE)
Block(9,5,0,RED_SANDSTONE)
Block(9,5,1,RED_SANDSTONE)
Block(9,5,2,RED_SANDSTONE)
Block(9,5,3,RED_SANDSTONE)
Block(9,6,-4,RED_SANDSTONE)
Block(9,6,-3,RED_SANDSTONE)
Block(9,6,-2,RED_SANDSTONE)
Block(9,6,-1,RED_SANDSTONE)
Block(9,6,0,RED_SANDSTONE)
Block(9,6,1,RED_SANDSTONE)
Block(9,6,2,RED_SANDSTONE)
Block(9,7,-3,STAINED_GLASS:1)
Block(9,7,-2,RED_SANDSTONE)
Block(9,7,-1,RED_SANDSTONE)
Block(9,7,0,RED_SANDSTONE)
Block(9,7,1,RED_SANDSTONE)
Block(9,8,-2,STAINED_GLASS:1)
Block(9,8,-1,RED_SANDSTONE)
Block(9,8,0,RED_SANDSTONE)
Block(9,8,1,RED_SANDSTONE)
Block(9,9,-2,STAINED_GLASS:1)
Block(9,9,-1,RED_SANDSTONE)
Block(9,9,0,RED_SANDSTONE)
Block(9,10,-2,STAINED_GLASS:1)
Block(9,10,-1,STAINED_GLASS:1)
Block(9,11,-2,STAINED_GLASS_PANE:1)
Block(10,0,-10,RED_SANDSTONE)
Block(10,0,-9,RED_SANDSTONE)
Block(10,0,-8,RED_SANDSTONE)
Block(10,0,-7,RED_SANDSTONE)
Block(10,0,-6,RED_SANDSTONE)
Block(10,0,-5,RED_SANDSTONE)
Block(10,0,-4,RED_SANDSTONE)
Block(10,0,-3,RED_SANDSTONE)
Block(10,0,-2,RED_SANDSTONE)
Block(10,0,-1,RED_SANDSTONE)
Block(10,0,0,RED_SANDSTONE)
Block(10,0,1,RED_SANDSTONE)
Block(10,0,2,RED_SANDSTONE)
Block(10,0,3,RED_SANDSTONE)
Block(10,0,4,RED_SANDSTONE)
Block(10,0,5,RED_SANDSTONE)
Block(10,0,6,RED_SANDSTONE)
Block(10,0,7,RED_SANDSTONE)
Block(10,0,8,RED_SANDSTONE)
Block(10,1,-10,RED_SANDSTONE)
Block(10,1,-9,RED_SANDSTONE)
Block(10,1,-8,RED_SANDSTONE)
Block(10,1,-7,RED_SANDSTONE)
Block(10,1,-6,RED_SANDSTONE)
Block(10,1,-5,RED_SANDSTONE)
Block(10,1,-4,RED_SANDSTONE)
Block(10,1,-3,RED_SANDSTONE)
Block(10,1,-2,RED_SANDSTONE)
Block(10,1,-1,RED_SANDSTONE)
Block(10,1,0,RED_SANDSTONE)
Block(10,1,1,RED_SANDSTONE)
Block(10,1,2,RED_SANDSTONE)
Block(10,1,3,RED_SANDSTONE)
Block(10,1,4,RED_SANDSTONE)
Block(10,1,5,RED_SANDSTONE)
Block(10,1,6,RED_SANDSTONE)
Block(10,2,-9,RED_SANDSTONE)
Block(10,2,-8,RED_SANDSTONE)
Block(10,2,-7,RED_SANDSTONE)
Block(10,2,-6,RED_SANDSTONE)
Block(10,2,-5,RED_SANDSTONE)
Block(10,2,-4,RED_SANDSTONE)
Block(10,2,-3,RED_SANDSTONE)
Block(10,2,-2,RED_SANDSTONE)
Block(10,2,-1,RED_SANDSTONE)
Block(10,2,0,STAINED_GLASS:1)
Block(10,2,3,RED_SANDSTONE)
Block(10,2,4,SAND:1)
Block(10,2,5,SAND:1)
Block(10,3,-8,RED_SANDSTONE)
Block(10,3,-7,RED_SANDSTONE)
Block(10,3,-6,RED_SANDSTONE)
Block(10,3,-5,RED_SANDSTONE)
Block(10,3,-4,RED_SANDSTONE)
Block(10,3,-3,RED_SANDSTONE)
Block(10,3,-2,RED_SANDSTONE)
Block(10,3,-1,RED_SANDSTONE)
Block(10,3,0,RED_SANDSTONE)
Block(10,3,2,RED_SANDSTONE)
Block(10,3,3,RED_SANDSTONE)
Block(10,4,-6,RED_SANDSTONE)
Block(10,4,-5,RED_SANDSTONE)
Block(10,4,-4,RED_SANDSTONE)
Block(10,4,-3,RED_SANDSTONE)
Block(10,4,-2,RED_SANDSTONE)
Block(10,4,-1,RED_SANDSTONE)
Block(10,4,0,RED_SANDSTONE)
Block(10,4,1,RED_SANDSTONE)
Block(10,4,2,RED_SANDSTONE)
Block(10,4,3,RED_SANDSTONE)
Block(10,5,-3,STAINED_GLASS:1)
Block(10,5,-2,STAINED_GLASS:1)
Block(10,5,-1,RED_SANDSTONE)
Block(10,5,0,RED_SANDSTONE)
Block(10,5,1,RED_SANDSTONE)
Block(10,5,2,RED_SANDSTONE)
Block(10,6,-2,STAINED_GLASS:1)
Block(10,6,-1,STAINED_GLASS:1)
Block(10,6,0,STAINED_GLASS:1)
Block(10,7,-2,STAINED_GLASS:1)
Block(10,8,-1,STAINED_GLASS:1)
Block(10,9,-2,STAINED_GLASS_PANE:1)
Block(10,9,-1,STAINED_GLASS:1)
Block(10,10,-2,STAINED_GLASS_PANE:1)
Block(10,10,-1,STAINED_GLASS_PANE:1)
Block(11,0,-9,RED_SANDSTONE)
Block(11,0,-8,RED_SANDSTONE)
Block(11,0,-7,RED_SANDSTONE)
Block(11,0,-6,RED_SANDSTONE)
Block(11,0,-5,RED_SANDSTONE)
Block(11,0,-4,RED_SANDSTONE)
Block(11,0,-3,RED_SANDSTONE)
Block(11,0,-2,RED_SANDSTONE)
Block(11,0,-1,RED_SANDSTONE)
Block(11,0,0,RED_SANDSTONE)
Block(11,0,1,RED_SANDSTONE)
Block(11,0,2,RED_SANDSTONE)
Block(11,0,3,RED_SANDSTONE)
Block(11,0,4,RED_SANDSTONE)
Block(11,0,5,RED_SANDSTONE)
Block(11,0,6,RED_SANDSTONE)
Block(11,0,8,RED_SANDSTONE)
Block(11,1,-9,RED_SANDSTONE)
Block(11,1,-8,RED_SANDSTONE)
Block(11,1,-7,RED_SANDSTONE)
Block(11,1,-6,RED_SANDSTONE)
Block(11,1,-5,RED_SANDSTONE)
Block(11,1,-4,RED_SANDSTONE)
Block(11,1,-3,RED_SANDSTONE)
Block(11,1,-2,RED_SANDSTONE)
Block(11,1,-1,RED_SANDSTONE)
Block(11,1,0,RED_SANDSTONE)
Block(11,1,1,RED_SANDSTONE)
Block(11,1,2,RED_SANDSTONE)
Block(11,1,3,RED_SANDSTONE)
Block(11,1,4,RED_SANDSTONE)
Block(11,1,5,RED_SANDSTONE)
Block(11,2,-9,RED_SANDSTONE)
Block(11,2,-8,RED_SANDSTONE)
Block(11,2,-7,RED_SANDSTONE)
Block(11,2,-6,RED_SANDSTONE)
Block(11,2,-5,RED_SANDSTONE)
Block(11,2,-4,RED_SANDSTONE)
Block(11,2,-3,STAINED_GLASS:1)
Block(11,2,-2,RED_SANDSTONE)
Block(11,2,-1,RED_SANDSTONE)
Block(11,2,0,RED_SANDSTONE)
Block(11,2,1,RED_SANDSTONE)
Block(11,2,2,RED_SANDSTONE)
Block(11,2,3,RED_SANDSTONE)
Block(11,2,4,SAND:1)
Block(11,3,-6,RED_SANDSTONE)
Block(11,3,-5,RED_SANDSTONE)
Block(11,3,-4,RED_SANDSTONE)
Block(11,3,-3,STAINED_GLASS:1)
Block(11,3,-2,STAINED_GLASS:1)
Block(11,3,-1,RED_SANDSTONE)
Block(11,3,0,RED_SANDSTONE)
Block(11,3,1,RED_SANDSTONE)
Block(11,3,2,RED_SANDSTONE)
Block(11,3,3,RED_SANDSTONE)
Block(11,4,-3,STAINED_GLASS_PANE:1)
Block(11,4,-2,RED_SANDSTONE)
Block(11,4,-1,RED_SANDSTONE)
Block(11,4,0,RED_SANDSTONE)
Block(11,4,1,RED_SANDSTONE)
Block(11,4,2,RED_SANDSTONE)
Block(11,5,-3,STAINED_GLASS_PANE:1)
Block(11,5,-2,STAINED_GLASS:1)
Block(11,6,-2,STAINED_GLASS_PANE:1)
Block(11,7,-2,STAINED_GLASS_PANE:1)
Block(12,0,-8,RED_SANDSTONE)
Block(12,0,-7,RED_SANDSTONE)
Block(12,0,-6,RED_SANDSTONE)
Block(12,0,-5,RED_SANDSTONE)
Block(12,0,-4,RED_SANDSTONE)
Block(12,0,-2,RED_SANDSTONE)
Block(12,0,-1,RED_SANDSTONE)
Block(12,0,0,RED_SANDSTONE)
Block(12,0,1,RED_SANDSTONE)
Block(12,0,2,RED_SANDSTONE)
Block(12,0,3,RED_SANDSTONE)
Block(12,0,4,RED_SANDSTONE)
Block(12,1,-8,RED_SANDSTONE)
Block(12,1,-7,RED_SANDSTONE)
Block(12,1,-6,RED_SANDSTONE)
Block(12,1,-5,RED_SANDSTONE)
Block(12,1,-4,RED_SANDSTONE)
Block(12,1,-3,STAINED_GLASS_PANE:1)
Block(12,1,-2,RED_SANDSTONE)
Block(12,1,-1,RED_SANDSTONE)
Block(12,1,0,RED_SANDSTONE)
Block(12,1,1,RED_SANDSTONE)
Block(12,1,2,RED_SANDSTONE)
Block(12,1,3,RED_SANDSTONE)
Block(12,1,4,RED_SANDSTONE)
Block(12,2,-7,RED_SANDSTONE)
Block(12,2,-6,RED_SANDSTONE)
Block(12,2,-5,RED_SANDSTONE)
Block(12,2,-3,STAINED_GLASS_PANE:1)
Block(12,2,-2,RED_SANDSTONE)
Block(12,2,-1,RED_SANDSTONE)
Block(12,2,0,RED_SANDSTONE)
Block(12,2,1,RED_SANDSTONE)
Block(12,2,2,RED_SANDSTONE)
Block(12,2,3,RED_SANDSTONE)
Block(12,3,-1,RED_SANDSTONE)
Block(12,3,0,RED_SANDSTONE)
Block(12,3,1,RED_SANDSTONE)
Block(12,3,2,RED_SANDSTONE)
Block(12,4,-3,STAINED_GLASS_PANE:1)
Block(12,4,-2,STAINED_GLASS:1)
Block(13,0,-1,RED_SANDSTONE)
Block(13,0,0,RED_SANDSTONE)
Block(13,0,1,RED_SANDSTONE)
Block(13,0,2,RED_SANDSTONE)
Block(13,0,3,RED_SANDSTONE)
Block(13,1,-1,RED_SANDSTONE)
Block(13,1,0,RED_SANDSTONE)
Block(13,1,1,RED_SANDSTONE)
Block(13,1,2,RED_SANDSTONE)
Block(13,1,3,RED_SANDSTONE)
Block(13,2,0,RED_SANDSTONE)
Block(13,2,1,RED_SANDSTONE)
Block(13,2,2,RED_SANDSTONE)

#######################################################################
# +-----------------------------------------------------------------+ #
# |                            BO3 checks                           | #
# +-----------------------------------------------------------------+ #
#######################################################################


#######################################################################
# +-----------------------------------------------------------------+ #
# |                             Branches                            | #
# +-----------------------------------------------------------------+ #
#######################################################################


#######################################################################
# +-----------------------------------------------------------------+ #
# |                             Entities                            | #
# +-----------------------------------------------------------------+ #
#######################################################################


#######################################################################
# +-----------------------------------------------------------------+ #
# |                            Particles                            | #
# +-----------------------------------------------------------------+ #
#######################################################################


#######################################################################
# +-----------------------------------------------------------------+ #
# |                             Spawners                            | #
# +-----------------------------------------------------------------+ #
#######################################################################


#######################################################################
# +-----------------------------------------------------------------+ #
# |                             ModData                             | #
# +-----------------------------------------------------------------+ #
#######################################################################

