
#######################################################################
# +-----------------------------------------------------------------+ #
# |                            BO3 object                           | #
# +-----------------------------------------------------------------+ #
#######################################################################

Author: kumquatmay

Description: No description given

Version: 3

SettingsMode: WriteWithoutComments


#######################################################################
# +-----------------------------------------------------------------+ #
# |                          Main settings                          | #
# +-----------------------------------------------------------------+ #
#######################################################################

Tree: false

Frequency: 0

Rarity: 50.0

RotateRandomly: true

SpawnHeight: highestBlock

SpawnHeightOffset: 0

SpawnHeightVariance: 0

##############################
# Height Limits for the BO3. #
##############################

MinHeight: 0

MaxHeight: 256

######################
# Extrusion settings #
######################

ExtrudeMode: None

ExtrudeThroughBlocks: AIR

MaxBranchDepth: 10

ExcludedBiomes: All


#######################################################################
# +-----------------------------------------------------------------+ #
# |                      Source block settings                      | #
# +-----------------------------------------------------------------+ #
#######################################################################

SourceBlocks: AIR

MaxPercentageOutsideSourceBlock: 10

OutsideSourceBlock: placeAnyway

IsOTGPlus: false


#######################################################################
# +-----------------------------------------------------------------+ #
# |                              Blocks                             | #
# +-----------------------------------------------------------------+ #
#######################################################################

Block(-11,1,-2,STAINED_CLAY:9)
Block(-11,1,-1,STAINED_CLAY:9)
Block(-11,1,0,STAINED_CLAY:9)
Block(-11,1,1,STAINED_CLAY:9)
Block(-11,1,2,STAINED_CLAY:9)
Block(-11,1,3,STAINED_CLAY:9)
Block(-11,2,-3,STAINED_CLAY:9)
Block(-11,2,-2,STAINED_CLAY:9)
Block(-11,2,-1,IRON_TRAPDOOR:6)
Block(-11,2,0,IRON_TRAPDOOR:6)
Block(-11,2,1,IRON_TRAPDOOR:6)
Block(-11,2,2,IRON_TRAPDOOR:6)
Block(-11,2,3,STAINED_CLAY:9)
Block(-11,2,4,STAINED_CLAY:9)
Block(-11,3,-3,STAINED_CLAY:9)
Block(-11,3,-2,IRON_TRAPDOOR:6)
Block(-11,3,-1,IRON_TRAPDOOR:6)
Block(-11,3,0,IRON_TRAPDOOR:6)
Block(-11,3,1,IRON_TRAPDOOR:6)
Block(-11,3,2,IRON_TRAPDOOR:6)
Block(-11,3,3,IRON_TRAPDOOR:6)
Block(-11,3,4,STAINED_CLAY:9)
Block(-11,4,-3,STAINED_CLAY:9)
Block(-11,4,-2,STAINED_CLAY:9)
Block(-11,4,-1,IRON_TRAPDOOR:6)
Block(-11,4,0,IRON_TRAPDOOR:6)
Block(-11,4,1,IRON_TRAPDOOR:6)
Block(-11,4,2,IRON_TRAPDOOR:6)
Block(-11,4,3,STAINED_CLAY:9)
Block(-11,4,4,STAINED_CLAY:9)
Block(-11,5,-2,STAINED_CLAY:9)
Block(-11,5,-1,STAINED_CLAY:9)
Block(-11,5,0,STAINED_CLAY:9)
Block(-11,5,1,STAINED_CLAY:9)
Block(-11,5,2,STAINED_CLAY:9)
Block(-11,5,3,STAINED_CLAY:9)
Block(-11,6,-3,IRON_TRAPDOOR:10)
Block(-11,6,-2,IRON_FENCE)
Block(-11,6,-1,IRON_FENCE)
Block(-11,6,2,IRON_FENCE)
Block(-11,6,4,IRON_TRAPDOOR:10)
Block(-11,7,2,IRON_FENCE)
Block(-10,1,-1,STEP:8)
Block(-10,1,0,STEP:8)
Block(-10,1,1,STEP:8)
Block(-10,1,2,STEP:8)
Block(-10,2,-2,SMOOTH_STAIRS:6)
Block(-10,2,-1,SEA_LANTERN)
Block(-10,2,0,SEA_LANTERN)
Block(-10,2,1,SEA_LANTERN)
Block(-10,2,2,SEA_LANTERN)
Block(-10,2,3,SMOOTH_STAIRS:7)
Block(-10,2,4,IRON_FENCE)
Block(-10,3,-3,IRON_TRAPDOOR:12)
Block(-10,3,-2,SEA_LANTERN)
Block(-10,3,-1,SEA_LANTERN)
Block(-10,3,0,SEA_LANTERN)
Block(-10,3,1,SEA_LANTERN)
Block(-10,3,2,SEA_LANTERN)
Block(-10,3,3,SEA_LANTERN)
Block(-10,3,4,IRON_TRAPDOOR:13)
Block(-10,4,-3,IRON_FENCE)
Block(-10,4,-2,CONCRETE:7)
Block(-10,4,-1,SEA_LANTERN)
Block(-10,4,0,SEA_LANTERN)
Block(-10,4,1,SEA_LANTERN)
Block(-10,4,2,SEA_LANTERN)
Block(-10,4,3,SMOOTH_STAIRS:0)
Block(-10,5,-3,IRON_FENCE)
Block(-10,5,-2,CONCRETE:7)
Block(-10,5,-1,WORKBENCH)
Block(-10,5,0,WORKBENCH)
Block(-10,5,1,ANVIL)
Block(-10,5,3,SMOOTH_STAIRS:7)
Block(-10,6,-3,STEP:8)
Block(-10,6,-2,CONCRETE:7)
Block(-10,6,-1,CONCRETE:7)
Block(-10,6,0,SMOOTH_STAIRS:0)
Block(-10,6,1,SMOOTH_STAIRS:0)
Block(-10,6,2,CONCRETE:7)
Block(-10,6,3,CONCRETE:7)
Block(-10,6,4,STEP:8)
Block(-10,7,-3,IRON_TRAPDOOR:2)
Block(-10,7,-1,CONCRETE:7)
Block(-10,7,0,SMOOTH_STAIRS:0)
Block(-10,7,1,SMOOTH_STAIRS:0)
Block(-10,7,2,CONCRETE:7)
Block(-10,7,4,IRON_TRAPDOOR:2)
Block(-9,0,-5,SMOOTH_STAIRS:2)
Block(-9,0,-4,SMOOTH_STAIRS:7)
Block(-9,1,-4,SMOOTH_STAIRS:2)
Block(-9,1,-3,SMOOTH_STAIRS:7)
Block(-9,1,0,STEP:8)
Block(-9,1,1,STEP:8)
Block(-9,2,-3,SMOOTH_STAIRS:2)
Block(-9,2,-2,SMOOTH_STAIRS:7)
Block(-9,2,-1,OBSERVER:1)
Block(-9,2,0,REDSTONE_BLOCK)
Block(-9,2,1,END_ROD:4)
Block(-9,2,2,OBSERVER:1)
Block(-9,2,3,IRON_TRAPDOOR:9)
Block(-9,2,4,IRON_FENCE)
Block(-9,3,-2,SMOOTH_STAIRS:2)
Block(-9,3,-1,STEP:13)
Block(-9,3,0,END_ROD:4)
Block(-9,3,1,GOLD_BLOCK)
Block(-9,3,3,CONCRETE:7)
Block(-9,3,4,IRON_FENCE)
Block(-9,4,0,IRON_TRAPDOOR:2)
Block(-9,4,1,STEP:5)
Block(-9,4,2,STEP:5)
Block(-9,4,3,CONCRETE:7)
Block(-9,5,3,CONCRETE:7)
Block(-9,6,-3,STEP:8)
Block(-9,6,-2,CONCRETE:7)
Block(-9,6,-1,IRON_TRAPDOOR:11)
Block(-9,6,0,IRON_TRAPDOOR:11)
Block(-9,6,1,IRON_TRAPDOOR:11)
Block(-9,6,2,IRON_TRAPDOOR:11)
Block(-9,6,3,SMOOTH_STAIRS:7)
Block(-9,6,4,STEP:8)
Block(-9,7,-2,OBSERVER:5)
Block(-9,7,0,CHEST:5,NetherZoxShip/1-chest.nbt)
Block(-9,7,3,OBSERVER:5)
Block(-9,8,-1,CONCRETE:7)
Block(-9,8,0,SMOOTH_STAIRS:0)
Block(-9,8,1,SMOOTH_STAIRS:0)
Block(-9,8,2,CONCRETE:7)
Block(-9,10,-1,IRON_FENCE)
Block(-8,0,-5,SMOOTH_STAIRS:2)
Block(-8,0,-4,SMOOTH_STAIRS:7)
Block(-8,1,-4,SMOOTH_STAIRS:2)
Block(-8,1,-3,SMOOTH_STAIRS:7)
Block(-8,1,0,STEP:8)
Block(-8,1,1,STEP:8)
Block(-8,2,-3,SMOOTH_STAIRS:2)
Block(-8,2,-2,SMOOTH_STAIRS:7)
Block(-8,2,-1,OBSERVER:4)
Block(-8,2,0,GOLD_BLOCK)
Block(-8,2,1,END_ROD:4)
Block(-8,2,2,OBSERVER:4)
Block(-8,2,3,IRON_TRAPDOOR:9)
Block(-8,3,-2,SMOOTH_STAIRS:2)
Block(-8,3,-1,STEP:13)
Block(-8,3,0,END_ROD:4)
Block(-8,3,1,REDSTONE_BLOCK)
Block(-8,3,3,CONCRETE:7)
Block(-8,3,4,IRON_TRAPDOOR:1)
Block(-8,4,-2,STAINED_GLASS_PANE:1)
Block(-8,4,0,IRON_TRAPDOOR:2)
Block(-8,4,1,STEP:5)
Block(-8,4,2,STEP:5)
Block(-8,4,3,SMOOTH_STAIRS:7)
Block(-8,5,-2,STAINED_GLASS_PANE:1)
Block(-8,5,3,SMOOTH_STAIRS:7)
Block(-8,6,-3,STEP:8)
Block(-8,6,-2,CONCRETE:7)
Block(-8,6,3,SMOOTH_STAIRS:7)
Block(-8,6,4,STEP:8)
Block(-8,7,-2,OBSERVER:5)
Block(-8,7,3,OBSERVER:5)
Block(-8,8,-2,CONCRETE:7)
Block(-8,8,-1,CONCRETE:7)
Block(-8,8,0,CONCRETE:7)
Block(-8,8,1,CONCRETE:7)
Block(-8,8,2,CONCRETE:7)
Block(-8,8,3,CONCRETE:7)
Block(-8,9,-1,IRON_FENCE)
Block(-8,9,1,LEVER:6)
Block(-8,10,-2,IRON_FENCE)
Block(-8,10,-1,IRON_FENCE)
Block(-7,0,3,SMOOTH_STAIRS:0)
Block(-7,1,0,STEP:8)
Block(-7,1,1,STEP:8)
Block(-7,2,-2,IRON_TRAPDOOR:8)
Block(-7,2,-1,OBSERVER:1)
Block(-7,2,0,GOLD_BLOCK)
Block(-7,2,1,END_ROD:4)
Block(-7,2,2,OBSERVER:1)
Block(-7,2,3,IRON_TRAPDOOR:9)
Block(-7,3,-2,CONCRETE:7)
Block(-7,3,0,END_ROD:4)
Block(-7,3,1,REDSTONE_BLOCK)
Block(-7,3,3,CONCRETE:7)
Block(-7,3,4,IRON_TRAPDOOR:1)
Block(-7,4,-2,CONCRETE:7)
Block(-7,4,-1,STEP:5)
Block(-7,4,0,STEP:5)
Block(-7,4,1,STEP:5)
Block(-7,4,2,STEP:5)
Block(-7,4,3,CONCRETE:7)
Block(-7,5,-2,CONCRETE:7)
Block(-7,5,3,CONCRETE:7)
Block(-7,6,-3,STEP:8)
Block(-7,6,-2,CONCRETE:7)
Block(-7,6,3,CONCRETE:7)
Block(-7,6,4,STEP:8)
Block(-7,7,-2,OBSERVER:5)
Block(-7,7,3,OBSERVER:5)
Block(-7,8,-2,CONCRETE:7)
Block(-7,8,-1,CLAY)
Block(-7,8,0,CLAY)
Block(-7,8,1,CLAY)
Block(-7,8,2,CLAY)
Block(-7,8,3,CONCRETE:7)
Block(-7,9,-1,DAYLIGHT_DETECTOR_INVERTED,NetherZoxShip/2-daylight_detector.nbt)
Block(-7,9,0,DAYLIGHT_DETECTOR_INVERTED,NetherZoxShip/3-daylight_detector.nbt)
Block(-7,9,1,LEVER:14)
Block(-7,9,2,IRON_FENCE)
Block(-7,10,2,IRON_FENCE)
Block(-7,11,2,IRON_FENCE)
Block(-6,0,2,SMOOTH_STAIRS:2)
Block(-6,0,3,STONE:6)
Block(-6,0,4,SMOOTH_STAIRS:0)
Block(-6,1,-1,IRON_TRAPDOOR:10)
Block(-6,1,0,IRON_TRAPDOOR:10)
Block(-6,1,1,IRON_TRAPDOOR:10)
Block(-6,1,2,IRON_TRAPDOOR:10)
Block(-6,1,3,COBBLE_WALL)
Block(-6,2,-2,DOUBLE_STEP)
Block(-6,2,-1,MAGMA)
Block(-6,2,0,MAGMA)
Block(-6,2,1,MAGMA)
Block(-6,2,2,MAGMA)
Block(-6,2,3,DOUBLE_STEP)
Block(-6,3,-3,STEP)
Block(-6,3,-2,DOUBLE_STEP)
Block(-6,3,-1,MAGMA)
Block(-6,3,0,MAGMA)
Block(-6,3,1,MAGMA)
Block(-6,3,2,MAGMA)
Block(-6,3,3,DOUBLE_STEP)
Block(-6,3,4,STEP)
Block(-6,4,-3,STEP:8)
Block(-6,4,-2,SEA_LANTERN)
Block(-6,4,-1,CLAY)
Block(-6,4,0,STEP:13)
Block(-6,4,1,STEP:13)
Block(-6,4,2,CLAY)
Block(-6,4,3,SEA_LANTERN)
Block(-6,4,4,STEP:8)
Block(-6,5,-3,END_ROD)
Block(-6,5,-2,STAINED_CLAY:9)
Block(-6,5,3,STAINED_CLAY:9)
Block(-6,5,4,END_ROD)
Block(-6,6,-3,STEP)
Block(-6,6,-2,CLAY)
Block(-6,6,3,CLAY)
Block(-6,6,4,STEP)
Block(-6,7,-2,CLAY)
Block(-6,7,2,WALL_SIGN,NetherZoxShip/4-sign.nbt)
Block(-6,7,3,CLAY)
Block(-6,8,-2,CLAY)
Block(-6,8,3,CLAY)
Block(-6,9,-1,STEP)
Block(-6,9,0,STEP)
Block(-6,9,1,STEP)
Block(-6,9,2,STEP)
Block(-6,9,3,IRON_FENCE)
Block(-5,0,3,SMOOTH_STAIRS:1)
Block(-5,1,0,STEP:8)
Block(-5,1,1,STEP:8)
Block(-5,2,-8,SMOOTH_STAIRS:6)
Block(-5,2,-7,CONCRETE:7)
Block(-5,2,-6,SMOOTH_STAIRS:7)
Block(-5,2,-3,IRON_TRAPDOOR:8)
Block(-5,2,-2,STEP:8)
Block(-5,2,-1,STEP)
Block(-5,2,2,STEP)
Block(-5,2,3,STEP:8)
Block(-5,2,4,IRON_TRAPDOOR:9)
Block(-5,2,7,SMOOTH_STAIRS:6)
Block(-5,2,8,CONCRETE:7)
Block(-5,2,9,SMOOTH_STAIRS:7)
Block(-5,3,-9,SMOOTH_STAIRS:6)
Block(-5,3,-8,END_ROD:2)
Block(-5,3,-7,END_ROD:2)
Block(-5,3,-6,END_ROD:2)
Block(-5,3,-5,SMOOTH_STAIRS:7)
Block(-5,3,-4,STEP)
Block(-5,3,-3,SEA_LANTERN)
Block(-5,3,-2,STEP)
Block(-5,3,-1,STEP:8)
Block(-5,3,2,STEP:8)
Block(-5,3,3,STEP)
Block(-5,3,4,SEA_LANTERN)
Block(-5,3,5,STEP)
Block(-5,3,6,SMOOTH_STAIRS:6)
Block(-5,3,7,END_ROD:3)
Block(-5,3,8,END_ROD:3)
Block(-5,3,9,END_ROD:3)
Block(-5,3,10,SMOOTH_STAIRS:7)
Block(-5,4,-9,CONCRETE:7)
Block(-5,4,-8,END_ROD:2)
Block(-5,4,-7,END_ROD:2)
Block(-5,4,-6,END_ROD:2)
Block(-5,4,-5,CONCRETE:7)
Block(-5,4,-4,STEP:8)
Block(-5,4,-3,SEA_LANTERN)
Block(-5,4,-2,STEP:8)
Block(-5,4,0,STEP)
Block(-5,4,1,STEP)
Block(-5,4,3,STEP:8)
Block(-5,4,4,SEA_LANTERN)
Block(-5,4,5,STEP:8)
Block(-5,4,6,CONCRETE:7)
Block(-5,4,7,END_ROD:3)
Block(-5,4,8,END_ROD:3)
Block(-5,4,9,END_ROD:3)
Block(-5,4,10,CONCRETE:7)
Block(-5,5,-9,SMOOTH_STAIRS:2)
Block(-5,5,-8,END_ROD:2)
Block(-5,5,-7,END_ROD:2)
Block(-5,5,-6,END_ROD:2)
Block(-5,5,-5,SMOOTH_STAIRS:0)
Block(-5,5,-4,END_ROD)
Block(-5,5,-3,CONCRETE)
Block(-5,5,-2,STAINED_CLAY:9)
Block(-5,5,-1,STAINED_CLAY:9)
Block(-5,5,0,STEP:5)
Block(-5,5,1,STEP:5)
Block(-5,5,2,STAINED_CLAY:9)
Block(-5,5,3,STAINED_CLAY:9)
Block(-5,5,4,CONCRETE)
Block(-5,5,6,SMOOTH_STAIRS:2)
Block(-5,5,7,END_ROD:3)
Block(-5,5,8,END_ROD:3)
Block(-5,5,9,END_ROD:3)
Block(-5,5,10,SMOOTH_STAIRS:0)
Block(-5,6,-8,SMOOTH_STAIRS:2)
Block(-5,6,-7,CONCRETE:7)
Block(-5,6,-6,SMOOTH_STAIRS:0)
Block(-5,6,-4,LEVER:12)
Block(-5,6,-3,CONCRETE)
Block(-5,6,-2,CONCRETE)
Block(-5,6,-1,STAINED_GLASS_PANE:1)
Block(-5,6,2,STAINED_GLASS_PANE:1)
Block(-5,6,3,CONCRETE)
Block(-5,6,4,CONCRETE)
Block(-5,6,7,SMOOTH_STAIRS:2)
Block(-5,6,8,CONCRETE:7)
Block(-5,6,9,SMOOTH_STAIRS:0)
Block(-5,7,-2,STAINED_GLASS:15)
Block(-5,7,3,STAINED_GLASS:15)
Block(-5,8,-2,CLAY)
Block(-5,8,3,CLAY)
Block(-5,9,-2,STEP)
Block(-5,9,-1,STEP)
Block(-5,9,0,CONCRETE:7)
Block(-5,9,1,CONCRETE:7)
Block(-5,9,2,STEP)
Block(-5,9,3,STEP)
Block(-4,2,-8,CONCRETE:7)
Block(-4,2,-7,CONCRETE:7)
Block(-4,2,-6,CONCRETE:7)
Block(-4,2,-4,IRON_TRAPDOOR:8)
Block(-4,2,-3,STEP:8)
Block(-4,2,4,STEP:8)
Block(-4,2,5,IRON_TRAPDOOR:9)
Block(-4,2,7,CONCRETE:7)
Block(-4,2,8,CONCRETE:7)
Block(-4,2,9,CONCRETE:7)
Block(-4,3,-9,CONCRETE:7)
Block(-4,3,-8,IRON_TRAPDOOR:7)
Block(-4,3,-7,IRON_TRAPDOOR:7)
Block(-4,3,-6,IRON_TRAPDOOR:7)
Block(-4,3,-5,CONCRETE:7)
Block(-4,3,-4,SEA_LANTERN)
Block(-4,3,5,SEA_LANTERN)
Block(-4,3,6,CONCRETE:7)
Block(-4,3,7,IRON_TRAPDOOR:7)
Block(-4,3,8,IRON_TRAPDOOR:7)
Block(-4,3,9,IRON_TRAPDOOR:7)
Block(-4,3,10,CONCRETE:7)
Block(-4,4,-9,CONCRETE:7)
Block(-4,4,-8,IRON_TRAPDOOR:7)
Block(-4,4,-7,IRON_TRAPDOOR:7)
Block(-4,4,-6,IRON_TRAPDOOR:7)
Block(-4,4,-5,CONCRETE:7)
Block(-4,4,-4,SEA_LANTERN)
Block(-4,4,-3,STEP:8)
Block(-4,4,-2,STEP:8)
Block(-4,4,3,STEP:8)
Block(-4,4,4,STEP:8)
Block(-4,4,5,SEA_LANTERN)
Block(-4,4,6,CONCRETE:7)
Block(-4,4,7,IRON_TRAPDOOR:7)
Block(-4,4,8,IRON_TRAPDOOR:7)
Block(-4,4,9,IRON_TRAPDOOR:7)
Block(-4,4,10,CONCRETE:7)
Block(-4,4,11,STONE_BUTTON:3)
Block(-4,5,-9,CONCRETE:7)
Block(-4,5,-8,IRON_TRAPDOOR:7)
Block(-4,5,-7,IRON_TRAPDOOR:7)
Block(-4,5,-6,IRON_TRAPDOOR:7)
Block(-4,5,-5,CONCRETE:7)
Block(-4,5,-4,IRON_TRAPDOOR:2)
Block(-4,5,-3,CONCRETE)
Block(-4,5,-1,DOUBLE_STEP)
Block(-4,5,0,DOUBLE_STEP)
Block(-4,5,1,DOUBLE_STEP)
Block(-4,5,2,DOUBLE_STEP)
Block(-4,5,4,CONCRETE)
Block(-4,5,5,IRON_TRAPDOOR:2)
Block(-4,5,6,CONCRETE:7)
Block(-4,5,7,IRON_TRAPDOOR:7)
Block(-4,5,8,IRON_TRAPDOOR:7)
Block(-4,5,9,IRON_TRAPDOOR:7)
Block(-4,5,10,CONCRETE:7)
Block(-4,5,11,STONE_BUTTON:3)
Block(-4,6,-8,CONCRETE:7)
Block(-4,6,-7,CONCRETE:7)
Block(-4,6,-6,CONCRETE:7)
Block(-4,6,-3,CONCRETE)
Block(-4,6,-2,CONCRETE)
Block(-4,6,-1,QUARTZ_STAIRS:1)
Block(-4,6,2,QUARTZ_STAIRS:1)
Block(-4,6,3,CONCRETE)
Block(-4,6,4,CONCRETE)
Block(-4,6,7,CONCRETE:7)
Block(-4,6,8,CONCRETE:7)
Block(-4,6,9,CONCRETE:7)
Block(-4,7,-7,DAYLIGHT_DETECTOR:8,NetherZoxShip/5-daylight_detector.nbt)
Block(-4,7,-2,STAINED_GLASS:15)
Block(-4,7,3,STAINED_GLASS:15)
Block(-4,7,8,DAYLIGHT_DETECTOR:8,NetherZoxShip/6-daylight_detector.nbt)
Block(-4,8,-2,CONCRETE:7)
Block(-4,8,3,CONCRETE:7)
Block(-4,9,-1,CONCRETE:7)
Block(-4,9,0,STAINED_GLASS:15)
Block(-4,9,1,STAINED_GLASS:15)
Block(-4,9,2,CONCRETE:7)
Block(-3,2,-9,CONCRETE:7)
Block(-3,2,-8,CONCRETE:7)
Block(-3,2,-7,CONCRETE:7)
Block(-3,2,-6,CONCRETE:7)
Block(-3,2,-5,CONCRETE:7)
Block(-3,2,-4,IRON_TRAPDOOR:8)
Block(-3,2,-3,STEP:8)
Block(-3,2,4,STEP:8)
Block(-3,2,5,IRON_TRAPDOOR:9)
Block(-3,2,6,CONCRETE:7)
Block(-3,2,7,CONCRETE:7)
Block(-3,2,8,CONCRETE:7)
Block(-3,2,9,CONCRETE:7)
Block(-3,2,10,CONCRETE:7)
Block(-3,3,-10,LEVER)
Block(-3,3,-9,CONCRETE:7)
Block(-3,3,-8,MAGMA)
Block(-3,3,-7,MAGMA)
Block(-3,3,-6,MAGMA)
Block(-3,3,-5,CONCRETE:7)
Block(-3,3,-4,SEA_LANTERN)
Block(-3,3,-3,STEP)
Block(-3,3,4,STEP)
Block(-3,3,5,SEA_LANTERN)
Block(-3,3,6,CONCRETE:7)
Block(-3,3,7,MAGMA)
Block(-3,3,8,MAGMA)
Block(-3,3,9,MAGMA)
Block(-3,3,10,CONCRETE:7)
Block(-3,3,11,LEVER:3)
Block(-3,4,-10,IRON_FENCE)
Block(-3,4,-9,CONCRETE:7)
Block(-3,4,-8,MAGMA)
Block(-3,4,-7,MAGMA)
Block(-3,4,-6,MAGMA)
Block(-3,4,-5,CONCRETE:7)
Block(-3,4,-4,SEA_LANTERN)
Block(-3,4,-3,STEP:8)
Block(-3,4,-2,STEP:8)
Block(-3,4,3,STEP:8)
Block(-3,4,4,STEP:8)
Block(-3,4,5,SEA_LANTERN)
Block(-3,4,6,CONCRETE:7)
Block(-3,4,7,MAGMA)
Block(-3,4,8,MAGMA)
Block(-3,4,9,MAGMA)
Block(-3,4,10,CONCRETE:7)
Block(-3,4,11,IRON_FENCE)
Block(-3,5,-10,LEVER:12)
Block(-3,5,-9,CONCRETE:7)
Block(-3,5,-8,MAGMA)
Block(-3,5,-7,MAGMA)
Block(-3,5,-6,MAGMA)
Block(-3,5,-5,CONCRETE:7)
Block(-3,5,-4,IRON_TRAPDOOR:2)
Block(-3,5,-3,CONCRETE)
Block(-3,5,-2,CONCRETE:7)
Block(-3,5,-1,STEP:8)
Block(-3,5,0,STEP:8)
Block(-3,5,1,STEP:8)
Block(-3,5,2,STEP:8)
Block(-3,5,3,CONCRETE:7)
Block(-3,5,4,CONCRETE)
Block(-3,5,5,IRON_TRAPDOOR:2)
Block(-3,5,6,CONCRETE:7)
Block(-3,5,7,MAGMA)
Block(-3,5,8,MAGMA)
Block(-3,5,9,MAGMA)
Block(-3,5,10,CONCRETE:7)
Block(-3,5,11,LEVER:11)
Block(-3,6,-9,CONCRETE:7)
Block(-3,6,-8,CONCRETE:7)
Block(-3,6,-7,CONCRETE:7)
Block(-3,6,-6,CONCRETE:7)
Block(-3,6,-5,CONCRETE:7)
Block(-3,6,-3,CONCRETE)
Block(-3,6,-2,CONCRETE)
Block(-3,6,3,CONCRETE)
Block(-3,6,4,CONCRETE)
Block(-3,6,6,CONCRETE:7)
Block(-3,6,7,CONCRETE:7)
Block(-3,6,8,CONCRETE:7)
Block(-3,6,9,CONCRETE:7)
Block(-3,6,10,CONCRETE:7)
Block(-3,7,-7,DAYLIGHT_DETECTOR_INVERTED,NetherZoxShip/7-daylight_detector.nbt)
Block(-3,7,-3,CONCRETE:7)
Block(-3,7,3,DIODE_BLOCK_OFF:6)
Block(-3,7,4,CONCRETE:7)
Block(-3,7,8,DAYLIGHT_DETECTOR_INVERTED,NetherZoxShip/8-daylight_detector.nbt)
Block(-3,8,-2,CONCRETE:7)
Block(-3,8,3,CONCRETE:7)
Block(-3,9,-1,STAINED_GLASS:15)
Block(-3,9,0,STAINED_GLASS:15)
Block(-3,9,1,STAINED_GLASS:15)
Block(-3,9,2,STAINED_GLASS:15)
Block(-2,0,-5,IRON_TRAPDOOR:10)
Block(-2,0,6,IRON_TRAPDOOR:10)
Block(-2,1,-5,IRON_FENCE)
Block(-2,1,6,IRON_FENCE)
Block(-2,2,-8,CONCRETE:7)
Block(-2,2,-7,CONCRETE:7)
Block(-2,2,-6,CONCRETE:7)
Block(-2,2,-5,SMOOTH_STAIRS:4)
Block(-2,2,-4,IRON_TRAPDOOR:8)
Block(-2,2,5,IRON_TRAPDOOR:9)
Block(-2,2,6,SMOOTH_STAIRS:4)
Block(-2,2,7,CONCRETE:7)
Block(-2,2,8,CONCRETE:7)
Block(-2,2,9,CONCRETE:7)
Block(-2,3,-9,CONCRETE:7)
Block(-2,3,-5,CONCRETE:7)
Block(-2,3,-4,SEA_LANTERN)
Block(-2,3,-3,STEP)
Block(-2,3,4,STEP)
Block(-2,3,5,SEA_LANTERN)
Block(-2,3,6,CONCRETE:7)
Block(-2,3,10,CONCRETE:7)
Block(-2,4,-9,CONCRETE:7)
Block(-2,4,-5,CONCRETE:7)
Block(-2,4,-4,SEA_LANTERN)
Block(-2,4,-3,STEP:8)
Block(-2,4,4,STEP:8)
Block(-2,4,5,SEA_LANTERN)
Block(-2,4,6,CONCRETE:7)
Block(-2,4,10,CONCRETE:7)
Block(-2,5,-9,CONCRETE:7)
Block(-2,5,-5,CONCRETE:7)
Block(-2,5,-4,IRON_TRAPDOOR:2)
Block(-2,5,-3,DOUBLE_STEP)
Block(-2,5,-2,STEP)
Block(-2,5,-1,STEP:8)
Block(-2,5,0,STEP:8)
Block(-2,5,1,STEP:8)
Block(-2,5,2,STEP:8)
Block(-2,5,3,STEP)
Block(-2,5,4,DOUBLE_STEP)
Block(-2,5,5,IRON_TRAPDOOR:2)
Block(-2,5,6,CONCRETE:7)
Block(-2,5,10,CONCRETE:7)
Block(-2,6,-8,CONCRETE:7)
Block(-2,6,-7,CONCRETE:7)
Block(-2,6,-6,CONCRETE:7)
Block(-2,6,-4,LEVER)
Block(-2,6,-3,CONCRETE:7)
Block(-2,6,-2,CONCRETE)
Block(-2,6,-1,QUARTZ_STAIRS:2)
Block(-2,6,2,QUARTZ_STAIRS:0)
Block(-2,6,3,CONCRETE)
Block(-2,6,4,CONCRETE:7)
Block(-2,6,5,LEVER:3)
Block(-2,6,7,CONCRETE:7)
Block(-2,6,8,CONCRETE:7)
Block(-2,6,9,CONCRETE:7)
Block(-2,7,-7,DAYLIGHT_DETECTOR:8,NetherZoxShip/9-daylight_detector.nbt)
Block(-2,7,-6,IRON_PLATE)
Block(-2,7,-4,LEVER:12)
Block(-2,7,-3,CONCRETE:7)
Block(-2,7,3,LEVER)
Block(-2,7,4,CONCRETE:7)
Block(-2,7,5,LEVER:11)
Block(-2,7,7,IRON_PLATE)
Block(-2,7,8,DAYLIGHT_DETECTOR:8,NetherZoxShip/10-daylight_detector.nbt)
Block(-2,8,-2,STAINED_GLASS:15)
Block(-2,8,3,STAINED_GLASS:15)
Block(-2,9,-1,STAINED_GLASS:15)
Block(-2,9,0,STAINED_GLASS:15)
Block(-2,9,1,STAINED_GLASS:15)
Block(-2,9,2,STAINED_GLASS:15)
Block(-1,0,-6,STEP:5)
Block(-1,0,-5,SMOOTH_STAIRS:4)
Block(-1,0,-4,STEP:5)
Block(-1,0,5,STEP:5)
Block(-1,0,6,SMOOTH_STAIRS:4)
Block(-1,0,7,STEP:5)
Block(-1,1,-5,COBBLE_WALL)
Block(-1,1,6,COBBLE_WALL)
Block(-1,2,-8,STONE:6)
Block(-1,2,-7,STONE:6)
Block(-1,2,-6,STONE:6)
Block(-1,2,-5,SMOOTH_STAIRS:1)
Block(-1,2,6,SMOOTH_STAIRS:1)
Block(-1,2,7,STONE:6)
Block(-1,2,8,STONE:6)
Block(-1,2,9,STONE:6)
Block(-1,3,-9,STONE:6)
Block(-1,3,-5,STONE:6)
Block(-1,3,-4,SMOOTH_STAIRS:5)
Block(-1,3,-3,DOUBLE_STEP)
Block(-1,3,4,DOUBLE_STEP)
Block(-1,3,5,SMOOTH_STAIRS:5)
Block(-1,3,6,STONE:6)
Block(-1,3,10,STONE:6)
Block(-1,4,-9,STONE:6)
Block(-1,4,-5,STONE:6)
Block(-1,4,-4,SEA_LANTERN)
Block(-1,4,-3,STEP:8)
Block(-1,4,4,STEP:8)
Block(-1,4,5,SEA_LANTERN)
Block(-1,4,6,STONE:6)
Block(-1,4,10,STONE:6)
Block(-1,5,-9,STONE:6)
Block(-1,5,-5,STONE:6)
Block(-1,5,-4,CONCRETE)
Block(-1,5,-3,DOUBLE_STEP)
Block(-1,5,-2,STEP)
Block(-1,5,-1,STEP:8)
Block(-1,5,0,STEP:8)
Block(-1,5,1,STEP:8)
Block(-1,5,2,STEP:8)
Block(-1,5,3,STEP)
Block(-1,5,4,DOUBLE_STEP)
Block(-1,5,5,CONCRETE)
Block(-1,5,6,STONE:6)
Block(-1,5,10,STONE:6)
Block(-1,6,-8,STONE:6)
Block(-1,6,-7,STONE:6)
Block(-1,6,-6,STONE:6)
Block(-1,6,-4,CONCRETE:7)
Block(-1,6,-3,CONCRETE:7)
Block(-1,6,-2,CONCRETE)
Block(-1,6,2,CHEST,NetherZoxShip/11-chest.nbt)
Block(-1,6,3,CONCRETE)
Block(-1,6,4,CONCRETE:7)
Block(-1,6,5,CONCRETE:7)
Block(-1,6,7,STONE:6)
Block(-1,6,8,STONE:6)
Block(-1,6,9,STONE:6)
Block(-1,7,-3,STAINED_GLASS:15)
Block(-1,7,-2,WOOD_BUTTON:5)
Block(-1,7,3,WOOD_BUTTON:5)
Block(-1,7,4,STAINED_GLASS:15)
Block(-1,8,-2,STAINED_GLASS:15)
Block(-1,8,3,STAINED_GLASS:15)
Block(-1,9,-1,STAINED_GLASS:15)
Block(-1,9,0,STAINED_GLASS:15)
Block(-1,9,1,STAINED_GLASS:15)
Block(-1,9,2,STAINED_GLASS:15)
Block(0,0,-6,SMOOTH_STAIRS:2)
Block(0,0,-5,STONE:6)
Block(0,0,-4,SMOOTH_STAIRS:0)
Block(0,0,5,SMOOTH_STAIRS:2)
Block(0,0,6,STONE:6)
Block(0,0,7,SMOOTH_STAIRS:0)
Block(0,1,-5,COBBLE_WALL)
Block(0,1,6,COBBLE_WALL)
Block(0,2,-8,STONE_BUTTON:0)
Block(0,2,-7,STONE_BUTTON:0)
Block(0,2,-6,STONE_BUTTON:0)
Block(0,2,-5,IRON_FENCE)
Block(0,2,6,IRON_FENCE)
Block(0,2,7,STONE_BUTTON:0)
Block(0,2,8,STONE_BUTTON:0)
Block(0,2,9,STONE_BUTTON:0)
Block(0,3,-9,STONE_BUTTON:0)
Block(0,3,-8,CLAY)
Block(0,3,-7,CLAY)
Block(0,3,-6,CLAY)
Block(0,3,-5,STONE_BUTTON:0)
Block(0,3,-4,IRON_TRAPDOOR:11)
Block(0,3,-3,STEP:8)
Block(0,3,4,STEP:8)
Block(0,3,5,IRON_TRAPDOOR:11)
Block(0,3,6,STONE_BUTTON:0)
Block(0,3,7,CLAY)
Block(0,3,8,CLAY)
Block(0,3,9,CLAY)
Block(0,3,10,STONE_BUTTON:0)
Block(0,4,-10,STONE_BUTTON)
Block(0,4,-9,CLAY)
Block(0,4,-8,MAGMA)
Block(0,4,-7,MAGMA)
Block(0,4,-6,MAGMA)
Block(0,4,-5,CLAY)
Block(0,4,-4,SEA_LANTERN)
Block(0,4,-3,STEP:8)
Block(0,4,4,STEP:8)
Block(0,4,5,SEA_LANTERN)
Block(0,4,6,CLAY)
Block(0,4,7,MAGMA)
Block(0,4,8,MAGMA)
Block(0,4,9,MAGMA)
Block(0,4,10,CLAY)
Block(0,4,11,STONE_BUTTON:3)
Block(0,5,-9,STONE_BUTTON:5)
Block(0,5,-8,CLAY)
Block(0,5,-7,CLAY)
Block(0,5,-6,CLAY)
Block(0,5,-5,STONE_BUTTON:5)
Block(0,5,-4,CONCRETE)
Block(0,5,-3,STAINED_CLAY:9)
Block(0,5,-2,DOUBLE_STEP)
Block(0,5,-1,STEP:8)
Block(0,5,0,STEP:8)
Block(0,5,1,STEP:8)
Block(0,5,2,STEP:8)
Block(0,5,3,DOUBLE_STEP)
Block(0,5,4,STAINED_CLAY:9)
Block(0,5,5,CONCRETE)
Block(0,5,6,STONE_BUTTON:5)
Block(0,5,7,CLAY)
Block(0,5,8,CLAY)
Block(0,5,9,CLAY)
Block(0,5,10,STONE_BUTTON:5)
Block(0,6,-8,STONE_BUTTON:5)
Block(0,6,-7,STONE_BUTTON:5)
Block(0,6,-6,STONE_BUTTON:5)
Block(0,6,-4,CONCRETE:7)
Block(0,6,-3,CONCRETE:7)
Block(0,6,-2,CONCRETE:7)
Block(0,6,-1,QUARTZ_STAIRS:1)
Block(0,6,2,QUARTZ_STAIRS:1)
Block(0,6,3,CONCRETE:7)
Block(0,6,4,CONCRETE:7)
Block(0,6,5,CONCRETE:7)
Block(0,6,7,STONE_BUTTON:5)
Block(0,6,8,STONE_BUTTON:5)
Block(0,6,9,STONE_BUTTON:5)
Block(0,7,-3,DAYLIGHT_DETECTOR_INVERTED,NetherZoxShip/12-daylight_detector.nbt)
Block(0,7,-2,STAINED_GLASS:15)
Block(0,7,3,STAINED_GLASS:15)
Block(0,7,4,DAYLIGHT_DETECTOR_INVERTED,NetherZoxShip/13-daylight_detector.nbt)
Block(0,8,-2,STAINED_GLASS:15)
Block(0,8,3,STAINED_GLASS:15)
Block(0,9,-1,STAINED_GLASS:15)
Block(0,9,0,STAINED_GLASS:15)
Block(0,9,1,STAINED_GLASS:15)
Block(0,9,2,STAINED_GLASS:15)
Block(1,0,-6,SMOOTH_STAIRS:1)
Block(1,0,-5,STONE:6)
Block(1,0,-4,SMOOTH_STAIRS:1)
Block(1,0,5,SMOOTH_STAIRS:1)
Block(1,0,6,STONE:6)
Block(1,0,7,SMOOTH_STAIRS:1)
Block(1,2,-5,IRON_FENCE)
Block(1,2,6,IRON_FENCE)
Block(1,3,-8,STAINED_CLAY:9)
Block(1,3,-7,CLAY)
Block(1,3,-6,STAINED_CLAY:9)
Block(1,3,-5,IRON_FENCE)
Block(1,3,-3,STEP:8)
Block(1,3,4,STEP:8)
Block(1,3,6,IRON_FENCE)
Block(1,3,7,STAINED_CLAY:9)
Block(1,3,8,CLAY)
Block(1,3,9,STAINED_CLAY:9)
Block(1,4,-9,STAINED_CLAY:9)
Block(1,4,-8,SEA_LANTERN)
Block(1,4,-7,END_ROD:5)
Block(1,4,-6,SEA_LANTERN)
Block(1,4,-5,STAINED_CLAY:9)
Block(1,4,-4,STAINED_CLAY:9)
Block(1,4,-3,DOUBLE_STEP)
Block(1,4,-2,DOUBLE_STEP)
Block(1,4,3,DOUBLE_STEP)
Block(1,4,4,DOUBLE_STEP)
Block(1,4,5,STAINED_CLAY:9)
Block(1,4,6,STAINED_CLAY:9)
Block(1,4,7,SEA_LANTERN)
Block(1,4,8,END_ROD:5)
Block(1,4,9,SEA_LANTERN)
Block(1,4,10,STAINED_CLAY:9)
Block(1,5,-8,STAINED_CLAY:9)
Block(1,5,-7,CLAY)
Block(1,5,-6,STAINED_CLAY:9)
Block(1,5,-4,STAINED_CLAY:9)
Block(1,5,-3,STAINED_CLAY:9)
Block(1,5,-2,DOUBLE_STEP)
Block(1,5,-1,DOUBLE_STEP)
Block(1,5,0,STEP:8)
Block(1,5,1,STEP:8)
Block(1,5,2,DOUBLE_STEP)
Block(1,5,3,DOUBLE_STEP)
Block(1,5,4,STAINED_CLAY:9)
Block(1,5,5,STAINED_CLAY:9)
Block(1,5,7,STAINED_CLAY:9)
Block(1,5,8,CLAY)
Block(1,5,9,STAINED_CLAY:9)
Block(1,6,-4,STEP)
Block(1,6,-3,CONCRETE:7)
Block(1,6,-2,CONCRETE:7)
Block(1,6,-1,SMOOTH_STAIRS:4)
Block(1,6,0,SMOOTH_STAIRS:4)
Block(1,6,1,SMOOTH_STAIRS:4)
Block(1,6,2,SMOOTH_STAIRS:4)
Block(1,6,3,CONCRETE:7)
Block(1,6,4,CONCRETE:7)
Block(1,6,5,STEP)
Block(1,7,-2,STAINED_GLASS:15)
Block(1,7,-1,LEVER:14)
Block(1,7,0,DAYLIGHT_DETECTOR_INVERTED,NetherZoxShip/14-daylight_detector.nbt)
Block(1,7,1,REDSTONE_COMPARATOR_OFF:5,NetherZoxShip/15-comparator.nbt)
Block(1,7,2,LEVER:14)
Block(1,7,3,STAINED_GLASS:15)
Block(1,8,-2,STAINED_GLASS:15)
Block(1,8,-1,STAINED_GLASS:15)
Block(1,8,2,STAINED_GLASS:15)
Block(1,8,3,STAINED_GLASS:15)
Block(1,9,0,STAINED_GLASS:15)
Block(1,9,1,STAINED_GLASS:15)
Block(2,0,-6,STEP:5)
Block(2,0,-5,STEP:5)
Block(2,0,-4,STEP:5)
Block(2,0,5,STEP:5)
Block(2,0,6,STEP:5)
Block(2,0,7,STEP:5)
Block(2,3,-8,STAINED_CLAY:9)
Block(2,3,-7,CLAY)
Block(2,3,-6,STAINED_CLAY:9)
Block(2,3,7,STAINED_CLAY:9)
Block(2,3,8,CLAY)
Block(2,3,9,STAINED_CLAY:9)
Block(2,4,-9,STAINED_CLAY:9)
Block(2,4,-8,SEA_LANTERN)
Block(2,4,-7,END_ROD:5)
Block(2,4,-6,SEA_LANTERN)
Block(2,4,-5,STAINED_CLAY:9)
Block(2,4,-4,STAINED_CLAY:9)
Block(2,4,-3,STAINED_CLAY:9)
Block(2,4,4,STAINED_CLAY:9)
Block(2,4,5,STAINED_CLAY:9)
Block(2,4,6,STAINED_CLAY:9)
Block(2,4,7,SEA_LANTERN)
Block(2,4,8,END_ROD:5)
Block(2,4,9,SEA_LANTERN)
Block(2,4,10,STAINED_CLAY:9)
Block(2,5,-8,STAINED_CLAY:9)
Block(2,5,-7,CLAY)
Block(2,5,-6,STAINED_CLAY:9)
Block(2,5,-3,STAINED_CLAY:9)
Block(2,5,-2,STAINED_CLAY:9)
Block(2,5,3,STAINED_CLAY:9)
Block(2,5,4,STAINED_CLAY:9)
Block(2,5,7,STAINED_CLAY:9)
Block(2,5,8,CLAY)
Block(2,5,9,STAINED_CLAY:9)
Block(2,6,-3,STEP)
Block(2,6,-2,STAINED_CLAY:9)
Block(2,6,-1,STAINED_CLAY:9)
Block(2,6,0,STAINED_CLAY:9)
Block(2,6,1,STAINED_CLAY:9)
Block(2,6,2,STAINED_CLAY:9)
Block(2,6,3,STAINED_CLAY:9)
Block(2,6,4,STEP)
Block(2,7,-2,STAINED_GLASS:15)
Block(2,7,-1,STAINED_GLASS:15)
Block(2,7,0,STAINED_GLASS:15)
Block(2,7,1,STAINED_GLASS:15)
Block(2,7,2,STAINED_GLASS:15)
Block(2,7,3,STAINED_GLASS:15)
Block(2,8,-1,STAINED_GLASS:15)
Block(2,8,0,STAINED_GLASS:15)
Block(2,8,1,STAINED_GLASS:15)
Block(2,8,2,STAINED_GLASS:15)
Block(3,0,-5,STEP:5)
Block(3,0,6,STEP:5)
Block(3,2,-4,SMOOTH_STAIRS:7)
Block(3,2,5,SMOOTH_STAIRS:6)
Block(3,3,-8,STAINED_CLAY:9)
Block(3,3,-7,CLAY)
Block(3,3,-6,STAINED_CLAY:9)
Block(3,3,-5,SMOOTH_STAIRS:6)
Block(3,3,-4,MONSTER_EGGS:2)
Block(3,3,5,MONSTER_EGGS:2)
Block(3,3,6,SMOOTH_STAIRS:7)
Block(3,3,7,STAINED_CLAY:9)
Block(3,3,8,CLAY)
Block(3,3,9,STAINED_CLAY:9)
Block(3,4,-9,STAINED_CLAY:9)
Block(3,4,-8,SEA_LANTERN)
Block(3,4,-7,END_ROD:5)
Block(3,4,-6,SEA_LANTERN)
Block(3,4,-5,STAINED_CLAY:9)
Block(3,4,-4,SMOOTH_STAIRS:1)
Block(3,4,-3,LEVER:1)
Block(3,4,5,SMOOTH_STAIRS:1)
Block(3,4,6,STAINED_CLAY:9)
Block(3,4,7,SEA_LANTERN)
Block(3,4,8,END_ROD:5)
Block(3,4,9,SEA_LANTERN)
Block(3,4,10,STAINED_CLAY:9)
Block(3,5,-8,STAINED_CLAY:9)
Block(3,5,-7,CLAY)
Block(3,5,-6,STAINED_CLAY:9)
Block(3,5,-3,LEVER:9)
Block(3,5,7,STAINED_CLAY:9)
Block(3,5,8,CLAY)
Block(3,5,9,STAINED_CLAY:9)
Block(3,6,-2,STEP:8)
Block(3,6,-1,STEP:8)
Block(3,6,0,STEP:8)
Block(3,6,1,STEP:8)
Block(3,6,2,STEP:8)
Block(3,6,3,STEP:8)
Block(4,2,-8,STONE_BUTTON:0)
Block(4,2,-7,STONE_BUTTON:0)
Block(4,2,-6,STONE_BUTTON:0)
Block(4,2,7,STONE_BUTTON:0)
Block(4,2,8,STONE_BUTTON:0)
Block(4,2,9,STONE_BUTTON:0)
Block(4,3,-9,STONE_BUTTON)
Block(4,3,-8,STAINED_CLAY:9)
Block(4,3,-7,CLAY)
Block(4,3,-6,STAINED_CLAY:9)
Block(4,3,-5,STONE_BUTTON:3)
Block(4,3,6,STONE_BUTTON)
Block(4,3,7,STAINED_CLAY:9)
Block(4,3,8,CLAY)
Block(4,3,9,STAINED_CLAY:9)
Block(4,3,10,STONE_BUTTON:3)
Block(4,4,-10,STONE_BUTTON)
Block(4,4,-9,STAINED_CLAY:9)
Block(4,4,-8,SEA_LANTERN)
Block(4,4,-7,END_ROD:5)
Block(4,4,-6,SEA_LANTERN)
Block(4,4,-5,STAINED_CLAY:9)
Block(4,4,-4,STONE_BUTTON:3)
Block(4,4,5,STONE_BUTTON)
Block(4,4,6,STAINED_CLAY:9)
Block(4,4,7,SEA_LANTERN)
Block(4,4,8,END_ROD:5)
Block(4,4,9,SEA_LANTERN)
Block(4,4,10,STAINED_CLAY:9)
Block(4,4,11,STONE_BUTTON:3)
Block(4,5,-9,STONE_BUTTON:5)
Block(4,5,-8,STAINED_CLAY:9)
Block(4,5,-7,CLAY)
Block(4,5,-6,STAINED_CLAY:9)
Block(4,5,-5,STONE_BUTTON:5)
Block(4,5,6,STONE_BUTTON:5)
Block(4,5,7,STAINED_CLAY:9)
Block(4,5,8,CLAY)
Block(4,5,9,STAINED_CLAY:9)
Block(4,5,10,STONE_BUTTON:5)
Block(4,6,-8,STONE_BUTTON:5)
Block(4,6,-7,STONE_BUTTON:5)
Block(4,6,-6,STONE_BUTTON:5)
Block(4,6,7,STONE_BUTTON:5)
Block(4,6,8,STONE_BUTTON:5)
Block(4,6,9,STONE_BUTTON:5)
Block(5,3,-8,STAINED_CLAY:9)
Block(5,3,-7,CLAY)
Block(5,3,-6,STAINED_CLAY:9)
Block(5,3,7,STAINED_CLAY:9)
Block(5,3,8,CLAY)
Block(5,3,9,STAINED_CLAY:9)
Block(5,4,-9,STAINED_CLAY:9)
Block(5,4,-8,SEA_LANTERN)
Block(5,4,-7,END_ROD:5)
Block(5,4,-6,SEA_LANTERN)
Block(5,4,-5,STAINED_CLAY:9)
Block(5,4,6,STAINED_CLAY:9)
Block(5,4,7,SEA_LANTERN)
Block(5,4,8,END_ROD:5)
Block(5,4,9,SEA_LANTERN)
Block(5,4,10,STAINED_CLAY:9)
Block(5,5,-8,STAINED_CLAY:9)
Block(5,5,-7,CLAY)
Block(5,5,-6,STAINED_CLAY:9)
Block(5,5,7,STAINED_CLAY:9)
Block(5,5,8,CLAY)
Block(5,5,9,STAINED_CLAY:9)
Block(6,3,-8,STAINED_CLAY:9)
Block(6,3,-7,CLAY)
Block(6,3,-6,STAINED_CLAY:9)
Block(6,3,7,STAINED_CLAY:9)
Block(6,3,8,CLAY)
Block(6,3,9,STAINED_CLAY:9)
Block(6,4,-9,STAINED_CLAY:9)
Block(6,4,-8,SEA_LANTERN)
Block(6,4,-7,END_ROD:5)
Block(6,4,-6,SEA_LANTERN)
Block(6,4,-5,STAINED_CLAY:9)
Block(6,4,6,STAINED_CLAY:9)
Block(6,4,7,SEA_LANTERN)
Block(6,4,8,END_ROD:5)
Block(6,4,9,SEA_LANTERN)
Block(6,4,10,STAINED_CLAY:9)
Block(6,5,-8,STAINED_CLAY:9)
Block(6,5,-7,CLAY)
Block(6,5,-6,STAINED_CLAY:9)
Block(6,5,-5,DAYLIGHT_DETECTOR_INVERTED,NetherZoxShip/16-daylight_detector.nbt)
Block(6,5,6,DAYLIGHT_DETECTOR_INVERTED,NetherZoxShip/17-daylight_detector.nbt)
Block(6,5,7,STAINED_CLAY:9)
Block(6,5,8,CLAY)
Block(6,5,9,STAINED_CLAY:9)
Block(7,3,-8,STAINED_CLAY:9)
Block(7,3,-7,CLAY)
Block(7,3,-6,STAINED_CLAY:9)
Block(7,3,7,STAINED_CLAY:9)
Block(7,3,8,CLAY)
Block(7,3,9,STAINED_CLAY:9)
Block(7,4,-9,STAINED_CLAY:9)
Block(7,4,-7,END_ROD:5)
Block(7,4,-5,STAINED_CLAY:9)
Block(7,4,6,STAINED_CLAY:9)
Block(7,4,8,END_ROD:5)
Block(7,4,10,STAINED_CLAY:9)
Block(7,5,-8,STAINED_CLAY:9)
Block(7,5,-7,CLAY)
Block(7,5,-6,STAINED_CLAY:9)
Block(7,5,-5,DAYLIGHT_DETECTOR:8,NetherZoxShip/18-daylight_detector.nbt)
Block(7,5,6,DAYLIGHT_DETECTOR:8,NetherZoxShip/19-daylight_detector.nbt)
Block(7,5,7,STAINED_CLAY:9)
Block(7,5,8,CLAY)
Block(7,5,9,STAINED_CLAY:9)
Block(8,3,-8,STAINED_CLAY:9)
Block(8,3,-7,CLAY)
Block(8,3,-6,STAINED_CLAY:9)
Block(8,3,7,STAINED_CLAY:9)
Block(8,3,8,CLAY)
Block(8,3,9,STAINED_CLAY:9)
Block(8,4,-9,STAINED_CLAY:9)
Block(8,4,-8,CLAY)
Block(8,4,-7,END_ROD:5)
Block(8,4,-6,CLAY)
Block(8,4,-5,STAINED_CLAY:9)
Block(8,4,6,STAINED_CLAY:9)
Block(8,4,7,CLAY)
Block(8,4,8,END_ROD:5)
Block(8,4,9,CLAY)
Block(8,4,10,STAINED_CLAY:9)
Block(8,5,-8,STAINED_CLAY:9)
Block(8,5,-7,CLAY)
Block(8,5,-6,STAINED_CLAY:9)
Block(8,5,7,STAINED_CLAY:9)
Block(8,5,8,CLAY)
Block(8,5,9,STAINED_CLAY:9)
Block(9,3,-8,STEP:13)
Block(9,3,-7,STEP:5)
Block(9,3,-6,STEP:13)
Block(9,3,7,STEP:13)
Block(9,3,8,STEP:5)
Block(9,3,9,STEP:13)
Block(9,4,-9,STONE_BUTTON:1)
Block(9,4,-8,SMOOTH_STAIRS:7)
Block(9,4,-7,END_ROD:5)
Block(9,4,-6,SMOOTH_STAIRS:6)
Block(9,4,-5,STONE_BUTTON:1)
Block(9,4,6,STONE_BUTTON:1)
Block(9,4,7,SMOOTH_STAIRS:7)
Block(9,4,8,END_ROD:5)
Block(9,4,9,SMOOTH_STAIRS:6)
Block(9,4,10,STONE_BUTTON:1)
Block(9,5,-8,STONE_BUTTON:1)
Block(9,5,-7,STEP:5)
Block(9,5,-6,STONE_BUTTON:1)
Block(9,5,7,STONE_BUTTON:1)
Block(9,5,8,STEP:5)
Block(9,5,9,STONE_BUTTON:1)
Block(10,3,-8,STEP:13)
Block(10,3,-7,STEP:5)
Block(10,3,-6,STEP:13)
Block(10,3,7,STEP:13)
Block(10,3,8,STEP:5)
Block(10,3,9,STEP:13)
Block(10,4,-8,SMOOTH_STAIRS:7)
Block(10,4,-7,END_ROD:5)
Block(10,4,-6,SMOOTH_STAIRS:6)
Block(10,4,7,SMOOTH_STAIRS:7)
Block(10,4,8,END_ROD:5)
Block(10,4,9,SMOOTH_STAIRS:6)
Block(10,5,-7,STEP:5)
Block(10,5,8,STEP:5)
Block(11,3,-8,STEP:13)
Block(11,3,-7,STEP:5)
Block(11,3,-6,STEP:13)
Block(11,3,7,STEP:13)
Block(11,3,8,STEP:5)
Block(11,3,9,STEP:13)
Block(11,4,-8,SMOOTH_STAIRS:7)
Block(11,4,-7,END_ROD:5)
Block(11,4,-6,SMOOTH_STAIRS:6)
Block(11,4,7,SMOOTH_STAIRS:7)
Block(11,4,8,END_ROD:5)
Block(11,4,9,SMOOTH_STAIRS:6)
Block(11,5,-7,STEP:5)
Block(11,5,8,STEP:5)

#######################################################################
# +-----------------------------------------------------------------+ #
# |                            BO3 checks                           | #
# +-----------------------------------------------------------------+ #
#######################################################################

BlockCheck(0,-1,0,STAINED_CLAY,NETHERRACK)
BlockCheck(0,-1,-5,STAINED_CLAY,NETHERRACK)
BlockCheck(0,-1,5,STAINED_CLAY,NETHERRACK)

#######################################################################
# +-----------------------------------------------------------------+ #
# |                             Branches                            | #
# +-----------------------------------------------------------------+ #
#######################################################################


#######################################################################
# +-----------------------------------------------------------------+ #
# |                             Entities                            | #
# +-----------------------------------------------------------------+ #
#######################################################################


#######################################################################
# +-----------------------------------------------------------------+ #
# |                            Particles                            | #
# +-----------------------------------------------------------------+ #
#######################################################################


#######################################################################
# +-----------------------------------------------------------------+ #
# |                             Spawners                            | #
# +-----------------------------------------------------------------+ #
#######################################################################


#######################################################################
# +-----------------------------------------------------------------+ #
# |                             ModData                             | #
# +-----------------------------------------------------------------+ #
#######################################################################

