
#######################################################################
# +-----------------------------------------------------------------+ #
# |                            BO3 object                           | #
# +-----------------------------------------------------------------+ #
#######################################################################

Author: kumquatmay

Description: No description given

Version: 3

SettingsMode: WriteWithoutComments


#######################################################################
# +-----------------------------------------------------------------+ #
# |                          Main settings                          | #
# +-----------------------------------------------------------------+ #
#######################################################################

Tree: false

Frequency: 0

Rarity: 100.0

RotateRandomly: true

SpawnHeight: highestBlock

SpawnHeightOffset: 0

SpawnHeightVariance: 0

##############################
# Height Limits for the BO3. #
##############################

MinHeight: 0

MaxHeight: 256

######################
# Extrusion settings #
######################

ExtrudeMode: None

ExtrudeThroughBlocks: AIR

MaxBranchDepth: 10

ExcludedBiomes: All


#######################################################################
# +-----------------------------------------------------------------+ #
# |                      Source block settings                      | #
# +-----------------------------------------------------------------+ #
#######################################################################

SourceBlocks: AIR

MaxPercentageOutsideSourceBlock: 40

OutsideSourceBlock: placeAnyway

IsOTGPlus: false


#######################################################################
# +-----------------------------------------------------------------+ #
# |                              Blocks                             | #
# +-----------------------------------------------------------------+ #
#######################################################################

Block(-12,0,7,COAL_BLOCK)
Block(-11,0,-12,COAL_BLOCK)
Block(-11,0,6,COAL_BLOCK)
Block(-11,0,7,COAL_BLOCK)
Block(-10,0,-12,COAL_BLOCK)
Block(-10,0,-11,COAL_BLOCK)
Block(-10,0,5,COAL_BLOCK)
Block(-10,0,6,COAL_BLOCK)
Block(-10,1,5,COAL_BLOCK)
Block(-10,16,1,GLOWSTONE)
Block(-10,17,0,GLOWSTONE)
Block(-10,17,1,GLOWSTONE)
Block(-10,17,2,GLOWSTONE)
Block(-10,18,1,GLOWSTONE)
Block(-10,19,-2,GLOWSTONE)
Block(-10,19,0,GLOWSTONE)
Block(-10,20,-3,GLOWSTONE)
Block(-10,20,-2,GLOWSTONE)
Block(-10,20,-1,GLOWSTONE)
Block(-10,20,0,GLOWSTONE)
Block(-10,20,1,GLOWSTONE)
Block(-10,21,-2,GLOWSTONE)
Block(-10,21,0,GLOWSTONE)
Block(-10,22,-1,GLOWSTONE)
Block(-10,22,0,GLOWSTONE)
Block(-10,22,1,GLOWSTONE)
Block(-10,23,0,GLOWSTONE)
Block(-9,0,-11,COAL_BLOCK)
Block(-9,0,-10,COAL_BLOCK)
Block(-9,0,-9,COAL_BLOCK)
Block(-9,0,4,COAL_BLOCK)
Block(-9,0,5,COAL_BLOCK)
Block(-9,1,-10,COAL_BLOCK)
Block(-9,1,4,COAL_BLOCK)
Block(-9,1,5,COAL_BLOCK)
Block(-9,13,1,GLOWSTONE)
Block(-9,14,1,GLOWSTONE)
Block(-9,15,1,GLOWSTONE)
Block(-9,15,2,GLOWSTONE)
Block(-9,16,0,GLOWSTONE)
Block(-9,16,1,GLOWSTONE)
Block(-9,16,2,GLOWSTONE)
Block(-9,17,-2,GLOWSTONE)
Block(-9,17,0,GLOWSTONE)
Block(-9,17,1,GLOWSTONE)
Block(-9,17,2,GLOWSTONE)
Block(-9,18,-3,GLOWSTONE)
Block(-9,18,-2,GLOWSTONE)
Block(-9,18,-1,GLOWSTONE)
Block(-9,18,0,GLOWSTONE)
Block(-9,18,1,GLOWSTONE)
Block(-9,18,2,GLOWSTONE)
Block(-9,19,-4,GLOWSTONE)
Block(-9,19,-3,GLOWSTONE)
Block(-9,19,-2,GLOWSTONE)
Block(-9,19,-1,GLOWSTONE)
Block(-9,19,0,GLOWSTONE)
Block(-9,19,1,GLOWSTONE)
Block(-9,20,-4,GLOWSTONE)
Block(-9,20,-3,GLOWSTONE)
Block(-9,20,-2,GLOWSTONE)
Block(-9,20,-1,GLOWSTONE)
Block(-9,20,0,GLOWSTONE)
Block(-9,20,1,GLOWSTONE)
Block(-9,21,-3,GLOWSTONE)
Block(-9,21,-2,GLOWSTONE)
Block(-9,21,-1,GLOWSTONE)
Block(-9,21,0,GLOWSTONE)
Block(-9,21,1,GLOWSTONE)
Block(-9,21,2,GLOWSTONE)
Block(-9,22,-1,GLOWSTONE)
Block(-9,22,0,GLOWSTONE)
Block(-9,22,1,GLOWSTONE)
Block(-9,22,2,GLOWSTONE)
Block(-9,22,3,GLOWSTONE)
Block(-9,23,-1,GLOWSTONE)
Block(-9,23,0,GLOWSTONE)
Block(-9,23,1,GLOWSTONE)
Block(-9,23,2,GLOWSTONE)
Block(-9,24,0,GLOWSTONE)
Block(-8,0,-10,COAL_BLOCK)
Block(-8,0,-9,COAL_BLOCK)
Block(-8,0,-8,COAL_BLOCK)
Block(-8,0,3,COAL_BLOCK)
Block(-8,0,4,COAL_BLOCK)
Block(-8,0,5,COAL_BLOCK)
Block(-8,1,-10,COAL_BLOCK)
Block(-8,1,-9,COAL_BLOCK)
Block(-8,1,4,COAL_BLOCK)
Block(-8,13,-2,GLOWSTONE)
Block(-8,14,-2,GLOWSTONE)
Block(-8,15,-3,GLOWSTONE)
Block(-8,15,-2,GLOWSTONE)
Block(-8,16,-3,GLOWSTONE)
Block(-8,16,-2,GLOWSTONE)
Block(-8,16,1,GLOWSTONE)
Block(-8,17,-3,GLOWSTONE)
Block(-8,17,-2,GLOWSTONE)
Block(-8,17,-1,GLOWSTONE)
Block(-8,17,0,COAL_BLOCK)
Block(-8,17,1,GLOWSTONE)
Block(-8,17,2,GLOWSTONE)
Block(-8,18,-4,GLOWSTONE)
Block(-8,18,-3,GLOWSTONE)
Block(-8,18,-2,GLOWSTONE)
Block(-8,18,-1,COAL_BLOCK)
Block(-8,18,0,COAL_BLOCK)
Block(-8,18,1,COAL_BLOCK)
Block(-8,18,2,GLOWSTONE)
Block(-8,19,-4,GLOWSTONE)
Block(-8,19,-3,GLOWSTONE)
Block(-8,19,-2,GLOWSTONE)
Block(-8,19,-1,GLOWSTONE)
Block(-8,19,0,COAL_BLOCK)
Block(-8,19,1,GLOWSTONE)
Block(-8,19,2,GLOWSTONE)
Block(-8,20,-4,GLOWSTONE)
Block(-8,20,-3,GLOWSTONE)
Block(-8,20,-2,GLOWSTONE)
Block(-8,20,-1,GLOWSTONE)
Block(-8,20,0,GLOWSTONE)
Block(-8,20,1,GLOWSTONE)
Block(-8,21,-4,GLOWSTONE)
Block(-8,21,-3,GLOWSTONE)
Block(-8,21,-2,GLOWSTONE)
Block(-8,21,-1,GLOWSTONE)
Block(-8,21,0,GLOWSTONE)
Block(-8,21,1,GLOWSTONE)
Block(-8,21,2,GLOWSTONE)
Block(-8,21,3,GLOWSTONE)
Block(-8,22,-3,GLOWSTONE)
Block(-8,22,-2,GLOWSTONE)
Block(-8,22,-1,GLOWSTONE)
Block(-8,22,0,GLOWSTONE)
Block(-8,22,1,GLOWSTONE)
Block(-8,22,2,GLOWSTONE)
Block(-8,22,3,GLOWSTONE)
Block(-8,23,-1,GLOWSTONE)
Block(-8,23,0,GLOWSTONE)
Block(-8,23,1,GLOWSTONE)
Block(-8,23,2,GLOWSTONE)
Block(-8,23,3,GLOWSTONE)
Block(-8,24,-1,GLOWSTONE)
Block(-8,24,0,GLOWSTONE)
Block(-8,24,1,GLOWSTONE)
Block(-8,25,-1,GLOWSTONE)
Block(-8,25,0,GLOWSTONE)
Block(-8,25,1,GLOWSTONE)
Block(-8,26,0,GLOWSTONE)
Block(-7,0,-9,COAL_BLOCK)
Block(-7,0,-8,COAL_BLOCK)
Block(-7,0,-7,COAL_BLOCK)
Block(-7,0,-6,COAL_BLOCK)
Block(-7,0,-1,COAL_BLOCK)
Block(-7,0,0,COAL_BLOCK)
Block(-7,0,1,COAL_BLOCK)
Block(-7,0,2,MOB_SPAWNER,NetherGricelTree/1-mob_spawner.nbt)
Block(-7,0,3,COAL_BLOCK)
Block(-7,0,4,COAL_BLOCK)
Block(-7,1,-9,COAL_BLOCK)
Block(-7,1,-8,COAL_BLOCK)
Block(-7,1,-7,COAL_BLOCK)
Block(-7,1,0,COAL_BLOCK)
Block(-7,1,1,COAL_BLOCK)
Block(-7,1,2,COAL_BLOCK)
Block(-7,1,3,COAL_BLOCK)
Block(-7,2,-8,COAL_BLOCK)
Block(-7,2,0,COAL_BLOCK)
Block(-7,2,1,COAL_BLOCK)
Block(-7,2,2,COAL_BLOCK)
Block(-7,3,1,COAL_BLOCK)
Block(-7,16,-7,GLOWSTONE)
Block(-7,17,-7,GLOWSTONE)
Block(-7,17,-2,GLOWSTONE)
Block(-7,17,-1,COAL_BLOCK)
Block(-7,17,0,COAL_BLOCK)
Block(-7,17,1,COAL_BLOCK)
Block(-7,18,-7,GLOWSTONE)
Block(-7,18,-3,GLOWSTONE)
Block(-7,18,-2,COAL_BLOCK)
Block(-7,18,-1,COAL_BLOCK)
Block(-7,18,0,COAL_BLOCK)
Block(-7,18,1,COAL_BLOCK)
Block(-7,18,2,GLOWSTONE)
Block(-7,19,-8,GLOWSTONE)
Block(-7,19,-7,GLOWSTONE)
Block(-7,19,-6,GLOWSTONE)
Block(-7,19,-4,GLOWSTONE)
Block(-7,19,-3,GLOWSTONE)
Block(-7,19,-2,GLOWSTONE)
Block(-7,19,-1,COAL_BLOCK)
Block(-7,19,0,COAL_BLOCK)
Block(-7,19,1,COAL_BLOCK)
Block(-7,20,-7,GLOWSTONE)
Block(-7,20,-4,GLOWSTONE)
Block(-7,20,-3,GLOWSTONE)
Block(-7,20,-2,GLOWSTONE)
Block(-7,20,-1,GLOWSTONE)
Block(-7,20,0,GLOWSTONE)
Block(-7,20,1,GLOWSTONE)
Block(-7,20,2,GLOWSTONE)
Block(-7,21,-4,GLOWSTONE)
Block(-7,21,-3,GLOWSTONE)
Block(-7,21,-2,GLOWSTONE)
Block(-7,21,-1,GLOWSTONE)
Block(-7,21,0,GLOWSTONE)
Block(-7,21,1,GLOWSTONE)
Block(-7,21,2,GLOWSTONE)
Block(-7,22,-4,GLOWSTONE)
Block(-7,22,-3,GLOWSTONE)
Block(-7,22,-2,GLOWSTONE)
Block(-7,22,-1,GLOWSTONE)
Block(-7,22,0,GLOWSTONE)
Block(-7,22,1,GLOWSTONE)
Block(-7,22,2,GLOWSTONE)
Block(-7,22,3,GLOWSTONE)
Block(-7,23,-3,GLOWSTONE)
Block(-7,23,-1,GLOWSTONE)
Block(-7,23,0,GLOWSTONE)
Block(-7,23,1,GLOWSTONE)
Block(-7,23,2,GLOWSTONE)
Block(-7,23,3,GLOWSTONE)
Block(-7,23,4,GLOWSTONE)
Block(-7,24,-1,GLOWSTONE)
Block(-7,24,0,GLOWSTONE)
Block(-7,24,1,GLOWSTONE)
Block(-7,24,3,GLOWSTONE)
Block(-7,25,-2,GLOWSTONE)
Block(-7,25,-1,GLOWSTONE)
Block(-7,25,0,GLOWSTONE)
Block(-7,25,1,GLOWSTONE)
Block(-7,26,-1,GLOWSTONE)
Block(-7,26,0,GLOWSTONE)
Block(-7,26,1,GLOWSTONE)
Block(-6,0,-8,COAL_BLOCK)
Block(-6,0,-7,COAL_BLOCK)
Block(-6,0,-6,COAL_BLOCK)
Block(-6,0,-5,COAL_BLOCK)
Block(-6,0,-2,COAL_BLOCK)
Block(-6,0,-1,COAL_BLOCK)
Block(-6,0,0,COAL_BLOCK)
Block(-6,0,1,COAL_BLOCK)
Block(-6,0,2,COAL_BLOCK)
Block(-6,0,3,COAL_BLOCK)
Block(-6,1,-8,COAL_BLOCK)
Block(-6,1,-7,COAL_BLOCK)
Block(-6,1,-6,COAL_BLOCK)
Block(-6,1,-1,COAL_BLOCK)
Block(-6,1,0,COAL_BLOCK)
Block(-6,1,1,COAL_BLOCK)
Block(-6,1,2,COAL_BLOCK)
Block(-6,1,3,COAL_BLOCK)
Block(-6,2,-8,COAL_BLOCK)
Block(-6,2,-7,COAL_BLOCK)
Block(-6,2,0,COAL_BLOCK)
Block(-6,2,1,COAL_BLOCK)
Block(-6,2,2,COAL_BLOCK)
Block(-6,2,3,COAL_BLOCK)
Block(-6,3,0,COAL_BLOCK)
Block(-6,3,1,COAL_BLOCK)
Block(-6,3,2,COAL_BLOCK)
Block(-6,14,-7,GLOWSTONE)
Block(-6,15,-7,GLOWSTONE)
Block(-6,16,-7,GLOWSTONE)
Block(-6,16,-6,GLOWSTONE)
Block(-6,16,3,GLOWSTONE)
Block(-6,17,-7,GLOWSTONE)
Block(-6,17,-2,COAL_BLOCK)
Block(-6,17,-1,COAL_BLOCK)
Block(-6,17,0,COAL_BLOCK)
Block(-6,17,3,GLOWSTONE)
Block(-6,18,-8,GLOWSTONE)
Block(-6,18,-7,GLOWSTONE)
Block(-6,18,-6,GLOWSTONE)
Block(-6,18,-3,COAL_BLOCK)
Block(-6,18,-2,COAL_BLOCK)
Block(-6,18,-1,COAL_BLOCK)
Block(-6,18,0,COAL_BLOCK)
Block(-6,18,1,COAL_BLOCK)
Block(-6,18,3,GLOWSTONE)
Block(-6,18,4,GLOWSTONE)
Block(-6,19,-8,GLOWSTONE)
Block(-6,19,-7,GLOWSTONE)
Block(-6,19,-6,GLOWSTONE)
Block(-6,19,-2,COAL_BLOCK)
Block(-6,19,-1,COAL_BLOCK)
Block(-6,19,0,COAL_BLOCK)
Block(-6,19,3,GLOWSTONE)
Block(-6,19,4,GLOWSTONE)
Block(-6,19,5,GLOWSTONE)
Block(-6,20,-8,GLOWSTONE)
Block(-6,20,-7,GLOWSTONE)
Block(-6,20,-6,GLOWSTONE)
Block(-6,20,-5,GLOWSTONE)
Block(-6,20,-3,GLOWSTONE)
Block(-6,20,-2,GLOWSTONE)
Block(-6,20,-1,GLOWSTONE)
Block(-6,20,0,GLOWSTONE)
Block(-6,20,1,GLOWSTONE)
Block(-6,20,4,GLOWSTONE)
Block(-6,21,-6,GLOWSTONE)
Block(-6,21,-5,GLOWSTONE)
Block(-6,21,-4,GLOWSTONE)
Block(-6,21,-3,GLOWSTONE)
Block(-6,21,-2,GLOWSTONE)
Block(-6,21,-1,GLOWSTONE)
Block(-6,21,0,GLOWSTONE)
Block(-6,21,1,GLOWSTONE)
Block(-6,21,2,GLOWSTONE)
Block(-6,21,3,GLOWSTONE)
Block(-6,22,-5,GLOWSTONE)
Block(-6,22,-4,GLOWSTONE)
Block(-6,22,-3,GLOWSTONE)
Block(-6,22,-2,GLOWSTONE)
Block(-6,22,-1,GLOWSTONE)
Block(-6,22,1,GLOWSTONE)
Block(-6,22,2,GLOWSTONE)
Block(-6,22,3,GLOWSTONE)
Block(-6,22,4,GLOWSTONE)
Block(-6,23,-4,GLOWSTONE)
Block(-6,23,-3,GLOWSTONE)
Block(-6,23,-2,GLOWSTONE)
Block(-6,23,-1,GLOWSTONE)
Block(-6,23,0,GLOWSTONE)
Block(-6,23,2,GLOWSTONE)
Block(-6,23,3,GLOWSTONE)
Block(-6,23,4,GLOWSTONE)
Block(-6,23,5,GLOWSTONE)
Block(-6,24,-2,GLOWSTONE)
Block(-6,24,-1,GLOWSTONE)
Block(-6,24,0,GLOWSTONE)
Block(-6,24,1,GLOWSTONE)
Block(-6,24,2,GLOWSTONE)
Block(-6,24,3,GLOWSTONE)
Block(-6,24,4,GLOWSTONE)
Block(-6,25,-2,GLOWSTONE)
Block(-6,25,-1,GLOWSTONE)
Block(-6,25,0,GLOWSTONE)
Block(-6,25,1,GLOWSTONE)
Block(-6,26,-2,GLOWSTONE)
Block(-6,26,-1,GLOWSTONE)
Block(-6,26,0,GLOWSTONE)
Block(-5,0,-8,COAL_BLOCK)
Block(-5,0,-7,COAL_BLOCK)
Block(-5,0,-6,COAL_BLOCK)
Block(-5,0,-5,COAL_BLOCK)
Block(-5,0,-3,COAL_BLOCK)
Block(-5,0,-2,COAL_BLOCK)
Block(-5,0,-1,COAL_BLOCK)
Block(-5,0,0,COAL_BLOCK)
Block(-5,0,1,COAL_BLOCK)
Block(-5,0,2,COAL_BLOCK)
Block(-5,0,3,COAL_BLOCK)
Block(-5,1,-7,MOB_SPAWNER,NetherGricelTree/2-mob_spawner.nbt)
Block(-5,1,-6,COAL_BLOCK)
Block(-5,1,-5,COAL_BLOCK)
Block(-5,1,-4,COAL_BLOCK)
Block(-5,1,-3,COAL_BLOCK)
Block(-5,1,-2,COAL_BLOCK)
Block(-5,1,-1,COAL_BLOCK)
Block(-5,1,0,COAL_BLOCK)
Block(-5,1,1,COAL_BLOCK)
Block(-5,1,2,COAL_BLOCK)
Block(-5,1,3,COAL_BLOCK)
Block(-5,2,-7,COAL_BLOCK)
Block(-5,2,-6,COAL_BLOCK)
Block(-5,2,-5,COAL_BLOCK)
Block(-5,2,-4,COAL_BLOCK)
Block(-5,2,-3,COAL_BLOCK)
Block(-5,2,-2,COAL_BLOCK)
Block(-5,2,-1,COAL_BLOCK)
Block(-5,2,0,COAL_BLOCK)
Block(-5,2,1,COAL_BLOCK)
Block(-5,2,2,COAL_BLOCK)
Block(-5,3,-6,COAL_BLOCK)
Block(-5,3,-4,COAL_BLOCK)
Block(-5,3,-3,COAL_BLOCK)
Block(-5,3,-2,COAL_BLOCK)
Block(-5,3,1,COAL_BLOCK)
Block(-5,4,-3,COAL_BLOCK)
Block(-5,15,4,GLOWSTONE)
Block(-5,16,-6,GLOWSTONE)
Block(-5,16,-2,COAL_BLOCK)
Block(-5,16,4,GLOWSTONE)
Block(-5,17,-8,GLOWSTONE)
Block(-5,17,-7,GLOWSTONE)
Block(-5,17,-6,GLOWSTONE)
Block(-5,17,-3,COAL_BLOCK)
Block(-5,17,-2,COAL_BLOCK)
Block(-5,17,-1,COAL_BLOCK)
Block(-5,17,4,GLOWSTONE)
Block(-5,17,5,GLOWSTONE)
Block(-5,18,-8,GLOWSTONE)
Block(-5,18,-7,GLOWSTONE)
Block(-5,18,-6,GLOWSTONE)
Block(-5,18,-5,GLOWSTONE)
Block(-5,18,-3,COAL_BLOCK)
Block(-5,18,-2,COAL_BLOCK)
Block(-5,18,-1,COAL_BLOCK)
Block(-5,18,0,COAL_BLOCK)
Block(-5,18,3,GLOWSTONE)
Block(-5,18,4,GLOWSTONE)
Block(-5,18,5,GLOWSTONE)
Block(-5,19,-8,GLOWSTONE)
Block(-5,19,-7,GLOWSTONE)
Block(-5,19,-6,GLOWSTONE)
Block(-5,19,-3,COAL_BLOCK)
Block(-5,19,-2,COAL_BLOCK)
Block(-5,19,-1,COAL_BLOCK)
Block(-5,19,0,GLOWSTONE)
Block(-5,19,3,GLOWSTONE)
Block(-5,19,4,GLOWSTONE)
Block(-5,19,5,GLOWSTONE)
Block(-5,20,-9,GLOWSTONE)
Block(-5,20,-8,GLOWSTONE)
Block(-5,20,-7,GLOWSTONE)
Block(-5,20,-6,GLOWSTONE)
Block(-5,20,-5,GLOWSTONE)
Block(-5,20,-4,GLOWSTONE)
Block(-5,20,-3,GLOWSTONE)
Block(-5,20,-2,GLOWSTONE)
Block(-5,20,-1,GLOWSTONE)
Block(-5,20,0,GLOWSTONE)
Block(-5,20,3,GLOWSTONE)
Block(-5,20,4,GLOWSTONE)
Block(-5,20,5,GLOWSTONE)
Block(-5,21,-8,GLOWSTONE)
Block(-5,21,-7,GLOWSTONE)
Block(-5,21,-6,GLOWSTONE)
Block(-5,21,-5,GLOWSTONE)
Block(-5,21,-4,GLOWSTONE)
Block(-5,21,-3,GLOWSTONE)
Block(-5,21,-2,GLOWSTONE)
Block(-5,21,-1,GLOWSTONE)
Block(-5,21,2,GLOWSTONE)
Block(-5,21,3,GLOWSTONE)
Block(-5,21,4,GLOWSTONE)
Block(-5,22,-6,GLOWSTONE)
Block(-5,22,-5,GLOWSTONE)
Block(-5,22,-4,GLOWSTONE)
Block(-5,22,-3,GLOWSTONE)
Block(-5,22,-2,GLOWSTONE)
Block(-5,22,-1,GLOWSTONE)
Block(-5,22,2,GLOWSTONE)
Block(-5,22,3,GLOWSTONE)
Block(-5,22,4,GLOWSTONE)
Block(-5,22,5,GLOWSTONE)
Block(-5,23,-4,GLOWSTONE)
Block(-5,23,-3,GLOWSTONE)
Block(-5,23,-2,GLOWSTONE)
Block(-5,23,-1,GLOWSTONE)
Block(-5,23,0,GLOWSTONE)
Block(-5,23,2,GLOWSTONE)
Block(-5,23,3,GLOWSTONE)
Block(-5,23,4,GLOWSTONE)
Block(-5,23,5,GLOWSTONE)
Block(-5,23,6,GLOWSTONE)
Block(-5,24,-3,GLOWSTONE)
Block(-5,24,-2,GLOWSTONE)
Block(-5,24,-1,GLOWSTONE)
Block(-5,24,0,GLOWSTONE)
Block(-5,24,1,GLOWSTONE)
Block(-5,24,2,GLOWSTONE)
Block(-5,24,3,GLOWSTONE)
Block(-5,24,4,GLOWSTONE)
Block(-5,24,5,GLOWSTONE)
Block(-5,24,6,GLOWSTONE)
Block(-5,25,-2,GLOWSTONE)
Block(-5,25,-1,GLOWSTONE)
Block(-5,25,0,GLOWSTONE)
Block(-5,25,2,GLOWSTONE)
Block(-5,25,4,GLOWSTONE)
Block(-5,25,5,GLOWSTONE)
Block(-5,25,6,GLOWSTONE)
Block(-5,25,7,GLOWSTONE)
Block(-5,26,-1,GLOWSTONE)
Block(-5,26,6,GLOWSTONE)
Block(-4,0,-8,COAL_BLOCK)
Block(-4,0,-7,COAL_BLOCK)
Block(-4,0,-6,COAL_BLOCK)
Block(-4,0,-5,COAL_BLOCK)
Block(-4,0,-4,COAL_BLOCK)
Block(-4,0,-3,COAL_BLOCK)
Block(-4,0,-2,COAL_BLOCK)
Block(-4,0,-1,COAL_BLOCK)
Block(-4,0,0,COAL_BLOCK)
Block(-4,0,1,COAL_BLOCK)
Block(-4,0,2,COAL_BLOCK)
Block(-4,0,3,COAL_BLOCK)
Block(-4,0,4,COAL_BLOCK)
Block(-4,0,9,COAL_BLOCK)
Block(-4,0,10,COAL_BLOCK)
Block(-4,0,11,COAL_BLOCK)
Block(-4,1,-7,COAL_BLOCK)
Block(-4,1,-6,COAL_BLOCK)
Block(-4,1,-5,COAL_BLOCK)
Block(-4,1,-4,COAL_BLOCK)
Block(-4,1,-3,COAL_BLOCK)
Block(-4,1,-2,COAL_BLOCK)
Block(-4,1,-1,COAL_BLOCK)
Block(-4,1,0,COAL_BLOCK)
Block(-4,1,1,COAL_BLOCK)
Block(-4,1,2,COAL_BLOCK)
Block(-4,2,-7,COAL_BLOCK)
Block(-4,2,-6,COAL_BLOCK)
Block(-4,2,-5,COAL_BLOCK)
Block(-4,2,-4,COAL_BLOCK)
Block(-4,2,-3,COAL_BLOCK)
Block(-4,2,-2,COAL_BLOCK)
Block(-4,2,-1,COAL_BLOCK)
Block(-4,2,0,COAL_BLOCK)
Block(-4,2,1,COAL_BLOCK)
Block(-4,3,-7,COAL_BLOCK)
Block(-4,3,-6,COAL_BLOCK)
Block(-4,3,-5,COAL_BLOCK)
Block(-4,3,-4,COAL_BLOCK)
Block(-4,3,-3,COAL_BLOCK)
Block(-4,3,-2,COAL_BLOCK)
Block(-4,3,-1,COAL_BLOCK)
Block(-4,3,0,COAL_BLOCK)
Block(-4,4,-5,COAL_BLOCK)
Block(-4,4,-4,COAL_BLOCK)
Block(-4,4,-3,COAL_BLOCK)
Block(-4,4,-2,COAL_BLOCK)
Block(-4,4,-1,COAL_BLOCK)
Block(-4,5,-4,COAL_BLOCK)
Block(-4,5,-3,COAL_BLOCK)
Block(-4,5,-2,COAL_BLOCK)
Block(-4,5,-1,COAL_BLOCK)
Block(-4,6,-4,COAL_BLOCK)
Block(-4,6,-3,COAL_BLOCK)
Block(-4,6,-2,COAL_BLOCK)
Block(-4,6,-1,COAL_BLOCK)
Block(-4,6,0,COAL_BLOCK)
Block(-4,7,-3,COAL_BLOCK)
Block(-4,7,-2,COAL_BLOCK)
Block(-4,7,-1,COAL_BLOCK)
Block(-4,8,-2,COAL_BLOCK)
Block(-4,9,-2,COAL_BLOCK)
Block(-4,9,-1,COAL_BLOCK)
Block(-4,9,0,COAL_BLOCK)
Block(-4,10,-2,COAL_BLOCK)
Block(-4,10,-1,COAL_BLOCK)
Block(-4,10,0,COAL_BLOCK)
Block(-4,11,-2,COAL_BLOCK)
Block(-4,11,-1,COAL_BLOCK)
Block(-4,11,0,COAL_BLOCK)
Block(-4,15,-7,GLOWSTONE)
Block(-4,15,-6,GLOWSTONE)
Block(-4,16,-7,GLOWSTONE)
Block(-4,16,-6,GLOWSTONE)
Block(-4,16,-3,COAL_BLOCK)
Block(-4,16,-2,COAL_BLOCK)
Block(-4,16,-1,COAL_BLOCK)
Block(-4,17,-7,GLOWSTONE)
Block(-4,17,-6,GLOWSTONE)
Block(-4,17,-5,GLOWSTONE)
Block(-4,17,-4,GLOWSTONE)
Block(-4,17,-3,COAL_BLOCK)
Block(-4,17,-2,COAL_BLOCK)
Block(-4,17,-1,COAL_BLOCK)
Block(-4,17,4,GLOWSTONE)
Block(-4,18,-8,GLOWSTONE)
Block(-4,18,-7,GLOWSTONE)
Block(-4,18,-6,GLOWSTONE)
Block(-4,18,-5,GLOWSTONE)
Block(-4,18,-4,GLOWSTONE)
Block(-4,18,-3,COAL_BLOCK)
Block(-4,18,-2,COAL_BLOCK)
Block(-4,18,-1,COAL_BLOCK)
Block(-4,18,4,GLOWSTONE)
Block(-4,19,-9,GLOWSTONE)
Block(-4,19,-8,GLOWSTONE)
Block(-4,19,-7,GLOWSTONE)
Block(-4,19,-6,GLOWSTONE)
Block(-4,19,-5,GLOWSTONE)
Block(-4,19,-4,GLOWSTONE)
Block(-4,19,-2,COAL_BLOCK)
Block(-4,19,-1,GLOWSTONE)
Block(-4,19,0,GLOWSTONE)
Block(-4,19,3,GLOWSTONE)
Block(-4,19,4,GLOWSTONE)
Block(-4,19,5,GLOWSTONE)
Block(-4,20,-9,GLOWSTONE)
Block(-4,20,-8,GLOWSTONE)
Block(-4,20,-7,GLOWSTONE)
Block(-4,20,-6,GLOWSTONE)
Block(-4,20,-5,GLOWSTONE)
Block(-4,20,-4,GLOWSTONE)
Block(-4,20,-3,GLOWSTONE)
Block(-4,20,-2,GLOWSTONE)
Block(-4,20,-1,GLOWSTONE)
Block(-4,20,2,GLOWSTONE)
Block(-4,20,3,GLOWSTONE)
Block(-4,20,4,GLOWSTONE)
Block(-4,20,5,GLOWSTONE)
Block(-4,21,-9,GLOWSTONE)
Block(-4,21,-8,GLOWSTONE)
Block(-4,21,-7,GLOWSTONE)
Block(-4,21,-6,GLOWSTONE)
Block(-4,21,-5,GLOWSTONE)
Block(-4,21,-4,GLOWSTONE)
Block(-4,21,-2,GLOWSTONE)
Block(-4,21,2,GLOWSTONE)
Block(-4,21,3,GLOWSTONE)
Block(-4,21,4,GLOWSTONE)
Block(-4,21,5,GLOWSTONE)
Block(-4,22,-8,GLOWSTONE)
Block(-4,22,-7,GLOWSTONE)
Block(-4,22,-6,GLOWSTONE)
Block(-4,22,-5,GLOWSTONE)
Block(-4,22,-4,GLOWSTONE)
Block(-4,22,-3,GLOWSTONE)
Block(-4,22,-2,GLOWSTONE)
Block(-4,22,2,GLOWSTONE)
Block(-4,22,3,GLOWSTONE)
Block(-4,22,4,COAL_BLOCK)
Block(-4,22,5,GLOWSTONE)
Block(-4,22,6,GLOWSTONE)
Block(-4,23,-7,GLOWSTONE)
Block(-4,23,-5,GLOWSTONE)
Block(-4,23,-4,GLOWSTONE)
Block(-4,23,-3,GLOWSTONE)
Block(-4,23,-2,GLOWSTONE)
Block(-4,23,-1,GLOWSTONE)
Block(-4,23,1,GLOWSTONE)
Block(-4,23,2,GLOWSTONE)
Block(-4,23,3,COAL_BLOCK)
Block(-4,23,4,COAL_BLOCK)
Block(-4,23,5,COAL_BLOCK)
Block(-4,23,6,GLOWSTONE)
Block(-4,24,-4,GLOWSTONE)
Block(-4,24,-3,GLOWSTONE)
Block(-4,24,-2,GLOWSTONE)
Block(-4,24,-1,GLOWSTONE)
Block(-4,24,0,GLOWSTONE)
Block(-4,24,1,GLOWSTONE)
Block(-4,24,2,GLOWSTONE)
Block(-4,24,3,GLOWSTONE)
Block(-4,24,4,COAL_BLOCK)
Block(-4,24,5,GLOWSTONE)
Block(-4,24,6,GLOWSTONE)
Block(-4,24,7,GLOWSTONE)
Block(-4,25,-2,GLOWSTONE)
Block(-4,25,-1,GLOWSTONE)
Block(-4,25,0,GLOWSTONE)
Block(-4,25,1,GLOWSTONE)
Block(-4,25,2,GLOWSTONE)
Block(-4,25,3,GLOWSTONE)
Block(-4,25,4,GLOWSTONE)
Block(-4,25,5,GLOWSTONE)
Block(-4,25,6,GLOWSTONE)
Block(-4,25,7,GLOWSTONE)
Block(-4,26,-2,GLOWSTONE)
Block(-4,26,-1,GLOWSTONE)
Block(-4,26,0,GLOWSTONE)
Block(-4,26,3,GLOWSTONE)
Block(-4,26,5,GLOWSTONE)
Block(-4,26,6,GLOWSTONE)
Block(-4,26,7,GLOWSTONE)
Block(-3,0,-8,COAL_BLOCK)
Block(-3,0,-7,COAL_BLOCK)
Block(-3,0,-6,COAL_BLOCK)
Block(-3,0,-5,COAL_BLOCK)
Block(-3,0,-4,COAL_BLOCK)
Block(-3,0,-3,COAL_BLOCK)
Block(-3,0,-2,COAL_BLOCK)
Block(-3,0,-1,COAL_BLOCK)
Block(-3,0,0,COAL_BLOCK)
Block(-3,0,1,COAL_BLOCK)
Block(-3,0,2,COAL_BLOCK)
Block(-3,0,3,COAL_BLOCK)
Block(-3,0,4,COAL_BLOCK)
Block(-3,0,7,COAL_BLOCK)
Block(-3,0,8,COAL_BLOCK)
Block(-3,0,9,COAL_BLOCK)
Block(-3,0,10,COAL_BLOCK)
Block(-3,1,-7,COAL_BLOCK)
Block(-3,1,-6,COAL_BLOCK)
Block(-3,1,-2,COAL_BLOCK)
Block(-3,1,-1,COAL_BLOCK)
Block(-3,1,0,COAL_BLOCK)
Block(-3,1,1,COAL_BLOCK)
Block(-3,2,-7,COAL_BLOCK)
Block(-3,2,-6,COAL_BLOCK)
Block(-3,2,-5,COAL_BLOCK)
Block(-3,2,-4,COAL_BLOCK)
Block(-3,2,-3,COAL_BLOCK)
Block(-3,2,-2,COAL_BLOCK)
Block(-3,2,-1,COAL_BLOCK)
Block(-3,2,0,COAL_BLOCK)
Block(-3,2,1,COAL_BLOCK)
Block(-3,3,-6,COAL_BLOCK)
Block(-3,3,-5,COAL_BLOCK)
Block(-3,3,-4,COAL_BLOCK)
Block(-3,3,-3,COAL_BLOCK)
Block(-3,3,-2,COAL_BLOCK)
Block(-3,3,-1,COAL_BLOCK)
Block(-3,3,0,COAL_BLOCK)
Block(-3,4,-6,COAL_BLOCK)
Block(-3,4,-5,COAL_BLOCK)
Block(-3,4,-4,COAL_BLOCK)
Block(-3,4,-3,COAL_BLOCK)
Block(-3,4,-2,COAL_BLOCK)
Block(-3,4,-1,COAL_BLOCK)
Block(-3,4,0,COAL_BLOCK)
Block(-3,5,-5,COAL_BLOCK)
Block(-3,5,-4,COAL_BLOCK)
Block(-3,5,-3,COAL_BLOCK)
Block(-3,5,-2,COAL_BLOCK)
Block(-3,5,-1,COAL_BLOCK)
Block(-3,5,0,COAL_BLOCK)
Block(-3,5,1,COAL_BLOCK)
Block(-3,6,-5,COAL_BLOCK)
Block(-3,6,-4,COAL_BLOCK)
Block(-3,6,-3,COAL_BLOCK)
Block(-3,6,-2,COAL_BLOCK)
Block(-3,6,-1,COAL_BLOCK)
Block(-3,6,0,COAL_BLOCK)
Block(-3,6,1,COAL_BLOCK)
Block(-3,7,-5,COAL_BLOCK)
Block(-3,7,-4,COAL_BLOCK)
Block(-3,7,-3,COAL_BLOCK)
Block(-3,7,-2,COAL_BLOCK)
Block(-3,7,-1,COAL_BLOCK)
Block(-3,7,0,COAL_BLOCK)
Block(-3,7,1,COAL_BLOCK)
Block(-3,8,-4,COAL_BLOCK)
Block(-3,8,-3,COAL_BLOCK)
Block(-3,8,-2,COAL_BLOCK)
Block(-3,8,-1,COAL_BLOCK)
Block(-3,8,0,COAL_BLOCK)
Block(-3,8,1,COAL_BLOCK)
Block(-3,9,-3,COAL_BLOCK)
Block(-3,9,-2,COAL_BLOCK)
Block(-3,9,-1,COAL_BLOCK)
Block(-3,9,0,COAL_BLOCK)
Block(-3,9,1,COAL_BLOCK)
Block(-3,10,-3,COAL_BLOCK)
Block(-3,10,-2,COAL_BLOCK)
Block(-3,10,-1,COAL_BLOCK)
Block(-3,10,0,COAL_BLOCK)
Block(-3,10,1,COAL_BLOCK)
Block(-3,11,-3,COAL_BLOCK)
Block(-3,11,-2,COAL_BLOCK)
Block(-3,11,-1,COAL_BLOCK)
Block(-3,11,0,COAL_BLOCK)
Block(-3,11,1,COAL_BLOCK)
Block(-3,12,-3,COAL_BLOCK)
Block(-3,12,-2,COAL_BLOCK)
Block(-3,12,-1,COAL_BLOCK)
Block(-3,12,0,COAL_BLOCK)
Block(-3,12,1,COAL_BLOCK)
Block(-3,13,-2,COAL_BLOCK)
Block(-3,13,-1,COAL_BLOCK)
Block(-3,13,0,COAL_BLOCK)
Block(-3,14,-2,COAL_BLOCK)
Block(-3,14,-1,COAL_BLOCK)
Block(-3,14,0,COAL_BLOCK)
Block(-3,15,-2,COAL_BLOCK)
Block(-3,15,-1,COAL_BLOCK)
Block(-3,15,0,COAL_BLOCK)
Block(-3,16,-3,GLOWSTONE)
Block(-3,16,-2,COAL_BLOCK)
Block(-3,16,-1,COAL_BLOCK)
Block(-3,16,0,COAL_BLOCK)
Block(-3,17,-6,GLOWSTONE)
Block(-3,17,-5,GLOWSTONE)
Block(-3,17,-4,GLOWSTONE)
Block(-3,17,-3,COAL_BLOCK)
Block(-3,17,-2,COAL_BLOCK)
Block(-3,17,-1,COAL_BLOCK)
Block(-3,17,0,COAL_BLOCK)
Block(-3,18,-7,GLOWSTONE)
Block(-3,18,-6,GLOWSTONE)
Block(-3,18,-5,GLOWSTONE)
Block(-3,18,-4,GLOWSTONE)
Block(-3,18,-3,COAL_BLOCK)
Block(-3,18,-2,COAL_BLOCK)
Block(-3,18,-1,COAL_BLOCK)
Block(-3,18,0,COAL_BLOCK)
Block(-3,19,-8,GLOWSTONE)
Block(-3,19,-7,GLOWSTONE)
Block(-3,19,-6,GLOWSTONE)
Block(-3,19,-5,GLOWSTONE)
Block(-3,19,-4,GLOWSTONE)
Block(-3,19,-3,COAL_BLOCK)
Block(-3,19,-2,COAL_BLOCK)
Block(-3,19,-1,COAL_BLOCK)
Block(-3,19,0,COAL_BLOCK)
Block(-3,19,4,GLOWSTONE)
Block(-3,20,-9,GLOWSTONE)
Block(-3,20,-8,GLOWSTONE)
Block(-3,20,-7,GLOWSTONE)
Block(-3,20,-6,GLOWSTONE)
Block(-3,20,-5,GLOWSTONE)
Block(-3,20,-2,COAL_BLOCK)
Block(-3,20,-1,COAL_BLOCK)
Block(-3,20,0,COAL_BLOCK)
Block(-3,20,3,GLOWSTONE)
Block(-3,20,4,GLOWSTONE)
Block(-3,20,5,GLOWSTONE)
Block(-3,21,-8,GLOWSTONE)
Block(-3,21,-7,GLOWSTONE)
Block(-3,21,-6,GLOWSTONE)
Block(-3,21,-5,GLOWSTONE)
Block(-3,21,-4,GLOWSTONE)
Block(-3,21,-2,GLOWSTONE)
Block(-3,21,-1,GLOWSTONE)
Block(-3,21,0,GLOWSTONE)
Block(-3,21,2,GLOWSTONE)
Block(-3,21,3,GLOWSTONE)
Block(-3,21,4,COAL_BLOCK)
Block(-3,21,5,GLOWSTONE)
Block(-3,21,6,GLOWSTONE)
Block(-3,22,-8,GLOWSTONE)
Block(-3,22,-7,GLOWSTONE)
Block(-3,22,-6,GLOWSTONE)
Block(-3,22,-5,GLOWSTONE)
Block(-3,22,-4,GLOWSTONE)
Block(-3,22,-3,GLOWSTONE)
Block(-3,22,-1,GLOWSTONE)
Block(-3,22,3,COAL_BLOCK)
Block(-3,22,4,COAL_BLOCK)
Block(-3,22,5,COAL_BLOCK)
Block(-3,22,6,GLOWSTONE)
Block(-3,22,7,GLOWSTONE)
Block(-3,23,-8,GLOWSTONE)
Block(-3,23,-7,GLOWSTONE)
Block(-3,23,-6,GLOWSTONE)
Block(-3,23,-5,GLOWSTONE)
Block(-3,23,-4,GLOWSTONE)
Block(-3,23,-3,GLOWSTONE)
Block(-3,23,-2,GLOWSTONE)
Block(-3,23,1,GLOWSTONE)
Block(-3,23,2,COAL_BLOCK)
Block(-3,23,3,COAL_BLOCK)
Block(-3,23,4,COAL_BLOCK)
Block(-3,23,5,COAL_BLOCK)
Block(-3,23,6,GLOWSTONE)
Block(-3,24,-5,GLOWSTONE)
Block(-3,24,-4,GLOWSTONE)
Block(-3,24,-3,GLOWSTONE)
Block(-3,24,-1,GLOWSTONE)
Block(-3,24,0,GLOWSTONE)
Block(-3,24,1,GLOWSTONE)
Block(-3,24,2,GLOWSTONE)
Block(-3,24,3,COAL_BLOCK)
Block(-3,24,4,COAL_BLOCK)
Block(-3,24,5,COAL_BLOCK)
Block(-3,24,6,GLOWSTONE)
Block(-3,25,-5,GLOWSTONE)
Block(-3,25,-4,GLOWSTONE)
Block(-3,25,-3,GLOWSTONE)
Block(-3,25,-2,GLOWSTONE)
Block(-3,25,-1,GLOWSTONE)
Block(-3,25,0,GLOWSTONE)
Block(-3,25,1,GLOWSTONE)
Block(-3,25,2,GLOWSTONE)
Block(-3,25,3,GLOWSTONE)
Block(-3,25,4,GLOWSTONE)
Block(-3,25,5,GLOWSTONE)
Block(-3,25,6,GLOWSTONE)
Block(-3,25,7,GLOWSTONE)
Block(-3,26,-4,GLOWSTONE)
Block(-3,26,-2,GLOWSTONE)
Block(-3,26,-1,GLOWSTONE)
Block(-3,26,0,GLOWSTONE)
Block(-3,26,2,GLOWSTONE)
Block(-3,26,3,GLOWSTONE)
Block(-3,26,4,GLOWSTONE)
Block(-3,26,5,GLOWSTONE)
Block(-3,26,6,GLOWSTONE)
Block(-3,27,-1,GLOWSTONE)
Block(-3,27,1,GLOWSTONE)
Block(-3,27,2,GLOWSTONE)
Block(-3,27,3,GLOWSTONE)
Block(-3,27,4,GLOWSTONE)
Block(-3,27,5,GLOWSTONE)
Block(-3,27,6,GLOWSTONE)
Block(-3,28,2,GLOWSTONE)
Block(-3,28,5,GLOWSTONE)
Block(-2,0,-9,COAL_BLOCK)
Block(-2,0,-8,COAL_BLOCK)
Block(-2,0,-7,COAL_BLOCK)
Block(-2,0,-6,COAL_BLOCK)
Block(-2,0,-5,COAL_BLOCK)
Block(-2,0,-4,COAL_BLOCK)
Block(-2,0,-3,COAL_BLOCK)
Block(-2,0,-2,COAL_BLOCK)
Block(-2,0,-1,COAL_BLOCK)
Block(-2,0,0,COAL_BLOCK)
Block(-2,0,1,COAL_BLOCK)
Block(-2,0,2,COAL_BLOCK)
Block(-2,0,3,COAL_BLOCK)
Block(-2,0,4,COAL_BLOCK)
Block(-2,0,5,COAL_BLOCK)
Block(-2,0,6,COAL_BLOCK)
Block(-2,0,7,COAL_BLOCK)
Block(-2,0,8,COAL_BLOCK)
Block(-2,0,9,COAL_BLOCK)
Block(-2,1,-7,COAL_BLOCK)
Block(-2,1,-6,COAL_BLOCK)
Block(-2,1,-4,COAL_BLOCK)
Block(-2,1,-2,COAL_BLOCK)
Block(-2,1,-1,COAL_BLOCK)
Block(-2,1,0,COAL_BLOCK)
Block(-2,1,1,COAL_BLOCK)
Block(-2,1,2,COAL_BLOCK)
Block(-2,1,3,COAL_BLOCK)
Block(-2,1,4,COAL_BLOCK)
Block(-2,1,5,COAL_BLOCK)
Block(-2,1,7,COAL_BLOCK)
Block(-2,1,8,COAL_BLOCK)
Block(-2,2,-7,COAL_BLOCK)
Block(-2,2,-6,COAL_BLOCK)
Block(-2,2,-5,COAL_BLOCK)
Block(-2,2,-4,COAL_BLOCK)
Block(-2,2,-3,COAL_BLOCK)
Block(-2,2,-2,COAL_BLOCK)
Block(-2,2,-1,COAL_BLOCK)
Block(-2,2,0,COAL_BLOCK)
Block(-2,2,1,COAL_BLOCK)
Block(-2,2,2,COAL_BLOCK)
Block(-2,2,3,COAL_BLOCK)
Block(-2,2,4,COAL_BLOCK)
Block(-2,3,-7,COAL_BLOCK)
Block(-2,3,-6,COAL_BLOCK)
Block(-2,3,-5,COAL_BLOCK)
Block(-2,3,-4,COAL_BLOCK)
Block(-2,3,-3,COAL_BLOCK)
Block(-2,3,-2,COAL_BLOCK)
Block(-2,3,-1,COAL_BLOCK)
Block(-2,3,0,COAL_BLOCK)
Block(-2,3,1,COAL_BLOCK)
Block(-2,4,-6,COAL_BLOCK)
Block(-2,4,-5,COAL_BLOCK)
Block(-2,4,-4,COAL_BLOCK)
Block(-2,4,-3,COAL_BLOCK)
Block(-2,4,-2,COAL_BLOCK)
Block(-2,4,-1,COAL_BLOCK)
Block(-2,4,0,COAL_BLOCK)
Block(-2,4,1,COAL_BLOCK)
Block(-2,5,-6,COAL_BLOCK)
Block(-2,5,-5,COAL_BLOCK)
Block(-2,5,-4,COAL_BLOCK)
Block(-2,5,-3,COAL_BLOCK)
Block(-2,5,-2,COAL_BLOCK)
Block(-2,5,-1,COAL_BLOCK)
Block(-2,5,0,COAL_BLOCK)
Block(-2,5,1,COAL_BLOCK)
Block(-2,6,-6,COAL_BLOCK)
Block(-2,6,-5,COAL_BLOCK)
Block(-2,6,-4,COAL_BLOCK)
Block(-2,6,-3,COAL_BLOCK)
Block(-2,6,-2,COAL_BLOCK)
Block(-2,6,-1,COAL_BLOCK)
Block(-2,6,0,COAL_BLOCK)
Block(-2,6,1,COAL_BLOCK)
Block(-2,6,2,COAL_BLOCK)
Block(-2,7,-5,COAL_BLOCK)
Block(-2,7,-4,COAL_BLOCK)
Block(-2,7,-3,COAL_BLOCK)
Block(-2,7,-2,COAL_BLOCK)
Block(-2,7,-1,COAL_BLOCK)
Block(-2,7,0,COAL_BLOCK)
Block(-2,7,1,COAL_BLOCK)
Block(-2,8,-5,COAL_BLOCK)
Block(-2,8,-4,COAL_BLOCK)
Block(-2,8,-3,COAL_BLOCK)
Block(-2,8,-2,COAL_BLOCK)
Block(-2,8,-1,COAL_BLOCK)
Block(-2,8,0,COAL_BLOCK)
Block(-2,8,1,COAL_BLOCK)
Block(-2,9,-4,COAL_BLOCK)
Block(-2,9,-3,COAL_BLOCK)
Block(-2,9,-2,COAL_BLOCK)
Block(-2,9,-1,COAL_BLOCK)
Block(-2,9,0,COAL_BLOCK)
Block(-2,9,1,COAL_BLOCK)
Block(-2,9,2,COAL_BLOCK)
Block(-2,10,-4,COAL_BLOCK)
Block(-2,10,-3,COAL_BLOCK)
Block(-2,10,-2,COAL_BLOCK)
Block(-2,10,-1,COAL_BLOCK)
Block(-2,10,0,COAL_BLOCK)
Block(-2,10,1,COAL_BLOCK)
Block(-2,10,2,COAL_BLOCK)
Block(-2,11,-4,COAL_BLOCK)
Block(-2,11,-3,COAL_BLOCK)
Block(-2,11,-2,COAL_BLOCK)
Block(-2,11,-1,COAL_BLOCK)
Block(-2,11,0,COAL_BLOCK)
Block(-2,11,1,COAL_BLOCK)
Block(-2,11,2,COAL_BLOCK)
Block(-2,12,-3,COAL_BLOCK)
Block(-2,12,-2,COAL_BLOCK)
Block(-2,12,-1,COAL_BLOCK)
Block(-2,12,0,COAL_BLOCK)
Block(-2,12,1,COAL_BLOCK)
Block(-2,13,-3,COAL_BLOCK)
Block(-2,13,-2,COAL_BLOCK)
Block(-2,13,-1,COAL_BLOCK)
Block(-2,13,0,COAL_BLOCK)
Block(-2,13,1,COAL_BLOCK)
Block(-2,14,-3,COAL_BLOCK)
Block(-2,14,-2,COAL_BLOCK)
Block(-2,14,-1,COAL_BLOCK)
Block(-2,14,0,LADDER:5)
Block(-2,14,1,COAL_BLOCK)
Block(-2,15,-3,COAL_BLOCK)
Block(-2,15,-2,FLOWER_POT,NetherGricelTree/3-flower_pot.nbt)
Block(-2,15,-1,COAL_BLOCK)
Block(-2,15,0,LADDER:5)
Block(-2,15,1,COAL_BLOCK)
Block(-2,16,-9,GLOWSTONE)
Block(-2,16,-4,GLOWSTONE)
Block(-2,16,-3,COAL_BLOCK)
Block(-2,16,-2,WOOD_STEP:13)
Block(-2,16,-1,COAL_BLOCK)
Block(-2,16,0,LADDER:5)
Block(-2,16,1,COAL_BLOCK)
Block(-2,17,-9,GLOWSTONE)
Block(-2,17,-5,GLOWSTONE)
Block(-2,17,-4,GLOWSTONE)
Block(-2,17,-3,COAL_BLOCK)
Block(-2,17,-2,CHEST:5,NetherGricelTree/4-chest.nbt)
Block(-2,17,-1,WOOD_STEP:13)
Block(-2,17,0,LADDER:5)
Block(-2,17,1,COAL_BLOCK)
Block(-2,18,-9,GLOWSTONE)
Block(-2,18,-6,GLOWSTONE)
Block(-2,18,-5,GLOWSTONE)
Block(-2,18,-4,GLOWSTONE)
Block(-2,18,-3,COAL_BLOCK)
Block(-2,18,-1,NETHER_FENCE)
Block(-2,18,0,LADDER:5)
Block(-2,18,1,COAL_BLOCK)
Block(-2,18,6,GLOWSTONE)
Block(-2,19,-10,GLOWSTONE)
Block(-2,19,-9,GLOWSTONE)
Block(-2,19,-8,GLOWSTONE)
Block(-2,19,-5,GLOWSTONE)
Block(-2,19,-4,GLOWSTONE)
Block(-2,19,-3,COAL_BLOCK)
Block(-2,19,1,COAL_BLOCK)
Block(-2,19,6,GLOWSTONE)
Block(-2,19,7,GLOWSTONE)
Block(-2,20,-9,GLOWSTONE)
Block(-2,20,-8,GLOWSTONE)
Block(-2,20,-7,GLOWSTONE)
Block(-2,20,-6,GLOWSTONE)
Block(-2,20,-5,GLOWSTONE)
Block(-2,20,-3,COAL_BLOCK)
Block(-2,20,-2,COAL_BLOCK)
Block(-2,20,-1,COAL_BLOCK)
Block(-2,20,0,COAL_BLOCK)
Block(-2,20,1,COAL_BLOCK)
Block(-2,20,2,COAL_BLOCK)
Block(-2,20,6,GLOWSTONE)
Block(-2,20,7,GLOWSTONE)
Block(-2,21,-8,GLOWSTONE)
Block(-2,21,-7,GLOWSTONE)
Block(-2,21,-6,GLOWSTONE)
Block(-2,21,-5,GLOWSTONE)
Block(-2,21,-2,COAL_BLOCK)
Block(-2,21,-1,COAL_BLOCK)
Block(-2,21,0,COAL_BLOCK)
Block(-2,21,1,COAL_BLOCK)
Block(-2,21,2,COAL_BLOCK)
Block(-2,21,3,COAL_BLOCK)
Block(-2,21,4,COAL_BLOCK)
Block(-2,21,5,COAL_BLOCK)
Block(-2,21,6,GLOWSTONE)
Block(-2,21,7,GLOWSTONE)
Block(-2,22,-8,GLOWSTONE)
Block(-2,22,-7,GLOWSTONE)
Block(-2,22,-6,GLOWSTONE)
Block(-2,22,-5,GLOWSTONE)
Block(-2,22,-4,GLOWSTONE)
Block(-2,22,-3,GLOWSTONE)
Block(-2,22,-2,GLOWSTONE)
Block(-2,22,-1,GLOWSTONE)
Block(-2,22,0,COAL_BLOCK)
Block(-2,22,1,COAL_BLOCK)
Block(-2,22,2,COAL_BLOCK)
Block(-2,22,3,COAL_BLOCK)
Block(-2,22,4,COAL_BLOCK)
Block(-2,22,5,COAL_BLOCK)
Block(-2,22,6,GLOWSTONE)
Block(-2,22,7,GLOWSTONE)
Block(-2,23,-8,GLOWSTONE)
Block(-2,23,-7,GLOWSTONE)
Block(-2,23,-6,GLOWSTONE)
Block(-2,23,-5,GLOWSTONE)
Block(-2,23,-4,GLOWSTONE)
Block(-2,23,-3,GLOWSTONE)
Block(-2,23,-2,GLOWSTONE)
Block(-2,23,1,COAL_BLOCK)
Block(-2,23,2,COAL_BLOCK)
Block(-2,23,3,COAL_BLOCK)
Block(-2,23,4,COAL_BLOCK)
Block(-2,23,5,COAL_BLOCK)
Block(-2,23,6,GLOWSTONE)
Block(-2,23,7,GLOWSTONE)
Block(-2,23,8,GLOWSTONE)
Block(-2,24,-7,GLOWSTONE)
Block(-2,24,-6,GLOWSTONE)
Block(-2,24,-5,GLOWSTONE)
Block(-2,24,-4,GLOWSTONE)
Block(-2,24,-3,GLOWSTONE)
Block(-2,24,-1,GLOWSTONE)
Block(-2,24,0,GLOWSTONE)
Block(-2,24,1,GLOWSTONE)
Block(-2,24,2,COAL_BLOCK)
Block(-2,24,3,COAL_BLOCK)
Block(-2,24,4,COAL_BLOCK)
Block(-2,24,5,GLOWSTONE)
Block(-2,24,6,GLOWSTONE)
Block(-2,24,7,GLOWSTONE)
Block(-2,25,-8,GLOWSTONE)
Block(-2,25,-7,GLOWSTONE)
Block(-2,25,-6,GLOWSTONE)
Block(-2,25,-5,GLOWSTONE)
Block(-2,25,-4,GLOWSTONE)
Block(-2,25,-3,GLOWSTONE)
Block(-2,25,-2,GLOWSTONE)
Block(-2,25,-1,GLOWSTONE)
Block(-2,25,0,GLOWSTONE)
Block(-2,25,1,GLOWSTONE)
Block(-2,25,2,GLOWSTONE)
Block(-2,25,3,GLOWSTONE)
Block(-2,25,4,GLOWSTONE)
Block(-2,25,5,GLOWSTONE)
Block(-2,25,6,GLOWSTONE)
Block(-2,26,-7,GLOWSTONE)
Block(-2,26,-5,GLOWSTONE)
Block(-2,26,-4,GLOWSTONE)
Block(-2,26,-3,GLOWSTONE)
Block(-2,26,-2,GLOWSTONE)
Block(-2,26,-1,GLOWSTONE)
Block(-2,26,0,GLOWSTONE)
Block(-2,26,1,GLOWSTONE)
Block(-2,26,2,GLOWSTONE)
Block(-2,26,3,GLOWSTONE)
Block(-2,26,4,GLOWSTONE)
Block(-2,26,5,GLOWSTONE)
Block(-2,26,6,GLOWSTONE)
Block(-2,27,-4,GLOWSTONE)
Block(-2,27,-3,GLOWSTONE)
Block(-2,27,-2,GLOWSTONE)
Block(-2,27,-1,GLOWSTONE)
Block(-2,27,0,GLOWSTONE)
Block(-2,27,1,GLOWSTONE)
Block(-2,27,2,GLOWSTONE)
Block(-2,27,3,GLOWSTONE)
Block(-2,27,4,GLOWSTONE)
Block(-2,27,5,GLOWSTONE)
Block(-2,27,6,GLOWSTONE)
Block(-2,28,-3,GLOWSTONE)
Block(-2,28,0,GLOWSTONE)
Block(-2,28,1,GLOWSTONE)
Block(-2,28,2,GLOWSTONE)
Block(-2,28,3,GLOWSTONE)
Block(-2,28,4,GLOWSTONE)
Block(-2,28,5,GLOWSTONE)
Block(-2,28,6,GLOWSTONE)
Block(-2,29,1,GLOWSTONE)
Block(-1,0,-10,COAL_BLOCK)
Block(-1,0,-9,COAL_BLOCK)
Block(-1,0,-8,COAL_BLOCK)
Block(-1,0,-7,COAL_BLOCK)
Block(-1,0,-6,COAL_BLOCK)
Block(-1,0,-5,COAL_BLOCK)
Block(-1,0,-4,COAL_BLOCK)
Block(-1,0,-3,COAL_BLOCK)
Block(-1,0,-2,COAL_BLOCK)
Block(-1,0,-1,COAL_BLOCK)
Block(-1,0,0,COAL_BLOCK)
Block(-1,0,1,COAL_BLOCK)
Block(-1,0,2,COAL_BLOCK)
Block(-1,0,3,COAL_BLOCK)
Block(-1,0,4,COAL_BLOCK)
Block(-1,0,5,COAL_BLOCK)
Block(-1,0,6,COAL_BLOCK)
Block(-1,0,7,COAL_BLOCK)
Block(-1,0,9,COAL_BLOCK)
Block(-1,0,10,COAL_BLOCK)
Block(-1,1,-9,COAL_BLOCK)
Block(-1,1,-8,COAL_BLOCK)
Block(-1,1,-7,COAL_BLOCK)
Block(-1,1,-4,COAL_BLOCK)
Block(-1,1,2,COAL_BLOCK)
Block(-1,1,3,COAL_BLOCK)
Block(-1,1,4,COAL_BLOCK)
Block(-1,1,5,COAL_BLOCK)
Block(-1,1,6,COAL_BLOCK)
Block(-1,1,7,COAL_BLOCK)
Block(-1,2,-7,COAL_BLOCK)
Block(-1,2,-6,COAL_BLOCK)
Block(-1,2,-5,COAL_BLOCK)
Block(-1,2,-4,COAL_BLOCK)
Block(-1,2,-3,COAL_BLOCK)
Block(-1,2,-2,COAL_BLOCK)
Block(-1,2,-1,COAL_BLOCK)
Block(-1,2,0,COAL_BLOCK)
Block(-1,2,1,WALL_SIGN,NetherGricelTree/5-sign.nbt)
Block(-1,2,2,COAL_BLOCK)
Block(-1,2,3,COAL_BLOCK)
Block(-1,2,4,COAL_BLOCK)
Block(-1,2,5,COAL_BLOCK)
Block(-1,3,-7,COAL_BLOCK)
Block(-1,3,-6,COAL_BLOCK)
Block(-1,3,-5,COAL_BLOCK)
Block(-1,3,-4,COAL_BLOCK)
Block(-1,3,-3,COAL_BLOCK)
Block(-1,3,-2,COAL_BLOCK)
Block(-1,3,-1,COAL_BLOCK)
Block(-1,3,0,COAL_BLOCK)
Block(-1,3,2,COAL_BLOCK)
Block(-1,3,3,COAL_BLOCK)
Block(-1,3,4,COAL_BLOCK)
Block(-1,4,-7,COAL_BLOCK)
Block(-1,4,-6,COAL_BLOCK)
Block(-1,4,-5,COAL_BLOCK)
Block(-1,4,-4,COAL_BLOCK)
Block(-1,4,-3,COAL_BLOCK)
Block(-1,4,-2,COAL_BLOCK)
Block(-1,4,-1,COAL_BLOCK)
Block(-1,4,0,COAL_BLOCK)
Block(-1,4,1,COAL_BLOCK)
Block(-1,5,-6,COAL_BLOCK)
Block(-1,5,-5,COAL_BLOCK)
Block(-1,5,-4,COAL_BLOCK)
Block(-1,5,-3,COAL_BLOCK)
Block(-1,5,-2,COAL_BLOCK)
Block(-1,5,-1,COAL_BLOCK)
Block(-1,5,0,COAL_BLOCK)
Block(-1,5,1,COAL_BLOCK)
Block(-1,5,2,COAL_BLOCK)
Block(-1,6,-6,COAL_BLOCK)
Block(-1,6,-5,COAL_BLOCK)
Block(-1,6,-4,COAL_BLOCK)
Block(-1,6,-3,COAL_BLOCK)
Block(-1,6,-2,COAL_BLOCK)
Block(-1,6,-1,COAL_BLOCK)
Block(-1,6,1,COAL_BLOCK)
Block(-1,6,2,COAL_BLOCK)
Block(-1,7,-6,COAL_BLOCK)
Block(-1,7,-5,COAL_BLOCK)
Block(-1,7,-4,COAL_BLOCK)
Block(-1,7,-3,COAL_BLOCK)
Block(-1,7,-2,COAL_BLOCK)
Block(-1,7,1,COAL_BLOCK)
Block(-1,7,2,COAL_BLOCK)
Block(-1,8,-5,COAL_BLOCK)
Block(-1,8,-4,COAL_BLOCK)
Block(-1,8,-3,COAL_BLOCK)
Block(-1,8,1,COAL_BLOCK)
Block(-1,9,-5,COAL_BLOCK)
Block(-1,9,-4,COAL_BLOCK)
Block(-1,9,-3,LADDER:5)
Block(-1,9,0,COAL_BLOCK)
Block(-1,9,1,COAL_BLOCK)
Block(-1,9,2,COAL_BLOCK)
Block(-1,10,-5,COAL_BLOCK)
Block(-1,10,-4,COAL_BLOCK)
Block(-1,10,-3,LADDER:5)
Block(-1,10,-1,COAL_BLOCK)
Block(-1,10,0,COAL_BLOCK)
Block(-1,10,1,COAL_BLOCK)
Block(-1,10,2,COAL_BLOCK)
Block(-1,11,-4,COAL_BLOCK)
Block(-1,11,-3,LADDER:5)
Block(-1,11,-2,COAL_BLOCK)
Block(-1,11,-1,COAL_BLOCK)
Block(-1,11,0,COAL_BLOCK)
Block(-1,11,1,COAL_BLOCK)
Block(-1,11,2,COAL_BLOCK)
Block(-1,12,-5,COAL_BLOCK)
Block(-1,12,-4,COAL_BLOCK)
Block(-1,12,-3,LADDER:5)
Block(-1,12,-2,COAL_BLOCK)
Block(-1,12,-1,COAL_BLOCK)
Block(-1,12,0,COAL_BLOCK)
Block(-1,12,1,COAL_BLOCK)
Block(-1,12,2,COAL_BLOCK)
Block(-1,13,-4,COAL_BLOCK)
Block(-1,13,-3,LADDER:5)
Block(-1,13,-2,COAL_BLOCK)
Block(-1,13,-1,COAL_BLOCK)
Block(-1,13,0,COAL_BLOCK)
Block(-1,13,1,COAL_BLOCK)
Block(-1,13,2,COAL_BLOCK)
Block(-1,14,-4,COAL_BLOCK)
Block(-1,14,2,COAL_BLOCK)
Block(-1,15,-4,COAL_BLOCK)
Block(-1,15,1,WOOD_STEP:13)
Block(-1,15,2,COAL_BLOCK)
Block(-1,16,-4,COAL_BLOCK)
Block(-1,16,1,NETHER_FENCE)
Block(-1,16,2,COAL_BLOCK)
Block(-1,17,-9,GLOWSTONE)
Block(-1,17,-4,COAL_BLOCK)
Block(-1,17,-1,WOOD_STEP:13)
Block(-1,17,0,WOOD_STEP:13)
Block(-1,17,1,WOOD_STEP:13)
Block(-1,17,2,COAL_BLOCK)
Block(-1,18,-10,GLOWSTONE)
Block(-1,18,-9,GLOWSTONE)
Block(-1,18,-8,GLOWSTONE)
Block(-1,18,-4,GLOWSTONE)
Block(-1,18,-3,COAL_BLOCK)
Block(-1,18,-1,NETHER_FENCE)
Block(-1,18,1,COAL_BLOCK)
Block(-1,18,2,COAL_BLOCK)
Block(-1,19,-10,GLOWSTONE)
Block(-1,19,-9,GLOWSTONE)
Block(-1,19,-8,GLOWSTONE)
Block(-1,19,-7,GLOWSTONE)
Block(-1,19,-3,COAL_BLOCK)
Block(-1,19,1,COAL_BLOCK)
Block(-1,19,2,COAL_BLOCK)
Block(-1,20,-10,GLOWSTONE)
Block(-1,20,-9,GLOWSTONE)
Block(-1,20,-8,GLOWSTONE)
Block(-1,20,-7,GLOWSTONE)
Block(-1,20,-6,GLOWSTONE)
Block(-1,20,-4,COAL_BLOCK)
Block(-1,20,-3,COAL_BLOCK)
Block(-1,20,-2,COAL_BLOCK)
Block(-1,20,-1,COAL_BLOCK)
Block(-1,20,0,COAL_BLOCK)
Block(-1,20,1,COAL_BLOCK)
Block(-1,20,2,COAL_BLOCK)
Block(-1,20,6,GLOWSTONE)
Block(-1,21,-9,GLOWSTONE)
Block(-1,21,-8,GLOWSTONE)
Block(-1,21,-7,GLOWSTONE)
Block(-1,21,-6,GLOWSTONE)
Block(-1,21,-5,COAL_BLOCK)
Block(-1,21,-4,COAL_BLOCK)
Block(-1,21,-3,COAL_BLOCK)
Block(-1,21,-2,COAL_BLOCK)
Block(-1,21,-1,COAL_BLOCK)
Block(-1,21,0,COAL_BLOCK)
Block(-1,21,1,COAL_BLOCK)
Block(-1,21,2,COAL_BLOCK)
Block(-1,21,4,COAL_BLOCK)
Block(-1,21,6,GLOWSTONE)
Block(-1,22,-10,GLOWSTONE)
Block(-1,22,-9,GLOWSTONE)
Block(-1,22,-8,GLOWSTONE)
Block(-1,22,-7,GLOWSTONE)
Block(-1,22,-6,GLOWSTONE)
Block(-1,22,-5,GLOWSTONE)
Block(-1,22,-4,COAL_BLOCK)
Block(-1,22,-3,GLOWSTONE)
Block(-1,22,-2,GLOWSTONE)
Block(-1,22,-1,GLOWSTONE)
Block(-1,22,0,COAL_BLOCK)
Block(-1,22,1,COAL_BLOCK)
Block(-1,22,2,COAL_BLOCK)
Block(-1,22,3,COAL_BLOCK)
Block(-1,22,4,COAL_BLOCK)
Block(-1,22,5,COAL_BLOCK)
Block(-1,22,6,GLOWSTONE)
Block(-1,22,7,GLOWSTONE)
Block(-1,22,8,GLOWSTONE)
Block(-1,23,-9,GLOWSTONE)
Block(-1,23,-8,GLOWSTONE)
Block(-1,23,-7,GLOWSTONE)
Block(-1,23,-6,GLOWSTONE)
Block(-1,23,-5,GLOWSTONE)
Block(-1,23,-4,GLOWSTONE)
Block(-1,23,-3,GLOWSTONE)
Block(-1,23,-2,GLOWSTONE)
Block(-1,23,-1,GLOWSTONE)
Block(-1,23,0,COAL_BLOCK)
Block(-1,23,1,COAL_BLOCK)
Block(-1,23,2,COAL_BLOCK)
Block(-1,23,3,COAL_BLOCK)
Block(-1,23,4,COAL_BLOCK)
Block(-1,23,5,GLOWSTONE)
Block(-1,23,6,GLOWSTONE)
Block(-1,23,7,GLOWSTONE)
Block(-1,23,8,GLOWSTONE)
Block(-1,24,-8,GLOWSTONE)
Block(-1,24,-7,GLOWSTONE)
Block(-1,24,-6,GLOWSTONE)
Block(-1,24,-5,GLOWSTONE)
Block(-1,24,-4,GLOWSTONE)
Block(-1,24,-3,GLOWSTONE)
Block(-1,24,-2,GLOWSTONE)
Block(-1,24,-1,GLOWSTONE)
Block(-1,24,0,GLOWSTONE)
Block(-1,24,1,COAL_BLOCK)
Block(-1,24,2,COAL_BLOCK)
Block(-1,24,3,COAL_BLOCK)
Block(-1,24,4,GLOWSTONE)
Block(-1,24,5,GLOWSTONE)
Block(-1,24,6,GLOWSTONE)
Block(-1,24,7,GLOWSTONE)
Block(-1,24,8,GLOWSTONE)
Block(-1,25,-8,GLOWSTONE)
Block(-1,25,-7,GLOWSTONE)
Block(-1,25,-6,GLOWSTONE)
Block(-1,25,-5,GLOWSTONE)
Block(-1,25,-4,GLOWSTONE)
Block(-1,25,-3,GLOWSTONE)
Block(-1,25,-2,GLOWSTONE)
Block(-1,25,-1,GLOWSTONE)
Block(-1,25,0,GLOWSTONE)
Block(-1,25,1,GLOWSTONE)
Block(-1,25,2,GLOWSTONE)
Block(-1,25,3,GLOWSTONE)
Block(-1,25,4,GLOWSTONE)
Block(-1,25,5,GLOWSTONE)
Block(-1,25,6,GLOWSTONE)
Block(-1,26,-8,GLOWSTONE)
Block(-1,26,-7,GLOWSTONE)
Block(-1,26,-6,GLOWSTONE)
Block(-1,26,-4,GLOWSTONE)
Block(-1,26,-3,GLOWSTONE)
Block(-1,26,-2,GLOWSTONE)
Block(-1,26,-1,GLOWSTONE)
Block(-1,26,0,GLOWSTONE)
Block(-1,26,1,GLOWSTONE)
Block(-1,26,2,GLOWSTONE)
Block(-1,26,3,GLOWSTONE)
Block(-1,26,4,GLOWSTONE)
Block(-1,26,5,GLOWSTONE)
Block(-1,26,6,GLOWSTONE)
Block(-1,27,-4,GLOWSTONE)
Block(-1,27,-3,GLOWSTONE)
Block(-1,27,-2,GLOWSTONE)
Block(-1,27,-1,GLOWSTONE)
Block(-1,27,0,GLOWSTONE)
Block(-1,27,1,GLOWSTONE)
Block(-1,27,2,GLOWSTONE)
Block(-1,27,3,GLOWSTONE)
Block(-1,27,4,GLOWSTONE)
Block(-1,27,5,GLOWSTONE)
Block(-1,27,6,GLOWSTONE)
Block(-1,28,-4,GLOWSTONE)
Block(-1,28,-3,GLOWSTONE)
Block(-1,28,-2,GLOWSTONE)
Block(-1,28,0,GLOWSTONE)
Block(-1,28,1,GLOWSTONE)
Block(-1,28,2,GLOWSTONE)
Block(-1,28,3,GLOWSTONE)
Block(-1,28,4,GLOWSTONE)
Block(-1,28,5,GLOWSTONE)
Block(-1,29,0,GLOWSTONE)
Block(-1,29,1,GLOWSTONE)
Block(-1,29,2,GLOWSTONE)
Block(0,0,-10,COAL_BLOCK)
Block(0,0,-9,COAL_BLOCK)
Block(0,0,-8,COAL_BLOCK)
Block(0,0,-7,COAL_BLOCK)
Block(0,0,-6,COAL_BLOCK)
Block(0,0,-5,COAL_BLOCK)
Block(0,0,-4,COAL_BLOCK)
Block(0,0,-2,COAL_BLOCK)
Block(0,0,-1,COAL_BLOCK)
Block(0,0,0,COAL_BLOCK)
Block(0,0,1,COAL_BLOCK)
Block(0,0,2,COAL_BLOCK)
Block(0,0,3,COAL_BLOCK)
Block(0,0,4,COAL_BLOCK)
Block(0,0,5,COAL_BLOCK)
Block(0,0,6,COAL_BLOCK)
Block(0,0,7,COAL_BLOCK)
Block(0,0,10,COAL_BLOCK)
Block(0,0,11,COAL_BLOCK)
Block(0,1,-9,COAL_BLOCK)
Block(0,1,-8,IRON_TRAPDOOR:11)
Block(0,1,-5,COAL_BLOCK)
Block(0,1,-4,COAL_BLOCK)
Block(0,1,-3,COAL_BLOCK)
Block(0,1,-2,COAL_BLOCK)
Block(0,1,-1,COAL_BLOCK)
Block(0,1,0,COAL_BLOCK)
Block(0,1,1,COAL_BLOCK)
Block(0,1,2,COAL_BLOCK)
Block(0,1,3,COAL_BLOCK)
Block(0,1,4,COAL_BLOCK)
Block(0,1,5,COAL_BLOCK)
Block(0,2,-8,CARPET:15)
Block(0,2,-7,COAL_BLOCK)
Block(0,2,-6,COAL_BLOCK)
Block(0,2,-5,COAL_BLOCK)
Block(0,2,-4,COAL_BLOCK)
Block(0,2,-3,COAL_BLOCK)
Block(0,2,-2,COAL_BLOCK)
Block(0,2,-1,COAL_BLOCK)
Block(0,2,0,COAL_BLOCK)
Block(0,2,2,COAL_BLOCK)
Block(0,2,3,COAL_BLOCK)
Block(0,2,4,COAL_BLOCK)
Block(0,3,-7,COAL_BLOCK)
Block(0,3,-6,COAL_BLOCK)
Block(0,3,-5,COAL_BLOCK)
Block(0,3,-4,COAL_BLOCK)
Block(0,3,-3,COAL_BLOCK)
Block(0,3,-2,COAL_BLOCK)
Block(0,3,-1,COAL_BLOCK)
Block(0,3,0,COAL_BLOCK)
Block(0,3,2,COAL_BLOCK)
Block(0,4,-6,COAL_BLOCK)
Block(0,4,-5,COAL_BLOCK)
Block(0,4,-4,COAL_BLOCK)
Block(0,4,-3,COAL_BLOCK)
Block(0,4,-2,COAL_BLOCK)
Block(0,4,-1,COAL_BLOCK)
Block(0,4,0,COAL_BLOCK)
Block(0,4,2,COAL_BLOCK)
Block(0,5,-6,COAL_BLOCK)
Block(0,5,-5,COAL_BLOCK)
Block(0,5,-4,COAL_BLOCK)
Block(0,5,-3,COAL_BLOCK)
Block(0,5,-2,COAL_BLOCK)
Block(0,5,-1,COAL_BLOCK)
Block(0,5,1,COAL_BLOCK)
Block(0,5,2,COAL_BLOCK)
Block(0,6,-6,COAL_BLOCK)
Block(0,6,-5,COAL_BLOCK)
Block(0,6,-4,COAL_BLOCK)
Block(0,6,-3,COAL_BLOCK)
Block(0,6,-2,COAL_BLOCK)
Block(0,6,-1,COAL_BLOCK)
Block(0,6,1,COAL_BLOCK)
Block(0,6,2,COAL_BLOCK)
Block(0,7,-6,COAL_BLOCK)
Block(0,7,-5,COAL_BLOCK)
Block(0,7,-4,COAL_BLOCK)
Block(0,7,-3,COAL_BLOCK)
Block(0,7,-2,COAL_BLOCK)
Block(0,7,-1,COAL_BLOCK)
Block(0,7,1,COAL_BLOCK)
Block(0,7,2,COAL_BLOCK)
Block(0,8,-6,COAL_BLOCK)
Block(0,8,-5,COAL_BLOCK)
Block(0,8,-4,COAL_BLOCK)
Block(0,8,-3,COAL_BLOCK)
Block(0,8,-2,COAL_BLOCK)
Block(0,8,-1,COAL_BLOCK)
Block(0,8,0,COAL_BLOCK)
Block(0,8,1,COAL_BLOCK)
Block(0,8,2,COAL_BLOCK)
Block(0,9,-5,COAL_BLOCK)
Block(0,9,-4,COAL_BLOCK)
Block(0,9,-3,COAL_BLOCK)
Block(0,9,-2,COAL_BLOCK)
Block(0,9,-1,COAL_BLOCK)
Block(0,9,0,COAL_BLOCK)
Block(0,9,1,COAL_BLOCK)
Block(0,9,2,COAL_BLOCK)
Block(0,10,-5,COAL_BLOCK)
Block(0,10,-4,COAL_BLOCK)
Block(0,10,-3,COAL_BLOCK)
Block(0,10,-2,COAL_BLOCK)
Block(0,10,-1,COAL_BLOCK)
Block(0,10,0,COAL_BLOCK)
Block(0,10,1,COAL_BLOCK)
Block(0,10,2,COAL_BLOCK)
Block(0,11,-5,COAL_BLOCK)
Block(0,11,-4,COAL_BLOCK)
Block(0,11,-3,COAL_BLOCK)
Block(0,11,-2,COAL_BLOCK)
Block(0,11,-1,COAL_BLOCK)
Block(0,11,0,COAL_BLOCK)
Block(0,11,1,COAL_BLOCK)
Block(0,11,2,COAL_BLOCK)
Block(0,12,-6,COAL_BLOCK)
Block(0,12,-5,COAL_BLOCK)
Block(0,12,-4,COAL_BLOCK)
Block(0,12,-3,COAL_BLOCK)
Block(0,12,-2,COAL_BLOCK)
Block(0,12,-1,COAL_BLOCK)
Block(0,12,0,COAL_BLOCK)
Block(0,12,1,COAL_BLOCK)
Block(0,12,2,COAL_BLOCK)
Block(0,13,-10,GLOWSTONE)
Block(0,13,-7,COAL_BLOCK)
Block(0,13,-6,COAL_BLOCK)
Block(0,13,-5,COAL_BLOCK)
Block(0,13,-4,COAL_BLOCK)
Block(0,13,-3,COAL_BLOCK)
Block(0,13,-2,COAL_BLOCK)
Block(0,13,-1,COAL_BLOCK)
Block(0,13,0,COAL_BLOCK)
Block(0,13,1,COAL_BLOCK)
Block(0,13,2,COAL_BLOCK)
Block(0,14,-11,GLOWSTONE)
Block(0,14,-10,GLOWSTONE)
Block(0,14,-6,COAL_BLOCK)
Block(0,14,-4,DARK_OAK_DOOR)
Block(0,14,2,COAL_BLOCK)
Block(0,15,-11,GLOWSTONE)
Block(0,15,-8,GLOWSTONE)
Block(0,15,-4,DARK_OAK_DOOR:8)
Block(0,15,1,WOOD_STEP:5)
Block(0,15,2,COAL_BLOCK)
Block(0,16,-10,GLOWSTONE)
Block(0,16,-9,GLOWSTONE)
Block(0,16,-8,GLOWSTONE)
Block(0,16,-7,GLOWSTONE)
Block(0,16,-4,COAL_BLOCK)
Block(0,16,2,COAL_BLOCK)
Block(0,17,-11,GLOWSTONE)
Block(0,17,-10,GLOWSTONE)
Block(0,17,-9,GLOWSTONE)
Block(0,17,-8,GLOWSTONE)
Block(0,17,-4,COAL_BLOCK)
Block(0,17,-1,WOOD_STEP:13)
Block(0,17,0,WOOD_STEP:13)
Block(0,17,1,WOOD_STEP:13)
Block(0,17,2,COAL_BLOCK)
Block(0,18,-12,GLOWSTONE)
Block(0,18,-11,GLOWSTONE)
Block(0,18,-10,GLOWSTONE)
Block(0,18,-9,GLOWSTONE)
Block(0,18,-8,GLOWSTONE)
Block(0,18,-3,COAL_BLOCK)
Block(0,18,-2,COAL_BLOCK)
Block(0,18,-1,NETHER_FENCE)
Block(0,18,1,DARK_OAK_DOOR:1)
Block(0,18,8,GLOWSTONE)
Block(0,19,-11,GLOWSTONE)
Block(0,19,-10,GLOWSTONE)
Block(0,19,-9,GLOWSTONE)
Block(0,19,-8,GLOWSTONE)
Block(0,19,-7,GLOWSTONE)
Block(0,19,-4,COAL_BLOCK)
Block(0,19,-3,COAL_BLOCK)
Block(0,19,-2,COAL_BLOCK)
Block(0,19,0,WALL_SIGN:4,NetherGricelTree/6-sign.nbt)
Block(0,19,1,DARK_OAK_DOOR:9)
Block(0,19,8,GLOWSTONE)
Block(0,20,-9,GLOWSTONE)
Block(0,20,-8,GLOWSTONE)
Block(0,20,-7,GLOWSTONE)
Block(0,20,-5,COAL_BLOCK)
Block(0,20,-4,COAL_BLOCK)
Block(0,20,-3,COAL_BLOCK)
Block(0,20,-2,COAL_BLOCK)
Block(0,20,-1,COAL_BLOCK)
Block(0,20,0,COAL_BLOCK)
Block(0,20,1,COAL_BLOCK)
Block(0,20,2,COAL_BLOCK)
Block(0,20,8,GLOWSTONE)
Block(0,21,-10,GLOWSTONE)
Block(0,21,-9,GLOWSTONE)
Block(0,21,-8,GLOWSTONE)
Block(0,21,-7,GLOWSTONE)
Block(0,21,-6,GLOWSTONE)
Block(0,21,-5,COAL_BLOCK)
Block(0,21,-4,COAL_BLOCK)
Block(0,21,-3,COAL_BLOCK)
Block(0,21,-2,COAL_BLOCK)
Block(0,21,-1,COAL_BLOCK)
Block(0,21,0,COAL_BLOCK)
Block(0,21,1,COAL_BLOCK)
Block(0,21,2,COAL_BLOCK)
Block(0,21,8,GLOWSTONE)
Block(0,22,-10,GLOWSTONE)
Block(0,22,-9,GLOWSTONE)
Block(0,22,-8,GLOWSTONE)
Block(0,22,-7,GLOWSTONE)
Block(0,22,-6,GLOWSTONE)
Block(0,22,-5,COAL_BLOCK)
Block(0,22,-4,COAL_BLOCK)
Block(0,22,-3,COAL_BLOCK)
Block(0,22,-2,GLOWSTONE)
Block(0,22,-1,GLOWSTONE)
Block(0,22,0,COAL_BLOCK)
Block(0,22,1,COAL_BLOCK)
Block(0,22,2,COAL_BLOCK)
Block(0,22,6,GLOWSTONE)
Block(0,22,7,GLOWSTONE)
Block(0,22,8,GLOWSTONE)
Block(0,23,-10,GLOWSTONE)
Block(0,23,-9,GLOWSTONE)
Block(0,23,-8,GLOWSTONE)
Block(0,23,-7,GLOWSTONE)
Block(0,23,-6,GLOWSTONE)
Block(0,23,-5,GLOWSTONE)
Block(0,23,-4,COAL_BLOCK)
Block(0,23,-3,GLOWSTONE)
Block(0,23,-2,GLOWSTONE)
Block(0,23,-1,GLOWSTONE)
Block(0,23,0,GLOWSTONE)
Block(0,23,1,COAL_BLOCK)
Block(0,23,2,COAL_BLOCK)
Block(0,23,3,COAL_BLOCK)
Block(0,23,5,GLOWSTONE)
Block(0,23,6,GLOWSTONE)
Block(0,23,7,GLOWSTONE)
Block(0,23,8,GLOWSTONE)
Block(0,23,9,GLOWSTONE)
Block(0,24,-9,GLOWSTONE)
Block(0,24,-8,GLOWSTONE)
Block(0,24,-7,GLOWSTONE)
Block(0,24,-6,GLOWSTONE)
Block(0,24,-5,GLOWSTONE)
Block(0,24,-4,GLOWSTONE)
Block(0,24,-3,GLOWSTONE)
Block(0,24,-2,GLOWSTONE)
Block(0,24,-1,GLOWSTONE)
Block(0,24,0,GLOWSTONE)
Block(0,24,1,GLOWSTONE)
Block(0,24,2,COAL_BLOCK)
Block(0,24,3,GLOWSTONE)
Block(0,24,4,GLOWSTONE)
Block(0,24,5,GLOWSTONE)
Block(0,24,6,GLOWSTONE)
Block(0,24,7,GLOWSTONE)
Block(0,24,8,GLOWSTONE)
Block(0,25,-8,GLOWSTONE)
Block(0,25,-7,GLOWSTONE)
Block(0,25,-6,GLOWSTONE)
Block(0,25,-5,GLOWSTONE)
Block(0,25,-4,GLOWSTONE)
Block(0,25,-3,GLOWSTONE)
Block(0,25,-2,GLOWSTONE)
Block(0,25,-1,GLOWSTONE)
Block(0,25,0,GLOWSTONE)
Block(0,25,1,GLOWSTONE)
Block(0,25,2,GLOWSTONE)
Block(0,25,3,GLOWSTONE)
Block(0,25,4,GLOWSTONE)
Block(0,25,5,GLOWSTONE)
Block(0,25,6,GLOWSTONE)
Block(0,26,-7,GLOWSTONE)
Block(0,26,-5,GLOWSTONE)
Block(0,26,-4,GLOWSTONE)
Block(0,26,-3,GLOWSTONE)
Block(0,26,-2,GLOWSTONE)
Block(0,26,-1,GLOWSTONE)
Block(0,26,0,GLOWSTONE)
Block(0,26,1,GLOWSTONE)
Block(0,26,2,GLOWSTONE)
Block(0,26,3,GLOWSTONE)
Block(0,26,4,GLOWSTONE)
Block(0,26,5,GLOWSTONE)
Block(0,26,6,GLOWSTONE)
Block(0,27,-4,GLOWSTONE)
Block(0,27,-3,GLOWSTONE)
Block(0,27,-2,GLOWSTONE)
Block(0,27,0,GLOWSTONE)
Block(0,27,1,GLOWSTONE)
Block(0,27,2,GLOWSTONE)
Block(0,27,3,GLOWSTONE)
Block(0,27,4,GLOWSTONE)
Block(0,27,5,GLOWSTONE)
Block(0,28,-3,GLOWSTONE)
Block(0,28,0,GLOWSTONE)
Block(0,28,1,GLOWSTONE)
Block(0,28,2,GLOWSTONE)
Block(0,28,3,GLOWSTONE)
Block(0,29,1,GLOWSTONE)
Block(1,0,-10,COAL_BLOCK)
Block(1,0,-9,COAL_BLOCK)
Block(1,0,-8,COAL_BLOCK)
Block(1,0,-7,COAL_BLOCK)
Block(1,0,-6,COAL_BLOCK)
Block(1,0,-5,COAL_BLOCK)
Block(1,0,-4,COAL_BLOCK)
Block(1,0,-3,COAL_BLOCK)
Block(1,0,-2,COAL_BLOCK)
Block(1,0,-1,COAL_BLOCK)
Block(1,0,0,COAL_BLOCK)
Block(1,0,1,COAL_BLOCK)
Block(1,0,2,COAL_BLOCK)
Block(1,0,3,COAL_BLOCK)
Block(1,0,4,COAL_BLOCK)
Block(1,1,-9,COAL_BLOCK)
Block(1,1,-8,COAL_BLOCK)
Block(1,1,-7,COAL_BLOCK)
Block(1,1,-6,COAL_BLOCK)
Block(1,1,-5,COAL_BLOCK)
Block(1,1,-4,COAL_BLOCK)
Block(1,1,-3,COAL_BLOCK)
Block(1,1,-2,COAL_BLOCK)
Block(1,1,-1,COAL_BLOCK)
Block(1,1,0,COAL_BLOCK)
Block(1,1,1,COAL_BLOCK)
Block(1,1,2,COAL_BLOCK)
Block(1,2,-8,STONE_BUTTON:5)
Block(1,2,-7,COAL_BLOCK)
Block(1,2,-6,COAL_BLOCK)
Block(1,2,-5,COAL_BLOCK)
Block(1,2,-4,COAL_BLOCK)
Block(1,2,-3,COAL_BLOCK)
Block(1,2,-2,COAL_BLOCK)
Block(1,2,-1,COAL_BLOCK)
Block(1,2,0,COAL_BLOCK)
Block(1,2,1,COAL_BLOCK)
Block(1,2,2,COAL_BLOCK)
Block(1,3,-6,COAL_BLOCK)
Block(1,3,-5,COAL_BLOCK)
Block(1,3,-4,COAL_BLOCK)
Block(1,3,-3,COAL_BLOCK)
Block(1,3,-2,COAL_BLOCK)
Block(1,3,-1,COAL_BLOCK)
Block(1,3,0,COAL_BLOCK)
Block(1,3,2,COAL_BLOCK)
Block(1,4,-6,COAL_BLOCK)
Block(1,4,-5,COAL_BLOCK)
Block(1,4,-4,COAL_BLOCK)
Block(1,4,-3,COAL_BLOCK)
Block(1,4,-2,COAL_BLOCK)
Block(1,4,-1,COAL_BLOCK)
Block(1,4,2,COAL_BLOCK)
Block(1,4,3,COAL_BLOCK)
Block(1,5,-6,COAL_BLOCK)
Block(1,5,-5,COAL_BLOCK)
Block(1,5,-4,COAL_BLOCK)
Block(1,5,-3,COAL_BLOCK)
Block(1,5,-2,COAL_BLOCK)
Block(1,5,-1,COAL_BLOCK)
Block(1,5,2,COAL_BLOCK)
Block(1,6,-6,COAL_BLOCK)
Block(1,6,-5,COAL_BLOCK)
Block(1,6,-4,COAL_BLOCK)
Block(1,6,-3,COAL_BLOCK)
Block(1,6,-2,COAL_BLOCK)
Block(1,6,-1,COAL_BLOCK)
Block(1,6,1,COAL_BLOCK)
Block(1,6,2,COAL_BLOCK)
Block(1,7,-6,COAL_BLOCK)
Block(1,7,-5,COAL_BLOCK)
Block(1,7,-4,COAL_BLOCK)
Block(1,7,-3,COAL_BLOCK)
Block(1,7,-2,COAL_BLOCK)
Block(1,7,-1,COAL_BLOCK)
Block(1,7,0,COAL_BLOCK)
Block(1,7,1,COAL_BLOCK)
Block(1,7,2,COAL_BLOCK)
Block(1,8,-5,COAL_BLOCK)
Block(1,8,-4,COAL_BLOCK)
Block(1,8,-3,COAL_BLOCK)
Block(1,8,-2,COAL_BLOCK)
Block(1,8,-1,COAL_BLOCK)
Block(1,8,0,COAL_BLOCK)
Block(1,8,1,COAL_BLOCK)
Block(1,9,-5,COAL_BLOCK)
Block(1,9,-4,COAL_BLOCK)
Block(1,9,-3,COAL_BLOCK)
Block(1,9,-2,COAL_BLOCK)
Block(1,9,-1,COAL_BLOCK)
Block(1,9,0,COAL_BLOCK)
Block(1,9,1,COAL_BLOCK)
Block(1,10,-10,GLOWSTONE)
Block(1,10,-5,COAL_BLOCK)
Block(1,10,-4,COAL_BLOCK)
Block(1,10,-3,COAL_BLOCK)
Block(1,10,-2,COAL_BLOCK)
Block(1,10,-1,COAL_BLOCK)
Block(1,10,0,COAL_BLOCK)
Block(1,10,1,COAL_BLOCK)
Block(1,11,-10,GLOWSTONE)
Block(1,11,-6,COAL_BLOCK)
Block(1,11,-5,COAL_BLOCK)
Block(1,11,-4,COAL_BLOCK)
Block(1,11,-3,COAL_BLOCK)
Block(1,11,-2,COAL_BLOCK)
Block(1,11,-1,COAL_BLOCK)
Block(1,11,0,COAL_BLOCK)
Block(1,11,1,COAL_BLOCK)
Block(1,12,-11,GLOWSTONE)
Block(1,12,-10,GLOWSTONE)
Block(1,12,-9,GLOWSTONE)
Block(1,12,-7,COAL_BLOCK)
Block(1,12,-6,COAL_BLOCK)
Block(1,12,-5,COAL_BLOCK)
Block(1,12,-4,COAL_BLOCK)
Block(1,12,-3,COAL_BLOCK)
Block(1,12,-2,COAL_BLOCK)
Block(1,12,-1,COAL_BLOCK)
Block(1,12,0,COAL_BLOCK)
Block(1,12,1,COAL_BLOCK)
Block(1,12,2,COAL_BLOCK)
Block(1,13,-11,GLOWSTONE)
Block(1,13,-10,GLOWSTONE)
Block(1,13,-9,GLOWSTONE)
Block(1,13,-8,COAL_BLOCK)
Block(1,13,-7,COAL_BLOCK)
Block(1,13,-6,COAL_BLOCK)
Block(1,13,-5,COAL_BLOCK)
Block(1,13,-4,COAL_BLOCK)
Block(1,13,-3,COAL_BLOCK)
Block(1,13,-2,COAL_BLOCK)
Block(1,13,-1,COAL_BLOCK)
Block(1,13,0,COAL_BLOCK)
Block(1,13,1,COAL_BLOCK)
Block(1,13,2,COAL_BLOCK)
Block(1,14,-12,GLOWSTONE)
Block(1,14,-11,GLOWSTONE)
Block(1,14,-10,GLOWSTONE)
Block(1,14,-8,COAL_BLOCK)
Block(1,14,-7,COAL_BLOCK)
Block(1,14,-6,COAL_BLOCK)
Block(1,14,-5,COAL_BLOCK)
Block(1,14,-4,COAL_BLOCK)
Block(1,14,-2,COBBLESTONE_STAIRS:1)
Block(1,14,1,WOOD_STEP:13)
Block(1,14,2,COAL_BLOCK)
Block(1,15,-11,GLOWSTONE)
Block(1,15,-10,GLOWSTONE)
Block(1,15,-9,COAL_BLOCK)
Block(1,15,-8,COAL_BLOCK)
Block(1,15,-7,COAL_BLOCK)
Block(1,15,-4,COAL_BLOCK)
Block(1,15,1,CARPET:7)
Block(1,15,2,COAL_BLOCK)
Block(1,16,-12,GLOWSTONE)
Block(1,16,-11,GLOWSTONE)
Block(1,16,-10,GLOWSTONE)
Block(1,16,-9,GLOWSTONE)
Block(1,16,-8,COAL_BLOCK)
Block(1,16,-7,GLOWSTONE)
Block(1,16,-3,COAL_BLOCK)
Block(1,16,2,COAL_BLOCK)
Block(1,16,3,COAL_BLOCK)
Block(1,17,-12,GLOWSTONE)
Block(1,17,-11,GLOWSTONE)
Block(1,17,-10,GLOWSTONE)
Block(1,17,-9,GLOWSTONE)
Block(1,17,-8,GLOWSTONE)
Block(1,17,-7,GLOWSTONE)
Block(1,17,-4,COAL_BLOCK)
Block(1,17,-3,COAL_BLOCK)
Block(1,17,-1,WOOD_STEP:13)
Block(1,17,0,WOOD_STEP:13)
Block(1,17,1,WOOD_STEP:13)
Block(1,17,2,COAL_BLOCK)
Block(1,18,-12,GLOWSTONE)
Block(1,18,-11,GLOWSTONE)
Block(1,18,-10,GLOWSTONE)
Block(1,18,-9,GLOWSTONE)
Block(1,18,-8,GLOWSTONE)
Block(1,18,-3,COAL_BLOCK)
Block(1,18,-2,COAL_BLOCK)
Block(1,18,-1,COAL_BLOCK)
Block(1,18,0,COAL_BLOCK)
Block(1,19,-12,GLOWSTONE)
Block(1,19,-11,GLOWSTONE)
Block(1,19,-10,GLOWSTONE)
Block(1,19,-9,GLOWSTONE)
Block(1,19,-8,GLOWSTONE)
Block(1,19,-7,GLOWSTONE)
Block(1,19,-4,GLOWSTONE)
Block(1,19,-3,COAL_BLOCK)
Block(1,19,-2,COAL_BLOCK)
Block(1,19,-1,COAL_BLOCK)
Block(1,19,0,COAL_BLOCK)
Block(1,20,-9,GLOWSTONE)
Block(1,20,-8,GLOWSTONE)
Block(1,20,-7,GLOWSTONE)
Block(1,20,-6,GLOWSTONE)
Block(1,20,-5,GLOWSTONE)
Block(1,20,-4,COAL_BLOCK)
Block(1,20,-3,COAL_BLOCK)
Block(1,20,-2,COAL_BLOCK)
Block(1,20,-1,COAL_BLOCK)
Block(1,20,0,COAL_BLOCK)
Block(1,21,-9,GLOWSTONE)
Block(1,21,-8,GLOWSTONE)
Block(1,21,-7,GLOWSTONE)
Block(1,21,-6,GLOWSTONE)
Block(1,21,-5,COAL_BLOCK)
Block(1,21,-4,COAL_BLOCK)
Block(1,21,-3,COAL_BLOCK)
Block(1,21,-2,GLOWSTONE)
Block(1,21,8,GLOWSTONE)
Block(1,22,-10,GLOWSTONE)
Block(1,22,-9,GLOWSTONE)
Block(1,22,-8,GLOWSTONE)
Block(1,22,-7,GLOWSTONE)
Block(1,22,-6,GLOWSTONE)
Block(1,22,-5,COAL_BLOCK)
Block(1,22,-4,COAL_BLOCK)
Block(1,22,-3,COAL_BLOCK)
Block(1,22,-1,GLOWSTONE)
Block(1,22,0,GLOWSTONE)
Block(1,22,1,GLOWSTONE)
Block(1,22,7,GLOWSTONE)
Block(1,22,8,GLOWSTONE)
Block(1,22,9,GLOWSTONE)
Block(1,23,-9,GLOWSTONE)
Block(1,23,-8,GLOWSTONE)
Block(1,23,-7,GLOWSTONE)
Block(1,23,-6,GLOWSTONE)
Block(1,23,-5,COAL_BLOCK)
Block(1,23,-4,COAL_BLOCK)
Block(1,23,-3,COAL_BLOCK)
Block(1,23,-2,GLOWSTONE)
Block(1,23,-1,GLOWSTONE)
Block(1,23,0,GLOWSTONE)
Block(1,23,1,GLOWSTONE)
Block(1,23,2,GLOWSTONE)
Block(1,23,5,GLOWSTONE)
Block(1,23,6,GLOWSTONE)
Block(1,23,7,GLOWSTONE)
Block(1,23,8,GLOWSTONE)
Block(1,23,9,GLOWSTONE)
Block(1,24,-8,GLOWSTONE)
Block(1,24,-6,GLOWSTONE)
Block(1,24,-5,GLOWSTONE)
Block(1,24,-4,GLOWSTONE)
Block(1,24,-3,GLOWSTONE)
Block(1,24,-1,GLOWSTONE)
Block(1,24,0,GLOWSTONE)
Block(1,24,1,GLOWSTONE)
Block(1,24,2,GLOWSTONE)
Block(1,24,4,GLOWSTONE)
Block(1,24,5,GLOWSTONE)
Block(1,24,6,GLOWSTONE)
Block(1,24,7,GLOWSTONE)
Block(1,24,8,GLOWSTONE)
Block(1,24,9,GLOWSTONE)
Block(1,25,-7,GLOWSTONE)
Block(1,25,-6,GLOWSTONE)
Block(1,25,-5,GLOWSTONE)
Block(1,25,-4,GLOWSTONE)
Block(1,25,-3,GLOWSTONE)
Block(1,25,-2,GLOWSTONE)
Block(1,25,-1,GLOWSTONE)
Block(1,25,0,GLOWSTONE)
Block(1,25,1,GLOWSTONE)
Block(1,25,2,GLOWSTONE)
Block(1,25,3,GLOWSTONE)
Block(1,25,4,GLOWSTONE)
Block(1,25,5,GLOWSTONE)
Block(1,25,6,GLOWSTONE)
Block(1,25,7,GLOWSTONE)
Block(1,26,-6,GLOWSTONE)
Block(1,26,-4,GLOWSTONE)
Block(1,26,-2,GLOWSTONE)
Block(1,26,-1,GLOWSTONE)
Block(1,26,0,GLOWSTONE)
Block(1,26,1,GLOWSTONE)
Block(1,26,2,GLOWSTONE)
Block(1,26,3,GLOWSTONE)
Block(1,26,4,GLOWSTONE)
Block(1,26,5,GLOWSTONE)
Block(1,26,6,GLOWSTONE)
Block(1,27,-3,GLOWSTONE)
Block(1,27,-2,GLOWSTONE)
Block(1,27,-1,GLOWSTONE)
Block(1,27,0,GLOWSTONE)
Block(1,27,1,GLOWSTONE)
Block(1,27,2,GLOWSTONE)
Block(1,27,3,GLOWSTONE)
Block(1,28,-2,GLOWSTONE)
Block(1,28,0,GLOWSTONE)
Block(1,28,1,GLOWSTONE)
Block(1,28,2,GLOWSTONE)
Block(2,0,-9,COAL_BLOCK)
Block(2,0,-8,COAL_BLOCK)
Block(2,0,-7,COAL_BLOCK)
Block(2,0,-5,COAL_BLOCK)
Block(2,0,-4,COAL_BLOCK)
Block(2,0,-3,COAL_BLOCK)
Block(2,0,-2,COAL_BLOCK)
Block(2,0,-1,COAL_BLOCK)
Block(2,0,0,COAL_BLOCK)
Block(2,0,1,COAL_BLOCK)
Block(2,0,2,COAL_BLOCK)
Block(2,1,-6,COAL_BLOCK)
Block(2,1,-5,COAL_BLOCK)
Block(2,1,-4,COAL_BLOCK)
Block(2,1,-3,COAL_BLOCK)
Block(2,1,-2,COAL_BLOCK)
Block(2,1,-1,COAL_BLOCK)
Block(2,1,0,COAL_BLOCK)
Block(2,1,1,COAL_BLOCK)
Block(2,1,2,COAL_BLOCK)
Block(2,1,3,COAL_BLOCK)
Block(2,2,-6,COAL_BLOCK)
Block(2,2,-5,COAL_BLOCK)
Block(2,2,-4,COAL_BLOCK)
Block(2,2,-3,COAL_BLOCK)
Block(2,2,-2,COAL_BLOCK)
Block(2,2,-1,COAL_BLOCK)
Block(2,2,0,COAL_BLOCK)
Block(2,2,1,COAL_BLOCK)
Block(2,2,2,COAL_BLOCK)
Block(2,3,-6,COAL_BLOCK)
Block(2,3,-5,COAL_BLOCK)
Block(2,3,-4,COAL_BLOCK)
Block(2,3,-3,COAL_BLOCK)
Block(2,3,-2,COAL_BLOCK)
Block(2,3,-1,COAL_BLOCK)
Block(2,3,0,COAL_BLOCK)
Block(2,3,1,COAL_BLOCK)
Block(2,3,2,COAL_BLOCK)
Block(2,3,3,COAL_BLOCK)
Block(2,4,-5,COAL_BLOCK)
Block(2,4,-4,COAL_BLOCK)
Block(2,4,-3,COAL_BLOCK)
Block(2,4,-2,COAL_BLOCK)
Block(2,4,-1,COAL_BLOCK)
Block(2,4,0,COAL_BLOCK)
Block(2,4,1,COAL_BLOCK)
Block(2,4,2,COAL_BLOCK)
Block(2,4,3,COAL_BLOCK)
Block(2,5,-5,COAL_BLOCK)
Block(2,5,-4,COAL_BLOCK)
Block(2,5,-3,COAL_BLOCK)
Block(2,5,-2,COAL_BLOCK)
Block(2,5,-1,COAL_BLOCK)
Block(2,5,0,COAL_BLOCK)
Block(2,5,1,COAL_BLOCK)
Block(2,5,2,COAL_BLOCK)
Block(2,5,3,COAL_BLOCK)
Block(2,6,-5,COAL_BLOCK)
Block(2,6,-4,COAL_BLOCK)
Block(2,6,-3,COAL_BLOCK)
Block(2,6,-2,COAL_BLOCK)
Block(2,6,-1,COAL_BLOCK)
Block(2,6,0,COAL_BLOCK)
Block(2,6,1,COAL_BLOCK)
Block(2,6,2,COAL_BLOCK)
Block(2,7,-5,COAL_BLOCK)
Block(2,7,-4,COAL_BLOCK)
Block(2,7,-3,COAL_BLOCK)
Block(2,7,-2,COAL_BLOCK)
Block(2,7,-1,COAL_BLOCK)
Block(2,7,0,COAL_BLOCK)
Block(2,7,1,COAL_BLOCK)
Block(2,8,-10,GLOWSTONE)
Block(2,8,-5,COAL_BLOCK)
Block(2,8,-4,COAL_BLOCK)
Block(2,8,-3,COAL_BLOCK)
Block(2,8,-2,COAL_BLOCK)
Block(2,8,-1,COAL_BLOCK)
Block(2,8,0,COAL_BLOCK)
Block(2,8,1,COAL_BLOCK)
Block(2,9,-10,GLOWSTONE)
Block(2,9,-4,COAL_BLOCK)
Block(2,9,-3,COAL_BLOCK)
Block(2,9,-2,COAL_BLOCK)
Block(2,9,-1,COAL_BLOCK)
Block(2,9,0,COAL_BLOCK)
Block(2,10,-11,GLOWSTONE)
Block(2,10,-10,GLOWSTONE)
Block(2,10,-2,COAL_BLOCK)
Block(2,10,-1,COAL_BLOCK)
Block(2,10,0,COAL_BLOCK)
Block(2,11,-11,GLOWSTONE)
Block(2,11,-10,GLOWSTONE)
Block(2,11,-9,GLOWSTONE)
Block(2,11,-5,COAL_BLOCK)
Block(2,11,-3,COAL_BLOCK)
Block(2,11,-2,COAL_BLOCK)
Block(2,11,-1,COAL_BLOCK)
Block(2,11,0,COAL_BLOCK)
Block(2,11,1,COAL_BLOCK)
Block(2,12,-11,GLOWSTONE)
Block(2,12,-10,GLOWSTONE)
Block(2,12,-9,GLOWSTONE)
Block(2,12,-8,COAL_BLOCK)
Block(2,12,-7,COAL_BLOCK)
Block(2,12,-6,COAL_BLOCK)
Block(2,12,-5,COAL_BLOCK)
Block(2,12,-4,COAL_BLOCK)
Block(2,12,-3,COAL_BLOCK)
Block(2,12,-2,COAL_BLOCK)
Block(2,12,-1,COAL_BLOCK)
Block(2,12,0,COAL_BLOCK)
Block(2,12,1,COAL_BLOCK)
Block(2,13,-12,GLOWSTONE)
Block(2,13,-11,GLOWSTONE)
Block(2,13,-10,GLOWSTONE)
Block(2,13,-9,GLOWSTONE)
Block(2,13,-8,COAL_BLOCK)
Block(2,13,-7,COAL_BLOCK)
Block(2,13,-6,COAL_BLOCK)
Block(2,13,-5,COAL_BLOCK)
Block(2,13,-3,COAL_BLOCK)
Block(2,13,-2,COAL_BLOCK)
Block(2,13,-1,COAL_BLOCK)
Block(2,13,0,COAL_BLOCK)
Block(2,13,1,COAL_BLOCK)
Block(2,13,2,COAL_BLOCK)
Block(2,14,-12,GLOWSTONE)
Block(2,14,-11,GLOWSTONE)
Block(2,14,-10,GLOWSTONE)
Block(2,14,-9,COAL_BLOCK)
Block(2,14,-8,COAL_BLOCK)
Block(2,14,-7,COAL_BLOCK)
Block(2,14,-6,COAL_BLOCK)
Block(2,14,-3,COAL_BLOCK)
Block(2,14,-2,PISTON_BASE:1)
Block(2,14,-1,COBBLESTONE_STAIRS:2)
Block(2,14,1,WOOD_STEP:13)
Block(2,14,2,COAL_BLOCK)
Block(2,15,-12,GLOWSTONE)
Block(2,15,-11,GLOWSTONE)
Block(2,15,-10,GLOWSTONE)
Block(2,15,-9,COAL_BLOCK)
Block(2,15,-8,COAL_BLOCK)
Block(2,15,-7,COAL_BLOCK)
Block(2,15,-6,COAL_BLOCK)
Block(2,15,-3,COAL_BLOCK)
Block(2,15,-2,FLOWER_POT,NetherGricelTree/7-flower_pot.nbt)
Block(2,15,1,NETHER_FENCE)
Block(2,15,2,COAL_BLOCK)
Block(2,15,3,COAL_BLOCK)
Block(2,16,-12,GLOWSTONE)
Block(2,16,-11,GLOWSTONE)
Block(2,16,-10,GLOWSTONE)
Block(2,16,-9,COAL_BLOCK)
Block(2,16,-8,COAL_BLOCK)
Block(2,16,-7,COAL_BLOCK)
Block(2,16,-3,COAL_BLOCK)
Block(2,16,-1,WALL_SIGN:4,NetherGricelTree/8-sign.nbt)
Block(2,16,1,COAL_BLOCK)
Block(2,16,2,COAL_BLOCK)
Block(2,16,3,COAL_BLOCK)
Block(2,16,4,COAL_BLOCK)
Block(2,17,-12,GLOWSTONE)
Block(2,17,-11,GLOWSTONE)
Block(2,17,-10,GLOWSTONE)
Block(2,17,-9,GLOWSTONE)
Block(2,17,-8,GLOWSTONE)
Block(2,17,-3,COAL_BLOCK)
Block(2,17,-2,COAL_BLOCK)
Block(2,17,0,WOOD_STEP:13)
Block(2,17,1,COAL_BLOCK)
Block(2,17,2,COAL_BLOCK)
Block(2,17,3,COAL_BLOCK)
Block(2,17,4,COAL_BLOCK)
Block(2,17,5,COAL_BLOCK)
Block(2,18,-12,GLOWSTONE)
Block(2,18,-11,GLOWSTONE)
Block(2,18,-10,GLOWSTONE)
Block(2,18,-9,GLOWSTONE)
Block(2,18,-8,GLOWSTONE)
Block(2,18,-7,GLOWSTONE)
Block(2,18,-4,GLOWSTONE)
Block(2,18,-3,COAL_BLOCK)
Block(2,18,-2,COAL_BLOCK)
Block(2,18,-1,COAL_BLOCK)
Block(2,18,0,COAL_BLOCK)
Block(2,18,1,COAL_BLOCK)
Block(2,18,4,COAL_BLOCK)
Block(2,19,-11,GLOWSTONE)
Block(2,19,-9,GLOWSTONE)
Block(2,19,-8,GLOWSTONE)
Block(2,19,-7,GLOWSTONE)
Block(2,19,-6,GLOWSTONE)
Block(2,19,-4,GLOWSTONE)
Block(2,19,-3,GLOWSTONE)
Block(2,19,-2,GLOWSTONE)
Block(2,19,-1,GLOWSTONE)
Block(2,20,-9,GLOWSTONE)
Block(2,20,-8,GLOWSTONE)
Block(2,20,-7,GLOWSTONE)
Block(2,20,-6,GLOWSTONE)
Block(2,20,-5,GLOWSTONE)
Block(2,20,-4,GLOWSTONE)
Block(2,20,-3,GLOWSTONE)
Block(2,20,-2,GLOWSTONE)
Block(2,21,-8,GLOWSTONE)
Block(2,21,-7,GLOWSTONE)
Block(2,21,-6,GLOWSTONE)
Block(2,21,-5,GLOWSTONE)
Block(2,21,-4,COAL_BLOCK)
Block(2,21,-3,GLOWSTONE)
Block(2,21,-2,GLOWSTONE)
Block(2,21,7,GLOWSTONE)
Block(2,22,-8,GLOWSTONE)
Block(2,22,-7,GLOWSTONE)
Block(2,22,-6,GLOWSTONE)
Block(2,22,-5,COAL_BLOCK)
Block(2,22,-4,COAL_BLOCK)
Block(2,22,-3,COAL_BLOCK)
Block(2,22,0,GLOWSTONE)
Block(2,22,1,GLOWSTONE)
Block(2,22,2,GLOWSTONE)
Block(2,22,6,GLOWSTONE)
Block(2,22,7,GLOWSTONE)
Block(2,22,8,GLOWSTONE)
Block(2,23,-7,GLOWSTONE)
Block(2,23,-6,GLOWSTONE)
Block(2,23,-5,GLOWSTONE)
Block(2,23,-4,COAL_BLOCK)
Block(2,23,-1,GLOWSTONE)
Block(2,23,0,GLOWSTONE)
Block(2,23,1,GLOWSTONE)
Block(2,23,2,GLOWSTONE)
Block(2,23,3,GLOWSTONE)
Block(2,23,4,GLOWSTONE)
Block(2,23,5,GLOWSTONE)
Block(2,23,6,GLOWSTONE)
Block(2,23,7,GLOWSTONE)
Block(2,23,8,GLOWSTONE)
Block(2,23,9,GLOWSTONE)
Block(2,24,-7,GLOWSTONE)
Block(2,24,-6,GLOWSTONE)
Block(2,24,-5,GLOWSTONE)
Block(2,24,-4,GLOWSTONE)
Block(2,24,-3,GLOWSTONE)
Block(2,24,-2,GLOWSTONE)
Block(2,24,-1,GLOWSTONE)
Block(2,24,0,GLOWSTONE)
Block(2,24,1,GLOWSTONE)
Block(2,24,2,GLOWSTONE)
Block(2,24,3,GLOWSTONE)
Block(2,24,4,GLOWSTONE)
Block(2,24,5,GLOWSTONE)
Block(2,24,6,GLOWSTONE)
Block(2,24,7,GLOWSTONE)
Block(2,24,8,GLOWSTONE)
Block(2,25,-7,GLOWSTONE)
Block(2,25,-6,GLOWSTONE)
Block(2,25,-5,GLOWSTONE)
Block(2,25,-4,GLOWSTONE)
Block(2,25,-3,GLOWSTONE)
Block(2,25,-2,GLOWSTONE)
Block(2,25,-1,GLOWSTONE)
Block(2,25,0,GLOWSTONE)
Block(2,25,1,GLOWSTONE)
Block(2,25,3,GLOWSTONE)
Block(2,25,4,GLOWSTONE)
Block(2,25,5,GLOWSTONE)
Block(2,25,6,GLOWSTONE)
Block(2,25,7,GLOWSTONE)
Block(2,25,8,GLOWSTONE)
Block(2,25,9,GLOWSTONE)
Block(2,26,-7,GLOWSTONE)
Block(2,26,-6,GLOWSTONE)
Block(2,26,-5,GLOWSTONE)
Block(2,26,-4,GLOWSTONE)
Block(2,26,-3,GLOWSTONE)
Block(2,26,-2,GLOWSTONE)
Block(2,26,-1,GLOWSTONE)
Block(2,26,0,GLOWSTONE)
Block(2,26,1,GLOWSTONE)
Block(2,26,2,GLOWSTONE)
Block(2,26,3,GLOWSTONE)
Block(2,26,4,GLOWSTONE)
Block(2,26,5,GLOWSTONE)
Block(2,26,7,GLOWSTONE)
Block(2,26,8,GLOWSTONE)
Block(2,27,-4,GLOWSTONE)
Block(2,27,-3,GLOWSTONE)
Block(2,27,-2,GLOWSTONE)
Block(2,27,-1,GLOWSTONE)
Block(2,27,0,GLOWSTONE)
Block(2,27,1,GLOWSTONE)
Block(2,27,2,GLOWSTONE)
Block(2,28,-3,GLOWSTONE)
Block(2,28,-2,GLOWSTONE)
Block(2,28,-1,GLOWSTONE)
Block(2,28,1,GLOWSTONE)
Block(3,0,-4,COAL_BLOCK)
Block(3,0,-3,COAL_BLOCK)
Block(3,0,-2,COAL_BLOCK)
Block(3,0,-1,COAL_BLOCK)
Block(3,0,0,COAL_BLOCK)
Block(3,0,1,COAL_BLOCK)
Block(3,0,2,COAL_BLOCK)
Block(3,0,3,COAL_BLOCK)
Block(3,1,-4,COAL_BLOCK)
Block(3,1,-3,COAL_BLOCK)
Block(3,1,-2,COAL_BLOCK)
Block(3,1,-1,COAL_BLOCK)
Block(3,1,0,MOB_SPAWNER,NetherGricelTree/9-mob_spawner.nbt)
Block(3,1,1,COAL_BLOCK)
Block(3,1,2,COAL_BLOCK)
Block(3,1,3,COAL_BLOCK)
Block(3,1,4,COAL_BLOCK)
Block(3,2,-5,COAL_BLOCK)
Block(3,2,-4,COAL_BLOCK)
Block(3,2,-3,COAL_BLOCK)
Block(3,2,-2,COAL_BLOCK)
Block(3,2,-1,COAL_BLOCK)
Block(3,2,0,COAL_BLOCK)
Block(3,2,1,COAL_BLOCK)
Block(3,2,2,COAL_BLOCK)
Block(3,2,3,COAL_BLOCK)
Block(3,3,-4,COAL_BLOCK)
Block(3,3,-3,COAL_BLOCK)
Block(3,3,-2,COAL_BLOCK)
Block(3,3,-1,COAL_BLOCK)
Block(3,3,0,COAL_BLOCK)
Block(3,3,1,COAL_BLOCK)
Block(3,3,2,COAL_BLOCK)
Block(3,3,3,COAL_BLOCK)
Block(3,4,-4,COAL_BLOCK)
Block(3,4,-3,COAL_BLOCK)
Block(3,4,-2,COAL_BLOCK)
Block(3,4,-1,COAL_BLOCK)
Block(3,4,0,COAL_BLOCK)
Block(3,4,1,COAL_BLOCK)
Block(3,4,2,COAL_BLOCK)
Block(3,4,3,COAL_BLOCK)
Block(3,5,-4,COAL_BLOCK)
Block(3,5,-3,COAL_BLOCK)
Block(3,5,-2,COAL_BLOCK)
Block(3,5,-1,COAL_BLOCK)
Block(3,5,0,COAL_BLOCK)
Block(3,5,1,COAL_BLOCK)
Block(3,5,2,COAL_BLOCK)
Block(3,6,-4,COAL_BLOCK)
Block(3,6,-3,COAL_BLOCK)
Block(3,6,-2,COAL_BLOCK)
Block(3,6,-1,COAL_BLOCK)
Block(3,6,0,COAL_BLOCK)
Block(3,6,1,COAL_BLOCK)
Block(3,7,-4,COAL_BLOCK)
Block(3,7,-3,COAL_BLOCK)
Block(3,7,-2,COAL_BLOCK)
Block(3,7,-1,COAL_BLOCK)
Block(3,7,0,COAL_BLOCK)
Block(3,7,1,COAL_BLOCK)
Block(3,8,-4,COAL_BLOCK)
Block(3,8,-3,COAL_BLOCK)
Block(3,8,-2,COAL_BLOCK)
Block(3,8,-1,COAL_BLOCK)
Block(3,8,0,COAL_BLOCK)
Block(3,9,-10,GLOWSTONE)
Block(3,9,-3,COAL_BLOCK)
Block(3,9,-2,COAL_BLOCK)
Block(3,9,-1,COAL_BLOCK)
Block(3,10,-10,GLOWSTONE)
Block(3,11,-10,GLOWSTONE)
Block(3,12,-11,GLOWSTONE)
Block(3,12,-10,GLOWSTONE)
Block(3,12,-9,GLOWSTONE)
Block(3,12,-7,COAL_BLOCK)
Block(3,12,-2,COAL_BLOCK)
Block(3,12,-1,COAL_BLOCK)
Block(3,12,0,COAL_BLOCK)
Block(3,13,-11,GLOWSTONE)
Block(3,13,-10,GLOWSTONE)
Block(3,13,-9,GLOWSTONE)
Block(3,13,-8,COAL_BLOCK)
Block(3,13,-7,COAL_BLOCK)
Block(3,13,-6,COAL_BLOCK)
Block(3,13,-2,COAL_BLOCK)
Block(3,13,-1,COAL_BLOCK)
Block(3,13,0,COAL_BLOCK)
Block(3,13,1,COAL_BLOCK)
Block(3,14,-12,GLOWSTONE)
Block(3,14,-11,GLOWSTONE)
Block(3,14,-10,GLOWSTONE)
Block(3,14,-8,COAL_BLOCK)
Block(3,14,-7,COAL_BLOCK)
Block(3,14,-6,COAL_BLOCK)
Block(3,14,-2,COAL_BLOCK)
Block(3,14,-1,COAL_BLOCK)
Block(3,14,0,COAL_BLOCK)
Block(3,14,1,COAL_BLOCK)
Block(3,14,2,COAL_BLOCK)
Block(3,15,-11,GLOWSTONE)
Block(3,15,-10,GLOWSTONE)
Block(3,15,-9,COAL_BLOCK)
Block(3,15,-8,COAL_BLOCK)
Block(3,15,-7,COAL_BLOCK)
Block(3,15,-4,GLOWSTONE)
Block(3,15,-2,COAL_BLOCK)
Block(3,15,-1,COAL_BLOCK)
Block(3,15,1,COAL_BLOCK)
Block(3,15,2,COAL_BLOCK)
Block(3,15,3,COAL_BLOCK)
Block(3,15,4,COAL_BLOCK)
Block(3,16,-12,GLOWSTONE)
Block(3,16,-11,GLOWSTONE)
Block(3,16,-10,GLOWSTONE)
Block(3,16,-9,GLOWSTONE)
Block(3,16,-8,COAL_BLOCK)
Block(3,16,-4,GLOWSTONE)
Block(3,16,-2,COAL_BLOCK)
Block(3,16,-1,COAL_BLOCK)
Block(3,16,0,COAL_BLOCK)
Block(3,16,1,COAL_BLOCK)
Block(3,16,2,COAL_BLOCK)
Block(3,16,3,COAL_BLOCK)
Block(3,16,4,COAL_BLOCK)
Block(3,16,5,COAL_BLOCK)
Block(3,17,-12,GLOWSTONE)
Block(3,17,-11,GLOWSTONE)
Block(3,17,-10,GLOWSTONE)
Block(3,17,-9,GLOWSTONE)
Block(3,17,-8,GLOWSTONE)
Block(3,17,-4,GLOWSTONE)
Block(3,17,-3,GLOWSTONE)
Block(3,17,-2,COAL_BLOCK)
Block(3,17,-1,COAL_BLOCK)
Block(3,17,0,COAL_BLOCK)
Block(3,17,1,COAL_BLOCK)
Block(3,17,2,COAL_BLOCK)
Block(3,17,3,COAL_BLOCK)
Block(3,17,4,COAL_BLOCK)
Block(3,17,5,COAL_BLOCK)
Block(3,17,6,COAL_BLOCK)
Block(3,17,10,GLOWSTONE)
Block(3,18,-12,GLOWSTONE)
Block(3,18,-11,GLOWSTONE)
Block(3,18,-10,GLOWSTONE)
Block(3,18,-9,GLOWSTONE)
Block(3,18,-8,GLOWSTONE)
Block(3,18,-4,GLOWSTONE)
Block(3,18,-3,GLOWSTONE)
Block(3,18,-2,GLOWSTONE)
Block(3,18,3,COAL_BLOCK)
Block(3,18,4,COAL_BLOCK)
Block(3,18,5,COAL_BLOCK)
Block(3,18,10,GLOWSTONE)
Block(3,19,-9,GLOWSTONE)
Block(3,19,-8,GLOWSTONE)
Block(3,19,-7,GLOWSTONE)
Block(3,19,-4,GLOWSTONE)
Block(3,19,-3,GLOWSTONE)
Block(3,19,-2,GLOWSTONE)
Block(3,19,9,GLOWSTONE)
Block(3,20,-8,GLOWSTONE)
Block(3,20,-7,GLOWSTONE)
Block(3,20,-6,GLOWSTONE)
Block(3,20,-4,GLOWSTONE)
Block(3,20,-3,GLOWSTONE)
Block(3,20,-2,GLOWSTONE)
Block(3,20,0,GLOWSTONE)
Block(3,20,8,GLOWSTONE)
Block(3,20,9,GLOWSTONE)
Block(3,20,10,GLOWSTONE)
Block(3,21,-7,GLOWSTONE)
Block(3,21,-4,GLOWSTONE)
Block(3,21,-3,GLOWSTONE)
Block(3,21,-2,GLOWSTONE)
Block(3,21,-1,GLOWSTONE)
Block(3,21,0,GLOWSTONE)
Block(3,21,1,GLOWSTONE)
Block(3,21,3,GLOWSTONE)
Block(3,21,6,GLOWSTONE)
Block(3,21,7,GLOWSTONE)
Block(3,21,8,GLOWSTONE)
Block(3,21,9,GLOWSTONE)
Block(3,21,10,GLOWSTONE)
Block(3,22,-6,GLOWSTONE)
Block(3,22,-5,GLOWSTONE)
Block(3,22,-4,GLOWSTONE)
Block(3,22,-3,GLOWSTONE)
Block(3,22,-2,GLOWSTONE)
Block(3,22,-1,GLOWSTONE)
Block(3,22,0,GLOWSTONE)
Block(3,22,1,GLOWSTONE)
Block(3,22,2,GLOWSTONE)
Block(3,22,3,GLOWSTONE)
Block(3,22,4,GLOWSTONE)
Block(3,22,6,GLOWSTONE)
Block(3,22,7,GLOWSTONE)
Block(3,22,8,GLOWSTONE)
Block(3,22,9,GLOWSTONE)
Block(3,22,10,GLOWSTONE)
Block(3,22,11,GLOWSTONE)
Block(3,23,-7,GLOWSTONE)
Block(3,23,-6,GLOWSTONE)
Block(3,23,-5,GLOWSTONE)
Block(3,23,-4,GLOWSTONE)
Block(3,23,-3,GLOWSTONE)
Block(3,23,-1,GLOWSTONE)
Block(3,23,0,GLOWSTONE)
Block(3,23,1,GLOWSTONE)
Block(3,23,2,GLOWSTONE)
Block(3,23,3,GLOWSTONE)
Block(3,23,4,GLOWSTONE)
Block(3,23,5,GLOWSTONE)
Block(3,23,6,GLOWSTONE)
Block(3,23,7,GLOWSTONE)
Block(3,23,8,GLOWSTONE)
Block(3,23,9,GLOWSTONE)
Block(3,23,10,GLOWSTONE)
Block(3,24,-6,GLOWSTONE)
Block(3,24,-5,GLOWSTONE)
Block(3,24,-4,GLOWSTONE)
Block(3,24,-3,GLOWSTONE)
Block(3,24,-2,GLOWSTONE)
Block(3,24,-1,GLOWSTONE)
Block(3,24,0,GLOWSTONE)
Block(3,24,1,GLOWSTONE)
Block(3,24,2,GLOWSTONE)
Block(3,24,3,GLOWSTONE)
Block(3,24,4,GLOWSTONE)
Block(3,24,5,GLOWSTONE)
Block(3,24,6,GLOWSTONE)
Block(3,24,7,GLOWSTONE)
Block(3,24,8,GLOWSTONE)
Block(3,24,9,GLOWSTONE)
Block(3,25,-7,GLOWSTONE)
Block(3,25,-6,GLOWSTONE)
Block(3,25,-5,GLOWSTONE)
Block(3,25,-4,GLOWSTONE)
Block(3,25,-3,GLOWSTONE)
Block(3,25,-2,GLOWSTONE)
Block(3,25,-1,GLOWSTONE)
Block(3,25,0,GLOWSTONE)
Block(3,25,1,GLOWSTONE)
Block(3,25,2,GLOWSTONE)
Block(3,25,3,GLOWSTONE)
Block(3,25,4,GLOWSTONE)
Block(3,25,5,GLOWSTONE)
Block(3,25,6,GLOWSTONE)
Block(3,25,7,GLOWSTONE)
Block(3,25,8,GLOWSTONE)
Block(3,25,9,GLOWSTONE)
Block(3,26,-6,GLOWSTONE)
Block(3,26,-5,GLOWSTONE)
Block(3,26,-4,GLOWSTONE)
Block(3,26,-3,GLOWSTONE)
Block(3,26,-2,GLOWSTONE)
Block(3,26,-1,GLOWSTONE)
Block(3,26,0,GLOWSTONE)
Block(3,26,1,GLOWSTONE)
Block(3,26,2,GLOWSTONE)
Block(3,26,3,GLOWSTONE)
Block(3,26,4,GLOWSTONE)
Block(3,26,6,GLOWSTONE)
Block(3,26,7,GLOWSTONE)
Block(3,26,8,GLOWSTONE)
Block(3,26,9,GLOWSTONE)
Block(3,27,-4,GLOWSTONE)
Block(3,27,-3,GLOWSTONE)
Block(3,27,-2,GLOWSTONE)
Block(3,27,-1,GLOWSTONE)
Block(3,27,0,GLOWSTONE)
Block(3,27,1,GLOWSTONE)
Block(3,27,2,GLOWSTONE)
Block(3,28,-4,GLOWSTONE)
Block(3,28,-3,GLOWSTONE)
Block(3,28,-2,GLOWSTONE)
Block(4,0,-4,COAL_BLOCK)
Block(4,0,-3,COAL_BLOCK)
Block(4,0,-2,COAL_BLOCK)
Block(4,0,-1,COAL_BLOCK)
Block(4,0,0,COAL_BLOCK)
Block(4,0,1,COAL_BLOCK)
Block(4,0,2,COAL_BLOCK)
Block(4,0,3,COAL_BLOCK)
Block(4,0,4,COAL_BLOCK)
Block(4,1,-3,COAL_BLOCK)
Block(4,1,-2,COAL_BLOCK)
Block(4,1,-1,COAL_BLOCK)
Block(4,1,1,COAL_BLOCK)
Block(4,1,2,COAL_BLOCK)
Block(4,1,3,COAL_BLOCK)
Block(4,1,4,COAL_BLOCK)
Block(4,2,-3,COAL_BLOCK)
Block(4,2,-2,COAL_BLOCK)
Block(4,2,-1,COAL_BLOCK)
Block(4,2,2,COAL_BLOCK)
Block(4,2,3,COAL_BLOCK)
Block(4,2,4,COAL_BLOCK)
Block(4,3,1,COAL_BLOCK)
Block(4,3,2,COAL_BLOCK)
Block(4,3,3,COAL_BLOCK)
Block(4,4,-2,COAL_BLOCK)
Block(4,4,2,COAL_BLOCK)
Block(4,5,-3,COAL_BLOCK)
Block(4,5,-2,COAL_BLOCK)
Block(4,5,-1,COAL_BLOCK)
Block(4,6,-3,COAL_BLOCK)
Block(4,6,-2,COAL_BLOCK)
Block(4,6,-1,COAL_BLOCK)
Block(4,6,0,COAL_BLOCK)
Block(4,7,-3,COAL_BLOCK)
Block(4,7,-2,COAL_BLOCK)
Block(4,7,-1,COAL_BLOCK)
Block(4,8,-2,COAL_BLOCK)
Block(4,13,-10,GLOWSTONE)
Block(4,14,-10,GLOWSTONE)
Block(4,14,-3,GLOWSTONE)
Block(4,14,1,COAL_BLOCK)
Block(4,15,-11,GLOWSTONE)
Block(4,15,-10,GLOWSTONE)
Block(4,15,-9,GLOWSTONE)
Block(4,15,-3,GLOWSTONE)
Block(4,15,0,COAL_BLOCK)
Block(4,15,1,COAL_BLOCK)
Block(4,15,2,COAL_BLOCK)
Block(4,15,3,COAL_BLOCK)
Block(4,15,4,COAL_BLOCK)
Block(4,15,9,GLOWSTONE)
Block(4,16,-11,GLOWSTONE)
Block(4,16,-10,GLOWSTONE)
Block(4,16,-9,GLOWSTONE)
Block(4,16,-8,GLOWSTONE)
Block(4,16,-3,GLOWSTONE)
Block(4,16,1,COAL_BLOCK)
Block(4,16,2,COAL_BLOCK)
Block(4,16,3,COAL_BLOCK)
Block(4,16,4,COAL_BLOCK)
Block(4,16,5,COAL_BLOCK)
Block(4,16,6,COAL_BLOCK)
Block(4,16,9,GLOWSTONE)
Block(4,17,-12,GLOWSTONE)
Block(4,17,-11,GLOWSTONE)
Block(4,17,-10,GLOWSTONE)
Block(4,17,-9,GLOWSTONE)
Block(4,17,-3,GLOWSTONE)
Block(4,17,1,GLOWSTONE)
Block(4,17,2,COAL_BLOCK)
Block(4,17,3,COAL_BLOCK)
Block(4,17,4,COAL_BLOCK)
Block(4,17,5,COAL_BLOCK)
Block(4,17,6,COAL_BLOCK)
Block(4,17,7,COAL_BLOCK)
Block(4,17,9,GLOWSTONE)
Block(4,18,-11,GLOWSTONE)
Block(4,18,-10,GLOWSTONE)
Block(4,18,-3,GLOWSTONE)
Block(4,18,-2,GLOWSTONE)
Block(4,18,2,GLOWSTONE)
Block(4,18,4,COAL_BLOCK)
Block(4,18,5,COAL_BLOCK)
Block(4,18,6,COAL_BLOCK)
Block(4,18,7,COAL_BLOCK)
Block(4,18,9,GLOWSTONE)
Block(4,18,10,GLOWSTONE)
Block(4,19,-4,GLOWSTONE)
Block(4,19,-3,GLOWSTONE)
Block(4,19,-2,GLOWSTONE)
Block(4,19,0,GLOWSTONE)
Block(4,19,6,COAL_BLOCK)
Block(4,19,7,COAL_BLOCK)
Block(4,19,8,COAL_BLOCK)
Block(4,19,9,GLOWSTONE)
Block(4,19,10,GLOWSTONE)
Block(4,20,-4,GLOWSTONE)
Block(4,20,-3,GLOWSTONE)
Block(4,20,-2,GLOWSTONE)
Block(4,20,-1,GLOWSTONE)
Block(4,20,0,GLOWSTONE)
Block(4,20,1,GLOWSTONE)
Block(4,20,3,GLOWSTONE)
Block(4,20,5,GLOWSTONE)
Block(4,20,6,GLOWSTONE)
Block(4,20,7,COAL_BLOCK)
Block(4,20,8,COAL_BLOCK)
Block(4,20,9,COAL_BLOCK)
Block(4,20,10,GLOWSTONE)
Block(4,21,-4,GLOWSTONE)
Block(4,21,-3,GLOWSTONE)
Block(4,21,-2,GLOWSTONE)
Block(4,21,-1,GLOWSTONE)
Block(4,21,0,GLOWSTONE)
Block(4,21,1,GLOWSTONE)
Block(4,21,2,GLOWSTONE)
Block(4,21,3,GLOWSTONE)
Block(4,21,4,GLOWSTONE)
Block(4,21,6,GLOWSTONE)
Block(4,21,7,GLOWSTONE)
Block(4,21,8,COAL_BLOCK)
Block(4,21,9,GLOWSTONE)
Block(4,21,10,GLOWSTONE)
Block(4,21,11,GLOWSTONE)
Block(4,22,-7,GLOWSTONE)
Block(4,22,-6,GLOWSTONE)
Block(4,22,-5,GLOWSTONE)
Block(4,22,-4,GLOWSTONE)
Block(4,22,-3,GLOWSTONE)
Block(4,22,-2,GLOWSTONE)
Block(4,22,-1,GLOWSTONE)
Block(4,22,0,GLOWSTONE)
Block(4,22,1,GLOWSTONE)
Block(4,22,2,GLOWSTONE)
Block(4,22,3,GLOWSTONE)
Block(4,22,4,GLOWSTONE)
Block(4,22,5,GLOWSTONE)
Block(4,22,6,GLOWSTONE)
Block(4,22,7,GLOWSTONE)
Block(4,22,8,GLOWSTONE)
Block(4,22,9,GLOWSTONE)
Block(4,22,10,GLOWSTONE)
Block(4,22,11,GLOWSTONE)
Block(4,23,-7,GLOWSTONE)
Block(4,23,-6,GLOWSTONE)
Block(4,23,-5,GLOWSTONE)
Block(4,23,-4,GLOWSTONE)
Block(4,23,-2,GLOWSTONE)
Block(4,23,-1,GLOWSTONE)
Block(4,23,0,GLOWSTONE)
Block(4,23,1,GLOWSTONE)
Block(4,23,2,GLOWSTONE)
Block(4,23,3,GLOWSTONE)
Block(4,23,4,GLOWSTONE)
Block(4,23,5,GLOWSTONE)
Block(4,23,6,GLOWSTONE)
Block(4,23,7,GLOWSTONE)
Block(4,23,8,GLOWSTONE)
Block(4,23,9,GLOWSTONE)
Block(4,23,10,GLOWSTONE)
Block(4,23,11,GLOWSTONE)
Block(4,24,-7,GLOWSTONE)
Block(4,24,-6,GLOWSTONE)
Block(4,24,-5,GLOWSTONE)
Block(4,24,-4,GLOWSTONE)
Block(4,24,-3,GLOWSTONE)
Block(4,24,-2,GLOWSTONE)
Block(4,24,-1,GLOWSTONE)
Block(4,24,0,GLOWSTONE)
Block(4,24,1,GLOWSTONE)
Block(4,24,2,GLOWSTONE)
Block(4,24,3,GLOWSTONE)
Block(4,24,4,GLOWSTONE)
Block(4,24,5,GLOWSTONE)
Block(4,24,6,GLOWSTONE)
Block(4,24,7,GLOWSTONE)
Block(4,24,8,GLOWSTONE)
Block(4,24,9,GLOWSTONE)
Block(4,24,10,GLOWSTONE)
Block(4,25,-6,GLOWSTONE)
Block(4,25,-5,GLOWSTONE)
Block(4,25,-4,GLOWSTONE)
Block(4,25,-3,GLOWSTONE)
Block(4,25,-2,GLOWSTONE)
Block(4,25,-1,GLOWSTONE)
Block(4,25,0,GLOWSTONE)
Block(4,25,1,GLOWSTONE)
Block(4,25,2,GLOWSTONE)
Block(4,25,3,GLOWSTONE)
Block(4,25,6,GLOWSTONE)
Block(4,25,7,GLOWSTONE)
Block(4,25,8,GLOWSTONE)
Block(4,25,9,GLOWSTONE)
Block(4,26,-5,GLOWSTONE)
Block(4,26,-4,GLOWSTONE)
Block(4,26,-3,GLOWSTONE)
Block(4,26,-2,GLOWSTONE)
Block(4,26,-1,GLOWSTONE)
Block(4,26,0,GLOWSTONE)
Block(4,26,1,GLOWSTONE)
Block(4,26,2,GLOWSTONE)
Block(4,26,3,GLOWSTONE)
Block(4,26,7,GLOWSTONE)
Block(4,26,8,GLOWSTONE)
Block(4,27,-4,GLOWSTONE)
Block(4,27,-3,GLOWSTONE)
Block(4,27,-2,GLOWSTONE)
Block(4,27,-1,GLOWSTONE)
Block(4,27,0,GLOWSTONE)
Block(4,27,1,GLOWSTONE)
Block(4,27,2,GLOWSTONE)
Block(4,27,3,GLOWSTONE)
Block(4,28,-3,GLOWSTONE)
Block(4,28,-2,GLOWSTONE)
Block(4,28,-1,GLOWSTONE)
Block(5,0,-4,COAL_BLOCK)
Block(5,0,-3,COAL_BLOCK)
Block(5,0,-2,COAL_BLOCK)
Block(5,0,-1,COAL_BLOCK)
Block(5,0,2,COAL_BLOCK)
Block(5,0,3,COAL_BLOCK)
Block(5,0,4,COAL_BLOCK)
Block(5,1,-4,COAL_BLOCK)
Block(5,1,-3,COAL_BLOCK)
Block(5,1,-2,COAL_BLOCK)
Block(5,1,-1,COAL_BLOCK)
Block(5,1,2,COAL_BLOCK)
Block(5,1,3,COAL_BLOCK)
Block(5,1,4,COAL_BLOCK)
Block(5,2,-2,COAL_BLOCK)
Block(5,2,3,COAL_BLOCK)
Block(5,15,1,COAL_BLOCK)
Block(5,15,2,COAL_BLOCK)
Block(5,15,3,COAL_BLOCK)
Block(5,16,-10,GLOWSTONE)
Block(5,16,-9,GLOWSTONE)
Block(5,16,1,COAL_BLOCK)
Block(5,16,2,COAL_BLOCK)
Block(5,16,3,COAL_BLOCK)
Block(5,16,4,COAL_BLOCK)
Block(5,16,5,COAL_BLOCK)
Block(5,16,6,COAL_BLOCK)
Block(5,16,7,COAL_BLOCK)
Block(5,17,-10,GLOWSTONE)
Block(5,17,1,COAL_BLOCK)
Block(5,17,2,COAL_BLOCK)
Block(5,17,3,COAL_BLOCK)
Block(5,17,4,COAL_BLOCK)
Block(5,17,5,COAL_BLOCK)
Block(5,17,6,COAL_BLOCK)
Block(5,17,7,COAL_BLOCK)
Block(5,17,9,GLOWSTONE)
Block(5,17,10,GLOWSTONE)
Block(5,18,-6,GLOWSTONE)
Block(5,18,1,GLOWSTONE)
Block(5,18,2,GLOWSTONE)
Block(5,18,3,GLOWSTONE)
Block(5,18,5,COAL_BLOCK)
Block(5,18,6,COAL_BLOCK)
Block(5,18,7,COAL_BLOCK)
Block(5,18,8,COAL_BLOCK)
Block(5,18,9,GLOWSTONE)
Block(5,18,10,GLOWSTONE)
Block(5,19,-6,GLOWSTONE)
Block(5,19,-1,GLOWSTONE)
Block(5,19,0,GLOWSTONE)
Block(5,19,1,GLOWSTONE)
Block(5,19,5,COAL_BLOCK)
Block(5,19,6,COAL_BLOCK)
Block(5,19,7,COAL_BLOCK)
Block(5,19,8,COAL_BLOCK)
Block(5,19,9,COAL_BLOCK)
Block(5,19,10,GLOWSTONE)
Block(5,20,-6,GLOWSTONE)
Block(5,20,-5,GLOWSTONE)
Block(5,20,-3,GLOWSTONE)
Block(5,20,-1,GLOWSTONE)
Block(5,20,0,GLOWSTONE)
Block(5,20,1,GLOWSTONE)
Block(5,20,2,GLOWSTONE)
Block(5,20,3,GLOWSTONE)
Block(5,20,4,GLOWSTONE)
Block(5,20,5,GLOWSTONE)
Block(5,20,6,COAL_BLOCK)
Block(5,20,7,COAL_BLOCK)
Block(5,20,8,COAL_BLOCK)
Block(5,20,9,COAL_BLOCK)
Block(5,20,10,COAL_BLOCK)
Block(5,20,11,GLOWSTONE)
Block(5,21,-7,GLOWSTONE)
Block(5,21,-6,GLOWSTONE)
Block(5,21,-5,GLOWSTONE)
Block(5,21,-4,GLOWSTONE)
Block(5,21,-3,GLOWSTONE)
Block(5,21,-2,GLOWSTONE)
Block(5,21,-1,GLOWSTONE)
Block(5,21,0,GLOWSTONE)
Block(5,21,1,GLOWSTONE)
Block(5,21,2,GLOWSTONE)
Block(5,21,3,GLOWSTONE)
Block(5,21,4,GLOWSTONE)
Block(5,21,5,GLOWSTONE)
Block(5,21,6,GLOWSTONE)
Block(5,21,7,COAL_BLOCK)
Block(5,21,8,COAL_BLOCK)
Block(5,21,9,COAL_BLOCK)
Block(5,21,10,COAL_BLOCK)
Block(5,21,11,COAL_BLOCK)
Block(5,22,-7,GLOWSTONE)
Block(5,22,-6,GLOWSTONE)
Block(5,22,-5,GLOWSTONE)
Block(5,22,-3,GLOWSTONE)
Block(5,22,-2,GLOWSTONE)
Block(5,22,-1,GLOWSTONE)
Block(5,22,0,GLOWSTONE)
Block(5,22,1,GLOWSTONE)
Block(5,22,2,GLOWSTONE)
Block(5,22,3,GLOWSTONE)
Block(5,22,4,GLOWSTONE)
Block(5,22,5,GLOWSTONE)
Block(5,22,6,GLOWSTONE)
Block(5,22,7,GLOWSTONE)
Block(5,22,8,GLOWSTONE)
Block(5,22,9,GLOWSTONE)
Block(5,22,10,COAL_BLOCK)
Block(5,22,11,GLOWSTONE)
Block(5,22,12,GLOWSTONE)
Block(5,23,-7,GLOWSTONE)
Block(5,23,-6,GLOWSTONE)
Block(5,23,-5,GLOWSTONE)
Block(5,23,-1,GLOWSTONE)
Block(5,23,0,GLOWSTONE)
Block(5,23,1,GLOWSTONE)
Block(5,23,2,GLOWSTONE)
Block(5,23,3,GLOWSTONE)
Block(5,23,4,GLOWSTONE)
Block(5,23,5,GLOWSTONE)
Block(5,23,6,GLOWSTONE)
Block(5,23,7,GLOWSTONE)
Block(5,23,8,GLOWSTONE)
Block(5,23,9,GLOWSTONE)
Block(5,23,10,GLOWSTONE)
Block(5,23,11,GLOWSTONE)
Block(5,24,-6,GLOWSTONE)
Block(5,24,-1,GLOWSTONE)
Block(5,24,0,GLOWSTONE)
Block(5,24,1,GLOWSTONE)
Block(5,24,2,GLOWSTONE)
Block(5,24,3,GLOWSTONE)
Block(5,24,4,GLOWSTONE)
Block(5,24,5,GLOWSTONE)
Block(5,24,6,GLOWSTONE)
Block(5,24,7,GLOWSTONE)
Block(5,24,8,GLOWSTONE)
Block(5,24,9,GLOWSTONE)
Block(5,24,10,GLOWSTONE)
Block(5,24,11,GLOWSTONE)
Block(5,25,-3,GLOWSTONE)
Block(5,25,-2,GLOWSTONE)
Block(5,25,-1,GLOWSTONE)
Block(5,25,0,GLOWSTONE)
Block(5,25,1,GLOWSTONE)
Block(5,25,2,GLOWSTONE)
Block(5,25,3,GLOWSTONE)
Block(5,25,7,GLOWSTONE)
Block(5,25,8,GLOWSTONE)
Block(5,25,9,GLOWSTONE)
Block(5,25,10,GLOWSTONE)
Block(5,26,-4,GLOWSTONE)
Block(5,26,-3,GLOWSTONE)
Block(5,26,-2,GLOWSTONE)
Block(5,26,-1,GLOWSTONE)
Block(5,26,0,GLOWSTONE)
Block(5,26,1,GLOWSTONE)
Block(5,26,2,GLOWSTONE)
Block(5,26,3,GLOWSTONE)
Block(5,26,7,GLOWSTONE)
Block(5,26,8,GLOWSTONE)
Block(5,26,9,GLOWSTONE)
Block(5,27,-3,GLOWSTONE)
Block(5,27,-2,GLOWSTONE)
Block(5,27,-1,GLOWSTONE)
Block(5,27,0,GLOWSTONE)
Block(5,27,1,GLOWSTONE)
Block(5,27,2,GLOWSTONE)
Block(5,28,-2,GLOWSTONE)
Block(6,0,-4,COAL_BLOCK)
Block(6,0,-3,COAL_BLOCK)
Block(6,0,-2,COAL_BLOCK)
Block(6,0,3,COAL_BLOCK)
Block(6,0,4,COAL_BLOCK)
Block(6,0,5,COAL_BLOCK)
Block(6,1,-3,COAL_BLOCK)
Block(6,1,3,COAL_BLOCK)
Block(6,1,4,MOB_SPAWNER,NetherGricelTree/10-mob_spawner.nbt)
Block(6,1,5,COAL_BLOCK)
Block(6,2,4,CARPET:15)
Block(6,15,1,COAL_BLOCK)
Block(6,15,2,COAL_BLOCK)
Block(6,15,3,COAL_BLOCK)
Block(6,16,0,GLOWSTONE)
Block(6,16,1,COAL_BLOCK)
Block(6,16,2,COAL_BLOCK)
Block(6,16,3,COAL_BLOCK)
Block(6,16,6,COAL_BLOCK)
Block(6,16,11,GLOWSTONE)
Block(6,17,-1,GLOWSTONE)
Block(6,17,0,GLOWSTONE)
Block(6,17,1,COAL_BLOCK)
Block(6,17,2,COAL_BLOCK)
Block(6,17,3,COAL_BLOCK)
Block(6,17,5,COAL_BLOCK)
Block(6,17,6,COAL_BLOCK)
Block(6,17,7,COAL_BLOCK)
Block(6,17,11,GLOWSTONE)
Block(6,18,0,GLOWSTONE)
Block(6,18,2,GLOWSTONE)
Block(6,18,5,COAL_BLOCK)
Block(6,18,6,COAL_BLOCK)
Block(6,18,7,COAL_BLOCK)
Block(6,18,9,GLOWSTONE)
Block(6,18,11,GLOWSTONE)
Block(6,19,0,GLOWSTONE)
Block(6,19,5,GLOWSTONE)
Block(6,19,6,COAL_BLOCK)
Block(6,19,7,COAL_BLOCK)
Block(6,19,8,COAL_BLOCK)
Block(6,19,9,COAL_BLOCK)
Block(6,19,10,COAL_BLOCK)
Block(6,19,11,GLOWSTONE)
Block(6,19,12,GLOWSTONE)
Block(6,20,-1,GLOWSTONE)
Block(6,20,0,GLOWSTONE)
Block(6,20,1,GLOWSTONE)
Block(6,20,3,GLOWSTONE)
Block(6,20,5,GLOWSTONE)
Block(6,20,6,GLOWSTONE)
Block(6,20,7,COAL_BLOCK)
Block(6,20,8,COAL_BLOCK)
Block(6,20,9,COAL_BLOCK)
Block(6,20,10,COAL_BLOCK)
Block(6,20,11,COAL_BLOCK)
Block(6,20,12,GLOWSTONE)
Block(6,20,13,GLOWSTONE)
Block(6,21,0,GLOWSTONE)
Block(6,21,1,GLOWSTONE)
Block(6,21,2,GLOWSTONE)
Block(6,21,3,GLOWSTONE)
Block(6,21,4,GLOWSTONE)
Block(6,21,6,GLOWSTONE)
Block(6,21,7,GLOWSTONE)
Block(6,21,8,COAL_BLOCK)
Block(6,21,9,COAL_BLOCK)
Block(6,21,10,COAL_BLOCK)
Block(6,21,11,COAL_BLOCK)
Block(6,21,12,GLOWSTONE)
Block(6,22,-6,GLOWSTONE)
Block(6,22,0,GLOWSTONE)
Block(6,22,1,GLOWSTONE)
Block(6,22,2,GLOWSTONE)
Block(6,22,3,GLOWSTONE)
Block(6,22,4,GLOWSTONE)
Block(6,22,5,GLOWSTONE)
Block(6,22,7,GLOWSTONE)
Block(6,22,8,GLOWSTONE)
Block(6,22,9,COAL_BLOCK)
Block(6,22,10,COAL_BLOCK)
Block(6,22,11,COAL_BLOCK)
Block(6,22,12,GLOWSTONE)
Block(6,22,13,GLOWSTONE)
Block(6,23,-6,GLOWSTONE)
Block(6,23,0,GLOWSTONE)
Block(6,23,1,GLOWSTONE)
Block(6,23,2,GLOWSTONE)
Block(6,23,3,GLOWSTONE)
Block(6,23,4,GLOWSTONE)
Block(6,23,5,GLOWSTONE)
Block(6,23,6,GLOWSTONE)
Block(6,23,8,GLOWSTONE)
Block(6,23,9,GLOWSTONE)
Block(6,23,10,GLOWSTONE)
Block(6,23,11,GLOWSTONE)
Block(6,23,12,GLOWSTONE)
Block(6,24,-1,GLOWSTONE)
Block(6,24,0,GLOWSTONE)
Block(6,24,1,GLOWSTONE)
Block(6,24,2,GLOWSTONE)
Block(6,24,3,GLOWSTONE)
Block(6,24,5,GLOWSTONE)
Block(6,24,8,GLOWSTONE)
Block(6,24,9,GLOWSTONE)
Block(6,24,10,GLOWSTONE)
Block(6,25,-1,GLOWSTONE)
Block(6,25,0,GLOWSTONE)
Block(6,25,1,GLOWSTONE)
Block(6,25,2,GLOWSTONE)
Block(6,25,7,GLOWSTONE)
Block(6,25,8,GLOWSTONE)
Block(6,25,9,GLOWSTONE)
Block(6,26,-1,GLOWSTONE)
Block(6,26,0,GLOWSTONE)
Block(6,26,1,GLOWSTONE)
Block(6,26,8,GLOWSTONE)
Block(6,27,0,GLOWSTONE)
Block(7,0,-4,COAL_BLOCK)
Block(7,0,-3,COAL_BLOCK)
Block(7,0,-2,COAL_BLOCK)
Block(7,0,4,COAL_BLOCK)
Block(7,0,5,COAL_BLOCK)
Block(7,1,-4,COAL_BLOCK)
Block(7,1,-3,COAL_BLOCK)
Block(7,1,4,COAL_BLOCK)
Block(7,10,1,GLOWSTONE)
Block(7,11,0,GLOWSTONE)
Block(7,11,1,GLOWSTONE)
Block(7,11,2,GLOWSTONE)
Block(7,12,0,GLOWSTONE)
Block(7,12,1,GLOWSTONE)
Block(7,12,2,GLOWSTONE)
Block(7,13,0,GLOWSTONE)
Block(7,13,1,GLOWSTONE)
Block(7,13,2,GLOWSTONE)
Block(7,13,7,GLOWSTONE)
Block(7,14,-1,GLOWSTONE)
Block(7,14,0,GLOWSTONE)
Block(7,14,1,GLOWSTONE)
Block(7,14,2,GLOWSTONE)
Block(7,14,3,GLOWSTONE)
Block(7,14,7,GLOWSTONE)
Block(7,14,11,GLOWSTONE)
Block(7,15,-1,GLOWSTONE)
Block(7,15,0,GLOWSTONE)
Block(7,15,1,GLOWSTONE)
Block(7,15,2,COAL_BLOCK)
Block(7,15,7,GLOWSTONE)
Block(7,15,11,GLOWSTONE)
Block(7,16,-1,GLOWSTONE)
Block(7,16,0,GLOWSTONE)
Block(7,16,1,COAL_BLOCK)
Block(7,16,2,COAL_BLOCK)
Block(7,16,3,COAL_BLOCK)
Block(7,16,5,GLOWSTONE)
Block(7,16,6,GLOWSTONE)
Block(7,16,7,GLOWSTONE)
Block(7,16,11,GLOWSTONE)
Block(7,17,-1,GLOWSTONE)
Block(7,17,0,GLOWSTONE)
Block(7,17,1,GLOWSTONE)
Block(7,17,2,COAL_BLOCK)
Block(7,17,5,GLOWSTONE)
Block(7,17,6,GLOWSTONE)
Block(7,17,7,GLOWSTONE)
Block(7,17,10,GLOWSTONE)
Block(7,17,11,GLOWSTONE)
Block(7,17,12,GLOWSTONE)
Block(7,18,-1,GLOWSTONE)
Block(7,18,0,GLOWSTONE)
Block(7,18,1,GLOWSTONE)
Block(7,18,5,GLOWSTONE)
Block(7,18,6,GLOWSTONE)
Block(7,18,7,GLOWSTONE)
Block(7,18,10,GLOWSTONE)
Block(7,18,11,GLOWSTONE)
Block(7,18,12,GLOWSTONE)
Block(7,19,6,GLOWSTONE)
Block(7,19,7,GLOWSTONE)
Block(7,19,8,GLOWSTONE)
Block(7,19,9,COAL_BLOCK)
Block(7,19,10,GLOWSTONE)
Block(7,19,11,GLOWSTONE)
Block(7,19,12,GLOWSTONE)
Block(7,19,13,GLOWSTONE)
Block(7,20,7,GLOWSTONE)
Block(7,20,8,COAL_BLOCK)
Block(7,20,9,COAL_BLOCK)
Block(7,20,10,COAL_BLOCK)
Block(7,20,11,GLOWSTONE)
Block(7,20,12,GLOWSTONE)
Block(7,20,13,GLOWSTONE)
Block(7,21,1,GLOWSTONE)
Block(7,21,2,GLOWSTONE)
Block(7,21,3,GLOWSTONE)
Block(7,21,7,GLOWSTONE)
Block(7,21,8,GLOWSTONE)
Block(7,21,9,COAL_BLOCK)
Block(7,21,10,COAL_BLOCK)
Block(7,21,11,COAL_BLOCK)
Block(7,21,12,GLOWSTONE)
Block(7,21,13,GLOWSTONE)
Block(7,22,1,GLOWSTONE)
Block(7,22,2,GLOWSTONE)
Block(7,22,3,GLOWSTONE)
Block(7,22,9,GLOWSTONE)
Block(7,22,10,COAL_BLOCK)
Block(7,22,11,GLOWSTONE)
Block(7,22,12,GLOWSTONE)
Block(7,22,13,GLOWSTONE)
Block(7,23,0,GLOWSTONE)
Block(7,23,1,GLOWSTONE)
Block(7,23,2,GLOWSTONE)
Block(7,23,3,GLOWSTONE)
Block(7,23,8,GLOWSTONE)
Block(7,23,9,GLOWSTONE)
Block(7,23,10,GLOWSTONE)
Block(7,23,11,GLOWSTONE)
Block(7,23,12,GLOWSTONE)
Block(7,23,13,GLOWSTONE)
Block(7,24,0,GLOWSTONE)
Block(7,24,1,GLOWSTONE)
Block(7,24,2,GLOWSTONE)
Block(7,24,9,GLOWSTONE)
Block(7,24,10,GLOWSTONE)
Block(7,24,11,GLOWSTONE)
Block(7,25,-1,GLOWSTONE)
Block(7,25,0,GLOWSTONE)
Block(7,25,1,GLOWSTONE)
Block(7,26,0,GLOWSTONE)
Block(8,0,-5,COAL_BLOCK)
Block(8,0,-4,COAL_BLOCK)
Block(8,0,-3,COAL_BLOCK)
Block(8,0,5,COAL_BLOCK)
Block(8,0,6,COAL_BLOCK)
Block(8,1,-4,COAL_BLOCK)
Block(8,7,0,GLOWSTONE)
Block(8,8,0,GLOWSTONE)
Block(8,8,2,GLOWSTONE)
Block(8,9,0,GLOWSTONE)
Block(8,9,1,GLOWSTONE)
Block(8,9,2,GLOWSTONE)
Block(8,10,0,GLOWSTONE)
Block(8,10,1,GLOWSTONE)
Block(8,10,2,GLOWSTONE)
Block(8,11,0,GLOWSTONE)
Block(8,11,1,GLOWSTONE)
Block(8,11,2,GLOWSTONE)
Block(8,12,-1,GLOWSTONE)
Block(8,12,0,GLOWSTONE)
Block(8,12,1,GLOWSTONE)
Block(8,12,2,GLOWSTONE)
Block(8,12,11,GLOWSTONE)
Block(8,13,-1,GLOWSTONE)
Block(8,13,0,GLOWSTONE)
Block(8,13,1,GLOWSTONE)
Block(8,13,2,GLOWSTONE)
Block(8,13,3,GLOWSTONE)
Block(8,13,10,GLOWSTONE)
Block(8,13,11,GLOWSTONE)
Block(8,14,-1,GLOWSTONE)
Block(8,14,0,GLOWSTONE)
Block(8,14,1,GLOWSTONE)
Block(8,14,2,GLOWSTONE)
Block(8,14,3,GLOWSTONE)
Block(8,14,6,GLOWSTONE)
Block(8,14,10,GLOWSTONE)
Block(8,14,11,GLOWSTONE)
Block(8,15,-1,GLOWSTONE)
Block(8,15,0,GLOWSTONE)
Block(8,15,1,GLOWSTONE)
Block(8,15,2,GLOWSTONE)
Block(8,15,3,GLOWSTONE)
Block(8,15,6,GLOWSTONE)
Block(8,15,10,GLOWSTONE)
Block(8,15,11,GLOWSTONE)
Block(8,15,12,GLOWSTONE)
Block(8,16,-1,GLOWSTONE)
Block(8,16,0,GLOWSTONE)
Block(8,16,1,GLOWSTONE)
Block(8,16,2,GLOWSTONE)
Block(8,16,3,GLOWSTONE)
Block(8,16,6,GLOWSTONE)
Block(8,16,10,GLOWSTONE)
Block(8,16,11,GLOWSTONE)
Block(8,16,12,GLOWSTONE)
Block(8,17,-1,GLOWSTONE)
Block(8,17,0,GLOWSTONE)
Block(8,17,1,GLOWSTONE)
Block(8,17,2,GLOWSTONE)
Block(8,17,3,GLOWSTONE)
Block(8,17,5,GLOWSTONE)
Block(8,17,6,GLOWSTONE)
Block(8,17,7,GLOWSTONE)
Block(8,17,10,GLOWSTONE)
Block(8,17,11,GLOWSTONE)
Block(8,17,12,GLOWSTONE)
Block(8,18,0,GLOWSTONE)
Block(8,18,6,GLOWSTONE)
Block(8,18,9,GLOWSTONE)
Block(8,18,10,GLOWSTONE)
Block(8,18,11,GLOWSTONE)
Block(8,18,12,GLOWSTONE)
Block(8,19,2,GLOWSTONE)
Block(8,19,8,GLOWSTONE)
Block(8,19,9,GLOWSTONE)
Block(8,19,10,GLOWSTONE)
Block(8,19,11,GLOWSTONE)
Block(8,19,12,GLOWSTONE)
Block(8,20,2,GLOWSTONE)
Block(8,20,7,GLOWSTONE)
Block(8,20,8,GLOWSTONE)
Block(8,20,9,GLOWSTONE)
Block(8,20,10,GLOWSTONE)
Block(8,20,11,GLOWSTONE)
Block(8,20,12,GLOWSTONE)
Block(8,20,13,GLOWSTONE)
Block(8,21,2,GLOWSTONE)
Block(8,21,8,GLOWSTONE)
Block(8,21,10,GLOWSTONE)
Block(8,21,11,GLOWSTONE)
Block(8,21,12,GLOWSTONE)
Block(8,21,13,GLOWSTONE)
Block(8,22,1,GLOWSTONE)
Block(8,22,2,GLOWSTONE)
Block(8,22,3,GLOWSTONE)
Block(8,22,10,GLOWSTONE)
Block(8,22,11,GLOWSTONE)
Block(8,22,12,GLOWSTONE)
Block(8,22,13,GLOWSTONE)
Block(8,23,2,GLOWSTONE)
Block(8,23,9,GLOWSTONE)
Block(8,23,10,GLOWSTONE)
Block(8,23,11,GLOWSTONE)
Block(8,23,12,GLOWSTONE)
Block(8,24,10,GLOWSTONE)
Block(9,0,-5,COAL_BLOCK)
Block(9,0,-4,MOB_SPAWNER,NetherGricelTree/11-mob_spawner.nbt)
Block(9,1,-5,COAL_BLOCK)
Block(9,1,-4,COAL_BLOCK)
Block(9,8,1,GLOWSTONE)
Block(9,9,1,GLOWSTONE)
Block(9,10,1,GLOWSTONE)
Block(9,11,0,GLOWSTONE)
Block(9,11,1,GLOWSTONE)
Block(9,11,2,GLOWSTONE)
Block(9,12,0,GLOWSTONE)
Block(9,12,1,GLOWSTONE)
Block(9,12,2,GLOWSTONE)
Block(9,13,-1,GLOWSTONE)
Block(9,13,0,GLOWSTONE)
Block(9,13,1,GLOWSTONE)
Block(9,13,2,GLOWSTONE)
Block(9,14,-1,GLOWSTONE)
Block(9,14,1,GLOWSTONE)
Block(9,14,2,GLOWSTONE)
Block(9,14,3,GLOWSTONE)
Block(9,14,11,GLOWSTONE)
Block(9,15,0,GLOWSTONE)
Block(9,15,1,GLOWSTONE)
Block(9,15,2,GLOWSTONE)
Block(9,15,10,GLOWSTONE)
Block(9,15,11,GLOWSTONE)
Block(9,16,1,GLOWSTONE)
Block(9,16,2,GLOWSTONE)
Block(9,16,3,GLOWSTONE)
Block(9,16,10,GLOWSTONE)
Block(9,16,11,GLOWSTONE)
Block(9,16,12,GLOWSTONE)
Block(9,17,2,GLOWSTONE)
Block(9,17,10,GLOWSTONE)
Block(9,17,11,GLOWSTONE)
Block(9,17,12,GLOWSTONE)
Block(9,18,10,GLOWSTONE)
Block(9,18,11,GLOWSTONE)
Block(9,18,12,GLOWSTONE)
Block(9,19,9,GLOWSTONE)
Block(9,19,10,GLOWSTONE)
Block(9,19,11,GLOWSTONE)
Block(9,19,12,GLOWSTONE)
Block(9,20,9,GLOWSTONE)
Block(9,20,10,GLOWSTONE)
Block(9,20,11,GLOWSTONE)
Block(9,20,12,GLOWSTONE)
Block(9,21,9,GLOWSTONE)
Block(9,21,10,GLOWSTONE)
Block(9,21,11,GLOWSTONE)
Block(9,21,12,GLOWSTONE)
Block(9,21,13,GLOWSTONE)
Block(9,22,10,GLOWSTONE)
Block(9,22,11,GLOWSTONE)
Block(9,22,12,GLOWSTONE)
Block(10,0,-6,COAL_BLOCK)
Block(10,0,-5,COAL_BLOCK)
Block(10,17,11,GLOWSTONE)
Block(10,18,11,GLOWSTONE)
Block(10,19,10,GLOWSTONE)
Block(10,19,11,GLOWSTONE)
Block(10,19,12,GLOWSTONE)
Block(10,20,11,GLOWSTONE)
Block(10,21,10,GLOWSTONE)
Block(10,21,11,GLOWSTONE)
Block(10,21,12,GLOWSTONE)
Block(10,22,11,GLOWSTONE)
Block(11,0,-7,COAL_BLOCK)
Block(11,0,-6,COAL_BLOCK)
Block(12,0,-7,COAL_BLOCK)

#######################################################################
# +-----------------------------------------------------------------+ #
# |                            BO3 checks                           | #
# +-----------------------------------------------------------------+ #
#######################################################################

BlockCheck(0,-1,0,CONCRETE_POWDER,NETHERRACK,MYCEL)

#######################################################################
# +-----------------------------------------------------------------+ #
# |                             Branches                            | #
# +-----------------------------------------------------------------+ #
#######################################################################


#######################################################################
# +-----------------------------------------------------------------+ #
# |                             Entities                            | #
# +-----------------------------------------------------------------+ #
#######################################################################


#######################################################################
# +-----------------------------------------------------------------+ #
# |                            Particles                            | #
# +-----------------------------------------------------------------+ #
#######################################################################


#######################################################################
# +-----------------------------------------------------------------+ #
# |                             Spawners                            | #
# +-----------------------------------------------------------------+ #
#######################################################################


#######################################################################
# +-----------------------------------------------------------------+ #
# |                             ModData                             | #
# +-----------------------------------------------------------------+ #
#######################################################################

